<robot name="telescoping_antenna_mast">
  <material name="aluminum">
    <color rgba="0.76 0.78 0.82 1" />
  </material>
  <material name="dark_mount">
    <color rgba="0.18 0.18 0.2 1" />
  </material>
  <link name="base_section">
    <inertial>
      <origin xyz="0 0 -0.2035" rpy="0 0 0" />
      <mass value="1.9" />
      <inertia ixx="0.0267978" ixy="0" ixz="0" iyy="0.0271911" iyz="0" izz="0.0015333" />
    </inertial>
    <visual>
      <geometry>
        <mesh filename="meshes/base_section.glb" />
      </geometry>
      <material name="dark_mount">
        <color rgba="0.18 0.18 0.2 1" />
      </material>
    </visual>
    <collision>
      <origin xyz="-0.01875 0 -0.17" rpy="0 0 0" />
      <geometry>
        <box size="0.0025 0.03 0.34" />
      </geometry>
    </collision>
    <collision>
      <origin xyz="0.01875 0 -0.17" rpy="0 0 0" />
      <geometry>
        <box size="0.0025 0.03 0.34" />
      </geometry>
    </collision>
    <collision>
      <origin xyz="0 -0.01375 -0.17" rpy="0 0 0" />
      <geometry>
        <box size="0.035 0.0025 0.34" />
      </geometry>
    </collision>
    <collision>
      <origin xyz="0 0.01375 -0.17" rpy="0 0 0" />
      <geometry>
        <box size="0.035 0.0025 0.34" />
      </geometry>
    </collision>
    <collision>
      <origin xyz="0 0 -0.3675" rpy="0 0 0" />
      <geometry>
        <box size="0.062 0.048 0.055" />
      </geometry>
    </collision>
    <collision>
      <origin xyz="0 0 -0.401" rpy="0 0 0" />
      <geometry>
        <box size="0.078 0.06 0.012" />
      </geometry>
    </collision>
  </link>
  <link name="middle_section">
    <inertial>
      <origin xyz="0 0 -0.03" rpy="0 0 0" />
      <mass value="0.72" />
      <inertia ixx="0.00542904" ixy="0" ixz="0" iyy="0.00546144" iyz="0" izz="9.048e-05" />
    </inertial>
    <visual>
      <geometry>
        <mesh filename="meshes/middle_section.glb" />
      </geometry>
      <material name="aluminum">
        <color rgba="0.76 0.78 0.82 1" />
      </material>
    </visual>
    <collision>
      <origin xyz="-0.015 0 -0.03" rpy="0 0 0" />
      <geometry>
        <box size="0.002 0.022 0.3" />
      </geometry>
    </collision>
    <collision>
      <origin xyz="0.015 0 -0.03" rpy="0 0 0" />
      <geometry>
        <box size="0.002 0.022 0.3" />
      </geometry>
    </collision>
    <collision>
      <origin xyz="0 -0.01 -0.03" rpy="0 0 0" />
      <geometry>
        <box size="0.028 0.002 0.3" />
      </geometry>
    </collision>
    <collision>
      <origin xyz="0 0.01 -0.03" rpy="0 0 0" />
      <geometry>
        <box size="0.028 0.002 0.3" />
      </geometry>
    </collision>
  </link>
  <link name="upper_section">
    <inertial>
      <origin xyz="0 0 0.062" rpy="0 0 0" />
      <mass value="0.48" />
      <inertia ixx="0.0078984" ixy="0" ixz="0" iyy="0.00791248" iyz="0" izz="4e-05" />
    </inertial>
    <visual>
      <geometry>
        <mesh filename="meshes/upper_section.glb" />
      </geometry>
      <material name="aluminum">
        <color rgba="0.76 0.78 0.82 1" />
      </material>
    </visual>
    <collision>
      <origin xyz="0 0 -0.03" rpy="0 0 0" />
      <geometry>
        <box size="0.025 0.016 0.26" />
      </geometry>
    </collision>
    <collision>
      <origin xyz="0 0 0.102" rpy="0 0 0" />
      <geometry>
        <box size="0.0214 0.0124 0.004" />
      </geometry>
    </collision>
    <collision>
      <origin xyz="0 0 0.194" rpy="0 0 0" />
      <geometry>
        <cylinder radius="0.003" length="0.18" />
      </geometry>
    </collision>
  </link>
  <joint name="base_to_middle" type="prismatic">
    <parent link="base_section" />
    <child link="middle_section" />
    <axis xyz="0 0 1" />
    <limit effort="70" velocity="0.4" lower="0" upper="0.12" />
  </joint>
  <joint name="middle_to_upper" type="prismatic">
    <origin xyz="0 0 0.12" rpy="0 0 0" />
    <parent link="middle_section" />
    <child link="upper_section" />
    <axis xyz="0 0 1" />
    <limit effort="45" velocity="0.45" lower="0" upper="0.105" />
  </joint>
</robot>