<robot name="luxury_watch_winder_box">
  <material name="walnut_wood">
    <color rgba="0.29 0.19 0.11 1" />
  </material>
  <material name="dark_lacquer">
    <color rgba="0.18 0.11 0.07 1" />
  </material>
  <material name="charcoal_velvet">
    <color rgba="0.11 0.11 0.12 1" />
  </material>
  <material name="brushed_steel">
    <color rgba="0.79 0.8 0.82 1" />
  </material>
  <material name="satin_brass">
    <color rgba="0.73 0.62 0.39 1" />
  </material>
  <material name="smoked_glass">
    <color rgba="0.38 0.44 0.48 0.28" />
  </material>
  <material name="black_leather">
    <color rgba="0.1 0.1 0.11 1" />
  </material>
  <link name="body">
    <inertial>
      <origin xyz="0 0 0.059" rpy="0 0 0" />
      <mass value="3.8" />
      <inertia ixx="0.0177172" ixy="0" ixz="0" iyy="0.0348409" iyz="0" izz="0.0437396" />
    </inertial>
    <visual>
      <geometry>
        <mesh filename="meshes/body_shell.glb" />
      </geometry>
      <material name="walnut_wood">
        <color rgba="0.29 0.19 0.11 1" />
      </material>
    </visual>
    <visual>
      <geometry>
        <mesh filename="meshes/body_bottom.glb" />
      </geometry>
      <material name="dark_lacquer">
        <color rgba="0.18 0.11 0.07 1" />
      </material>
    </visual>
    <visual>
      <geometry>
        <mesh filename="meshes/body_plinth.glb" />
      </geometry>
      <material name="dark_lacquer">
        <color rgba="0.18 0.11 0.07 1" />
      </material>
    </visual>
    <visual>
      <geometry>
        <mesh filename="meshes/body_trim.glb" />
      </geometry>
      <material name="satin_brass">
        <color rgba="0.73 0.62 0.39 1" />
      </material>
    </visual>
    <visual>
      <geometry>
        <mesh filename="meshes/body_lining.glb" />
      </geometry>
      <material name="charcoal_velvet">
        <color rgba="0.11 0.11 0.12 1" />
      </material>
    </visual>
    <visual>
      <origin xyz="0 0 0.029" rpy="0 0 0" />
      <geometry>
        <box size="0.274 0.169 0.01" />
      </geometry>
      <material name="charcoal_velvet">
        <color rgba="0.11 0.11 0.12 1" />
      </material>
    </visual>
    <visual>
      <origin xyz="0 0.004 0.031" rpy="0 0 0" />
      <geometry>
        <box size="0.23 0.096 0.004" />
      </geometry>
      <material name="charcoal_velvet">
        <color rgba="0.11 0.11 0.12 1" />
      </material>
    </visual>
    <visual>
      <origin xyz="0 -0.056 0.046" rpy="-0.16 0 0" />
      <geometry>
        <box size="0.216 0.03 0.024" />
      </geometry>
      <material name="charcoal_velvet">
        <color rgba="0.11 0.11 0.12 1" />
      </material>
    </visual>
    <visual>
      <origin xyz="-0.104 0.022 0.05" rpy="0 0 0" />
      <geometry>
        <box size="0.052 0.016 0.01" />
      </geometry>
      <material name="brushed_steel">
        <color rgba="0.79 0.8 0.82 1" />
      </material>
    </visual>
    <visual>
      <origin xyz="-0.074 0.022 0.032" rpy="0 0 0" />
      <geometry>
        <box size="0.026 0.01 0.006" />
      </geometry>
      <material name="brushed_steel">
        <color rgba="0.79 0.8 0.82 1" />
      </material>
    </visual>
    <visual>
      <origin xyz="-0.061 0.022 0.067" rpy="0 1.5708 0" />
      <geometry>
        <cylinder radius="0.012" length="0.01" />
      </geometry>
      <material name="brushed_steel">
        <color rgba="0.79 0.8 0.82 1" />
      </material>
    </visual>
    <visual>
      <origin xyz="0 0.0935 0.044" rpy="0 0 0" />
      <geometry>
        <box size="0.09 0.018 0.006" />
      </geometry>
      <material name="satin_brass">
        <color rgba="0.73 0.62 0.39 1" />
      </material>
    </visual>
    <collision name="body__visual_1__hull_001">
      <geometry>
        <mesh filename="meshes/collision/cache/6bb69feff7583f939104f1c2__hull_001.obj" />
      </geometry>
    </collision>
    <collision name="body__visual_1__hull_002">
      <geometry>
        <mesh filename="meshes/collision/cache/6bb69feff7583f939104f1c2__hull_002.obj" />
      </geometry>
    </collision>
    <collision name="body__visual_1__hull_003">
      <geometry>
        <mesh filename="meshes/collision/cache/6bb69feff7583f939104f1c2__hull_003.obj" />
      </geometry>
    </collision>
    <collision name="body__visual_1__hull_004">
      <geometry>
        <mesh filename="meshes/collision/cache/6bb69feff7583f939104f1c2__hull_004.obj" />
      </geometry>
    </collision>
    <collision name="body__visual_1__hull_005">
      <geometry>
        <mesh filename="meshes/collision/cache/6bb69feff7583f939104f1c2__hull_005.obj" />
      </geometry>
    </collision>
    <collision name="body__visual_1__hull_006">
      <geometry>
        <mesh filename="meshes/collision/cache/6bb69feff7583f939104f1c2__hull_006.obj" />
      </geometry>
    </collision>
    <collision name="body__visual_1__hull_007">
      <geometry>
        <mesh filename="meshes/collision/cache/6bb69feff7583f939104f1c2__hull_007.obj" />
      </geometry>
    </collision>
    <collision name="body__visual_1__hull_008">
      <geometry>
        <mesh filename="meshes/collision/cache/6bb69feff7583f939104f1c2__hull_008.obj" />
      </geometry>
    </collision>
    <collision name="body__visual_1__hull_009">
      <geometry>
        <mesh filename="meshes/collision/cache/6bb69feff7583f939104f1c2__hull_009.obj" />
      </geometry>
    </collision>
    <collision name="body__visual_2__hull_001">
      <geometry>
        <mesh filename="meshes/collision/cache/6b8eeb7a798a42d3f897189c__hull_001.obj" />
      </geometry>
    </collision>
    <collision name="body__visual_3__hull_001">
      <geometry>
        <mesh filename="meshes/collision/cache/d0e422c140035827056e72ba__hull_001.obj" />
      </geometry>
    </collision>
    <collision name="body__visual_4__hull_001">
      <geometry>
        <mesh filename="meshes/collision/cache/7421152eb941c2d18c6fce20__hull_001.obj" />
      </geometry>
    </collision>
    <collision name="body__visual_4__hull_002">
      <geometry>
        <mesh filename="meshes/collision/cache/7421152eb941c2d18c6fce20__hull_002.obj" />
      </geometry>
    </collision>
    <collision name="body__visual_4__hull_003">
      <geometry>
        <mesh filename="meshes/collision/cache/7421152eb941c2d18c6fce20__hull_003.obj" />
      </geometry>
    </collision>
    <collision name="body__visual_4__hull_004">
      <geometry>
        <mesh filename="meshes/collision/cache/7421152eb941c2d18c6fce20__hull_004.obj" />
      </geometry>
    </collision>
    <collision name="body__visual_4__hull_005">
      <geometry>
        <mesh filename="meshes/collision/cache/7421152eb941c2d18c6fce20__hull_005.obj" />
      </geometry>
    </collision>
    <collision name="body__visual_5__hull_001">
      <geometry>
        <mesh filename="meshes/collision/cache/f27a7cc081a23063f232e8f2__hull_001.obj" />
      </geometry>
    </collision>
    <collision name="body__visual_5__hull_002">
      <geometry>
        <mesh filename="meshes/collision/cache/f27a7cc081a23063f232e8f2__hull_002.obj" />
      </geometry>
    </collision>
    <collision name="body__visual_5__hull_003">
      <geometry>
        <mesh filename="meshes/collision/cache/f27a7cc081a23063f232e8f2__hull_003.obj" />
      </geometry>
    </collision>
    <collision name="body__visual_5__hull_004">
      <geometry>
        <mesh filename="meshes/collision/cache/f27a7cc081a23063f232e8f2__hull_004.obj" />
      </geometry>
    </collision>
    <collision name="body__visual_5__hull_005">
      <geometry>
        <mesh filename="meshes/collision/cache/f27a7cc081a23063f232e8f2__hull_005.obj" />
      </geometry>
    </collision>
    <collision name="body__visual_5__hull_006">
      <geometry>
        <mesh filename="meshes/collision/cache/f27a7cc081a23063f232e8f2__hull_006.obj" />
      </geometry>
    </collision>
    <collision name="body__visual_5__hull_007">
      <geometry>
        <mesh filename="meshes/collision/cache/f27a7cc081a23063f232e8f2__hull_007.obj" />
      </geometry>
    </collision>
    <collision name="body__visual_5__hull_008">
      <geometry>
        <mesh filename="meshes/collision/cache/f27a7cc081a23063f232e8f2__hull_008.obj" />
      </geometry>
    </collision>
    <collision name="body__visual_6">
      <origin xyz="0 0 0.029" rpy="0 0 0" />
      <geometry>
        <box size="0.274 0.169 0.01" />
      </geometry>
    </collision>
    <collision name="body__visual_7">
      <origin xyz="0 0.004 0.031" rpy="0 0 0" />
      <geometry>
        <box size="0.23 0.096 0.004" />
      </geometry>
    </collision>
    <collision name="body__visual_8">
      <origin xyz="0 -0.056 0.046" rpy="-0.16 0 0" />
      <geometry>
        <box size="0.216 0.03 0.024" />
      </geometry>
    </collision>
    <collision name="body__visual_9">
      <origin xyz="-0.104 0.022 0.05" rpy="0 0 0" />
      <geometry>
        <box size="0.052 0.016 0.01" />
      </geometry>
    </collision>
    <collision name="body__visual_10">
      <origin xyz="-0.074 0.022 0.032" rpy="0 0 0" />
      <geometry>
        <box size="0.026 0.01 0.006" />
      </geometry>
    </collision>
    <collision name="body__visual_11">
      <origin xyz="-0.061 0.022 0.067" rpy="0 1.5708 0" />
      <geometry>
        <cylinder radius="0.012" length="0.01" />
      </geometry>
    </collision>
    <collision name="body__visual_12">
      <origin xyz="0 0.0935 0.044" rpy="0 0 0" />
      <geometry>
        <box size="0.09 0.018 0.006" />
      </geometry>
    </collision>
  </link>
  <link name="lid">
    <inertial>
      <origin xyz="0 0.0905 0.016" rpy="0 0 0" />
      <mass value="1.2" />
      <inertia ixx="0.0044705" ixy="0" ixz="0" iyy="0.009962" iyz="0" izz="0.0142277" />
    </inertial>
    <visual>
      <origin xyz="0 0.0905 0" rpy="0 0 0" />
      <geometry>
        <mesh filename="meshes/lid_frame.glb" />
      </geometry>
      <material name="walnut_wood">
        <color rgba="0.29 0.19 0.11 1" />
      </material>
    </visual>
    <visual>
      <origin xyz="0 0.0905 0" rpy="0 0 0" />
      <geometry>
        <mesh filename="meshes/lid_bezel.glb" />
      </geometry>
      <material name="satin_brass">
        <color rgba="0.73 0.62 0.39 1" />
      </material>
    </visual>
    <visual>
      <origin xyz="0 0.0905 0" rpy="0 0 0" />
      <geometry>
        <mesh filename="meshes/lid_glass.glb" />
      </geometry>
      <material name="smoked_glass">
        <color rgba="0.38 0.44 0.48 0.28" />
      </material>
    </visual>
    <visual>
      <origin xyz="0 0.0905 0.005" rpy="0 0 0" />
      <geometry>
        <box size="0.258 0.153 0.01" />
      </geometry>
      <material name="charcoal_velvet">
        <color rgba="0.11 0.11 0.12 1" />
      </material>
    </visual>
    <collision name="lid__visual_1__hull_001">
      <origin xyz="0 0.0905 0" rpy="0 0 0" />
      <geometry>
        <mesh filename="meshes/collision/cache/33ad639d8919306523b4540b__hull_001.obj" />
      </geometry>
    </collision>
    <collision name="lid__visual_1__hull_002">
      <origin xyz="0 0.0905 0" rpy="0 0 0" />
      <geometry>
        <mesh filename="meshes/collision/cache/33ad639d8919306523b4540b__hull_002.obj" />
      </geometry>
    </collision>
    <collision name="lid__visual_1__hull_003">
      <origin xyz="0 0.0905 0" rpy="0 0 0" />
      <geometry>
        <mesh filename="meshes/collision/cache/33ad639d8919306523b4540b__hull_003.obj" />
      </geometry>
    </collision>
    <collision name="lid__visual_1__hull_004">
      <origin xyz="0 0.0905 0" rpy="0 0 0" />
      <geometry>
        <mesh filename="meshes/collision/cache/33ad639d8919306523b4540b__hull_004.obj" />
      </geometry>
    </collision>
    <collision name="lid__visual_1__hull_005">
      <origin xyz="0 0.0905 0" rpy="0 0 0" />
      <geometry>
        <mesh filename="meshes/collision/cache/33ad639d8919306523b4540b__hull_005.obj" />
      </geometry>
    </collision>
    <collision name="lid__visual_1__hull_006">
      <origin xyz="0 0.0905 0" rpy="0 0 0" />
      <geometry>
        <mesh filename="meshes/collision/cache/33ad639d8919306523b4540b__hull_006.obj" />
      </geometry>
    </collision>
    <collision name="lid__visual_1__hull_007">
      <origin xyz="0 0.0905 0" rpy="0 0 0" />
      <geometry>
        <mesh filename="meshes/collision/cache/33ad639d8919306523b4540b__hull_007.obj" />
      </geometry>
    </collision>
    <collision name="lid__visual_2__hull_001">
      <origin xyz="0 0.0905 0" rpy="0 0 0" />
      <geometry>
        <mesh filename="meshes/collision/cache/027fdceff3a2694344d153ac__hull_001.obj" />
      </geometry>
    </collision>
    <collision name="lid__visual_2__hull_002">
      <origin xyz="0 0.0905 0" rpy="0 0 0" />
      <geometry>
        <mesh filename="meshes/collision/cache/027fdceff3a2694344d153ac__hull_002.obj" />
      </geometry>
    </collision>
    <collision name="lid__visual_2__hull_003">
      <origin xyz="0 0.0905 0" rpy="0 0 0" />
      <geometry>
        <mesh filename="meshes/collision/cache/027fdceff3a2694344d153ac__hull_003.obj" />
      </geometry>
    </collision>
    <collision name="lid__visual_2__hull_004">
      <origin xyz="0 0.0905 0" rpy="0 0 0" />
      <geometry>
        <mesh filename="meshes/collision/cache/027fdceff3a2694344d153ac__hull_004.obj" />
      </geometry>
    </collision>
    <collision name="lid__visual_2__hull_005">
      <origin xyz="0 0.0905 0" rpy="0 0 0" />
      <geometry>
        <mesh filename="meshes/collision/cache/027fdceff3a2694344d153ac__hull_005.obj" />
      </geometry>
    </collision>
    <collision name="lid__visual_3__hull_001">
      <origin xyz="0 0.0905 0" rpy="0 0 0" />
      <geometry>
        <mesh filename="meshes/collision/cache/b41f5a0e55faa49bb5cfcdb8__hull_001.obj" />
      </geometry>
    </collision>
    <collision name="lid__visual_4">
      <origin xyz="0 0.0905 0.005" rpy="0 0 0" />
      <geometry>
        <box size="0.258 0.153 0.01" />
      </geometry>
    </collision>
  </link>
  <link name="winder_rotor">
    <inertial>
      <mass value="0.65" />
      <inertia ixx="0.000782708" ixy="0" ixz="0" iyy="0.00130677" iyz="0" izz="0.00130677" />
    </inertial>
    <visual>
      <origin xyz="-0.045 0 0" rpy="0 1.5708 0" />
      <geometry>
        <cylinder radius="0.007" length="0.02" />
      </geometry>
      <material name="brushed_steel">
        <color rgba="0.79 0.8 0.82 1" />
      </material>
    </visual>
    <visual>
      <origin xyz="-0.02 0 0" rpy="0 1.5708 0" />
      <geometry>
        <cylinder radius="0.028" length="0.018" />
      </geometry>
      <material name="brushed_steel">
        <color rgba="0.79 0.8 0.82 1" />
      </material>
    </visual>
    <visual>
      <origin xyz="0.01 0 0" rpy="0 1.5708 0" />
      <geometry>
        <cylinder radius="0.026" length="0.062" />
      </geometry>
      <material name="black_leather">
        <color rgba="0.1 0.1 0.11 1" />
      </material>
    </visual>
    <visual>
      <origin xyz="-0.021 0 0" rpy="0 0 0" />
      <geometry>
        <sphere radius="0.026" />
      </geometry>
      <material name="black_leather">
        <color rgba="0.1 0.1 0.11 1" />
      </material>
    </visual>
    <visual>
      <origin xyz="0.041 0 0" rpy="0 0 0" />
      <geometry>
        <sphere radius="0.026" />
      </geometry>
      <material name="black_leather">
        <color rgba="0.1 0.1 0.11 1" />
      </material>
    </visual>
    <visual>
      <origin xyz="0.046 0 0" rpy="0 1.5708 0" />
      <geometry>
        <cylinder radius="0.029" length="0.01" />
      </geometry>
      <material name="brushed_steel">
        <color rgba="0.79 0.8 0.82 1" />
      </material>
    </visual>
    <collision name="winder_rotor__visual_1">
      <origin xyz="-0.045 0 0" rpy="0 1.5708 0" />
      <geometry>
        <cylinder radius="0.007" length="0.02" />
      </geometry>
    </collision>
    <collision name="winder_rotor__visual_2">
      <origin xyz="-0.02 0 0" rpy="0 1.5708 0" />
      <geometry>
        <cylinder radius="0.028" length="0.018" />
      </geometry>
    </collision>
    <collision name="winder_rotor__visual_3">
      <origin xyz="0.01 0 0" rpy="0 1.5708 0" />
      <geometry>
        <cylinder radius="0.026" length="0.062" />
      </geometry>
    </collision>
    <collision name="winder_rotor__visual_4">
      <origin xyz="-0.021 0 0" rpy="0 0 0" />
      <geometry>
        <sphere radius="0.026" />
      </geometry>
    </collision>
    <collision name="winder_rotor__visual_5">
      <origin xyz="0.041 0 0" rpy="0 0 0" />
      <geometry>
        <sphere radius="0.026" />
      </geometry>
    </collision>
    <collision name="winder_rotor__visual_6">
      <origin xyz="0.046 0 0" rpy="0 1.5708 0" />
      <geometry>
        <cylinder radius="0.029" length="0.01" />
      </geometry>
    </collision>
  </link>
  <joint name="lid_hinge" type="revolute">
    <origin xyz="0 -0.0885 0.119" rpy="0 0 0" />
    <parent link="body" />
    <child link="lid" />
    <axis xyz="1 0 0" />
    <limit effort="8" velocity="2.5" lower="0" upper="1.18" />
  </joint>
  <joint name="winder_spin" type="continuous">
    <origin xyz="-0.045 0.022 0.067" rpy="0 0 0" />
    <parent link="body" />
    <child link="winder_rotor" />
    <axis xyz="1 0 0" />
    <limit effort="1.6" velocity="8" />
  </joint>
</robot>