<robot name="quadcopter_drone">
  <material name="shell_white">
    <color rgba="0.93 0.94 0.96 1" />
  </material>
  <material name="carbon_gray">
    <color rgba="0.22 0.24 0.27 1" />
  </material>
  <material name="satin_black">
    <color rgba="0.08 0.09 0.1 1" />
  </material>
  <material name="brushed_metal">
    <color rgba="0.69 0.71 0.74 1" />
  </material>
  <material name="rubber_black">
    <color rgba="0.05 0.05 0.06 1" />
  </material>
  <material name="glass_smoke">
    <color rgba="0.18 0.22 0.27 0.4" />
  </material>
  <material name="status_red">
    <color rgba="0.73 0.18 0.16 1" />
  </material>
  <material name="status_green">
    <color rgba="0.24 0.6 0.31 1" />
  </material>
  <link name="body">
    <inertial>
      <origin xyz="0 0 0.01" rpy="0 0 0" />
      <mass value="1.35" />
      <inertia ixx="0.0124312" ixy="0" ixz="0" iyy="0.0189113" iyz="0" izz="0.02952" />
    </inertial>
    <visual>
      <geometry>
        <mesh filename="meshes/airframe_shell.glb" />
      </geometry>
      <material name="shell_white">
        <color rgba="0.93 0.94 0.96 1" />
      </material>
    </visual>
    <visual>
      <origin xyz="0 0 -0.0165" rpy="0 0 0" />
      <geometry>
        <box size="0.1 0.118 0.01" />
      </geometry>
      <material name="carbon_gray">
        <color rgba="0.22 0.24 0.27 1" />
      </material>
    </visual>
    <visual>
      <origin xyz="0 0.048 -0.0175" rpy="0 0 0" />
      <geometry>
        <box size="0.044 0.03 0.01" />
      </geometry>
      <material name="carbon_gray">
        <color rgba="0.22 0.24 0.27 1" />
      </material>
    </visual>
    <visual>
      <origin xyz="0 -0.018 0.045" rpy="0 0 0" />
      <geometry>
        <cylinder radius="0.018" length="0.006" />
      </geometry>
      <material name="brushed_metal">
        <color rgba="0.69 0.71 0.74 1" />
      </material>
    </visual>
    <visual>
      <origin xyz="0 -0.018 0.049" rpy="0 0 0" />
      <geometry>
        <sphere radius="0.012" />
      </geometry>
      <material name="shell_white">
        <color rgba="0.93 0.94 0.96 1" />
      </material>
    </visual>
    <visual>
      <origin xyz="-0.019 0.094 0.003" rpy="1.5708 0 0" />
      <geometry>
        <cylinder radius="0.01" length="0.012" />
      </geometry>
      <material name="satin_black">
        <color rgba="0.08 0.09 0.1 1" />
      </material>
    </visual>
    <visual>
      <origin xyz="-0.019 0.1 0.003" rpy="0 0 0" />
      <geometry>
        <sphere radius="0.0045" />
      </geometry>
      <material name="glass_smoke">
        <color rgba="0.18 0.22 0.27 0.4" />
      </material>
    </visual>
    <visual>
      <origin xyz="0.019 0.094 0.003" rpy="1.5708 0 0" />
      <geometry>
        <cylinder radius="0.01" length="0.012" />
      </geometry>
      <material name="satin_black">
        <color rgba="0.08 0.09 0.1 1" />
      </material>
    </visual>
    <visual>
      <origin xyz="0.019 0.1 0.003" rpy="0 0 0" />
      <geometry>
        <sphere radius="0.0045" />
      </geometry>
      <material name="glass_smoke">
        <color rgba="0.18 0.22 0.27 0.4" />
      </material>
    </visual>
    <visual>
      <origin xyz="-0.04 -0.1 0.072" rpy="0 0 0" />
      <geometry>
        <sphere radius="0.003" />
      </geometry>
      <material name="rubber_black">
        <color rgba="0.05 0.05 0.06 1" />
      </material>
    </visual>
    <visual>
      <origin xyz="0.04 -0.1 0.072" rpy="0 0 0" />
      <geometry>
        <sphere radius="0.003" />
      </geometry>
      <material name="rubber_black">
        <color rgba="0.05 0.05 0.06 1" />
      </material>
    </visual>
    <visual>
      <origin xyz="-0.032 -0.085 0.048" rpy="0 0.616297 -2.06075" />
      <geometry>
        <cylinder radius="0.0025" length="0.0588218" />
      </geometry>
      <material name="satin_black">
        <color rgba="0.08 0.09 0.1 1" />
      </material>
    </visual>
    <visual>
      <origin xyz="0.032 -0.085 0.048" rpy="0 0.616297 -1.08084" />
      <geometry>
        <cylinder radius="0.0025" length="0.0588218" />
      </geometry>
      <material name="satin_black">
        <color rgba="0.08 0.09 0.1 1" />
      </material>
    </visual>
    <visual>
      <origin xyz="-0.11055 0.0938 0.017" rpy="0 1.52881 2.43798" />
      <geometry>
        <cylinder radius="0.01" length="0.142944" />
      </geometry>
      <material name="carbon_gray">
        <color rgba="0.22 0.24 0.27 1" />
      </material>
    </visual>
    <visual>
      <origin xyz="0.11055 0.0938 0.017" rpy="0 1.52881 0.703614" />
      <geometry>
        <cylinder radius="0.01" length="0.142944" />
      </geometry>
      <material name="carbon_gray">
        <color rgba="0.22 0.24 0.27 1" />
      </material>
    </visual>
    <visual>
      <origin xyz="-0.10385 -0.0938 0.017" rpy="0 1.5273 -2.407" />
      <geometry>
        <cylinder radius="0.01" length="0.137982" />
      </geometry>
      <material name="carbon_gray">
        <color rgba="0.22 0.24 0.27 1" />
      </material>
    </visual>
    <visual>
      <origin xyz="0.10385 -0.0938 0.017" rpy="0 1.5273 -0.734594" />
      <geometry>
        <cylinder radius="0.01" length="0.137982" />
      </geometry>
      <material name="carbon_gray">
        <color rgba="0.22 0.24 0.27 1" />
      </material>
    </visual>
    <collision name="body__visual_1__hull_001">
      <geometry>
        <mesh filename="meshes/collision/cache/d68436dd98472557be36ec2e__hull_001.obj" />
      </geometry>
    </collision>
    <collision name="body__visual_1__hull_002">
      <geometry>
        <mesh filename="meshes/collision/cache/d68436dd98472557be36ec2e__hull_002.obj" />
      </geometry>
    </collision>
    <collision name="body__visual_1__hull_003">
      <geometry>
        <mesh filename="meshes/collision/cache/d68436dd98472557be36ec2e__hull_003.obj" />
      </geometry>
    </collision>
    <collision name="body__visual_1__hull_004">
      <geometry>
        <mesh filename="meshes/collision/cache/d68436dd98472557be36ec2e__hull_004.obj" />
      </geometry>
    </collision>
    <collision name="body__visual_1__hull_005">
      <geometry>
        <mesh filename="meshes/collision/cache/d68436dd98472557be36ec2e__hull_005.obj" />
      </geometry>
    </collision>
    <collision name="body__visual_1__hull_006">
      <geometry>
        <mesh filename="meshes/collision/cache/d68436dd98472557be36ec2e__hull_006.obj" />
      </geometry>
    </collision>
    <collision name="body__visual_2">
      <origin xyz="0 0 -0.0165" rpy="0 0 0" />
      <geometry>
        <box size="0.1 0.118 0.01" />
      </geometry>
    </collision>
    <collision name="body__visual_3">
      <origin xyz="0 0.048 -0.0175" rpy="0 0 0" />
      <geometry>
        <box size="0.044 0.03 0.01" />
      </geometry>
    </collision>
    <collision name="body__visual_4">
      <origin xyz="0 -0.018 0.045" rpy="0 0 0" />
      <geometry>
        <cylinder radius="0.018" length="0.006" />
      </geometry>
    </collision>
    <collision name="body__visual_5">
      <origin xyz="0 -0.018 0.049" rpy="0 0 0" />
      <geometry>
        <sphere radius="0.012" />
      </geometry>
    </collision>
    <collision name="body__visual_6">
      <origin xyz="-0.019 0.094 0.003" rpy="1.5708 0 0" />
      <geometry>
        <cylinder radius="0.01" length="0.012" />
      </geometry>
    </collision>
    <collision name="body__visual_7">
      <origin xyz="-0.019 0.1 0.003" rpy="0 0 0" />
      <geometry>
        <sphere radius="0.0045" />
      </geometry>
    </collision>
    <collision name="body__visual_8">
      <origin xyz="0.019 0.094 0.003" rpy="1.5708 0 0" />
      <geometry>
        <cylinder radius="0.01" length="0.012" />
      </geometry>
    </collision>
    <collision name="body__visual_9">
      <origin xyz="0.019 0.1 0.003" rpy="0 0 0" />
      <geometry>
        <sphere radius="0.0045" />
      </geometry>
    </collision>
    <collision name="body__visual_10">
      <origin xyz="-0.04 -0.1 0.072" rpy="0 0 0" />
      <geometry>
        <sphere radius="0.003" />
      </geometry>
    </collision>
    <collision name="body__visual_11">
      <origin xyz="0.04 -0.1 0.072" rpy="0 0 0" />
      <geometry>
        <sphere radius="0.003" />
      </geometry>
    </collision>
    <collision name="body__visual_12">
      <origin xyz="-0.032 -0.085 0.048" rpy="0 0.616297 -2.06075" />
      <geometry>
        <cylinder radius="0.0025" length="0.0588218" />
      </geometry>
    </collision>
    <collision name="body__visual_13">
      <origin xyz="0.032 -0.085 0.048" rpy="0 0.616297 -1.08084" />
      <geometry>
        <cylinder radius="0.0025" length="0.0588218" />
      </geometry>
    </collision>
    <collision name="body__visual_14">
      <origin xyz="-0.11055 0.0938 0.017" rpy="0 1.52881 2.43798" />
      <geometry>
        <cylinder radius="0.01" length="0.142944" />
      </geometry>
    </collision>
    <collision name="body__visual_15">
      <origin xyz="0.11055 0.0938 0.017" rpy="0 1.52881 0.703614" />
      <geometry>
        <cylinder radius="0.01" length="0.142944" />
      </geometry>
    </collision>
    <collision name="body__visual_16">
      <origin xyz="-0.10385 -0.0938 0.017" rpy="0 1.5273 -2.407" />
      <geometry>
        <cylinder radius="0.01" length="0.137982" />
      </geometry>
    </collision>
    <collision name="body__visual_17">
      <origin xyz="0.10385 -0.0938 0.017" rpy="0 1.5273 -0.734594" />
      <geometry>
        <cylinder radius="0.01" length="0.137982" />
      </geometry>
    </collision>
  </link>
  <link name="landing_gear">
    <inertial>
      <origin xyz="0 0 -0.07" rpy="0 0 0" />
      <mass value="0.18" />
      <inertia ixx="0.000795" ixy="0" ixz="0" iyy="0.001191" iyz="0" izz="0.001479" />
    </inertial>
    <visual>
      <origin xyz="-0.052 0 -0.01" rpy="0 0 0" />
      <geometry>
        <box size="0.024 0.052 0.008" />
      </geometry>
      <material name="carbon_gray">
        <color rgba="0.22 0.24 0.27 1" />
      </material>
    </visual>
    <visual>
      <origin xyz="-0.108 0 -0.112" rpy="1.5708 0 0" />
      <geometry>
        <cylinder radius="0.006" length="0.188" />
      </geometry>
      <material name="rubber_black">
        <color rgba="0.05 0.05 0.06 1" />
      </material>
    </visual>
    <visual>
      <origin xyz="-0.108 -0.072 -0.112" rpy="1.5708 0 0" />
      <geometry>
        <cylinder radius="0.008" length="0.024" />
      </geometry>
      <material name="satin_black">
        <color rgba="0.08 0.09 0.1 1" />
      </material>
    </visual>
    <visual>
      <origin xyz="-0.108 0.072 -0.112" rpy="1.5708 0 0" />
      <geometry>
        <cylinder radius="0.008" length="0.024" />
      </geometry>
      <material name="satin_black">
        <color rgba="0.08 0.09 0.1 1" />
      </material>
    </visual>
    <visual>
      <origin xyz="-0.08 -0.043 -0.057" rpy="0 2.53292 -2.59594" />
      <geometry>
        <cylinder radius="0.0048" length="0.114577" />
      </geometry>
      <material name="brushed_metal">
        <color rgba="0.69 0.71 0.74 1" />
      </material>
    </visual>
    <visual>
      <origin xyz="-0.08 0.043 -0.057" rpy="0 2.53292 2.59594" />
      <geometry>
        <cylinder radius="0.0048" length="0.114577" />
      </geometry>
      <material name="brushed_metal">
        <color rgba="0.69 0.71 0.74 1" />
      </material>
    </visual>
    <visual>
      <origin xyz="0.052 0 -0.01" rpy="0 0 0" />
      <geometry>
        <box size="0.024 0.052 0.008" />
      </geometry>
      <material name="carbon_gray">
        <color rgba="0.22 0.24 0.27 1" />
      </material>
    </visual>
    <visual>
      <origin xyz="0.108 0 -0.112" rpy="1.5708 0 0" />
      <geometry>
        <cylinder radius="0.006" length="0.188" />
      </geometry>
      <material name="rubber_black">
        <color rgba="0.05 0.05 0.06 1" />
      </material>
    </visual>
    <visual>
      <origin xyz="0.108 -0.072 -0.112" rpy="1.5708 0 0" />
      <geometry>
        <cylinder radius="0.008" length="0.024" />
      </geometry>
      <material name="satin_black">
        <color rgba="0.08 0.09 0.1 1" />
      </material>
    </visual>
    <visual>
      <origin xyz="0.108 0.072 -0.112" rpy="1.5708 0 0" />
      <geometry>
        <cylinder radius="0.008" length="0.024" />
      </geometry>
      <material name="satin_black">
        <color rgba="0.08 0.09 0.1 1" />
      </material>
    </visual>
    <visual>
      <origin xyz="0.08 -0.043 -0.057" rpy="0 2.53292 -0.545655" />
      <geometry>
        <cylinder radius="0.0048" length="0.114577" />
      </geometry>
      <material name="brushed_metal">
        <color rgba="0.69 0.71 0.74 1" />
      </material>
    </visual>
    <visual>
      <origin xyz="0.08 0.043 -0.057" rpy="0 2.53292 0.545655" />
      <geometry>
        <cylinder radius="0.0048" length="0.114577" />
      </geometry>
      <material name="brushed_metal">
        <color rgba="0.69 0.71 0.74 1" />
      </material>
    </visual>
    <visual>
      <origin xyz="0 0 -0.01" rpy="0 0 0" />
      <geometry>
        <box size="0.086 0.018 0.008" />
      </geometry>
      <material name="carbon_gray">
        <color rgba="0.22 0.24 0.27 1" />
      </material>
    </visual>
    <visual>
      <origin xyz="0 -0.06 -0.112" rpy="0 1.5708 0" />
      <geometry>
        <cylinder radius="0.005" length="0.216" />
      </geometry>
      <material name="satin_black">
        <color rgba="0.08 0.09 0.1 1" />
      </material>
    </visual>
    <visual>
      <origin xyz="0 0.06 -0.112" rpy="0 1.5708 0" />
      <geometry>
        <cylinder radius="0.005" length="0.216" />
      </geometry>
      <material name="satin_black">
        <color rgba="0.08 0.09 0.1 1" />
      </material>
    </visual>
    <collision name="landing_gear__visual_1">
      <origin xyz="-0.052 0 -0.01" rpy="0 0 0" />
      <geometry>
        <box size="0.024 0.052 0.008" />
      </geometry>
    </collision>
    <collision name="landing_gear__visual_2">
      <origin xyz="-0.108 0 -0.112" rpy="1.5708 0 0" />
      <geometry>
        <cylinder radius="0.006" length="0.188" />
      </geometry>
    </collision>
    <collision name="landing_gear__visual_3">
      <origin xyz="-0.108 -0.072 -0.112" rpy="1.5708 0 0" />
      <geometry>
        <cylinder radius="0.008" length="0.024" />
      </geometry>
    </collision>
    <collision name="landing_gear__visual_4">
      <origin xyz="-0.108 0.072 -0.112" rpy="1.5708 0 0" />
      <geometry>
        <cylinder radius="0.008" length="0.024" />
      </geometry>
    </collision>
    <collision name="landing_gear__visual_5">
      <origin xyz="-0.08 -0.043 -0.057" rpy="0 2.53292 -2.59594" />
      <geometry>
        <cylinder radius="0.0048" length="0.114577" />
      </geometry>
    </collision>
    <collision name="landing_gear__visual_6">
      <origin xyz="-0.08 0.043 -0.057" rpy="0 2.53292 2.59594" />
      <geometry>
        <cylinder radius="0.0048" length="0.114577" />
      </geometry>
    </collision>
    <collision name="landing_gear__visual_7">
      <origin xyz="0.052 0 -0.01" rpy="0 0 0" />
      <geometry>
        <box size="0.024 0.052 0.008" />
      </geometry>
    </collision>
    <collision name="landing_gear__visual_8">
      <origin xyz="0.108 0 -0.112" rpy="1.5708 0 0" />
      <geometry>
        <cylinder radius="0.006" length="0.188" />
      </geometry>
    </collision>
    <collision name="landing_gear__visual_9">
      <origin xyz="0.108 -0.072 -0.112" rpy="1.5708 0 0" />
      <geometry>
        <cylinder radius="0.008" length="0.024" />
      </geometry>
    </collision>
    <collision name="landing_gear__visual_10">
      <origin xyz="0.108 0.072 -0.112" rpy="1.5708 0 0" />
      <geometry>
        <cylinder radius="0.008" length="0.024" />
      </geometry>
    </collision>
    <collision name="landing_gear__visual_11">
      <origin xyz="0.08 -0.043 -0.057" rpy="0 2.53292 -0.545655" />
      <geometry>
        <cylinder radius="0.0048" length="0.114577" />
      </geometry>
    </collision>
    <collision name="landing_gear__visual_12">
      <origin xyz="0.08 0.043 -0.057" rpy="0 2.53292 0.545655" />
      <geometry>
        <cylinder radius="0.0048" length="0.114577" />
      </geometry>
    </collision>
    <collision name="landing_gear__visual_13">
      <origin xyz="0 0 -0.01" rpy="0 0 0" />
      <geometry>
        <box size="0.086 0.018 0.008" />
      </geometry>
    </collision>
    <collision name="landing_gear__visual_14">
      <origin xyz="0 -0.06 -0.112" rpy="0 1.5708 0" />
      <geometry>
        <cylinder radius="0.005" length="0.216" />
      </geometry>
    </collision>
    <collision name="landing_gear__visual_15">
      <origin xyz="0 0.06 -0.112" rpy="0 1.5708 0" />
      <geometry>
        <cylinder radius="0.005" length="0.216" />
      </geometry>
    </collision>
  </link>
  <link name="gimbal_yaw">
    <inertial>
      <origin xyz="0 0 -0.018" rpy="0 0 0" />
      <mass value="0.05" />
      <inertia ixx="1.04167e-05" ixy="0" ixz="0" iyy="2.16667e-05" iyz="0" izz="1.875e-05" />
    </inertial>
    <visual>
      <origin xyz="0 0 -0.005" rpy="0 0 0" />
      <geometry>
        <cylinder radius="0.014" length="0.004" />
      </geometry>
      <material name="brushed_metal">
        <color rgba="0.69 0.71 0.74 1" />
      </material>
    </visual>
    <visual>
      <origin xyz="0 0 -0.013" rpy="0 0 0" />
      <geometry>
        <box size="0.05 0.014 0.016" />
      </geometry>
      <material name="satin_black">
        <color rgba="0.08 0.09 0.1 1" />
      </material>
    </visual>
    <visual>
      <origin xyz="0 0 -0.034" rpy="0 0 0" />
      <geometry>
        <box size="0.054 0.008 0.004" />
      </geometry>
      <material name="satin_black">
        <color rgba="0.08 0.09 0.1 1" />
      </material>
    </visual>
    <visual>
      <origin xyz="-0.0225 0 -0.024" rpy="0 0 0" />
      <geometry>
        <box size="0.004 0.008 0.026" />
      </geometry>
      <material name="satin_black">
        <color rgba="0.08 0.09 0.1 1" />
      </material>
    </visual>
    <visual>
      <origin xyz="-0.0225 0 -0.02" rpy="0 1.5708 0" />
      <geometry>
        <cylinder radius="0.0045" length="0.008" />
      </geometry>
      <material name="brushed_metal">
        <color rgba="0.69 0.71 0.74 1" />
      </material>
    </visual>
    <visual>
      <origin xyz="0.0225 0 -0.024" rpy="0 0 0" />
      <geometry>
        <box size="0.004 0.008 0.026" />
      </geometry>
      <material name="satin_black">
        <color rgba="0.08 0.09 0.1 1" />
      </material>
    </visual>
    <visual>
      <origin xyz="0.0225 0 -0.02" rpy="0 1.5708 0" />
      <geometry>
        <cylinder radius="0.0045" length="0.008" />
      </geometry>
      <material name="brushed_metal">
        <color rgba="0.69 0.71 0.74 1" />
      </material>
    </visual>
    <collision name="gimbal_yaw__visual_1">
      <origin xyz="0 0 -0.005" rpy="0 0 0" />
      <geometry>
        <cylinder radius="0.014" length="0.004" />
      </geometry>
    </collision>
    <collision name="gimbal_yaw__visual_2">
      <origin xyz="0 0 -0.013" rpy="0 0 0" />
      <geometry>
        <box size="0.05 0.014 0.016" />
      </geometry>
    </collision>
    <collision name="gimbal_yaw__visual_3">
      <origin xyz="0 0 -0.034" rpy="0 0 0" />
      <geometry>
        <box size="0.054 0.008 0.004" />
      </geometry>
    </collision>
    <collision name="gimbal_yaw__visual_4">
      <origin xyz="-0.0225 0 -0.024" rpy="0 0 0" />
      <geometry>
        <box size="0.004 0.008 0.026" />
      </geometry>
    </collision>
    <collision name="gimbal_yaw__visual_5">
      <origin xyz="-0.0225 0 -0.02" rpy="0 1.5708 0" />
      <geometry>
        <cylinder radius="0.0045" length="0.008" />
      </geometry>
    </collision>
    <collision name="gimbal_yaw__visual_6">
      <origin xyz="0.0225 0 -0.024" rpy="0 0 0" />
      <geometry>
        <box size="0.004 0.008 0.026" />
      </geometry>
    </collision>
    <collision name="gimbal_yaw__visual_7">
      <origin xyz="0.0225 0 -0.02" rpy="0 1.5708 0" />
      <geometry>
        <cylinder radius="0.0045" length="0.008" />
      </geometry>
    </collision>
  </link>
  <link name="camera_pitch">
    <inertial>
      <origin xyz="0 0.024 -0.032" rpy="0 0 0" />
      <mass value="0.12" />
      <inertia ixx="5e-05" ixy="0" ixz="0" iyy="5e-05" iyz="0" izz="5e-05" />
    </inertial>
    <visual>
      <origin xyz="0 0 0" rpy="0 1.5708 0" />
      <geometry>
        <cylinder radius="0.0035" length="0.034" />
      </geometry>
      <material name="brushed_metal">
        <color rgba="0.69 0.71 0.74 1" />
      </material>
    </visual>
    <visual>
      <origin xyz="0 0.008 -0.005" rpy="0 0 0" />
      <geometry>
        <box size="0.016 0.012 0.006" />
      </geometry>
      <material name="satin_black">
        <color rgba="0.08 0.09 0.1 1" />
      </material>
    </visual>
    <visual>
      <origin xyz="0 0.014 -0.017" rpy="0 0 0" />
      <geometry>
        <box size="0.01 0.012 0.014" />
      </geometry>
      <material name="satin_black">
        <color rgba="0.08 0.09 0.1 1" />
      </material>
    </visual>
    <visual>
      <origin xyz="0 0.028 -0.038" rpy="0 0 0" />
      <geometry>
        <box size="0.03 0.026 0.022" />
      </geometry>
      <material name="carbon_gray">
        <color rgba="0.22 0.24 0.27 1" />
      </material>
    </visual>
    <visual>
      <origin xyz="0 0.017 -0.025" rpy="0 0 0" />
      <geometry>
        <box size="0.022 0.014 0.006" />
      </geometry>
      <material name="satin_black">
        <color rgba="0.08 0.09 0.1 1" />
      </material>
    </visual>
    <visual>
      <origin xyz="0 0.042 -0.038" rpy="1.5708 0 0" />
      <geometry>
        <cylinder radius="0.009" length="0.01" />
      </geometry>
      <material name="satin_black">
        <color rgba="0.08 0.09 0.1 1" />
      </material>
    </visual>
    <visual>
      <origin xyz="0 0.048 -0.038" rpy="0 0 0" />
      <geometry>
        <sphere radius="0.0075" />
      </geometry>
      <material name="glass_smoke">
        <color rgba="0.18 0.22 0.27 0.4" />
      </material>
    </visual>
    <collision name="camera_pitch__visual_1">
      <origin xyz="0 0 0" rpy="0 1.5708 0" />
      <geometry>
        <cylinder radius="0.0035" length="0.034" />
      </geometry>
    </collision>
    <collision name="camera_pitch__visual_2">
      <origin xyz="0 0.008 -0.005" rpy="0 0 0" />
      <geometry>
        <box size="0.016 0.012 0.006" />
      </geometry>
    </collision>
    <collision name="camera_pitch__visual_3">
      <origin xyz="0 0.014 -0.017" rpy="0 0 0" />
      <geometry>
        <box size="0.01 0.012 0.014" />
      </geometry>
    </collision>
    <collision name="camera_pitch__visual_4">
      <origin xyz="0 0.028 -0.038" rpy="0 0 0" />
      <geometry>
        <box size="0.03 0.026 0.022" />
      </geometry>
    </collision>
    <collision name="camera_pitch__visual_5">
      <origin xyz="0 0.017 -0.025" rpy="0 0 0" />
      <geometry>
        <box size="0.022 0.014 0.006" />
      </geometry>
    </collision>
    <collision name="camera_pitch__visual_6">
      <origin xyz="0 0.042 -0.038" rpy="1.5708 0 0" />
      <geometry>
        <cylinder radius="0.009" length="0.01" />
      </geometry>
    </collision>
    <collision name="camera_pitch__visual_7">
      <origin xyz="0 0.048 -0.038" rpy="0 0 0" />
      <geometry>
        <sphere radius="0.0075" />
      </geometry>
    </collision>
  </link>
  <link name="motor_front_left">
    <inertial>
      <origin xyz="0 0 0.013" rpy="0 0 0" />
      <mass value="0.05" />
      <inertia ixx="5.6e-06" ixy="0" ixz="0" iyy="5.6e-06" iyz="0" izz="6.4e-06" />
    </inertial>
    <visual>
      <origin xyz="0 0 0.004" rpy="0 0 0" />
      <geometry>
        <cylinder radius="0.016" length="0.004" />
      </geometry>
      <material name="brushed_metal">
        <color rgba="0.69 0.71 0.74 1" />
      </material>
    </visual>
    <visual>
      <origin xyz="0 0 0.014" rpy="0 0 0" />
      <geometry>
        <cylinder radius="0.014" length="0.018" />
      </geometry>
      <material name="satin_black">
        <color rgba="0.08 0.09 0.1 1" />
      </material>
    </visual>
    <visual>
      <origin xyz="0 0 0.01" rpy="0 0 0" />
      <geometry>
        <cylinder radius="0.015" length="0.003" />
      </geometry>
      <material name="status_red">
        <color rgba="0.73 0.18 0.16 1" />
      </material>
    </visual>
    <collision name="motor_front_left__visual_1">
      <origin xyz="0 0 0.004" rpy="0 0 0" />
      <geometry>
        <cylinder radius="0.016" length="0.004" />
      </geometry>
    </collision>
    <collision name="motor_front_left__visual_2">
      <origin xyz="0 0 0.014" rpy="0 0 0" />
      <geometry>
        <cylinder radius="0.014" length="0.018" />
      </geometry>
    </collision>
    <collision name="motor_front_left__visual_3">
      <origin xyz="0 0 0.01" rpy="0 0 0" />
      <geometry>
        <cylinder radius="0.015" length="0.003" />
      </geometry>
    </collision>
  </link>
  <link name="prop_front_left">
    <inertial>
      <origin xyz="0 0 0.005" rpy="0 0 0" />
      <mass value="0.012" />
      <inertia ixx="2.2288e-05" ixy="0" ixz="0" iyy="2.2288e-05" iyz="0" izz="4.4376e-05" />
    </inertial>
    <visual>
      <origin xyz="0 0 0.005" rpy="0 0 0" />
      <geometry>
        <cylinder radius="0.013" length="0.006" />
      </geometry>
      <material name="satin_black">
        <color rgba="0.08 0.09 0.1 1" />
      </material>
    </visual>
    <visual>
      <origin xyz="0 0 0.01" rpy="0 0 0" />
      <geometry>
        <cylinder radius="0.0055" length="0.004" />
      </geometry>
      <material name="brushed_metal">
        <color rgba="0.69 0.71 0.74 1" />
      </material>
    </visual>
    <visual>
      <origin xyz="0 0 0.004" rpy="0 0 0" />
      <geometry>
        <box size="0.168 0.016 0.003" />
      </geometry>
      <material name="satin_black">
        <color rgba="0.08 0.09 0.1 1" />
      </material>
    </visual>
    <visual>
      <origin xyz="0 0 0.0042" rpy="0 0 0" />
      <geometry>
        <box size="0.05 0.024 0.0035" />
      </geometry>
      <material name="satin_black">
        <color rgba="0.08 0.09 0.1 1" />
      </material>
    </visual>
    <visual>
      <origin xyz="-0.06 0.005 0.0045" rpy="0 0 0.16" />
      <geometry>
        <box size="0.046 0.01 0.0026" />
      </geometry>
      <material name="satin_black">
        <color rgba="0.08 0.09 0.1 1" />
      </material>
    </visual>
    <visual>
      <origin xyz="0.06 -0.005 0.0045" rpy="0 0 -0.16" />
      <geometry>
        <box size="0.046 0.01 0.0026" />
      </geometry>
      <material name="satin_black">
        <color rgba="0.08 0.09 0.1 1" />
      </material>
    </visual>
    <collision name="prop_front_left__visual_1">
      <origin xyz="0 0 0.005" rpy="0 0 0" />
      <geometry>
        <cylinder radius="0.013" length="0.006" />
      </geometry>
    </collision>
    <collision name="prop_front_left__visual_2">
      <origin xyz="0 0 0.01" rpy="0 0 0" />
      <geometry>
        <cylinder radius="0.0055" length="0.004" />
      </geometry>
    </collision>
    <collision name="prop_front_left__visual_3">
      <origin xyz="0 0 0.004" rpy="0 0 0" />
      <geometry>
        <box size="0.168 0.016 0.003" />
      </geometry>
    </collision>
    <collision name="prop_front_left__visual_4">
      <origin xyz="0 0 0.0042" rpy="0 0 0" />
      <geometry>
        <box size="0.05 0.024 0.0035" />
      </geometry>
    </collision>
    <collision name="prop_front_left__visual_5">
      <origin xyz="-0.06 0.005 0.0045" rpy="0 0 0.16" />
      <geometry>
        <box size="0.046 0.01 0.0026" />
      </geometry>
    </collision>
    <collision name="prop_front_left__visual_6">
      <origin xyz="0.06 -0.005 0.0045" rpy="0 0 -0.16" />
      <geometry>
        <box size="0.046 0.01 0.0026" />
      </geometry>
    </collision>
  </link>
  <link name="motor_front_right">
    <inertial>
      <origin xyz="0 0 0.013" rpy="0 0 0" />
      <mass value="0.05" />
      <inertia ixx="5.6e-06" ixy="0" ixz="0" iyy="5.6e-06" iyz="0" izz="6.4e-06" />
    </inertial>
    <visual>
      <origin xyz="0 0 0.004" rpy="0 0 0" />
      <geometry>
        <cylinder radius="0.016" length="0.004" />
      </geometry>
      <material name="brushed_metal">
        <color rgba="0.69 0.71 0.74 1" />
      </material>
    </visual>
    <visual>
      <origin xyz="0 0 0.014" rpy="0 0 0" />
      <geometry>
        <cylinder radius="0.014" length="0.018" />
      </geometry>
      <material name="satin_black">
        <color rgba="0.08 0.09 0.1 1" />
      </material>
    </visual>
    <visual>
      <origin xyz="0 0 0.01" rpy="0 0 0" />
      <geometry>
        <cylinder radius="0.015" length="0.003" />
      </geometry>
      <material name="status_green">
        <color rgba="0.24 0.6 0.31 1" />
      </material>
    </visual>
    <collision name="motor_front_right__visual_1">
      <origin xyz="0 0 0.004" rpy="0 0 0" />
      <geometry>
        <cylinder radius="0.016" length="0.004" />
      </geometry>
    </collision>
    <collision name="motor_front_right__visual_2">
      <origin xyz="0 0 0.014" rpy="0 0 0" />
      <geometry>
        <cylinder radius="0.014" length="0.018" />
      </geometry>
    </collision>
    <collision name="motor_front_right__visual_3">
      <origin xyz="0 0 0.01" rpy="0 0 0" />
      <geometry>
        <cylinder radius="0.015" length="0.003" />
      </geometry>
    </collision>
  </link>
  <link name="prop_front_right">
    <inertial>
      <origin xyz="0 0 0.005" rpy="0 0 0" />
      <mass value="0.012" />
      <inertia ixx="2.2288e-05" ixy="0" ixz="0" iyy="2.2288e-05" iyz="0" izz="4.4376e-05" />
    </inertial>
    <visual>
      <origin xyz="0 0 0.005" rpy="0 0 0" />
      <geometry>
        <cylinder radius="0.013" length="0.006" />
      </geometry>
      <material name="satin_black">
        <color rgba="0.08 0.09 0.1 1" />
      </material>
    </visual>
    <visual>
      <origin xyz="0 0 0.01" rpy="0 0 0" />
      <geometry>
        <cylinder radius="0.0055" length="0.004" />
      </geometry>
      <material name="brushed_metal">
        <color rgba="0.69 0.71 0.74 1" />
      </material>
    </visual>
    <visual>
      <origin xyz="0 0 0.004" rpy="0 0 0" />
      <geometry>
        <box size="0.168 0.016 0.003" />
      </geometry>
      <material name="satin_black">
        <color rgba="0.08 0.09 0.1 1" />
      </material>
    </visual>
    <visual>
      <origin xyz="0 0 0.0042" rpy="0 0 0" />
      <geometry>
        <box size="0.05 0.024 0.0035" />
      </geometry>
      <material name="satin_black">
        <color rgba="0.08 0.09 0.1 1" />
      </material>
    </visual>
    <visual>
      <origin xyz="-0.06 0.005 0.0045" rpy="0 0 0.16" />
      <geometry>
        <box size="0.046 0.01 0.0026" />
      </geometry>
      <material name="satin_black">
        <color rgba="0.08 0.09 0.1 1" />
      </material>
    </visual>
    <visual>
      <origin xyz="0.06 -0.005 0.0045" rpy="0 0 -0.16" />
      <geometry>
        <box size="0.046 0.01 0.0026" />
      </geometry>
      <material name="satin_black">
        <color rgba="0.08 0.09 0.1 1" />
      </material>
    </visual>
    <collision name="prop_front_right__visual_1">
      <origin xyz="0 0 0.005" rpy="0 0 0" />
      <geometry>
        <cylinder radius="0.013" length="0.006" />
      </geometry>
    </collision>
    <collision name="prop_front_right__visual_2">
      <origin xyz="0 0 0.01" rpy="0 0 0" />
      <geometry>
        <cylinder radius="0.0055" length="0.004" />
      </geometry>
    </collision>
    <collision name="prop_front_right__visual_3">
      <origin xyz="0 0 0.004" rpy="0 0 0" />
      <geometry>
        <box size="0.168 0.016 0.003" />
      </geometry>
    </collision>
    <collision name="prop_front_right__visual_4">
      <origin xyz="0 0 0.0042" rpy="0 0 0" />
      <geometry>
        <box size="0.05 0.024 0.0035" />
      </geometry>
    </collision>
    <collision name="prop_front_right__visual_5">
      <origin xyz="-0.06 0.005 0.0045" rpy="0 0 0.16" />
      <geometry>
        <box size="0.046 0.01 0.0026" />
      </geometry>
    </collision>
    <collision name="prop_front_right__visual_6">
      <origin xyz="0.06 -0.005 0.0045" rpy="0 0 -0.16" />
      <geometry>
        <box size="0.046 0.01 0.0026" />
      </geometry>
    </collision>
  </link>
  <link name="motor_rear_left">
    <inertial>
      <origin xyz="0 0 0.013" rpy="0 0 0" />
      <mass value="0.05" />
      <inertia ixx="5.6e-06" ixy="0" ixz="0" iyy="5.6e-06" iyz="0" izz="6.4e-06" />
    </inertial>
    <visual>
      <origin xyz="0 0 0.004" rpy="0 0 0" />
      <geometry>
        <cylinder radius="0.016" length="0.004" />
      </geometry>
      <material name="brushed_metal">
        <color rgba="0.69 0.71 0.74 1" />
      </material>
    </visual>
    <visual>
      <origin xyz="0 0 0.014" rpy="0 0 0" />
      <geometry>
        <cylinder radius="0.014" length="0.018" />
      </geometry>
      <material name="satin_black">
        <color rgba="0.08 0.09 0.1 1" />
      </material>
    </visual>
    <visual>
      <origin xyz="0 0 0.01" rpy="0 0 0" />
      <geometry>
        <cylinder radius="0.015" length="0.003" />
      </geometry>
      <material name="brushed_metal">
        <color rgba="0.69 0.71 0.74 1" />
      </material>
    </visual>
    <collision name="motor_rear_left__visual_1">
      <origin xyz="0 0 0.004" rpy="0 0 0" />
      <geometry>
        <cylinder radius="0.016" length="0.004" />
      </geometry>
    </collision>
    <collision name="motor_rear_left__visual_2">
      <origin xyz="0 0 0.014" rpy="0 0 0" />
      <geometry>
        <cylinder radius="0.014" length="0.018" />
      </geometry>
    </collision>
    <collision name="motor_rear_left__visual_3">
      <origin xyz="0 0 0.01" rpy="0 0 0" />
      <geometry>
        <cylinder radius="0.015" length="0.003" />
      </geometry>
    </collision>
  </link>
  <link name="prop_rear_left">
    <inertial>
      <origin xyz="0 0 0.005" rpy="0 0 0" />
      <mass value="0.012" />
      <inertia ixx="2.2288e-05" ixy="0" ixz="0" iyy="2.2288e-05" iyz="0" izz="4.4376e-05" />
    </inertial>
    <visual>
      <origin xyz="0 0 0.005" rpy="0 0 0" />
      <geometry>
        <cylinder radius="0.013" length="0.006" />
      </geometry>
      <material name="satin_black">
        <color rgba="0.08 0.09 0.1 1" />
      </material>
    </visual>
    <visual>
      <origin xyz="0 0 0.01" rpy="0 0 0" />
      <geometry>
        <cylinder radius="0.0055" length="0.004" />
      </geometry>
      <material name="brushed_metal">
        <color rgba="0.69 0.71 0.74 1" />
      </material>
    </visual>
    <visual>
      <origin xyz="0 0 0.004" rpy="0 0 0" />
      <geometry>
        <box size="0.168 0.016 0.003" />
      </geometry>
      <material name="satin_black">
        <color rgba="0.08 0.09 0.1 1" />
      </material>
    </visual>
    <visual>
      <origin xyz="0 0 0.0042" rpy="0 0 0" />
      <geometry>
        <box size="0.05 0.024 0.0035" />
      </geometry>
      <material name="satin_black">
        <color rgba="0.08 0.09 0.1 1" />
      </material>
    </visual>
    <visual>
      <origin xyz="-0.06 0.005 0.0045" rpy="0 0 0.16" />
      <geometry>
        <box size="0.046 0.01 0.0026" />
      </geometry>
      <material name="satin_black">
        <color rgba="0.08 0.09 0.1 1" />
      </material>
    </visual>
    <visual>
      <origin xyz="0.06 -0.005 0.0045" rpy="0 0 -0.16" />
      <geometry>
        <box size="0.046 0.01 0.0026" />
      </geometry>
      <material name="satin_black">
        <color rgba="0.08 0.09 0.1 1" />
      </material>
    </visual>
    <collision name="prop_rear_left__visual_1">
      <origin xyz="0 0 0.005" rpy="0 0 0" />
      <geometry>
        <cylinder radius="0.013" length="0.006" />
      </geometry>
    </collision>
    <collision name="prop_rear_left__visual_2">
      <origin xyz="0 0 0.01" rpy="0 0 0" />
      <geometry>
        <cylinder radius="0.0055" length="0.004" />
      </geometry>
    </collision>
    <collision name="prop_rear_left__visual_3">
      <origin xyz="0 0 0.004" rpy="0 0 0" />
      <geometry>
        <box size="0.168 0.016 0.003" />
      </geometry>
    </collision>
    <collision name="prop_rear_left__visual_4">
      <origin xyz="0 0 0.0042" rpy="0 0 0" />
      <geometry>
        <box size="0.05 0.024 0.0035" />
      </geometry>
    </collision>
    <collision name="prop_rear_left__visual_5">
      <origin xyz="-0.06 0.005 0.0045" rpy="0 0 0.16" />
      <geometry>
        <box size="0.046 0.01 0.0026" />
      </geometry>
    </collision>
    <collision name="prop_rear_left__visual_6">
      <origin xyz="0.06 -0.005 0.0045" rpy="0 0 -0.16" />
      <geometry>
        <box size="0.046 0.01 0.0026" />
      </geometry>
    </collision>
  </link>
  <link name="motor_rear_right">
    <inertial>
      <origin xyz="0 0 0.013" rpy="0 0 0" />
      <mass value="0.05" />
      <inertia ixx="5.6e-06" ixy="0" ixz="0" iyy="5.6e-06" iyz="0" izz="6.4e-06" />
    </inertial>
    <visual>
      <origin xyz="0 0 0.004" rpy="0 0 0" />
      <geometry>
        <cylinder radius="0.016" length="0.004" />
      </geometry>
      <material name="brushed_metal">
        <color rgba="0.69 0.71 0.74 1" />
      </material>
    </visual>
    <visual>
      <origin xyz="0 0 0.014" rpy="0 0 0" />
      <geometry>
        <cylinder radius="0.014" length="0.018" />
      </geometry>
      <material name="satin_black">
        <color rgba="0.08 0.09 0.1 1" />
      </material>
    </visual>
    <visual>
      <origin xyz="0 0 0.01" rpy="0 0 0" />
      <geometry>
        <cylinder radius="0.015" length="0.003" />
      </geometry>
      <material name="brushed_metal">
        <color rgba="0.69 0.71 0.74 1" />
      </material>
    </visual>
    <collision name="motor_rear_right__visual_1">
      <origin xyz="0 0 0.004" rpy="0 0 0" />
      <geometry>
        <cylinder radius="0.016" length="0.004" />
      </geometry>
    </collision>
    <collision name="motor_rear_right__visual_2">
      <origin xyz="0 0 0.014" rpy="0 0 0" />
      <geometry>
        <cylinder radius="0.014" length="0.018" />
      </geometry>
    </collision>
    <collision name="motor_rear_right__visual_3">
      <origin xyz="0 0 0.01" rpy="0 0 0" />
      <geometry>
        <cylinder radius="0.015" length="0.003" />
      </geometry>
    </collision>
  </link>
  <link name="prop_rear_right">
    <inertial>
      <origin xyz="0 0 0.005" rpy="0 0 0" />
      <mass value="0.012" />
      <inertia ixx="2.2288e-05" ixy="0" ixz="0" iyy="2.2288e-05" iyz="0" izz="4.4376e-05" />
    </inertial>
    <visual>
      <origin xyz="0 0 0.005" rpy="0 0 0" />
      <geometry>
        <cylinder radius="0.013" length="0.006" />
      </geometry>
      <material name="satin_black">
        <color rgba="0.08 0.09 0.1 1" />
      </material>
    </visual>
    <visual>
      <origin xyz="0 0 0.01" rpy="0 0 0" />
      <geometry>
        <cylinder radius="0.0055" length="0.004" />
      </geometry>
      <material name="brushed_metal">
        <color rgba="0.69 0.71 0.74 1" />
      </material>
    </visual>
    <visual>
      <origin xyz="0 0 0.004" rpy="0 0 0" />
      <geometry>
        <box size="0.168 0.016 0.003" />
      </geometry>
      <material name="satin_black">
        <color rgba="0.08 0.09 0.1 1" />
      </material>
    </visual>
    <visual>
      <origin xyz="0 0 0.0042" rpy="0 0 0" />
      <geometry>
        <box size="0.05 0.024 0.0035" />
      </geometry>
      <material name="satin_black">
        <color rgba="0.08 0.09 0.1 1" />
      </material>
    </visual>
    <visual>
      <origin xyz="-0.06 0.005 0.0045" rpy="0 0 0.16" />
      <geometry>
        <box size="0.046 0.01 0.0026" />
      </geometry>
      <material name="satin_black">
        <color rgba="0.08 0.09 0.1 1" />
      </material>
    </visual>
    <visual>
      <origin xyz="0.06 -0.005 0.0045" rpy="0 0 -0.16" />
      <geometry>
        <box size="0.046 0.01 0.0026" />
      </geometry>
      <material name="satin_black">
        <color rgba="0.08 0.09 0.1 1" />
      </material>
    </visual>
    <collision name="prop_rear_right__visual_1">
      <origin xyz="0 0 0.005" rpy="0 0 0" />
      <geometry>
        <cylinder radius="0.013" length="0.006" />
      </geometry>
    </collision>
    <collision name="prop_rear_right__visual_2">
      <origin xyz="0 0 0.01" rpy="0 0 0" />
      <geometry>
        <cylinder radius="0.0055" length="0.004" />
      </geometry>
    </collision>
    <collision name="prop_rear_right__visual_3">
      <origin xyz="0 0 0.004" rpy="0 0 0" />
      <geometry>
        <box size="0.168 0.016 0.003" />
      </geometry>
    </collision>
    <collision name="prop_rear_right__visual_4">
      <origin xyz="0 0 0.0042" rpy="0 0 0" />
      <geometry>
        <box size="0.05 0.024 0.0035" />
      </geometry>
    </collision>
    <collision name="prop_rear_right__visual_5">
      <origin xyz="-0.06 0.005 0.0045" rpy="0 0 0.16" />
      <geometry>
        <box size="0.046 0.01 0.0026" />
      </geometry>
    </collision>
    <collision name="prop_rear_right__visual_6">
      <origin xyz="0.06 -0.005 0.0045" rpy="0 0 -0.16" />
      <geometry>
        <box size="0.046 0.01 0.0026" />
      </geometry>
    </collision>
  </link>
  <joint name="body_to_landing_gear" type="fixed">
    <origin xyz="0 0 -0.0225" rpy="0 0 0" />
    <parent link="body" />
    <child link="landing_gear" />
  </joint>
  <joint name="gimbal_yaw" type="revolute">
    <origin xyz="0 0.048 -0.025" rpy="0 0 0" />
    <parent link="body" />
    <child link="gimbal_yaw" />
    <axis xyz="0 0 1" />
    <limit effort="1.5" velocity="3.5" lower="-0.9" upper="0.9" />
  </joint>
  <joint name="gimbal_pitch" type="revolute">
    <origin xyz="0 0 -0.022" rpy="0 0 0" />
    <parent link="gimbal_yaw" />
    <child link="camera_pitch" />
    <axis xyz="1 0 0" />
    <limit effort="1.5" velocity="3.5" lower="-0.35" upper="0.65" />
  </joint>
  <joint name="body_to_motor_front_left" type="fixed">
    <origin xyz="-0.165 0.14 0.02" rpy="0 0 0" />
    <parent link="body" />
    <child link="motor_front_left" />
  </joint>
  <joint name="spin_front_left" type="continuous">
    <origin xyz="0 0 0.026" rpy="0 0 0" />
    <parent link="motor_front_left" />
    <child link="prop_front_left" />
    <axis xyz="0 0 1" />
    <limit effort="0.4" velocity="120" />
  </joint>
  <joint name="body_to_motor_front_right" type="fixed">
    <origin xyz="0.165 0.14 0.02" rpy="0 0 0" />
    <parent link="body" />
    <child link="motor_front_right" />
  </joint>
  <joint name="spin_front_right" type="continuous">
    <origin xyz="0 0 0.026" rpy="0 0 0" />
    <parent link="motor_front_right" />
    <child link="prop_front_right" />
    <axis xyz="0 0 1" />
    <limit effort="0.4" velocity="120" />
  </joint>
  <joint name="body_to_motor_rear_left" type="fixed">
    <origin xyz="-0.155 -0.14 0.02" rpy="0 0 0" />
    <parent link="body" />
    <child link="motor_rear_left" />
  </joint>
  <joint name="spin_rear_left" type="continuous">
    <origin xyz="0 0 0.026" rpy="0 0 0" />
    <parent link="motor_rear_left" />
    <child link="prop_rear_left" />
    <axis xyz="0 0 1" />
    <limit effort="0.4" velocity="120" />
  </joint>
  <joint name="body_to_motor_rear_right" type="fixed">
    <origin xyz="0.155 -0.14 0.02" rpy="0 0 0" />
    <parent link="body" />
    <child link="motor_rear_right" />
  </joint>
  <joint name="spin_rear_right" type="continuous">
    <origin xyz="0 0 0.026" rpy="0 0 0" />
    <parent link="motor_rear_right" />
    <child link="prop_rear_right" />
    <axis xyz="0 0 1" />
    <limit effort="0.4" velocity="120" />
  </joint>
</robot>