<robot name="survey_telescoping_mast">
  <material name="housing_dark">
    <color rgba="0.21 0.23 0.26 1" />
    </material>
  <material name="housing_light">
    <color rgba="0.34 0.36 0.4 1" />
    </material>
  <material name="mast_graphite">
    <color rgba="0.11 0.12 0.14 1" />
    </material>
  <material name="machined_aluminum">
    <color rgba="0.75 0.77 0.8 1" />
    </material>
  <material name="rubber">
    <color rgba="0.07 0.07 0.08 1" />
    </material>
  <material name="optic_glass">
    <color rgba="0.18 0.4 0.55 0.75" />
    </material>
  <material name="accent_orange">
    <color rgba="0.9 0.48 0.18 1" />
    </material>
  <link name="base">
    <inertial>
      <origin xyz="0 0 0.175" rpy="0 0 0" />
      <mass value="18" />
      <inertia ixx="0.33735" ixy="0" ixz="0" iyy="0.47415" iyz="0" izz="0.444" />
      </inertial>
    <visual>
      <origin xyz="0 0 0.045" rpy="0 0 0" />
      <geometry>
        <box size="0.44 0.32 0.09" />
        </geometry>
      <material name="housing_dark" />
      </visual>
    <visual>
      <origin xyz="0 0 0.115" rpy="0 0 0" />
      <geometry>
        <box size="0.3 0.22 0.05" />
        </geometry>
      <material name="housing_light" />
      </visual>
    <visual>
      <origin xyz="-0.14 0 0.1025" rpy="0 0 0" />
      <geometry>
        <box size="0.08 0.18 0.025" />
        </geometry>
      <material name="housing_dark" />
      </visual>
    <visual>
      <origin xyz="0.228 0 0.075" rpy="0 0 0" />
      <geometry>
        <box size="0.016 0.18 0.06" />
        </geometry>
      <material name="machined_aluminum" />
      </visual>
    <visual>
      <origin xyz="0.237 0 0.108" rpy="0 0 0" />
      <geometry>
        <box size="0.01 0.08 0.012" />
        </geometry>
      <material name="accent_orange" />
      </visual>
    <visual>
      <origin xyz="0 0.167 0.085" rpy="1.5708 0 0" />
      <geometry>
        <cylinder radius="0.012" length="0.11" />
        </geometry>
      <material name="machined_aluminum" />
      </visual>
    <visual>
      <origin xyz="0 -0.167 0.085" rpy="1.5708 0 0" />
      <geometry>
        <cylinder radius="0.012" length="0.11" />
        </geometry>
      <material name="machined_aluminum" />
      </visual>
    <visual>
      <origin xyz="-0.16 -0.11 0.006" rpy="0 0 0" />
      <geometry>
        <cylinder radius="0.024" length="0.012" />
        </geometry>
      <material name="rubber" />
      </visual>
    <visual>
      <origin xyz="-0.16 0.11 0.006" rpy="0 0 0" />
      <geometry>
        <cylinder radius="0.024" length="0.012" />
        </geometry>
      <material name="rubber" />
      </visual>
    <visual>
      <origin xyz="0.16 -0.11 0.006" rpy="0 0 0" />
      <geometry>
        <cylinder radius="0.024" length="0.012" />
        </geometry>
      <material name="rubber" />
      </visual>
    <visual>
      <origin xyz="0.16 0.11 0.006" rpy="0 0 0" />
      <geometry>
        <cylinder radius="0.024" length="0.012" />
        </geometry>
      <material name="rubber" />
      </visual>
    <visual>
      <origin xyz="0.0535 0 0.145" rpy="0 0 0" />
      <geometry>
        <box size="0.011 0.118 0.016" />
        </geometry>
      <material name="machined_aluminum" />
      </visual>
    <visual>
      <origin xyz="-0.0535 0 0.145" rpy="0 0 0" />
      <geometry>
        <box size="0.011 0.118 0.016" />
        </geometry>
      <material name="machined_aluminum" />
      </visual>
    <visual>
      <origin xyz="0 0.0535 0.145" rpy="0 0 0" />
      <geometry>
        <box size="0.118 0.011 0.016" />
        </geometry>
      <material name="machined_aluminum" />
      </visual>
    <visual>
      <origin xyz="0 -0.0535 0.145" rpy="0 0 0" />
      <geometry>
        <box size="0.118 0.011 0.016" />
        </geometry>
      <material name="machined_aluminum" />
      </visual>
    <visual>
      <origin xyz="0.052 0 0.241" rpy="0 0 0" />
      <geometry>
        <box size="0.008 0.112 0.184" />
        </geometry>
      <material name="mast_graphite" />
      </visual>
    <visual>
      <origin xyz="-0.052 0 0.241" rpy="0 0 0" />
      <geometry>
        <box size="0.008 0.112 0.184" />
        </geometry>
      <material name="mast_graphite" />
      </visual>
    <visual>
      <origin xyz="0 0.052 0.241" rpy="0 0 0" />
      <geometry>
        <box size="0.112 0.008 0.184" />
        </geometry>
      <material name="mast_graphite" />
      </visual>
    <visual>
      <origin xyz="0 -0.052 0.241" rpy="0 0 0" />
      <geometry>
        <box size="0.112 0.008 0.184" />
        </geometry>
      <material name="mast_graphite" />
      </visual>
    <visual>
      <origin xyz="0.054 0 0.34" rpy="0 0 0" />
      <geometry>
        <box size="0.014 0.122 0.018" />
        </geometry>
      <material name="machined_aluminum" />
      </visual>
    <visual>
      <origin xyz="-0.054 0 0.34" rpy="0 0 0" />
      <geometry>
        <box size="0.014 0.122 0.018" />
        </geometry>
      <material name="machined_aluminum" />
      </visual>
    <visual>
      <origin xyz="0 0.054 0.34" rpy="0 0 0" />
      <geometry>
        <box size="0.122 0.014 0.018" />
        </geometry>
      <material name="machined_aluminum" />
      </visual>
    <visual>
      <origin xyz="0 -0.054 0.34" rpy="0 0 0" />
      <geometry>
        <box size="0.122 0.014 0.018" />
        </geometry>
      <material name="machined_aluminum" />
      </visual>
    <collision name="base__visual_1">
      <origin xyz="0 0 0.045" rpy="0 0 0" />
      <geometry>
        <box size="0.44 0.32 0.09" />
        </geometry>
      </collision>
    <collision name="base__visual_2">
      <origin xyz="0 0 0.115" rpy="0 0 0" />
      <geometry>
        <box size="0.3 0.22 0.05" />
        </geometry>
      </collision>
    <collision name="base__visual_3">
      <origin xyz="-0.14 0 0.1025" rpy="0 0 0" />
      <geometry>
        <box size="0.08 0.18 0.025" />
        </geometry>
      </collision>
    <collision name="base__visual_4">
      <origin xyz="0.228 0 0.075" rpy="0 0 0" />
      <geometry>
        <box size="0.016 0.18 0.06" />
        </geometry>
      </collision>
    <collision name="base__visual_5">
      <origin xyz="0.237 0 0.108" rpy="0 0 0" />
      <geometry>
        <box size="0.01 0.08 0.012" />
        </geometry>
      </collision>
    <collision name="base__visual_6">
      <origin xyz="0 0.167 0.085" rpy="1.5708 0 0" />
      <geometry>
        <cylinder radius="0.012" length="0.11" />
        </geometry>
      </collision>
    <collision name="base__visual_7">
      <origin xyz="0 -0.167 0.085" rpy="1.5708 0 0" />
      <geometry>
        <cylinder radius="0.012" length="0.11" />
        </geometry>
      </collision>
    <collision name="base__visual_8">
      <origin xyz="-0.16 -0.11 0.006" rpy="0 0 0" />
      <geometry>
        <cylinder radius="0.024" length="0.012" />
        </geometry>
      </collision>
    <collision name="base__visual_9">
      <origin xyz="-0.16 0.11 0.006" rpy="0 0 0" />
      <geometry>
        <cylinder radius="0.024" length="0.012" />
        </geometry>
      </collision>
    <collision name="base__visual_10">
      <origin xyz="0.16 -0.11 0.006" rpy="0 0 0" />
      <geometry>
        <cylinder radius="0.024" length="0.012" />
        </geometry>
      </collision>
    <collision name="base__visual_11">
      <origin xyz="0.16 0.11 0.006" rpy="0 0 0" />
      <geometry>
        <cylinder radius="0.024" length="0.012" />
        </geometry>
      </collision>
    <collision name="base__visual_12">
      <origin xyz="0.0535 0 0.145" rpy="0 0 0" />
      <geometry>
        <box size="0.011 0.118 0.016" />
        </geometry>
      </collision>
    <collision name="base__visual_13">
      <origin xyz="-0.0535 0 0.145" rpy="0 0 0" />
      <geometry>
        <box size="0.011 0.118 0.016" />
        </geometry>
      </collision>
    <collision name="base__visual_14">
      <origin xyz="0 0.0535 0.145" rpy="0 0 0" />
      <geometry>
        <box size="0.118 0.011 0.016" />
        </geometry>
      </collision>
    <collision name="base__visual_15">
      <origin xyz="0 -0.0535 0.145" rpy="0 0 0" />
      <geometry>
        <box size="0.118 0.011 0.016" />
        </geometry>
      </collision>
    <collision name="base__visual_16">
      <origin xyz="0.052 0 0.241" rpy="0 0 0" />
      <geometry>
        <box size="0.008 0.112 0.184" />
        </geometry>
      </collision>
    <collision name="base__visual_17">
      <origin xyz="-0.052 0 0.241" rpy="0 0 0" />
      <geometry>
        <box size="0.008 0.112 0.184" />
        </geometry>
      </collision>
    <collision name="base__visual_18">
      <origin xyz="0 0.052 0.241" rpy="0 0 0" />
      <geometry>
        <box size="0.112 0.008 0.184" />
        </geometry>
      </collision>
    <collision name="base__visual_19">
      <origin xyz="0 -0.052 0.241" rpy="0 0 0" />
      <geometry>
        <box size="0.112 0.008 0.184" />
        </geometry>
      </collision>
    <collision name="base__visual_20">
      <origin xyz="0.054 0 0.34" rpy="0 0 0" />
      <geometry>
        <box size="0.014 0.122 0.018" />
        </geometry>
      </collision>
    <collision name="base__visual_21">
      <origin xyz="-0.054 0 0.34" rpy="0 0 0" />
      <geometry>
        <box size="0.014 0.122 0.018" />
        </geometry>
      </collision>
    <collision name="base__visual_22">
      <origin xyz="0 0.054 0.34" rpy="0 0 0" />
      <geometry>
        <box size="0.122 0.014 0.018" />
        </geometry>
      </collision>
    <collision name="base__visual_23">
      <origin xyz="0 -0.054 0.34" rpy="0 0 0" />
      <geometry>
        <box size="0.122 0.014 0.018" />
        </geometry>
      </collision>
    </link>
  <link name="mast_stage">
    <inertial>
      <origin xyz="0 0 0.26" rpy="0 0 0" />
      <mass value="3.2" />
      <inertia ixx="0.0747733" ixy="0" ixz="0" iyy="0.0747733" iyz="0" izz="0.00533333" />
      </inertial>
    <visual>
      <origin xyz="0 0 0.01" rpy="0 0 0" />
      <geometry>
        <box size="0.082 0.082 0.02" />
        </geometry>
      <material name="machined_aluminum" />
      </visual>
    <visual>
      <origin xyz="0.0405 0 0.191" rpy="0 0 0" />
      <geometry>
        <box size="0.007 0.088 0.366" />
        </geometry>
      <material name="mast_graphite" />
      </visual>
    <visual>
      <origin xyz="-0.0405 0 0.191" rpy="0 0 0" />
      <geometry>
        <box size="0.007 0.088 0.366" />
        </geometry>
      <material name="mast_graphite" />
      </visual>
    <visual>
      <origin xyz="0 0.0405 0.191" rpy="0 0 0" />
      <geometry>
        <box size="0.088 0.007 0.366" />
        </geometry>
      <material name="mast_graphite" />
      </visual>
    <visual>
      <origin xyz="0 -0.0405 0.191" rpy="0 0 0" />
      <geometry>
        <box size="0.088 0.007 0.366" />
        </geometry>
      <material name="mast_graphite" />
      </visual>
    <visual>
      <origin xyz="0 0 0.378" rpy="0 0 0" />
      <geometry>
        <box size="0.084 0.084 0.02" />
        </geometry>
      <material name="machined_aluminum" />
      </visual>
    <visual>
      <origin xyz="0.0365 0 0.42" rpy="0 0 0" />
      <geometry>
        <box size="0.005 0.078 0.136" />
        </geometry>
      <material name="machined_aluminum" />
      </visual>
    <visual>
      <origin xyz="-0.0365 0 0.42" rpy="0 0 0" />
      <geometry>
        <box size="0.005 0.078 0.136" />
        </geometry>
      <material name="machined_aluminum" />
      </visual>
    <visual>
      <origin xyz="0 0.0365 0.42" rpy="0 0 0" />
      <geometry>
        <box size="0.078 0.005 0.136" />
        </geometry>
      <material name="machined_aluminum" />
      </visual>
    <visual>
      <origin xyz="0 -0.0365 0.42" rpy="0 0 0" />
      <geometry>
        <box size="0.078 0.005 0.136" />
        </geometry>
      <material name="machined_aluminum" />
      </visual>
    <visual>
      <origin xyz="0 0 0.495" rpy="0 0 0" />
      <geometry>
        <cylinder radius="0.029" length="0.032" />
        </geometry>
      <material name="machined_aluminum" />
      </visual>
    <visual>
      <origin xyz="0 0 0.506" rpy="0 0 0" />
      <geometry>
        <cylinder radius="0.034" length="0.018" />
        </geometry>
      <material name="accent_orange" />
      </visual>
    <visual>
      <origin xyz="0 0 0.519" rpy="0 0 0" />
      <geometry>
        <cylinder radius="0.038" length="0.014" />
        </geometry>
      <material name="machined_aluminum" />
      </visual>
    <collision name="mast_stage__visual_1">
      <origin xyz="0 0 0.01" rpy="0 0 0" />
      <geometry>
        <box size="0.082 0.082 0.02" />
        </geometry>
      </collision>
    <collision name="mast_stage__visual_2">
      <origin xyz="0.0405 0 0.191" rpy="0 0 0" />
      <geometry>
        <box size="0.007 0.088 0.366" />
        </geometry>
      </collision>
    <collision name="mast_stage__visual_3">
      <origin xyz="-0.0405 0 0.191" rpy="0 0 0" />
      <geometry>
        <box size="0.007 0.088 0.366" />
        </geometry>
      </collision>
    <collision name="mast_stage__visual_4">
      <origin xyz="0 0.0405 0.191" rpy="0 0 0" />
      <geometry>
        <box size="0.088 0.007 0.366" />
        </geometry>
      </collision>
    <collision name="mast_stage__visual_5">
      <origin xyz="0 -0.0405 0.191" rpy="0 0 0" />
      <geometry>
        <box size="0.088 0.007 0.366" />
        </geometry>
      </collision>
    <collision name="mast_stage__visual_6">
      <origin xyz="0 0 0.378" rpy="0 0 0" />
      <geometry>
        <box size="0.084 0.084 0.02" />
        </geometry>
      </collision>
    <collision name="mast_stage__visual_7">
      <origin xyz="0.0365 0 0.42" rpy="0 0 0" />
      <geometry>
        <box size="0.005 0.078 0.136" />
        </geometry>
      </collision>
    <collision name="mast_stage__visual_8">
      <origin xyz="-0.0365 0 0.42" rpy="0 0 0" />
      <geometry>
        <box size="0.005 0.078 0.136" />
        </geometry>
      </collision>
    <collision name="mast_stage__visual_9">
      <origin xyz="0 0.0365 0.42" rpy="0 0 0" />
      <geometry>
        <box size="0.078 0.005 0.136" />
        </geometry>
      </collision>
    <collision name="mast_stage__visual_10">
      <origin xyz="0 -0.0365 0.42" rpy="0 0 0" />
      <geometry>
        <box size="0.078 0.005 0.136" />
        </geometry>
      </collision>
    <collision name="mast_stage__visual_11">
      <origin xyz="0 0 0.495" rpy="0 0 0" />
      <geometry>
        <cylinder radius="0.029" length="0.032" />
        </geometry>
      </collision>
    <collision name="mast_stage__visual_12">
      <origin xyz="0 0 0.506" rpy="0 0 0" />
      <geometry>
        <cylinder radius="0.034" length="0.018" />
        </geometry>
      </collision>
    <collision name="mast_stage__visual_13">
      <origin xyz="0 0 0.519" rpy="0 0 0" />
      <geometry>
        <cylinder radius="0.038" length="0.014" />
        </geometry>
      </collision>
    </link>
  <link name="pan_head">
    <inertial>
      <origin xyz="0.005 0 0.065" rpy="0 0 0" />
      <mass value="1.8" />
      <inertia ixx="0.004035" ixy="0" ixz="0" iyy="0.008535" iyz="0" izz="0.0075" />
      </inertial>
    <visual>
      <origin xyz="0 0 0.016" rpy="0 0 0" />
      <geometry>
        <cylinder radius="0.045" length="0.032" />
        </geometry>
      <material name="machined_aluminum" />
      </visual>
    <visual>
      <origin xyz="0 0 0.035" rpy="0 0 0" />
      <geometry>
        <box size="0.09 0.09 0.01" />
        </geometry>
      <material name="housing_light" />
      </visual>
    <visual>
      <origin xyz="0 0 0.048" rpy="0 0 0" />
      <geometry>
        <box size="0.052 0.052 0.02" />
        </geometry>
      <material name="housing_dark" />
      </visual>
    <visual>
      <origin xyz="0.01 0 0.0855" rpy="0 0 0" />
      <geometry>
        <box size="0.15 0.08 0.055" />
        </geometry>
      <material name="housing_light" />
      </visual>
    <visual>
      <origin xyz="0.1 0 0.0855" rpy="0 0 0" />
      <geometry>
        <box size="0.03 0.078 0.042" />
        </geometry>
      <material name="housing_dark" />
      </visual>
    <visual>
      <origin xyz="0.113 0 0.086" rpy="0 0 0" />
      <geometry>
        <box size="0.004 0.05 0.028" />
        </geometry>
      <material name="optic_glass" />
      </visual>
    <visual>
      <origin xyz="-0.082 0 0.083" rpy="0 1.5708 0" />
      <geometry>
        <cylinder radius="0.022" length="0.055" />
        </geometry>
      <material name="housing_dark" />
      </visual>
    <visual>
      <origin xyz="-0.008 0 0.117" rpy="0 0 0" />
      <geometry>
        <cylinder radius="0.016" length="0.01" />
        </geometry>
      <material name="accent_orange" />
      </visual>
    <collision name="pan_head__visual_1">
      <origin xyz="0 0 0.016" rpy="0 0 0" />
      <geometry>
        <cylinder radius="0.045" length="0.032" />
        </geometry>
      </collision>
    <collision name="pan_head__visual_2">
      <origin xyz="0 0 0.035" rpy="0 0 0" />
      <geometry>
        <box size="0.09 0.09 0.01" />
        </geometry>
      </collision>
    <collision name="pan_head__visual_3">
      <origin xyz="0 0 0.048" rpy="0 0 0" />
      <geometry>
        <box size="0.052 0.052 0.02" />
        </geometry>
      </collision>
    <collision name="pan_head__visual_4">
      <origin xyz="0.01 0 0.0855" rpy="0 0 0" />
      <geometry>
        <box size="0.15 0.08 0.055" />
        </geometry>
      </collision>
    <collision name="pan_head__visual_5">
      <origin xyz="0.1 0 0.0855" rpy="0 0 0" />
      <geometry>
        <box size="0.03 0.078 0.042" />
        </geometry>
      </collision>
    <collision name="pan_head__visual_6">
      <origin xyz="0.113 0 0.086" rpy="0 0 0" />
      <geometry>
        <box size="0.004 0.05 0.028" />
        </geometry>
      </collision>
    <collision name="pan_head__visual_7">
      <origin xyz="-0.082 0 0.083" rpy="0 1.5708 0" />
      <geometry>
        <cylinder radius="0.022" length="0.055" />
        </geometry>
      </collision>
    <collision name="pan_head__visual_8">
      <origin xyz="-0.008 0 0.117" rpy="0 0 0" />
      <geometry>
        <cylinder radius="0.016" length="0.01" />
        </geometry>
      </collision>
    </link>
  <joint name="mast_extension" type="prismatic">
    <origin xyz="0 0 0.14" rpy="0 0 0" />
    <parent link="base" />
    <child link="mast_stage" />
    <axis xyz="0 0 1" />
    <limit effort="150" velocity="0.25" lower="0" upper="0.28" />
    </joint>
  <joint name="pan_yaw" type="revolute">
    <origin xyz="0 0 0.528" rpy="0 0 0" />
    <parent link="mast_stage" />
    <child link="pan_head" />
    <axis xyz="0 0 1" />
    <limit effort="20" velocity="1.5" lower="-3.14159" upper="3.14159" />
    </joint>
  </robot>
