<robot name="hand_truck_dolly">
  <material name="painted_steel">
    <color rgba="0.17 0.18 0.2 1" />
  </material>
  <material name="brushed_steel">
    <color rgba="0.55 0.57 0.6 1" />
  </material>
  <material name="black_rubber">
    <color rgba="0.08 0.08 0.08 1" />
  </material>
  <material name="dark_polymer">
    <color rgba="0.14 0.14 0.15 1" />
  </material>
  <link name="frame">
    <inertial>
      <origin xyz="0 0.018 0.63" rpy="0 0 0" />
      <mass value="7.8" />
      <inertia ixx="0.91442" ixy="0" ixz="0" iyy="1.05482" iyz="0" izz="0.15912" />
    </inertial>
    <visual>
      <geometry>
        <mesh filename="meshes/frame.glb" />
      </geometry>
      <material name="painted_steel">
        <color rgba="0.17 0.18 0.2 1" />
      </material>
    </visual>
    <collision name="frame__visual_1__hull_001">
      <geometry>
        <mesh filename="meshes/collision/cache/539afef2043c40fd7223d4e5__hull_001.obj" />
      </geometry>
    </collision>
    <collision name="frame__visual_1__hull_002">
      <geometry>
        <mesh filename="meshes/collision/cache/539afef2043c40fd7223d4e5__hull_002.obj" />
      </geometry>
    </collision>
    <collision name="frame__visual_1__hull_003">
      <geometry>
        <mesh filename="meshes/collision/cache/539afef2043c40fd7223d4e5__hull_003.obj" />
      </geometry>
    </collision>
    <collision name="frame__visual_1__hull_004">
      <geometry>
        <mesh filename="meshes/collision/cache/539afef2043c40fd7223d4e5__hull_004.obj" />
      </geometry>
    </collision>
    <collision name="frame__visual_1__hull_005">
      <geometry>
        <mesh filename="meshes/collision/cache/539afef2043c40fd7223d4e5__hull_005.obj" />
      </geometry>
    </collision>
    <collision name="frame__visual_1__hull_006">
      <geometry>
        <mesh filename="meshes/collision/cache/539afef2043c40fd7223d4e5__hull_006.obj" />
      </geometry>
    </collision>
    <collision name="frame__visual_1__hull_007">
      <geometry>
        <mesh filename="meshes/collision/cache/539afef2043c40fd7223d4e5__hull_007.obj" />
      </geometry>
    </collision>
    <collision name="frame__visual_1__hull_008">
      <geometry>
        <mesh filename="meshes/collision/cache/539afef2043c40fd7223d4e5__hull_008.obj" />
      </geometry>
    </collision>
    <collision name="frame__visual_1__hull_009">
      <geometry>
        <mesh filename="meshes/collision/cache/539afef2043c40fd7223d4e5__hull_009.obj" />
      </geometry>
    </collision>
  </link>
  <link name="toe_plate">
    <inertial>
      <origin xyz="0 0.12 0.018" rpy="0 0 0" />
      <mass value="2.1" />
      <inertia ixx="0.012355" ixy="0" ixz="0" iyy="0.0216475" iyz="0" izz="0.0311675" />
    </inertial>
    <visual>
      <geometry>
        <mesh filename="meshes/toe_plate.glb" />
      </geometry>
      <material name="brushed_steel">
        <color rgba="0.55 0.57 0.6 1" />
      </material>
    </visual>
    <collision name="toe_plate__visual_1__hull_001">
      <geometry>
        <mesh filename="meshes/collision/cache/704c2d75970f3a1a1082b8c9__hull_001.obj" />
      </geometry>
    </collision>
    <collision name="toe_plate__visual_1__hull_002">
      <geometry>
        <mesh filename="meshes/collision/cache/704c2d75970f3a1a1082b8c9__hull_002.obj" />
      </geometry>
    </collision>
    <collision name="toe_plate__visual_1__hull_003">
      <geometry>
        <mesh filename="meshes/collision/cache/704c2d75970f3a1a1082b8c9__hull_003.obj" />
      </geometry>
    </collision>
    <collision name="toe_plate__visual_1__hull_004">
      <geometry>
        <mesh filename="meshes/collision/cache/704c2d75970f3a1a1082b8c9__hull_004.obj" />
      </geometry>
    </collision>
    <collision name="toe_plate__visual_1__hull_005">
      <geometry>
        <mesh filename="meshes/collision/cache/704c2d75970f3a1a1082b8c9__hull_005.obj" />
      </geometry>
    </collision>
    <collision name="toe_plate__visual_1__hull_006">
      <geometry>
        <mesh filename="meshes/collision/cache/704c2d75970f3a1a1082b8c9__hull_006.obj" />
      </geometry>
    </collision>
    <collision name="toe_plate__visual_1__hull_007">
      <geometry>
        <mesh filename="meshes/collision/cache/704c2d75970f3a1a1082b8c9__hull_007.obj" />
      </geometry>
    </collision>
    <collision name="toe_plate__visual_1__hull_008">
      <geometry>
        <mesh filename="meshes/collision/cache/704c2d75970f3a1a1082b8c9__hull_008.obj" />
      </geometry>
    </collision>
    <collision name="toe_plate__visual_1__hull_009">
      <geometry>
        <mesh filename="meshes/collision/cache/704c2d75970f3a1a1082b8c9__hull_009.obj" />
      </geometry>
    </collision>
    <collision name="toe_plate__visual_1__hull_010">
      <geometry>
        <mesh filename="meshes/collision/cache/704c2d75970f3a1a1082b8c9__hull_010.obj" />
      </geometry>
    </collision>
    <collision name="toe_plate__visual_1__hull_011">
      <geometry>
        <mesh filename="meshes/collision/cache/704c2d75970f3a1a1082b8c9__hull_011.obj" />
      </geometry>
    </collision>
    <collision name="toe_plate__visual_1__hull_012">
      <geometry>
        <mesh filename="meshes/collision/cache/704c2d75970f3a1a1082b8c9__hull_012.obj" />
      </geometry>
    </collision>
    <collision name="toe_plate__visual_1__hull_013">
      <geometry>
        <mesh filename="meshes/collision/cache/704c2d75970f3a1a1082b8c9__hull_013.obj" />
      </geometry>
    </collision>
    <collision name="toe_plate__visual_1__hull_014">
      <geometry>
        <mesh filename="meshes/collision/cache/704c2d75970f3a1a1082b8c9__hull_014.obj" />
      </geometry>
    </collision>
    <collision name="toe_plate__visual_1__hull_015">
      <geometry>
        <mesh filename="meshes/collision/cache/704c2d75970f3a1a1082b8c9__hull_015.obj" />
      </geometry>
    </collision>
    <collision name="toe_plate__visual_1__hull_016">
      <geometry>
        <mesh filename="meshes/collision/cache/704c2d75970f3a1a1082b8c9__hull_016.obj" />
      </geometry>
    </collision>
  </link>
  <link name="toe_extension">
    <inertial>
      <origin xyz="0 0.065 0.006" rpy="0 0 0" />
      <mass value="0.8" />
      <inertia ixx="0.00134833" ixy="0" ixz="0" iyy="0.00454833" iyz="0" izz="0.00581333" />
    </inertial>
    <visual>
      <origin xyz="0 0.055 -0.003" rpy="0 0 0" />
      <geometry>
        <box size="0.26 0.13 0.006" />
      </geometry>
      <material name="brushed_steel">
        <color rgba="0.55 0.57 0.6 1" />
      </material>
    </visual>
    <visual>
      <origin xyz="0 0.12 0.007" rpy="0 0 0" />
      <geometry>
        <box size="0.26 0.006 0.018" />
      </geometry>
      <material name="painted_steel">
        <color rgba="0.17 0.18 0.2 1" />
      </material>
    </visual>
    <visual>
      <origin xyz="0 0.06 0.003" rpy="0 1.5708 0" />
      <geometry>
        <cylinder radius="0.006" length="0.2" />
      </geometry>
      <material name="painted_steel">
        <color rgba="0.17 0.18 0.2 1" />
      </material>
    </visual>
    <collision name="toe_extension__visual_1">
      <origin xyz="0 0.055 -0.003" rpy="0 0 0" />
      <geometry>
        <box size="0.26 0.13 0.006" />
      </geometry>
    </collision>
    <collision name="toe_extension__visual_2">
      <origin xyz="0 0.12 0.007" rpy="0 0 0" />
      <geometry>
        <box size="0.26 0.006 0.018" />
      </geometry>
    </collision>
    <collision name="toe_extension__visual_3">
      <origin xyz="0 0.06 0.003" rpy="0 1.5708 0" />
      <geometry>
        <cylinder radius="0.006" length="0.2" />
      </geometry>
    </collision>
  </link>
  <link name="left_wheel">
    <inertial>
      <origin xyz="0.026 0 0" rpy="0 1.5708 0" />
      <mass value="1.9" />
      <inertia ixx="0.00842333" ixy="0" ixz="0" iyy="0.00842333" iyz="0" izz="0.016055" />
    </inertial>
    <visual>
      <origin xyz="0.026 0 0" rpy="0 1.5708 0" />
      <geometry>
        <cylinder radius="0.13" length="0.05" />
      </geometry>
      <material name="black_rubber">
        <color rgba="0.08 0.08 0.08 1" />
      </material>
    </visual>
    <visual>
      <origin xyz="0.026 0 0" rpy="0 1.5708 0" />
      <geometry>
        <cylinder radius="0.07" length="0.036" />
      </geometry>
      <material name="dark_polymer">
        <color rgba="0.14 0.14 0.15 1" />
      </material>
    </visual>
    <visual>
      <origin xyz="0.026 0 0" rpy="0 1.5708 0" />
      <geometry>
        <cylinder radius="0.03" length="0.044" />
      </geometry>
      <material name="brushed_steel">
        <color rgba="0.55 0.57 0.6 1" />
      </material>
    </visual>
    <collision name="left_wheel__visual_1">
      <origin xyz="0.026 0 0" rpy="0 1.5708 0" />
      <geometry>
        <cylinder radius="0.13" length="0.05" />
      </geometry>
    </collision>
    <collision name="left_wheel__visual_2">
      <origin xyz="0.026 0 0" rpy="0 1.5708 0" />
      <geometry>
        <cylinder radius="0.07" length="0.036" />
      </geometry>
    </collision>
    <collision name="left_wheel__visual_3">
      <origin xyz="0.026 0 0" rpy="0 1.5708 0" />
      <geometry>
        <cylinder radius="0.03" length="0.044" />
      </geometry>
    </collision>
  </link>
  <link name="right_wheel">
    <inertial>
      <origin xyz="-0.026 0 0" rpy="0 1.5708 0" />
      <mass value="1.9" />
      <inertia ixx="0.00842333" ixy="0" ixz="0" iyy="0.00842333" iyz="0" izz="0.016055" />
    </inertial>
    <visual>
      <origin xyz="-0.026 0 0" rpy="0 1.5708 0" />
      <geometry>
        <cylinder radius="0.13" length="0.05" />
      </geometry>
      <material name="black_rubber">
        <color rgba="0.08 0.08 0.08 1" />
      </material>
    </visual>
    <visual>
      <origin xyz="-0.026 0 0" rpy="0 1.5708 0" />
      <geometry>
        <cylinder radius="0.07" length="0.036" />
      </geometry>
      <material name="dark_polymer">
        <color rgba="0.14 0.14 0.15 1" />
      </material>
    </visual>
    <visual>
      <origin xyz="-0.026 0 0" rpy="0 1.5708 0" />
      <geometry>
        <cylinder radius="0.03" length="0.044" />
      </geometry>
      <material name="brushed_steel">
        <color rgba="0.55 0.57 0.6 1" />
      </material>
    </visual>
    <collision name="right_wheel__visual_1">
      <origin xyz="-0.026 0 0" rpy="0 1.5708 0" />
      <geometry>
        <cylinder radius="0.13" length="0.05" />
      </geometry>
    </collision>
    <collision name="right_wheel__visual_2">
      <origin xyz="-0.026 0 0" rpy="0 1.5708 0" />
      <geometry>
        <cylinder radius="0.07" length="0.036" />
      </geometry>
    </collision>
    <collision name="right_wheel__visual_3">
      <origin xyz="-0.026 0 0" rpy="0 1.5708 0" />
      <geometry>
        <cylinder radius="0.03" length="0.044" />
      </geometry>
    </collision>
  </link>
  <joint name="frame_to_toe_plate" type="fixed">
    <origin xyz="0 0.03 0.055" rpy="0 0 0" />
    <parent link="frame" />
    <child link="toe_plate" />
  </joint>
  <joint name="toe_extension_hinge" type="revolute">
    <origin xyz="0 0.235 0" rpy="0 0 0" />
    <parent link="toe_plate" />
    <child link="toe_extension" />
    <axis xyz="1 0 0" />
    <limit effort="12" velocity="2.5" lower="0" upper="1.35" />
  </joint>
  <joint name="left_wheel_spin" type="continuous">
    <origin xyz="0.235 0 0.165" rpy="0 0 0" />
    <parent link="frame" />
    <child link="left_wheel" />
    <axis xyz="1 0 0" />
    <limit effort="18" velocity="20" />
  </joint>
  <joint name="right_wheel_spin" type="continuous">
    <origin xyz="-0.235 0 0.165" rpy="0 0 0" />
    <parent link="frame" />
    <child link="right_wheel" />
    <axis xyz="1 0 0" />
    <limit effort="18" velocity="20" />
  </joint>
</robot>