<robot name="atv_quad_bike">
  <material name="body_red">
    <color rgba="0.6 0.09 0.08 1" />
    </material>
  <material name="matte_black">
    <color rgba="0.08 0.08 0.08 1" />
    </material>
  <material name="frame_black">
    <color rgba="0.14 0.14 0.15 1" />
    </material>
  <material name="rubber">
    <color rgba="0.03 0.03 0.03 1" />
    </material>
  <material name="steel">
    <color rgba="0.57 0.59 0.62 1" />
    </material>
  <material name="aluminum">
    <color rgba="0.74 0.76 0.79 1" />
    </material>
  <material name="seat_vinyl">
    <color rgba="0.07 0.07 0.08 1" />
    </material>
  <material name="spring_yellow">
    <color rgba="0.82 0.73 0.1 1" />
    </material>
  <link name="chassis">
    <inertial>
      <origin xyz="-0.03 0 0.38" rpy="0 0 0" />
      <mass value="185" />
      <inertia ixx="17.151" ixy="0" ixz="0" iyy="34.8802" iyz="0" izz="42.7042" />
      </inertial>
    <visual>
      <geometry>
        <mesh filename="meshes/atv_chassis_body.obj" />
        </geometry>
      <material name="body_red">
        <color rgba="0.6 0.09 0.08 1" />
        </material>
      </visual>
    <visual>
      <origin xyz="0.02 0 0.47" rpy="0 0 0" />
      <geometry>
        <box size="0.34 0.24 0.11" />
        </geometry>
      <material name="body_red">
        <color rgba="0.6 0.09 0.08 1" />
        </material>
      </visual>
    <visual>
      <origin xyz="-0.18 0 0.54" rpy="0 0 0" />
      <geometry>
        <box size="0.48 0.31 0.1" />
        </geometry>
      <material name="seat_vinyl">
        <color rgba="0.07 0.07 0.08 1" />
        </material>
      </visual>
    <visual>
      <origin xyz="-0.42 0 0.58" rpy="0 0 0" />
      <geometry>
        <box size="0.22 0.31 0.08" />
        </geometry>
      <material name="seat_vinyl">
        <color rgba="0.07 0.07 0.08 1" />
        </material>
      </visual>
    <visual>
      <origin xyz="-0.02 0 0.27" rpy="0 0 0" />
      <geometry>
        <box size="0.28 0.28 0.18" />
        </geometry>
      <material name="frame_black">
        <color rgba="0.14 0.14 0.15 1" />
        </material>
      </visual>
    <visual>
      <origin xyz="0.4 0 0.42" rpy="0 0 0" />
      <geometry>
        <cylinder radius="0.045" length="0.18" />
        </geometry>
      <material name="frame_black">
        <color rgba="0.14 0.14 0.15 1" />
        </material>
      </visual>
    <visual>
      <origin xyz="-0.56 0.45 0.3" rpy="0 0 0" />
      <geometry>
        <box size="0.12 0.18 0.12" />
        </geometry>
      <material name="frame_black">
        <color rgba="0.14 0.14 0.15 1" />
        </material>
      </visual>
    <visual>
      <origin xyz="-0.56 -0.45 0.3" rpy="0 0 0" />
      <geometry>
        <box size="0.12 0.18 0.12" />
        </geometry>
      <material name="frame_black">
        <color rgba="0.14 0.14 0.15 1" />
        </material>
      </visual>
    <visual>
      <origin xyz="-0.12 0.28 0.23" rpy="0 0 0" />
      <geometry>
        <box size="0.3 0.24 0.05" />
        </geometry>
      <material name="matte_black">
        <color rgba="0.08 0.08 0.08 1" />
        </material>
      </visual>
    <visual>
      <origin xyz="-0.12 -0.28 0.23" rpy="0 0 0" />
      <geometry>
        <box size="0.3 0.24 0.05" />
        </geometry>
      <material name="matte_black">
        <color rgba="0.08 0.08 0.08 1" />
        </material>
      </visual>
    <visual>
      <origin xyz="-0.54 0 0.3" rpy="0 1.5708 1.5708" />
      <geometry>
        <cylinder radius="0.03" length="0.72" />
        </geometry>
      <material name="frame_black">
        <color rgba="0.14 0.14 0.15 1" />
        </material>
      </visual>
    <visual>
      <origin xyz="-0.115 -0.16 0.28" rpy="0 1.5708 0.037718" />
      <geometry>
        <cylinder radius="0.025" length="0.530377" />
        </geometry>
      <material name="frame_black">
        <color rgba="0.14 0.14 0.15 1" />
        </material>
      </visual>
    <visual>
      <origin xyz="-0.115 0.16 0.28" rpy="0 1.5708 -0.037718" />
      <geometry>
        <cylinder radius="0.025" length="0.530377" />
        </geometry>
      <material name="frame_black">
        <color rgba="0.14 0.14 0.15 1" />
        </material>
      </visual>
    <visual>
      <origin xyz="0.24 -0.085 0.395" rpy="0 1.46571 0.176709" />
      <geometry>
        <cylinder radius="0.022" length="0.286007" />
        </geometry>
      <material name="frame_black">
        <color rgba="0.14 0.14 0.15 1" />
        </material>
      </visual>
    <visual>
      <origin xyz="0.24 0.085 0.395" rpy="0 1.46571 -0.176709" />
      <geometry>
        <cylinder radius="0.022" length="0.286007" />
        </geometry>
      <material name="frame_black">
        <color rgba="0.14 0.14 0.15 1" />
        </material>
      </visual>
    <visual>
      <origin xyz="-0.39 0.26 0.4" rpy="0 0.98439 2.41495" />
      <geometry>
        <cylinder radius="0.018" length="0.289137" />
        </geometry>
      <material name="spring_yellow">
        <color rgba="0.82 0.73 0.1 1" />
        </material>
      </visual>
    <visual>
      <origin xyz="-0.39 -0.26 0.4" rpy="0 0.98439 -2.41495" />
      <geometry>
        <cylinder radius="0.018" length="0.289137" />
        </geometry>
      <material name="spring_yellow">
        <color rgba="0.82 0.73 0.1 1" />
        </material>
      </visual>
    <collision name="chassis__visual_1__hull_001">
      <geometry>
        <mesh filename="meshes/collision/cache/19f4c818bb36ed2a8f04a693__hull_001.obj" />
        </geometry>
      </collision>
    <collision name="chassis__visual_1__hull_002">
      <geometry>
        <mesh filename="meshes/collision/cache/19f4c818bb36ed2a8f04a693__hull_002.obj" />
        </geometry>
      </collision>
    <collision name="chassis__visual_2">
      <origin xyz="0.02 0 0.47" rpy="0 0 0" />
      <geometry>
        <box size="0.34 0.24 0.11" />
        </geometry>
      </collision>
    <collision name="chassis__visual_3">
      <origin xyz="-0.18 0 0.54" rpy="0 0 0" />
      <geometry>
        <box size="0.48 0.31 0.1" />
        </geometry>
      </collision>
    <collision name="chassis__visual_4">
      <origin xyz="-0.42 0 0.58" rpy="0 0 0" />
      <geometry>
        <box size="0.22 0.31 0.08" />
        </geometry>
      </collision>
    <collision name="chassis__visual_5">
      <origin xyz="-0.02 0 0.27" rpy="0 0 0" />
      <geometry>
        <box size="0.28 0.28 0.18" />
        </geometry>
      </collision>
    <collision name="chassis__visual_6">
      <origin xyz="0.4 0 0.42" rpy="0 0 0" />
      <geometry>
        <cylinder radius="0.045" length="0.18" />
        </geometry>
      </collision>
    <collision name="chassis__visual_7">
      <origin xyz="-0.56 0.45 0.3" rpy="0 0 0" />
      <geometry>
        <box size="0.12 0.18 0.12" />
        </geometry>
      </collision>
    <collision name="chassis__visual_8">
      <origin xyz="-0.56 -0.45 0.3" rpy="0 0 0" />
      <geometry>
        <box size="0.12 0.18 0.12" />
        </geometry>
      </collision>
    <collision name="chassis__visual_9">
      <origin xyz="-0.12 0.28 0.23" rpy="0 0 0" />
      <geometry>
        <box size="0.3 0.24 0.05" />
        </geometry>
      </collision>
    <collision name="chassis__visual_10">
      <origin xyz="-0.12 -0.28 0.23" rpy="0 0 0" />
      <geometry>
        <box size="0.3 0.24 0.05" />
        </geometry>
      </collision>
    <collision name="chassis__visual_11">
      <origin xyz="-0.54 0 0.3" rpy="0 1.5708 1.5708" />
      <geometry>
        <cylinder radius="0.03" length="0.72" />
        </geometry>
      </collision>
    <collision name="chassis__visual_12">
      <origin xyz="-0.115 -0.16 0.28" rpy="0 1.5708 0.037718" />
      <geometry>
        <cylinder radius="0.025" length="0.530377" />
        </geometry>
      </collision>
    <collision name="chassis__visual_13">
      <origin xyz="-0.115 0.16 0.28" rpy="0 1.5708 -0.037718" />
      <geometry>
        <cylinder radius="0.025" length="0.530377" />
        </geometry>
      </collision>
    <collision name="chassis__visual_14">
      <origin xyz="0.24 -0.085 0.395" rpy="0 1.46571 0.176709" />
      <geometry>
        <cylinder radius="0.022" length="0.286007" />
        </geometry>
      </collision>
    <collision name="chassis__visual_15">
      <origin xyz="0.24 0.085 0.395" rpy="0 1.46571 -0.176709" />
      <geometry>
        <cylinder radius="0.022" length="0.286007" />
        </geometry>
      </collision>
    <collision name="chassis__visual_16">
      <origin xyz="-0.39 0.26 0.4" rpy="0 0.98439 2.41495" />
      <geometry>
        <cylinder radius="0.018" length="0.289137" />
        </geometry>
      </collision>
    <collision name="chassis__visual_17">
      <origin xyz="-0.39 -0.26 0.4" rpy="0 0.98439 -2.41495" />
      <geometry>
        <cylinder radius="0.018" length="0.289137" />
        </geometry>
      </collision>
    </link>
  <link name="front_steering">
    <inertial>
      <origin xyz="0.08 0 0.08" rpy="0 0 0" />
      <mass value="28" />
      <inertia ixx="2.94677" ixy="0" ixz="0" iyy="1.91543" iyz="0" izz="3.45053" />
      </inertial>
    <visual>
      <origin xyz="0 0 0.1" rpy="0 0 0" />
      <geometry>
        <cylinder radius="0.035" length="0.26" />
        </geometry>
      <material name="frame_black">
        <color rgba="0.14 0.14 0.15 1" />
        </material>
      </visual>
    <visual>
      <origin xyz="-0.01 0 0.22" rpy="0 0 0" />
      <geometry>
        <box size="0.09 0.2 0.05" />
        </geometry>
      <material name="frame_black">
        <color rgba="0.14 0.14 0.15 1" />
        </material>
      </visual>
    <visual>
      <geometry>
        <mesh filename="meshes/atv_handlebar.obj" />
        </geometry>
      <material name="steel">
        <color rgba="0.57 0.59 0.62 1" />
        </material>
      </visual>
    <visual>
      <origin xyz="-0.1 0.36 0.27" rpy="1.5708 0 0" />
      <geometry>
        <cylinder radius="0.016" length="0.12" />
        </geometry>
      <material name="rubber">
        <color rgba="0.03 0.03 0.03 1" />
        </material>
      </visual>
    <visual>
      <origin xyz="-0.1 -0.36 0.27" rpy="1.5708 0 0" />
      <geometry>
        <cylinder radius="0.016" length="0.12" />
        </geometry>
      <material name="rubber">
        <color rgba="0.03 0.03 0.03 1" />
        </material>
      </visual>
    <visual>
      <origin xyz="0.1 0 0.14" rpy="0 0 0" />
      <geometry>
        <box size="0.22 0.52 0.05" />
        </geometry>
      <material name="body_red">
        <color rgba="0.6 0.09 0.08 1" />
        </material>
      </visual>
    <visual>
      <origin xyz="0.16 0 0.07" rpy="0 0 0" />
      <geometry>
        <box size="0.18 0.24 0.08" />
        </geometry>
      <material name="body_red">
        <color rgba="0.6 0.09 0.08 1" />
        </material>
      </visual>
    <visual>
      <origin xyz="0.19 0.3 0.17" rpy="0 0 0" />
      <geometry>
        <box size="0.34 0.22 0.05" />
        </geometry>
      <material name="body_red">
        <color rgba="0.6 0.09 0.08 1" />
        </material>
      </visual>
    <visual>
      <origin xyz="0.19 -0.3 0.17" rpy="0 0 0" />
      <geometry>
        <box size="0.34 0.22 0.05" />
        </geometry>
      <material name="body_red">
        <color rgba="0.6 0.09 0.08 1" />
        </material>
      </visual>
    <visual>
      <origin xyz="0.22 0.46 -0.12" rpy="0 0 0" />
      <geometry>
        <box size="0.08 0.12 0.24" />
        </geometry>
      <material name="frame_black">
        <color rgba="0.14 0.14 0.15 1" />
        </material>
      </visual>
    <visual>
      <origin xyz="0.22 -0.46 -0.12" rpy="0 0 0" />
      <geometry>
        <box size="0.08 0.12 0.24" />
        </geometry>
      <material name="frame_black">
        <color rgba="0.14 0.14 0.15 1" />
        </material>
      </visual>
    <visual>
      <origin xyz="0.105 0.255 -0.06" rpy="0 1.81647 1.00887" />
      <geometry>
        <cylinder radius="0.018" length="0.328938" />
        </geometry>
      <material name="frame_black">
        <color rgba="0.14 0.14 0.15 1" />
        </material>
      </visual>
    <visual>
      <origin xyz="0.105 0.315 -0.06" rpy="0 1.91002 0.722979" />
      <geometry>
        <cylinder radius="0.018" length="0.240416" />
        </geometry>
      <material name="frame_black">
        <color rgba="0.14 0.14 0.15 1" />
        </material>
      </visual>
    <visual>
      <origin xyz="0.105 -0.255 -0.06" rpy="0 1.81647 -1.00887" />
      <geometry>
        <cylinder radius="0.018" length="0.328938" />
        </geometry>
      <material name="frame_black">
        <color rgba="0.14 0.14 0.15 1" />
        </material>
      </visual>
    <visual>
      <origin xyz="0.105 -0.315 -0.06" rpy="0 1.91002 -0.722979" />
      <geometry>
        <cylinder radius="0.018" length="0.240416" />
        </geometry>
      <material name="frame_black">
        <color rgba="0.14 0.14 0.15 1" />
        </material>
      </visual>
    <visual>
      <origin xyz="0.09 0.24 0.035" rpy="0 1.84807 0.965252" />
      <geometry>
        <cylinder radius="0.015" length="0.328786" />
        </geometry>
      <material name="frame_black">
        <color rgba="0.14 0.14 0.15 1" />
        </material>
      </visual>
    <visual>
      <origin xyz="0.09 -0.24 0.035" rpy="0 1.84807 -0.965252" />
      <geometry>
        <cylinder radius="0.015" length="0.328786" />
        </geometry>
      <material name="frame_black">
        <color rgba="0.14 0.14 0.15 1" />
        </material>
      </visual>
    <visual>
      <origin xyz="0.115 0.27 0.075" rpy="0 1.11082 0.945311" />
      <geometry>
        <cylinder radius="0.018" length="0.24779" />
        </geometry>
      <material name="spring_yellow">
        <color rgba="0.82 0.73 0.1 1" />
        </material>
      </visual>
    <visual>
      <origin xyz="0.115 -0.27 0.075" rpy="0 1.11082 -0.945311" />
      <geometry>
        <cylinder radius="0.018" length="0.24779" />
        </geometry>
      <material name="spring_yellow">
        <color rgba="0.82 0.73 0.1 1" />
        </material>
      </visual>
    <visual>
      <origin xyz="0.16 0 -0.03" rpy="0 1.5708 1.5708" />
      <geometry>
        <cylinder radius="0.014" length="0.64" />
        </geometry>
      <material name="steel">
        <color rgba="0.57 0.59 0.62 1" />
        </material>
      </visual>
    <collision name="front_steering__visual_1">
      <origin xyz="0 0 0.1" rpy="0 0 0" />
      <geometry>
        <cylinder radius="0.035" length="0.26" />
        </geometry>
      </collision>
    <collision name="front_steering__visual_2">
      <origin xyz="-0.01 0 0.22" rpy="0 0 0" />
      <geometry>
        <box size="0.09 0.2 0.05" />
        </geometry>
      </collision>
    <collision name="front_steering__visual_3__hull_001">
      <geometry>
        <mesh filename="meshes/collision/cache/23e0dc63bc26329e60cbe8ce__hull_001.obj" />
        </geometry>
      </collision>
    <collision name="front_steering__visual_3__hull_002">
      <geometry>
        <mesh filename="meshes/collision/cache/23e0dc63bc26329e60cbe8ce__hull_002.obj" />
        </geometry>
      </collision>
    <collision name="front_steering__visual_3__hull_003">
      <geometry>
        <mesh filename="meshes/collision/cache/23e0dc63bc26329e60cbe8ce__hull_003.obj" />
        </geometry>
      </collision>
    <collision name="front_steering__visual_3__hull_004">
      <geometry>
        <mesh filename="meshes/collision/cache/23e0dc63bc26329e60cbe8ce__hull_004.obj" />
        </geometry>
      </collision>
    <collision name="front_steering__visual_4">
      <origin xyz="-0.1 0.36 0.27" rpy="1.5708 0 0" />
      <geometry>
        <cylinder radius="0.016" length="0.12" />
        </geometry>
      </collision>
    <collision name="front_steering__visual_5">
      <origin xyz="-0.1 -0.36 0.27" rpy="1.5708 0 0" />
      <geometry>
        <cylinder radius="0.016" length="0.12" />
        </geometry>
      </collision>
    <collision name="front_steering__visual_6">
      <origin xyz="0.1 0 0.14" rpy="0 0 0" />
      <geometry>
        <box size="0.22 0.52 0.05" />
        </geometry>
      </collision>
    <collision name="front_steering__visual_7">
      <origin xyz="0.16 0 0.07" rpy="0 0 0" />
      <geometry>
        <box size="0.18 0.24 0.08" />
        </geometry>
      </collision>
    <collision name="front_steering__visual_8">
      <origin xyz="0.19 0.3 0.17" rpy="0 0 0" />
      <geometry>
        <box size="0.34 0.22 0.05" />
        </geometry>
      </collision>
    <collision name="front_steering__visual_9">
      <origin xyz="0.19 -0.3 0.17" rpy="0 0 0" />
      <geometry>
        <box size="0.34 0.22 0.05" />
        </geometry>
      </collision>
    <collision name="front_steering__visual_10">
      <origin xyz="0.22 0.46 -0.12" rpy="0 0 0" />
      <geometry>
        <box size="0.08 0.12 0.24" />
        </geometry>
      </collision>
    <collision name="front_steering__visual_11">
      <origin xyz="0.22 -0.46 -0.12" rpy="0 0 0" />
      <geometry>
        <box size="0.08 0.12 0.24" />
        </geometry>
      </collision>
    <collision name="front_steering__visual_12">
      <origin xyz="0.105 0.255 -0.06" rpy="0 1.81647 1.00887" />
      <geometry>
        <cylinder radius="0.018" length="0.328938" />
        </geometry>
      </collision>
    <collision name="front_steering__visual_13">
      <origin xyz="0.105 0.315 -0.06" rpy="0 1.91002 0.722979" />
      <geometry>
        <cylinder radius="0.018" length="0.240416" />
        </geometry>
      </collision>
    <collision name="front_steering__visual_14">
      <origin xyz="0.105 -0.255 -0.06" rpy="0 1.81647 -1.00887" />
      <geometry>
        <cylinder radius="0.018" length="0.328938" />
        </geometry>
      </collision>
    <collision name="front_steering__visual_15">
      <origin xyz="0.105 -0.315 -0.06" rpy="0 1.91002 -0.722979" />
      <geometry>
        <cylinder radius="0.018" length="0.240416" />
        </geometry>
      </collision>
    <collision name="front_steering__visual_16">
      <origin xyz="0.09 0.24 0.035" rpy="0 1.84807 0.965252" />
      <geometry>
        <cylinder radius="0.015" length="0.328786" />
        </geometry>
      </collision>
    <collision name="front_steering__visual_17">
      <origin xyz="0.09 -0.24 0.035" rpy="0 1.84807 -0.965252" />
      <geometry>
        <cylinder radius="0.015" length="0.328786" />
        </geometry>
      </collision>
    <collision name="front_steering__visual_18">
      <origin xyz="0.115 0.27 0.075" rpy="0 1.11082 0.945311" />
      <geometry>
        <cylinder radius="0.018" length="0.24779" />
        </geometry>
      </collision>
    <collision name="front_steering__visual_19">
      <origin xyz="0.115 -0.27 0.075" rpy="0 1.11082 -0.945311" />
      <geometry>
        <cylinder radius="0.018" length="0.24779" />
        </geometry>
      </collision>
    <collision name="front_steering__visual_20">
      <origin xyz="0.16 0 -0.03" rpy="0 1.5708 1.5708" />
      <geometry>
        <cylinder radius="0.014" length="0.64" />
        </geometry>
      </collision>
    </link>
  <link name="front_left_wheel">
    <inertial>
      <origin xyz="0 0 0" rpy="1.5708 0 0" />
      <mass value="18" />
      <inertia ixx="0.45915" ixy="0" ixz="0" iyy="0.45915" iyz="0" izz="0.81" />
      </inertial>
    <visual>
      <origin xyz="0 0 0" rpy="1.5708 0 0" />
      <geometry>
        <cylinder radius="0.3" length="0.19" />
        </geometry>
      <material name="rubber">
        <color rgba="0.03 0.03 0.03 1" />
        </material>
      </visual>
    <visual>
      <origin xyz="0 0 0" rpy="1.5708 0 0" />
      <geometry>
        <cylinder radius="0.19" length="0.155" />
        </geometry>
      <material name="aluminum">
        <color rgba="0.74 0.76 0.79 1" />
        </material>
      </visual>
    <visual>
      <origin xyz="0 0 0" rpy="1.5708 0 0" />
      <geometry>
        <cylinder radius="0.07" length="0.24" />
        </geometry>
      <material name="steel">
        <color rgba="0.57 0.59 0.62 1" />
        </material>
      </visual>
    <visual>
      <origin xyz="0 0.055 0" rpy="1.5708 0 0" />
      <geometry>
        <cylinder radius="0.12" length="0.035" />
        </geometry>
      <material name="aluminum">
        <color rgba="0.74 0.76 0.79 1" />
        </material>
      </visual>
    <collision name="front_left_wheel__visual_1">
      <origin xyz="0 0 0" rpy="1.5708 0 0" />
      <geometry>
        <cylinder radius="0.3" length="0.19" />
        </geometry>
      </collision>
    <collision name="front_left_wheel__visual_2">
      <origin xyz="0 0 0" rpy="1.5708 0 0" />
      <geometry>
        <cylinder radius="0.19" length="0.155" />
        </geometry>
      </collision>
    <collision name="front_left_wheel__visual_3">
      <origin xyz="0 0 0" rpy="1.5708 0 0" />
      <geometry>
        <cylinder radius="0.07" length="0.24" />
        </geometry>
      </collision>
    <collision name="front_left_wheel__visual_4">
      <origin xyz="0 0.055 0" rpy="1.5708 0 0" />
      <geometry>
        <cylinder radius="0.12" length="0.035" />
        </geometry>
      </collision>
    </link>
  <link name="front_right_wheel">
    <inertial>
      <origin xyz="0 0 0" rpy="1.5708 0 0" />
      <mass value="18" />
      <inertia ixx="0.45915" ixy="0" ixz="0" iyy="0.45915" iyz="0" izz="0.81" />
      </inertial>
    <visual>
      <origin xyz="0 0 0" rpy="1.5708 0 0" />
      <geometry>
        <cylinder radius="0.3" length="0.19" />
        </geometry>
      <material name="rubber">
        <color rgba="0.03 0.03 0.03 1" />
        </material>
      </visual>
    <visual>
      <origin xyz="0 0 0" rpy="1.5708 0 0" />
      <geometry>
        <cylinder radius="0.19" length="0.155" />
        </geometry>
      <material name="aluminum">
        <color rgba="0.74 0.76 0.79 1" />
        </material>
      </visual>
    <visual>
      <origin xyz="0 0 0" rpy="1.5708 0 0" />
      <geometry>
        <cylinder radius="0.07" length="0.24" />
        </geometry>
      <material name="steel">
        <color rgba="0.57 0.59 0.62 1" />
        </material>
      </visual>
    <visual>
      <origin xyz="0 0.055 0" rpy="1.5708 0 0" />
      <geometry>
        <cylinder radius="0.12" length="0.035" />
        </geometry>
      <material name="aluminum">
        <color rgba="0.74 0.76 0.79 1" />
        </material>
      </visual>
    <collision name="front_right_wheel__visual_1">
      <origin xyz="0 0 0" rpy="1.5708 0 0" />
      <geometry>
        <cylinder radius="0.3" length="0.19" />
        </geometry>
      </collision>
    <collision name="front_right_wheel__visual_2">
      <origin xyz="0 0 0" rpy="1.5708 0 0" />
      <geometry>
        <cylinder radius="0.19" length="0.155" />
        </geometry>
      </collision>
    <collision name="front_right_wheel__visual_3">
      <origin xyz="0 0 0" rpy="1.5708 0 0" />
      <geometry>
        <cylinder radius="0.07" length="0.24" />
        </geometry>
      </collision>
    <collision name="front_right_wheel__visual_4">
      <origin xyz="0 0.055 0" rpy="1.5708 0 0" />
      <geometry>
        <cylinder radius="0.12" length="0.035" />
        </geometry>
      </collision>
    </link>
  <link name="rear_left_wheel">
    <inertial>
      <origin xyz="0 0 0" rpy="1.5708 0 0" />
      <mass value="18" />
      <inertia ixx="0.45915" ixy="0" ixz="0" iyy="0.45915" iyz="0" izz="0.81" />
      </inertial>
    <visual>
      <origin xyz="0 0 0" rpy="1.5708 0 0" />
      <geometry>
        <cylinder radius="0.3" length="0.19" />
        </geometry>
      <material name="rubber">
        <color rgba="0.03 0.03 0.03 1" />
        </material>
      </visual>
    <visual>
      <origin xyz="0 0 0" rpy="1.5708 0 0" />
      <geometry>
        <cylinder radius="0.19" length="0.155" />
        </geometry>
      <material name="aluminum">
        <color rgba="0.74 0.76 0.79 1" />
        </material>
      </visual>
    <visual>
      <origin xyz="0 0 0" rpy="1.5708 0 0" />
      <geometry>
        <cylinder radius="0.07" length="0.24" />
        </geometry>
      <material name="steel">
        <color rgba="0.57 0.59 0.62 1" />
        </material>
      </visual>
    <visual>
      <origin xyz="0 0.055 0" rpy="1.5708 0 0" />
      <geometry>
        <cylinder radius="0.12" length="0.035" />
        </geometry>
      <material name="aluminum">
        <color rgba="0.74 0.76 0.79 1" />
        </material>
      </visual>
    <collision name="rear_left_wheel__visual_1">
      <origin xyz="0 0 0" rpy="1.5708 0 0" />
      <geometry>
        <cylinder radius="0.3" length="0.19" />
        </geometry>
      </collision>
    <collision name="rear_left_wheel__visual_2">
      <origin xyz="0 0 0" rpy="1.5708 0 0" />
      <geometry>
        <cylinder radius="0.19" length="0.155" />
        </geometry>
      </collision>
    <collision name="rear_left_wheel__visual_3">
      <origin xyz="0 0 0" rpy="1.5708 0 0" />
      <geometry>
        <cylinder radius="0.07" length="0.24" />
        </geometry>
      </collision>
    <collision name="rear_left_wheel__visual_4">
      <origin xyz="0 0.055 0" rpy="1.5708 0 0" />
      <geometry>
        <cylinder radius="0.12" length="0.035" />
        </geometry>
      </collision>
    </link>
  <link name="rear_right_wheel">
    <inertial>
      <origin xyz="0 0 0" rpy="1.5708 0 0" />
      <mass value="18" />
      <inertia ixx="0.45915" ixy="0" ixz="0" iyy="0.45915" iyz="0" izz="0.81" />
      </inertial>
    <visual>
      <origin xyz="0 0 0" rpy="1.5708 0 0" />
      <geometry>
        <cylinder radius="0.3" length="0.19" />
        </geometry>
      <material name="rubber">
        <color rgba="0.03 0.03 0.03 1" />
        </material>
      </visual>
    <visual>
      <origin xyz="0 0 0" rpy="1.5708 0 0" />
      <geometry>
        <cylinder radius="0.19" length="0.155" />
        </geometry>
      <material name="aluminum">
        <color rgba="0.74 0.76 0.79 1" />
        </material>
      </visual>
    <visual>
      <origin xyz="0 0 0" rpy="1.5708 0 0" />
      <geometry>
        <cylinder radius="0.07" length="0.24" />
        </geometry>
      <material name="steel">
        <color rgba="0.57 0.59 0.62 1" />
        </material>
      </visual>
    <visual>
      <origin xyz="0 0.055 0" rpy="1.5708 0 0" />
      <geometry>
        <cylinder radius="0.12" length="0.035" />
        </geometry>
      <material name="aluminum">
        <color rgba="0.74 0.76 0.79 1" />
        </material>
      </visual>
    <collision name="rear_right_wheel__visual_1">
      <origin xyz="0 0 0" rpy="1.5708 0 0" />
      <geometry>
        <cylinder radius="0.3" length="0.19" />
        </geometry>
      </collision>
    <collision name="rear_right_wheel__visual_2">
      <origin xyz="0 0 0" rpy="1.5708 0 0" />
      <geometry>
        <cylinder radius="0.19" length="0.155" />
        </geometry>
      </collision>
    <collision name="rear_right_wheel__visual_3">
      <origin xyz="0 0 0" rpy="1.5708 0 0" />
      <geometry>
        <cylinder radius="0.07" length="0.24" />
        </geometry>
      </collision>
    <collision name="rear_right_wheel__visual_4">
      <origin xyz="0 0.055 0" rpy="1.5708 0 0" />
      <geometry>
        <cylinder radius="0.12" length="0.035" />
        </geometry>
      </collision>
    </link>
  <joint name="front_steering_joint" type="revolute">
    <origin xyz="0.4 0 0.42" rpy="0 0 0" />
    <parent link="chassis" />
    <child link="front_steering" />
    <axis xyz="0 0 1" />
    <limit effort="35" velocity="1.6" lower="-0.6" upper="0.6" />
    </joint>
  <joint name="front_left_wheel_spin" type="continuous">
    <origin xyz="0.22 0.46 -0.12" rpy="0 0 0" />
    <parent link="front_steering" />
    <child link="front_left_wheel" />
    <axis xyz="0 1 0" />
    <limit effort="90" velocity="22" />
    </joint>
  <joint name="front_right_wheel_spin" type="continuous">
    <origin xyz="0.22 -0.46 -0.12" rpy="0 0 0" />
    <parent link="front_steering" />
    <child link="front_right_wheel" />
    <axis xyz="0 1 0" />
    <limit effort="90" velocity="22" />
    </joint>
  <joint name="rear_left_wheel_spin" type="continuous">
    <origin xyz="-0.56 0.45 0.3" rpy="0 0 0" />
    <parent link="chassis" />
    <child link="rear_left_wheel" />
    <axis xyz="0 1 0" />
    <limit effort="110" velocity="22" />
    </joint>
  <joint name="rear_right_wheel_spin" type="continuous">
    <origin xyz="-0.56 -0.45 0.3" rpy="0 0 0" />
    <parent link="chassis" />
    <child link="rear_right_wheel" />
    <axis xyz="0 1 0" />
    <limit effort="110" velocity="22" />
    </joint>
  </robot>
