<robot name="premium_over_ear_headphones">
  <link name="headband">
    <inertial>
      <origin xyz="0 0 0.11" rpy="0 0 0" />
      <mass value="0.28" />
      <inertia ixx="0.000569333" ixy="0" ixz="0" iyy="0.00179433" iyz="0" izz="0.00169167" />
      </inertial>
    <visual>
      <geometry>
        <mesh filename="assets/meshes/headband_outer.obj" />
        </geometry>
      <material name="matte_graphite">
        <color rgba="0.15 0.16 0.18 1" />
        </material>
      </visual>
    <visual>
      <geometry>
        <mesh filename="assets/meshes/headband_trim.obj" />
        </geometry>
      <material name="satin_aluminum">
        <color rgba="0.7 0.72 0.75 1" />
        </material>
      </visual>
    <visual>
      <geometry>
        <mesh filename="assets/meshes/headband_pad.obj" />
        </geometry>
      <material name="black_leather">
        <color rgba="0.09 0.09 0.1 1" />
        </material>
      </visual>
    <visual>
      <origin xyz="-0.108 0 0.112" rpy="0 0 0" />
      <geometry>
        <box size="0.022 0.042 0.014" />
        </geometry>
      <material name="matte_graphite">
        <color rgba="0.15 0.16 0.18 1" />
        </material>
      </visual>
    <visual>
      <origin xyz="-0.108 0 0.103" rpy="0 0 0" />
      <geometry>
        <box size="0.01 0.07 0.01" />
        </geometry>
      <material name="matte_graphite">
        <color rgba="0.15 0.16 0.18 1" />
        </material>
      </visual>
    <visual>
      <origin xyz="-0.108 0.026 0.098" rpy="0 0 0" />
      <geometry>
        <box size="0.008 0.012 0.022" />
        </geometry>
      <material name="satin_aluminum">
        <color rgba="0.7 0.72 0.75 1" />
        </material>
      </visual>
    <visual>
      <origin xyz="-0.108 -0.026 0.098" rpy="0 0 0" />
      <geometry>
        <box size="0.008 0.012 0.022" />
        </geometry>
      <material name="satin_aluminum">
        <color rgba="0.7 0.72 0.75 1" />
        </material>
      </visual>
    <visual>
      <origin xyz="-0.108 0 0.09" rpy="1.5708 0 0" />
      <geometry>
        <cylinder radius="0.0055" length="0.064" />
        </geometry>
      <material name="satin_aluminum">
        <color rgba="0.7 0.72 0.75 1" />
        </material>
      </visual>
    <visual>
      <origin xyz="0.108 0 0.112" rpy="0 0 0" />
      <geometry>
        <box size="0.022 0.042 0.014" />
        </geometry>
      <material name="matte_graphite">
        <color rgba="0.15 0.16 0.18 1" />
        </material>
      </visual>
    <visual>
      <origin xyz="0.108 0 0.103" rpy="0 0 0" />
      <geometry>
        <box size="0.01 0.07 0.01" />
        </geometry>
      <material name="matte_graphite">
        <color rgba="0.15 0.16 0.18 1" />
        </material>
      </visual>
    <visual>
      <origin xyz="0.108 0.026 0.098" rpy="0 0 0" />
      <geometry>
        <box size="0.008 0.012 0.022" />
        </geometry>
      <material name="satin_aluminum">
        <color rgba="0.7 0.72 0.75 1" />
        </material>
      </visual>
    <visual>
      <origin xyz="0.108 -0.026 0.098" rpy="0 0 0" />
      <geometry>
        <box size="0.008 0.012 0.022" />
        </geometry>
      <material name="satin_aluminum">
        <color rgba="0.7 0.72 0.75 1" />
        </material>
      </visual>
    <visual>
      <origin xyz="0.108 0 0.09" rpy="1.5708 0 0" />
      <geometry>
        <cylinder radius="0.0055" length="0.064" />
        </geometry>
      <material name="satin_aluminum">
        <color rgba="0.7 0.72 0.75 1" />
        </material>
      </visual>
    </link>
  <link name="left_earcup">
    <inertial>
      <origin xyz="0 0 -0.056" rpy="0 0 0" />
      <mass value="0.16" />
      <inertia ixx="0.000256907" ixy="0" ixz="0" iyy="0.000207587" iyz="0" izz="0.000129987" />
      </inertial>
    <visual>
      <geometry>
        <mesh filename="assets/meshes/earcup_shell.obj" />
        </geometry>
      <material name="matte_graphite">
        <color rgba="0.15 0.16 0.18 1" />
        </material>
      </visual>
    <visual>
      <origin xyz="0 0 -0.01" rpy="0 0 0" />
      <geometry>
        <box size="0.02 0.07 0.014" />
        </geometry>
      <material name="satin_aluminum">
        <color rgba="0.7 0.72 0.75 1" />
        </material>
      </visual>
    <visual>
      <origin xyz="0 0 -0.002" rpy="1.5708 0 0" />
      <geometry>
        <cylinder radius="0.008" length="0.058" />
        </geometry>
      <material name="satin_aluminum">
        <color rgba="0.7 0.72 0.75 1" />
        </material>
      </visual>
    <visual>
      <origin xyz="0.0175 0 -0.056" rpy="0 0 0" />
      <geometry>
        <box size="0.0025 0.05 0.07" />
        </geometry>
      <material name="acoustic_fabric">
        <color rgba="0.18 0.19 0.21 1" />
        </material>
      </visual>
    <visual>
      <origin xyz="0.022 0 -0.056" rpy="0 0 0" />
      <geometry>
        <mesh filename="assets/meshes/earcup_trim_ring.obj" />
        </geometry>
      <material name="satin_aluminum">
        <color rgba="0.7 0.72 0.75 1" />
        </material>
      </visual>
    <visual>
      <origin xyz="0.033 0 -0.056" rpy="0 0 0" />
      <geometry>
        <mesh filename="assets/meshes/earcup_cushion_ring.obj" />
        </geometry>
      <material name="black_leather">
        <color rgba="0.09 0.09 0.1 1" />
        </material>
      </visual>
    <visual>
      <origin xyz="-0.026 0 -0.055" rpy="0 0 0" />
      <geometry>
        <box size="0.004 0.054 0.078" />
        </geometry>
      <material name="matte_graphite">
        <color rgba="0.15 0.16 0.18 1" />
        </material>
      </visual>
    <visual>
      <origin xyz="-0.028 0 -0.028" rpy="0 0 0" />
      <geometry>
        <box size="0.005 0.02 0.034" />
        </geometry>
      <material name="satin_aluminum">
        <color rgba="0.7 0.72 0.75 1" />
        </material>
      </visual>
    </link>
  <link name="right_earcup">
    <inertial>
      <origin xyz="0 0 -0.056" rpy="0 0 0" />
      <mass value="0.16" />
      <inertia ixx="0.000256907" ixy="0" ixz="0" iyy="0.000207587" iyz="0" izz="0.000129987" />
      </inertial>
    <visual>
      <geometry>
        <mesh filename="assets/meshes/earcup_shell.obj" />
        </geometry>
      <material name="matte_graphite">
        <color rgba="0.15 0.16 0.18 1" />
        </material>
      </visual>
    <visual>
      <origin xyz="0 0 -0.01" rpy="0 0 0" />
      <geometry>
        <box size="0.02 0.07 0.014" />
        </geometry>
      <material name="satin_aluminum">
        <color rgba="0.7 0.72 0.75 1" />
        </material>
      </visual>
    <visual>
      <origin xyz="0 0 -0.002" rpy="1.5708 0 0" />
      <geometry>
        <cylinder radius="0.008" length="0.058" />
        </geometry>
      <material name="satin_aluminum">
        <color rgba="0.7 0.72 0.75 1" />
        </material>
      </visual>
    <visual>
      <origin xyz="-0.0175 0 -0.056" rpy="0 0 0" />
      <geometry>
        <box size="0.0025 0.05 0.07" />
        </geometry>
      <material name="acoustic_fabric">
        <color rgba="0.18 0.19 0.21 1" />
        </material>
      </visual>
    <visual>
      <origin xyz="-0.022 0 -0.056" rpy="0 0 0" />
      <geometry>
        <mesh filename="assets/meshes/earcup_trim_ring.obj" />
        </geometry>
      <material name="satin_aluminum">
        <color rgba="0.7 0.72 0.75 1" />
        </material>
      </visual>
    <visual>
      <origin xyz="-0.033 0 -0.056" rpy="0 0 0" />
      <geometry>
        <mesh filename="assets/meshes/earcup_cushion_ring.obj" />
        </geometry>
      <material name="black_leather">
        <color rgba="0.09 0.09 0.1 1" />
        </material>
      </visual>
    <visual>
      <origin xyz="0.026 0 -0.055" rpy="0 0 0" />
      <geometry>
        <box size="0.004 0.054 0.078" />
        </geometry>
      <material name="matte_graphite">
        <color rgba="0.15 0.16 0.18 1" />
        </material>
      </visual>
    <visual>
      <origin xyz="0.028 0 -0.028" rpy="0 0 0" />
      <geometry>
        <box size="0.005 0.02 0.034" />
        </geometry>
      <material name="satin_aluminum">
        <color rgba="0.7 0.72 0.75 1" />
        </material>
      </visual>
    </link>
  <joint name="left_cup_fold" type="revolute">
    <origin xyz="-0.108 0 0.09" rpy="0 0 0" />
    <parent link="headband" />
    <child link="left_earcup" />
    <axis xyz="0 -1 0" />
    <limit effort="4" velocity="2.5" lower="0" upper="0.55" />
    </joint>
  <joint name="right_cup_fold" type="revolute">
    <origin xyz="0.108 0 0.09" rpy="0 0 0" />
    <parent link="headband" />
    <child link="right_earcup" />
    <axis xyz="0 1 0" />
    <limit effort="4" velocity="2.5" lower="0" upper="0.55" />
    </joint>
  </robot>
