<robot name="humanoid_robotic_leg">
  <material name="graphite_shell">
    <color rgba="0.22 0.23 0.25 1" />
  </material>
  <material name="brushed_steel">
    <color rgba="0.67 0.7 0.73 1" />
  </material>
  <material name="matte_polymer">
    <color rgba="0.12 0.13 0.14 1" />
  </material>
  <material name="rubber_tread">
    <color rgba="0.08 0.08 0.09 1" />
  </material>
  <link name="hip_mount">
    <inertial>
      <origin xyz="0 0 0.028" rpy="0 0 0" />
      <mass value="1.6" />
      <inertia ixx="0.00181333" ixy="0" ixz="0" iyy="0.0025968" iyz="0" izz="0.00345013" />
    </inertial>
    <visual name="hip_mount_shell">
      <geometry>
        <mesh filename="meshes/hip_mount_body.glb" />
      </geometry>
      <material name="graphite_shell">
        <color rgba="0.22 0.23 0.25 1" />
      </material>
    </visual>
    <visual name="hip_bearing_barrel">
      <origin xyz="0 0 0.012" rpy="1.5708 0 0" />
      <geometry>
        <cylinder radius="0.017" length="0.094" />
      </geometry>
      <material name="brushed_steel">
        <color rgba="0.67 0.7 0.73 1" />
      </material>
    </visual>
    <visual name="hip_front_pod">
      <origin xyz="0.038 0 0.022" rpy="0 1.5708 0" />
      <geometry>
        <cylinder radius="0.015" length="0.028" />
      </geometry>
      <material name="matte_polymer">
        <color rgba="0.12 0.13 0.14 1" />
      </material>
    </visual>
    <visual name="hip_rear_pod">
      <origin xyz="-0.032 0 0.018" rpy="0 1.5708 0" />
      <geometry>
        <cylinder radius="0.012" length="0.024" />
      </geometry>
      <material name="matte_polymer">
        <color rgba="0.12 0.13 0.14 1" />
      </material>
    </visual>
    <collision name="hip_mount__hip_mount_shell__hull_001">
      <geometry>
        <mesh filename="meshes/collision/cache/74118da3e3e3fa9957ff0e37__hull_001.obj" />
      </geometry>
    </collision>
    <collision name="hip_mount__hip_bearing_barrel">
      <origin xyz="0 0 0.012" rpy="1.5708 0 0" />
      <geometry>
        <cylinder radius="0.017" length="0.094" />
      </geometry>
    </collision>
    <collision name="hip_mount__hip_front_pod">
      <origin xyz="0.038 0 0.022" rpy="0 1.5708 0" />
      <geometry>
        <cylinder radius="0.015" length="0.028" />
      </geometry>
    </collision>
    <collision name="hip_mount__hip_rear_pod">
      <origin xyz="-0.032 0 0.018" rpy="0 1.5708 0" />
      <geometry>
        <cylinder radius="0.012" length="0.024" />
      </geometry>
    </collision>
  </link>
  <link name="thigh">
    <inertial>
      <origin xyz="0.01 0 -0.15" rpy="0 0 0" />
      <mass value="3.4" />
      <inertia ixx="0.0313052" ixy="0" ixz="0" iyy="0.0306252" iyz="0" izz="0.00817417" />
    </inertial>
    <visual name="thigh_shell">
      <geometry>
        <mesh filename="meshes/thigh_shell.glb" />
      </geometry>
      <material name="graphite_shell">
        <color rgba="0.22 0.23 0.25 1" />
      </material>
    </visual>
    <visual name="thigh_actuator_fairing">
      <geometry>
        <mesh filename="meshes/thigh_blister.glb" />
      </geometry>
      <material name="matte_polymer">
        <color rgba="0.12 0.13 0.14 1" />
      </material>
    </visual>
    <visual name="hip_joint_cover">
      <origin xyz="0 0 -0.008" rpy="1.5708 0 0" />
      <geometry>
        <cylinder radius="0.024" length="0.088" />
      </geometry>
      <material name="brushed_steel">
        <color rgba="0.67 0.7 0.73 1" />
      </material>
    </visual>
    <visual name="knee_joint_cover_upper">
      <origin xyz="-0.004 0 -0.292" rpy="1.5708 0 0" />
      <geometry>
        <cylinder radius="0.022" length="0.102" />
      </geometry>
      <material name="brushed_steel">
        <color rgba="0.67 0.7 0.73 1" />
      </material>
    </visual>
    <collision name="thigh__thigh_shell__hull_001">
      <geometry>
        <mesh filename="meshes/collision/cache/c43f08192b4878ac530114ca__hull_001.obj" />
      </geometry>
    </collision>
    <collision name="thigh__thigh_actuator_fairing__hull_001">
      <geometry>
        <mesh filename="meshes/collision/cache/8e4881764d6b6fa5e1d52b95__hull_001.obj" />
      </geometry>
    </collision>
    <collision name="thigh__hip_joint_cover">
      <origin xyz="0 0 -0.008" rpy="1.5708 0 0" />
      <geometry>
        <cylinder radius="0.024" length="0.088" />
      </geometry>
    </collision>
    <collision name="thigh__knee_joint_cover_upper">
      <origin xyz="-0.004 0 -0.292" rpy="1.5708 0 0" />
      <geometry>
        <cylinder radius="0.022" length="0.102" />
      </geometry>
    </collision>
  </link>
  <link name="shin">
    <inertial>
      <origin xyz="0.006 0 -0.152" rpy="0 0 0" />
      <mass value="2.7" />
      <inertia ixx="0.0235053" ixy="0" ixz="0" iyy="0.0230868" iyz="0" izz="0.0039033" />
    </inertial>
    <visual name="shin_shell">
      <geometry>
        <mesh filename="meshes/shin_shell.glb" />
      </geometry>
      <material name="graphite_shell">
        <color rgba="0.22 0.23 0.25 1" />
      </material>
    </visual>
    <visual name="shin_actuator_fairing">
      <geometry>
        <mesh filename="meshes/shin_blister.glb" />
      </geometry>
      <material name="matte_polymer">
        <color rgba="0.12 0.13 0.14 1" />
      </material>
    </visual>
    <visual name="shin_tendon_rail">
      <geometry>
        <mesh filename="meshes/shin_tendon_rail.glb" />
      </geometry>
      <material name="brushed_steel">
        <color rgba="0.67 0.7 0.73 1" />
      </material>
    </visual>
    <visual name="knee_joint_cover_lower">
      <origin xyz="-0.004 0 0" rpy="1.5708 0 0" />
      <geometry>
        <cylinder radius="0.024" length="0.094" />
      </geometry>
      <material name="brushed_steel">
        <color rgba="0.67 0.7 0.73 1" />
      </material>
    </visual>
    <visual name="ankle_joint_cover_upper">
      <origin xyz="0 0 -0.298" rpy="1.5708 0 0" />
      <geometry>
        <cylinder radius="0.021" length="0.082" />
      </geometry>
      <material name="brushed_steel">
        <color rgba="0.67 0.7 0.73 1" />
      </material>
    </visual>
    <collision name="shin__shin_shell__hull_001">
      <geometry>
        <mesh filename="meshes/collision/cache/aa194d1ee68b750fbffb2b6a__hull_001.obj" />
      </geometry>
    </collision>
    <collision name="shin__shin_actuator_fairing__hull_001">
      <geometry>
        <mesh filename="meshes/collision/cache/b6e8addb57822cecea0aec42__hull_001.obj" />
      </geometry>
    </collision>
    <collision name="shin__shin_tendon_rail__hull_001">
      <geometry>
        <mesh filename="meshes/collision/cache/0be76dbaea0634d90e454c4f__hull_001.obj" />
      </geometry>
    </collision>
    <collision name="shin__knee_joint_cover_lower">
      <origin xyz="-0.004 0 0" rpy="1.5708 0 0" />
      <geometry>
        <cylinder radius="0.024" length="0.094" />
      </geometry>
    </collision>
    <collision name="shin__ankle_joint_cover_upper">
      <origin xyz="0 0 -0.298" rpy="1.5708 0 0" />
      <geometry>
        <cylinder radius="0.021" length="0.082" />
      </geometry>
    </collision>
  </link>
  <link name="foot">
    <inertial>
      <origin xyz="0.052 0 -0.046" rpy="0 0 0" />
      <mass value="1.2" />
      <inertia ixx="0.00149" ixy="0" ixz="0" iyy="0.00449" iyz="0" izz="0.005" />
    </inertial>
    <visual name="foot_shell">
      <geometry>
        <mesh filename="meshes/foot_shell.glb" />
      </geometry>
      <material name="graphite_shell">
        <color rgba="0.22 0.23 0.25 1" />
      </material>
    </visual>
    <visual name="foot_top_cap">
      <geometry>
        <mesh filename="meshes/foot_top_cap.glb" />
      </geometry>
      <material name="matte_polymer">
        <color rgba="0.12 0.13 0.14 1" />
      </material>
    </visual>
    <visual name="foot_sole">
      <geometry>
        <mesh filename="meshes/foot_sole.glb" />
      </geometry>
      <material name="rubber_tread">
        <color rgba="0.08 0.08 0.09 1" />
      </material>
    </visual>
    <visual name="ankle_joint_cover_lower">
      <origin xyz="-0.004 0 -0.002" rpy="1.5708 0 0" />
      <geometry>
        <cylinder radius="0.022" length="0.084" />
      </geometry>
      <material name="brushed_steel">
        <color rgba="0.67 0.7 0.73 1" />
      </material>
    </visual>
    <visual name="toe_bumper">
      <origin xyz="0.148 0 -0.04" rpy="1.5708 0 0" />
      <geometry>
        <cylinder radius="0.009" length="0.07" />
      </geometry>
      <material name="rubber_tread">
        <color rgba="0.08 0.08 0.09 1" />
      </material>
    </visual>
    <visual name="heel_bumper">
      <origin xyz="-0.046 0 -0.066" rpy="1.5708 0 0" />
      <geometry>
        <cylinder radius="0.01" length="0.058" />
      </geometry>
      <material name="rubber_tread">
        <color rgba="0.08 0.08 0.09 1" />
      </material>
    </visual>
    <collision name="foot__foot_shell__hull_001">
      <geometry>
        <mesh filename="meshes/collision/cache/3970762f0580dcd00f502285__hull_001.obj" />
      </geometry>
    </collision>
    <collision name="foot__foot_top_cap__hull_001">
      <geometry>
        <mesh filename="meshes/collision/cache/70e0e62fc6ebd36f0c2cc8b9__hull_001.obj" />
      </geometry>
    </collision>
    <collision name="foot__foot_sole__hull_001">
      <geometry>
        <mesh filename="meshes/collision/cache/594c9837d70ce4708a0357de__hull_001.obj" />
      </geometry>
    </collision>
    <collision name="foot__ankle_joint_cover_lower">
      <origin xyz="-0.004 0 -0.002" rpy="1.5708 0 0" />
      <geometry>
        <cylinder radius="0.022" length="0.084" />
      </geometry>
    </collision>
    <collision name="foot__toe_bumper">
      <origin xyz="0.148 0 -0.04" rpy="1.5708 0 0" />
      <geometry>
        <cylinder radius="0.009" length="0.07" />
      </geometry>
    </collision>
    <collision name="foot__heel_bumper">
      <origin xyz="-0.046 0 -0.066" rpy="1.5708 0 0" />
      <geometry>
        <cylinder radius="0.01" length="0.058" />
      </geometry>
    </collision>
  </link>
  <joint name="hip_pitch" type="revolute">
    <parent link="hip_mount" />
    <child link="thigh" />
    <axis xyz="0 -1 0" />
    <limit effort="220" velocity="2.2" lower="-0.85" upper="0.95" />
  </joint>
  <joint name="knee_pitch" type="revolute">
    <origin xyz="-0.004 0 -0.3" rpy="0 0 0" />
    <parent link="thigh" />
    <child link="shin" />
    <axis xyz="0 1 0" />
    <limit effort="260" velocity="2.8" lower="0" upper="1.6" />
  </joint>
  <joint name="ankle_pitch" type="revolute">
    <origin xyz="0 0 -0.304" rpy="0 0 0" />
    <parent link="shin" />
    <child link="foot" />
    <axis xyz="0 -1 0" />
    <limit effort="180" velocity="3" lower="-0.6" upper="0.6" />
  </joint>
</robot>