<robot name="radial_arm_mechanism">
  <material name="cast_iron">
    <color rgba="0.28 0.29 0.31 1" />
    </material>
  <material name="machine_gray">
    <color rgba="0.72 0.74 0.78 1" />
    </material>
  <material name="safety_orange">
    <color rgba="0.88 0.43 0.14 1" />
    </material>
  <material name="polished_steel">
    <color rgba="0.78 0.8 0.83 1" />
    </material>
  <link name="base">
    <inertial>
      <origin xyz="0 0 0.2" rpy="0 0 0" />
      <mass value="38" />
      <inertia ixx="0.791667" ixy="0" ixz="0" iyy="0.917067" iyz="0" izz="0.6954" />
      </inertial>
    <visual>
      <geometry>
        <mesh filename="meshes/base.obj" />
        </geometry>
      <material name="cast_iron" />
      </visual>
    <collision name="base__visual_1__hull_001">
      <geometry>
        <mesh filename="meshes/collision/cache/base__6473b9a971568d66__hull_001.obj" />
        </geometry>
      </collision>
    <collision name="base__visual_1__hull_002">
      <geometry>
        <mesh filename="meshes/collision/cache/base__6473b9a971568d66__hull_002.obj" />
        </geometry>
      </collision>
    <collision name="base__visual_1__hull_003">
      <geometry>
        <mesh filename="meshes/collision/cache/base__6473b9a971568d66__hull_003.obj" />
        </geometry>
      </collision>
    <collision name="base__visual_1__hull_004">
      <geometry>
        <mesh filename="meshes/collision/cache/base__6473b9a971568d66__hull_004.obj" />
        </geometry>
      </collision>
    <collision name="base__visual_1__hull_005">
      <geometry>
        <mesh filename="meshes/collision/cache/base__6473b9a971568d66__hull_005.obj" />
        </geometry>
      </collision>
    <collision name="base__visual_1__hull_006">
      <geometry>
        <mesh filename="meshes/collision/cache/base__6473b9a971568d66__hull_006.obj" />
        </geometry>
      </collision>
    <collision name="base__visual_1__hull_007">
      <geometry>
        <mesh filename="meshes/collision/cache/base__6473b9a971568d66__hull_007.obj" />
        </geometry>
      </collision>
    <collision name="base__visual_1__hull_008">
      <geometry>
        <mesh filename="meshes/collision/cache/base__6473b9a971568d66__hull_008.obj" />
        </geometry>
      </collision>
    <collision name="base__visual_1__hull_009">
      <geometry>
        <mesh filename="meshes/collision/cache/base__6473b9a971568d66__hull_009.obj" />
        </geometry>
      </collision>
    </link>
  <link name="arm">
    <inertial>
      <origin xyz="0.24 0 0" rpy="0 0 0" />
      <mass value="13.5" />
      <inertia ixx="0.0410625" ixy="0" ixz="0" iyy="0.509063" iyz="0" izz="0.5121" />
      </inertial>
    <visual>
      <geometry>
        <mesh filename="meshes/arm.obj" />
        </geometry>
      <material name="machine_gray" />
      </visual>
    <collision name="arm__visual_1__hull_001">
      <geometry>
        <mesh filename="meshes/collision/cache/arm__c18c5b5ca7e82f97__hull_001.obj" />
        </geometry>
      </collision>
    <collision name="arm__visual_1__hull_002">
      <geometry>
        <mesh filename="meshes/collision/cache/arm__c18c5b5ca7e82f97__hull_002.obj" />
        </geometry>
      </collision>
    <collision name="arm__visual_1__hull_003">
      <geometry>
        <mesh filename="meshes/collision/cache/arm__c18c5b5ca7e82f97__hull_003.obj" />
        </geometry>
      </collision>
    <collision name="arm__visual_1__hull_004">
      <geometry>
        <mesh filename="meshes/collision/cache/arm__c18c5b5ca7e82f97__hull_004.obj" />
        </geometry>
      </collision>
    <collision name="arm__visual_1__hull_005">
      <geometry>
        <mesh filename="meshes/collision/cache/arm__c18c5b5ca7e82f97__hull_005.obj" />
        </geometry>
      </collision>
    </link>
  <link name="carriage">
    <inertial>
      <origin xyz="-0.01 0 -0.04" rpy="0 0 0" />
      <mass value="6.5" />
      <inertia ixx="0.0377542" ixy="0" ixz="0" iyy="0.0316875" iyz="0" izz="0.0216667" />
      </inertial>
    <visual>
      <origin xyz="-0.01 0 0" rpy="0 0 0" />
      <geometry>
        <mesh filename="meshes/carriage.obj" />
        </geometry>
      <material name="safety_orange" />
      </visual>
    <visual>
      <origin xyz="-0.01 0 -0.16" rpy="0 0 0" />
      <geometry>
        <cylinder radius="0.02" length="0.08" />
        </geometry>
      <material name="polished_steel" />
      </visual>
    <collision name="carriage__visual_1__hull_001">
      <origin xyz="-0.01 0 0" rpy="0 0 0" />
      <geometry>
        <mesh filename="meshes/collision/cache/carriage__fb0252b16ddd6ced__hull_001.obj" />
        </geometry>
      </collision>
    <collision name="carriage__visual_1__hull_002">
      <origin xyz="-0.01 0 0" rpy="0 0 0" />
      <geometry>
        <mesh filename="meshes/collision/cache/carriage__fb0252b16ddd6ced__hull_002.obj" />
        </geometry>
      </collision>
    <collision name="carriage__visual_1__hull_003">
      <origin xyz="-0.01 0 0" rpy="0 0 0" />
      <geometry>
        <mesh filename="meshes/collision/cache/carriage__fb0252b16ddd6ced__hull_003.obj" />
        </geometry>
      </collision>
    <collision name="carriage__visual_1__hull_004">
      <origin xyz="-0.01 0 0" rpy="0 0 0" />
      <geometry>
        <mesh filename="meshes/collision/cache/carriage__fb0252b16ddd6ced__hull_004.obj" />
        </geometry>
      </collision>
    <collision name="carriage__visual_1__hull_005">
      <origin xyz="-0.01 0 0" rpy="0 0 0" />
      <geometry>
        <mesh filename="meshes/collision/cache/carriage__fb0252b16ddd6ced__hull_005.obj" />
        </geometry>
      </collision>
    <collision name="carriage__visual_1__hull_006">
      <origin xyz="-0.01 0 0" rpy="0 0 0" />
      <geometry>
        <mesh filename="meshes/collision/cache/carriage__fb0252b16ddd6ced__hull_006.obj" />
        </geometry>
      </collision>
    <collision name="carriage__visual_1__hull_007">
      <origin xyz="-0.01 0 0" rpy="0 0 0" />
      <geometry>
        <mesh filename="meshes/collision/cache/carriage__fb0252b16ddd6ced__hull_007.obj" />
        </geometry>
      </collision>
    <collision name="carriage__visual_1__hull_008">
      <origin xyz="-0.01 0 0" rpy="0 0 0" />
      <geometry>
        <mesh filename="meshes/collision/cache/carriage__fb0252b16ddd6ced__hull_008.obj" />
        </geometry>
      </collision>
    <collision name="carriage__visual_1__hull_009">
      <origin xyz="-0.01 0 0" rpy="0 0 0" />
      <geometry>
        <mesh filename="meshes/collision/cache/carriage__fb0252b16ddd6ced__hull_009.obj" />
        </geometry>
      </collision>
    <collision name="carriage__visual_1__hull_010">
      <origin xyz="-0.01 0 0" rpy="0 0 0" />
      <geometry>
        <mesh filename="meshes/collision/cache/carriage__fb0252b16ddd6ced__hull_010.obj" />
        </geometry>
      </collision>
    <collision name="carriage__visual_1__hull_011">
      <origin xyz="-0.01 0 0" rpy="0 0 0" />
      <geometry>
        <mesh filename="meshes/collision/cache/carriage__fb0252b16ddd6ced__hull_011.obj" />
        </geometry>
      </collision>
    <collision name="carriage__visual_2">
      <origin xyz="-0.01 0 -0.16" rpy="0 0 0" />
      <geometry>
        <cylinder radius="0.02" length="0.08" />
        </geometry>
      </collision>
    </link>
  <joint name="arm_swing" type="revolute">
    <origin xyz="0 0 0.38" rpy="0 0 0" />
    <parent link="base" />
    <child link="arm" />
    <axis xyz="0 0 1" />
    <limit effort="120" velocity="1.2" lower="-2.2" upper="2.2" />
    </joint>
  <joint name="carriage_slide" type="prismatic">
    <origin xyz="0.21 0 0" rpy="0 0 0" />
    <parent link="arm" />
    <child link="carriage" />
    <axis xyz="1 0 0" />
    <limit effort="60" velocity="0.25" lower="0" upper="0.24" />
    </joint>
  </robot>
