<robot name="studio_spotlight">
  <link name="stand">
    <inertial>
      <origin xyz="0 0 0.46" rpy="0 0 0" />
      <mass value="18" />
      <inertia ixx="1.4046" ixy="0" ixz="0" iyy="1.5342" iyz="0" izz="0.3996" />
    </inertial>
    <visual name="base_plate">
      <origin xyz="0 0 0.014" rpy="0 0 0" />
      <geometry>
        <box size="0.42 0.3 0.028" />
      </geometry>
    </visual>
    <visual name="base_plinth">
      <origin xyz="0 0 0.049" rpy="0 0 0" />
      <geometry>
        <box size="0.24 0.16 0.042" />
      </geometry>
    </visual>
    <visual name="ballast_box">
      <origin xyz="0 -0.07 0.115" rpy="0 0 0" />
      <geometry>
        <box size="0.18 0.1 0.09" />
      </geometry>
    </visual>
    <visual name="lower_riser">
      <origin xyz="0 0 0.38" rpy="0 0 0" />
      <geometry>
        <cylinder radius="0.032" length="0.62" />
      </geometry>
    </visual>
    <visual name="lock_collar">
      <origin xyz="0 0 0.71" rpy="0 0 0" />
      <geometry>
        <cylinder radius="0.05" length="0.04" />
      </geometry>
    </visual>
    <visual name="upper_riser">
      <origin xyz="0 0 0.795" rpy="0 0 0" />
      <geometry>
        <cylinder radius="0.022" length="0.13" />
      </geometry>
    </visual>
    <visual name="pan_head">
      <origin xyz="0 0 0.871" rpy="0 0 0" />
      <geometry>
        <box size="0.1 0.08 0.022" />
      </geometry>
    </visual>
    <visual name="foot_l_b">
      <origin xyz="-0.155 -0.105 -0.004" rpy="0 0 0" />
      <geometry>
        <box size="0.045 0.045 0.008" />
      </geometry>
    </visual>
    <visual name="foot_l_f">
      <origin xyz="-0.155 0.105 -0.004" rpy="0 0 0" />
      <geometry>
        <box size="0.045 0.045 0.008" />
      </geometry>
    </visual>
    <visual name="foot_r_b">
      <origin xyz="0.155 -0.105 -0.004" rpy="0 0 0" />
      <geometry>
        <box size="0.045 0.045 0.008" />
      </geometry>
    </visual>
    <visual name="foot_r_f">
      <origin xyz="0.155 0.105 -0.004" rpy="0 0 0" />
      <geometry>
        <box size="0.045 0.045 0.008" />
      </geometry>
    </visual>
    <collision name="stand__base_plate">
      <origin xyz="0 0 0.014" rpy="0 0 0" />
      <geometry>
        <box size="0.42 0.3 0.028" />
      </geometry>
    </collision>
    <collision name="stand__base_plinth">
      <origin xyz="0 0 0.049" rpy="0 0 0" />
      <geometry>
        <box size="0.24 0.16 0.042" />
      </geometry>
    </collision>
    <collision name="stand__ballast_box">
      <origin xyz="0 -0.07 0.115" rpy="0 0 0" />
      <geometry>
        <box size="0.18 0.1 0.09" />
      </geometry>
    </collision>
    <collision name="stand__lower_riser">
      <origin xyz="0 0 0.38" rpy="0 0 0" />
      <geometry>
        <cylinder radius="0.032" length="0.62" />
      </geometry>
    </collision>
    <collision name="stand__lock_collar">
      <origin xyz="0 0 0.71" rpy="0 0 0" />
      <geometry>
        <cylinder radius="0.05" length="0.04" />
      </geometry>
    </collision>
    <collision name="stand__upper_riser">
      <origin xyz="0 0 0.795" rpy="0 0 0" />
      <geometry>
        <cylinder radius="0.022" length="0.13" />
      </geometry>
    </collision>
    <collision name="stand__pan_head">
      <origin xyz="0 0 0.871" rpy="0 0 0" />
      <geometry>
        <box size="0.1 0.08 0.022" />
      </geometry>
    </collision>
    <collision name="stand__foot_l_b">
      <origin xyz="-0.155 -0.105 -0.004" rpy="0 0 0" />
      <geometry>
        <box size="0.045 0.045 0.008" />
      </geometry>
    </collision>
    <collision name="stand__foot_l_f">
      <origin xyz="-0.155 0.105 -0.004" rpy="0 0 0" />
      <geometry>
        <box size="0.045 0.045 0.008" />
      </geometry>
    </collision>
    <collision name="stand__foot_r_b">
      <origin xyz="0.155 -0.105 -0.004" rpy="0 0 0" />
      <geometry>
        <box size="0.045 0.045 0.008" />
      </geometry>
    </collision>
    <collision name="stand__foot_r_f">
      <origin xyz="0.155 0.105 -0.004" rpy="0 0 0" />
      <geometry>
        <box size="0.045 0.045 0.008" />
      </geometry>
    </collision>
  </link>
  <link name="yoke">
    <inertial>
      <origin xyz="0 0.05 -0.135" rpy="0 0 0" />
      <mass value="3.4" />
      <inertia ixx="0.0234883" ixy="0" ixz="0" iyy="0.057375" iyz="0" izz="0.0395533" />
    </inertial>
    <visual name="top_bridge">
      <origin xyz="0 0.05 -0.006" rpy="0 0 0" />
      <geometry>
        <box size="0.36 0.08 0.012" />
      </geometry>
    </visual>
    <visual name="pan_crown">
      <origin xyz="0 0.018 -0.011" rpy="0 0 0" />
      <geometry>
        <box size="0.12 0.1 0.022" />
      </geometry>
    </visual>
    <visual name="center_trunnion_block">
      <origin xyz="0 0.082 -0.132" rpy="0 0 0" />
      <geometry>
        <box size="0.09 0.06 0.052" />
      </geometry>
    </visual>
    <visual name="side_arm_l">
      <origin xyz="-0.17 0.082 -0.14" rpy="0 0 0" />
      <geometry>
        <box size="0.024 0.05 0.26" />
      </geometry>
    </visual>
    <visual name="tilt_collar_l">
      <origin xyz="-0.154 0.11 -0.125" rpy="0 1.5708 0" />
      <geometry>
        <cylinder radius="0.032" length="0.016" />
      </geometry>
    </visual>
    <visual name="side_arm_r">
      <origin xyz="0.17 0.082 -0.14" rpy="0 0 0" />
      <geometry>
        <box size="0.024 0.05 0.26" />
      </geometry>
    </visual>
    <visual name="tilt_collar_r">
      <origin xyz="0.154 0.11 -0.125" rpy="0 1.5708 0" />
      <geometry>
        <cylinder radius="0.032" length="0.016" />
      </geometry>
    </visual>
    <visual name="tilt_backbrace">
      <origin xyz="0 0.05 -0.145" rpy="0 0 0" />
      <geometry>
        <box size="0.342 0.028 0.028" />
      </geometry>
    </visual>
    <visual name="lower_stiffener">
      <origin xyz="0 0.068 -0.235" rpy="0 0 0" />
      <geometry>
        <box size="0.342 0.018 0.022" />
      </geometry>
    </visual>
    <collision name="yoke__top_bridge">
      <origin xyz="0 0.05 -0.006" rpy="0 0 0" />
      <geometry>
        <box size="0.36 0.08 0.012" />
      </geometry>
    </collision>
    <collision name="yoke__pan_crown">
      <origin xyz="0 0.018 -0.011" rpy="0 0 0" />
      <geometry>
        <box size="0.12 0.1 0.022" />
      </geometry>
    </collision>
    <collision name="yoke__center_trunnion_block">
      <origin xyz="0 0.082 -0.132" rpy="0 0 0" />
      <geometry>
        <box size="0.09 0.06 0.052" />
      </geometry>
    </collision>
    <collision name="yoke__side_arm_l">
      <origin xyz="-0.17 0.082 -0.14" rpy="0 0 0" />
      <geometry>
        <box size="0.024 0.05 0.26" />
      </geometry>
    </collision>
    <collision name="yoke__tilt_collar_l">
      <origin xyz="-0.154 0.11 -0.125" rpy="0 1.5708 0" />
      <geometry>
        <cylinder radius="0.032" length="0.016" />
      </geometry>
    </collision>
    <collision name="yoke__side_arm_r">
      <origin xyz="0.17 0.082 -0.14" rpy="0 0 0" />
      <geometry>
        <box size="0.024 0.05 0.26" />
      </geometry>
    </collision>
    <collision name="yoke__tilt_collar_r">
      <origin xyz="0.154 0.11 -0.125" rpy="0 1.5708 0" />
      <geometry>
        <cylinder radius="0.032" length="0.016" />
      </geometry>
    </collision>
    <collision name="yoke__tilt_backbrace">
      <origin xyz="0 0.05 -0.145" rpy="0 0 0" />
      <geometry>
        <box size="0.342 0.028 0.028" />
      </geometry>
    </collision>
    <collision name="yoke__lower_stiffener">
      <origin xyz="0 0.068 -0.235" rpy="0 0 0" />
      <geometry>
        <box size="0.342 0.018 0.022" />
      </geometry>
    </collision>
  </link>
  <link name="lamp">
    <inertial>
      <origin xyz="0 0.18 0.085" rpy="0 0 0" />
      <mass value="6.8" />
      <inertia ixx="0.123533" ixy="0" ixz="0" iyy="0.109027" iyz="0" izz="0.116507" />
    </inertial>
    <visual name="tilt_axle">
      <origin xyz="0 0 0" rpy="0 1.5708 0" />
      <geometry>
        <cylinder radius="0.015" length="0.23" />
      </geometry>
    </visual>
    <visual name="tilt_knob_l">
      <origin xyz="-0.127 0 0" rpy="0 1.5708 0" />
      <geometry>
        <cylinder radius="0.036" length="0.024" />
      </geometry>
    </visual>
    <visual name="tilt_knob_r">
      <origin xyz="0.127 0 0" rpy="0 1.5708 0" />
      <geometry>
        <cylinder radius="0.036" length="0.024" />
      </geometry>
    </visual>
    <visual name="rear_body">
      <origin xyz="0 0.1 0.06" rpy="0 0 0" />
      <geometry>
        <box size="0.2 0.08 0.18" />
      </geometry>
    </visual>
    <visual name="trunnion_core">
      <origin xyz="0 0.05 0.045" rpy="0 0 0" />
      <geometry>
        <box size="0.15 0.09 0.12" />
      </geometry>
    </visual>
    <visual name="main_drum">
      <origin xyz="0 0.19 0.08" rpy="1.5708 0 0" />
      <geometry>
        <cylinder radius="0.13" length="0.2" />
      </geometry>
    </visual>
    <visual name="front_bezel">
      <origin xyz="0 0.3 0.08" rpy="1.5708 0 0" />
      <geometry>
        <cylinder radius="0.145" length="0.03" />
      </geometry>
    </visual>
    <visual name="lens_tube">
      <origin xyz="0 0.255 0.08" rpy="1.5708 0 0" />
      <geometry>
        <cylinder radius="0.102" length="0.06" />
      </geometry>
    </visual>
    <visual name="front_lens">
      <origin xyz="0 0.287 0.08" rpy="1.5708 0 0" />
      <geometry>
        <cylinder radius="0.122" length="0.008" />
      </geometry>
    </visual>
    <visual name="driver_housing">
      <origin xyz="0 0.165 0.165" rpy="0 0 0" />
      <geometry>
        <box size="0.18 0.11 0.08" />
      </geometry>
    </visual>
    <visual name="lower_chin">
      <origin xyz="0 0.155 -0.025" rpy="0 0 0" />
      <geometry>
        <box size="0.18 0.09 0.05" />
      </geometry>
    </visual>
    <visual name="cooling_fin_1">
      <origin xyz="0 0.105 0.222" rpy="0 0 0" />
      <geometry>
        <box size="0.15 0.014 0.06" />
      </geometry>
    </visual>
    <visual name="cooling_fin_2">
      <origin xyz="0 0.13 0.222" rpy="0 0 0" />
      <geometry>
        <box size="0.15 0.014 0.06" />
      </geometry>
    </visual>
    <visual name="cooling_fin_3">
      <origin xyz="0 0.155 0.222" rpy="0 0 0" />
      <geometry>
        <box size="0.15 0.014 0.06" />
      </geometry>
    </visual>
    <visual name="cooling_fin_4">
      <origin xyz="0 0.18 0.222" rpy="0 0 0" />
      <geometry>
        <box size="0.15 0.014 0.06" />
      </geometry>
    </visual>
    <visual name="cooling_fin_5">
      <origin xyz="0 0.205 0.222" rpy="0 0 0" />
      <geometry>
        <box size="0.15 0.014 0.06" />
      </geometry>
    </visual>
    <visual name="side_cheek_l">
      <origin xyz="-0.1 0.09 0.075" rpy="0 0 0" />
      <geometry>
        <box size="0.022 0.14 0.13" />
      </geometry>
    </visual>
    <visual name="side_cheek_r">
      <origin xyz="0.1 0.09 0.075" rpy="0 0 0" />
      <geometry>
        <box size="0.022 0.14 0.13" />
      </geometry>
    </visual>
    <visual name="accessory_tab_1">
      <origin xyz="0 0.305 -0.05" rpy="0 0 0" />
      <geometry>
        <box size="0.055 0.012 0.028" />
      </geometry>
    </visual>
    <visual name="accessory_tab_2">
      <origin xyz="0 0.305 0.176" rpy="0 0 0" />
      <geometry>
        <box size="0.055 0.012 0.028" />
      </geometry>
    </visual>
    <visual name="carry_handle">
      <geometry>
        <mesh filename="meshes/lamp_handle.glb" />
      </geometry>
    </visual>
    <collision name="lamp__tilt_axle">
      <origin xyz="0 0 0" rpy="0 1.5708 0" />
      <geometry>
        <cylinder radius="0.015" length="0.23" />
      </geometry>
    </collision>
    <collision name="lamp__tilt_knob_l">
      <origin xyz="-0.127 0 0" rpy="0 1.5708 0" />
      <geometry>
        <cylinder radius="0.036" length="0.024" />
      </geometry>
    </collision>
    <collision name="lamp__tilt_knob_r">
      <origin xyz="0.127 0 0" rpy="0 1.5708 0" />
      <geometry>
        <cylinder radius="0.036" length="0.024" />
      </geometry>
    </collision>
    <collision name="lamp__rear_body">
      <origin xyz="0 0.1 0.06" rpy="0 0 0" />
      <geometry>
        <box size="0.2 0.08 0.18" />
      </geometry>
    </collision>
    <collision name="lamp__trunnion_core">
      <origin xyz="0 0.05 0.045" rpy="0 0 0" />
      <geometry>
        <box size="0.15 0.09 0.12" />
      </geometry>
    </collision>
    <collision name="lamp__main_drum">
      <origin xyz="0 0.19 0.08" rpy="1.5708 0 0" />
      <geometry>
        <cylinder radius="0.13" length="0.2" />
      </geometry>
    </collision>
    <collision name="lamp__front_bezel">
      <origin xyz="0 0.3 0.08" rpy="1.5708 0 0" />
      <geometry>
        <cylinder radius="0.145" length="0.03" />
      </geometry>
    </collision>
    <collision name="lamp__lens_tube">
      <origin xyz="0 0.255 0.08" rpy="1.5708 0 0" />
      <geometry>
        <cylinder radius="0.102" length="0.06" />
      </geometry>
    </collision>
    <collision name="lamp__front_lens">
      <origin xyz="0 0.287 0.08" rpy="1.5708 0 0" />
      <geometry>
        <cylinder radius="0.122" length="0.008" />
      </geometry>
    </collision>
    <collision name="lamp__driver_housing">
      <origin xyz="0 0.165 0.165" rpy="0 0 0" />
      <geometry>
        <box size="0.18 0.11 0.08" />
      </geometry>
    </collision>
    <collision name="lamp__lower_chin">
      <origin xyz="0 0.155 -0.025" rpy="0 0 0" />
      <geometry>
        <box size="0.18 0.09 0.05" />
      </geometry>
    </collision>
    <collision name="lamp__cooling_fin_1">
      <origin xyz="0 0.105 0.222" rpy="0 0 0" />
      <geometry>
        <box size="0.15 0.014 0.06" />
      </geometry>
    </collision>
    <collision name="lamp__cooling_fin_2">
      <origin xyz="0 0.13 0.222" rpy="0 0 0" />
      <geometry>
        <box size="0.15 0.014 0.06" />
      </geometry>
    </collision>
    <collision name="lamp__cooling_fin_3">
      <origin xyz="0 0.155 0.222" rpy="0 0 0" />
      <geometry>
        <box size="0.15 0.014 0.06" />
      </geometry>
    </collision>
    <collision name="lamp__cooling_fin_4">
      <origin xyz="0 0.18 0.222" rpy="0 0 0" />
      <geometry>
        <box size="0.15 0.014 0.06" />
      </geometry>
    </collision>
    <collision name="lamp__cooling_fin_5">
      <origin xyz="0 0.205 0.222" rpy="0 0 0" />
      <geometry>
        <box size="0.15 0.014 0.06" />
      </geometry>
    </collision>
    <collision name="lamp__side_cheek_l">
      <origin xyz="-0.1 0.09 0.075" rpy="0 0 0" />
      <geometry>
        <box size="0.022 0.14 0.13" />
      </geometry>
    </collision>
    <collision name="lamp__side_cheek_r">
      <origin xyz="0.1 0.09 0.075" rpy="0 0 0" />
      <geometry>
        <box size="0.022 0.14 0.13" />
      </geometry>
    </collision>
    <collision name="lamp__accessory_tab_1">
      <origin xyz="0 0.305 -0.05" rpy="0 0 0" />
      <geometry>
        <box size="0.055 0.012 0.028" />
      </geometry>
    </collision>
    <collision name="lamp__accessory_tab_2">
      <origin xyz="0 0.305 0.176" rpy="0 0 0" />
      <geometry>
        <box size="0.055 0.012 0.028" />
      </geometry>
    </collision>
    <collision name="lamp__carry_handle__hull_001">
      <geometry>
        <mesh filename="meshes/collision/cache/d42eedbc9567bdf8d83b6e36__hull_001.obj" />
      </geometry>
    </collision>
    <collision name="lamp__carry_handle__hull_002">
      <geometry>
        <mesh filename="meshes/collision/cache/d42eedbc9567bdf8d83b6e36__hull_002.obj" />
      </geometry>
    </collision>
    <collision name="lamp__carry_handle__hull_003">
      <geometry>
        <mesh filename="meshes/collision/cache/d42eedbc9567bdf8d83b6e36__hull_003.obj" />
      </geometry>
    </collision>
    <collision name="lamp__carry_handle__hull_004">
      <geometry>
        <mesh filename="meshes/collision/cache/d42eedbc9567bdf8d83b6e36__hull_004.obj" />
      </geometry>
    </collision>
  </link>
  <joint name="stand_pan" type="revolute">
    <origin xyz="0 0 0.89" rpy="0 0 0" />
    <parent link="stand" />
    <child link="yoke" />
    <axis xyz="0 0 1" />
    <limit effort="40" velocity="1.5" lower="-1.9" upper="1.9" />
  </joint>
  <joint name="yoke_tilt" type="revolute">
    <origin xyz="0 0.11 -0.125" rpy="0 0 0" />
    <parent link="yoke" />
    <child link="lamp" />
    <axis xyz="1 0 0" />
    <limit effort="22" velocity="1.8" lower="-1.05" upper="0.65" />
  </joint>
</robot>