<robot name="fidget_spinner">
  <material name="frame_black">
    <color rgba="0.11 0.12 0.14 1" />
    </material>
  <material name="satin_graphite">
    <color rgba="0.19 0.2 0.22 1" />
    </material>
  <material name="brushed_steel">
    <color rgba="0.73 0.74 0.77 1" />
    </material>
  <link name="hub">
    <inertial>
      <mass value="0.028" />
      <inertia ixx="1.33819e-06" ixy="0" ixz="0" iyy="1.33819e-06" iyz="0" izz="1.78766e-06" />
      </inertial>
    <visual>
      <geometry>
        <mesh filename="meshes/hub.obj" />
        </geometry>
      <material name="satin_graphite" />
      </visual>
    <collision name="hub__visual_1__hull_001">
      <geometry>
        <mesh filename="meshes/collision/cache/hub__981faa83dab69fb6__hull_001.obj" />
        </geometry>
      </collision>
    <collision name="hub__visual_1__hull_002">
      <geometry>
        <mesh filename="meshes/collision/cache/hub__981faa83dab69fb6__hull_002.obj" />
        </geometry>
      </collision>
    <collision name="hub__visual_1__hull_003">
      <geometry>
        <mesh filename="meshes/collision/cache/hub__981faa83dab69fb6__hull_003.obj" />
        </geometry>
      </collision>
    <collision name="hub__visual_1__hull_004">
      <geometry>
        <mesh filename="meshes/collision/cache/hub__981faa83dab69fb6__hull_004.obj" />
        </geometry>
      </collision>
    <collision name="hub__visual_1__hull_005">
      <geometry>
        <mesh filename="meshes/collision/cache/hub__981faa83dab69fb6__hull_005.obj" />
        </geometry>
      </collision>
    </link>
  <link name="spinner">
    <inertial>
      <mass value="0.112" />
      <inertia ixx="5.47191e-05" ixy="0" ixz="0" iyy="5.47191e-05" iyz="0" izz="0.000108416" />
      </inertial>
    <visual>
      <geometry>
        <mesh filename="meshes/spinner_frame.obj" />
        </geometry>
      <material name="frame_black" />
      </visual>
    <visual>
      <geometry>
        <mesh filename="meshes/spinner_accents.obj" />
        </geometry>
      <material name="brushed_steel" />
      </visual>
    <collision name="spinner__visual_1__hull_001">
      <geometry>
        <mesh filename="meshes/collision/cache/spinner_frame__7d791e404a91db62__hull_001.obj" />
        </geometry>
      </collision>
    <collision name="spinner__visual_1__hull_002">
      <geometry>
        <mesh filename="meshes/collision/cache/spinner_frame__7d791e404a91db62__hull_002.obj" />
        </geometry>
      </collision>
    <collision name="spinner__visual_1__hull_003">
      <geometry>
        <mesh filename="meshes/collision/cache/spinner_frame__7d791e404a91db62__hull_003.obj" />
        </geometry>
      </collision>
    <collision name="spinner__visual_1__hull_004">
      <geometry>
        <mesh filename="meshes/collision/cache/spinner_frame__7d791e404a91db62__hull_004.obj" />
        </geometry>
      </collision>
    <collision name="spinner__visual_1__hull_005">
      <geometry>
        <mesh filename="meshes/collision/cache/spinner_frame__7d791e404a91db62__hull_005.obj" />
        </geometry>
      </collision>
    <collision name="spinner__visual_1__hull_006">
      <geometry>
        <mesh filename="meshes/collision/cache/spinner_frame__7d791e404a91db62__hull_006.obj" />
        </geometry>
      </collision>
    <collision name="spinner__visual_1__hull_007">
      <geometry>
        <mesh filename="meshes/collision/cache/spinner_frame__7d791e404a91db62__hull_007.obj" />
        </geometry>
      </collision>
    <collision name="spinner__visual_1__hull_008">
      <geometry>
        <mesh filename="meshes/collision/cache/spinner_frame__7d791e404a91db62__hull_008.obj" />
        </geometry>
      </collision>
    <collision name="spinner__visual_1__hull_009">
      <geometry>
        <mesh filename="meshes/collision/cache/spinner_frame__7d791e404a91db62__hull_009.obj" />
        </geometry>
      </collision>
    <collision name="spinner__visual_1__hull_010">
      <geometry>
        <mesh filename="meshes/collision/cache/spinner_frame__7d791e404a91db62__hull_010.obj" />
        </geometry>
      </collision>
    <collision name="spinner__visual_1__hull_011">
      <geometry>
        <mesh filename="meshes/collision/cache/spinner_frame__7d791e404a91db62__hull_011.obj" />
        </geometry>
      </collision>
    <collision name="spinner__visual_1__hull_012">
      <geometry>
        <mesh filename="meshes/collision/cache/spinner_frame__7d791e404a91db62__hull_012.obj" />
        </geometry>
      </collision>
    <collision name="spinner__visual_1__hull_013">
      <geometry>
        <mesh filename="meshes/collision/cache/spinner_frame__7d791e404a91db62__hull_013.obj" />
        </geometry>
      </collision>
    <collision name="spinner__visual_1__hull_014">
      <geometry>
        <mesh filename="meshes/collision/cache/spinner_frame__7d791e404a91db62__hull_014.obj" />
        </geometry>
      </collision>
    <collision name="spinner__visual_1__hull_015">
      <geometry>
        <mesh filename="meshes/collision/cache/spinner_frame__7d791e404a91db62__hull_015.obj" />
        </geometry>
      </collision>
    <collision name="spinner__visual_1__hull_016">
      <geometry>
        <mesh filename="meshes/collision/cache/spinner_frame__7d791e404a91db62__hull_016.obj" />
        </geometry>
      </collision>
    <collision name="spinner__visual_2__hull_001">
      <geometry>
        <mesh filename="meshes/collision/cache/spinner_accents__c158a68188156a94__hull_001.obj" />
        </geometry>
      </collision>
    <collision name="spinner__visual_2__hull_002">
      <geometry>
        <mesh filename="meshes/collision/cache/spinner_accents__c158a68188156a94__hull_002.obj" />
        </geometry>
      </collision>
    <collision name="spinner__visual_2__hull_003">
      <geometry>
        <mesh filename="meshes/collision/cache/spinner_accents__c158a68188156a94__hull_003.obj" />
        </geometry>
      </collision>
    <collision name="spinner__visual_2__hull_004">
      <geometry>
        <mesh filename="meshes/collision/cache/spinner_accents__c158a68188156a94__hull_004.obj" />
        </geometry>
      </collision>
    <collision name="spinner__visual_2__hull_005">
      <geometry>
        <mesh filename="meshes/collision/cache/spinner_accents__c158a68188156a94__hull_005.obj" />
        </geometry>
      </collision>
    <collision name="spinner__visual_2__hull_006">
      <geometry>
        <mesh filename="meshes/collision/cache/spinner_accents__c158a68188156a94__hull_006.obj" />
        </geometry>
      </collision>
    <collision name="spinner__visual_2__hull_007">
      <geometry>
        <mesh filename="meshes/collision/cache/spinner_accents__c158a68188156a94__hull_007.obj" />
        </geometry>
      </collision>
    <collision name="spinner__visual_2__hull_008">
      <geometry>
        <mesh filename="meshes/collision/cache/spinner_accents__c158a68188156a94__hull_008.obj" />
        </geometry>
      </collision>
    <collision name="spinner__visual_2__hull_009">
      <geometry>
        <mesh filename="meshes/collision/cache/spinner_accents__c158a68188156a94__hull_009.obj" />
        </geometry>
      </collision>
    <collision name="spinner__visual_2__hull_010">
      <geometry>
        <mesh filename="meshes/collision/cache/spinner_accents__c158a68188156a94__hull_010.obj" />
        </geometry>
      </collision>
    <collision name="spinner__visual_2__hull_011">
      <geometry>
        <mesh filename="meshes/collision/cache/spinner_accents__c158a68188156a94__hull_011.obj" />
        </geometry>
      </collision>
    <collision name="spinner__visual_2__hull_012">
      <geometry>
        <mesh filename="meshes/collision/cache/spinner_accents__c158a68188156a94__hull_012.obj" />
        </geometry>
      </collision>
    <collision name="spinner__visual_2__hull_013">
      <geometry>
        <mesh filename="meshes/collision/cache/spinner_accents__c158a68188156a94__hull_013.obj" />
        </geometry>
      </collision>
    <collision name="spinner__visual_2__hull_014">
      <geometry>
        <mesh filename="meshes/collision/cache/spinner_accents__c158a68188156a94__hull_014.obj" />
        </geometry>
      </collision>
    <collision name="spinner__visual_2__hull_015">
      <geometry>
        <mesh filename="meshes/collision/cache/spinner_accents__c158a68188156a94__hull_015.obj" />
        </geometry>
      </collision>
    <collision name="spinner__visual_2__hull_016">
      <geometry>
        <mesh filename="meshes/collision/cache/spinner_accents__c158a68188156a94__hull_016.obj" />
        </geometry>
      </collision>
    </link>
  <joint name="hub_to_spinner" type="continuous">
    <parent link="hub" />
    <child link="spinner" />
    <axis xyz="0 0 1" />
    <limit effort="0.2" velocity="60" />
    </joint>
  </robot>
