<robot name="dual_rail_gantry_axis">
  <material name="anodized_black">
    <color rgba="0.15 0.16 0.18 1" />
    </material>
  <material name="rail_steel">
    <color rgba="0.74 0.76 0.79 1" />
    </material>
  <material name="carriage_silver">
    <color rgba="0.84 0.86 0.89 1" />
    </material>
  <material name="block_graphite">
    <color rgba="0.24 0.25 0.28 1" />
    </material>
  <material name="accent_blue">
    <color rgba="0.22 0.33 0.54 1" />
    </material>
  <link name="base">
    <inertial>
      <origin xyz="0 0 0.02" rpy="0 0 0" />
      <mass value="10.5" />
      <inertia ixx="0.0329875" ixy="0" ixz="0" iyy="0.29575" iyz="0" izz="0.325937" />
      </inertial>
    <visual>
      <origin xyz="0 0 0.008" rpy="0 0 0" />
      <geometry>
        <box size="0.58 0.19 0.016" />
        </geometry>
      <material name="anodized_black" />
      </visual>
    <visual>
      <origin xyz="0 0 0.024" rpy="0 0 0" />
      <geometry>
        <box size="0.48 0.032 0.016" />
        </geometry>
      <material name="anodized_black" />
      </visual>
    <visual>
      <origin xyz="0 0.06 0.023" rpy="0 0 0" />
      <geometry>
        <box size="0.52 0.028 0.014" />
        </geometry>
      <material name="anodized_black" />
      </visual>
    <visual>
      <origin xyz="0 -0.06 0.023" rpy="0 0 0" />
      <geometry>
        <box size="0.52 0.028 0.014" />
        </geometry>
      <material name="anodized_black" />
      </visual>
    <visual>
      <origin xyz="0 0.06 0.035" rpy="0 0 0" />
      <geometry>
        <box size="0.5 0.015 0.01" />
        </geometry>
      <material name="rail_steel" />
      </visual>
    <visual>
      <origin xyz="0 -0.06 0.035" rpy="0 0 0" />
      <geometry>
        <box size="0.5 0.015 0.01" />
        </geometry>
      <material name="rail_steel" />
      </visual>
    <visual>
      <origin xyz="0.274 0 0.015" rpy="0 0 0" />
      <geometry>
        <box size="0.032 0.16 0.03" />
        </geometry>
      <material name="accent_blue" />
      </visual>
    <visual>
      <origin xyz="-0.274 0 0.015" rpy="0 0 0" />
      <geometry>
        <box size="0.032 0.16 0.03" />
        </geometry>
      <material name="accent_blue" />
      </visual>
    <visual>
      <origin xyz="0 0.083 0.022" rpy="0 0 0" />
      <geometry>
        <box size="0.5 0.014 0.012" />
        </geometry>
      <material name="anodized_black" />
      </visual>
    <visual>
      <origin xyz="0 -0.083 0.022" rpy="0 0 0" />
      <geometry>
        <box size="0.5 0.014 0.012" />
        </geometry>
      <material name="anodized_black" />
      </visual>
    </link>
  <link name="carriage">
    <inertial>
      <origin xyz="0 0 0.0275" rpy="0 0 0" />
      <mass value="2.8" />
      <inertia ixx="0.00760877" ixy="0" ixz="0" iyy="0.00561167" iyz="0" izz="0.0118088" />
      </inertial>
    <visual>
      <origin xyz="-0.036 0.06 0.0125" rpy="0 0 0" />
      <geometry>
        <box size="0.065 0.032 0.023" />
        </geometry>
      <material name="block_graphite" />
      </visual>
    <visual>
      <origin xyz="-0.036 -0.06 0.0125" rpy="0 0 0" />
      <geometry>
        <box size="0.065 0.032 0.023" />
        </geometry>
      <material name="block_graphite" />
      </visual>
    <visual>
      <origin xyz="0.036 0.06 0.0125" rpy="0 0 0" />
      <geometry>
        <box size="0.065 0.032 0.023" />
        </geometry>
      <material name="block_graphite" />
      </visual>
    <visual>
      <origin xyz="0.036 -0.06 0.0125" rpy="0 0 0" />
      <geometry>
        <box size="0.065 0.032 0.023" />
        </geometry>
      <material name="block_graphite" />
      </visual>
    <visual>
      <origin xyz="0 0.06 0.024" rpy="0 0 0" />
      <geometry>
        <box size="0.145 0.02 0.012" />
        </geometry>
      <material name="carriage_silver" />
      </visual>
    <visual>
      <origin xyz="0 -0.06 0.024" rpy="0 0 0" />
      <geometry>
        <box size="0.145 0.02 0.012" />
        </geometry>
      <material name="carriage_silver" />
      </visual>
    <visual>
      <origin xyz="0 0 0.0125" rpy="0 0 0" />
      <geometry>
        <box size="0.112 0.03 0.025" />
        </geometry>
      <material name="carriage_silver" />
      </visual>
    <visual>
      <origin xyz="0 0 0.032" rpy="0 0 0" />
      <geometry>
        <box size="0.145 0.172 0.014" />
        </geometry>
      <material name="carriage_silver" />
      </visual>
    <visual>
      <origin xyz="0 0 0.047" rpy="0 0 0" />
      <geometry>
        <box size="0.09 0.11 0.016" />
        </geometry>
      <material name="accent_blue" />
      </visual>
    <visual>
      <origin xyz="0.052 0 0.053" rpy="0 0 0" />
      <geometry>
        <box size="0.014 0.1 0.028" />
        </geometry>
      <material name="carriage_silver" />
      </visual>
    <visual>
      <origin xyz="-0.052 0 0.053" rpy="0 0 0" />
      <geometry>
        <box size="0.014 0.1 0.028" />
        </geometry>
      <material name="carriage_silver" />
      </visual>
    </link>
  <joint name="gantry_slide" type="prismatic">
    <origin xyz="0 0 0.041" rpy="0 0 0" />
    <parent link="base" />
    <child link="carriage" />
    <axis xyz="1 0 0" />
    <limit effort="250" velocity="1" lower="-0.2" upper="0.2" />
    </joint>
  </robot>
