<robot name="microwave_oven">
  <material name="stainless">
    <color rgba="0.74 0.75 0.77 1" />
    </material>
  <material name="black_glass">
    <color rgba="0.08 0.09 0.1 1" />
    </material>
  <material name="smoked_glass">
    <color rgba="0.22 0.25 0.28 0.32" />
    </material>
  <material name="charcoal">
    <color rgba="0.18 0.19 0.21 1" />
    </material>
  <material name="graphite">
    <color rgba="0.28 0.29 0.31 1" />
    </material>
  <material name="aluminum">
    <color rgba="0.84 0.85 0.86 1" />
    </material>
  <material name="rubber">
    <color rgba="0.06 0.06 0.06 1" />
    </material>
  <link name="body_shell">
    <inertial>
      <origin xyz="0 0 0.145" rpy="0 0 0" />
      <mass value="8.8" />
      <inertia ixx="0.173213" ixy="0" ixz="0" iyy="0.237747" iyz="0" izz="0.287613" />
      </inertial>
    <visual name="bottom_panel">
      <origin xyz="0 0 0.014" rpy="0 0 0" />
      <geometry>
        <box size="0.49 0.39 0.012" />
        </geometry>
      <material name="stainless">
        <color rgba="0.74 0.75 0.77 1" />
        </material>
      </visual>
    <visual name="top_panel">
      <origin xyz="0 0 0.284" rpy="0 0 0" />
      <geometry>
        <box size="0.49 0.39 0.012" />
        </geometry>
      <material name="stainless">
        <color rgba="0.74 0.75 0.77 1" />
        </material>
      </visual>
    <visual name="left_shell">
      <origin xyz="-0.239 0 0.152" rpy="0 0 0" />
      <geometry>
        <box size="0.012 0.39 0.264" />
        </geometry>
      <material name="stainless">
        <color rgba="0.74 0.75 0.77 1" />
        </material>
      </visual>
    <visual name="right_shell">
      <origin xyz="0.239 0 0.152" rpy="0 0 0" />
      <geometry>
        <box size="0.012 0.39 0.264" />
        </geometry>
      <material name="stainless">
        <color rgba="0.74 0.75 0.77 1" />
        </material>
      </visual>
    <visual name="rear_shell">
      <origin xyz="0 -0.189 0.152" rpy="0 0 0" />
      <geometry>
        <box size="0.466 0.012 0.264" />
        </geometry>
      <material name="stainless">
        <color rgba="0.74 0.75 0.77 1" />
        </material>
      </visual>
    <visual name="front_bezel_bottom">
      <origin xyz="-0.044 0.191 0.016" rpy="0 0 0" />
      <geometry>
        <box size="0.378 0.008 0.01" />
        </geometry>
      <material name="charcoal">
        <color rgba="0.18 0.19 0.21 1" />
        </material>
      </visual>
    <visual name="front_bezel_top">
      <origin xyz="-0.044 0.191 0.274" rpy="0 0 0" />
      <geometry>
        <box size="0.378 0.008 0.01" />
        </geometry>
      <material name="charcoal">
        <color rgba="0.18 0.19 0.21 1" />
        </material>
      </visual>
    <visual name="front_bezel_right">
      <origin xyz="0.139 0.191 0.145" rpy="0 0 0" />
      <geometry>
        <box size="0.01 0.008 0.248" />
        </geometry>
      <material name="charcoal">
        <color rgba="0.18 0.19 0.21 1" />
        </material>
      </visual>
    <visual name="foot_l_b">
      <origin xyz="-0.195 -0.145 0.004" rpy="0 0 0" />
      <geometry>
        <box size="0.03 0.018 0.008" />
        </geometry>
      <material name="rubber">
        <color rgba="0.06 0.06 0.06 1" />
        </material>
      </visual>
    <visual name="foot_l_f">
      <origin xyz="-0.195 0.145 0.004" rpy="0 0 0" />
      <geometry>
        <box size="0.03 0.018 0.008" />
        </geometry>
      <material name="rubber">
        <color rgba="0.06 0.06 0.06 1" />
        </material>
      </visual>
    <visual name="foot_r_b">
      <origin xyz="0.195 -0.145 0.004" rpy="0 0 0" />
      <geometry>
        <box size="0.03 0.018 0.008" />
        </geometry>
      <material name="rubber">
        <color rgba="0.06 0.06 0.06 1" />
        </material>
      </visual>
    <visual name="foot_r_f">
      <origin xyz="0.195 0.145 0.004" rpy="0 0 0" />
      <geometry>
        <box size="0.03 0.018 0.008" />
        </geometry>
      <material name="rubber">
        <color rgba="0.06 0.06 0.06 1" />
        </material>
      </visual>
    <visual name="rear_vent">
      <origin xyz="0.01 -0.1965 0.205" rpy="1.5708 0 0" />
      <geometry>
        <mesh filename="assets/meshes/microwave_rear_vent.obj" />
        </geometry>
      <material name="charcoal">
        <color rgba="0.18 0.19 0.21 1" />
        </material>
      </visual>
    </link>
  <link name="cavity_liner">
    <inertial>
      <origin xyz="0.182 0 -0.005" rpy="0 0 0" />
      <mass value="1" />
      <inertia ixx="0.0140104" ixy="0" ixz="0" iyy="0.0158887" iyz="0" izz="0.0194824" />
      </inertial>
    <visual name="floor">
      <origin xyz="0.182 0 -0.112" rpy="0 0 0" />
      <geometry>
        <box size="0.358 0.325 0.006" />
        </geometry>
      <material name="charcoal">
        <color rgba="0.18 0.19 0.21 1" />
        </material>
      </visual>
    <visual name="ceiling">
      <origin xyz="0.182 0 0.112" rpy="0 0 0" />
      <geometry>
        <box size="0.358 0.325 0.006" />
        </geometry>
      <material name="charcoal">
        <color rgba="0.18 0.19 0.21 1" />
        </material>
      </visual>
    <visual name="left_wall">
      <origin xyz="0.003 0 0" rpy="0 0 0" />
      <geometry>
        <box size="0.006 0.325 0.228" />
        </geometry>
      <material name="charcoal">
        <color rgba="0.18 0.19 0.21 1" />
        </material>
      </visual>
    <visual name="right_wall">
      <origin xyz="0.361 0 0" rpy="0 0 0" />
      <geometry>
        <box size="0.006 0.325 0.228" />
        </geometry>
      <material name="charcoal">
        <color rgba="0.18 0.19 0.21 1" />
        </material>
      </visual>
    <visual name="back_wall">
      <origin xyz="0.182 -0.159 0" rpy="0 0 0" />
      <geometry>
        <box size="0.358 0.006 0.228" />
        </geometry>
      <material name="charcoal">
        <color rgba="0.18 0.19 0.21 1" />
        </material>
      </visual>
    <visual name="waveguide_cover">
      <origin xyz="0.343 -0.05 0.07" rpy="0 0 0" />
      <geometry>
        <box size="0.04 0.004 0.032" />
        </geometry>
      <material name="black_glass">
        <color rgba="0.08 0.09 0.1 1" />
        </material>
      </visual>
    </link>
  <link name="turntable">
    <inertial>
      <origin xyz="0 0 0.006" rpy="0 0 0" />
      <mass value="0.45" />
      <inertia ixx="0.00202065" ixy="0" ixz="0" iyy="0.00202065" iyz="0" izz="0.0040401" />
      </inertial>
    <visual name="glass_plate">
      <origin xyz="0 0 0.006" rpy="0 0 0" />
      <geometry>
        <cylinder radius="0.134" length="0.004" />
        </geometry>
      <material name="smoked_glass">
        <color rgba="0.22 0.25 0.28 0.32" />
        </material>
      </visual>
    <visual name="hub">
      <origin xyz="0 0 0.002" rpy="0 0 0" />
      <geometry>
        <cylinder radius="0.014" length="0.004" />
        </geometry>
      <material name="aluminum">
        <color rgba="0.84 0.85 0.86 1" />
        </material>
      </visual>
    </link>
  <link name="control_panel">
    <inertial>
      <origin xyz="-0.042 0.01 0" rpy="0 0 0" />
      <mass value="0.7" />
      <inertia ixx="0.0039354" ixy="0" ixz="0" iyy="0.0042945" iyz="0" izz="0.0004641" />
      </inertial>
    <visual name="panel_face">
      <origin xyz="-0.042 0 0" rpy="0 0 0" />
      <geometry>
        <box size="0.084 0.008 0.258" />
        </geometry>
      <material name="charcoal">
        <color rgba="0.18 0.19 0.21 1" />
        </material>
      </visual>
    <visual name="display_trim">
      <origin xyz="-0.042 0.005 0.085" rpy="0 0 0" />
      <geometry>
        <box size="0.068 0.002 0.036" />
        </geometry>
      <material name="aluminum">
        <color rgba="0.84 0.85 0.86 1" />
        </material>
      </visual>
    <visual name="display_lens">
      <origin xyz="-0.042 0.006 0.085" rpy="0 0 0" />
      <geometry>
        <box size="0.056 0.004 0.024" />
        </geometry>
      <material name="black_glass">
        <color rgba="0.08 0.09 0.1 1" />
        </material>
      </visual>
    <visual name="button_1">
      <origin xyz="-0.064 0.006 0.03" rpy="0 0 0" />
      <geometry>
        <box size="0.018 0.004 0.012" />
        </geometry>
      <material name="aluminum">
        <color rgba="0.84 0.85 0.86 1" />
        </material>
      </visual>
    <visual name="button_2">
      <origin xyz="-0.042 0.006 0.03" rpy="0 0 0" />
      <geometry>
        <box size="0.018 0.004 0.012" />
        </geometry>
      <material name="aluminum">
        <color rgba="0.84 0.85 0.86 1" />
        </material>
      </visual>
    <visual name="button_3">
      <origin xyz="-0.02 0.006 0.03" rpy="0 0 0" />
      <geometry>
        <box size="0.018 0.004 0.012" />
        </geometry>
      <material name="aluminum">
        <color rgba="0.84 0.85 0.86 1" />
        </material>
      </visual>
    <visual name="brand_badge">
      <origin xyz="-0.042 0.005 -0.074" rpy="0 0 0" />
      <geometry>
        <box size="0.06 0.002 0.018" />
        </geometry>
      <material name="aluminum">
        <color rgba="0.84 0.85 0.86 1" />
        </material>
      </visual>
    </link>
  <link name="door">
    <inertial>
      <origin xyz="0.182 0.017 0" rpy="0 0 0" />
      <mass value="2.1" />
      <inertia ixx="0.0104279" ixy="0" ixz="0" iyy="0.0331814" iyz="0" izz="0.0231119" />
      </inertial>
    <visual name="frame_left">
      <origin xyz="0.027 0.017 0" rpy="0 0 0" />
      <geometry>
        <box size="0.05 0.032 0.242" />
        </geometry>
      <material name="black_glass">
        <color rgba="0.08 0.09 0.1 1" />
        </material>
      </visual>
    <visual name="frame_right">
      <origin xyz="0.337 0.017 0" rpy="0 0 0" />
      <geometry>
        <box size="0.05 0.032 0.242" />
        </geometry>
      <material name="black_glass">
        <color rgba="0.08 0.09 0.1 1" />
        </material>
      </visual>
    <visual name="frame_top">
      <origin xyz="0.182 0.017 0.1" rpy="0 0 0" />
      <geometry>
        <box size="0.29 0.032 0.042" />
        </geometry>
      <material name="black_glass">
        <color rgba="0.08 0.09 0.1 1" />
        </material>
      </visual>
    <visual name="frame_bottom">
      <origin xyz="0.182 0.017 -0.1" rpy="0 0 0" />
      <geometry>
        <box size="0.29 0.032 0.042" />
        </geometry>
      <material name="black_glass">
        <color rgba="0.08 0.09 0.1 1" />
        </material>
      </visual>
    <visual name="window">
      <origin xyz="0.182 0.01 0" rpy="0 0 0" />
      <geometry>
        <box size="0.252 0.004 0.158" />
        </geometry>
      <material name="smoked_glass">
        <color rgba="0.22 0.25 0.28 0.32" />
        </material>
      </visual>
    <visual name="handle_mount_top">
      <origin xyz="0.315 0.035 0.078" rpy="0 0 0" />
      <geometry>
        <box size="0.024 0.01 0.022" />
        </geometry>
      <material name="aluminum">
        <color rgba="0.84 0.85 0.86 1" />
        </material>
      </visual>
    <visual name="handle_mount_bottom">
      <origin xyz="0.315 0.035 -0.078" rpy="0 0 0" />
      <geometry>
        <box size="0.024 0.01 0.022" />
        </geometry>
      <material name="aluminum">
        <color rgba="0.84 0.85 0.86 1" />
        </material>
      </visual>
    <visual name="handle">
      <geometry>
        <mesh filename="assets/meshes/microwave_door_handle.obj" />
        </geometry>
      <material name="aluminum">
        <color rgba="0.84 0.85 0.86 1" />
        </material>
      </visual>
    </link>
  <link name="upper_knob">
    <inertial>
      <origin xyz="0 0.014 0" rpy="0 0 0" />
      <mass value="0.08" />
      <inertia ixx="1.56267e-05" ixy="0" ixz="0" iyy="1.92533e-05" iyz="0" izz="1.56267e-05" />
      </inertial>
    <visual name="knob_body">
      <origin xyz="0 0.017 0" rpy="1.5708 0 0" />
      <geometry>
        <cylinder radius="0.019" length="0.025" />
        </geometry>
      <material name="graphite">
        <color rgba="0.28 0.29 0.31 1" />
        </material>
      </visual>
    <visual name="knob_cap">
      <origin xyz="0 0.03 0" rpy="1.5708 0 0" />
      <geometry>
        <cylinder radius="0.014" length="0.005" />
        </geometry>
      <material name="aluminum">
        <color rgba="0.84 0.85 0.86 1" />
        </material>
      </visual>
    <visual name="indicator">
      <origin xyz="0 0.0325 0.013" rpy="0 0 0" />
      <geometry>
        <box size="0.003 0.002 0.012" />
        </geometry>
      <material name="aluminum">
        <color rgba="0.84 0.85 0.86 1" />
        </material>
      </visual>
    </link>
  <link name="lower_knob">
    <inertial>
      <origin xyz="0 0.014 0" rpy="0 0 0" />
      <mass value="0.09" />
      <inertia ixx="1.998e-05" ixy="0" ixz="0" iyy="2.646e-05" iyz="0" izz="1.998e-05" />
      </inertial>
    <visual name="knob_body">
      <origin xyz="0 0.017 0" rpy="1.5708 0 0" />
      <geometry>
        <cylinder radius="0.021" length="0.025" />
        </geometry>
      <material name="graphite">
        <color rgba="0.28 0.29 0.31 1" />
        </material>
      </visual>
    <visual name="knob_cap">
      <origin xyz="0 0.03 0" rpy="1.5708 0 0" />
      <geometry>
        <cylinder radius="0.015" length="0.005" />
        </geometry>
      <material name="aluminum">
        <color rgba="0.84 0.85 0.86 1" />
        </material>
      </visual>
    <visual name="indicator">
      <origin xyz="0 0.0325 0.014" rpy="0 0 0" />
      <geometry>
        <box size="0.003 0.002 0.013" />
        </geometry>
      <material name="aluminum">
        <color rgba="0.84 0.85 0.86 1" />
        </material>
      </visual>
    </link>
  <joint name="cavity_mount" type="fixed">
    <origin xyz="-0.229 0 0.145" rpy="0 0 0" />
    <parent link="body_shell" />
    <child link="cavity_liner" />
    </joint>
  <joint name="turntable_mount" type="fixed">
    <origin xyz="0.182 0 -0.108" rpy="0 0 0" />
    <parent link="cavity_liner" />
    <child link="turntable" />
    </joint>
  <joint name="panel_mount" type="fixed">
    <origin xyz="0.233 0.191 0.145" rpy="0 0 0" />
    <parent link="body_shell" />
    <child link="control_panel" />
    </joint>
  <joint name="door_hinge" type="revolute">
    <origin xyz="-0.24 0.198 0.145" rpy="0 0 0" />
    <parent link="body_shell" />
    <child link="door" />
    <axis xyz="0 0 1" />
    <limit effort="18" velocity="1.8" lower="0" upper="1.6" />
    </joint>
  <joint name="upper_knob_joint" type="revolute">
    <origin xyz="-0.042 0.004 0.06" rpy="0 0 0" />
    <parent link="control_panel" />
    <child link="upper_knob" />
    <axis xyz="0 1 0" />
    <limit effort="1.2" velocity="5" lower="-0.7" upper="2.6" />
    </joint>
  <joint name="lower_knob_joint" type="revolute">
    <origin xyz="-0.042 0.004 -0.035" rpy="0 0 0" />
    <parent link="control_panel" />
    <child link="lower_knob" />
    <axis xyz="0 1 0" />
    <limit effort="1.5" velocity="5" lower="0" upper="5.5" />
    </joint>
  </robot>
