<robot name="passenger_elevator">
  <link name="shaft_frame">
    <inertial>
      <origin xyz="0 0 2.175" rpy="0 0 0" />
      <mass value="1800" />
      <inertia ixx="3468.75" ixy="0" ixz="0" iyy="3597.75" iyz="0" izz="1389.75" />
      </inertial>
    <visual>
      <origin xyz="0 0 0.06" rpy="0 0 0" />
      <geometry>
        <box size="2.25 2.05 0.12" />
        </geometry>
      </visual>
    <visual>
      <origin xyz="0 -0.975 2.175" rpy="0 0 0" />
      <geometry>
        <box size="2.25 0.1 4.35" />
        </geometry>
      </visual>
    <visual>
      <origin xyz="-1.075 0 2.175" rpy="0 0 0" />
      <geometry>
        <box size="0.1 2.05 4.35" />
        </geometry>
      </visual>
    <visual>
      <origin xyz="1.075 0 2.175" rpy="0 0 0" />
      <geometry>
        <box size="0.1 2.05 4.35" />
        </geometry>
      </visual>
    <visual>
      <origin xyz="0 0.955 0.14" rpy="0 0 0" />
      <geometry>
        <box size="1.95 0.14 0.04" />
        </geometry>
      </visual>
    <visual>
      <origin xyz="-0.9 0.955 1.395" rpy="0 0 0" />
      <geometry>
        <box size="0.25 0.14 2.55" />
        </geometry>
      </visual>
    <visual>
      <origin xyz="0.9 0.955 1.395" rpy="0 0 0" />
      <geometry>
        <box size="0.25 0.14 2.55" />
        </geometry>
      </visual>
    <visual>
      <origin xyz="0 0.955 2.75" rpy="0 0 0" />
      <geometry>
        <box size="1.95 0.14 0.16" />
        </geometry>
      </visual>
    <visual>
      <origin xyz="0 0.915 3.55" rpy="0 0 0" />
      <geometry>
        <box size="1.95 0.06 1.44" />
        </geometry>
      </visual>
    <visual>
      <origin xyz="-0.5 -0.93 2.12" rpy="0 0 0" />
      <geometry>
        <box size="0.04 0.03 4" />
        </geometry>
      </visual>
    <visual>
      <origin xyz="-0.5 -0.9 2.12" rpy="0 0 0" />
      <geometry>
        <box size="0.012 0.08 4" />
        </geometry>
      </visual>
    <visual>
      <origin xyz="-0.5 -0.9 0.32" rpy="0 0 0" />
      <geometry>
        <box size="0.08 0.1 0.06" />
        </geometry>
      </visual>
    <visual>
      <origin xyz="-0.5 -0.9 1.38" rpy="0 0 0" />
      <geometry>
        <box size="0.08 0.1 0.06" />
        </geometry>
      </visual>
    <visual>
      <origin xyz="-0.5 -0.9 2.44" rpy="0 0 0" />
      <geometry>
        <box size="0.08 0.1 0.06" />
        </geometry>
      </visual>
    <visual>
      <origin xyz="-0.5 -0.9 3.5" rpy="0 0 0" />
      <geometry>
        <box size="0.08 0.1 0.06" />
        </geometry>
      </visual>
    <visual>
      <origin xyz="0.5 -0.93 2.12" rpy="0 0 0" />
      <geometry>
        <box size="0.04 0.03 4" />
        </geometry>
      </visual>
    <visual>
      <origin xyz="0.5 -0.9 2.12" rpy="0 0 0" />
      <geometry>
        <box size="0.012 0.08 4" />
        </geometry>
      </visual>
    <visual>
      <origin xyz="0.5 -0.9 0.32" rpy="0 0 0" />
      <geometry>
        <box size="0.08 0.1 0.06" />
        </geometry>
      </visual>
    <visual>
      <origin xyz="0.5 -0.9 1.38" rpy="0 0 0" />
      <geometry>
        <box size="0.08 0.1 0.06" />
        </geometry>
      </visual>
    <visual>
      <origin xyz="0.5 -0.9 2.44" rpy="0 0 0" />
      <geometry>
        <box size="0.08 0.1 0.06" />
        </geometry>
      </visual>
    <visual>
      <origin xyz="0.5 -0.9 3.5" rpy="0 0 0" />
      <geometry>
        <box size="0.08 0.1 0.06" />
        </geometry>
      </visual>
    <visual>
      <origin xyz="0 -0.9 0.32" rpy="0 0 0" />
      <geometry>
        <box size="1.12 0.06 0.08" />
        </geometry>
      </visual>
    <visual>
      <origin xyz="0 -0.9 1.38" rpy="0 0 0" />
      <geometry>
        <box size="1.12 0.06 0.08" />
        </geometry>
      </visual>
    <visual>
      <origin xyz="0 -0.9 2.44" rpy="0 0 0" />
      <geometry>
        <box size="1.12 0.06 0.08" />
        </geometry>
      </visual>
    <visual>
      <origin xyz="0 -0.9 3.5" rpy="0 0 0" />
      <geometry>
        <box size="1.12 0.06 0.08" />
        </geometry>
      </visual>
    <visual>
      <origin xyz="0 -0.9 4.1" rpy="0 0 0" />
      <geometry>
        <box size="1.12 0.06 0.08" />
        </geometry>
      </visual>
    <visual>
      <origin xyz="0 0.1 0.09" rpy="0 0 0" />
      <geometry>
        <box size="0.2 0.2 0.06" />
        </geometry>
      </visual>
    <visual>
      <origin xyz="0.81 0.905 1.05" rpy="0 0 0" />
      <geometry>
        <box size="0.04 0.05 0.28" />
        </geometry>
      </visual>
    <visual>
      <origin xyz="0 0.915 2.93" rpy="0 0 0" />
      <geometry>
        <box size="0.28 0.05 0.1" />
        </geometry>
      </visual>
    <collision name="shaft_frame__visual_1">
      <origin xyz="0 0 0.06" rpy="0 0 0" />
      <geometry>
        <box size="2.25 2.05 0.12" />
        </geometry>
      </collision>
    <collision name="shaft_frame__visual_2">
      <origin xyz="0 -0.975 2.175" rpy="0 0 0" />
      <geometry>
        <box size="2.25 0.1 4.35" />
        </geometry>
      </collision>
    <collision name="shaft_frame__visual_3">
      <origin xyz="-1.075 0 2.175" rpy="0 0 0" />
      <geometry>
        <box size="0.1 2.05 4.35" />
        </geometry>
      </collision>
    <collision name="shaft_frame__visual_4">
      <origin xyz="1.075 0 2.175" rpy="0 0 0" />
      <geometry>
        <box size="0.1 2.05 4.35" />
        </geometry>
      </collision>
    <collision name="shaft_frame__visual_5">
      <origin xyz="0 0.955 0.14" rpy="0 0 0" />
      <geometry>
        <box size="1.95 0.14 0.04" />
        </geometry>
      </collision>
    <collision name="shaft_frame__visual_6">
      <origin xyz="-0.9 0.955 1.395" rpy="0 0 0" />
      <geometry>
        <box size="0.25 0.14 2.55" />
        </geometry>
      </collision>
    <collision name="shaft_frame__visual_7">
      <origin xyz="0.9 0.955 1.395" rpy="0 0 0" />
      <geometry>
        <box size="0.25 0.14 2.55" />
        </geometry>
      </collision>
    <collision name="shaft_frame__visual_8">
      <origin xyz="0 0.955 2.75" rpy="0 0 0" />
      <geometry>
        <box size="1.95 0.14 0.16" />
        </geometry>
      </collision>
    <collision name="shaft_frame__visual_9">
      <origin xyz="0 0.915 3.55" rpy="0 0 0" />
      <geometry>
        <box size="1.95 0.06 1.44" />
        </geometry>
      </collision>
    <collision name="shaft_frame__visual_10">
      <origin xyz="-0.5 -0.93 2.12" rpy="0 0 0" />
      <geometry>
        <box size="0.04 0.03 4" />
        </geometry>
      </collision>
    <collision name="shaft_frame__visual_11">
      <origin xyz="-0.5 -0.9 2.12" rpy="0 0 0" />
      <geometry>
        <box size="0.012 0.08 4" />
        </geometry>
      </collision>
    <collision name="shaft_frame__visual_12">
      <origin xyz="-0.5 -0.9 0.32" rpy="0 0 0" />
      <geometry>
        <box size="0.08 0.1 0.06" />
        </geometry>
      </collision>
    <collision name="shaft_frame__visual_13">
      <origin xyz="-0.5 -0.9 1.38" rpy="0 0 0" />
      <geometry>
        <box size="0.08 0.1 0.06" />
        </geometry>
      </collision>
    <collision name="shaft_frame__visual_14">
      <origin xyz="-0.5 -0.9 2.44" rpy="0 0 0" />
      <geometry>
        <box size="0.08 0.1 0.06" />
        </geometry>
      </collision>
    <collision name="shaft_frame__visual_15">
      <origin xyz="-0.5 -0.9 3.5" rpy="0 0 0" />
      <geometry>
        <box size="0.08 0.1 0.06" />
        </geometry>
      </collision>
    <collision name="shaft_frame__visual_16">
      <origin xyz="0.5 -0.93 2.12" rpy="0 0 0" />
      <geometry>
        <box size="0.04 0.03 4" />
        </geometry>
      </collision>
    <collision name="shaft_frame__visual_17">
      <origin xyz="0.5 -0.9 2.12" rpy="0 0 0" />
      <geometry>
        <box size="0.012 0.08 4" />
        </geometry>
      </collision>
    <collision name="shaft_frame__visual_18">
      <origin xyz="0.5 -0.9 0.32" rpy="0 0 0" />
      <geometry>
        <box size="0.08 0.1 0.06" />
        </geometry>
      </collision>
    <collision name="shaft_frame__visual_19">
      <origin xyz="0.5 -0.9 1.38" rpy="0 0 0" />
      <geometry>
        <box size="0.08 0.1 0.06" />
        </geometry>
      </collision>
    <collision name="shaft_frame__visual_20">
      <origin xyz="0.5 -0.9 2.44" rpy="0 0 0" />
      <geometry>
        <box size="0.08 0.1 0.06" />
        </geometry>
      </collision>
    <collision name="shaft_frame__visual_21">
      <origin xyz="0.5 -0.9 3.5" rpy="0 0 0" />
      <geometry>
        <box size="0.08 0.1 0.06" />
        </geometry>
      </collision>
    <collision name="shaft_frame__visual_22">
      <origin xyz="0 -0.9 0.32" rpy="0 0 0" />
      <geometry>
        <box size="1.12 0.06 0.08" />
        </geometry>
      </collision>
    <collision name="shaft_frame__visual_23">
      <origin xyz="0 -0.9 1.38" rpy="0 0 0" />
      <geometry>
        <box size="1.12 0.06 0.08" />
        </geometry>
      </collision>
    <collision name="shaft_frame__visual_24">
      <origin xyz="0 -0.9 2.44" rpy="0 0 0" />
      <geometry>
        <box size="1.12 0.06 0.08" />
        </geometry>
      </collision>
    <collision name="shaft_frame__visual_25">
      <origin xyz="0 -0.9 3.5" rpy="0 0 0" />
      <geometry>
        <box size="1.12 0.06 0.08" />
        </geometry>
      </collision>
    <collision name="shaft_frame__visual_26">
      <origin xyz="0 -0.9 4.1" rpy="0 0 0" />
      <geometry>
        <box size="1.12 0.06 0.08" />
        </geometry>
      </collision>
    <collision name="shaft_frame__visual_27">
      <origin xyz="0 0.1 0.09" rpy="0 0 0" />
      <geometry>
        <box size="0.2 0.2 0.06" />
        </geometry>
      </collision>
    <collision name="shaft_frame__visual_28">
      <origin xyz="0.81 0.905 1.05" rpy="0 0 0" />
      <geometry>
        <box size="0.04 0.05 0.28" />
        </geometry>
      </collision>
    <collision name="shaft_frame__visual_29">
      <origin xyz="0 0.915 2.93" rpy="0 0 0" />
      <geometry>
        <box size="0.28 0.05 0.1" />
        </geometry>
      </collision>
    </link>
  <link name="cab">
    <inertial>
      <origin xyz="0 0 1.18" rpy="0 0 0" />
      <mass value="950" />
      <inertia ixx="573.958" ixy="0" ixz="0" iyy="634.323" iyz="0" izz="370.698" />
      </inertial>
    <visual>
      <origin xyz="0 0 0.02" rpy="0 0 0" />
      <geometry>
        <box size="0.18 0.1 0.04" />
        </geometry>
      </visual>
    <visual>
      <origin xyz="0 0 0.06" rpy="0 0 0" />
      <geometry>
        <box size="1.55 1.3 0.06" />
        </geometry>
      </visual>
    <visual>
      <origin xyz="0 -0.63 1.18" rpy="0 0 0" />
      <geometry>
        <box size="1.55 0.04 2.18" />
        </geometry>
      </visual>
    <visual>
      <origin xyz="-0.755 0 1.18" rpy="0 0 0" />
      <geometry>
        <box size="0.04 1.26 2.18" />
        </geometry>
      </visual>
    <visual>
      <origin xyz="0.755 0 1.18" rpy="0 0 0" />
      <geometry>
        <box size="0.04 1.26 2.18" />
        </geometry>
      </visual>
    <visual>
      <origin xyz="0 0 2.34" rpy="0 0 0" />
      <geometry>
        <box size="1.55 1.3 0.04" />
        </geometry>
      </visual>
    <visual>
      <origin xyz="0 0.62 0.07" rpy="0 0 0" />
      <geometry>
        <box size="1.55 0.08 0.02" />
        </geometry>
      </visual>
    <visual>
      <origin xyz="-0.72 0.62 1.18" rpy="0 0 0" />
      <geometry>
        <box size="0.08 0.08 2.18" />
        </geometry>
      </visual>
    <visual>
      <origin xyz="0.72 0.62 1.18" rpy="0 0 0" />
      <geometry>
        <box size="0.08 0.08 2.18" />
        </geometry>
      </visual>
    <visual>
      <origin xyz="0 0.62 2.31" rpy="0 0 0" />
      <geometry>
        <box size="1.55 0.08 0.1" />
        </geometry>
      </visual>
    <visual>
      <origin xyz="0 0.675 2.245" rpy="0 0 0" />
      <geometry>
        <box size="1.12 0.05 0.03" />
        </geometry>
      </visual>
    <visual>
      <origin xyz="-0.275 0.66 2.22" rpy="0 0 0" />
      <geometry>
        <box size="0.12 0.02 0.02" />
        </geometry>
      </visual>
    <visual>
      <origin xyz="0.275 0.66 2.22" rpy="0 0 0" />
      <geometry>
        <box size="0.12 0.02 0.02" />
        </geometry>
      </visual>
    <visual>
      <origin xyz="0 -0.6 0.16" rpy="0 0 0" />
      <geometry>
        <box size="1.18 0.08 0.1" />
        </geometry>
      </visual>
    <visual>
      <origin xyz="0 -0.6 2.26" rpy="0 0 0" />
      <geometry>
        <box size="1.18 0.08 0.1" />
        </geometry>
      </visual>
    <visual>
      <origin xyz="-0.5 -0.6 1.18" rpy="0 0 0" />
      <geometry>
        <box size="0.08 0.08 2.18" />
        </geometry>
      </visual>
    <visual>
      <origin xyz="0.5 -0.6 1.18" rpy="0 0 0" />
      <geometry>
        <box size="0.08 0.08 2.18" />
        </geometry>
      </visual>
    <visual>
      <origin xyz="-0.5 -0.64 0.18" rpy="0 0 0" />
      <geometry>
        <box size="0.08 0.14 0.1" />
        </geometry>
      </visual>
    <visual>
      <origin xyz="-0.5 -0.64 2.24" rpy="0 0 0" />
      <geometry>
        <box size="0.08 0.14 0.1" />
        </geometry>
      </visual>
    <visual>
      <origin xyz="0.5 -0.64 0.18" rpy="0 0 0" />
      <geometry>
        <box size="0.08 0.14 0.1" />
        </geometry>
      </visual>
    <visual>
      <origin xyz="0.5 -0.64 2.24" rpy="0 0 0" />
      <geometry>
        <box size="0.08 0.14 0.1" />
        </geometry>
      </visual>
    <visual>
      <origin xyz="0.736 0.24 1.24" rpy="0 0 0" />
      <geometry>
        <box size="0.04 0.22 1.1" />
        </geometry>
      </visual>
    <visual>
      <origin xyz="0 0 2.315" rpy="0 0 0" />
      <geometry>
        <box size="0.9 0.5 0.03" />
        </geometry>
      </visual>
    <visual>
      <origin xyz="0 -0.61 1.08" rpy="0 1.5708 0" />
      <geometry>
        <cylinder radius="0.014" length="0.9" />
        </geometry>
      </visual>
    <visual>
      <origin xyz="-0.742 0.1 1.06" rpy="1.5708 0 0" />
      <geometry>
        <cylinder radius="0.012" length="0.6" />
        </geometry>
      </visual>
    <visual>
      <origin xyz="0.742 0.1 1.06" rpy="1.5708 0 0" />
      <geometry>
        <cylinder radius="0.012" length="0.6" />
        </geometry>
      </visual>
    <visual>
      <origin xyz="-0.32 -0.625 1.08" rpy="0 0 0" />
      <geometry>
        <box size="0.1 0.04 0.08" />
        </geometry>
      </visual>
    <visual>
      <origin xyz="0.32 -0.625 1.08" rpy="0 0 0" />
      <geometry>
        <box size="0.1 0.04 0.08" />
        </geometry>
      </visual>
    <visual>
      <origin xyz="-0.742 0.1 1.06" rpy="0 0 0" />
      <geometry>
        <box size="0.024 0.68 0.08" />
        </geometry>
      </visual>
    <visual>
      <origin xyz="0.742 0.1 1.06" rpy="0 0 0" />
      <geometry>
        <box size="0.024 0.68 0.08" />
        </geometry>
      </visual>
    <collision name="cab__visual_1">
      <origin xyz="0 0 0.02" rpy="0 0 0" />
      <geometry>
        <box size="0.18 0.1 0.04" />
        </geometry>
      </collision>
    <collision name="cab__visual_2">
      <origin xyz="0 0 0.06" rpy="0 0 0" />
      <geometry>
        <box size="1.55 1.3 0.06" />
        </geometry>
      </collision>
    <collision name="cab__visual_3">
      <origin xyz="0 -0.63 1.18" rpy="0 0 0" />
      <geometry>
        <box size="1.55 0.04 2.18" />
        </geometry>
      </collision>
    <collision name="cab__visual_4">
      <origin xyz="-0.755 0 1.18" rpy="0 0 0" />
      <geometry>
        <box size="0.04 1.26 2.18" />
        </geometry>
      </collision>
    <collision name="cab__visual_5">
      <origin xyz="0.755 0 1.18" rpy="0 0 0" />
      <geometry>
        <box size="0.04 1.26 2.18" />
        </geometry>
      </collision>
    <collision name="cab__visual_6">
      <origin xyz="0 0 2.34" rpy="0 0 0" />
      <geometry>
        <box size="1.55 1.3 0.04" />
        </geometry>
      </collision>
    <collision name="cab__visual_7">
      <origin xyz="0 0.62 0.07" rpy="0 0 0" />
      <geometry>
        <box size="1.55 0.08 0.02" />
        </geometry>
      </collision>
    <collision name="cab__visual_8">
      <origin xyz="-0.72 0.62 1.18" rpy="0 0 0" />
      <geometry>
        <box size="0.08 0.08 2.18" />
        </geometry>
      </collision>
    <collision name="cab__visual_9">
      <origin xyz="0.72 0.62 1.18" rpy="0 0 0" />
      <geometry>
        <box size="0.08 0.08 2.18" />
        </geometry>
      </collision>
    <collision name="cab__visual_10">
      <origin xyz="0 0.62 2.31" rpy="0 0 0" />
      <geometry>
        <box size="1.55 0.08 0.1" />
        </geometry>
      </collision>
    <collision name="cab__visual_11">
      <origin xyz="0 0.675 2.245" rpy="0 0 0" />
      <geometry>
        <box size="1.12 0.05 0.03" />
        </geometry>
      </collision>
    <collision name="cab__visual_12">
      <origin xyz="-0.275 0.66 2.22" rpy="0 0 0" />
      <geometry>
        <box size="0.12 0.02 0.02" />
        </geometry>
      </collision>
    <collision name="cab__visual_13">
      <origin xyz="0.275 0.66 2.22" rpy="0 0 0" />
      <geometry>
        <box size="0.12 0.02 0.02" />
        </geometry>
      </collision>
    <collision name="cab__visual_14">
      <origin xyz="0 -0.6 0.16" rpy="0 0 0" />
      <geometry>
        <box size="1.18 0.08 0.1" />
        </geometry>
      </collision>
    <collision name="cab__visual_15">
      <origin xyz="0 -0.6 2.26" rpy="0 0 0" />
      <geometry>
        <box size="1.18 0.08 0.1" />
        </geometry>
      </collision>
    <collision name="cab__visual_16">
      <origin xyz="-0.5 -0.6 1.18" rpy="0 0 0" />
      <geometry>
        <box size="0.08 0.08 2.18" />
        </geometry>
      </collision>
    <collision name="cab__visual_17">
      <origin xyz="0.5 -0.6 1.18" rpy="0 0 0" />
      <geometry>
        <box size="0.08 0.08 2.18" />
        </geometry>
      </collision>
    <collision name="cab__visual_18">
      <origin xyz="-0.5 -0.64 0.18" rpy="0 0 0" />
      <geometry>
        <box size="0.08 0.14 0.1" />
        </geometry>
      </collision>
    <collision name="cab__visual_19">
      <origin xyz="-0.5 -0.64 2.24" rpy="0 0 0" />
      <geometry>
        <box size="0.08 0.14 0.1" />
        </geometry>
      </collision>
    <collision name="cab__visual_20">
      <origin xyz="0.5 -0.64 0.18" rpy="0 0 0" />
      <geometry>
        <box size="0.08 0.14 0.1" />
        </geometry>
      </collision>
    <collision name="cab__visual_21">
      <origin xyz="0.5 -0.64 2.24" rpy="0 0 0" />
      <geometry>
        <box size="0.08 0.14 0.1" />
        </geometry>
      </collision>
    <collision name="cab__visual_22">
      <origin xyz="0.736 0.24 1.24" rpy="0 0 0" />
      <geometry>
        <box size="0.04 0.22 1.1" />
        </geometry>
      </collision>
    <collision name="cab__visual_23">
      <origin xyz="0 0 2.315" rpy="0 0 0" />
      <geometry>
        <box size="0.9 0.5 0.03" />
        </geometry>
      </collision>
    <collision name="cab__visual_24">
      <origin xyz="0 -0.61 1.08" rpy="0 1.5708 0" />
      <geometry>
        <cylinder radius="0.014" length="0.9" />
        </geometry>
      </collision>
    <collision name="cab__visual_25">
      <origin xyz="-0.742 0.1 1.06" rpy="1.5708 0 0" />
      <geometry>
        <cylinder radius="0.012" length="0.6" />
        </geometry>
      </collision>
    <collision name="cab__visual_26">
      <origin xyz="0.742 0.1 1.06" rpy="1.5708 0 0" />
      <geometry>
        <cylinder radius="0.012" length="0.6" />
        </geometry>
      </collision>
    <collision name="cab__visual_27">
      <origin xyz="-0.32 -0.625 1.08" rpy="0 0 0" />
      <geometry>
        <box size="0.1 0.04 0.08" />
        </geometry>
      </collision>
    <collision name="cab__visual_28">
      <origin xyz="0.32 -0.625 1.08" rpy="0 0 0" />
      <geometry>
        <box size="0.1 0.04 0.08" />
        </geometry>
      </collision>
    <collision name="cab__visual_29">
      <origin xyz="-0.742 0.1 1.06" rpy="0 0 0" />
      <geometry>
        <box size="0.024 0.68 0.08" />
        </geometry>
      </collision>
    <collision name="cab__visual_30">
      <origin xyz="0.742 0.1 1.06" rpy="0 0 0" />
      <geometry>
        <box size="0.024 0.68 0.08" />
        </geometry>
      </collision>
    </link>
  <link name="left_door">
    <inertial>
      <origin xyz="0 0 -1.05" rpy="0 0 0" />
      <mass value="75" />
      <inertia ixx="27.5664" ixy="0" ixz="0" iyy="29.385" iyz="0" izz="1.82641" />
      </inertial>
    <visual>
      <origin xyz="0 0 -1.05" rpy="0 0 0" />
      <geometry>
        <box size="0.54 0.025 2.1" />
        </geometry>
      </visual>
    <visual>
      <origin xyz="-0.255 0.0075 -1.05" rpy="0 0 0" />
      <geometry>
        <box size="0.03 0.01 2.1" />
        </geometry>
      </visual>
    <visual>
      <origin xyz="0.255 0.0075 -1.05" rpy="0 0 0" />
      <geometry>
        <box size="0.03 0.01 2.1" />
        </geometry>
      </visual>
    <visual>
      <origin xyz="0 0.0075 -0.48" rpy="0 0 0" />
      <geometry>
        <box size="0.44 0.01 0.04" />
        </geometry>
      </visual>
    <visual>
      <origin xyz="0 0.0075 -1.34" rpy="0 0 0" />
      <geometry>
        <box size="0.44 0.01 0.04" />
        </geometry>
      </visual>
    <collision name="left_door__visual_1">
      <origin xyz="0 0 -1.05" rpy="0 0 0" />
      <geometry>
        <box size="0.54 0.025 2.1" />
        </geometry>
      </collision>
    <collision name="left_door__visual_2">
      <origin xyz="-0.255 0.0075 -1.05" rpy="0 0 0" />
      <geometry>
        <box size="0.03 0.01 2.1" />
        </geometry>
      </collision>
    <collision name="left_door__visual_3">
      <origin xyz="0.255 0.0075 -1.05" rpy="0 0 0" />
      <geometry>
        <box size="0.03 0.01 2.1" />
        </geometry>
      </collision>
    <collision name="left_door__visual_4">
      <origin xyz="0 0.0075 -0.48" rpy="0 0 0" />
      <geometry>
        <box size="0.44 0.01 0.04" />
        </geometry>
      </collision>
    <collision name="left_door__visual_5">
      <origin xyz="0 0.0075 -1.34" rpy="0 0 0" />
      <geometry>
        <box size="0.44 0.01 0.04" />
        </geometry>
      </collision>
    </link>
  <link name="right_door">
    <inertial>
      <origin xyz="0 0 -1.05" rpy="0 0 0" />
      <mass value="75" />
      <inertia ixx="27.5664" ixy="0" ixz="0" iyy="29.385" iyz="0" izz="1.82641" />
      </inertial>
    <visual>
      <origin xyz="0 0 -1.05" rpy="0 0 0" />
      <geometry>
        <box size="0.54 0.025 2.1" />
        </geometry>
      </visual>
    <visual>
      <origin xyz="-0.255 0.0075 -1.05" rpy="0 0 0" />
      <geometry>
        <box size="0.03 0.01 2.1" />
        </geometry>
      </visual>
    <visual>
      <origin xyz="0.255 0.0075 -1.05" rpy="0 0 0" />
      <geometry>
        <box size="0.03 0.01 2.1" />
        </geometry>
      </visual>
    <visual>
      <origin xyz="0 0.0075 -0.48" rpy="0 0 0" />
      <geometry>
        <box size="0.44 0.01 0.04" />
        </geometry>
      </visual>
    <visual>
      <origin xyz="0 0.0075 -1.34" rpy="0 0 0" />
      <geometry>
        <box size="0.44 0.01 0.04" />
        </geometry>
      </visual>
    <collision name="right_door__visual_1">
      <origin xyz="0 0 -1.05" rpy="0 0 0" />
      <geometry>
        <box size="0.54 0.025 2.1" />
        </geometry>
      </collision>
    <collision name="right_door__visual_2">
      <origin xyz="-0.255 0.0075 -1.05" rpy="0 0 0" />
      <geometry>
        <box size="0.03 0.01 2.1" />
        </geometry>
      </collision>
    <collision name="right_door__visual_3">
      <origin xyz="0.255 0.0075 -1.05" rpy="0 0 0" />
      <geometry>
        <box size="0.03 0.01 2.1" />
        </geometry>
      </collision>
    <collision name="right_door__visual_4">
      <origin xyz="0 0.0075 -0.48" rpy="0 0 0" />
      <geometry>
        <box size="0.44 0.01 0.04" />
        </geometry>
      </collision>
    <collision name="right_door__visual_5">
      <origin xyz="0 0.0075 -1.34" rpy="0 0 0" />
      <geometry>
        <box size="0.44 0.01 0.04" />
        </geometry>
      </collision>
    </link>
  <joint name="shaft_to_cab" type="prismatic">
    <origin xyz="0 0.1 0.12" rpy="0 0 0" />
    <parent link="shaft_frame" />
    <child link="cab" />
    <axis xyz="0 0 1" />
    <limit effort="6000" velocity="1.5" lower="0" upper="1.45" />
    </joint>
  <joint name="cab_to_left_door" type="prismatic">
    <origin xyz="-0.275 0.685 2.22" rpy="0 0 0" />
    <parent link="cab" />
    <child link="left_door" />
    <axis xyz="-1 0 0" />
    <limit effort="400" velocity="1.2" lower="0" upper="0.31" />
    </joint>
  <joint name="cab_to_right_door" type="prismatic">
    <origin xyz="0.275 0.685 2.22" rpy="0 0 0" />
    <parent link="cab" />
    <child link="right_door" />
    <axis xyz="1 0 0" />
    <limit effort="400" velocity="1.2" lower="0" upper="0.31" />
    </joint>
  </robot>
