<robot name="four_link_deployable_arm">
  <material name="base_metal">
    <color rgba="0.34 0.37 0.41 1" />
  </material>
  <material name="accent_dark">
    <color rgba="0.18 0.2 0.23 1" />
  </material>
  <material name="arm_metal">
    <color rgba="0.72 0.74 0.77 1" />
  </material>
  <material name="arm_joint_dark">
    <color rgba="0.24 0.25 0.28 1" />
  </material>
  <material name="sensor_body">
    <color rgba="0.16 0.18 0.2 1" />
  </material>
  <material name="sensor_lens">
    <color rgba="0.32 0.52 0.68 1" />
  </material>
  <link name="base">
    <inertial>
      <mass value="4.5" />
      <inertia ixx="0.0103875" ixy="0" ixz="0" iyy="0.0126375" iyz="0" izz="0.01695" />
    </inertial>
    <visual>
      <geometry>
        <mesh filename="meshes/deployable_arm_base.glb" />
      </geometry>
      <material name="base_metal" />
    </visual>
    <collision>
      <geometry>
        <box size="0.16 0.14 0.09" />
      </geometry>
    </collision>
  </link>
  <link name="link1">
    <inertial>
      <origin xyz="0.11 0 0.014" rpy="0 0 0" />
      <mass value="1.2" />
      <inertia ixx="0.00034" ixy="0" ixz="0" iyy="0.00493" iyz="0" izz="0.00509" />
    </inertial>
    <visual>
      <geometry>
        <mesh filename="meshes/deployable_arm_link1.glb" />
      </geometry>
      <material name="arm_metal" />
    </visual>
    <collision>
      <origin xyz="0.016 0 0.014" rpy="0 0 0" />
      <geometry>
        <box size="0.022 0.05 0.02" />
      </geometry>
    </collision>
    <collision>
      <origin xyz="0.114 0 0.014" rpy="0 0 0" />
      <geometry>
        <box size="0.178 0.034 0.02" />
      </geometry>
    </collision>
    <collision>
      <origin xyz="0.211 0 0.014" rpy="0 0 0" />
      <geometry>
        <box size="0.018 0.05 0.02" />
      </geometry>
    </collision>
  </link>
  <link name="link2">
    <inertial>
      <origin xyz="0.09 0 0" rpy="0 0 0" />
      <mass value="0.95" />
      <inertia ixx="0.000269167" ixy="0" ixz="0" iyy="0.00263625" iyz="0" izz="0.00276292" />
    </inertial>
    <visual>
      <geometry>
        <mesh filename="meshes/deployable_arm_link2.glb" />
      </geometry>
      <material name="arm_metal" />
    </visual>
    <collision>
      <origin xyz="0.016 0 0" rpy="0 0 0" />
      <geometry>
        <box size="0.022 0.05 0.02" />
      </geometry>
    </collision>
    <collision>
      <origin xyz="0.094 0 0" rpy="0 0 0" />
      <geometry>
        <box size="0.138 0.034 0.02" />
      </geometry>
    </collision>
    <collision>
      <origin xyz="0.171 0 0" rpy="0 0 0" />
      <geometry>
        <box size="0.018 0.05 0.02" />
      </geometry>
    </collision>
  </link>
  <link name="link3">
    <inertial>
      <origin xyz="0.07 0 0" rpy="0 0 0" />
      <mass value="0.7" />
      <inertia ixx="0.000163858" ixy="0" ixz="0" iyy="0.00118907" iyz="0" izz="0.00126146" />
    </inertial>
    <visual>
      <geometry>
        <mesh filename="meshes/deployable_arm_link3.glb" />
      </geometry>
      <material name="arm_metal" />
    </visual>
    <collision>
      <origin xyz="0.016 0 0" rpy="0 0 0" />
      <geometry>
        <box size="0.022 0.05 0.02" />
      </geometry>
    </collision>
    <collision>
      <origin xyz="0.074 0 0" rpy="0 0 0" />
      <geometry>
        <box size="0.098 0.034 0.02" />
      </geometry>
    </collision>
    <collision>
      <origin xyz="0.131 0 0" rpy="0 0 0" />
      <geometry>
        <box size="0.018 0.05 0.02" />
      </geometry>
    </collision>
  </link>
  <link name="link4">
    <inertial>
      <origin xyz="0.05 0 0" rpy="0 0 0" />
      <mass value="0.45" />
      <inertia ixx="9.15e-05" ixy="0" ixz="0" iyy="0.00040035" iyz="0" izz="0.00044115" />
    </inertial>
    <visual>
      <geometry>
        <mesh filename="meshes/deployable_arm_link4.glb" />
      </geometry>
      <material name="arm_metal" />
    </visual>
    <collision>
      <origin xyz="0.016 0 0" rpy="0 0 0" />
      <geometry>
        <box size="0.022 0.05 0.02" />
      </geometry>
    </collision>
    <collision>
      <origin xyz="0.054 0 0" rpy="0 0 0" />
      <geometry>
        <box size="0.058 0.034 0.02" />
      </geometry>
    </collision>
    <collision>
      <origin xyz="0.091 0 0" rpy="0 0 0" />
      <geometry>
        <box size="0.018 0.05 0.02" />
      </geometry>
    </collision>
  </link>
  <link name="sensor_pod">
    <inertial>
      <origin xyz="0.036 0 0.045" rpy="0 0 0" />
      <mass value="0.18" />
      <inertia ixx="9.15e-05" ixy="0" ixz="0" iyy="0.0001275" iyz="0" izz="0.000111" />
    </inertial>
    <visual>
      <geometry>
        <mesh filename="meshes/deployable_arm_sensor_pod.glb" />
      </geometry>
      <material name="sensor_body" />
    </visual>
    <collision>
      <origin xyz="0.014 0 0.028" rpy="0 0 0" />
      <geometry>
        <box size="0.02 0.024 0.018" />
      </geometry>
    </collision>
    <collision>
      <origin xyz="0.036 0 0.052" rpy="0 0 0" />
      <geometry>
        <box size="0.052 0.04 0.03" />
      </geometry>
    </collision>
  </link>
  <joint name="base_to_link1" type="revolute">
    <origin xyz="0 0 0.045" rpy="0 0 0" />
    <parent link="base" />
    <child link="link1" />
    <axis xyz="0 0 1" />
    <limit effort="12" velocity="1.5" lower="-1.6" upper="1.6" />
  </joint>
  <joint name="link1_to_link2" type="revolute">
    <origin xyz="0.22 0 0.014" rpy="0 0 0" />
    <parent link="link1" />
    <child link="link2" />
    <axis xyz="0 -1 0" />
    <limit effort="9" velocity="1.8" lower="0" upper="1.2" />
  </joint>
  <joint name="link2_to_link3" type="revolute">
    <origin xyz="0.18 0 0" rpy="0 0 0" />
    <parent link="link2" />
    <child link="link3" />
    <axis xyz="0 -1 0" />
    <limit effort="7.5" velocity="2" lower="0" upper="1.35" />
  </joint>
  <joint name="link3_to_link4" type="revolute">
    <origin xyz="0.14 0 0" rpy="0 0 0" />
    <parent link="link3" />
    <child link="link4" />
    <axis xyz="0 -1 0" />
    <limit effort="5.5" velocity="2.2" lower="0" upper="1.2" />
  </joint>
  <joint name="link4_to_sensor_pod" type="fixed">
    <origin xyz="0.1 0 0" rpy="0 0 0" />
    <parent link="link4" />
    <child link="sensor_pod" />
  </joint>
</robot>