<robot name="kitchen_range_hood">
  <link name="hood_body">
    <inertial>
      <origin xyz="0 0.015 0.29" rpy="0 0 0" />
      <mass value="18" />
      <inertia ixx="0.687" ixy="0" ixz="0" iyy="1.1238" iyz="0" izz="0.87" />
    </inertial>
    <visual>
      <geometry>
        <mesh filename="meshes/range_hood_canopy.glb" />
      </geometry>
      <material name="stainless_steel">
        <color rgba="0.8 0.81 0.83 1" />
      </material>
    </visual>
    <visual>
      <origin xyz="0 -0.028 0.208" rpy="0 0 0" />
      <geometry>
        <box size="0.4 0.24 0.016" />
      </geometry>
      <material name="stainless_steel">
        <color rgba="0.8 0.81 0.83 1" />
      </material>
    </visual>
    <visual>
      <origin xyz="0 -0.028 0.41" rpy="0 0 0" />
      <geometry>
        <box size="0.34 0.22 0.36" />
      </geometry>
      <material name="stainless_steel">
        <color rgba="0.8 0.81 0.83 1" />
      </material>
    </visual>
    <visual>
      <origin xyz="0 -0.028 0.223" rpy="0 0 0" />
      <geometry>
        <box size="0.3 0.18 0.032" />
      </geometry>
      <material name="stainless_steel">
        <color rgba="0.8 0.81 0.83 1" />
      </material>
    </visual>
    <visual>
      <origin xyz="0 0.02 0.029" rpy="0 0 0" />
      <geometry>
        <mesh filename="meshes/range_hood_underside_frame.glb" />
      </geometry>
      <material name="brushed_aluminum">
        <color rgba="0.69 0.7 0.72 1" />
      </material>
    </visual>
    <visual>
      <origin xyz="0 0.01 0.04" rpy="0 0 0" />
      <geometry>
        <box size="0.36 0.22 0.024" />
      </geometry>
      <material name="dark_trim">
        <color rgba="0.19 0.2 0.22 1" />
      </material>
    </visual>
    <visual>
      <origin xyz="0 0.02 0.044" rpy="0 0 0" />
      <geometry>
        <box size="0.6 0.3 0.024" />
      </geometry>
      <material name="dark_trim">
        <color rgba="0.19 0.2 0.22 1" />
      </material>
    </visual>
    <visual>
      <origin xyz="0 0.14 0.052" rpy="0 0 0" />
      <geometry>
        <box size="0.46 0.06 0.012" />
      </geometry>
      <material name="stainless_steel">
        <color rgba="0.8 0.81 0.83 1" />
      </material>
    </visual>
    <visual>
      <origin xyz="0 0.182 0.068" rpy="0 0 0" />
      <geometry>
        <box size="0.46 0.036 0.014" />
      </geometry>
      <material name="stainless_steel">
        <color rgba="0.8 0.81 0.83 1" />
      </material>
    </visual>
    <visual>
      <origin xyz="0.09 0.204 0.066" rpy="0 0 0" />
      <geometry>
        <box size="0.28 0.024 0.016" />
      </geometry>
      <material name="dark_trim">
        <color rgba="0.19 0.2 0.22 1" />
      </material>
    </visual>
    <visual>
      <origin xyz="0 0.198 0.068" rpy="0 0 0" />
      <geometry>
        <box size="0.25 0.014 0.004" />
      </geometry>
      <material name="dark_trim">
        <color rgba="0.19 0.2 0.22 1" />
      </material>
    </visual>
    <visual>
      <origin xyz="0 0.082 0.447" rpy="-1.5708 0 0" />
      <geometry>
        <mesh filename="meshes/range_hood_chimney_vent.glb" />
      </geometry>
      <material name="dark_trim">
        <color rgba="0.19 0.2 0.22 1" />
      </material>
    </visual>
    <visual>
      <origin xyz="0 0.076 0.447" rpy="0 0 0" />
      <geometry>
        <box size="0.246 0.012 0.112" />
      </geometry>
      <material name="dark_trim">
        <color rgba="0.19 0.2 0.22 1" />
      </material>
    </visual>
    <visual>
      <origin xyz="-0.275 0.118 0.024" rpy="0 0 0" />
      <geometry>
        <cylinder radius="0.019" length="0.008" />
      </geometry>
      <material name="lens_white">
        <color rgba="0.95 0.97 1 0.45" />
      </material>
    </visual>
    <visual>
      <origin xyz="-0.275 0.118 0.032" rpy="0 0 0" />
      <geometry>
        <box size="0.052 0.052 0.016" />
      </geometry>
      <material name="brushed_aluminum">
        <color rgba="0.69 0.7 0.72 1" />
      </material>
    </visual>
    <visual>
      <origin xyz="0.275 0.118 0.024" rpy="0 0 0" />
      <geometry>
        <cylinder radius="0.019" length="0.008" />
      </geometry>
      <material name="lens_white">
        <color rgba="0.95 0.97 1 0.45" />
      </material>
    </visual>
    <visual>
      <origin xyz="0.275 0.118 0.032" rpy="0 0 0" />
      <geometry>
        <box size="0.052 0.052 0.016" />
      </geometry>
      <material name="brushed_aluminum">
        <color rgba="0.69 0.7 0.72 1" />
      </material>
    </visual>
    <collision name="hood_body__visual_1__hull_001">
      <geometry>
        <mesh filename="meshes/collision/cache/be519ddf8b2af117ed7802d4__hull_001.obj" />
      </geometry>
    </collision>
    <collision name="hood_body__visual_2">
      <origin xyz="0 -0.028 0.208" rpy="0 0 0" />
      <geometry>
        <box size="0.4 0.24 0.016" />
      </geometry>
    </collision>
    <collision name="hood_body__visual_3">
      <origin xyz="0 -0.028 0.41" rpy="0 0 0" />
      <geometry>
        <box size="0.34 0.22 0.36" />
      </geometry>
    </collision>
    <collision name="hood_body__visual_4">
      <origin xyz="0 -0.028 0.223" rpy="0 0 0" />
      <geometry>
        <box size="0.3 0.18 0.032" />
      </geometry>
    </collision>
    <collision name="hood_body__visual_5__hull_001">
      <origin xyz="0 0.02 0.029" rpy="0 0 0" />
      <geometry>
        <mesh filename="meshes/collision/cache/8a486c426ff12e5c9e946d49__hull_001.obj" />
      </geometry>
    </collision>
    <collision name="hood_body__visual_5__hull_002">
      <origin xyz="0 0.02 0.029" rpy="0 0 0" />
      <geometry>
        <mesh filename="meshes/collision/cache/8a486c426ff12e5c9e946d49__hull_002.obj" />
      </geometry>
    </collision>
    <collision name="hood_body__visual_5__hull_003">
      <origin xyz="0 0.02 0.029" rpy="0 0 0" />
      <geometry>
        <mesh filename="meshes/collision/cache/8a486c426ff12e5c9e946d49__hull_003.obj" />
      </geometry>
    </collision>
    <collision name="hood_body__visual_5__hull_004">
      <origin xyz="0 0.02 0.029" rpy="0 0 0" />
      <geometry>
        <mesh filename="meshes/collision/cache/8a486c426ff12e5c9e946d49__hull_004.obj" />
      </geometry>
    </collision>
    <collision name="hood_body__visual_5__hull_005">
      <origin xyz="0 0.02 0.029" rpy="0 0 0" />
      <geometry>
        <mesh filename="meshes/collision/cache/8a486c426ff12e5c9e946d49__hull_005.obj" />
      </geometry>
    </collision>
    <collision name="hood_body__visual_5__hull_006">
      <origin xyz="0 0.02 0.029" rpy="0 0 0" />
      <geometry>
        <mesh filename="meshes/collision/cache/8a486c426ff12e5c9e946d49__hull_006.obj" />
      </geometry>
    </collision>
    <collision name="hood_body__visual_5__hull_007">
      <origin xyz="0 0.02 0.029" rpy="0 0 0" />
      <geometry>
        <mesh filename="meshes/collision/cache/8a486c426ff12e5c9e946d49__hull_007.obj" />
      </geometry>
    </collision>
    <collision name="hood_body__visual_5__hull_008">
      <origin xyz="0 0.02 0.029" rpy="0 0 0" />
      <geometry>
        <mesh filename="meshes/collision/cache/8a486c426ff12e5c9e946d49__hull_008.obj" />
      </geometry>
    </collision>
    <collision name="hood_body__visual_6">
      <origin xyz="0 0.01 0.04" rpy="0 0 0" />
      <geometry>
        <box size="0.36 0.22 0.024" />
      </geometry>
    </collision>
    <collision name="hood_body__visual_7">
      <origin xyz="0 0.02 0.044" rpy="0 0 0" />
      <geometry>
        <box size="0.6 0.3 0.024" />
      </geometry>
    </collision>
    <collision name="hood_body__visual_8">
      <origin xyz="0 0.14 0.052" rpy="0 0 0" />
      <geometry>
        <box size="0.46 0.06 0.012" />
      </geometry>
    </collision>
    <collision name="hood_body__visual_9">
      <origin xyz="0 0.182 0.068" rpy="0 0 0" />
      <geometry>
        <box size="0.46 0.036 0.014" />
      </geometry>
    </collision>
    <collision name="hood_body__visual_10">
      <origin xyz="0.09 0.204 0.066" rpy="0 0 0" />
      <geometry>
        <box size="0.28 0.024 0.016" />
      </geometry>
    </collision>
    <collision name="hood_body__visual_11">
      <origin xyz="0 0.198 0.068" rpy="0 0 0" />
      <geometry>
        <box size="0.25 0.014 0.004" />
      </geometry>
    </collision>
    <collision name="hood_body__visual_12__hull_001">
      <origin xyz="0 0.082 0.447" rpy="-1.5708 0 0" />
      <geometry>
        <mesh filename="meshes/collision/cache/615d06d4f22e577e84a1aefb__hull_001.obj" />
      </geometry>
    </collision>
    <collision name="hood_body__visual_13">
      <origin xyz="0 0.076 0.447" rpy="0 0 0" />
      <geometry>
        <box size="0.246 0.012 0.112" />
      </geometry>
    </collision>
    <collision name="hood_body__visual_14">
      <origin xyz="-0.275 0.118 0.024" rpy="0 0 0" />
      <geometry>
        <cylinder radius="0.019" length="0.008" />
      </geometry>
    </collision>
    <collision name="hood_body__visual_15">
      <origin xyz="-0.275 0.118 0.032" rpy="0 0 0" />
      <geometry>
        <box size="0.052 0.052 0.016" />
      </geometry>
    </collision>
    <collision name="hood_body__visual_16">
      <origin xyz="0.275 0.118 0.024" rpy="0 0 0" />
      <geometry>
        <cylinder radius="0.019" length="0.008" />
      </geometry>
    </collision>
    <collision name="hood_body__visual_17">
      <origin xyz="0.275 0.118 0.032" rpy="0 0 0" />
      <geometry>
        <box size="0.052 0.052 0.016" />
      </geometry>
    </collision>
  </link>
  <link name="left_filter">
    <inertial>
      <origin xyz="0 0.097 -0.007" rpy="0 0 0" />
      <mass value="0.9" />
      <inertia ixx="0.0028374" ixy="0" ixz="0" iyy="0.0044799" iyz="0" izz="0.0072879" />
    </inertial>
    <visual>
      <origin xyz="0 0.097 -0.005" rpy="0 0 0" />
      <geometry>
        <mesh filename="meshes/range_hood_filter.glb" />
      </geometry>
      <material name="brushed_aluminum">
        <color rgba="0.69 0.7 0.72 1" />
      </material>
    </visual>
    <visual>
      <origin xyz="0 0.187 -0.011" rpy="0 0 0" />
      <geometry>
        <box size="0.084 0.01 0.006" />
      </geometry>
      <material name="dark_trim">
        <color rgba="0.19 0.2 0.22 1" />
      </material>
    </visual>
    <collision name="left_filter__visual_1__hull_001">
      <origin xyz="0 0.097 -0.005" rpy="0 0 0" />
      <geometry>
        <mesh filename="meshes/collision/cache/e8e5491c0fb81023d051ddff__hull_001.obj" />
      </geometry>
    </collision>
    <collision name="left_filter__visual_2">
      <origin xyz="0 0.187 -0.011" rpy="0 0 0" />
      <geometry>
        <box size="0.084 0.01 0.006" />
      </geometry>
    </collision>
  </link>
  <link name="right_filter">
    <inertial>
      <origin xyz="0 0.097 -0.007" rpy="0 0 0" />
      <mass value="0.9" />
      <inertia ixx="0.0028374" ixy="0" ixz="0" iyy="0.0044799" iyz="0" izz="0.0072879" />
    </inertial>
    <visual>
      <origin xyz="0 0.097 -0.005" rpy="0 0 0" />
      <geometry>
        <mesh filename="meshes/range_hood_filter.glb" />
      </geometry>
      <material name="brushed_aluminum">
        <color rgba="0.69 0.7 0.72 1" />
      </material>
    </visual>
    <visual>
      <origin xyz="0 0.187 -0.011" rpy="0 0 0" />
      <geometry>
        <box size="0.084 0.01 0.006" />
      </geometry>
      <material name="dark_trim">
        <color rgba="0.19 0.2 0.22 1" />
      </material>
    </visual>
    <collision name="right_filter__visual_1__hull_001">
      <origin xyz="0 0.097 -0.005" rpy="0 0 0" />
      <geometry>
        <mesh filename="meshes/collision/cache/e8e5491c0fb81023d051ddff__hull_001.obj" />
      </geometry>
    </collision>
    <collision name="right_filter__visual_2">
      <origin xyz="0 0.187 -0.011" rpy="0 0 0" />
      <geometry>
        <box size="0.084 0.01 0.006" />
      </geometry>
    </collision>
  </link>
  <link name="fan_switch">
    <inertial>
      <origin xyz="0 -0.002 -0.005" rpy="0 0 0" />
      <mass value="0.05" />
      <inertia ixx="8.33333e-07" ixy="0" ixz="0" iyy="1.23333e-06" iyz="0" izz="1.23333e-06" />
    </inertial>
    <visual>
      <origin xyz="0 0 0" rpy="0 1.5708 0" />
      <geometry>
        <cylinder radius="0.0025" length="0.014" />
      </geometry>
      <material name="black_plastic">
        <color rgba="0.08 0.08 0.09 1" />
      </material>
    </visual>
    <visual>
      <origin xyz="0 -0.002 -0.005" rpy="0 0 0" />
      <geometry>
        <box size="0.014 0.01 0.01" />
      </geometry>
      <material name="black_plastic">
        <color rgba="0.08 0.08 0.09 1" />
      </material>
    </visual>
    <collision name="fan_switch__visual_1">
      <origin xyz="0 0 0" rpy="0 1.5708 0" />
      <geometry>
        <cylinder radius="0.0025" length="0.014" />
      </geometry>
    </collision>
    <collision name="fan_switch__visual_2">
      <origin xyz="0 -0.002 -0.005" rpy="0 0 0" />
      <geometry>
        <box size="0.014 0.01 0.01" />
      </geometry>
    </collision>
  </link>
  <joint name="left_filter_hinge" type="revolute">
    <origin xyz="-0.156 -0.084 0.0205" rpy="0 0 0" />
    <parent link="hood_body" />
    <child link="left_filter" />
    <axis xyz="1 0 0" />
    <limit effort="8" velocity="1.5" lower="-1.18" upper="0" />
  </joint>
  <joint name="right_filter_hinge" type="revolute">
    <origin xyz="0.156 -0.084 0.0205" rpy="0 0 0" />
    <parent link="hood_body" />
    <child link="right_filter" />
    <axis xyz="1 0 0" />
    <limit effort="8" velocity="1.5" lower="-1.18" upper="0" />
  </joint>
  <joint name="fan_switch_hinge" type="revolute">
    <origin xyz="0.208 0.197 0.071" rpy="0 0 0" />
    <parent link="hood_body" />
    <child link="fan_switch" />
    <axis xyz="1 0 0" />
    <limit effort="1" velocity="6" lower="-0.35" upper="0.35" />
  </joint>
</robot>