<robot name="internet_router_with_4_antennas">
  <material name="body_black">
    <color rgba="0.12 0.12 0.13 1" />
    </material>
  <material name="trim_gray">
    <color rgba="0.23 0.24 0.25 1" />
    </material>
  <material name="rubber">
    <color rgba="0.05 0.05 0.06 1" />
    </material>
  <material name="led_glass">
    <color rgba="0.4 0.86 0.9 0.45" />
    </material>
  <material name="io_black">
    <color rgba="0.08 0.08 0.09 1" />
    </material>
  <material name="antenna_black">
    <color rgba="0.09 0.09 0.1 1" />
    </material>
  <link name="body">
    <inertial>
      <origin xyz="0 0 0.014" rpy="0 0 0" />
      <mass value="0.95" />
      <inertia ixx="0.00329238" ixy="0" ixz="0" iyy="0.00776847" iyz="0" izz="0.0109367" />
      </inertial>
    <visual name="shell">
      <geometry>
        <mesh filename="assets/meshes/router_body_shell.obj" />
        </geometry>
      <material name="body_black">
        <color rgba="0.12 0.12 0.13 1" />
        </material>
      </visual>
    <visual name="underside_plate">
      <origin xyz="0 0 0.003" rpy="0 0 0" />
      <geometry>
        <box size="0.286 0.168 0.006" />
        </geometry>
      <material name="trim_gray">
        <color rgba="0.23 0.24 0.25 1" />
        </material>
      </visual>
    <visual name="front_led_strip">
      <origin xyz="0 -0.097 0.011" rpy="0 0 0" />
      <geometry>
        <box size="0.176 0.006 0.004" />
        </geometry>
      <material name="led_glass">
        <color rgba="0.4 0.86 0.9 0.45" />
        </material>
      </visual>
    <visual name="rear_io_panel">
      <origin xyz="0 0.097 0.01" rpy="0 0 0" />
      <geometry>
        <box size="0.218 0.01 0.01" />
        </geometry>
      <material name="io_black">
        <color rgba="0.08 0.08 0.09 1" />
        </material>
      </visual>
    <visual name="lan_port_-0.068">
      <origin xyz="-0.068 0.101 0.012" rpy="0 0 0" />
      <geometry>
        <box size="0.022 0.01 0.013" />
        </geometry>
      <material name="trim_gray">
        <color rgba="0.23 0.24 0.25 1" />
        </material>
      </visual>
    <visual name="lan_port_-0.038">
      <origin xyz="-0.038 0.101 0.012" rpy="0 0 0" />
      <geometry>
        <box size="0.022 0.01 0.013" />
        </geometry>
      <material name="trim_gray">
        <color rgba="0.23 0.24 0.25 1" />
        </material>
      </visual>
    <visual name="lan_port_-0.008">
      <origin xyz="-0.008 0.101 0.012" rpy="0 0 0" />
      <geometry>
        <box size="0.022 0.01 0.013" />
        </geometry>
      <material name="trim_gray">
        <color rgba="0.23 0.24 0.25 1" />
        </material>
      </visual>
    <visual name="lan_port_+0.022">
      <origin xyz="0.022 0.101 0.012" rpy="0 0 0" />
      <geometry>
        <box size="0.022 0.01 0.013" />
        </geometry>
      <material name="trim_gray">
        <color rgba="0.23 0.24 0.25 1" />
        </material>
      </visual>
    <visual name="wan_port">
      <origin xyz="0.056 0.101 0.012" rpy="0 0 0" />
      <geometry>
        <box size="0.022 0.01 0.013" />
        </geometry>
      <material name="led_glass">
        <color rgba="0.4 0.86 0.9 0.45" />
        </material>
      </visual>
    <visual name="usb_port">
      <origin xyz="0.088 0.101 0.01" rpy="0 0 0" />
      <geometry>
        <box size="0.016 0.01 0.007" />
        </geometry>
      <material name="trim_gray">
        <color rgba="0.23 0.24 0.25 1" />
        </material>
      </visual>
    <visual name="power_jack">
      <origin xyz="0.118 0.101 0.011" rpy="1.5708 0 0" />
      <geometry>
        <cylinder radius="0.006" length="0.01" />
        </geometry>
      <material name="trim_gray">
        <color rgba="0.23 0.24 0.25 1" />
        </material>
      </visual>
    <visual name="foot_l_f">
      <origin xyz="-0.108 -0.065 0.002" rpy="0 0 0" />
      <geometry>
        <box size="0.032 0.018 0.004" />
        </geometry>
      <material name="rubber">
        <color rgba="0.05 0.05 0.06 1" />
        </material>
      </visual>
    <visual name="foot_l_b">
      <origin xyz="-0.108 0.065 0.002" rpy="0 0 0" />
      <geometry>
        <box size="0.032 0.018 0.004" />
        </geometry>
      <material name="rubber">
        <color rgba="0.05 0.05 0.06 1" />
        </material>
      </visual>
    <visual name="foot_r_f">
      <origin xyz="0.108 -0.065 0.002" rpy="0 0 0" />
      <geometry>
        <box size="0.032 0.018 0.004" />
        </geometry>
      <material name="rubber">
        <color rgba="0.05 0.05 0.06 1" />
        </material>
      </visual>
    <visual name="foot_r_b">
      <origin xyz="0.108 0.065 0.002" rpy="0 0 0" />
      <geometry>
        <box size="0.032 0.018 0.004" />
        </geometry>
      <material name="rubber">
        <color rgba="0.05 0.05 0.06 1" />
        </material>
      </visual>
    <visual name="vent_rib_-0.054">
      <origin xyz="-0.054 -0.004 0.029" rpy="0 0 0" />
      <geometry>
        <box size="0.01 0.092 0.002" />
        </geometry>
      <material name="trim_gray">
        <color rgba="0.23 0.24 0.25 1" />
        </material>
      </visual>
    <visual name="vent_rib_-0.036">
      <origin xyz="-0.036 -0.004 0.029" rpy="0 0 0" />
      <geometry>
        <box size="0.01 0.092 0.002" />
        </geometry>
      <material name="trim_gray">
        <color rgba="0.23 0.24 0.25 1" />
        </material>
      </visual>
    <visual name="vent_rib_-0.018">
      <origin xyz="-0.018 -0.004 0.029" rpy="0 0 0" />
      <geometry>
        <box size="0.01 0.092 0.002" />
        </geometry>
      <material name="trim_gray">
        <color rgba="0.23 0.24 0.25 1" />
        </material>
      </visual>
    <visual name="vent_rib_+0.000">
      <origin xyz="0 -0.004 0.029" rpy="0 0 0" />
      <geometry>
        <box size="0.01 0.092 0.002" />
        </geometry>
      <material name="trim_gray">
        <color rgba="0.23 0.24 0.25 1" />
        </material>
      </visual>
    <visual name="vent_rib_+0.018">
      <origin xyz="0.018 -0.004 0.029" rpy="0 0 0" />
      <geometry>
        <box size="0.01 0.092 0.002" />
        </geometry>
      <material name="trim_gray">
        <color rgba="0.23 0.24 0.25 1" />
        </material>
      </visual>
    <visual name="vent_rib_+0.036">
      <origin xyz="0.036 -0.004 0.029" rpy="0 0 0" />
      <geometry>
        <box size="0.01 0.092 0.002" />
        </geometry>
      <material name="trim_gray">
        <color rgba="0.23 0.24 0.25 1" />
        </material>
      </visual>
    <visual name="vent_rib_+0.054">
      <origin xyz="0.054 -0.004 0.029" rpy="0 0 0" />
      <geometry>
        <box size="0.01 0.092 0.002" />
        </geometry>
      <material name="trim_gray">
        <color rgba="0.23 0.24 0.25 1" />
        </material>
      </visual>
    <visual name="antenna_left_outer_pedestal">
      <origin xyz="-0.118 0.078 0.029" rpy="0 0 0" />
      <geometry>
        <box size="0.028 0.018 0.01" />
        </geometry>
      <material name="trim_gray">
        <color rgba="0.23 0.24 0.25 1" />
        </material>
      </visual>
    <visual name="antenna_left_inner_pedestal">
      <origin xyz="-0.04 0.078 0.029" rpy="0 0 0" />
      <geometry>
        <box size="0.028 0.018 0.01" />
        </geometry>
      <material name="trim_gray">
        <color rgba="0.23 0.24 0.25 1" />
        </material>
      </visual>
    <visual name="antenna_right_inner_pedestal">
      <origin xyz="0.04 0.078 0.029" rpy="0 0 0" />
      <geometry>
        <box size="0.028 0.018 0.01" />
        </geometry>
      <material name="trim_gray">
        <color rgba="0.23 0.24 0.25 1" />
        </material>
      </visual>
    <visual name="antenna_right_outer_pedestal">
      <origin xyz="0.118 0.078 0.029" rpy="0 0 0" />
      <geometry>
        <box size="0.028 0.018 0.01" />
        </geometry>
      <material name="trim_gray">
        <color rgba="0.23 0.24 0.25 1" />
        </material>
      </visual>
    </link>
  <link name="antenna_left_outer">
    <inertial>
      <origin xyz="0 0 0.07" rpy="0 0 0" />
      <mass value="0.06" />
      <inertia ixx="9.8375e-05" ixy="0" ixz="0" iyy="9.8375e-05" iyz="0" izz="7.5e-07" />
      </inertial>
    <visual name="hinge_barrel">
      <origin xyz="0 0 0" rpy="0 1.5708 0" />
      <geometry>
        <cylinder radius="0.006" length="0.024" />
        </geometry>
      <material name="trim_gray">
        <color rgba="0.23 0.24 0.25 1" />
        </material>
      </visual>
    <visual name="hinge_collar">
      <origin xyz="0 0 0.006" rpy="0 0 0" />
      <geometry>
        <box size="0.016 0.012 0.008" />
        </geometry>
      <material name="trim_gray">
        <color rgba="0.23 0.24 0.25 1" />
        </material>
      </visual>
    <visual name="main_mast">
      <origin xyz="-0.00557247 0 0.0617491" rpy="0 -0.09 0" />
      <geometry>
        <cylinder radius="0.0048" length="0.112" />
        </geometry>
      <material name="antenna_black">
        <color rgba="0.09 0.09 0.1 1" />
        </material>
      </visual>
    <visual name="upper_tip">
      <origin xyz="-0.0116842 0 0.129474" rpy="0 -0.09 0" />
      <geometry>
        <cylinder radius="0.0034" length="0.024" />
        </geometry>
      <material name="antenna_black">
        <color rgba="0.09 0.09 0.1 1" />
        </material>
      </visual>
    <visual name="end_cap">
      <origin xyz="-0.0130863 0 0.145011" rpy="0 0 0" />
      <geometry>
        <sphere radius="0.0036" />
        </geometry>
      <material name="antenna_black">
        <color rgba="0.09 0.09 0.1 1" />
        </material>
      </visual>
    </link>
  <link name="antenna_left_inner">
    <inertial>
      <origin xyz="0 0 0.07" rpy="0 0 0" />
      <mass value="0.06" />
      <inertia ixx="9.8375e-05" ixy="0" ixz="0" iyy="9.8375e-05" iyz="0" izz="7.5e-07" />
      </inertial>
    <visual name="hinge_barrel">
      <origin xyz="0 0 0" rpy="0 1.5708 0" />
      <geometry>
        <cylinder radius="0.006" length="0.024" />
        </geometry>
      <material name="trim_gray">
        <color rgba="0.23 0.24 0.25 1" />
        </material>
      </visual>
    <visual name="hinge_collar">
      <origin xyz="0 0 0.006" rpy="0 0 0" />
      <geometry>
        <box size="0.016 0.012 0.008" />
        </geometry>
      <material name="trim_gray">
        <color rgba="0.23 0.24 0.25 1" />
        </material>
      </visual>
    <visual name="main_mast">
      <origin xyz="-0.00185972 0 0.0619721" rpy="0 -0.03 0" />
      <geometry>
        <cylinder radius="0.0048" length="0.112" />
        </geometry>
      <material name="antenna_black">
        <color rgba="0.09 0.09 0.1 1" />
        </material>
      </visual>
    <visual name="upper_tip">
      <origin xyz="-0.00389942 0 0.129942" rpy="0 -0.03 0" />
      <geometry>
        <cylinder radius="0.0034" length="0.024" />
        </geometry>
      <material name="antenna_black">
        <color rgba="0.09 0.09 0.1 1" />
        </material>
      </visual>
    <visual name="end_cap">
      <origin xyz="-0.00436734 0 0.145534" rpy="0 0 0" />
      <geometry>
        <sphere radius="0.0036" />
        </geometry>
      <material name="antenna_black">
        <color rgba="0.09 0.09 0.1 1" />
        </material>
      </visual>
    </link>
  <link name="antenna_right_inner">
    <inertial>
      <origin xyz="0 0 0.07" rpy="0 0 0" />
      <mass value="0.06" />
      <inertia ixx="9.8375e-05" ixy="0" ixz="0" iyy="9.8375e-05" iyz="0" izz="7.5e-07" />
      </inertial>
    <visual name="hinge_barrel">
      <origin xyz="0 0 0" rpy="0 1.5708 0" />
      <geometry>
        <cylinder radius="0.006" length="0.024" />
        </geometry>
      <material name="trim_gray">
        <color rgba="0.23 0.24 0.25 1" />
        </material>
      </visual>
    <visual name="hinge_collar">
      <origin xyz="0 0 0.006" rpy="0 0 0" />
      <geometry>
        <box size="0.016 0.012 0.008" />
        </geometry>
      <material name="trim_gray">
        <color rgba="0.23 0.24 0.25 1" />
        </material>
      </visual>
    <visual name="main_mast">
      <origin xyz="0.00185972 0 0.0619721" rpy="0 0.03 0" />
      <geometry>
        <cylinder radius="0.0048" length="0.112" />
        </geometry>
      <material name="antenna_black">
        <color rgba="0.09 0.09 0.1 1" />
        </material>
      </visual>
    <visual name="upper_tip">
      <origin xyz="0.00389942 0 0.129942" rpy="0 0.03 0" />
      <geometry>
        <cylinder radius="0.0034" length="0.024" />
        </geometry>
      <material name="antenna_black">
        <color rgba="0.09 0.09 0.1 1" />
        </material>
      </visual>
    <visual name="end_cap">
      <origin xyz="0.00436734 0 0.145534" rpy="0 0 0" />
      <geometry>
        <sphere radius="0.0036" />
        </geometry>
      <material name="antenna_black">
        <color rgba="0.09 0.09 0.1 1" />
        </material>
      </visual>
    </link>
  <link name="antenna_right_outer">
    <inertial>
      <origin xyz="0 0 0.07" rpy="0 0 0" />
      <mass value="0.06" />
      <inertia ixx="9.8375e-05" ixy="0" ixz="0" iyy="9.8375e-05" iyz="0" izz="7.5e-07" />
      </inertial>
    <visual name="hinge_barrel">
      <origin xyz="0 0 0" rpy="0 1.5708 0" />
      <geometry>
        <cylinder radius="0.006" length="0.024" />
        </geometry>
      <material name="trim_gray">
        <color rgba="0.23 0.24 0.25 1" />
        </material>
      </visual>
    <visual name="hinge_collar">
      <origin xyz="0 0 0.006" rpy="0 0 0" />
      <geometry>
        <box size="0.016 0.012 0.008" />
        </geometry>
      <material name="trim_gray">
        <color rgba="0.23 0.24 0.25 1" />
        </material>
      </visual>
    <visual name="main_mast">
      <origin xyz="0.00557247 0 0.0617491" rpy="0 0.09 0" />
      <geometry>
        <cylinder radius="0.0048" length="0.112" />
        </geometry>
      <material name="antenna_black">
        <color rgba="0.09 0.09 0.1 1" />
        </material>
      </visual>
    <visual name="upper_tip">
      <origin xyz="0.0116842 0 0.129474" rpy="0 0.09 0" />
      <geometry>
        <cylinder radius="0.0034" length="0.024" />
        </geometry>
      <material name="antenna_black">
        <color rgba="0.09 0.09 0.1 1" />
        </material>
      </visual>
    <visual name="end_cap">
      <origin xyz="0.0130863 0 0.145011" rpy="0 0 0" />
      <geometry>
        <sphere radius="0.0036" />
        </geometry>
      <material name="antenna_black">
        <color rgba="0.09 0.09 0.1 1" />
        </material>
      </visual>
    </link>
  <joint name="body_to_antenna_left_outer" type="revolute">
    <origin xyz="-0.118 0.078 0.032" rpy="0 0 0" />
    <parent link="body" />
    <child link="antenna_left_outer" />
    <axis xyz="1 0 0" />
    <limit effort="1.5" velocity="2.5" lower="-1.15" upper="0.35" />
    </joint>
  <joint name="body_to_antenna_left_inner" type="revolute">
    <origin xyz="-0.04 0.078 0.032" rpy="0 0 0" />
    <parent link="body" />
    <child link="antenna_left_inner" />
    <axis xyz="1 0 0" />
    <limit effort="1.5" velocity="2.5" lower="-1.15" upper="0.35" />
    </joint>
  <joint name="body_to_antenna_right_inner" type="revolute">
    <origin xyz="0.04 0.078 0.032" rpy="0 0 0" />
    <parent link="body" />
    <child link="antenna_right_inner" />
    <axis xyz="1 0 0" />
    <limit effort="1.5" velocity="2.5" lower="-1.15" upper="0.35" />
    </joint>
  <joint name="body_to_antenna_right_outer" type="revolute">
    <origin xyz="0.118 0.078 0.032" rpy="0 0 0" />
    <parent link="body" />
    <child link="antenna_right_outer" />
    <axis xyz="1 0 0" />
    <limit effort="1.5" velocity="2.5" lower="-1.15" upper="0.35" />
    </joint>
  </robot>
