<robot name="conventional_oven">
  <material name="stainless_steel">
    <color rgba="0.74 0.76 0.78 1" />
  </material>
  <material name="brushed_metal">
    <color rgba="0.67 0.69 0.71 1" />
  </material>
  <material name="charcoal_enamel">
    <color rgba="0.14 0.15 0.17 1" />
  </material>
  <material name="matte_black">
    <color rgba="0.1 0.1 0.11 1" />
  </material>
  <material name="rubber">
    <color rgba="0.08 0.08 0.08 1" />
  </material>
  <material name="chrome_rack">
    <color rgba="0.82 0.83 0.84 1" />
  </material>
  <material name="smoked_glass">
    <color rgba="0.15 0.18 0.2 0.35" />
  </material>
  <material name="display_glass">
    <color rgba="0.08 0.11 0.14 0.75" />
  </material>
  <material name="indicator_silver">
    <color rgba="0.9 0.91 0.92 1" />
  </material>
  <link name="body">
    <inertial>
      <origin xyz="0 0 0.45" rpy="0 0 0" />
      <mass value="58" />
      <inertia ixx="6.70673" ixy="0" ixz="0" iyy="5.77293" iyz="0" izz="4.64967" />
    </inertial>
    <visual>
      <origin xyz="0 -0.365 0.44" rpy="0 0 0" />
      <geometry>
        <box size="0.6 0.03 0.82" />
      </geometry>
      <material name="stainless_steel">
        <color rgba="0.74 0.76 0.78 1" />
      </material>
    </visual>
    <visual>
      <origin xyz="0 0.365 0.44" rpy="0 0 0" />
      <geometry>
        <box size="0.6 0.03 0.82" />
      </geometry>
      <material name="stainless_steel">
        <color rgba="0.74 0.76 0.78 1" />
      </material>
    </visual>
    <visual>
      <origin xyz="0 0 0.875" rpy="0 0 0" />
      <geometry>
        <box size="0.6 0.76 0.05" />
      </geometry>
      <material name="stainless_steel">
        <color rgba="0.74 0.76 0.78 1" />
      </material>
    </visual>
    <visual>
      <origin xyz="-0.01 0 0.0325" rpy="0 0 0" />
      <geometry>
        <box size="0.56 0.7 0.045" />
      </geometry>
      <material name="stainless_steel">
        <color rgba="0.74 0.76 0.78 1" />
      </material>
    </visual>
    <visual>
      <origin xyz="-0.285 0 0.435" rpy="0 0 0" />
      <geometry>
        <box size="0.03 0.7 0.8" />
      </geometry>
      <material name="stainless_steel">
        <color rgba="0.74 0.76 0.78 1" />
      </material>
    </visual>
    <visual>
      <origin xyz="0.285 -0.365 0.37" rpy="0 0 0" />
      <geometry>
        <box size="0.06 0.03 0.62" />
      </geometry>
      <material name="stainless_steel">
        <color rgba="0.74 0.76 0.78 1" />
      </material>
    </visual>
    <visual>
      <origin xyz="0.285 0.365 0.37" rpy="0 0 0" />
      <geometry>
        <box size="0.06 0.03 0.62" />
      </geometry>
      <material name="stainless_steel">
        <color rgba="0.74 0.76 0.78 1" />
      </material>
    </visual>
    <visual>
      <origin xyz="0.285 0 0.055" rpy="0 0 0" />
      <geometry>
        <box size="0.06 0.73 0.11" />
      </geometry>
      <material name="stainless_steel">
        <color rgba="0.74 0.76 0.78 1" />
      </material>
    </visual>
    <visual>
      <origin xyz="0.285 0 0.6825" rpy="0 0 0" />
      <geometry>
        <box size="0.06 0.73 0.055" />
      </geometry>
      <material name="stainless_steel">
        <color rgba="0.74 0.76 0.78 1" />
      </material>
    </visual>
    <visual>
      <origin xyz="0.285 0 0.73" rpy="0 0 0" />
      <geometry>
        <box size="0.06 0.73 0.04" />
      </geometry>
      <material name="stainless_steel">
        <color rgba="0.74 0.76 0.78 1" />
      </material>
    </visual>
    <visual>
      <origin xyz="0.285 0 0.8125" rpy="0 0 0" />
      <geometry>
        <box size="0.06 0.73 0.125" />
      </geometry>
      <material name="stainless_steel">
        <color rgba="0.74 0.76 0.78 1" />
      </material>
    </visual>
    <visual>
      <origin xyz="0.3075 0 0.885" rpy="0 0 0" />
      <geometry>
        <box size="0.015 0.76 0.03" />
      </geometry>
      <material name="brushed_metal">
        <color rgba="0.67 0.69 0.71 1" />
      </material>
    </visual>
    <visual>
      <origin xyz="0.0025 -0.339 0.39" rpy="0 0 0" />
      <geometry>
        <box size="0.505 0.018 0.55" />
      </geometry>
      <material name="charcoal_enamel">
        <color rgba="0.14 0.15 0.17 1" />
      </material>
    </visual>
    <visual>
      <origin xyz="0.0025 0.339 0.39" rpy="0 0 0" />
      <geometry>
        <box size="0.505 0.018 0.55" />
      </geometry>
      <material name="charcoal_enamel">
        <color rgba="0.14 0.15 0.17 1" />
      </material>
    </visual>
    <visual>
      <origin xyz="0.0025 0 0.116" rpy="0 0 0" />
      <geometry>
        <box size="0.505 0.66 0.018" />
      </geometry>
      <material name="charcoal_enamel">
        <color rgba="0.14 0.15 0.17 1" />
      </material>
    </visual>
    <visual>
      <origin xyz="0.0025 0 0.664" rpy="0 0 0" />
      <geometry>
        <box size="0.505 0.66 0.018" />
      </geometry>
      <material name="charcoal_enamel">
        <color rgba="0.14 0.15 0.17 1" />
      </material>
    </visual>
    <visual>
      <origin xyz="-0.246 0 0.39" rpy="0 0 0" />
      <geometry>
        <box size="0.018 0.66 0.55" />
      </geometry>
      <material name="charcoal_enamel">
        <color rgba="0.14 0.15 0.17 1" />
      </material>
    </visual>
    <visual>
      <origin xyz="0.252 -0.324 0.39" rpy="0 0 0" />
      <geometry>
        <box size="0.01 0.012 0.55" />
      </geometry>
      <material name="matte_black">
        <color rgba="0.1 0.1 0.11 1" />
      </material>
    </visual>
    <visual>
      <origin xyz="0.252 0.324 0.39" rpy="0 0 0" />
      <geometry>
        <box size="0.01 0.012 0.55" />
      </geometry>
      <material name="matte_black">
        <color rgba="0.1 0.1 0.11 1" />
      </material>
    </visual>
    <visual>
      <origin xyz="0.252 0 0.121" rpy="0 0 0" />
      <geometry>
        <box size="0.01 0.64 0.012" />
      </geometry>
      <material name="matte_black">
        <color rgba="0.1 0.1 0.11 1" />
      </material>
    </visual>
    <visual>
      <origin xyz="0.252 0 0.659" rpy="0 0 0" />
      <geometry>
        <box size="0.01 0.64 0.012" />
      </geometry>
      <material name="matte_black">
        <color rgba="0.1 0.1 0.11 1" />
      </material>
    </visual>
    <visual>
      <origin xyz="-0.236 0 0.405" rpy="0 1.5708 0" />
      <geometry>
        <cylinder radius="0.078" length="0.004" />
      </geometry>
      <material name="matte_black">
        <color rgba="0.1 0.1 0.11 1" />
      </material>
    </visual>
    <visual>
      <origin xyz="-0.231 0 0.405" rpy="0 1.5708 0" />
      <geometry>
        <cylinder radius="0.018" length="0.01" />
      </geometry>
      <material name="brushed_metal">
        <color rgba="0.67 0.69 0.71 1" />
      </material>
    </visual>
    <visual>
      <origin xyz="-0.231 0.235 0.58" rpy="0 1.5708 0" />
      <geometry>
        <cylinder radius="0.025" length="0.008" />
      </geometry>
      <material name="smoked_glass">
        <color rgba="0.15 0.18 0.2 0.35" />
      </material>
    </visual>
    <visual>
      <origin xyz="0.005 -0.321 0.276" rpy="0 0 0" />
      <geometry>
        <box size="0.46 0.026 0.006" />
      </geometry>
      <material name="charcoal_enamel">
        <color rgba="0.14 0.15 0.17 1" />
      </material>
    </visual>
    <visual>
      <origin xyz="0.005 0.321 0.276" rpy="0 0 0" />
      <geometry>
        <box size="0.46 0.026 0.006" />
      </geometry>
      <material name="charcoal_enamel">
        <color rgba="0.14 0.15 0.17 1" />
      </material>
    </visual>
    <visual>
      <origin xyz="0.005 0 0.276" rpy="0 0 0" />
      <geometry>
        <mesh filename="meshes/oven_rack.glb" />
      </geometry>
      <material name="chrome_rack">
        <color rgba="0.82 0.83 0.84 1" />
      </material>
    </visual>
    <visual>
      <origin xyz="0.005 -0.321 0.463" rpy="0 0 0" />
      <geometry>
        <box size="0.46 0.026 0.006" />
      </geometry>
      <material name="charcoal_enamel">
        <color rgba="0.14 0.15 0.17 1" />
      </material>
    </visual>
    <visual>
      <origin xyz="0.005 0.321 0.463" rpy="0 0 0" />
      <geometry>
        <box size="0.46 0.026 0.006" />
      </geometry>
      <material name="charcoal_enamel">
        <color rgba="0.14 0.15 0.17 1" />
      </material>
    </visual>
    <visual>
      <origin xyz="0.005 0 0.463" rpy="0 0 0" />
      <geometry>
        <mesh filename="meshes/oven_rack.glb" />
      </geometry>
      <material name="chrome_rack">
        <color rgba="0.82 0.83 0.84 1" />
      </material>
    </visual>
    <visual>
      <origin xyz="0.308 0 0.815" rpy="0 0 0" />
      <geometry>
        <box size="0.008 0.145 0.065" />
      </geometry>
      <material name="matte_black">
        <color rgba="0.1 0.1 0.11 1" />
      </material>
    </visual>
    <visual>
      <origin xyz="0.312 0 0.815" rpy="0 0 0" />
      <geometry>
        <box size="0.002 0.118 0.045" />
      </geometry>
      <material name="display_glass">
        <color rgba="0.08 0.11 0.14 0.75" />
      </material>
    </visual>
    <visual>
      <origin xyz="0.307 -0.085 0.775" rpy="0 0 0" />
      <geometry>
        <box size="0.006 0.022 0.014" />
      </geometry>
      <material name="matte_black">
        <color rgba="0.1 0.1 0.11 1" />
      </material>
    </visual>
    <visual>
      <origin xyz="0.307 -0.04 0.775" rpy="0 0 0" />
      <geometry>
        <box size="0.006 0.022 0.014" />
      </geometry>
      <material name="matte_black">
        <color rgba="0.1 0.1 0.11 1" />
      </material>
    </visual>
    <visual>
      <origin xyz="0.307 0.04 0.775" rpy="0 0 0" />
      <geometry>
        <box size="0.006 0.022 0.014" />
      </geometry>
      <material name="matte_black">
        <color rgba="0.1 0.1 0.11 1" />
      </material>
    </visual>
    <visual>
      <origin xyz="0.307 0.085 0.775" rpy="0 0 0" />
      <geometry>
        <box size="0.006 0.022 0.014" />
      </geometry>
      <material name="matte_black">
        <color rgba="0.1 0.1 0.11 1" />
      </material>
    </visual>
    <visual>
      <origin xyz="0.307 -0.18 0.732" rpy="0 0 0" />
      <geometry>
        <box size="0.003 0.058 0.004" />
      </geometry>
      <material name="matte_black">
        <color rgba="0.1 0.1 0.11 1" />
      </material>
    </visual>
    <visual>
      <origin xyz="0.307 -0.09 0.732" rpy="0 0 0" />
      <geometry>
        <box size="0.003 0.058 0.004" />
      </geometry>
      <material name="matte_black">
        <color rgba="0.1 0.1 0.11 1" />
      </material>
    </visual>
    <visual>
      <origin xyz="0.307 0 0.732" rpy="0 0 0" />
      <geometry>
        <box size="0.003 0.058 0.004" />
      </geometry>
      <material name="matte_black">
        <color rgba="0.1 0.1 0.11 1" />
      </material>
    </visual>
    <visual>
      <origin xyz="0.307 0.09 0.732" rpy="0 0 0" />
      <geometry>
        <box size="0.003 0.058 0.004" />
      </geometry>
      <material name="matte_black">
        <color rgba="0.1 0.1 0.11 1" />
      </material>
    </visual>
    <visual>
      <origin xyz="0.307 0.18 0.732" rpy="0 0 0" />
      <geometry>
        <box size="0.003 0.058 0.004" />
      </geometry>
      <material name="matte_black">
        <color rgba="0.1 0.1 0.11 1" />
      </material>
    </visual>
    <visual>
      <origin xyz="0.313 -0.27 0.822" rpy="0 1.5708 0" />
      <geometry>
        <cylinder radius="0.032" length="0.004" />
      </geometry>
      <material name="matte_black">
        <color rgba="0.1 0.1 0.11 1" />
      </material>
    </visual>
    <visual>
      <origin xyz="0.313 -0.09 0.822" rpy="0 1.5708 0" />
      <geometry>
        <cylinder radius="0.032" length="0.004" />
      </geometry>
      <material name="matte_black">
        <color rgba="0.1 0.1 0.11 1" />
      </material>
    </visual>
    <visual>
      <origin xyz="0.313 0.09 0.822" rpy="0 1.5708 0" />
      <geometry>
        <cylinder radius="0.032" length="0.004" />
      </geometry>
      <material name="matte_black">
        <color rgba="0.1 0.1 0.11 1" />
      </material>
    </visual>
    <visual>
      <origin xyz="0.313 0.27 0.822" rpy="0 1.5708 0" />
      <geometry>
        <cylinder radius="0.032" length="0.004" />
      </geometry>
      <material name="matte_black">
        <color rgba="0.1 0.1 0.11 1" />
      </material>
    </visual>
    <visual>
      <origin xyz="-0.26 -0.31 0.01" rpy="0 0 0" />
      <geometry>
        <cylinder radius="0.022" length="0.02" />
      </geometry>
      <material name="rubber">
        <color rgba="0.08 0.08 0.08 1" />
      </material>
    </visual>
    <visual>
      <origin xyz="-0.26 0.31 0.01" rpy="0 0 0" />
      <geometry>
        <cylinder radius="0.022" length="0.02" />
      </geometry>
      <material name="rubber">
        <color rgba="0.08 0.08 0.08 1" />
      </material>
    </visual>
    <visual>
      <origin xyz="0.26 -0.31 0.01" rpy="0 0 0" />
      <geometry>
        <cylinder radius="0.022" length="0.02" />
      </geometry>
      <material name="rubber">
        <color rgba="0.08 0.08 0.08 1" />
      </material>
    </visual>
    <visual>
      <origin xyz="0.26 0.31 0.01" rpy="0 0 0" />
      <geometry>
        <cylinder radius="0.022" length="0.02" />
      </geometry>
      <material name="rubber">
        <color rgba="0.08 0.08 0.08 1" />
      </material>
    </visual>
    <collision name="body__visual_1">
      <origin xyz="0 -0.365 0.44" rpy="0 0 0" />
      <geometry>
        <box size="0.6 0.03 0.82" />
      </geometry>
    </collision>
    <collision name="body__visual_2">
      <origin xyz="0 0.365 0.44" rpy="0 0 0" />
      <geometry>
        <box size="0.6 0.03 0.82" />
      </geometry>
    </collision>
    <collision name="body__visual_3">
      <origin xyz="0 0 0.875" rpy="0 0 0" />
      <geometry>
        <box size="0.6 0.76 0.05" />
      </geometry>
    </collision>
    <collision name="body__visual_4">
      <origin xyz="-0.01 0 0.0325" rpy="0 0 0" />
      <geometry>
        <box size="0.56 0.7 0.045" />
      </geometry>
    </collision>
    <collision name="body__visual_5">
      <origin xyz="-0.285 0 0.435" rpy="0 0 0" />
      <geometry>
        <box size="0.03 0.7 0.8" />
      </geometry>
    </collision>
    <collision name="body__visual_6">
      <origin xyz="0.285 -0.365 0.37" rpy="0 0 0" />
      <geometry>
        <box size="0.06 0.03 0.62" />
      </geometry>
    </collision>
    <collision name="body__visual_7">
      <origin xyz="0.285 0.365 0.37" rpy="0 0 0" />
      <geometry>
        <box size="0.06 0.03 0.62" />
      </geometry>
    </collision>
    <collision name="body__visual_8">
      <origin xyz="0.285 0 0.055" rpy="0 0 0" />
      <geometry>
        <box size="0.06 0.73 0.11" />
      </geometry>
    </collision>
    <collision name="body__visual_9">
      <origin xyz="0.285 0 0.6825" rpy="0 0 0" />
      <geometry>
        <box size="0.06 0.73 0.055" />
      </geometry>
    </collision>
    <collision name="body__visual_10">
      <origin xyz="0.285 0 0.73" rpy="0 0 0" />
      <geometry>
        <box size="0.06 0.73 0.04" />
      </geometry>
    </collision>
    <collision name="body__visual_11">
      <origin xyz="0.285 0 0.8125" rpy="0 0 0" />
      <geometry>
        <box size="0.06 0.73 0.125" />
      </geometry>
    </collision>
    <collision name="body__visual_12">
      <origin xyz="0.3075 0 0.885" rpy="0 0 0" />
      <geometry>
        <box size="0.015 0.76 0.03" />
      </geometry>
    </collision>
    <collision name="body__visual_13">
      <origin xyz="0.0025 -0.339 0.39" rpy="0 0 0" />
      <geometry>
        <box size="0.505 0.018 0.55" />
      </geometry>
    </collision>
    <collision name="body__visual_14">
      <origin xyz="0.0025 0.339 0.39" rpy="0 0 0" />
      <geometry>
        <box size="0.505 0.018 0.55" />
      </geometry>
    </collision>
    <collision name="body__visual_15">
      <origin xyz="0.0025 0 0.116" rpy="0 0 0" />
      <geometry>
        <box size="0.505 0.66 0.018" />
      </geometry>
    </collision>
    <collision name="body__visual_16">
      <origin xyz="0.0025 0 0.664" rpy="0 0 0" />
      <geometry>
        <box size="0.505 0.66 0.018" />
      </geometry>
    </collision>
    <collision name="body__visual_17">
      <origin xyz="-0.246 0 0.39" rpy="0 0 0" />
      <geometry>
        <box size="0.018 0.66 0.55" />
      </geometry>
    </collision>
    <collision name="body__visual_18">
      <origin xyz="0.252 -0.324 0.39" rpy="0 0 0" />
      <geometry>
        <box size="0.01 0.012 0.55" />
      </geometry>
    </collision>
    <collision name="body__visual_19">
      <origin xyz="0.252 0.324 0.39" rpy="0 0 0" />
      <geometry>
        <box size="0.01 0.012 0.55" />
      </geometry>
    </collision>
    <collision name="body__visual_20">
      <origin xyz="0.252 0 0.121" rpy="0 0 0" />
      <geometry>
        <box size="0.01 0.64 0.012" />
      </geometry>
    </collision>
    <collision name="body__visual_21">
      <origin xyz="0.252 0 0.659" rpy="0 0 0" />
      <geometry>
        <box size="0.01 0.64 0.012" />
      </geometry>
    </collision>
    <collision name="body__visual_22">
      <origin xyz="-0.236 0 0.405" rpy="0 1.5708 0" />
      <geometry>
        <cylinder radius="0.078" length="0.004" />
      </geometry>
    </collision>
    <collision name="body__visual_23">
      <origin xyz="-0.231 0 0.405" rpy="0 1.5708 0" />
      <geometry>
        <cylinder radius="0.018" length="0.01" />
      </geometry>
    </collision>
    <collision name="body__visual_24">
      <origin xyz="-0.231 0.235 0.58" rpy="0 1.5708 0" />
      <geometry>
        <cylinder radius="0.025" length="0.008" />
      </geometry>
    </collision>
    <collision name="body__visual_25">
      <origin xyz="0.005 -0.321 0.276" rpy="0 0 0" />
      <geometry>
        <box size="0.46 0.026 0.006" />
      </geometry>
    </collision>
    <collision name="body__visual_26">
      <origin xyz="0.005 0.321 0.276" rpy="0 0 0" />
      <geometry>
        <box size="0.46 0.026 0.006" />
      </geometry>
    </collision>
    <collision name="body__visual_27__hull_001">
      <origin xyz="0.005 0 0.276" rpy="0 0 0" />
      <geometry>
        <mesh filename="meshes/collision/cache/5aa86e798744a3d0bfeb0429__hull_001.obj" />
      </geometry>
    </collision>
    <collision name="body__visual_27__hull_002">
      <origin xyz="0.005 0 0.276" rpy="0 0 0" />
      <geometry>
        <mesh filename="meshes/collision/cache/5aa86e798744a3d0bfeb0429__hull_002.obj" />
      </geometry>
    </collision>
    <collision name="body__visual_27__hull_003">
      <origin xyz="0.005 0 0.276" rpy="0 0 0" />
      <geometry>
        <mesh filename="meshes/collision/cache/5aa86e798744a3d0bfeb0429__hull_003.obj" />
      </geometry>
    </collision>
    <collision name="body__visual_27__hull_004">
      <origin xyz="0.005 0 0.276" rpy="0 0 0" />
      <geometry>
        <mesh filename="meshes/collision/cache/5aa86e798744a3d0bfeb0429__hull_004.obj" />
      </geometry>
    </collision>
    <collision name="body__visual_27__hull_005">
      <origin xyz="0.005 0 0.276" rpy="0 0 0" />
      <geometry>
        <mesh filename="meshes/collision/cache/5aa86e798744a3d0bfeb0429__hull_005.obj" />
      </geometry>
    </collision>
    <collision name="body__visual_27__hull_006">
      <origin xyz="0.005 0 0.276" rpy="0 0 0" />
      <geometry>
        <mesh filename="meshes/collision/cache/5aa86e798744a3d0bfeb0429__hull_006.obj" />
      </geometry>
    </collision>
    <collision name="body__visual_27__hull_007">
      <origin xyz="0.005 0 0.276" rpy="0 0 0" />
      <geometry>
        <mesh filename="meshes/collision/cache/5aa86e798744a3d0bfeb0429__hull_007.obj" />
      </geometry>
    </collision>
    <collision name="body__visual_27__hull_008">
      <origin xyz="0.005 0 0.276" rpy="0 0 0" />
      <geometry>
        <mesh filename="meshes/collision/cache/5aa86e798744a3d0bfeb0429__hull_008.obj" />
      </geometry>
    </collision>
    <collision name="body__visual_27__hull_009">
      <origin xyz="0.005 0 0.276" rpy="0 0 0" />
      <geometry>
        <mesh filename="meshes/collision/cache/5aa86e798744a3d0bfeb0429__hull_009.obj" />
      </geometry>
    </collision>
    <collision name="body__visual_28">
      <origin xyz="0.005 -0.321 0.463" rpy="0 0 0" />
      <geometry>
        <box size="0.46 0.026 0.006" />
      </geometry>
    </collision>
    <collision name="body__visual_29">
      <origin xyz="0.005 0.321 0.463" rpy="0 0 0" />
      <geometry>
        <box size="0.46 0.026 0.006" />
      </geometry>
    </collision>
    <collision name="body__visual_30__hull_001">
      <origin xyz="0.005 0 0.463" rpy="0 0 0" />
      <geometry>
        <mesh filename="meshes/collision/cache/5aa86e798744a3d0bfeb0429__hull_001.obj" />
      </geometry>
    </collision>
    <collision name="body__visual_30__hull_002">
      <origin xyz="0.005 0 0.463" rpy="0 0 0" />
      <geometry>
        <mesh filename="meshes/collision/cache/5aa86e798744a3d0bfeb0429__hull_002.obj" />
      </geometry>
    </collision>
    <collision name="body__visual_30__hull_003">
      <origin xyz="0.005 0 0.463" rpy="0 0 0" />
      <geometry>
        <mesh filename="meshes/collision/cache/5aa86e798744a3d0bfeb0429__hull_003.obj" />
      </geometry>
    </collision>
    <collision name="body__visual_30__hull_004">
      <origin xyz="0.005 0 0.463" rpy="0 0 0" />
      <geometry>
        <mesh filename="meshes/collision/cache/5aa86e798744a3d0bfeb0429__hull_004.obj" />
      </geometry>
    </collision>
    <collision name="body__visual_30__hull_005">
      <origin xyz="0.005 0 0.463" rpy="0 0 0" />
      <geometry>
        <mesh filename="meshes/collision/cache/5aa86e798744a3d0bfeb0429__hull_005.obj" />
      </geometry>
    </collision>
    <collision name="body__visual_30__hull_006">
      <origin xyz="0.005 0 0.463" rpy="0 0 0" />
      <geometry>
        <mesh filename="meshes/collision/cache/5aa86e798744a3d0bfeb0429__hull_006.obj" />
      </geometry>
    </collision>
    <collision name="body__visual_30__hull_007">
      <origin xyz="0.005 0 0.463" rpy="0 0 0" />
      <geometry>
        <mesh filename="meshes/collision/cache/5aa86e798744a3d0bfeb0429__hull_007.obj" />
      </geometry>
    </collision>
    <collision name="body__visual_30__hull_008">
      <origin xyz="0.005 0 0.463" rpy="0 0 0" />
      <geometry>
        <mesh filename="meshes/collision/cache/5aa86e798744a3d0bfeb0429__hull_008.obj" />
      </geometry>
    </collision>
    <collision name="body__visual_30__hull_009">
      <origin xyz="0.005 0 0.463" rpy="0 0 0" />
      <geometry>
        <mesh filename="meshes/collision/cache/5aa86e798744a3d0bfeb0429__hull_009.obj" />
      </geometry>
    </collision>
    <collision name="body__visual_31">
      <origin xyz="0.308 0 0.815" rpy="0 0 0" />
      <geometry>
        <box size="0.008 0.145 0.065" />
      </geometry>
    </collision>
    <collision name="body__visual_32">
      <origin xyz="0.312 0 0.815" rpy="0 0 0" />
      <geometry>
        <box size="0.002 0.118 0.045" />
      </geometry>
    </collision>
    <collision name="body__visual_33">
      <origin xyz="0.307 -0.085 0.775" rpy="0 0 0" />
      <geometry>
        <box size="0.006 0.022 0.014" />
      </geometry>
    </collision>
    <collision name="body__visual_34">
      <origin xyz="0.307 -0.04 0.775" rpy="0 0 0" />
      <geometry>
        <box size="0.006 0.022 0.014" />
      </geometry>
    </collision>
    <collision name="body__visual_35">
      <origin xyz="0.307 0.04 0.775" rpy="0 0 0" />
      <geometry>
        <box size="0.006 0.022 0.014" />
      </geometry>
    </collision>
    <collision name="body__visual_36">
      <origin xyz="0.307 0.085 0.775" rpy="0 0 0" />
      <geometry>
        <box size="0.006 0.022 0.014" />
      </geometry>
    </collision>
    <collision name="body__visual_37">
      <origin xyz="0.307 -0.18 0.732" rpy="0 0 0" />
      <geometry>
        <box size="0.003 0.058 0.004" />
      </geometry>
    </collision>
    <collision name="body__visual_38">
      <origin xyz="0.307 -0.09 0.732" rpy="0 0 0" />
      <geometry>
        <box size="0.003 0.058 0.004" />
      </geometry>
    </collision>
    <collision name="body__visual_39">
      <origin xyz="0.307 0 0.732" rpy="0 0 0" />
      <geometry>
        <box size="0.003 0.058 0.004" />
      </geometry>
    </collision>
    <collision name="body__visual_40">
      <origin xyz="0.307 0.09 0.732" rpy="0 0 0" />
      <geometry>
        <box size="0.003 0.058 0.004" />
      </geometry>
    </collision>
    <collision name="body__visual_41">
      <origin xyz="0.307 0.18 0.732" rpy="0 0 0" />
      <geometry>
        <box size="0.003 0.058 0.004" />
      </geometry>
    </collision>
    <collision name="body__visual_42">
      <origin xyz="0.313 -0.27 0.822" rpy="0 1.5708 0" />
      <geometry>
        <cylinder radius="0.032" length="0.004" />
      </geometry>
    </collision>
    <collision name="body__visual_43">
      <origin xyz="0.313 -0.09 0.822" rpy="0 1.5708 0" />
      <geometry>
        <cylinder radius="0.032" length="0.004" />
      </geometry>
    </collision>
    <collision name="body__visual_44">
      <origin xyz="0.313 0.09 0.822" rpy="0 1.5708 0" />
      <geometry>
        <cylinder radius="0.032" length="0.004" />
      </geometry>
    </collision>
    <collision name="body__visual_45">
      <origin xyz="0.313 0.27 0.822" rpy="0 1.5708 0" />
      <geometry>
        <cylinder radius="0.032" length="0.004" />
      </geometry>
    </collision>
    <collision name="body__visual_46">
      <origin xyz="-0.26 -0.31 0.01" rpy="0 0 0" />
      <geometry>
        <cylinder radius="0.022" length="0.02" />
      </geometry>
    </collision>
    <collision name="body__visual_47">
      <origin xyz="-0.26 0.31 0.01" rpy="0 0 0" />
      <geometry>
        <cylinder radius="0.022" length="0.02" />
      </geometry>
    </collision>
    <collision name="body__visual_48">
      <origin xyz="0.26 -0.31 0.01" rpy="0 0 0" />
      <geometry>
        <cylinder radius="0.022" length="0.02" />
      </geometry>
    </collision>
    <collision name="body__visual_49">
      <origin xyz="0.26 0.31 0.01" rpy="0 0 0" />
      <geometry>
        <cylinder radius="0.022" length="0.02" />
      </geometry>
    </collision>
  </link>
  <link name="door">
    <inertial>
      <origin xyz="0.0225 0 0.3" rpy="0 0 0" />
      <mass value="9" />
      <inertia ixx="0.6588" ixy="0" ixz="0" iyy="0.271519" iyz="0" izz="0.390319" />
    </inertial>
    <visual>
      <origin xyz="0.02 0 0.3" rpy="0 0 0" />
      <geometry>
        <box size="0.04 0.72 0.6" />
      </geometry>
      <material name="stainless_steel">
        <color rgba="0.74 0.76 0.78 1" />
      </material>
    </visual>
    <visual>
      <origin xyz="0.039 0 0.31" rpy="0 0 0" />
      <geometry>
        <box size="0.004 0.56 0.38" />
      </geometry>
      <material name="matte_black">
        <color rgba="0.1 0.1 0.11 1" />
      </material>
    </visual>
    <visual>
      <origin xyz="0.042 0 0.31" rpy="0 0 0" />
      <geometry>
        <box size="0.006 0.44 0.26" />
      </geometry>
      <material name="smoked_glass">
        <color rgba="0.15 0.18 0.2 0.35" />
      </material>
    </visual>
    <visual>
      <origin xyz="0.014 0 0.275" rpy="0 0 0" />
      <geometry>
        <box size="0.024 0.64 0.48" />
      </geometry>
      <material name="charcoal_enamel">
        <color rgba="0.14 0.15 0.17 1" />
      </material>
    </visual>
    <visual>
      <origin xyz="0.02 0 0.29" rpy="0 0 0" />
      <geometry>
        <box size="0.004 0.4 0.22" />
      </geometry>
      <material name="smoked_glass">
        <color rgba="0.15 0.18 0.2 0.35" />
      </material>
    </visual>
    <visual>
      <origin xyz="0.039 0 0.145" rpy="0 0 0" />
      <geometry>
        <box size="0.004 0.58 0.018" />
      </geometry>
      <material name="brushed_metal">
        <color rgba="0.67 0.69 0.71 1" />
      </material>
    </visual>
    <visual>
      <origin xyz="0.085 0 0.515" rpy="1.5708 0 0" />
      <geometry>
        <cylinder radius="0.014" length="0.54" />
      </geometry>
      <material name="brushed_metal">
        <color rgba="0.67 0.69 0.71 1" />
      </material>
    </visual>
    <visual>
      <origin xyz="0.055 -0.255 0.515" rpy="0 1.5708 0" />
      <geometry>
        <cylinder radius="0.01" length="0.06" />
      </geometry>
      <material name="brushed_metal">
        <color rgba="0.67 0.69 0.71 1" />
      </material>
    </visual>
    <visual>
      <origin xyz="0.055 0.255 0.515" rpy="0 1.5708 0" />
      <geometry>
        <cylinder radius="0.01" length="0.06" />
      </geometry>
      <material name="brushed_metal">
        <color rgba="0.67 0.69 0.71 1" />
      </material>
    </visual>
    <collision name="door__visual_1">
      <origin xyz="0.02 0 0.3" rpy="0 0 0" />
      <geometry>
        <box size="0.04 0.72 0.6" />
      </geometry>
    </collision>
    <collision name="door__visual_2">
      <origin xyz="0.039 0 0.31" rpy="0 0 0" />
      <geometry>
        <box size="0.004 0.56 0.38" />
      </geometry>
    </collision>
    <collision name="door__visual_3">
      <origin xyz="0.042 0 0.31" rpy="0 0 0" />
      <geometry>
        <box size="0.006 0.44 0.26" />
      </geometry>
    </collision>
    <collision name="door__visual_4">
      <origin xyz="0.014 0 0.275" rpy="0 0 0" />
      <geometry>
        <box size="0.024 0.64 0.48" />
      </geometry>
    </collision>
    <collision name="door__visual_5">
      <origin xyz="0.02 0 0.29" rpy="0 0 0" />
      <geometry>
        <box size="0.004 0.4 0.22" />
      </geometry>
    </collision>
    <collision name="door__visual_6">
      <origin xyz="0.039 0 0.145" rpy="0 0 0" />
      <geometry>
        <box size="0.004 0.58 0.018" />
      </geometry>
    </collision>
    <collision name="door__visual_7">
      <origin xyz="0.085 0 0.515" rpy="1.5708 0 0" />
      <geometry>
        <cylinder radius="0.014" length="0.54" />
      </geometry>
    </collision>
    <collision name="door__visual_8">
      <origin xyz="0.055 -0.255 0.515" rpy="0 1.5708 0" />
      <geometry>
        <cylinder radius="0.01" length="0.06" />
      </geometry>
    </collision>
    <collision name="door__visual_9">
      <origin xyz="0.055 0.255 0.515" rpy="0 1.5708 0" />
      <geometry>
        <cylinder radius="0.01" length="0.06" />
      </geometry>
    </collision>
  </link>
  <link name="knob_left_outer">
    <inertial>
      <origin xyz="0.027 0 0" rpy="0 0 0" />
      <mass value="0.12" />
      <inertia ixx="4.232e-05" ixy="0" ixz="0" iyy="5.032e-05" iyz="0" izz="5.032e-05" />
    </inertial>
    <visual>
      <origin xyz="0.007 0 0" rpy="0 1.5708 0" />
      <geometry>
        <cylinder radius="0.006" length="0.014" />
      </geometry>
      <material name="matte_black">
        <color rgba="0.1 0.1 0.11 1" />
      </material>
    </visual>
    <visual>
      <origin xyz="0.012 0 0" rpy="0 0 0" />
      <geometry>
        <mesh filename="meshes/oven_knob.glb" />
      </geometry>
      <material name="brushed_metal">
        <color rgba="0.67 0.69 0.71 1" />
      </material>
    </visual>
    <visual>
      <origin xyz="0.046 0 0.01" rpy="0 0 0" />
      <geometry>
        <box size="0.006 0.004 0.012" />
      </geometry>
      <material name="indicator_silver">
        <color rgba="0.9 0.91 0.92 1" />
      </material>
    </visual>
    <collision name="knob_left_outer__visual_1">
      <origin xyz="0.007 0 0" rpy="0 1.5708 0" />
      <geometry>
        <cylinder radius="0.006" length="0.014" />
      </geometry>
    </collision>
    <collision name="knob_left_outer__visual_2__hull_001">
      <origin xyz="0.012 0 0" rpy="0 0 0" />
      <geometry>
        <mesh filename="meshes/collision/cache/20d692170c2c46d5f72ab93c__hull_001.obj" />
      </geometry>
    </collision>
    <collision name="knob_left_outer__visual_3">
      <origin xyz="0.046 0 0.01" rpy="0 0 0" />
      <geometry>
        <box size="0.006 0.004 0.012" />
      </geometry>
    </collision>
  </link>
  <link name="knob_left_inner">
    <inertial>
      <origin xyz="0.027 0 0" rpy="0 0 0" />
      <mass value="0.12" />
      <inertia ixx="4.232e-05" ixy="0" ixz="0" iyy="5.032e-05" iyz="0" izz="5.032e-05" />
    </inertial>
    <visual>
      <origin xyz="0.007 0 0" rpy="0 1.5708 0" />
      <geometry>
        <cylinder radius="0.006" length="0.014" />
      </geometry>
      <material name="matte_black">
        <color rgba="0.1 0.1 0.11 1" />
      </material>
    </visual>
    <visual>
      <origin xyz="0.012 0 0" rpy="0 0 0" />
      <geometry>
        <mesh filename="meshes/oven_knob.glb" />
      </geometry>
      <material name="brushed_metal">
        <color rgba="0.67 0.69 0.71 1" />
      </material>
    </visual>
    <visual>
      <origin xyz="0.046 0 0.01" rpy="0 0 0" />
      <geometry>
        <box size="0.006 0.004 0.012" />
      </geometry>
      <material name="indicator_silver">
        <color rgba="0.9 0.91 0.92 1" />
      </material>
    </visual>
    <collision name="knob_left_inner__visual_1">
      <origin xyz="0.007 0 0" rpy="0 1.5708 0" />
      <geometry>
        <cylinder radius="0.006" length="0.014" />
      </geometry>
    </collision>
    <collision name="knob_left_inner__visual_2__hull_001">
      <origin xyz="0.012 0 0" rpy="0 0 0" />
      <geometry>
        <mesh filename="meshes/collision/cache/20d692170c2c46d5f72ab93c__hull_001.obj" />
      </geometry>
    </collision>
    <collision name="knob_left_inner__visual_3">
      <origin xyz="0.046 0 0.01" rpy="0 0 0" />
      <geometry>
        <box size="0.006 0.004 0.012" />
      </geometry>
    </collision>
  </link>
  <link name="knob_right_inner">
    <inertial>
      <origin xyz="0.027 0 0" rpy="0 0 0" />
      <mass value="0.12" />
      <inertia ixx="4.232e-05" ixy="0" ixz="0" iyy="5.032e-05" iyz="0" izz="5.032e-05" />
    </inertial>
    <visual>
      <origin xyz="0.007 0 0" rpy="0 1.5708 0" />
      <geometry>
        <cylinder radius="0.006" length="0.014" />
      </geometry>
      <material name="matte_black">
        <color rgba="0.1 0.1 0.11 1" />
      </material>
    </visual>
    <visual>
      <origin xyz="0.012 0 0" rpy="0 0 0" />
      <geometry>
        <mesh filename="meshes/oven_knob.glb" />
      </geometry>
      <material name="brushed_metal">
        <color rgba="0.67 0.69 0.71 1" />
      </material>
    </visual>
    <visual>
      <origin xyz="0.046 0 0.01" rpy="0 0 0" />
      <geometry>
        <box size="0.006 0.004 0.012" />
      </geometry>
      <material name="indicator_silver">
        <color rgba="0.9 0.91 0.92 1" />
      </material>
    </visual>
    <collision name="knob_right_inner__visual_1">
      <origin xyz="0.007 0 0" rpy="0 1.5708 0" />
      <geometry>
        <cylinder radius="0.006" length="0.014" />
      </geometry>
    </collision>
    <collision name="knob_right_inner__visual_2__hull_001">
      <origin xyz="0.012 0 0" rpy="0 0 0" />
      <geometry>
        <mesh filename="meshes/collision/cache/20d692170c2c46d5f72ab93c__hull_001.obj" />
      </geometry>
    </collision>
    <collision name="knob_right_inner__visual_3">
      <origin xyz="0.046 0 0.01" rpy="0 0 0" />
      <geometry>
        <box size="0.006 0.004 0.012" />
      </geometry>
    </collision>
  </link>
  <link name="knob_right_outer">
    <inertial>
      <origin xyz="0.027 0 0" rpy="0 0 0" />
      <mass value="0.12" />
      <inertia ixx="4.232e-05" ixy="0" ixz="0" iyy="5.032e-05" iyz="0" izz="5.032e-05" />
    </inertial>
    <visual>
      <origin xyz="0.007 0 0" rpy="0 1.5708 0" />
      <geometry>
        <cylinder radius="0.006" length="0.014" />
      </geometry>
      <material name="matte_black">
        <color rgba="0.1 0.1 0.11 1" />
      </material>
    </visual>
    <visual>
      <origin xyz="0.012 0 0" rpy="0 0 0" />
      <geometry>
        <mesh filename="meshes/oven_knob.glb" />
      </geometry>
      <material name="brushed_metal">
        <color rgba="0.67 0.69 0.71 1" />
      </material>
    </visual>
    <visual>
      <origin xyz="0.046 0 0.01" rpy="0 0 0" />
      <geometry>
        <box size="0.006 0.004 0.012" />
      </geometry>
      <material name="indicator_silver">
        <color rgba="0.9 0.91 0.92 1" />
      </material>
    </visual>
    <collision name="knob_right_outer__visual_1">
      <origin xyz="0.007 0 0" rpy="0 1.5708 0" />
      <geometry>
        <cylinder radius="0.006" length="0.014" />
      </geometry>
    </collision>
    <collision name="knob_right_outer__visual_2__hull_001">
      <origin xyz="0.012 0 0" rpy="0 0 0" />
      <geometry>
        <mesh filename="meshes/collision/cache/20d692170c2c46d5f72ab93c__hull_001.obj" />
      </geometry>
    </collision>
    <collision name="knob_right_outer__visual_3">
      <origin xyz="0.046 0 0.01" rpy="0 0 0" />
      <geometry>
        <box size="0.006 0.004 0.012" />
      </geometry>
    </collision>
  </link>
  <joint name="door_hinge" type="revolute">
    <origin xyz="0.316 0 0.105" rpy="0 0 0" />
    <parent link="body" />
    <child link="door" />
    <axis xyz="0 1 0" />
    <limit effort="90" velocity="1.5" lower="0" upper="1.55" />
  </joint>
  <joint name="knob_left_outer_joint" type="revolute">
    <origin xyz="0.316 -0.27 0.822" rpy="0 0 0" />
    <parent link="body" />
    <child link="knob_left_outer" />
    <axis xyz="1 0 0" />
    <limit effort="0.7" velocity="4" lower="-2.35" upper="2.35" />
  </joint>
  <joint name="knob_left_inner_joint" type="revolute">
    <origin xyz="0.316 -0.09 0.822" rpy="0 0 0" />
    <parent link="body" />
    <child link="knob_left_inner" />
    <axis xyz="1 0 0" />
    <limit effort="0.7" velocity="4" lower="-2.35" upper="2.35" />
  </joint>
  <joint name="knob_right_inner_joint" type="revolute">
    <origin xyz="0.316 0.09 0.822" rpy="0 0 0" />
    <parent link="body" />
    <child link="knob_right_inner" />
    <axis xyz="1 0 0" />
    <limit effort="0.7" velocity="4" lower="-2.35" upper="2.35" />
  </joint>
  <joint name="knob_right_outer_joint" type="revolute">
    <origin xyz="0.316 0.27 0.822" rpy="0 0 0" />
    <parent link="body" />
    <child link="knob_right_outer" />
    <axis xyz="1 0 0" />
    <limit effort="0.7" velocity="4" lower="-2.35" upper="2.35" />
  </joint>
</robot>