<robot name="precision_tripod_device">
  <material name="satin_black">
    <color rgba="0.12 0.12 0.13 1" />
    </material>
  <material name="carbon_fiber">
    <color rgba="0.18 0.19 0.21 1" />
    </material>
  <material name="machined_aluminum">
    <color rgba="0.64 0.66 0.69 1" />
    </material>
  <material name="soft_rubber">
    <color rgba="0.06 0.06 0.06 1" />
    </material>
  <material name="lens_glass">
    <color rgba="0.58 0.7 0.84 0.36" />
    </material>
  <material name="accent_red">
    <color rgba="0.64 0.14 0.12 1" />
    </material>
  <link name="spider">
    <inertial>
      <origin xyz="0 0 0.06" rpy="0 0 0" />
      <mass value="1.4" />
      <inertia ixx="0.003885" ixy="0" ixz="0" iyy="0.003885" iyz="0" izz="0.00252" />
      </inertial>
    <visual>
      <geometry>
        <cylinder radius="0.055" length="0.028" />
        </geometry>
      <material name="machined_aluminum">
        <color rgba="0.64 0.66 0.69 1" />
        </material>
      </visual>
    <visual>
      <origin xyz="0 0 0.018" rpy="0 0 0" />
      <geometry>
        <cylinder radius="0.044" length="0.012" />
        </geometry>
      <material name="satin_black">
        <color rgba="0.12 0.12 0.13 1" />
        </material>
      </visual>
    <visual>
      <origin xyz="0 0 0.026" rpy="0 0 0" />
      <geometry>
        <cylinder radius="0.032" length="0.022" />
        </geometry>
      <material name="machined_aluminum">
        <color rgba="0.64 0.66 0.69 1" />
        </material>
      </visual>
    <visual>
      <origin xyz="0 0 0.074" rpy="0 0 0" />
      <geometry>
        <cylinder radius="0.024" length="0.11" />
        </geometry>
      <material name="machined_aluminum">
        <color rgba="0.64 0.66 0.69 1" />
        </material>
      </visual>
    <visual>
      <origin xyz="0 0 0.025" rpy="0 0 0" />
      <geometry>
        <cylinder radius="0.012" length="0.004" />
        </geometry>
      <material name="lens_glass">
        <color rgba="0.58 0.7 0.84 0.36" />
        </material>
      </visual>
    <visual>
      <origin xyz="0.0686488 0 -0.0374895" rpy="0 2.53073 0" />
      <geometry>
        <cylinder radius="0.02" length="0.072" />
        </geometry>
      <material name="satin_black">
        <color rgba="0.12 0.12 0.13 1" />
        </material>
      </visual>
    <visual>
      <origin xyz="0.0694715 0 -0.024383" rpy="0 0 0" />
      <geometry>
        <box size="0.024 0.04 0.03" />
        </geometry>
      <material name="satin_black">
        <color rgba="0.12 0.12 0.13 1" />
        </material>
      </visual>
    <visual>
      <origin xyz="-0.0343244 0.0594516 -0.0374895" rpy="0 2.53073 2.0944" />
      <geometry>
        <cylinder radius="0.02" length="0.072" />
        </geometry>
      <material name="satin_black">
        <color rgba="0.12 0.12 0.13 1" />
        </material>
      </visual>
    <visual>
      <origin xyz="-0.0347358 0.0601641 -0.024383" rpy="0 0 2.0944" />
      <geometry>
        <box size="0.024 0.04 0.03" />
        </geometry>
      <material name="satin_black">
        <color rgba="0.12 0.12 0.13 1" />
        </material>
      </visual>
    <visual>
      <origin xyz="-0.0343244 -0.0594516 -0.0374895" rpy="0 2.53073 4.18879" />
      <geometry>
        <cylinder radius="0.02" length="0.072" />
        </geometry>
      <material name="satin_black">
        <color rgba="0.12 0.12 0.13 1" />
        </material>
      </visual>
    <visual>
      <origin xyz="-0.0347358 -0.0601641 -0.024383" rpy="0 0 4.18879" />
      <geometry>
        <box size="0.024 0.04 0.03" />
        </geometry>
      <material name="satin_black">
        <color rgba="0.12 0.12 0.13 1" />
        </material>
      </visual>
    <collision name="spider__visual_1">
      <geometry>
        <cylinder radius="0.055" length="0.028" />
        </geometry>
      </collision>
    <collision name="spider__visual_2">
      <origin xyz="0 0 0.018" rpy="0 0 0" />
      <geometry>
        <cylinder radius="0.044" length="0.012" />
        </geometry>
      </collision>
    <collision name="spider__visual_3">
      <origin xyz="0 0 0.026" rpy="0 0 0" />
      <geometry>
        <cylinder radius="0.032" length="0.022" />
        </geometry>
      </collision>
    <collision name="spider__visual_4">
      <origin xyz="0 0 0.074" rpy="0 0 0" />
      <geometry>
        <cylinder radius="0.024" length="0.11" />
        </geometry>
      </collision>
    <collision name="spider__visual_5">
      <origin xyz="0 0 0.025" rpy="0 0 0" />
      <geometry>
        <cylinder radius="0.012" length="0.004" />
        </geometry>
      </collision>
    <collision name="spider__visual_6">
      <origin xyz="0.0686488 0 -0.0374895" rpy="0 2.53073 0" />
      <geometry>
        <cylinder radius="0.02" length="0.072" />
        </geometry>
      </collision>
    <collision name="spider__visual_7">
      <origin xyz="0.0694715 0 -0.024383" rpy="0 0 0" />
      <geometry>
        <box size="0.024 0.04 0.03" />
        </geometry>
      </collision>
    <collision name="spider__visual_8">
      <origin xyz="-0.0343244 0.0594516 -0.0374895" rpy="0 2.53073 2.0944" />
      <geometry>
        <cylinder radius="0.02" length="0.072" />
        </geometry>
      </collision>
    <collision name="spider__visual_9">
      <origin xyz="-0.0347358 0.0601641 -0.024383" rpy="0 0 2.0944" />
      <geometry>
        <box size="0.024 0.04 0.03" />
        </geometry>
      </collision>
    <collision name="spider__visual_10">
      <origin xyz="-0.0343244 -0.0594516 -0.0374895" rpy="0 2.53073 4.18879" />
      <geometry>
        <cylinder radius="0.02" length="0.072" />
        </geometry>
      </collision>
    <collision name="spider__visual_11">
      <origin xyz="-0.0347358 -0.0601641 -0.024383" rpy="0 0 4.18879" />
      <geometry>
        <box size="0.024 0.04 0.03" />
        </geometry>
      </collision>
    </link>
  <link name="upper_leg_1">
    <inertial>
      <origin xyz="0 0 0.17" rpy="0 0 0" />
      <mass value="0.44" />
      <inertia ixx="0.00427431" ixy="0" ixz="0" iyy="0.00427431" iyz="0" izz="7.128e-05" />
      </inertial>
    <visual>
      <origin xyz="0 0 0.13" rpy="0 0 0" />
      <geometry>
        <cylinder radius="0.016" length="0.26" />
        </geometry>
      <material name="carbon_fiber">
        <color rgba="0.18 0.19 0.21 1" />
        </material>
      </visual>
    <visual>
      <origin xyz="0 0 0.29" rpy="0 0 0" />
      <geometry>
        <cylinder radius="0.018" length="0.1" />
        </geometry>
      <material name="satin_black">
        <color rgba="0.12 0.12 0.13 1" />
        </material>
      </visual>
    <visual>
      <origin xyz="0 0 0.025" rpy="0 0 0" />
      <geometry>
        <cylinder radius="0.021" length="0.05" />
        </geometry>
      <material name="machined_aluminum">
        <color rgba="0.64 0.66 0.69 1" />
        </material>
      </visual>
    <visual>
      <origin xyz="0.016 0 0.286" rpy="0 0 0" />
      <geometry>
        <box size="0.048 0.02 0.042" />
        </geometry>
      <material name="satin_black">
        <color rgba="0.12 0.12 0.13 1" />
        </material>
      </visual>
    <visual>
      <origin xyz="0.04 0 0.29" rpy="0 0 0" />
      <geometry>
        <box size="0.012 0.034 0.01" />
        </geometry>
      <material name="machined_aluminum">
        <color rgba="0.64 0.66 0.69 1" />
        </material>
      </visual>
    <collision name="upper_leg_1__visual_1">
      <origin xyz="0 0 0.13" rpy="0 0 0" />
      <geometry>
        <cylinder radius="0.016" length="0.26" />
        </geometry>
      </collision>
    <collision name="upper_leg_1__visual_2">
      <origin xyz="0 0 0.29" rpy="0 0 0" />
      <geometry>
        <cylinder radius="0.018" length="0.1" />
        </geometry>
      </collision>
    <collision name="upper_leg_1__visual_3">
      <origin xyz="0 0 0.025" rpy="0 0 0" />
      <geometry>
        <cylinder radius="0.021" length="0.05" />
        </geometry>
      </collision>
    <collision name="upper_leg_1__visual_4">
      <origin xyz="0.016 0 0.286" rpy="0 0 0" />
      <geometry>
        <box size="0.048 0.02 0.042" />
        </geometry>
      </collision>
    <collision name="upper_leg_1__visual_5">
      <origin xyz="0.04 0 0.29" rpy="0 0 0" />
      <geometry>
        <box size="0.012 0.034 0.01" />
        </geometry>
      </collision>
    </link>
  <link name="lower_leg_1">
    <inertial>
      <origin xyz="0 0 0.17" rpy="0 0 0" />
      <mass value="0.3" />
      <inertia ixx="0.00226687" ixy="0" ixz="0" iyy="0.00226687" iyz="0" izz="3.375e-05" />
      </inertial>
    <visual>
      <origin xyz="0 0 0.18" rpy="0 0 0" />
      <geometry>
        <cylinder radius="0.0125" length="0.3" />
        </geometry>
      <material name="carbon_fiber">
        <color rgba="0.18 0.19 0.21 1" />
        </material>
      </visual>
    <visual>
      <origin xyz="0 0 0.013" rpy="0 0 0" />
      <geometry>
        <cylinder radius="0.0158" length="0.026" />
        </geometry>
      <material name="machined_aluminum">
        <color rgba="0.64 0.66 0.69 1" />
        </material>
      </visual>
    <visual>
      <origin xyz="0 0 0.038" rpy="0 0 0" />
      <geometry>
        <cylinder radius="0.0168" length="0.036" />
        </geometry>
      <material name="satin_black">
        <color rgba="0.12 0.12 0.13 1" />
        </material>
      </visual>
    <visual>
      <origin xyz="0 0 0.312" rpy="0 0 0" />
      <geometry>
        <cylinder radius="0.015" length="0.024" />
        </geometry>
      <material name="machined_aluminum">
        <color rgba="0.64 0.66 0.69 1" />
        </material>
      </visual>
    <visual>
      <origin xyz="0 0 0.338" rpy="0 0 0" />
      <geometry>
        <sphere radius="0.018" />
        </geometry>
      <material name="soft_rubber">
        <color rgba="0.06 0.06 0.06 1" />
        </material>
      </visual>
    <collision name="lower_leg_1__visual_1">
      <origin xyz="0 0 0.18" rpy="0 0 0" />
      <geometry>
        <cylinder radius="0.0125" length="0.3" />
        </geometry>
      </collision>
    <collision name="lower_leg_1__visual_2">
      <origin xyz="0 0 0.013" rpy="0 0 0" />
      <geometry>
        <cylinder radius="0.0158" length="0.026" />
        </geometry>
      </collision>
    <collision name="lower_leg_1__visual_3">
      <origin xyz="0 0 0.038" rpy="0 0 0" />
      <geometry>
        <cylinder radius="0.0168" length="0.036" />
        </geometry>
      </collision>
    <collision name="lower_leg_1__visual_4">
      <origin xyz="0 0 0.312" rpy="0 0 0" />
      <geometry>
        <cylinder radius="0.015" length="0.024" />
        </geometry>
      </collision>
    <collision name="lower_leg_1__visual_5">
      <origin xyz="0 0 0.338" rpy="0 0 0" />
      <geometry>
        <sphere radius="0.018" />
        </geometry>
      </collision>
    </link>
  <link name="upper_leg_2">
    <inertial>
      <origin xyz="0 0 0.17" rpy="0 0 0" />
      <mass value="0.44" />
      <inertia ixx="0.00427431" ixy="0" ixz="0" iyy="0.00427431" iyz="0" izz="7.128e-05" />
      </inertial>
    <visual>
      <origin xyz="0 0 0.13" rpy="0 0 0" />
      <geometry>
        <cylinder radius="0.016" length="0.26" />
        </geometry>
      <material name="carbon_fiber">
        <color rgba="0.18 0.19 0.21 1" />
        </material>
      </visual>
    <visual>
      <origin xyz="0 0 0.29" rpy="0 0 0" />
      <geometry>
        <cylinder radius="0.018" length="0.1" />
        </geometry>
      <material name="satin_black">
        <color rgba="0.12 0.12 0.13 1" />
        </material>
      </visual>
    <visual>
      <origin xyz="0 0 0.025" rpy="0 0 0" />
      <geometry>
        <cylinder radius="0.021" length="0.05" />
        </geometry>
      <material name="machined_aluminum">
        <color rgba="0.64 0.66 0.69 1" />
        </material>
      </visual>
    <visual>
      <origin xyz="0.016 0 0.286" rpy="0 0 0" />
      <geometry>
        <box size="0.048 0.02 0.042" />
        </geometry>
      <material name="satin_black">
        <color rgba="0.12 0.12 0.13 1" />
        </material>
      </visual>
    <visual>
      <origin xyz="0.04 0 0.29" rpy="0 0 0" />
      <geometry>
        <box size="0.012 0.034 0.01" />
        </geometry>
      <material name="machined_aluminum">
        <color rgba="0.64 0.66 0.69 1" />
        </material>
      </visual>
    <collision name="upper_leg_2__visual_1">
      <origin xyz="0 0 0.13" rpy="0 0 0" />
      <geometry>
        <cylinder radius="0.016" length="0.26" />
        </geometry>
      </collision>
    <collision name="upper_leg_2__visual_2">
      <origin xyz="0 0 0.29" rpy="0 0 0" />
      <geometry>
        <cylinder radius="0.018" length="0.1" />
        </geometry>
      </collision>
    <collision name="upper_leg_2__visual_3">
      <origin xyz="0 0 0.025" rpy="0 0 0" />
      <geometry>
        <cylinder radius="0.021" length="0.05" />
        </geometry>
      </collision>
    <collision name="upper_leg_2__visual_4">
      <origin xyz="0.016 0 0.286" rpy="0 0 0" />
      <geometry>
        <box size="0.048 0.02 0.042" />
        </geometry>
      </collision>
    <collision name="upper_leg_2__visual_5">
      <origin xyz="0.04 0 0.29" rpy="0 0 0" />
      <geometry>
        <box size="0.012 0.034 0.01" />
        </geometry>
      </collision>
    </link>
  <link name="lower_leg_2">
    <inertial>
      <origin xyz="0 0 0.17" rpy="0 0 0" />
      <mass value="0.3" />
      <inertia ixx="0.00226687" ixy="0" ixz="0" iyy="0.00226687" iyz="0" izz="3.375e-05" />
      </inertial>
    <visual>
      <origin xyz="0 0 0.18" rpy="0 0 0" />
      <geometry>
        <cylinder radius="0.0125" length="0.3" />
        </geometry>
      <material name="carbon_fiber">
        <color rgba="0.18 0.19 0.21 1" />
        </material>
      </visual>
    <visual>
      <origin xyz="0 0 0.013" rpy="0 0 0" />
      <geometry>
        <cylinder radius="0.0158" length="0.026" />
        </geometry>
      <material name="machined_aluminum">
        <color rgba="0.64 0.66 0.69 1" />
        </material>
      </visual>
    <visual>
      <origin xyz="0 0 0.038" rpy="0 0 0" />
      <geometry>
        <cylinder radius="0.0168" length="0.036" />
        </geometry>
      <material name="satin_black">
        <color rgba="0.12 0.12 0.13 1" />
        </material>
      </visual>
    <visual>
      <origin xyz="0 0 0.312" rpy="0 0 0" />
      <geometry>
        <cylinder radius="0.015" length="0.024" />
        </geometry>
      <material name="machined_aluminum">
        <color rgba="0.64 0.66 0.69 1" />
        </material>
      </visual>
    <visual>
      <origin xyz="0 0 0.338" rpy="0 0 0" />
      <geometry>
        <sphere radius="0.018" />
        </geometry>
      <material name="soft_rubber">
        <color rgba="0.06 0.06 0.06 1" />
        </material>
      </visual>
    <collision name="lower_leg_2__visual_1">
      <origin xyz="0 0 0.18" rpy="0 0 0" />
      <geometry>
        <cylinder radius="0.0125" length="0.3" />
        </geometry>
      </collision>
    <collision name="lower_leg_2__visual_2">
      <origin xyz="0 0 0.013" rpy="0 0 0" />
      <geometry>
        <cylinder radius="0.0158" length="0.026" />
        </geometry>
      </collision>
    <collision name="lower_leg_2__visual_3">
      <origin xyz="0 0 0.038" rpy="0 0 0" />
      <geometry>
        <cylinder radius="0.0168" length="0.036" />
        </geometry>
      </collision>
    <collision name="lower_leg_2__visual_4">
      <origin xyz="0 0 0.312" rpy="0 0 0" />
      <geometry>
        <cylinder radius="0.015" length="0.024" />
        </geometry>
      </collision>
    <collision name="lower_leg_2__visual_5">
      <origin xyz="0 0 0.338" rpy="0 0 0" />
      <geometry>
        <sphere radius="0.018" />
        </geometry>
      </collision>
    </link>
  <link name="upper_leg_3">
    <inertial>
      <origin xyz="0 0 0.17" rpy="0 0 0" />
      <mass value="0.44" />
      <inertia ixx="0.00427431" ixy="0" ixz="0" iyy="0.00427431" iyz="0" izz="7.128e-05" />
      </inertial>
    <visual>
      <origin xyz="0 0 0.13" rpy="0 0 0" />
      <geometry>
        <cylinder radius="0.016" length="0.26" />
        </geometry>
      <material name="carbon_fiber">
        <color rgba="0.18 0.19 0.21 1" />
        </material>
      </visual>
    <visual>
      <origin xyz="0 0 0.29" rpy="0 0 0" />
      <geometry>
        <cylinder radius="0.018" length="0.1" />
        </geometry>
      <material name="satin_black">
        <color rgba="0.12 0.12 0.13 1" />
        </material>
      </visual>
    <visual>
      <origin xyz="0 0 0.025" rpy="0 0 0" />
      <geometry>
        <cylinder radius="0.021" length="0.05" />
        </geometry>
      <material name="machined_aluminum">
        <color rgba="0.64 0.66 0.69 1" />
        </material>
      </visual>
    <visual>
      <origin xyz="0.016 0 0.286" rpy="0 0 0" />
      <geometry>
        <box size="0.048 0.02 0.042" />
        </geometry>
      <material name="satin_black">
        <color rgba="0.12 0.12 0.13 1" />
        </material>
      </visual>
    <visual>
      <origin xyz="0.04 0 0.29" rpy="0 0 0" />
      <geometry>
        <box size="0.012 0.034 0.01" />
        </geometry>
      <material name="machined_aluminum">
        <color rgba="0.64 0.66 0.69 1" />
        </material>
      </visual>
    <collision name="upper_leg_3__visual_1">
      <origin xyz="0 0 0.13" rpy="0 0 0" />
      <geometry>
        <cylinder radius="0.016" length="0.26" />
        </geometry>
      </collision>
    <collision name="upper_leg_3__visual_2">
      <origin xyz="0 0 0.29" rpy="0 0 0" />
      <geometry>
        <cylinder radius="0.018" length="0.1" />
        </geometry>
      </collision>
    <collision name="upper_leg_3__visual_3">
      <origin xyz="0 0 0.025" rpy="0 0 0" />
      <geometry>
        <cylinder radius="0.021" length="0.05" />
        </geometry>
      </collision>
    <collision name="upper_leg_3__visual_4">
      <origin xyz="0.016 0 0.286" rpy="0 0 0" />
      <geometry>
        <box size="0.048 0.02 0.042" />
        </geometry>
      </collision>
    <collision name="upper_leg_3__visual_5">
      <origin xyz="0.04 0 0.29" rpy="0 0 0" />
      <geometry>
        <box size="0.012 0.034 0.01" />
        </geometry>
      </collision>
    </link>
  <link name="lower_leg_3">
    <inertial>
      <origin xyz="0 0 0.17" rpy="0 0 0" />
      <mass value="0.3" />
      <inertia ixx="0.00226687" ixy="0" ixz="0" iyy="0.00226687" iyz="0" izz="3.375e-05" />
      </inertial>
    <visual>
      <origin xyz="0 0 0.18" rpy="0 0 0" />
      <geometry>
        <cylinder radius="0.0125" length="0.3" />
        </geometry>
      <material name="carbon_fiber">
        <color rgba="0.18 0.19 0.21 1" />
        </material>
      </visual>
    <visual>
      <origin xyz="0 0 0.013" rpy="0 0 0" />
      <geometry>
        <cylinder radius="0.0158" length="0.026" />
        </geometry>
      <material name="machined_aluminum">
        <color rgba="0.64 0.66 0.69 1" />
        </material>
      </visual>
    <visual>
      <origin xyz="0 0 0.038" rpy="0 0 0" />
      <geometry>
        <cylinder radius="0.0168" length="0.036" />
        </geometry>
      <material name="satin_black">
        <color rgba="0.12 0.12 0.13 1" />
        </material>
      </visual>
    <visual>
      <origin xyz="0 0 0.312" rpy="0 0 0" />
      <geometry>
        <cylinder radius="0.015" length="0.024" />
        </geometry>
      <material name="machined_aluminum">
        <color rgba="0.64 0.66 0.69 1" />
        </material>
      </visual>
    <visual>
      <origin xyz="0 0 0.338" rpy="0 0 0" />
      <geometry>
        <sphere radius="0.018" />
        </geometry>
      <material name="soft_rubber">
        <color rgba="0.06 0.06 0.06 1" />
        </material>
      </visual>
    <collision name="lower_leg_3__visual_1">
      <origin xyz="0 0 0.18" rpy="0 0 0" />
      <geometry>
        <cylinder radius="0.0125" length="0.3" />
        </geometry>
      </collision>
    <collision name="lower_leg_3__visual_2">
      <origin xyz="0 0 0.013" rpy="0 0 0" />
      <geometry>
        <cylinder radius="0.0158" length="0.026" />
        </geometry>
      </collision>
    <collision name="lower_leg_3__visual_3">
      <origin xyz="0 0 0.038" rpy="0 0 0" />
      <geometry>
        <cylinder radius="0.0168" length="0.036" />
        </geometry>
      </collision>
    <collision name="lower_leg_3__visual_4">
      <origin xyz="0 0 0.312" rpy="0 0 0" />
      <geometry>
        <cylinder radius="0.015" length="0.024" />
        </geometry>
      </collision>
    <collision name="lower_leg_3__visual_5">
      <origin xyz="0 0 0.338" rpy="0 0 0" />
      <geometry>
        <sphere radius="0.018" />
        </geometry>
      </collision>
    </link>
  <link name="center_column">
    <inertial>
      <origin xyz="0 0 0.01" rpy="0 0 0" />
      <mass value="0.7" />
      <inertia ixx="0.00685271" ixy="0" ixz="0" iyy="0.00685271" iyz="0" izz="0.00021875" />
      </inertial>
    <visual>
      <origin xyz="0 0 0.01" rpy="0 0 0" />
      <geometry>
        <cylinder radius="0.018" length="0.34" />
        </geometry>
      <material name="machined_aluminum">
        <color rgba="0.64 0.66 0.69 1" />
        </material>
      </visual>
    <visual>
      <origin xyz="0 0 -0.09" rpy="0 0 0" />
      <geometry>
        <cylinder radius="0.028" length="0.032" />
        </geometry>
      <material name="satin_black">
        <color rgba="0.12 0.12 0.13 1" />
        </material>
      </visual>
    <visual>
      <origin xyz="0.026 0 -0.09" rpy="0 0 0" />
      <geometry>
        <box size="0.016 0.05 0.014" />
        </geometry>
      <material name="machined_aluminum">
        <color rgba="0.64 0.66 0.69 1" />
        </material>
      </visual>
    <visual>
      <origin xyz="0 0 0.187" rpy="0 0 0" />
      <geometry>
        <cylinder radius="0.028" length="0.014" />
        </geometry>
      <material name="satin_black">
        <color rgba="0.12 0.12 0.13 1" />
        </material>
      </visual>
    <visual>
      <origin xyz="0 0 0.199" rpy="0 0 0" />
      <geometry>
        <cylinder radius="0.006" length="0.01" />
        </geometry>
      <material name="machined_aluminum">
        <color rgba="0.64 0.66 0.69 1" />
        </material>
      </visual>
    <collision name="center_column__visual_1">
      <origin xyz="0 0 0.01" rpy="0 0 0" />
      <geometry>
        <cylinder radius="0.018" length="0.34" />
        </geometry>
      </collision>
    <collision name="center_column__visual_2">
      <origin xyz="0 0 -0.09" rpy="0 0 0" />
      <geometry>
        <cylinder radius="0.028" length="0.032" />
        </geometry>
      </collision>
    <collision name="center_column__visual_3">
      <origin xyz="0.026 0 -0.09" rpy="0 0 0" />
      <geometry>
        <box size="0.016 0.05 0.014" />
        </geometry>
      </collision>
    <collision name="center_column__visual_4">
      <origin xyz="0 0 0.187" rpy="0 0 0" />
      <geometry>
        <cylinder radius="0.028" length="0.014" />
        </geometry>
      </collision>
    <collision name="center_column__visual_5">
      <origin xyz="0 0 0.199" rpy="0 0 0" />
      <geometry>
        <cylinder radius="0.006" length="0.01" />
        </geometry>
      </collision>
    </link>
  <link name="pan_head">
    <inertial>
      <origin xyz="0 -0.045 0.07" rpy="0 0 0" />
      <mass value="0.82" />
      <inertia ixx="0.00435283" ixy="0" ixz="0" iyy="0.00232333" iyz="0" izz="0.0039975" />
      </inertial>
    <visual>
      <origin xyz="0 0 0.018" rpy="0 0 0" />
      <geometry>
        <cylinder radius="0.032" length="0.036" />
        </geometry>
      <material name="satin_black">
        <color rgba="0.12 0.12 0.13 1" />
        </material>
      </visual>
    <visual>
      <origin xyz="0 0 0.026" rpy="0 0 0" />
      <geometry>
        <box size="0.118 0.034 0.012" />
        </geometry>
      <material name="machined_aluminum">
        <color rgba="0.64 0.66 0.69 1" />
        </material>
      </visual>
    <visual>
      <origin xyz="0 0 0.048" rpy="0 0 0" />
      <geometry>
        <box size="0.09 0.032 0.008" />
        </geometry>
      <material name="satin_black">
        <color rgba="0.12 0.12 0.13 1" />
        </material>
      </visual>
    <visual>
      <origin xyz="-0.053 0 0.086" rpy="0 0 0" />
      <geometry>
        <box size="0.012 0.042 0.1" />
        </geometry>
      <material name="machined_aluminum">
        <color rgba="0.64 0.66 0.69 1" />
        </material>
      </visual>
    <visual>
      <origin xyz="0.053 0 0.086" rpy="0 0 0" />
      <geometry>
        <box size="0.012 0.042 0.1" />
        </geometry>
      <material name="machined_aluminum">
        <color rgba="0.64 0.66 0.69 1" />
        </material>
      </visual>
    <visual>
      <origin xyz="0.041 0 0.018" rpy="0 1.5708 0" />
      <geometry>
        <cylinder radius="0.01" length="0.02" />
        </geometry>
      <material name="machined_aluminum">
        <color rgba="0.64 0.66 0.69 1" />
        </material>
      </visual>
    <visual>
      <origin xyz="-0.066 -0.004 0.094" rpy="0 1.5708 0" />
      <geometry>
        <cylinder radius="0.009" length="0.018" />
        </geometry>
      <material name="satin_black">
        <color rgba="0.12 0.12 0.13 1" />
        </material>
      </visual>
    <visual>
      <origin xyz="0.066 -0.004 0.094" rpy="0 1.5708 0" />
      <geometry>
        <cylinder radius="0.009" length="0.018" />
        </geometry>
      <material name="satin_black">
        <color rgba="0.12 0.12 0.13 1" />
        </material>
      </visual>
    <visual>
      <origin xyz="0 -0.004 0.094" rpy="0 1.5708 0" />
      <geometry>
        <cylinder radius="0.006" length="0.106" />
        </geometry>
      <material name="machined_aluminum">
        <color rgba="0.64 0.66 0.69 1" />
        </material>
      </visual>
    <visual>
      <origin xyz="0 -0.004 0.094" rpy="0 0 0" />
      <geometry>
        <box size="0.054 0.02 0.016" />
        </geometry>
      <material name="satin_black">
        <color rgba="0.12 0.12 0.13 1" />
        </material>
      </visual>
    <visual>
      <geometry>
        <mesh filename="meshes/pan_handle.obj" />
        </geometry>
      <material name="soft_rubber">
        <color rgba="0.06 0.06 0.06 1" />
        </material>
      </visual>
    <collision name="pan_head__visual_1">
      <origin xyz="0 0 0.018" rpy="0 0 0" />
      <geometry>
        <cylinder radius="0.032" length="0.036" />
        </geometry>
      </collision>
    <collision name="pan_head__visual_2">
      <origin xyz="0 0 0.026" rpy="0 0 0" />
      <geometry>
        <box size="0.118 0.034 0.012" />
        </geometry>
      </collision>
    <collision name="pan_head__visual_3">
      <origin xyz="0 0 0.048" rpy="0 0 0" />
      <geometry>
        <box size="0.09 0.032 0.008" />
        </geometry>
      </collision>
    <collision name="pan_head__visual_4">
      <origin xyz="-0.053 0 0.086" rpy="0 0 0" />
      <geometry>
        <box size="0.012 0.042 0.1" />
        </geometry>
      </collision>
    <collision name="pan_head__visual_5">
      <origin xyz="0.053 0 0.086" rpy="0 0 0" />
      <geometry>
        <box size="0.012 0.042 0.1" />
        </geometry>
      </collision>
    <collision name="pan_head__visual_6">
      <origin xyz="0.041 0 0.018" rpy="0 1.5708 0" />
      <geometry>
        <cylinder radius="0.01" length="0.02" />
        </geometry>
      </collision>
    <collision name="pan_head__visual_7">
      <origin xyz="-0.066 -0.004 0.094" rpy="0 1.5708 0" />
      <geometry>
        <cylinder radius="0.009" length="0.018" />
        </geometry>
      </collision>
    <collision name="pan_head__visual_8">
      <origin xyz="0.066 -0.004 0.094" rpy="0 1.5708 0" />
      <geometry>
        <cylinder radius="0.009" length="0.018" />
        </geometry>
      </collision>
    <collision name="pan_head__visual_9">
      <origin xyz="0 -0.004 0.094" rpy="0 1.5708 0" />
      <geometry>
        <cylinder radius="0.006" length="0.106" />
        </geometry>
      </collision>
    <collision name="pan_head__visual_10">
      <origin xyz="0 -0.004 0.094" rpy="0 0 0" />
      <geometry>
        <box size="0.054 0.02 0.016" />
        </geometry>
      </collision>
    <collision name="pan_head__visual_11__hull_001">
      <geometry>
        <mesh filename="meshes/collision/cache/3e29d3fe3bdc9b1efb8492d5__hull_001.obj" />
        </geometry>
      </collision>
    </link>
  <link name="camera_body">
    <inertial>
      <origin xyz="0 0.02 0.012" rpy="0 0 0" />
      <mass value="0.95" />
      <inertia ixx="0.00228792" ixy="0" ixz="0" iyy="0.00114792" iyz="0" izz="0.0024225" />
      </inertial>
    <visual>
      <geometry>
        <mesh filename="meshes/camera_body_shell.obj" />
        </geometry>
      <material name="satin_black">
        <color rgba="0.12 0.12 0.13 1" />
        </material>
      </visual>
    <visual>
      <origin xyz="-0.049 -0.004 0" rpy="0 1.5708 0" />
      <geometry>
        <cylinder radius="0.009" length="0.02" />
        </geometry>
      <material name="machined_aluminum">
        <color rgba="0.64 0.66 0.69 1" />
        </material>
      </visual>
    <visual>
      <origin xyz="0.049 -0.004 0" rpy="0 1.5708 0" />
      <geometry>
        <cylinder radius="0.009" length="0.02" />
        </geometry>
      <material name="machined_aluminum">
        <color rgba="0.64 0.66 0.69 1" />
        </material>
      </visual>
    <visual>
      <origin xyz="0 0.086 0.006" rpy="-1.5708 0 0" />
      <geometry>
        <cylinder radius="0.02" length="0.052" />
        </geometry>
      <material name="machined_aluminum">
        <color rgba="0.64 0.66 0.69 1" />
        </material>
      </visual>
    <visual>
      <origin xyz="0 0.105 0.006" rpy="-1.5708 0 0" />
      <geometry>
        <cylinder radius="0.022" length="0.004" />
        </geometry>
      <material name="accent_red">
        <color rgba="0.64 0.14 0.12 1" />
        </material>
      </visual>
    <visual>
      <origin xyz="0 0.124 0.006" rpy="-1.5708 0 0" />
      <geometry>
        <cylinder radius="0.026" length="0.024" />
        </geometry>
      <material name="satin_black">
        <color rgba="0.12 0.12 0.13 1" />
        </material>
      </visual>
    <visual>
      <origin xyz="0 0.137 0.006" rpy="-1.5708 0 0" />
      <geometry>
        <cylinder radius="0.017" length="0.004" />
        </geometry>
      <material name="lens_glass">
        <color rgba="0.58 0.7 0.84 0.36" />
        </material>
      </visual>
    <visual>
      <origin xyz="0 0.002 0.052" rpy="0 0 0" />
      <geometry>
        <box size="0.036 0.022 0.01" />
        </geometry>
      <material name="machined_aluminum">
        <color rgba="0.64 0.66 0.69 1" />
        </material>
      </visual>
    <visual>
      <origin xyz="0 -0.04 0.008" rpy="0 0 0" />
      <geometry>
        <box size="0.052 0.026 0.038" />
        </geometry>
      <material name="satin_black">
        <color rgba="0.12 0.12 0.13 1" />
        </material>
      </visual>
    <visual>
      <origin xyz="-0.039 0.004 0.018" rpy="0 0 0" />
      <geometry>
        <box size="0.006 0.028 0.02" />
        </geometry>
      <material name="lens_glass">
        <color rgba="0.58 0.7 0.84 0.36" />
        </material>
      </visual>
    <collision name="camera_body__visual_1__hull_001">
      <geometry>
        <mesh filename="meshes/collision/cache/955722122c993db837446ddb__hull_001.obj" />
        </geometry>
      </collision>
    <collision name="camera_body__visual_2">
      <origin xyz="-0.049 -0.004 0" rpy="0 1.5708 0" />
      <geometry>
        <cylinder radius="0.009" length="0.02" />
        </geometry>
      </collision>
    <collision name="camera_body__visual_3">
      <origin xyz="0.049 -0.004 0" rpy="0 1.5708 0" />
      <geometry>
        <cylinder radius="0.009" length="0.02" />
        </geometry>
      </collision>
    <collision name="camera_body__visual_4">
      <origin xyz="0 0.086 0.006" rpy="-1.5708 0 0" />
      <geometry>
        <cylinder radius="0.02" length="0.052" />
        </geometry>
      </collision>
    <collision name="camera_body__visual_5">
      <origin xyz="0 0.105 0.006" rpy="-1.5708 0 0" />
      <geometry>
        <cylinder radius="0.022" length="0.004" />
        </geometry>
      </collision>
    <collision name="camera_body__visual_6">
      <origin xyz="0 0.124 0.006" rpy="-1.5708 0 0" />
      <geometry>
        <cylinder radius="0.026" length="0.024" />
        </geometry>
      </collision>
    <collision name="camera_body__visual_7">
      <origin xyz="0 0.137 0.006" rpy="-1.5708 0 0" />
      <geometry>
        <cylinder radius="0.017" length="0.004" />
        </geometry>
      </collision>
    <collision name="camera_body__visual_8">
      <origin xyz="0 0.002 0.052" rpy="0 0 0" />
      <geometry>
        <box size="0.036 0.022 0.01" />
        </geometry>
      </collision>
    <collision name="camera_body__visual_9">
      <origin xyz="0 -0.04 0.008" rpy="0 0 0" />
      <geometry>
        <box size="0.052 0.026 0.038" />
        </geometry>
      </collision>
    <collision name="camera_body__visual_10">
      <origin xyz="-0.039 0.004 0.018" rpy="0 0 0" />
      <geometry>
        <box size="0.006 0.028 0.02" />
        </geometry>
      </collision>
    </link>
  <joint name="spider_to_upper_leg_1" type="fixed">
    <origin xyz="0.048 0 -0.008" rpy="0 2.53073 0" />
    <parent link="spider" />
    <child link="upper_leg_1" />
    </joint>
  <joint name="leg_1_extension" type="prismatic">
    <origin xyz="0 0 0.14" rpy="0 0 0" />
    <parent link="upper_leg_1" />
    <child link="lower_leg_1" />
    <axis xyz="0 0 1" />
    <limit effort="120" velocity="0.25" lower="0" upper="0.12" />
    </joint>
  <joint name="spider_to_upper_leg_2" type="fixed">
    <origin xyz="-0.024 0.0415692 -0.008" rpy="0 2.53073 2.0944" />
    <parent link="spider" />
    <child link="upper_leg_2" />
    </joint>
  <joint name="leg_2_extension" type="prismatic">
    <origin xyz="0 0 0.14" rpy="0 0 0" />
    <parent link="upper_leg_2" />
    <child link="lower_leg_2" />
    <axis xyz="0 0 1" />
    <limit effort="120" velocity="0.25" lower="0" upper="0.12" />
    </joint>
  <joint name="spider_to_upper_leg_3" type="fixed">
    <origin xyz="-0.024 -0.0415692 -0.008" rpy="0 2.53073 4.18879" />
    <parent link="spider" />
    <child link="upper_leg_3" />
    </joint>
  <joint name="leg_3_extension" type="prismatic">
    <origin xyz="0 0 0.14" rpy="0 0 0" />
    <parent link="upper_leg_3" />
    <child link="lower_leg_3" />
    <axis xyz="0 0 1" />
    <limit effort="120" velocity="0.25" lower="0" upper="0.12" />
    </joint>
  <joint name="center_column_lift" type="prismatic">
    <origin xyz="0 0 0.129" rpy="0 0 0" />
    <parent link="spider" />
    <child link="center_column" />
    <axis xyz="0 0 1" />
    <limit effort="180" velocity="0.2" lower="0" upper="0.12" />
    </joint>
  <joint name="head_pan" type="revolute">
    <origin xyz="0 0 0.194" rpy="0 0 0" />
    <parent link="center_column" />
    <child link="pan_head" />
    <axis xyz="0 0 1" />
    <limit effort="30" velocity="2.5" lower="-3.14159" upper="3.14159" />
    </joint>
  <joint name="camera_tilt" type="revolute">
    <origin xyz="0 -0.004 0.094" rpy="0 0 0" />
    <parent link="pan_head" />
    <child link="camera_body" />
    <axis xyz="1 0 0" />
    <limit effort="20" velocity="2" lower="-0.35" upper="1.05" />
    </joint>
  </robot>
