<robot name="two_axis_positioning_stage">
  <material name="frame_gray">
    <color rgba="0.58 0.6 0.64 1" />
  </material>
  <material name="rail_steel">
    <color rgba="0.73 0.75 0.77 1" />
  </material>
  <material name="dark_hardware">
    <color rgba="0.15 0.15 0.17 1" />
  </material>
  <material name="payload_orange">
    <color rgba="0.96 0.56 0.18 1" />
  </material>
  <link name="base">
    <inertial>
      <origin xyz="0 0 0.014" rpy="0 0 0" />
      <mass value="7.5" />
      <inertia ixx="0.02074" ixy="0" ixz="0" iyy="0.08149" iyz="0" izz="0.10125" />
    </inertial>
    <visual>
      <origin xyz="0 0 0.014" rpy="0 0 0" />
      <geometry>
        <box size="0.36 0.18 0.028" />
      </geometry>
      <material name="frame_gray" />
    </visual>
    <visual>
      <origin xyz="0 0.055 0.037" rpy="0 0 0" />
      <geometry>
        <box size="0.28 0.016 0.018" />
      </geometry>
      <material name="rail_steel" />
    </visual>
    <visual>
      <origin xyz="0 -0.055 0.037" rpy="0 0 0" />
      <geometry>
        <box size="0.28 0.016 0.018" />
      </geometry>
      <material name="rail_steel" />
    </visual>
    <visual>
      <origin xyz="0 0 0.04" rpy="0 1.5708 0" />
      <geometry>
        <cylinder radius="0.006" length="0.24" />
      </geometry>
      <material name="dark_hardware" />
    </visual>
    <visual>
      <origin xyz="0.145 0 0.042" rpy="0 0 0" />
      <geometry>
        <box size="0.022 0.09 0.028" />
      </geometry>
      <material name="dark_hardware" />
    </visual>
    <visual>
      <origin xyz="-0.145 0 0.042" rpy="0 0 0" />
      <geometry>
        <box size="0.022 0.09 0.028" />
      </geometry>
      <material name="dark_hardware" />
    </visual>
    <collision>
      <origin xyz="0 0 0.014" rpy="0 0 0" />
      <geometry>
        <box size="0.36 0.18 0.028" />
      </geometry>
    </collision>
    <collision>
      <origin xyz="0 0.055 0.037" rpy="0 0 0" />
      <geometry>
        <box size="0.28 0.016 0.018" />
      </geometry>
    </collision>
    <collision>
      <origin xyz="0 -0.055 0.037" rpy="0 0 0" />
      <geometry>
        <box size="0.28 0.016 0.018" />
      </geometry>
    </collision>
    <collision>
      <origin xyz="0 0 0.04" rpy="0 1.5708 0" />
      <geometry>
        <cylinder radius="0.006" length="0.24" />
      </geometry>
    </collision>
  </link>
  <link name="x_stage">
    <inertial>
      <origin xyz="0 0 0.095" rpy="0 0 0" />
      <mass value="2.4" />
      <inertia ixx="0.01114" ixy="0" ixz="0" iyy="0.01172" iyz="0" izz="0.00842" />
    </inertial>
    <visual>
      <origin xyz="0 0 0.007" rpy="0 0 0" />
      <geometry>
        <box size="0.108 0.05 0.014" />
      </geometry>
      <material name="dark_hardware" />
    </visual>
    <visual>
      <origin xyz="0 0 0.021" rpy="0 0 0" />
      <geometry>
        <box size="0.15 0.14 0.012" />
      </geometry>
      <material name="frame_gray" />
    </visual>
    <visual>
      <origin xyz="0.04 0.055 0.01" rpy="0 0 0" />
      <geometry>
        <box size="0.032 0.024 0.02" />
      </geometry>
      <material name="dark_hardware" />
    </visual>
    <visual>
      <origin xyz="-0.04 0.055 0.01" rpy="0 0 0" />
      <geometry>
        <box size="0.032 0.024 0.02" />
      </geometry>
      <material name="dark_hardware" />
    </visual>
    <visual>
      <origin xyz="0.04 -0.055 0.01" rpy="0 0 0" />
      <geometry>
        <box size="0.032 0.024 0.02" />
      </geometry>
      <material name="dark_hardware" />
    </visual>
    <visual>
      <origin xyz="-0.04 -0.055 0.01" rpy="0 0 0" />
      <geometry>
        <box size="0.032 0.024 0.02" />
      </geometry>
      <material name="dark_hardware" />
    </visual>
    <visual>
      <origin xyz="0 0 0.105" rpy="0 0 0" />
      <geometry>
        <box size="0.132 0.018 0.18" />
      </geometry>
      <material name="frame_gray" />
    </visual>
    <visual>
      <origin xyz="0 0 0.105" rpy="0 0 0" />
      <geometry>
        <box size="0.12 0.016 0.18" />
      </geometry>
    </visual>
    <visual>
      <origin xyz="0.036 0.015 0.087" rpy="0 0 0" />
      <geometry>
        <box size="0.016 0.012 0.14" />
      </geometry>
      <material name="rail_steel" />
    </visual>
    <visual>
      <origin xyz="-0.036 0.015 0.087" rpy="0 0 0" />
      <geometry>
        <box size="0.016 0.012 0.14" />
      </geometry>
      <material name="rail_steel" />
    </visual>
    <visual>
      <origin xyz="0 0.012 0.19" rpy="0 0 0" />
      <geometry>
        <box size="0.09 0.04 0.01" />
      </geometry>
      <material name="dark_hardware" />
    </visual>
    <collision>
      <origin xyz="0 0 0.007" rpy="0 0 0" />
      <geometry>
        <box size="0.108 0.05 0.014" />
      </geometry>
    </collision>
    <collision>
      <origin xyz="0 0 0.021" rpy="0 0 0" />
      <geometry>
        <box size="0.15 0.14 0.012" />
      </geometry>
    </collision>
    <collision>
      <origin xyz="0 0 0.105" rpy="0 0 0" />
      <geometry>
        <box size="0.12 0.016 0.18" />
      </geometry>
    </collision>
  </link>
  <link name="z_stage">
    <inertial>
      <origin xyz="0 0.055 0.055" rpy="0 0 0" />
      <mass value="1.3" />
      <inertia ixx="0.00262167" ixy="0" ixz="0" iyy="0.00262167" iyz="0" izz="0.00262167" />
    </inertial>
    <visual>
      <origin xyz="0 0.023 0.03" rpy="0 0 0" />
      <geometry>
        <box size="0.092 0.026 0.06" />
      </geometry>
      <material name="frame_gray" />
    </visual>
    <visual>
      <origin xyz="0 0.021 0.03" rpy="0 0 0" />
      <geometry>
        <box size="0.092 0.022 0.06" />
      </geometry>
    </visual>
    <visual>
      <origin xyz="0.036 0.009 0.018" rpy="0 0 0" />
      <geometry>
        <box size="0.028 0.014 0.022" />
      </geometry>
      <material name="dark_hardware" />
    </visual>
    <visual>
      <origin xyz="-0.036 0.009 0.018" rpy="0 0 0" />
      <geometry>
        <box size="0.028 0.014 0.022" />
      </geometry>
      <material name="dark_hardware" />
    </visual>
    <visual>
      <origin xyz="0.036 0.009 0.052" rpy="0 0 0" />
      <geometry>
        <box size="0.028 0.014 0.022" />
      </geometry>
      <material name="dark_hardware" />
    </visual>
    <visual>
      <origin xyz="-0.036 0.009 0.052" rpy="0 0 0" />
      <geometry>
        <box size="0.028 0.014 0.022" />
      </geometry>
      <material name="dark_hardware" />
    </visual>
    <visual>
      <origin xyz="0 0.035 0.065" rpy="0 0 0" />
      <geometry>
        <box size="0.05 0.04 0.038" />
      </geometry>
      <material name="dark_hardware" />
    </visual>
    <visual>
      <origin xyz="0 0.035 0.065" rpy="0 0 0" />
      <geometry>
        <box size="0.05 0.036 0.038" />
      </geometry>
    </visual>
    <visual>
      <origin xyz="0 0.055 0.094" rpy="0 0 0" />
      <geometry>
        <box size="0.11 0.11 0.012" />
      </geometry>
      <material name="payload_orange" />
    </visual>
    <visual>
      <origin xyz="0 0.095 0.075" rpy="0 0 0" />
      <geometry>
        <box size="0.09 0.02 0.018" />
      </geometry>
      <material name="dark_hardware" />
    </visual>
    <collision>
      <origin xyz="0 0.021 0.03" rpy="0 0 0" />
      <geometry>
        <box size="0.092 0.022 0.06" />
      </geometry>
    </collision>
    <collision>
      <origin xyz="0 0.035 0.065" rpy="0 0 0" />
      <geometry>
        <box size="0.05 0.036 0.038" />
      </geometry>
    </collision>
    <collision>
      <origin xyz="0 0.055 0.094" rpy="0 0 0" />
      <geometry>
        <box size="0.11 0.11 0.012" />
      </geometry>
    </collision>
  </link>
  <joint name="base_to_x" type="prismatic">
    <origin xyz="0 0 0.046" rpy="0 0 0" />
    <parent link="base" />
    <child link="x_stage" />
    <axis xyz="1 0 0" />
    <limit effort="150" velocity="0.25" lower="-0.075" upper="0.075" />
  </joint>
  <joint name="x_to_z" type="prismatic">
    <origin xyz="0 0.008 0.055" rpy="0 0 0" />
    <parent link="x_stage" />
    <child link="z_stage" />
    <axis xyz="0 0 1" />
    <limit effort="120" velocity="0.2" lower="0" upper="0.12" />
  </joint>
</robot>