<robot name="desktop_pc_tower">
  <material name="body_black">
    <color rgba="0.11 0.12 0.13 1" />
    </material>
  <material name="powder_steel">
    <color rgba="0.18 0.19 0.2 1" />
    </material>
  <material name="mesh_black">
    <color rgba="0.07 0.08 0.09 1" />
    </material>
  <material name="satin_aluminum">
    <color rgba="0.36 0.37 0.39 1" />
    </material>
  <material name="fan_gray">
    <color rgba="0.23 0.24 0.25 1" />
    </material>
  <material name="smoked_glass">
    <color rgba="0.38 0.44 0.48 0.28" />
    </material>
  <material name="rubber">
    <color rgba="0.06 0.06 0.06 1" />
    </material>
  <material name="io_dark">
    <color rgba="0.09 0.09 0.1 1" />
    </material>
  <material name="status_led">
    <color rgba="0.14 0.39 0.76 1" />
    </material>
  <link name="chassis">
    <inertial>
      <origin xyz="0 0 0.2705" rpy="0 0 0" />
      <mass value="12" />
      <inertia ixx="0.475925" ixy="0" ixz="0" iyy="0.308849" iyz="0" izz="0.274724" />
      </inertial>
    <visual>
      <origin xyz="0 0 0.2705" rpy="0 0 0" />
      <geometry>
        <box size="0.232 0.47 0.505" />
        </geometry>
      <material name="body_black" />
      </visual>
    <visual>
      <origin xyz="0 -0.231 0.05" rpy="0 0 0" />
      <geometry>
        <mesh filename="assets/meshes/front_intake_panel.obj" />
        </geometry>
      <material name="mesh_black" />
      </visual>
    <visual>
      <origin xyz="0.01 -0.012 0.522" rpy="0 0 0" />
      <geometry>
        <mesh filename="assets/meshes/top_vent_panel.obj" />
        </geometry>
      <material name="mesh_black" />
      </visual>
    <visual>
      <origin xyz="0 -0.205 0.192" rpy="1.5708 0 0" />
      <geometry>
        <cylinder radius="0.064" length="0.014" />
        </geometry>
      <material name="fan_gray" />
      </visual>
    <visual>
      <origin xyz="0 -0.205 0.192" rpy="1.5708 0 0" />
      <geometry>
        <cylinder radius="0.016" length="0.018" />
        </geometry>
      <material name="io_dark" />
      </visual>
    <visual>
      <origin xyz="0 -0.205 0.336" rpy="1.5708 0 0" />
      <geometry>
        <cylinder radius="0.064" length="0.014" />
        </geometry>
      <material name="fan_gray" />
      </visual>
    <visual>
      <origin xyz="0 -0.205 0.336" rpy="1.5708 0 0" />
      <geometry>
        <cylinder radius="0.016" length="0.018" />
        </geometry>
      <material name="io_dark" />
      </visual>
    <visual>
      <origin xyz="0 0.238 0.282" rpy="0 0 0" />
      <geometry>
        <box size="0.184 0.006 0.344" />
        </geometry>
      <material name="powder_steel" />
      </visual>
    <visual>
      <origin xyz="0 0.238 0.1" rpy="0 0 0" />
      <geometry>
        <box size="0.152 0.006 0.096" />
        </geometry>
      <material name="io_dark" />
      </visual>
    <visual>
      <origin xyz="0.032 0.2385 0.175" rpy="0 0 0" />
      <geometry>
        <box size="0.11 0.007 0.008" />
        </geometry>
      <material name="satin_aluminum" />
      </visual>
    <visual>
      <origin xyz="0.032 0.2385 0.187" rpy="0 0 0" />
      <geometry>
        <box size="0.11 0.007 0.008" />
        </geometry>
      <material name="satin_aluminum" />
      </visual>
    <visual>
      <origin xyz="0.032 0.2385 0.199" rpy="0 0 0" />
      <geometry>
        <box size="0.11 0.007 0.008" />
        </geometry>
      <material name="satin_aluminum" />
      </visual>
    <visual>
      <origin xyz="0.032 0.2385 0.211" rpy="0 0 0" />
      <geometry>
        <box size="0.11 0.007 0.008" />
        </geometry>
      <material name="satin_aluminum" />
      </visual>
    <visual>
      <origin xyz="0.032 0.2385 0.223" rpy="0 0 0" />
      <geometry>
        <box size="0.11 0.007 0.008" />
        </geometry>
      <material name="satin_aluminum" />
      </visual>
    <visual>
      <origin xyz="0.032 0.2385 0.235" rpy="0 0 0" />
      <geometry>
        <box size="0.11 0.007 0.008" />
        </geometry>
      <material name="satin_aluminum" />
      </visual>
    <visual>
      <origin xyz="0.032 0.2385 0.247" rpy="0 0 0" />
      <geometry>
        <box size="0.11 0.007 0.008" />
        </geometry>
      <material name="satin_aluminum" />
      </visual>
    <visual>
      <origin xyz="-0.07 0.239 0.392" rpy="0 0 0" />
      <geometry>
        <box size="0.018 0.008 0.014" />
        </geometry>
      <material name="io_dark" />
      </visual>
    <visual>
      <origin xyz="-0.062 0.239 0.354" rpy="0 0 0" />
      <geometry>
        <box size="0.018 0.008 0.014" />
        </geometry>
      <material name="io_dark" />
      </visual>
    <visual>
      <origin xyz="-0.08 0.239 0.318" rpy="0 0 0" />
      <geometry>
        <box size="0.018 0.008 0.014" />
        </geometry>
      <material name="io_dark" />
      </visual>
    <visual>
      <origin xyz="-0.048 0.239 0.318" rpy="0 0 0" />
      <geometry>
        <box size="0.018 0.008 0.014" />
        </geometry>
      <material name="io_dark" />
      </visual>
    <visual>
      <origin xyz="0.056 0.237 0.422" rpy="1.5708 0 0" />
      <geometry>
        <cylinder radius="0.06" length="0.01" />
        </geometry>
      <material name="mesh_black" />
      </visual>
    <visual>
      <origin xyz="0.056 0.237 0.422" rpy="1.5708 0 0" />
      <geometry>
        <cylinder radius="0.015" length="0.014" />
        </geometry>
      <material name="io_dark" />
      </visual>
    <visual>
      <origin xyz="0.024 -0.124 0.527" rpy="0 0 0" />
      <geometry>
        <box size="0.08 0.05 0.01" />
        </geometry>
      <material name="powder_steel" />
      </visual>
    <visual>
      <origin xyz="0.057 -0.12 0.531" rpy="0 0 0" />
      <geometry>
        <cylinder radius="0.009" length="0.006" />
        </geometry>
      <material name="satin_aluminum" />
      </visual>
    <visual>
      <origin xyz="0.016 -0.125 0.53" rpy="0 0 0" />
      <geometry>
        <box size="0.02 0.01 0.004" />
        </geometry>
      <material name="io_dark" />
      </visual>
    <visual>
      <origin xyz="0.057 -0.12 0.5345" rpy="0 0 0" />
      <geometry>
        <box size="0.006 0.002 0.002" />
        </geometry>
      <material name="status_led" />
      </visual>
    <visual>
      <origin xyz="0.106 -0.231 0.293" rpy="0 0 0" />
      <geometry>
        <box size="0.01 0.008 0.18" />
        </geometry>
      <material name="satin_aluminum" />
      </visual>
    <visual>
      <origin xyz="-0.078 -0.18 0.009" rpy="0 0 0" />
      <geometry>
        <cylinder radius="0.018" length="0.018" />
        </geometry>
      <material name="rubber" />
      </visual>
    <visual>
      <origin xyz="-0.078 0.18 0.009" rpy="0 0 0" />
      <geometry>
        <cylinder radius="0.018" length="0.018" />
        </geometry>
      <material name="rubber" />
      </visual>
    <visual>
      <origin xyz="0.078 -0.18 0.009" rpy="0 0 0" />
      <geometry>
        <cylinder radius="0.018" length="0.018" />
        </geometry>
      <material name="rubber" />
      </visual>
    <visual>
      <origin xyz="0.078 0.18 0.009" rpy="0 0 0" />
      <geometry>
        <cylinder radius="0.018" length="0.018" />
        </geometry>
      <material name="rubber" />
      </visual>
    </link>
  <link name="side_panel">
    <inertial>
      <origin xyz="0 -0.225 0.2445" rpy="0 0 0" />
      <mass value="2.8" />
      <inertia ixx="0.103045" ixy="0" ixz="0" iyy="0.0558063" iyz="0" izz="0.0472614" />
      </inertial>
    <visual>
      <geometry>
        <mesh filename="assets/meshes/side_panel_frame.obj" />
        </geometry>
      <material name="powder_steel" />
      </visual>
    <visual>
      <origin xyz="0 -0.225 0.2445" rpy="0 0 0" />
      <geometry>
        <box size="0.003 0.42 0.445" />
        </geometry>
      <material name="smoked_glass" />
      </visual>
    <visual>
      <origin xyz="0 -0.43 0.118" rpy="0 1.5708 0" />
      <geometry>
        <cylinder radius="0.005" length="0.01" />
        </geometry>
      <material name="satin_aluminum" />
      </visual>
    <visual>
      <origin xyz="0 -0.43 0.374" rpy="0 1.5708 0" />
      <geometry>
        <cylinder radius="0.005" length="0.01" />
        </geometry>
      <material name="satin_aluminum" />
      </visual>
    </link>
  <link name="front_door">
    <inertial>
      <origin xyz="-0.112 0 0.2405" rpy="0 0 0" />
      <mass value="1.3" />
      <inertia ixx="0.0250853" ixy="0" ixz="0" iyy="0.0304998" iyz="0" izz="0.00545697" />
      </inertial>
    <visual>
      <geometry>
        <mesh filename="assets/meshes/front_door.obj" />
        </geometry>
      <material name="powder_steel" />
      </visual>
    <visual>
      <origin xyz="-0.21 -0.012 0.245" rpy="0 0 0" />
      <geometry>
        <box size="0.01 0.018 0.208" />
        </geometry>
      <material name="satin_aluminum" />
      </visual>
    </link>
  <joint name="chassis_to_side_panel" type="revolute">
    <origin xyz="-0.1205 0.225 0.026" rpy="0 0 0" />
    <parent link="chassis" />
    <child link="side_panel" />
    <axis xyz="0 0 -1" />
    <limit effort="6" velocity="1.4" lower="0" upper="1.22" />
    </joint>
  <joint name="chassis_to_front_door" type="revolute">
    <origin xyz="0.112 -0.242 0.03" rpy="0 0 0" />
    <parent link="chassis" />
    <child link="front_door" />
    <axis xyz="0 0 -1" />
    <limit effort="4" velocity="1.8" lower="0" upper="1.65" />
    </joint>
  </robot>
