<robot name="manual_wheelchair">
  <link name="frame">
    <inertial>
      <origin xyz="0 0.04 0.48" rpy="0 0 0" />
      <mass value="11.5" />
      <inertia ixx="1.69433" ixy="0" ixz="0" iyy="1.35278" iyz="0" izz="1.28072" />
    </inertial>
    <visual>
      <geometry>
        <mesh filename="meshes/wheelchair_frame.glb" />
      </geometry>
      <material name="frame_metal">
        <color rgba="0.7 0.73 0.77 1" />
      </material>
    </visual>
    <visual>
      <origin xyz="0 0.03 0.482" rpy="-0.05 0 0" />
      <geometry>
        <box size="0.46 0.4 0.018" />
      </geometry>
      <material name="upholstery_black">
        <color rgba="0.12 0.12 0.13 1" />
      </material>
    </visual>
    <visual>
      <origin xyz="0 -0.145 0.675" rpy="-0.08 0 0" />
      <geometry>
        <box size="0.44 0.018 0.34" />
      </geometry>
      <material name="upholstery_black">
        <color rgba="0.12 0.12 0.13 1" />
      </material>
    </visual>
    <visual>
      <origin xyz="0.232 -0.045 0.695" rpy="0 0 0" />
      <geometry>
        <box size="0.04 0.27 0.028" />
      </geometry>
      <material name="black_plastic">
        <color rgba="0.14 0.15 0.16 1" />
      </material>
    </visual>
    <visual>
      <origin xyz="-0.232 -0.045 0.695" rpy="0 0 0" />
      <geometry>
        <box size="0.04 0.27 0.028" />
      </geometry>
      <material name="black_plastic">
        <color rgba="0.14 0.15 0.16 1" />
      </material>
    </visual>
    <collision name="frame__visual_1__hull_001">
      <geometry>
        <mesh filename="meshes/collision/cache/a0a8b97e14a4a19c974d6c08__hull_001.obj" />
      </geometry>
    </collision>
    <collision name="frame__visual_1__hull_002">
      <geometry>
        <mesh filename="meshes/collision/cache/a0a8b97e14a4a19c974d6c08__hull_002.obj" />
      </geometry>
    </collision>
    <collision name="frame__visual_1__hull_003">
      <geometry>
        <mesh filename="meshes/collision/cache/a0a8b97e14a4a19c974d6c08__hull_003.obj" />
      </geometry>
    </collision>
    <collision name="frame__visual_1__hull_004">
      <geometry>
        <mesh filename="meshes/collision/cache/a0a8b97e14a4a19c974d6c08__hull_004.obj" />
      </geometry>
    </collision>
    <collision name="frame__visual_1__hull_005">
      <geometry>
        <mesh filename="meshes/collision/cache/a0a8b97e14a4a19c974d6c08__hull_005.obj" />
      </geometry>
    </collision>
    <collision name="frame__visual_1__hull_006">
      <geometry>
        <mesh filename="meshes/collision/cache/a0a8b97e14a4a19c974d6c08__hull_006.obj" />
      </geometry>
    </collision>
    <collision name="frame__visual_1__hull_007">
      <geometry>
        <mesh filename="meshes/collision/cache/a0a8b97e14a4a19c974d6c08__hull_007.obj" />
      </geometry>
    </collision>
    <collision name="frame__visual_1__hull_008">
      <geometry>
        <mesh filename="meshes/collision/cache/a0a8b97e14a4a19c974d6c08__hull_008.obj" />
      </geometry>
    </collision>
    <collision name="frame__visual_1__hull_009">
      <geometry>
        <mesh filename="meshes/collision/cache/a0a8b97e14a4a19c974d6c08__hull_009.obj" />
      </geometry>
    </collision>
    <collision name="frame__visual_1__hull_010">
      <geometry>
        <mesh filename="meshes/collision/cache/a0a8b97e14a4a19c974d6c08__hull_010.obj" />
      </geometry>
    </collision>
    <collision name="frame__visual_1__hull_011">
      <geometry>
        <mesh filename="meshes/collision/cache/a0a8b97e14a4a19c974d6c08__hull_011.obj" />
      </geometry>
    </collision>
    <collision name="frame__visual_1__hull_012">
      <geometry>
        <mesh filename="meshes/collision/cache/a0a8b97e14a4a19c974d6c08__hull_012.obj" />
      </geometry>
    </collision>
    <collision name="frame__visual_1__hull_013">
      <geometry>
        <mesh filename="meshes/collision/cache/a0a8b97e14a4a19c974d6c08__hull_013.obj" />
      </geometry>
    </collision>
    <collision name="frame__visual_1__hull_014">
      <geometry>
        <mesh filename="meshes/collision/cache/a0a8b97e14a4a19c974d6c08__hull_014.obj" />
      </geometry>
    </collision>
    <collision name="frame__visual_1__hull_015">
      <geometry>
        <mesh filename="meshes/collision/cache/a0a8b97e14a4a19c974d6c08__hull_015.obj" />
      </geometry>
    </collision>
    <collision name="frame__visual_1__hull_016">
      <geometry>
        <mesh filename="meshes/collision/cache/a0a8b97e14a4a19c974d6c08__hull_016.obj" />
      </geometry>
    </collision>
    <collision name="frame__visual_2">
      <origin xyz="0 0.03 0.482" rpy="-0.05 0 0" />
      <geometry>
        <box size="0.46 0.4 0.018" />
      </geometry>
    </collision>
    <collision name="frame__visual_3">
      <origin xyz="0 -0.145 0.675" rpy="-0.08 0 0" />
      <geometry>
        <box size="0.44 0.018 0.34" />
      </geometry>
    </collision>
    <collision name="frame__visual_4">
      <origin xyz="0.232 -0.045 0.695" rpy="0 0 0" />
      <geometry>
        <box size="0.04 0.27 0.028" />
      </geometry>
    </collision>
    <collision name="frame__visual_5">
      <origin xyz="-0.232 -0.045 0.695" rpy="0 0 0" />
      <geometry>
        <box size="0.04 0.27 0.028" />
      </geometry>
    </collision>
  </link>
  <link name="left_rear_wheel">
    <inertial>
      <origin xyz="0 0 0" rpy="0 1.5708 0" />
      <mass value="1.8" />
      <inertia ixx="0.0420149" ixy="0" ixz="0" iyy="0.0420149" iyz="0" izz="0.0837225" />
    </inertial>
    <visual>
      <origin xyz="0 0 0" rpy="0 1.5708 0" />
      <geometry>
        <mesh filename="meshes/wheelchair_rear_tire.glb" />
      </geometry>
      <material name="rubber_black">
        <color rgba="0.07 0.07 0.08 1" />
      </material>
    </visual>
    <visual>
      <origin xyz="0 0 0" rpy="0 1.5708 0" />
      <geometry>
        <mesh filename="meshes/wheelchair_rear_wheel_core.glb" />
      </geometry>
      <material name="aluminum">
        <color rgba="0.82 0.84 0.87 1" />
      </material>
    </visual>
    <visual>
      <origin xyz="0 0 0" rpy="0 1.5708 0" />
      <geometry>
        <mesh filename="meshes/wheelchair_handrim.glb" />
      </geometry>
      <material name="brushed_steel">
        <color rgba="0.69 0.71 0.74 1" />
      </material>
    </visual>
    <collision name="left_rear_wheel__visual_1__hull_001">
      <origin xyz="0 0 0" rpy="0 1.5708 0" />
      <geometry>
        <mesh filename="meshes/collision/cache/e2d360d35b584ca676bdd950__hull_001.obj" />
      </geometry>
    </collision>
    <collision name="left_rear_wheel__visual_1__hull_002">
      <origin xyz="0 0 0" rpy="0 1.5708 0" />
      <geometry>
        <mesh filename="meshes/collision/cache/e2d360d35b584ca676bdd950__hull_002.obj" />
      </geometry>
    </collision>
    <collision name="left_rear_wheel__visual_1__hull_003">
      <origin xyz="0 0 0" rpy="0 1.5708 0" />
      <geometry>
        <mesh filename="meshes/collision/cache/e2d360d35b584ca676bdd950__hull_003.obj" />
      </geometry>
    </collision>
    <collision name="left_rear_wheel__visual_1__hull_004">
      <origin xyz="0 0 0" rpy="0 1.5708 0" />
      <geometry>
        <mesh filename="meshes/collision/cache/e2d360d35b584ca676bdd950__hull_004.obj" />
      </geometry>
    </collision>
    <collision name="left_rear_wheel__visual_1__hull_005">
      <origin xyz="0 0 0" rpy="0 1.5708 0" />
      <geometry>
        <mesh filename="meshes/collision/cache/e2d360d35b584ca676bdd950__hull_005.obj" />
      </geometry>
    </collision>
    <collision name="left_rear_wheel__visual_1__hull_006">
      <origin xyz="0 0 0" rpy="0 1.5708 0" />
      <geometry>
        <mesh filename="meshes/collision/cache/e2d360d35b584ca676bdd950__hull_006.obj" />
      </geometry>
    </collision>
    <collision name="left_rear_wheel__visual_1__hull_007">
      <origin xyz="0 0 0" rpy="0 1.5708 0" />
      <geometry>
        <mesh filename="meshes/collision/cache/e2d360d35b584ca676bdd950__hull_007.obj" />
      </geometry>
    </collision>
    <collision name="left_rear_wheel__visual_1__hull_008">
      <origin xyz="0 0 0" rpy="0 1.5708 0" />
      <geometry>
        <mesh filename="meshes/collision/cache/e2d360d35b584ca676bdd950__hull_008.obj" />
      </geometry>
    </collision>
    <collision name="left_rear_wheel__visual_1__hull_009">
      <origin xyz="0 0 0" rpy="0 1.5708 0" />
      <geometry>
        <mesh filename="meshes/collision/cache/e2d360d35b584ca676bdd950__hull_009.obj" />
      </geometry>
    </collision>
    <collision name="left_rear_wheel__visual_2__hull_001">
      <origin xyz="0 0 0" rpy="0 1.5708 0" />
      <geometry>
        <mesh filename="meshes/collision/cache/db1868ba5911adfc08900841__hull_001.obj" />
      </geometry>
    </collision>
    <collision name="left_rear_wheel__visual_2__hull_002">
      <origin xyz="0 0 0" rpy="0 1.5708 0" />
      <geometry>
        <mesh filename="meshes/collision/cache/db1868ba5911adfc08900841__hull_002.obj" />
      </geometry>
    </collision>
    <collision name="left_rear_wheel__visual_2__hull_003">
      <origin xyz="0 0 0" rpy="0 1.5708 0" />
      <geometry>
        <mesh filename="meshes/collision/cache/db1868ba5911adfc08900841__hull_003.obj" />
      </geometry>
    </collision>
    <collision name="left_rear_wheel__visual_2__hull_004">
      <origin xyz="0 0 0" rpy="0 1.5708 0" />
      <geometry>
        <mesh filename="meshes/collision/cache/db1868ba5911adfc08900841__hull_004.obj" />
      </geometry>
    </collision>
    <collision name="left_rear_wheel__visual_2__hull_005">
      <origin xyz="0 0 0" rpy="0 1.5708 0" />
      <geometry>
        <mesh filename="meshes/collision/cache/db1868ba5911adfc08900841__hull_005.obj" />
      </geometry>
    </collision>
    <collision name="left_rear_wheel__visual_2__hull_006">
      <origin xyz="0 0 0" rpy="0 1.5708 0" />
      <geometry>
        <mesh filename="meshes/collision/cache/db1868ba5911adfc08900841__hull_006.obj" />
      </geometry>
    </collision>
    <collision name="left_rear_wheel__visual_2__hull_007">
      <origin xyz="0 0 0" rpy="0 1.5708 0" />
      <geometry>
        <mesh filename="meshes/collision/cache/db1868ba5911adfc08900841__hull_007.obj" />
      </geometry>
    </collision>
    <collision name="left_rear_wheel__visual_2__hull_008">
      <origin xyz="0 0 0" rpy="0 1.5708 0" />
      <geometry>
        <mesh filename="meshes/collision/cache/db1868ba5911adfc08900841__hull_008.obj" />
      </geometry>
    </collision>
    <collision name="left_rear_wheel__visual_2__hull_009">
      <origin xyz="0 0 0" rpy="0 1.5708 0" />
      <geometry>
        <mesh filename="meshes/collision/cache/db1868ba5911adfc08900841__hull_009.obj" />
      </geometry>
    </collision>
    <collision name="left_rear_wheel__visual_2__hull_010">
      <origin xyz="0 0 0" rpy="0 1.5708 0" />
      <geometry>
        <mesh filename="meshes/collision/cache/db1868ba5911adfc08900841__hull_010.obj" />
      </geometry>
    </collision>
    <collision name="left_rear_wheel__visual_2__hull_011">
      <origin xyz="0 0 0" rpy="0 1.5708 0" />
      <geometry>
        <mesh filename="meshes/collision/cache/db1868ba5911adfc08900841__hull_011.obj" />
      </geometry>
    </collision>
    <collision name="left_rear_wheel__visual_2__hull_012">
      <origin xyz="0 0 0" rpy="0 1.5708 0" />
      <geometry>
        <mesh filename="meshes/collision/cache/db1868ba5911adfc08900841__hull_012.obj" />
      </geometry>
    </collision>
    <collision name="left_rear_wheel__visual_2__hull_013">
      <origin xyz="0 0 0" rpy="0 1.5708 0" />
      <geometry>
        <mesh filename="meshes/collision/cache/db1868ba5911adfc08900841__hull_013.obj" />
      </geometry>
    </collision>
    <collision name="left_rear_wheel__visual_2__hull_014">
      <origin xyz="0 0 0" rpy="0 1.5708 0" />
      <geometry>
        <mesh filename="meshes/collision/cache/db1868ba5911adfc08900841__hull_014.obj" />
      </geometry>
    </collision>
    <collision name="left_rear_wheel__visual_2__hull_015">
      <origin xyz="0 0 0" rpy="0 1.5708 0" />
      <geometry>
        <mesh filename="meshes/collision/cache/db1868ba5911adfc08900841__hull_015.obj" />
      </geometry>
    </collision>
    <collision name="left_rear_wheel__visual_2__hull_016">
      <origin xyz="0 0 0" rpy="0 1.5708 0" />
      <geometry>
        <mesh filename="meshes/collision/cache/db1868ba5911adfc08900841__hull_016.obj" />
      </geometry>
    </collision>
    <collision name="left_rear_wheel__visual_3__hull_001">
      <origin xyz="0 0 0" rpy="0 1.5708 0" />
      <geometry>
        <mesh filename="meshes/collision/cache/5903c3b7986324b7185f1c7a__hull_001.obj" />
      </geometry>
    </collision>
    <collision name="left_rear_wheel__visual_3__hull_002">
      <origin xyz="0 0 0" rpy="0 1.5708 0" />
      <geometry>
        <mesh filename="meshes/collision/cache/5903c3b7986324b7185f1c7a__hull_002.obj" />
      </geometry>
    </collision>
    <collision name="left_rear_wheel__visual_3__hull_003">
      <origin xyz="0 0 0" rpy="0 1.5708 0" />
      <geometry>
        <mesh filename="meshes/collision/cache/5903c3b7986324b7185f1c7a__hull_003.obj" />
      </geometry>
    </collision>
    <collision name="left_rear_wheel__visual_3__hull_004">
      <origin xyz="0 0 0" rpy="0 1.5708 0" />
      <geometry>
        <mesh filename="meshes/collision/cache/5903c3b7986324b7185f1c7a__hull_004.obj" />
      </geometry>
    </collision>
    <collision name="left_rear_wheel__visual_3__hull_005">
      <origin xyz="0 0 0" rpy="0 1.5708 0" />
      <geometry>
        <mesh filename="meshes/collision/cache/5903c3b7986324b7185f1c7a__hull_005.obj" />
      </geometry>
    </collision>
    <collision name="left_rear_wheel__visual_3__hull_006">
      <origin xyz="0 0 0" rpy="0 1.5708 0" />
      <geometry>
        <mesh filename="meshes/collision/cache/5903c3b7986324b7185f1c7a__hull_006.obj" />
      </geometry>
    </collision>
    <collision name="left_rear_wheel__visual_3__hull_007">
      <origin xyz="0 0 0" rpy="0 1.5708 0" />
      <geometry>
        <mesh filename="meshes/collision/cache/5903c3b7986324b7185f1c7a__hull_007.obj" />
      </geometry>
    </collision>
    <collision name="left_rear_wheel__visual_3__hull_008">
      <origin xyz="0 0 0" rpy="0 1.5708 0" />
      <geometry>
        <mesh filename="meshes/collision/cache/5903c3b7986324b7185f1c7a__hull_008.obj" />
      </geometry>
    </collision>
    <collision name="left_rear_wheel__visual_3__hull_009">
      <origin xyz="0 0 0" rpy="0 1.5708 0" />
      <geometry>
        <mesh filename="meshes/collision/cache/5903c3b7986324b7185f1c7a__hull_009.obj" />
      </geometry>
    </collision>
    <collision name="left_rear_wheel__visual_3__hull_010">
      <origin xyz="0 0 0" rpy="0 1.5708 0" />
      <geometry>
        <mesh filename="meshes/collision/cache/5903c3b7986324b7185f1c7a__hull_010.obj" />
      </geometry>
    </collision>
    <collision name="left_rear_wheel__visual_3__hull_011">
      <origin xyz="0 0 0" rpy="0 1.5708 0" />
      <geometry>
        <mesh filename="meshes/collision/cache/5903c3b7986324b7185f1c7a__hull_011.obj" />
      </geometry>
    </collision>
    <collision name="left_rear_wheel__visual_3__hull_012">
      <origin xyz="0 0 0" rpy="0 1.5708 0" />
      <geometry>
        <mesh filename="meshes/collision/cache/5903c3b7986324b7185f1c7a__hull_012.obj" />
      </geometry>
    </collision>
    <collision name="left_rear_wheel__visual_3__hull_013">
      <origin xyz="0 0 0" rpy="0 1.5708 0" />
      <geometry>
        <mesh filename="meshes/collision/cache/5903c3b7986324b7185f1c7a__hull_013.obj" />
      </geometry>
    </collision>
    <collision name="left_rear_wheel__visual_3__hull_014">
      <origin xyz="0 0 0" rpy="0 1.5708 0" />
      <geometry>
        <mesh filename="meshes/collision/cache/5903c3b7986324b7185f1c7a__hull_014.obj" />
      </geometry>
    </collision>
  </link>
  <link name="right_rear_wheel">
    <inertial>
      <origin xyz="0 0 0" rpy="0 -1.5708 0" />
      <mass value="1.8" />
      <inertia ixx="0.0420149" ixy="0" ixz="0" iyy="0.0420149" iyz="0" izz="0.0837225" />
    </inertial>
    <visual>
      <origin xyz="0 0 0" rpy="0 -1.5708 0" />
      <geometry>
        <mesh filename="meshes/wheelchair_rear_tire.glb" />
      </geometry>
      <material name="rubber_black">
        <color rgba="0.07 0.07 0.08 1" />
      </material>
    </visual>
    <visual>
      <origin xyz="0 0 0" rpy="0 -1.5708 0" />
      <geometry>
        <mesh filename="meshes/wheelchair_rear_wheel_core.glb" />
      </geometry>
      <material name="aluminum">
        <color rgba="0.82 0.84 0.87 1" />
      </material>
    </visual>
    <visual>
      <origin xyz="0 0 0" rpy="0 -1.5708 0" />
      <geometry>
        <mesh filename="meshes/wheelchair_handrim.glb" />
      </geometry>
      <material name="brushed_steel">
        <color rgba="0.69 0.71 0.74 1" />
      </material>
    </visual>
    <collision name="right_rear_wheel__visual_1__hull_001">
      <origin xyz="0 0 0" rpy="0 -1.5708 0" />
      <geometry>
        <mesh filename="meshes/collision/cache/e2d360d35b584ca676bdd950__hull_001.obj" />
      </geometry>
    </collision>
    <collision name="right_rear_wheel__visual_1__hull_002">
      <origin xyz="0 0 0" rpy="0 -1.5708 0" />
      <geometry>
        <mesh filename="meshes/collision/cache/e2d360d35b584ca676bdd950__hull_002.obj" />
      </geometry>
    </collision>
    <collision name="right_rear_wheel__visual_1__hull_003">
      <origin xyz="0 0 0" rpy="0 -1.5708 0" />
      <geometry>
        <mesh filename="meshes/collision/cache/e2d360d35b584ca676bdd950__hull_003.obj" />
      </geometry>
    </collision>
    <collision name="right_rear_wheel__visual_1__hull_004">
      <origin xyz="0 0 0" rpy="0 -1.5708 0" />
      <geometry>
        <mesh filename="meshes/collision/cache/e2d360d35b584ca676bdd950__hull_004.obj" />
      </geometry>
    </collision>
    <collision name="right_rear_wheel__visual_1__hull_005">
      <origin xyz="0 0 0" rpy="0 -1.5708 0" />
      <geometry>
        <mesh filename="meshes/collision/cache/e2d360d35b584ca676bdd950__hull_005.obj" />
      </geometry>
    </collision>
    <collision name="right_rear_wheel__visual_1__hull_006">
      <origin xyz="0 0 0" rpy="0 -1.5708 0" />
      <geometry>
        <mesh filename="meshes/collision/cache/e2d360d35b584ca676bdd950__hull_006.obj" />
      </geometry>
    </collision>
    <collision name="right_rear_wheel__visual_1__hull_007">
      <origin xyz="0 0 0" rpy="0 -1.5708 0" />
      <geometry>
        <mesh filename="meshes/collision/cache/e2d360d35b584ca676bdd950__hull_007.obj" />
      </geometry>
    </collision>
    <collision name="right_rear_wheel__visual_1__hull_008">
      <origin xyz="0 0 0" rpy="0 -1.5708 0" />
      <geometry>
        <mesh filename="meshes/collision/cache/e2d360d35b584ca676bdd950__hull_008.obj" />
      </geometry>
    </collision>
    <collision name="right_rear_wheel__visual_1__hull_009">
      <origin xyz="0 0 0" rpy="0 -1.5708 0" />
      <geometry>
        <mesh filename="meshes/collision/cache/e2d360d35b584ca676bdd950__hull_009.obj" />
      </geometry>
    </collision>
    <collision name="right_rear_wheel__visual_2__hull_001">
      <origin xyz="0 0 0" rpy="0 -1.5708 0" />
      <geometry>
        <mesh filename="meshes/collision/cache/db1868ba5911adfc08900841__hull_001.obj" />
      </geometry>
    </collision>
    <collision name="right_rear_wheel__visual_2__hull_002">
      <origin xyz="0 0 0" rpy="0 -1.5708 0" />
      <geometry>
        <mesh filename="meshes/collision/cache/db1868ba5911adfc08900841__hull_002.obj" />
      </geometry>
    </collision>
    <collision name="right_rear_wheel__visual_2__hull_003">
      <origin xyz="0 0 0" rpy="0 -1.5708 0" />
      <geometry>
        <mesh filename="meshes/collision/cache/db1868ba5911adfc08900841__hull_003.obj" />
      </geometry>
    </collision>
    <collision name="right_rear_wheel__visual_2__hull_004">
      <origin xyz="0 0 0" rpy="0 -1.5708 0" />
      <geometry>
        <mesh filename="meshes/collision/cache/db1868ba5911adfc08900841__hull_004.obj" />
      </geometry>
    </collision>
    <collision name="right_rear_wheel__visual_2__hull_005">
      <origin xyz="0 0 0" rpy="0 -1.5708 0" />
      <geometry>
        <mesh filename="meshes/collision/cache/db1868ba5911adfc08900841__hull_005.obj" />
      </geometry>
    </collision>
    <collision name="right_rear_wheel__visual_2__hull_006">
      <origin xyz="0 0 0" rpy="0 -1.5708 0" />
      <geometry>
        <mesh filename="meshes/collision/cache/db1868ba5911adfc08900841__hull_006.obj" />
      </geometry>
    </collision>
    <collision name="right_rear_wheel__visual_2__hull_007">
      <origin xyz="0 0 0" rpy="0 -1.5708 0" />
      <geometry>
        <mesh filename="meshes/collision/cache/db1868ba5911adfc08900841__hull_007.obj" />
      </geometry>
    </collision>
    <collision name="right_rear_wheel__visual_2__hull_008">
      <origin xyz="0 0 0" rpy="0 -1.5708 0" />
      <geometry>
        <mesh filename="meshes/collision/cache/db1868ba5911adfc08900841__hull_008.obj" />
      </geometry>
    </collision>
    <collision name="right_rear_wheel__visual_2__hull_009">
      <origin xyz="0 0 0" rpy="0 -1.5708 0" />
      <geometry>
        <mesh filename="meshes/collision/cache/db1868ba5911adfc08900841__hull_009.obj" />
      </geometry>
    </collision>
    <collision name="right_rear_wheel__visual_2__hull_010">
      <origin xyz="0 0 0" rpy="0 -1.5708 0" />
      <geometry>
        <mesh filename="meshes/collision/cache/db1868ba5911adfc08900841__hull_010.obj" />
      </geometry>
    </collision>
    <collision name="right_rear_wheel__visual_2__hull_011">
      <origin xyz="0 0 0" rpy="0 -1.5708 0" />
      <geometry>
        <mesh filename="meshes/collision/cache/db1868ba5911adfc08900841__hull_011.obj" />
      </geometry>
    </collision>
    <collision name="right_rear_wheel__visual_2__hull_012">
      <origin xyz="0 0 0" rpy="0 -1.5708 0" />
      <geometry>
        <mesh filename="meshes/collision/cache/db1868ba5911adfc08900841__hull_012.obj" />
      </geometry>
    </collision>
    <collision name="right_rear_wheel__visual_2__hull_013">
      <origin xyz="0 0 0" rpy="0 -1.5708 0" />
      <geometry>
        <mesh filename="meshes/collision/cache/db1868ba5911adfc08900841__hull_013.obj" />
      </geometry>
    </collision>
    <collision name="right_rear_wheel__visual_2__hull_014">
      <origin xyz="0 0 0" rpy="0 -1.5708 0" />
      <geometry>
        <mesh filename="meshes/collision/cache/db1868ba5911adfc08900841__hull_014.obj" />
      </geometry>
    </collision>
    <collision name="right_rear_wheel__visual_2__hull_015">
      <origin xyz="0 0 0" rpy="0 -1.5708 0" />
      <geometry>
        <mesh filename="meshes/collision/cache/db1868ba5911adfc08900841__hull_015.obj" />
      </geometry>
    </collision>
    <collision name="right_rear_wheel__visual_2__hull_016">
      <origin xyz="0 0 0" rpy="0 -1.5708 0" />
      <geometry>
        <mesh filename="meshes/collision/cache/db1868ba5911adfc08900841__hull_016.obj" />
      </geometry>
    </collision>
    <collision name="right_rear_wheel__visual_3__hull_001">
      <origin xyz="0 0 0" rpy="0 -1.5708 0" />
      <geometry>
        <mesh filename="meshes/collision/cache/5903c3b7986324b7185f1c7a__hull_001.obj" />
      </geometry>
    </collision>
    <collision name="right_rear_wheel__visual_3__hull_002">
      <origin xyz="0 0 0" rpy="0 -1.5708 0" />
      <geometry>
        <mesh filename="meshes/collision/cache/5903c3b7986324b7185f1c7a__hull_002.obj" />
      </geometry>
    </collision>
    <collision name="right_rear_wheel__visual_3__hull_003">
      <origin xyz="0 0 0" rpy="0 -1.5708 0" />
      <geometry>
        <mesh filename="meshes/collision/cache/5903c3b7986324b7185f1c7a__hull_003.obj" />
      </geometry>
    </collision>
    <collision name="right_rear_wheel__visual_3__hull_004">
      <origin xyz="0 0 0" rpy="0 -1.5708 0" />
      <geometry>
        <mesh filename="meshes/collision/cache/5903c3b7986324b7185f1c7a__hull_004.obj" />
      </geometry>
    </collision>
    <collision name="right_rear_wheel__visual_3__hull_005">
      <origin xyz="0 0 0" rpy="0 -1.5708 0" />
      <geometry>
        <mesh filename="meshes/collision/cache/5903c3b7986324b7185f1c7a__hull_005.obj" />
      </geometry>
    </collision>
    <collision name="right_rear_wheel__visual_3__hull_006">
      <origin xyz="0 0 0" rpy="0 -1.5708 0" />
      <geometry>
        <mesh filename="meshes/collision/cache/5903c3b7986324b7185f1c7a__hull_006.obj" />
      </geometry>
    </collision>
    <collision name="right_rear_wheel__visual_3__hull_007">
      <origin xyz="0 0 0" rpy="0 -1.5708 0" />
      <geometry>
        <mesh filename="meshes/collision/cache/5903c3b7986324b7185f1c7a__hull_007.obj" />
      </geometry>
    </collision>
    <collision name="right_rear_wheel__visual_3__hull_008">
      <origin xyz="0 0 0" rpy="0 -1.5708 0" />
      <geometry>
        <mesh filename="meshes/collision/cache/5903c3b7986324b7185f1c7a__hull_008.obj" />
      </geometry>
    </collision>
    <collision name="right_rear_wheel__visual_3__hull_009">
      <origin xyz="0 0 0" rpy="0 -1.5708 0" />
      <geometry>
        <mesh filename="meshes/collision/cache/5903c3b7986324b7185f1c7a__hull_009.obj" />
      </geometry>
    </collision>
    <collision name="right_rear_wheel__visual_3__hull_010">
      <origin xyz="0 0 0" rpy="0 -1.5708 0" />
      <geometry>
        <mesh filename="meshes/collision/cache/5903c3b7986324b7185f1c7a__hull_010.obj" />
      </geometry>
    </collision>
    <collision name="right_rear_wheel__visual_3__hull_011">
      <origin xyz="0 0 0" rpy="0 -1.5708 0" />
      <geometry>
        <mesh filename="meshes/collision/cache/5903c3b7986324b7185f1c7a__hull_011.obj" />
      </geometry>
    </collision>
    <collision name="right_rear_wheel__visual_3__hull_012">
      <origin xyz="0 0 0" rpy="0 -1.5708 0" />
      <geometry>
        <mesh filename="meshes/collision/cache/5903c3b7986324b7185f1c7a__hull_012.obj" />
      </geometry>
    </collision>
    <collision name="right_rear_wheel__visual_3__hull_013">
      <origin xyz="0 0 0" rpy="0 -1.5708 0" />
      <geometry>
        <mesh filename="meshes/collision/cache/5903c3b7986324b7185f1c7a__hull_013.obj" />
      </geometry>
    </collision>
    <collision name="right_rear_wheel__visual_3__hull_014">
      <origin xyz="0 0 0" rpy="0 -1.5708 0" />
      <geometry>
        <mesh filename="meshes/collision/cache/5903c3b7986324b7185f1c7a__hull_014.obj" />
      </geometry>
    </collision>
  </link>
  <link name="left_caster_fork">
    <inertial>
      <origin xyz="0 -0.024 -0.072" rpy="0 0 0" />
      <mass value="0.35" />
      <inertia ixx="0.000492917" ixy="0" ixz="0" iyy="0.000525" iyz="0" izz="0.000177917" />
    </inertial>
    <visual>
      <origin xyz="0 0 -0.02" rpy="0 0 0" />
      <geometry>
        <cylinder radius="0.008" length="0.04" />
      </geometry>
      <material name="frame_metal">
        <color rgba="0.7 0.73 0.77 1" />
      </material>
    </visual>
    <visual>
      <origin xyz="0 -0.02 -0.046" rpy="0 0 0" />
      <geometry>
        <box size="0.048 0.018 0.01" />
      </geometry>
      <material name="frame_metal">
        <color rgba="0.7 0.73 0.77 1" />
      </material>
    </visual>
    <visual>
      <origin xyz="0.02 -0.034 -0.09" rpy="0 0 0" />
      <geometry>
        <box size="0.006 0.016 0.084" />
      </geometry>
      <material name="frame_metal">
        <color rgba="0.7 0.73 0.77 1" />
      </material>
    </visual>
    <visual>
      <origin xyz="-0.02 -0.034 -0.09" rpy="0 0 0" />
      <geometry>
        <box size="0.006 0.016 0.084" />
      </geometry>
      <material name="frame_metal">
        <color rgba="0.7 0.73 0.77 1" />
      </material>
    </visual>
    <visual>
      <origin xyz="0 -0.034 -0.112" rpy="0 1.5708 0" />
      <geometry>
        <cylinder radius="0.0045" length="0.04" />
      </geometry>
      <material name="brushed_steel">
        <color rgba="0.69 0.71 0.74 1" />
      </material>
    </visual>
    <collision name="left_caster_fork__visual_1">
      <origin xyz="0 0 -0.02" rpy="0 0 0" />
      <geometry>
        <cylinder radius="0.008" length="0.04" />
      </geometry>
    </collision>
    <collision name="left_caster_fork__visual_2">
      <origin xyz="0 -0.02 -0.046" rpy="0 0 0" />
      <geometry>
        <box size="0.048 0.018 0.01" />
      </geometry>
    </collision>
    <collision name="left_caster_fork__visual_3">
      <origin xyz="0.02 -0.034 -0.09" rpy="0 0 0" />
      <geometry>
        <box size="0.006 0.016 0.084" />
      </geometry>
    </collision>
    <collision name="left_caster_fork__visual_4">
      <origin xyz="-0.02 -0.034 -0.09" rpy="0 0 0" />
      <geometry>
        <box size="0.006 0.016 0.084" />
      </geometry>
    </collision>
    <collision name="left_caster_fork__visual_5">
      <origin xyz="0 -0.034 -0.112" rpy="0 1.5708 0" />
      <geometry>
        <cylinder radius="0.0045" length="0.04" />
      </geometry>
    </collision>
  </link>
  <link name="left_caster_wheel">
    <inertial>
      <origin xyz="0 0 0" rpy="0 1.5708 0" />
      <mass value="0.28" />
      <inertia ixx="0.000352333" ixy="0" ixz="0" iyy="0.000352333" iyz="0" izz="0.000686" />
    </inertial>
    <visual>
      <origin xyz="0 0 0" rpy="0 1.5708 0" />
      <geometry>
        <mesh filename="meshes/wheelchair_caster_tire.glb" />
      </geometry>
      <material name="rubber_black">
        <color rgba="0.07 0.07 0.08 1" />
      </material>
    </visual>
    <visual>
      <origin xyz="0 0 0" rpy="0 1.5708 0" />
      <geometry>
        <mesh filename="meshes/wheelchair_caster_hub.glb" />
      </geometry>
      <material name="aluminum">
        <color rgba="0.82 0.84 0.87 1" />
      </material>
    </visual>
    <collision name="left_caster_wheel__visual_1__hull_001">
      <origin xyz="0 0 0" rpy="0 1.5708 0" />
      <geometry>
        <mesh filename="meshes/collision/cache/773236f8217c225650b29055__hull_001.obj" />
      </geometry>
    </collision>
    <collision name="left_caster_wheel__visual_1__hull_002">
      <origin xyz="0 0 0" rpy="0 1.5708 0" />
      <geometry>
        <mesh filename="meshes/collision/cache/773236f8217c225650b29055__hull_002.obj" />
      </geometry>
    </collision>
    <collision name="left_caster_wheel__visual_1__hull_003">
      <origin xyz="0 0 0" rpy="0 1.5708 0" />
      <geometry>
        <mesh filename="meshes/collision/cache/773236f8217c225650b29055__hull_003.obj" />
      </geometry>
    </collision>
    <collision name="left_caster_wheel__visual_1__hull_004">
      <origin xyz="0 0 0" rpy="0 1.5708 0" />
      <geometry>
        <mesh filename="meshes/collision/cache/773236f8217c225650b29055__hull_004.obj" />
      </geometry>
    </collision>
    <collision name="left_caster_wheel__visual_1__hull_005">
      <origin xyz="0 0 0" rpy="0 1.5708 0" />
      <geometry>
        <mesh filename="meshes/collision/cache/773236f8217c225650b29055__hull_005.obj" />
      </geometry>
    </collision>
    <collision name="left_caster_wheel__visual_1__hull_006">
      <origin xyz="0 0 0" rpy="0 1.5708 0" />
      <geometry>
        <mesh filename="meshes/collision/cache/773236f8217c225650b29055__hull_006.obj" />
      </geometry>
    </collision>
    <collision name="left_caster_wheel__visual_1__hull_007">
      <origin xyz="0 0 0" rpy="0 1.5708 0" />
      <geometry>
        <mesh filename="meshes/collision/cache/773236f8217c225650b29055__hull_007.obj" />
      </geometry>
    </collision>
    <collision name="left_caster_wheel__visual_1__hull_008">
      <origin xyz="0 0 0" rpy="0 1.5708 0" />
      <geometry>
        <mesh filename="meshes/collision/cache/773236f8217c225650b29055__hull_008.obj" />
      </geometry>
    </collision>
    <collision name="left_caster_wheel__visual_2__hull_001">
      <origin xyz="0 0 0" rpy="0 1.5708 0" />
      <geometry>
        <mesh filename="meshes/collision/cache/67d3fe663d1792aef8849491__hull_001.obj" />
      </geometry>
    </collision>
    <collision name="left_caster_wheel__visual_2__hull_002">
      <origin xyz="0 0 0" rpy="0 1.5708 0" />
      <geometry>
        <mesh filename="meshes/collision/cache/67d3fe663d1792aef8849491__hull_002.obj" />
      </geometry>
    </collision>
  </link>
  <link name="left_footplate">
    <inertial>
      <origin xyz="0 0.08 -0.07" rpy="0 0 0" />
      <mass value="0.25" />
      <inertia ixx="0.000308333" ixy="0" ixz="0" iyy="0.000177083" iyz="0" izz="0.00046875" />
    </inertial>
    <visual>
      <origin xyz="0 0.005 -0.003" rpy="0 0 0" />
      <geometry>
        <box size="0.05 0.01 0.012" />
      </geometry>
      <material name="frame_metal">
        <color rgba="0.7 0.73 0.77 1" />
      </material>
    </visual>
    <visual>
      <origin xyz="0 0.024 -0.045" rpy="0 0 0" />
      <geometry>
        <box size="0.012 0.02 0.078" />
      </geometry>
      <material name="frame_metal">
        <color rgba="0.7 0.73 0.77 1" />
      </material>
    </visual>
    <visual>
      <origin xyz="0 0.082 -0.085" rpy="0 0 0" />
      <geometry>
        <box size="0.09 0.12 0.008" />
      </geometry>
      <material name="black_plastic">
        <color rgba="0.14 0.15 0.16 1" />
      </material>
    </visual>
    <visual>
      <origin xyz="0 0.138 -0.072" rpy="0 0 0" />
      <geometry>
        <box size="0.09 0.008 0.02" />
      </geometry>
      <material name="black_plastic">
        <color rgba="0.14 0.15 0.16 1" />
      </material>
    </visual>
    <visual>
      <origin xyz="0.041 0.082 -0.078" rpy="0 0 0" />
      <geometry>
        <box size="0.008 0.12 0.012" />
      </geometry>
      <material name="black_plastic">
        <color rgba="0.14 0.15 0.16 1" />
      </material>
    </visual>
    <visual>
      <origin xyz="-0.041 0.082 -0.078" rpy="0 0 0" />
      <geometry>
        <box size="0.008 0.12 0.012" />
      </geometry>
      <material name="black_plastic">
        <color rgba="0.14 0.15 0.16 1" />
      </material>
    </visual>
    <collision name="left_footplate__visual_1">
      <origin xyz="0 0.005 -0.003" rpy="0 0 0" />
      <geometry>
        <box size="0.05 0.01 0.012" />
      </geometry>
    </collision>
    <collision name="left_footplate__visual_2">
      <origin xyz="0 0.024 -0.045" rpy="0 0 0" />
      <geometry>
        <box size="0.012 0.02 0.078" />
      </geometry>
    </collision>
    <collision name="left_footplate__visual_3">
      <origin xyz="0 0.082 -0.085" rpy="0 0 0" />
      <geometry>
        <box size="0.09 0.12 0.008" />
      </geometry>
    </collision>
    <collision name="left_footplate__visual_4">
      <origin xyz="0 0.138 -0.072" rpy="0 0 0" />
      <geometry>
        <box size="0.09 0.008 0.02" />
      </geometry>
    </collision>
    <collision name="left_footplate__visual_5">
      <origin xyz="0.041 0.082 -0.078" rpy="0 0 0" />
      <geometry>
        <box size="0.008 0.12 0.012" />
      </geometry>
    </collision>
    <collision name="left_footplate__visual_6">
      <origin xyz="-0.041 0.082 -0.078" rpy="0 0 0" />
      <geometry>
        <box size="0.008 0.12 0.012" />
      </geometry>
    </collision>
  </link>
  <link name="right_caster_fork">
    <inertial>
      <origin xyz="0 -0.024 -0.072" rpy="0 0 0" />
      <mass value="0.35" />
      <inertia ixx="0.000492917" ixy="0" ixz="0" iyy="0.000525" iyz="0" izz="0.000177917" />
    </inertial>
    <visual>
      <origin xyz="0 0 -0.02" rpy="0 0 0" />
      <geometry>
        <cylinder radius="0.008" length="0.04" />
      </geometry>
      <material name="frame_metal">
        <color rgba="0.7 0.73 0.77 1" />
      </material>
    </visual>
    <visual>
      <origin xyz="0 -0.02 -0.046" rpy="0 0 0" />
      <geometry>
        <box size="0.048 0.018 0.01" />
      </geometry>
      <material name="frame_metal">
        <color rgba="0.7 0.73 0.77 1" />
      </material>
    </visual>
    <visual>
      <origin xyz="0.02 -0.034 -0.09" rpy="0 0 0" />
      <geometry>
        <box size="0.006 0.016 0.084" />
      </geometry>
      <material name="frame_metal">
        <color rgba="0.7 0.73 0.77 1" />
      </material>
    </visual>
    <visual>
      <origin xyz="-0.02 -0.034 -0.09" rpy="0 0 0" />
      <geometry>
        <box size="0.006 0.016 0.084" />
      </geometry>
      <material name="frame_metal">
        <color rgba="0.7 0.73 0.77 1" />
      </material>
    </visual>
    <visual>
      <origin xyz="0 -0.034 -0.112" rpy="0 1.5708 0" />
      <geometry>
        <cylinder radius="0.0045" length="0.04" />
      </geometry>
      <material name="brushed_steel">
        <color rgba="0.69 0.71 0.74 1" />
      </material>
    </visual>
    <collision name="right_caster_fork__visual_1">
      <origin xyz="0 0 -0.02" rpy="0 0 0" />
      <geometry>
        <cylinder radius="0.008" length="0.04" />
      </geometry>
    </collision>
    <collision name="right_caster_fork__visual_2">
      <origin xyz="0 -0.02 -0.046" rpy="0 0 0" />
      <geometry>
        <box size="0.048 0.018 0.01" />
      </geometry>
    </collision>
    <collision name="right_caster_fork__visual_3">
      <origin xyz="0.02 -0.034 -0.09" rpy="0 0 0" />
      <geometry>
        <box size="0.006 0.016 0.084" />
      </geometry>
    </collision>
    <collision name="right_caster_fork__visual_4">
      <origin xyz="-0.02 -0.034 -0.09" rpy="0 0 0" />
      <geometry>
        <box size="0.006 0.016 0.084" />
      </geometry>
    </collision>
    <collision name="right_caster_fork__visual_5">
      <origin xyz="0 -0.034 -0.112" rpy="0 1.5708 0" />
      <geometry>
        <cylinder radius="0.0045" length="0.04" />
      </geometry>
    </collision>
  </link>
  <link name="right_caster_wheel">
    <inertial>
      <origin xyz="0 0 0" rpy="0 1.5708 0" />
      <mass value="0.28" />
      <inertia ixx="0.000352333" ixy="0" ixz="0" iyy="0.000352333" iyz="0" izz="0.000686" />
    </inertial>
    <visual>
      <origin xyz="0 0 0" rpy="0 1.5708 0" />
      <geometry>
        <mesh filename="meshes/wheelchair_caster_tire.glb" />
      </geometry>
      <material name="rubber_black">
        <color rgba="0.07 0.07 0.08 1" />
      </material>
    </visual>
    <visual>
      <origin xyz="0 0 0" rpy="0 1.5708 0" />
      <geometry>
        <mesh filename="meshes/wheelchair_caster_hub.glb" />
      </geometry>
      <material name="aluminum">
        <color rgba="0.82 0.84 0.87 1" />
      </material>
    </visual>
    <collision name="right_caster_wheel__visual_1__hull_001">
      <origin xyz="0 0 0" rpy="0 1.5708 0" />
      <geometry>
        <mesh filename="meshes/collision/cache/773236f8217c225650b29055__hull_001.obj" />
      </geometry>
    </collision>
    <collision name="right_caster_wheel__visual_1__hull_002">
      <origin xyz="0 0 0" rpy="0 1.5708 0" />
      <geometry>
        <mesh filename="meshes/collision/cache/773236f8217c225650b29055__hull_002.obj" />
      </geometry>
    </collision>
    <collision name="right_caster_wheel__visual_1__hull_003">
      <origin xyz="0 0 0" rpy="0 1.5708 0" />
      <geometry>
        <mesh filename="meshes/collision/cache/773236f8217c225650b29055__hull_003.obj" />
      </geometry>
    </collision>
    <collision name="right_caster_wheel__visual_1__hull_004">
      <origin xyz="0 0 0" rpy="0 1.5708 0" />
      <geometry>
        <mesh filename="meshes/collision/cache/773236f8217c225650b29055__hull_004.obj" />
      </geometry>
    </collision>
    <collision name="right_caster_wheel__visual_1__hull_005">
      <origin xyz="0 0 0" rpy="0 1.5708 0" />
      <geometry>
        <mesh filename="meshes/collision/cache/773236f8217c225650b29055__hull_005.obj" />
      </geometry>
    </collision>
    <collision name="right_caster_wheel__visual_1__hull_006">
      <origin xyz="0 0 0" rpy="0 1.5708 0" />
      <geometry>
        <mesh filename="meshes/collision/cache/773236f8217c225650b29055__hull_006.obj" />
      </geometry>
    </collision>
    <collision name="right_caster_wheel__visual_1__hull_007">
      <origin xyz="0 0 0" rpy="0 1.5708 0" />
      <geometry>
        <mesh filename="meshes/collision/cache/773236f8217c225650b29055__hull_007.obj" />
      </geometry>
    </collision>
    <collision name="right_caster_wheel__visual_1__hull_008">
      <origin xyz="0 0 0" rpy="0 1.5708 0" />
      <geometry>
        <mesh filename="meshes/collision/cache/773236f8217c225650b29055__hull_008.obj" />
      </geometry>
    </collision>
    <collision name="right_caster_wheel__visual_2__hull_001">
      <origin xyz="0 0 0" rpy="0 1.5708 0" />
      <geometry>
        <mesh filename="meshes/collision/cache/67d3fe663d1792aef8849491__hull_001.obj" />
      </geometry>
    </collision>
    <collision name="right_caster_wheel__visual_2__hull_002">
      <origin xyz="0 0 0" rpy="0 1.5708 0" />
      <geometry>
        <mesh filename="meshes/collision/cache/67d3fe663d1792aef8849491__hull_002.obj" />
      </geometry>
    </collision>
  </link>
  <link name="right_footplate">
    <inertial>
      <origin xyz="0 0.08 -0.07" rpy="0 0 0" />
      <mass value="0.25" />
      <inertia ixx="0.000308333" ixy="0" ixz="0" iyy="0.000177083" iyz="0" izz="0.00046875" />
    </inertial>
    <visual>
      <origin xyz="0 0.005 -0.003" rpy="0 0 0" />
      <geometry>
        <box size="0.05 0.01 0.012" />
      </geometry>
      <material name="frame_metal">
        <color rgba="0.7 0.73 0.77 1" />
      </material>
    </visual>
    <visual>
      <origin xyz="0 0.024 -0.045" rpy="0 0 0" />
      <geometry>
        <box size="0.012 0.02 0.078" />
      </geometry>
      <material name="frame_metal">
        <color rgba="0.7 0.73 0.77 1" />
      </material>
    </visual>
    <visual>
      <origin xyz="0 0.082 -0.085" rpy="0 0 0" />
      <geometry>
        <box size="0.09 0.12 0.008" />
      </geometry>
      <material name="black_plastic">
        <color rgba="0.14 0.15 0.16 1" />
      </material>
    </visual>
    <visual>
      <origin xyz="0 0.138 -0.072" rpy="0 0 0" />
      <geometry>
        <box size="0.09 0.008 0.02" />
      </geometry>
      <material name="black_plastic">
        <color rgba="0.14 0.15 0.16 1" />
      </material>
    </visual>
    <visual>
      <origin xyz="0.041 0.082 -0.078" rpy="0 0 0" />
      <geometry>
        <box size="0.008 0.12 0.012" />
      </geometry>
      <material name="black_plastic">
        <color rgba="0.14 0.15 0.16 1" />
      </material>
    </visual>
    <visual>
      <origin xyz="-0.041 0.082 -0.078" rpy="0 0 0" />
      <geometry>
        <box size="0.008 0.12 0.012" />
      </geometry>
      <material name="black_plastic">
        <color rgba="0.14 0.15 0.16 1" />
      </material>
    </visual>
    <collision name="right_footplate__visual_1">
      <origin xyz="0 0.005 -0.003" rpy="0 0 0" />
      <geometry>
        <box size="0.05 0.01 0.012" />
      </geometry>
    </collision>
    <collision name="right_footplate__visual_2">
      <origin xyz="0 0.024 -0.045" rpy="0 0 0" />
      <geometry>
        <box size="0.012 0.02 0.078" />
      </geometry>
    </collision>
    <collision name="right_footplate__visual_3">
      <origin xyz="0 0.082 -0.085" rpy="0 0 0" />
      <geometry>
        <box size="0.09 0.12 0.008" />
      </geometry>
    </collision>
    <collision name="right_footplate__visual_4">
      <origin xyz="0 0.138 -0.072" rpy="0 0 0" />
      <geometry>
        <box size="0.09 0.008 0.02" />
      </geometry>
    </collision>
    <collision name="right_footplate__visual_5">
      <origin xyz="0.041 0.082 -0.078" rpy="0 0 0" />
      <geometry>
        <box size="0.008 0.12 0.012" />
      </geometry>
    </collision>
    <collision name="right_footplate__visual_6">
      <origin xyz="-0.041 0.082 -0.078" rpy="0 0 0" />
      <geometry>
        <box size="0.008 0.12 0.012" />
      </geometry>
    </collision>
  </link>
  <joint name="left_rear_wheel_spin" type="continuous">
    <origin xyz="0.33 -0.06 0.31" rpy="0 0 0" />
    <parent link="frame" />
    <child link="left_rear_wheel" />
    <axis xyz="1 0 0" />
    <limit effort="12" velocity="30" />
  </joint>
  <joint name="right_rear_wheel_spin" type="continuous">
    <origin xyz="-0.33 -0.06 0.31" rpy="0 0 0" />
    <parent link="frame" />
    <child link="right_rear_wheel" />
    <axis xyz="1 0 0" />
    <limit effort="12" velocity="30" />
  </joint>
  <joint name="left_caster_swivel" type="continuous">
    <origin xyz="0.18 0.34 0.17" rpy="0 0 0" />
    <parent link="frame" />
    <child link="left_caster_fork" />
    <axis xyz="0 0 1" />
    <limit effort="4" velocity="8" />
  </joint>
  <joint name="right_caster_swivel" type="continuous">
    <origin xyz="-0.18 0.34 0.17" rpy="0 0 0" />
    <parent link="frame" />
    <child link="right_caster_fork" />
    <axis xyz="0 0 1" />
    <limit effort="4" velocity="8" />
  </joint>
  <joint name="left_caster_roll" type="continuous">
    <origin xyz="0 -0.034 -0.112" rpy="0 0 0" />
    <parent link="left_caster_fork" />
    <child link="left_caster_wheel" />
    <axis xyz="1 0 0" />
    <limit effort="3" velocity="22" />
  </joint>
  <joint name="right_caster_roll" type="continuous">
    <origin xyz="0 -0.034 -0.112" rpy="0 0 0" />
    <parent link="right_caster_fork" />
    <child link="right_caster_wheel" />
    <axis xyz="1 0 0" />
    <limit effort="3" velocity="22" />
  </joint>
  <joint name="left_footplate_hinge" type="revolute">
    <origin xyz="0.1 0.37 0.145" rpy="0 0 0" />
    <parent link="frame" />
    <child link="left_footplate" />
    <axis xyz="1 0 0" />
    <limit effort="6" velocity="3" lower="0" upper="1.35" />
  </joint>
  <joint name="right_footplate_hinge" type="revolute">
    <origin xyz="-0.1 0.37 0.145" rpy="0 0 0" />
    <parent link="frame" />
    <child link="right_footplate" />
    <axis xyz="1 0 0" />
    <limit effort="6" velocity="3" lower="0" upper="1.35" />
  </joint>
</robot>