<robot name="kick_scooter">
  <link name="frame">
    <inertial>
      <origin xyz="-0.02 0 0.09" rpy="0 0 0" />
      <mass value="3.8" />
      <inertia ixx="0.00991167" ixy="0" ixz="0" iyy="0.127078" iyz="0" izz="0.126287" />
      </inertial>
    <visual>
      <origin xyz="-0.035 0 0.066" rpy="0 0 0" />
      <geometry>
        <box size="0.41 0.112 0.022" />
        </geometry>
      </visual>
    <visual>
      <origin xyz="0.17 0 0.069" rpy="0 0 0" />
      <geometry>
        <box size="0.08 0.048 0.018" />
        </geometry>
      </visual>
    <visual>
      <origin xyz="0.21 0 0.108" rpy="0 -0.68 0" />
      <geometry>
        <box size="0.105 0.036 0.046" />
        </geometry>
      </visual>
    <visual>
      <origin xyz="0.275 0 0.155" rpy="0 0 0" />
      <geometry>
        <cylinder radius="0.024" length="0.094" />
        </geometry>
      </visual>
    <visual>
      <origin xyz="-0.03 0.049 0.076" rpy="0 0 0" />
      <geometry>
        <box size="0.32 0.01 0.014" />
        </geometry>
      </visual>
    <visual>
      <origin xyz="-0.03 -0.049 0.076" rpy="0 0 0" />
      <geometry>
        <box size="0.32 0.01 0.014" />
        </geometry>
      </visual>
    <visual>
      <origin xyz="-0.255 0.032 0.098" rpy="0 0.24 0" />
      <geometry>
        <box size="0.16 0.012 0.1" />
        </geometry>
      </visual>
    <visual>
      <origin xyz="-0.255 -0.032 0.098" rpy="0 0.24 0" />
      <geometry>
        <box size="0.16 0.012 0.1" />
        </geometry>
      </visual>
    <visual>
      <origin xyz="-0.382 0 0.145" rpy="0 0 0" />
      <geometry>
        <box size="0.085 0.085 0.012" />
        </geometry>
      </visual>
    <visual>
      <origin xyz="-0.315 0 0.085" rpy="1.5708 0 0" />
      <geometry>
        <cylinder radius="0.007" length="0.076" />
        </geometry>
      </visual>
    </link>
  <link name="front_assembly">
    <inertial>
      <origin xyz="0.01 0 0.345" rpy="0 0 0" />
      <mass value="1.6" />
      <inertia ixx="0.105227" ixy="0" ixz="0" iyy="0.110347" iyz="0" izz="0.0615467" />
      </inertial>
    <visual>
      <origin xyz="0 0 0.025" rpy="0 0 0" />
      <geometry>
        <cylinder radius="0.018" length="0.05" />
        </geometry>
      </visual>
    <visual>
      <origin xyz="0 0 0.35" rpy="0 0 0" />
      <geometry>
        <cylinder radius="0.017" length="0.6" />
        </geometry>
      </visual>
    <visual>
      <origin xyz="0 0 0.63" rpy="0 0 0" />
      <geometry>
        <cylinder radius="0.022" length="0.06" />
        </geometry>
      </visual>
    <visual>
      <origin xyz="0 0 0.63" rpy="0 0 0" />
      <geometry>
        <box size="0.052 0.03 0.036" />
        </geometry>
      </visual>
    <visual>
      <origin xyz="0 0 0.665" rpy="1.5708 0 0" />
      <geometry>
        <cylinder radius="0.013" length="0.46" />
        </geometry>
      </visual>
    <visual>
      <origin xyz="0 0.176 0.665" rpy="1.5708 0 0" />
      <geometry>
        <cylinder radius="0.017" length="0.11" />
        </geometry>
      </visual>
    <visual>
      <origin xyz="0 -0.176 0.665" rpy="1.5708 0 0" />
      <geometry>
        <cylinder radius="0.017" length="0.11" />
        </geometry>
      </visual>
    <visual>
      <origin xyz="0.05 0 0.034" rpy="0 0 0" />
      <geometry>
        <box size="0.055 0.06 0.016" />
        </geometry>
      </visual>
    <visual>
      <geometry>
        <mesh filename="assets/meshes/front_fork_left.obj" />
        </geometry>
      </visual>
    <visual>
      <geometry>
        <mesh filename="assets/meshes/front_fork_right.obj" />
        </geometry>
      </visual>
    <visual>
      <origin xyz="0.155 0 -0.025" rpy="1.5708 0 0" />
      <geometry>
        <cylinder radius="0.007" length="0.07" />
        </geometry>
      </visual>
    </link>
  <link name="front_wheel">
    <inertial>
      <origin xyz="0 0 0" rpy="1.5708 0 0" />
      <mass value="0.7" />
      <inertia ixx="0.00129798" ixy="0" ixz="0" iyy="0.00129798" iyz="0" izz="0.00252875" />
      </inertial>
    <visual>
      <origin xyz="0 0 0" rpy="1.5708 0 0" />
      <geometry>
        <cylinder radius="0.085" length="0.024" />
        </geometry>
      </visual>
    <visual>
      <origin xyz="0 0 0" rpy="1.5708 0 0" />
      <geometry>
        <cylinder radius="0.072" length="0.018" />
        </geometry>
      </visual>
    <visual>
      <origin xyz="0 0 0" rpy="1.5708 0 0" />
      <geometry>
        <cylinder radius="0.018" length="0.034" />
        </geometry>
      </visual>
    <visual>
      <geometry>
        <box size="0.006 0.008 0.146" />
        </geometry>
      </visual>
    <visual>
      <origin xyz="0 0 0" rpy="0 0.523599 0" />
      <geometry>
        <box size="0.006 0.008 0.128" />
        </geometry>
      </visual>
    <visual>
      <origin xyz="0 0 0" rpy="0 1.0472 0" />
      <geometry>
        <box size="0.006 0.008 0.146" />
        </geometry>
      </visual>
    <visual>
      <origin xyz="0 0 0" rpy="0 1.5708 0" />
      <geometry>
        <box size="0.006 0.008 0.128" />
        </geometry>
      </visual>
    <visual>
      <origin xyz="0 0 0" rpy="0 2.0944 0" />
      <geometry>
        <box size="0.006 0.008 0.146" />
        </geometry>
      </visual>
    <visual>
      <origin xyz="0 0 0" rpy="0 2.61799 0" />
      <geometry>
        <box size="0.006 0.008 0.128" />
        </geometry>
      </visual>
    </link>
  <link name="rear_wheel">
    <inertial>
      <origin xyz="0 0 0" rpy="1.5708 0 0" />
      <mass value="0.7" />
      <inertia ixx="0.00129798" ixy="0" ixz="0" iyy="0.00129798" iyz="0" izz="0.00252875" />
      </inertial>
    <visual>
      <origin xyz="0 0 0" rpy="1.5708 0 0" />
      <geometry>
        <cylinder radius="0.085" length="0.024" />
        </geometry>
      </visual>
    <visual>
      <origin xyz="0 0 0" rpy="1.5708 0 0" />
      <geometry>
        <cylinder radius="0.072" length="0.018" />
        </geometry>
      </visual>
    <visual>
      <origin xyz="0 0 0" rpy="1.5708 0 0" />
      <geometry>
        <cylinder radius="0.018" length="0.034" />
        </geometry>
      </visual>
    <visual>
      <geometry>
        <box size="0.006 0.008 0.146" />
        </geometry>
      </visual>
    <visual>
      <origin xyz="0 0 0" rpy="0 0.523599 0" />
      <geometry>
        <box size="0.006 0.008 0.128" />
        </geometry>
      </visual>
    <visual>
      <origin xyz="0 0 0" rpy="0 1.0472 0" />
      <geometry>
        <box size="0.006 0.008 0.146" />
        </geometry>
      </visual>
    <visual>
      <origin xyz="0 0 0" rpy="0 1.5708 0" />
      <geometry>
        <box size="0.006 0.008 0.128" />
        </geometry>
      </visual>
    <visual>
      <origin xyz="0 0 0" rpy="0 2.0944 0" />
      <geometry>
        <box size="0.006 0.008 0.146" />
        </geometry>
      </visual>
    <visual>
      <origin xyz="0 0 0" rpy="0 2.61799 0" />
      <geometry>
        <box size="0.006 0.008 0.128" />
        </geometry>
      </visual>
    </link>
  <joint name="steering_head" type="revolute">
    <origin xyz="0.275 0 0.11" rpy="0 0 0" />
    <parent link="frame" />
    <child link="front_assembly" />
    <axis xyz="0 0 1" />
    <limit effort="12" velocity="4" lower="-0.85" upper="0.85" />
    </joint>
  <joint name="front_wheel_roll" type="continuous">
    <origin xyz="0.155 0 -0.025" rpy="0 0 0" />
    <parent link="front_assembly" />
    <child link="front_wheel" />
    <axis xyz="0 1 0" />
    <limit effort="8" velocity="40" />
    </joint>
  <joint name="rear_wheel_roll" type="continuous">
    <origin xyz="-0.315 0 0.085" rpy="0 0 0" />
    <parent link="frame" />
    <child link="rear_wheel" />
    <axis xyz="0 1 0" />
    <limit effort="8" velocity="40" />
    </joint>
  </robot>
