<robot name="front_load_dryer">
  <material name="white_enamel">
    <color rgba="0.95 0.95 0.96 1" />
  </material>
  <material name="graphite_plastic">
    <color rgba="0.15 0.16 0.18 1" />
  </material>
  <material name="dark_glass">
    <color rgba="0.1 0.12 0.14 0.45" />
  </material>
  <material name="display_black">
    <color rgba="0.05 0.06 0.07 0.88" />
  </material>
  <material name="brushed_steel">
    <color rgba="0.75 0.77 0.8 1" />
  </material>
  <material name="rubber">
    <color rgba="0.19 0.2 0.21 1" />
  </material>
  <material name="chrome">
    <color rgba="0.84 0.85 0.87 1" />
  </material>
  <link name="cabinet">
    <inertial>
      <origin xyz="0 0 0.44" rpy="0 0 0" />
      <mass value="46" />
      <inertia ixx="4.95573" ixy="0" ixz="0" iyy="4.68932" iyz="0" izz="3.70798" />
    </inertial>
    <visual>
      <origin xyz="-0.325 0 0.455" rpy="0 0 0" />
      <geometry>
        <box size="0.02 0.72 0.85" />
      </geometry>
      <material name="white_enamel">
        <color rgba="0.95 0.95 0.96 1" />
      </material>
    </visual>
    <visual>
      <origin xyz="0.325 0 0.455" rpy="0 0 0" />
      <geometry>
        <box size="0.02 0.72 0.85" />
      </geometry>
      <material name="white_enamel">
        <color rgba="0.95 0.95 0.96 1" />
      </material>
    </visual>
    <visual>
      <origin xyz="0 0 0.04" rpy="0 0 0" />
      <geometry>
        <box size="0.63 0.72 0.02" />
      </geometry>
      <material name="white_enamel">
        <color rgba="0.95 0.95 0.96 1" />
      </material>
    </visual>
    <visual>
      <origin xyz="0 0 0.87" rpy="0 0 0" />
      <geometry>
        <box size="0.63 0.72 0.02" />
      </geometry>
      <material name="white_enamel">
        <color rgba="0.95 0.95 0.96 1" />
      </material>
    </visual>
    <visual>
      <origin xyz="0 0.35 0.445" rpy="0 0 0" />
      <geometry>
        <box size="0.63 0.02 0.81" />
      </geometry>
      <material name="white_enamel">
        <color rgba="0.95 0.95 0.96 1" />
      </material>
    </visual>
    <visual>
      <origin xyz="-0.28 -0.34 0.38" rpy="0 0 0" />
      <geometry>
        <box size="0.11 0.04 0.7" />
      </geometry>
      <material name="white_enamel">
        <color rgba="0.95 0.95 0.96 1" />
      </material>
    </visual>
    <visual>
      <origin xyz="0.28 -0.34 0.38" rpy="0 0 0" />
      <geometry>
        <box size="0.11 0.04 0.7" />
      </geometry>
      <material name="white_enamel">
        <color rgba="0.95 0.95 0.96 1" />
      </material>
    </visual>
    <visual>
      <origin xyz="0 -0.34 0.085" rpy="0 0 0" />
      <geometry>
        <box size="0.45 0.04 0.11" />
      </geometry>
      <material name="white_enamel">
        <color rgba="0.95 0.95 0.96 1" />
      </material>
    </visual>
    <visual>
      <origin xyz="0 -0.34 0.67" rpy="0 0 0" />
      <geometry>
        <box size="0.45 0.04 0.12" />
      </geometry>
      <material name="white_enamel">
        <color rgba="0.95 0.95 0.96 1" />
      </material>
    </visual>
    <visual>
      <origin xyz="0 -0.34 0.085" rpy="0 0 0" />
      <geometry>
        <box size="0.63 0.04 0.11" />
      </geometry>
      <material name="graphite_plastic">
        <color rgba="0.15 0.16 0.18 1" />
      </material>
    </visual>
    <visual>
      <origin xyz="0 -0.24 0.79" rpy="0 0 0" />
      <geometry>
        <box size="0.63 0.2 0.15" />
      </geometry>
      <material name="white_enamel">
        <color rgba="0.95 0.95 0.96 1" />
      </material>
    </visual>
    <visual>
      <origin xyz="0 -0.35 0.79" rpy="0 0 0" />
      <geometry>
        <box size="0.63 0.02 0.1" />
      </geometry>
      <material name="white_enamel">
        <color rgba="0.95 0.95 0.96 1" />
      </material>
    </visual>
    <visual>
      <origin xyz="-0.17 -0.356 0.79" rpy="0 0 0" />
      <geometry>
        <box size="0.21 0.008 0.09" />
      </geometry>
      <material name="graphite_plastic">
        <color rgba="0.15 0.16 0.18 1" />
      </material>
    </visual>
    <visual>
      <origin xyz="0.15 -0.356 0.824" rpy="0 0 0" />
      <geometry>
        <box size="0.25 0.008 0.068" />
      </geometry>
      <material name="display_black">
        <color rgba="0.05 0.06 0.07 0.88" />
      </material>
    </visual>
    <visual>
      <origin xyz="0.16 -0.356 0.77" rpy="0 0 0" />
      <geometry>
        <box size="0.24 0.008 0.04" />
      </geometry>
      <material name="graphite_plastic">
        <color rgba="0.15 0.16 0.18 1" />
      </material>
    </visual>
    <visual>
      <origin xyz="0 -0.329 0.4" rpy="0 0 0" />
      <geometry>
        <mesh filename="meshes/cabinet_bezel.glb" />
      </geometry>
      <material name="white_enamel">
        <color rgba="0.95 0.95 0.96 1" />
      </material>
    </visual>
    <visual>
      <origin xyz="0 -0.349 0.4" rpy="0 0 0" />
      <geometry>
        <mesh filename="meshes/door_gasket.glb" />
      </geometry>
      <material name="rubber">
        <color rgba="0.19 0.2 0.21 1" />
      </material>
    </visual>
    <visual>
      <origin xyz="0 0.08 0.4" rpy="1.5708 0 0" />
      <geometry>
        <cylinder radius="0.245" length="0.44" />
      </geometry>
      <material name="brushed_steel">
        <color rgba="0.75 0.77 0.8 1" />
      </material>
    </visual>
    <visual>
      <origin xyz="0 -0.18 0.4" rpy="0 0 0" />
      <geometry>
        <mesh filename="meshes/drum_lip.glb" />
      </geometry>
      <material name="brushed_steel">
        <color rgba="0.75 0.77 0.8 1" />
      </material>
    </visual>
    <visual>
      <origin xyz="0 0.32 0.4" rpy="1.5708 0 0" />
      <geometry>
        <cylinder radius="0.23" length="0.04" />
      </geometry>
      <material name="brushed_steel">
        <color rgba="0.75 0.77 0.8 1" />
      </material>
    </visual>
    <visual>
      <origin xyz="0 0.35 0.4" rpy="1.5708 0 0" />
      <geometry>
        <cylinder radius="0.04" length="0.08" />
      </geometry>
      <material name="graphite_plastic">
        <color rgba="0.15 0.16 0.18 1" />
      </material>
    </visual>
    <visual>
      <origin xyz="-0.24 -0.27 0.015" rpy="0 0 0" />
      <geometry>
        <cylinder radius="0.025" length="0.03" />
      </geometry>
      <material name="rubber">
        <color rgba="0.19 0.2 0.21 1" />
      </material>
    </visual>
    <visual>
      <origin xyz="0.24 -0.27 0.015" rpy="0 0 0" />
      <geometry>
        <cylinder radius="0.025" length="0.03" />
      </geometry>
      <material name="rubber">
        <color rgba="0.19 0.2 0.21 1" />
      </material>
    </visual>
    <visual>
      <origin xyz="-0.24 0.27 0.015" rpy="0 0 0" />
      <geometry>
        <cylinder radius="0.025" length="0.03" />
      </geometry>
      <material name="rubber">
        <color rgba="0.19 0.2 0.21 1" />
      </material>
    </visual>
    <visual>
      <origin xyz="0.24 0.27 0.015" rpy="0 0 0" />
      <geometry>
        <cylinder radius="0.025" length="0.03" />
      </geometry>
      <material name="rubber">
        <color rgba="0.19 0.2 0.21 1" />
      </material>
    </visual>
    <collision name="cabinet__visual_1">
      <origin xyz="-0.325 0 0.455" rpy="0 0 0" />
      <geometry>
        <box size="0.02 0.72 0.85" />
      </geometry>
    </collision>
    <collision name="cabinet__visual_2">
      <origin xyz="0.325 0 0.455" rpy="0 0 0" />
      <geometry>
        <box size="0.02 0.72 0.85" />
      </geometry>
    </collision>
    <collision name="cabinet__visual_3">
      <origin xyz="0 0 0.04" rpy="0 0 0" />
      <geometry>
        <box size="0.63 0.72 0.02" />
      </geometry>
    </collision>
    <collision name="cabinet__visual_4">
      <origin xyz="0 0 0.87" rpy="0 0 0" />
      <geometry>
        <box size="0.63 0.72 0.02" />
      </geometry>
    </collision>
    <collision name="cabinet__visual_5">
      <origin xyz="0 0.35 0.445" rpy="0 0 0" />
      <geometry>
        <box size="0.63 0.02 0.81" />
      </geometry>
    </collision>
    <collision name="cabinet__visual_6">
      <origin xyz="-0.28 -0.34 0.38" rpy="0 0 0" />
      <geometry>
        <box size="0.11 0.04 0.7" />
      </geometry>
    </collision>
    <collision name="cabinet__visual_7">
      <origin xyz="0.28 -0.34 0.38" rpy="0 0 0" />
      <geometry>
        <box size="0.11 0.04 0.7" />
      </geometry>
    </collision>
    <collision name="cabinet__visual_8">
      <origin xyz="0 -0.34 0.085" rpy="0 0 0" />
      <geometry>
        <box size="0.45 0.04 0.11" />
      </geometry>
    </collision>
    <collision name="cabinet__visual_9">
      <origin xyz="0 -0.34 0.67" rpy="0 0 0" />
      <geometry>
        <box size="0.45 0.04 0.12" />
      </geometry>
    </collision>
    <collision name="cabinet__visual_10">
      <origin xyz="0 -0.34 0.085" rpy="0 0 0" />
      <geometry>
        <box size="0.63 0.04 0.11" />
      </geometry>
    </collision>
    <collision name="cabinet__visual_11">
      <origin xyz="0 -0.24 0.79" rpy="0 0 0" />
      <geometry>
        <box size="0.63 0.2 0.15" />
      </geometry>
    </collision>
    <collision name="cabinet__visual_12">
      <origin xyz="0 -0.35 0.79" rpy="0 0 0" />
      <geometry>
        <box size="0.63 0.02 0.1" />
      </geometry>
    </collision>
    <collision name="cabinet__visual_13">
      <origin xyz="-0.17 -0.356 0.79" rpy="0 0 0" />
      <geometry>
        <box size="0.21 0.008 0.09" />
      </geometry>
    </collision>
    <collision name="cabinet__visual_14">
      <origin xyz="0.15 -0.356 0.824" rpy="0 0 0" />
      <geometry>
        <box size="0.25 0.008 0.068" />
      </geometry>
    </collision>
    <collision name="cabinet__visual_15">
      <origin xyz="0.16 -0.356 0.77" rpy="0 0 0" />
      <geometry>
        <box size="0.24 0.008 0.04" />
      </geometry>
    </collision>
    <collision name="cabinet__visual_16__hull_001">
      <origin xyz="0 -0.329 0.4" rpy="0 0 0" />
      <geometry>
        <mesh filename="meshes/collision/cache/7fc3fc2ec7fb8a11b90c95b3__hull_001.obj" />
      </geometry>
    </collision>
    <collision name="cabinet__visual_16__hull_002">
      <origin xyz="0 -0.329 0.4" rpy="0 0 0" />
      <geometry>
        <mesh filename="meshes/collision/cache/7fc3fc2ec7fb8a11b90c95b3__hull_002.obj" />
      </geometry>
    </collision>
    <collision name="cabinet__visual_16__hull_003">
      <origin xyz="0 -0.329 0.4" rpy="0 0 0" />
      <geometry>
        <mesh filename="meshes/collision/cache/7fc3fc2ec7fb8a11b90c95b3__hull_003.obj" />
      </geometry>
    </collision>
    <collision name="cabinet__visual_16__hull_004">
      <origin xyz="0 -0.329 0.4" rpy="0 0 0" />
      <geometry>
        <mesh filename="meshes/collision/cache/7fc3fc2ec7fb8a11b90c95b3__hull_004.obj" />
      </geometry>
    </collision>
    <collision name="cabinet__visual_16__hull_005">
      <origin xyz="0 -0.329 0.4" rpy="0 0 0" />
      <geometry>
        <mesh filename="meshes/collision/cache/7fc3fc2ec7fb8a11b90c95b3__hull_005.obj" />
      </geometry>
    </collision>
    <collision name="cabinet__visual_16__hull_006">
      <origin xyz="0 -0.329 0.4" rpy="0 0 0" />
      <geometry>
        <mesh filename="meshes/collision/cache/7fc3fc2ec7fb8a11b90c95b3__hull_006.obj" />
      </geometry>
    </collision>
    <collision name="cabinet__visual_16__hull_007">
      <origin xyz="0 -0.329 0.4" rpy="0 0 0" />
      <geometry>
        <mesh filename="meshes/collision/cache/7fc3fc2ec7fb8a11b90c95b3__hull_007.obj" />
      </geometry>
    </collision>
    <collision name="cabinet__visual_16__hull_008">
      <origin xyz="0 -0.329 0.4" rpy="0 0 0" />
      <geometry>
        <mesh filename="meshes/collision/cache/7fc3fc2ec7fb8a11b90c95b3__hull_008.obj" />
      </geometry>
    </collision>
    <collision name="cabinet__visual_16__hull_009">
      <origin xyz="0 -0.329 0.4" rpy="0 0 0" />
      <geometry>
        <mesh filename="meshes/collision/cache/7fc3fc2ec7fb8a11b90c95b3__hull_009.obj" />
      </geometry>
    </collision>
    <collision name="cabinet__visual_16__hull_010">
      <origin xyz="0 -0.329 0.4" rpy="0 0 0" />
      <geometry>
        <mesh filename="meshes/collision/cache/7fc3fc2ec7fb8a11b90c95b3__hull_010.obj" />
      </geometry>
    </collision>
    <collision name="cabinet__visual_17__hull_001">
      <origin xyz="0 -0.349 0.4" rpy="0 0 0" />
      <geometry>
        <mesh filename="meshes/collision/cache/11598ca94e4fbb0785334a2d__hull_001.obj" />
      </geometry>
    </collision>
    <collision name="cabinet__visual_17__hull_002">
      <origin xyz="0 -0.349 0.4" rpy="0 0 0" />
      <geometry>
        <mesh filename="meshes/collision/cache/11598ca94e4fbb0785334a2d__hull_002.obj" />
      </geometry>
    </collision>
    <collision name="cabinet__visual_17__hull_003">
      <origin xyz="0 -0.349 0.4" rpy="0 0 0" />
      <geometry>
        <mesh filename="meshes/collision/cache/11598ca94e4fbb0785334a2d__hull_003.obj" />
      </geometry>
    </collision>
    <collision name="cabinet__visual_17__hull_004">
      <origin xyz="0 -0.349 0.4" rpy="0 0 0" />
      <geometry>
        <mesh filename="meshes/collision/cache/11598ca94e4fbb0785334a2d__hull_004.obj" />
      </geometry>
    </collision>
    <collision name="cabinet__visual_17__hull_005">
      <origin xyz="0 -0.349 0.4" rpy="0 0 0" />
      <geometry>
        <mesh filename="meshes/collision/cache/11598ca94e4fbb0785334a2d__hull_005.obj" />
      </geometry>
    </collision>
    <collision name="cabinet__visual_17__hull_006">
      <origin xyz="0 -0.349 0.4" rpy="0 0 0" />
      <geometry>
        <mesh filename="meshes/collision/cache/11598ca94e4fbb0785334a2d__hull_006.obj" />
      </geometry>
    </collision>
    <collision name="cabinet__visual_17__hull_007">
      <origin xyz="0 -0.349 0.4" rpy="0 0 0" />
      <geometry>
        <mesh filename="meshes/collision/cache/11598ca94e4fbb0785334a2d__hull_007.obj" />
      </geometry>
    </collision>
    <collision name="cabinet__visual_17__hull_008">
      <origin xyz="0 -0.349 0.4" rpy="0 0 0" />
      <geometry>
        <mesh filename="meshes/collision/cache/11598ca94e4fbb0785334a2d__hull_008.obj" />
      </geometry>
    </collision>
    <collision name="cabinet__visual_17__hull_009">
      <origin xyz="0 -0.349 0.4" rpy="0 0 0" />
      <geometry>
        <mesh filename="meshes/collision/cache/11598ca94e4fbb0785334a2d__hull_009.obj" />
      </geometry>
    </collision>
    <collision name="cabinet__visual_18">
      <origin xyz="0 0.08 0.4" rpy="1.5708 0 0" />
      <geometry>
        <cylinder radius="0.245" length="0.44" />
      </geometry>
    </collision>
    <collision name="cabinet__visual_19__hull_001">
      <origin xyz="0 -0.18 0.4" rpy="0 0 0" />
      <geometry>
        <mesh filename="meshes/collision/cache/299534ec5368a539b0e06906__hull_001.obj" />
      </geometry>
    </collision>
    <collision name="cabinet__visual_19__hull_002">
      <origin xyz="0 -0.18 0.4" rpy="0 0 0" />
      <geometry>
        <mesh filename="meshes/collision/cache/299534ec5368a539b0e06906__hull_002.obj" />
      </geometry>
    </collision>
    <collision name="cabinet__visual_19__hull_003">
      <origin xyz="0 -0.18 0.4" rpy="0 0 0" />
      <geometry>
        <mesh filename="meshes/collision/cache/299534ec5368a539b0e06906__hull_003.obj" />
      </geometry>
    </collision>
    <collision name="cabinet__visual_19__hull_004">
      <origin xyz="0 -0.18 0.4" rpy="0 0 0" />
      <geometry>
        <mesh filename="meshes/collision/cache/299534ec5368a539b0e06906__hull_004.obj" />
      </geometry>
    </collision>
    <collision name="cabinet__visual_19__hull_005">
      <origin xyz="0 -0.18 0.4" rpy="0 0 0" />
      <geometry>
        <mesh filename="meshes/collision/cache/299534ec5368a539b0e06906__hull_005.obj" />
      </geometry>
    </collision>
    <collision name="cabinet__visual_19__hull_006">
      <origin xyz="0 -0.18 0.4" rpy="0 0 0" />
      <geometry>
        <mesh filename="meshes/collision/cache/299534ec5368a539b0e06906__hull_006.obj" />
      </geometry>
    </collision>
    <collision name="cabinet__visual_19__hull_007">
      <origin xyz="0 -0.18 0.4" rpy="0 0 0" />
      <geometry>
        <mesh filename="meshes/collision/cache/299534ec5368a539b0e06906__hull_007.obj" />
      </geometry>
    </collision>
    <collision name="cabinet__visual_19__hull_008">
      <origin xyz="0 -0.18 0.4" rpy="0 0 0" />
      <geometry>
        <mesh filename="meshes/collision/cache/299534ec5368a539b0e06906__hull_008.obj" />
      </geometry>
    </collision>
    <collision name="cabinet__visual_20">
      <origin xyz="0 0.32 0.4" rpy="1.5708 0 0" />
      <geometry>
        <cylinder radius="0.23" length="0.04" />
      </geometry>
    </collision>
    <collision name="cabinet__visual_21">
      <origin xyz="0 0.35 0.4" rpy="1.5708 0 0" />
      <geometry>
        <cylinder radius="0.04" length="0.08" />
      </geometry>
    </collision>
    <collision name="cabinet__visual_22">
      <origin xyz="-0.24 -0.27 0.015" rpy="0 0 0" />
      <geometry>
        <cylinder radius="0.025" length="0.03" />
      </geometry>
    </collision>
    <collision name="cabinet__visual_23">
      <origin xyz="0.24 -0.27 0.015" rpy="0 0 0" />
      <geometry>
        <cylinder radius="0.025" length="0.03" />
      </geometry>
    </collision>
    <collision name="cabinet__visual_24">
      <origin xyz="-0.24 0.27 0.015" rpy="0 0 0" />
      <geometry>
        <cylinder radius="0.025" length="0.03" />
      </geometry>
    </collision>
    <collision name="cabinet__visual_25">
      <origin xyz="0.24 0.27 0.015" rpy="0 0 0" />
      <geometry>
        <cylinder radius="0.025" length="0.03" />
      </geometry>
    </collision>
  </link>
  <link name="door">
    <inertial>
      <origin xyz="0.235 -0.043 0" rpy="1.5708 0 0" />
      <mass value="4.8" />
      <inertia ixx="0.09828" ixy="0" ixz="0" iyy="0.09828" iyz="0" izz="0.19494" />
    </inertial>
    <visual>
      <origin xyz="0.235 -0.043 0" rpy="0 0 0" />
      <geometry>
        <mesh filename="meshes/door_outer_ring.glb" />
      </geometry>
      <material name="graphite_plastic">
        <color rgba="0.15 0.16 0.18 1" />
      </material>
    </visual>
    <visual>
      <origin xyz="0.235 -0.056 0" rpy="0 0 0" />
      <geometry>
        <mesh filename="meshes/door_inner_ring.glb" />
      </geometry>
      <material name="graphite_plastic">
        <color rgba="0.15 0.16 0.18 1" />
      </material>
    </visual>
    <visual>
      <origin xyz="0.235 -0.049 0" rpy="1.5708 0 0" />
      <geometry>
        <cylinder radius="0.206" length="0.01" />
      </geometry>
      <material name="dark_glass">
        <color rgba="0.1 0.12 0.14 0.45" />
      </material>
    </visual>
    <visual>
      <geometry>
        <mesh filename="meshes/door_handle.glb" />
      </geometry>
      <material name="chrome">
        <color rgba="0.84 0.85 0.87 1" />
      </material>
    </visual>
    <visual>
      <origin xyz="0.015 -0.03 0" rpy="0 0 0" />
      <geometry>
        <box size="0.05 0.028 0.22" />
      </geometry>
      <material name="graphite_plastic">
        <color rgba="0.15 0.16 0.18 1" />
      </material>
    </visual>
    <visual>
      <origin xyz="0 -0.016 0" rpy="0 0 0" />
      <geometry>
        <cylinder radius="0.012" length="0.22" />
      </geometry>
      <material name="chrome">
        <color rgba="0.84 0.85 0.87 1" />
      </material>
    </visual>
    <collision name="door__visual_1__hull_001">
      <origin xyz="0.235 -0.043 0" rpy="0 0 0" />
      <geometry>
        <mesh filename="meshes/collision/cache/68e9a79b0dfddbb21307ee66__hull_001.obj" />
      </geometry>
    </collision>
    <collision name="door__visual_1__hull_002">
      <origin xyz="0.235 -0.043 0" rpy="0 0 0" />
      <geometry>
        <mesh filename="meshes/collision/cache/68e9a79b0dfddbb21307ee66__hull_002.obj" />
      </geometry>
    </collision>
    <collision name="door__visual_1__hull_003">
      <origin xyz="0.235 -0.043 0" rpy="0 0 0" />
      <geometry>
        <mesh filename="meshes/collision/cache/68e9a79b0dfddbb21307ee66__hull_003.obj" />
      </geometry>
    </collision>
    <collision name="door__visual_1__hull_004">
      <origin xyz="0.235 -0.043 0" rpy="0 0 0" />
      <geometry>
        <mesh filename="meshes/collision/cache/68e9a79b0dfddbb21307ee66__hull_004.obj" />
      </geometry>
    </collision>
    <collision name="door__visual_1__hull_005">
      <origin xyz="0.235 -0.043 0" rpy="0 0 0" />
      <geometry>
        <mesh filename="meshes/collision/cache/68e9a79b0dfddbb21307ee66__hull_005.obj" />
      </geometry>
    </collision>
    <collision name="door__visual_1__hull_006">
      <origin xyz="0.235 -0.043 0" rpy="0 0 0" />
      <geometry>
        <mesh filename="meshes/collision/cache/68e9a79b0dfddbb21307ee66__hull_006.obj" />
      </geometry>
    </collision>
    <collision name="door__visual_1__hull_007">
      <origin xyz="0.235 -0.043 0" rpy="0 0 0" />
      <geometry>
        <mesh filename="meshes/collision/cache/68e9a79b0dfddbb21307ee66__hull_007.obj" />
      </geometry>
    </collision>
    <collision name="door__visual_1__hull_008">
      <origin xyz="0.235 -0.043 0" rpy="0 0 0" />
      <geometry>
        <mesh filename="meshes/collision/cache/68e9a79b0dfddbb21307ee66__hull_008.obj" />
      </geometry>
    </collision>
    <collision name="door__visual_2__hull_001">
      <origin xyz="0.235 -0.056 0" rpy="0 0 0" />
      <geometry>
        <mesh filename="meshes/collision/cache/0fef74682f5f105fde3f2565__hull_001.obj" />
      </geometry>
    </collision>
    <collision name="door__visual_2__hull_002">
      <origin xyz="0.235 -0.056 0" rpy="0 0 0" />
      <geometry>
        <mesh filename="meshes/collision/cache/0fef74682f5f105fde3f2565__hull_002.obj" />
      </geometry>
    </collision>
    <collision name="door__visual_2__hull_003">
      <origin xyz="0.235 -0.056 0" rpy="0 0 0" />
      <geometry>
        <mesh filename="meshes/collision/cache/0fef74682f5f105fde3f2565__hull_003.obj" />
      </geometry>
    </collision>
    <collision name="door__visual_2__hull_004">
      <origin xyz="0.235 -0.056 0" rpy="0 0 0" />
      <geometry>
        <mesh filename="meshes/collision/cache/0fef74682f5f105fde3f2565__hull_004.obj" />
      </geometry>
    </collision>
    <collision name="door__visual_2__hull_005">
      <origin xyz="0.235 -0.056 0" rpy="0 0 0" />
      <geometry>
        <mesh filename="meshes/collision/cache/0fef74682f5f105fde3f2565__hull_005.obj" />
      </geometry>
    </collision>
    <collision name="door__visual_2__hull_006">
      <origin xyz="0.235 -0.056 0" rpy="0 0 0" />
      <geometry>
        <mesh filename="meshes/collision/cache/0fef74682f5f105fde3f2565__hull_006.obj" />
      </geometry>
    </collision>
    <collision name="door__visual_2__hull_007">
      <origin xyz="0.235 -0.056 0" rpy="0 0 0" />
      <geometry>
        <mesh filename="meshes/collision/cache/0fef74682f5f105fde3f2565__hull_007.obj" />
      </geometry>
    </collision>
    <collision name="door__visual_2__hull_008">
      <origin xyz="0.235 -0.056 0" rpy="0 0 0" />
      <geometry>
        <mesh filename="meshes/collision/cache/0fef74682f5f105fde3f2565__hull_008.obj" />
      </geometry>
    </collision>
    <collision name="door__visual_3">
      <origin xyz="0.235 -0.049 0" rpy="1.5708 0 0" />
      <geometry>
        <cylinder radius="0.206" length="0.01" />
      </geometry>
    </collision>
    <collision name="door__visual_4__hull_001">
      <geometry>
        <mesh filename="meshes/collision/cache/f20c236e14c5951c5da1bc87__hull_001.obj" />
      </geometry>
    </collision>
    <collision name="door__visual_4__hull_002">
      <geometry>
        <mesh filename="meshes/collision/cache/f20c236e14c5951c5da1bc87__hull_002.obj" />
      </geometry>
    </collision>
    <collision name="door__visual_4__hull_003">
      <geometry>
        <mesh filename="meshes/collision/cache/f20c236e14c5951c5da1bc87__hull_003.obj" />
      </geometry>
    </collision>
    <collision name="door__visual_4__hull_004">
      <geometry>
        <mesh filename="meshes/collision/cache/f20c236e14c5951c5da1bc87__hull_004.obj" />
      </geometry>
    </collision>
    <collision name="door__visual_5">
      <origin xyz="0.015 -0.03 0" rpy="0 0 0" />
      <geometry>
        <box size="0.05 0.028 0.22" />
      </geometry>
    </collision>
    <collision name="door__visual_6">
      <origin xyz="0 -0.016 0" rpy="0 0 0" />
      <geometry>
        <cylinder radius="0.012" length="0.22" />
      </geometry>
    </collision>
  </link>
  <link name="selector_knob">
    <inertial>
      <origin xyz="0 -0.038 0" rpy="1.5708 0 0" />
      <mass value="0.25" />
      <inertia ixx="0.000135146" ixy="0" ixz="0" iyy="0.000135146" iyz="0" izz="0.000210125" />
    </inertial>
    <visual>
      <geometry>
        <mesh filename="meshes/selector_knob.glb" />
      </geometry>
      <material name="brushed_steel">
        <color rgba="0.75 0.77 0.8 1" />
      </material>
    </visual>
    <collision name="selector_knob__visual_1__hull_001">
      <geometry>
        <mesh filename="meshes/collision/cache/eaa6bc2e6241ec099a02d12a__hull_001.obj" />
      </geometry>
    </collision>
  </link>
  <link name="power_button">
    <inertial>
      <origin xyz="0 -0.007 0" rpy="0 0 0" />
      <mass value="0.03" />
      <inertia ixx="1.2125e-06" ixy="0" ixz="0" iyy="3.9625e-06" iyz="0" izz="3.73e-06" />
    </inertial>
    <visual>
      <origin xyz="0 -0.007 0" rpy="0 0 0" />
      <geometry>
        <box size="0.036 0.014 0.017" />
      </geometry>
      <material name="graphite_plastic">
        <color rgba="0.15 0.16 0.18 1" />
      </material>
    </visual>
    <collision name="power_button__visual_1">
      <origin xyz="0 -0.007 0" rpy="0 0 0" />
      <geometry>
        <box size="0.036 0.014 0.017" />
      </geometry>
    </collision>
  </link>
  <link name="start_button">
    <inertial>
      <origin xyz="0 -0.007 0" rpy="0 0 0" />
      <mass value="0.04" />
      <inertia ixx="1.73333e-06" ixy="0" ixz="0" iyy="9.41333e-06" iyz="0" izz="8.98667e-06" />
    </inertial>
    <visual>
      <origin xyz="0 -0.007 0" rpy="0 0 0" />
      <geometry>
        <box size="0.05 0.014 0.018" />
      </geometry>
      <material name="graphite_plastic">
        <color rgba="0.15 0.16 0.18 1" />
      </material>
    </visual>
    <collision name="start_button__visual_1">
      <origin xyz="0 -0.007 0" rpy="0 0 0" />
      <geometry>
        <box size="0.05 0.014 0.018" />
      </geometry>
    </collision>
  </link>
  <joint name="door_hinge" type="revolute">
    <origin xyz="-0.235 -0.349 0.4" rpy="0 0 0" />
    <parent link="cabinet" />
    <child link="door" />
    <axis xyz="0 0 1" />
    <limit effort="30" velocity="2.5" lower="-2.35" upper="0" />
  </joint>
  <joint name="selector_dial" type="revolute">
    <origin xyz="-0.17 -0.36 0.79" rpy="0 0 0" />
    <parent link="cabinet" />
    <child link="selector_knob" />
    <axis xyz="0 1 0" />
    <limit effort="2" velocity="8" lower="-2.4" upper="2.4" />
  </joint>
  <joint name="power_button_press" type="prismatic">
    <origin xyz="0.09 -0.35 0.77" rpy="0 0 0" />
    <parent link="cabinet" />
    <child link="power_button" />
    <axis xyz="0 1 0" />
    <limit effort="8" velocity="0.06" lower="0" upper="0.004" />
  </joint>
  <joint name="start_button_press" type="prismatic">
    <origin xyz="0.22 -0.35 0.77" rpy="0 0 0" />
    <parent link="cabinet" />
    <child link="start_button" />
    <axis xyz="0 1 0" />
    <limit effort="8" velocity="0.06" lower="0" upper="0.004" />
  </joint>
</robot>