<robot name="stick_vacuum">
  <material name="satin_graphite">
    <color rgba="0.17 0.18 0.2 1" />
  </material>
  <material name="brushed_aluminum">
    <color rgba="0.72 0.74 0.77 1" />
  </material>
  <material name="soft_black">
    <color rgba="0.08 0.08 0.09 1" />
  </material>
  <material name="smoke_clear">
    <color rgba="0.72 0.8 0.88 0.34" />
  </material>
  <material name="bronze_accent">
    <color rgba="0.72 0.42 0.16 1" />
  </material>
  <link name="body">
    <inertial>
      <origin xyz="0 -0.01 -0.02" rpy="0 0 0" />
      <mass value="2.35" />
      <inertia ixx="0.0389512" ixy="0" ixz="0" iyy="0.037365" iyz="0" izz="0.00722625" />
    </inertial>
    <visual>
      <geometry>
        <mesh filename="meshes/vacuum_body_shell.glb" />
      </geometry>
      <material name="satin_graphite">
        <color rgba="0.17 0.18 0.2 1" />
      </material>
    </visual>
    <visual>
      <origin xyz="0 -0.024 0" rpy="0 0 0" />
      <geometry>
        <box size="0.048 0.034 0.14" />
      </geometry>
      <material name="satin_graphite">
        <color rgba="0.17 0.18 0.2 1" />
      </material>
    </visual>
    <visual>
      <origin xyz="0 -0.074 0.108" rpy="0.72 0 0" />
      <geometry>
        <cylinder radius="0.011" length="0.128" />
      </geometry>
      <material name="soft_black">
        <color rgba="0.08 0.08 0.09 1" />
      </material>
    </visual>
    <visual>
      <origin xyz="0 -0.027 0.118" rpy="0.1 0 0" />
      <geometry>
        <cylinder radius="0.01" length="0.088" />
      </geometry>
      <material name="soft_black">
        <color rgba="0.08 0.08 0.09 1" />
      </material>
    </visual>
    <visual>
      <origin xyz="0 -0.046 0.176" rpy="1.5708 0 0" />
      <geometry>
        <cylinder radius="0.012" length="0.052" />
      </geometry>
      <material name="soft_black">
        <color rgba="0.08 0.08 0.09 1" />
      </material>
    </visual>
    <visual>
      <origin xyz="0 -0.026 0.09" rpy="0 0 0" />
      <geometry>
        <box size="0.02 0.01 0.038" />
      </geometry>
      <material name="soft_black">
        <color rgba="0.08 0.08 0.09 1" />
      </material>
    </visual>
    <visual>
      <origin xyz="0 0.01 -0.13" rpy="0 0 0" />
      <geometry>
        <cylinder radius="0.031" length="0.16" />
      </geometry>
      <material name="smoke_clear">
        <color rgba="0.72 0.8 0.88 0.34" />
      </material>
    </visual>
    <visual>
      <origin xyz="0 0 -0.065" rpy="0 0 0" />
      <geometry>
        <cylinder radius="0.036" length="0.032" />
      </geometry>
      <material name="bronze_accent">
        <color rgba="0.72 0.42 0.16 1" />
      </material>
    </visual>
    <visual>
      <origin xyz="0 0 -0.246" rpy="0 0 0" />
      <geometry>
        <cylinder radius="0.019" length="0.086" />
      </geometry>
      <material name="brushed_aluminum">
        <color rgba="0.72 0.74 0.77 1" />
      </material>
    </visual>
    <visual>
      <origin xyz="0 0 0.137" rpy="0 0 0" />
      <geometry>
        <box size="0.022 0.046 0.008" />
      </geometry>
      <material name="soft_black">
        <color rgba="0.08 0.08 0.09 1" />
      </material>
    </visual>
    <collision name="body__visual_1__hull_001">
      <geometry>
        <mesh filename="meshes/collision/cache/86f68cf7d84224545b97eac5__hull_001.obj" />
      </geometry>
    </collision>
    <collision name="body__visual_1__hull_002">
      <geometry>
        <mesh filename="meshes/collision/cache/86f68cf7d84224545b97eac5__hull_002.obj" />
      </geometry>
    </collision>
    <collision name="body__visual_1__hull_003">
      <geometry>
        <mesh filename="meshes/collision/cache/86f68cf7d84224545b97eac5__hull_003.obj" />
      </geometry>
    </collision>
    <collision name="body__visual_1__hull_004">
      <geometry>
        <mesh filename="meshes/collision/cache/86f68cf7d84224545b97eac5__hull_004.obj" />
      </geometry>
    </collision>
    <collision name="body__visual_1__hull_005">
      <geometry>
        <mesh filename="meshes/collision/cache/86f68cf7d84224545b97eac5__hull_005.obj" />
      </geometry>
    </collision>
    <collision name="body__visual_1__hull_006">
      <geometry>
        <mesh filename="meshes/collision/cache/86f68cf7d84224545b97eac5__hull_006.obj" />
      </geometry>
    </collision>
    <collision name="body__visual_1__hull_007">
      <geometry>
        <mesh filename="meshes/collision/cache/86f68cf7d84224545b97eac5__hull_007.obj" />
      </geometry>
    </collision>
    <collision name="body__visual_1__hull_008">
      <geometry>
        <mesh filename="meshes/collision/cache/86f68cf7d84224545b97eac5__hull_008.obj" />
      </geometry>
    </collision>
    <collision name="body__visual_1__hull_009">
      <geometry>
        <mesh filename="meshes/collision/cache/86f68cf7d84224545b97eac5__hull_009.obj" />
      </geometry>
    </collision>
    <collision name="body__visual_1__hull_010">
      <geometry>
        <mesh filename="meshes/collision/cache/86f68cf7d84224545b97eac5__hull_010.obj" />
      </geometry>
    </collision>
    <collision name="body__visual_1__hull_011">
      <geometry>
        <mesh filename="meshes/collision/cache/86f68cf7d84224545b97eac5__hull_011.obj" />
      </geometry>
    </collision>
    <collision name="body__visual_1__hull_012">
      <geometry>
        <mesh filename="meshes/collision/cache/86f68cf7d84224545b97eac5__hull_012.obj" />
      </geometry>
    </collision>
    <collision name="body__visual_1__hull_013">
      <geometry>
        <mesh filename="meshes/collision/cache/86f68cf7d84224545b97eac5__hull_013.obj" />
      </geometry>
    </collision>
    <collision name="body__visual_1__hull_014">
      <geometry>
        <mesh filename="meshes/collision/cache/86f68cf7d84224545b97eac5__hull_014.obj" />
      </geometry>
    </collision>
    <collision name="body__visual_1__hull_015">
      <geometry>
        <mesh filename="meshes/collision/cache/86f68cf7d84224545b97eac5__hull_015.obj" />
      </geometry>
    </collision>
    <collision name="body__visual_1__hull_016">
      <geometry>
        <mesh filename="meshes/collision/cache/86f68cf7d84224545b97eac5__hull_016.obj" />
      </geometry>
    </collision>
    <collision name="body__visual_2">
      <origin xyz="0 -0.024 0" rpy="0 0 0" />
      <geometry>
        <box size="0.048 0.034 0.14" />
      </geometry>
    </collision>
    <collision name="body__visual_3">
      <origin xyz="0 -0.074 0.108" rpy="0.72 0 0" />
      <geometry>
        <cylinder radius="0.011" length="0.128" />
      </geometry>
    </collision>
    <collision name="body__visual_4">
      <origin xyz="0 -0.027 0.118" rpy="0.1 0 0" />
      <geometry>
        <cylinder radius="0.01" length="0.088" />
      </geometry>
    </collision>
    <collision name="body__visual_5">
      <origin xyz="0 -0.046 0.176" rpy="1.5708 0 0" />
      <geometry>
        <cylinder radius="0.012" length="0.052" />
      </geometry>
    </collision>
    <collision name="body__visual_6">
      <origin xyz="0 -0.026 0.09" rpy="0 0 0" />
      <geometry>
        <box size="0.02 0.01 0.038" />
      </geometry>
    </collision>
    <collision name="body__visual_7">
      <origin xyz="0 0.01 -0.13" rpy="0 0 0" />
      <geometry>
        <cylinder radius="0.031" length="0.16" />
      </geometry>
    </collision>
    <collision name="body__visual_8">
      <origin xyz="0 0 -0.065" rpy="0 0 0" />
      <geometry>
        <cylinder radius="0.036" length="0.032" />
      </geometry>
    </collision>
    <collision name="body__visual_9">
      <origin xyz="0 0 -0.246" rpy="0 0 0" />
      <geometry>
        <cylinder radius="0.019" length="0.086" />
      </geometry>
    </collision>
    <collision name="body__visual_10">
      <origin xyz="0 0 0.137" rpy="0 0 0" />
      <geometry>
        <box size="0.022 0.046 0.008" />
      </geometry>
    </collision>
  </link>
  <link name="trigger">
    <inertial>
      <origin xyz="0 -0.01 -0.016" rpy="0 0 0" />
      <mass value="0.03" />
      <inertia ixx="2.5e-06" ixy="0" ixz="0" iyy="2.89e-06" iyz="0" izz="8.9e-07" />
    </inertial>
    <visual>
      <origin xyz="0 -0.01 -0.016" rpy="0 0 0" />
      <geometry>
        <box size="0.016 0.01 0.03" />
      </geometry>
      <material name="soft_black">
        <color rgba="0.08 0.08 0.09 1" />
      </material>
    </visual>
    <collision name="trigger__visual_1">
      <origin xyz="0 -0.01 -0.016" rpy="0 0 0" />
      <geometry>
        <box size="0.016 0.01 0.03" />
      </geometry>
    </collision>
  </link>
  <link name="mode_slider">
    <inertial>
      <mass value="0.02" />
      <inertia ixx="8.66667e-07" ixy="0" ixz="0" iyy="3e-07" iyz="0" izz="1.04667e-06" />
    </inertial>
    <visual>
      <geometry>
        <box size="0.012 0.022 0.006" />
      </geometry>
      <material name="bronze_accent">
        <color rgba="0.72 0.42 0.16 1" />
      </material>
    </visual>
    <collision name="mode_slider__visual_1">
      <geometry>
        <box size="0.012 0.022 0.006" />
      </geometry>
    </collision>
  </link>
  <link name="wand">
    <inertial>
      <origin xyz="0 0 -0.2825" rpy="0 0 0" />
      <mass value="0.58" />
      <inertia ixx="0.0154762" ixy="0" ixz="0" iyy="0.0154762" iyz="0" izz="9.396e-05" />
    </inertial>
    <visual>
      <origin xyz="0 0 -0.27" rpy="0 0 0" />
      <geometry>
        <cylinder radius="0.0165" length="0.54" />
      </geometry>
      <material name="brushed_aluminum">
        <color rgba="0.72 0.74 0.77 1" />
      </material>
    </visual>
    <visual>
      <origin xyz="0 0 -0.024" rpy="0 0 0" />
      <geometry>
        <cylinder radius="0.019" length="0.048" />
      </geometry>
      <material name="brushed_aluminum">
        <color rgba="0.72 0.74 0.77 1" />
      </material>
    </visual>
    <visual>
      <origin xyz="0 0 -0.545" rpy="0 0 0" />
      <geometry>
        <cylinder radius="0.0185" length="0.02" />
      </geometry>
      <material name="soft_black">
        <color rgba="0.08 0.08 0.09 1" />
      </material>
    </visual>
    <collision name="wand__visual_1">
      <origin xyz="0 0 -0.27" rpy="0 0 0" />
      <geometry>
        <cylinder radius="0.0165" length="0.54" />
      </geometry>
    </collision>
    <collision name="wand__visual_2">
      <origin xyz="0 0 -0.024" rpy="0 0 0" />
      <geometry>
        <cylinder radius="0.019" length="0.048" />
      </geometry>
    </collision>
    <collision name="wand__visual_3">
      <origin xyz="0 0 -0.545" rpy="0 0 0" />
      <geometry>
        <cylinder radius="0.0185" length="0.02" />
      </geometry>
    </collision>
  </link>
  <link name="swivel">
    <inertial>
      <origin xyz="0 0 -0.052" rpy="0 0 0" />
      <mass value="0.22" />
      <inertia ixx="0.000199833" ixy="0" ixz="0" iyy="0.000331833" iyz="0" izz="0.000165" />
    </inertial>
    <visual>
      <origin xyz="0 0 -0.011" rpy="0 0 0" />
      <geometry>
        <cylinder radius="0.02" length="0.022" />
      </geometry>
      <material name="soft_black">
        <color rgba="0.08 0.08 0.09 1" />
      </material>
    </visual>
    <visual>
      <origin xyz="0 0 -0.045" rpy="0 0 0" />
      <geometry>
        <cylinder radius="0.014" length="0.05" />
      </geometry>
      <material name="soft_black">
        <color rgba="0.08 0.08 0.09 1" />
      </material>
    </visual>
    <visual>
      <origin xyz="0 0 -0.054" rpy="0 0 0" />
      <geometry>
        <box size="0.086 0.018 0.014" />
      </geometry>
      <material name="soft_black">
        <color rgba="0.08 0.08 0.09 1" />
      </material>
    </visual>
    <visual>
      <origin xyz="0 0 -0.076" rpy="0 1.5708 0" />
      <geometry>
        <cylinder radius="0.009" length="0.048" />
      </geometry>
      <material name="soft_black">
        <color rgba="0.08 0.08 0.09 1" />
      </material>
    </visual>
    <visual>
      <origin xyz="-0.036 0 -0.069" rpy="0 0 0" />
      <geometry>
        <box size="0.012 0.018 0.052" />
      </geometry>
      <material name="soft_black">
        <color rgba="0.08 0.08 0.09 1" />
      </material>
    </visual>
    <visual>
      <origin xyz="0.036 0 -0.069" rpy="0 0 0" />
      <geometry>
        <box size="0.012 0.018 0.052" />
      </geometry>
      <material name="soft_black">
        <color rgba="0.08 0.08 0.09 1" />
      </material>
    </visual>
    <collision name="swivel__visual_1">
      <origin xyz="0 0 -0.011" rpy="0 0 0" />
      <geometry>
        <cylinder radius="0.02" length="0.022" />
      </geometry>
    </collision>
    <collision name="swivel__visual_2">
      <origin xyz="0 0 -0.045" rpy="0 0 0" />
      <geometry>
        <cylinder radius="0.014" length="0.05" />
      </geometry>
    </collision>
    <collision name="swivel__visual_3">
      <origin xyz="0 0 -0.054" rpy="0 0 0" />
      <geometry>
        <box size="0.086 0.018 0.014" />
      </geometry>
    </collision>
    <collision name="swivel__visual_4">
      <origin xyz="0 0 -0.076" rpy="0 1.5708 0" />
      <geometry>
        <cylinder radius="0.009" length="0.048" />
      </geometry>
    </collision>
    <collision name="swivel__visual_5">
      <origin xyz="-0.036 0 -0.069" rpy="0 0 0" />
      <geometry>
        <box size="0.012 0.018 0.052" />
      </geometry>
    </collision>
    <collision name="swivel__visual_6">
      <origin xyz="0.036 0 -0.069" rpy="0 0 0" />
      <geometry>
        <box size="0.012 0.018 0.052" />
      </geometry>
    </collision>
  </link>
  <link name="floor_head">
    <inertial>
      <origin xyz="0 0.012 -0.028" rpy="0 0 0" />
      <mass value="0.82" />
      <inertia ixx="0.000997667" ixy="0" ixz="0" iyy="0.00552817" iyz="0" izz="0.00618417" />
    </inertial>
    <visual>
      <geometry>
        <mesh filename="meshes/vacuum_floor_head_shell.glb" />
      </geometry>
      <material name="satin_graphite">
        <color rgba="0.17 0.18 0.2 1" />
      </material>
    </visual>
    <visual>
      <origin xyz="0 0 -0.011" rpy="0 0 0" />
      <geometry>
        <box size="0.06 0.022 0.026" />
      </geometry>
      <material name="soft_black">
        <color rgba="0.08 0.08 0.09 1" />
      </material>
    </visual>
    <visual>
      <origin xyz="0 0 -0.003" rpy="0 1.5708 0" />
      <geometry>
        <cylinder radius="0.0065" length="0.03" />
      </geometry>
      <material name="soft_black">
        <color rgba="0.08 0.08 0.09 1" />
      </material>
    </visual>
    <visual>
      <origin xyz="-0.024 0 -0.004" rpy="0 1.5708 0" />
      <geometry>
        <cylinder radius="0.008" length="0.01" />
      </geometry>
      <material name="soft_black">
        <color rgba="0.08 0.08 0.09 1" />
      </material>
    </visual>
    <visual>
      <origin xyz="0.024 0 -0.004" rpy="0 1.5708 0" />
      <geometry>
        <cylinder radius="0.008" length="0.01" />
      </geometry>
      <material name="soft_black">
        <color rgba="0.08 0.08 0.09 1" />
      </material>
    </visual>
    <visual>
      <origin xyz="0 0.016 -0.04" rpy="0 0 0" />
      <geometry>
        <box size="0.24 0.068 0.006" />
      </geometry>
      <material name="soft_black">
        <color rgba="0.08 0.08 0.09 1" />
      </material>
    </visual>
    <visual>
      <origin xyz="0 0.05 -0.032" rpy="0 0 0" />
      <geometry>
        <box size="0.168 0.012 0.007" />
      </geometry>
      <material name="brushed_aluminum">
        <color rgba="0.72 0.74 0.77 1" />
      </material>
    </visual>
    <collision name="floor_head__visual_1__hull_001">
      <geometry>
        <mesh filename="meshes/collision/cache/57dc6d454e320e1bd7f86586__hull_001.obj" />
      </geometry>
    </collision>
    <collision name="floor_head__visual_2">
      <origin xyz="0 0 -0.011" rpy="0 0 0" />
      <geometry>
        <box size="0.06 0.022 0.026" />
      </geometry>
    </collision>
    <collision name="floor_head__visual_3">
      <origin xyz="0 0 -0.003" rpy="0 1.5708 0" />
      <geometry>
        <cylinder radius="0.0065" length="0.03" />
      </geometry>
    </collision>
    <collision name="floor_head__visual_4">
      <origin xyz="-0.024 0 -0.004" rpy="0 1.5708 0" />
      <geometry>
        <cylinder radius="0.008" length="0.01" />
      </geometry>
    </collision>
    <collision name="floor_head__visual_5">
      <origin xyz="0.024 0 -0.004" rpy="0 1.5708 0" />
      <geometry>
        <cylinder radius="0.008" length="0.01" />
      </geometry>
    </collision>
    <collision name="floor_head__visual_6">
      <origin xyz="0 0.016 -0.04" rpy="0 0 0" />
      <geometry>
        <box size="0.24 0.068 0.006" />
      </geometry>
    </collision>
    <collision name="floor_head__visual_7">
      <origin xyz="0 0.05 -0.032" rpy="0 0 0" />
      <geometry>
        <box size="0.168 0.012 0.007" />
      </geometry>
    </collision>
  </link>
  <joint name="trigger_pull" type="revolute">
    <origin xyz="0 -0.043 0.105" rpy="0 0 0" />
    <parent link="body" />
    <child link="trigger" />
    <axis xyz="-1 0 0" />
    <limit effort="4" velocity="4" lower="0" upper="0.42" />
  </joint>
  <joint name="power_slider" type="prismatic">
    <origin xyz="0 -0.01 0.143" rpy="0 0 0" />
    <parent link="body" />
    <child link="mode_slider" />
    <axis xyz="0 1 0" />
    <limit effort="2" velocity="0.15" lower="0" upper="0.014" />
  </joint>
  <joint name="body_to_wand" type="fixed">
    <origin xyz="0 0 -0.289" rpy="0 0 0" />
    <parent link="body" />
    <child link="wand" />
  </joint>
  <joint name="wand_swivel" type="revolute">
    <origin xyz="0 0 -0.555" rpy="0 0 0" />
    <parent link="wand" />
    <child link="swivel" />
    <axis xyz="0 0 1" />
    <limit effort="7" velocity="2.5" lower="-0.75" upper="0.75" />
  </joint>
  <joint name="head_pitch" type="revolute">
    <origin xyz="0 0 -0.086" rpy="0 0 0" />
    <parent link="swivel" />
    <child link="floor_head" />
    <axis xyz="1 0 0" />
    <limit effort="9" velocity="2.5" lower="0" upper="0.75" />
  </joint>
</robot>