<robot name="barrier_gate">
  <link name="base_housing">
    <inertial>
      <origin xyz="0 0 0.495" rpy="0 0 0" />
      <mass value="135" />
      <inertia ixx="16.2281" ixy="0" ixz="0" iyy="20.1386" iyz="0" izz="14.3145" />
      </inertial>
    <visual name="ground_plinth">
      <origin xyz="0 0 0.04" rpy="0 0 0" />
      <geometry>
        <box size="0.9 0.68 0.08" />
        </geometry>
      <material name="rubber_black">
        <color rgba="0.1 0.1 0.11 1" />
        </material>
      </visual>
    <visual name="lower_skirt">
      <origin xyz="0 0 0.095" rpy="0 0 0" />
      <geometry>
        <box size="0.76 0.54 0.03" />
        </geometry>
      <material name="rubber_black">
        <color rgba="0.1 0.1 0.11 1" />
        </material>
      </visual>
    <visual name="main_cabinet">
      <origin xyz="0 0 0.475" rpy="0 0 0" />
      <geometry>
        <box size="0.58 0.44 0.73" />
        </geometry>
      <material name="cabinet_red">
        <color rgba="0.76 0.1 0.08 1" />
        </material>
      </visual>
    <visual name="top_motor_cover">
      <origin xyz="0.03 0 0.915" rpy="0 0 0" />
      <geometry>
        <box size="0.46 0.46 0.15" />
        </geometry>
      <material name="cover_gray">
        <color rgba="0.23 0.24 0.27 1" />
        </material>
      </visual>
    <visual name="hinge_pedestal">
      <origin xyz="0.29 0 0.895" rpy="0 0 0" />
      <geometry>
        <box size="0.14 0.24 0.19" />
        </geometry>
      <material name="cover_gray">
        <color rgba="0.23 0.24 0.27 1" />
        </material>
      </visual>
    <visual name="service_door">
      <origin xyz="0.02 -0.224 0.43" rpy="0 0 0" />
      <geometry>
        <box size="0.34 0.008 0.5" />
        </geometry>
      <material name="control_gray">
        <color rgba="0.78 0.79 0.8 1" />
        </material>
      </visual>
    <visual name="door_handle">
      <origin xyz="0.17 -0.239 0.43" rpy="0 0 0" />
      <geometry>
        <box size="0.03 0.026 0.1" />
        </geometry>
      <material name="rubber_black">
        <color rgba="0.1 0.1 0.11 1" />
        </material>
      </visual>
    <visual name="control_pod">
      <origin xyz="-0.1 0.25 0.52" rpy="0 0 0" />
      <geometry>
        <box size="0.14 0.06 0.22" />
        </geometry>
      <material name="control_gray">
        <color rgba="0.78 0.79 0.8 1" />
        </material>
      </visual>
    <visual name="emergency_stop">
      <origin xyz="-0.1 0.295 0.57" rpy="1.5708 0 0" />
      <geometry>
        <cylinder radius="0.022" length="0.03" />
        </geometry>
      <material name="cabinet_red">
        <color rgba="0.76 0.1 0.08 1" />
        </material>
      </visual>
    <visual name="key_switch">
      <origin xyz="-0.1 0.29 0.49" rpy="1.5708 0 0" />
      <geometry>
        <cylinder radius="0.012" length="0.02" />
        </geometry>
      <material name="steel">
        <color rgba="0.63 0.65 0.68 1" />
        </material>
      </visual>
    <visual name="beacon_base">
      <origin xyz="-0.14 0 1" rpy="0 0 0" />
      <geometry>
        <cylinder radius="0.03" length="0.02" />
        </geometry>
      <material name="rubber_black">
        <color rgba="0.1 0.1 0.11 1" />
        </material>
      </visual>
    <visual name="beacon_lens">
      <origin xyz="-0.14 0 1.04" rpy="0 0 0" />
      <geometry>
        <sphere radius="0.03" />
        </geometry>
      <material name="amber_lens">
        <color rgba="0.95 0.62 0.1 0.72" />
        </material>
      </visual>
    </link>
  <link name="gate_arm">
    <inertial>
      <origin xyz="2.13 0 0.06" rpy="0 0 0" />
      <mass value="18" />
      <inertia ixx="0.087" ixy="0" ixz="0" iyy="27.2598" iyz="0" izz="27.27" />
      </inertial>
    <visual name="hinge_head">
      <origin xyz="0.12 0 0.054" rpy="0 0 0" />
      <geometry>
        <box size="0.24 0.16 0.1" />
        </geometry>
      <material name="cover_gray">
        <color rgba="0.23 0.24 0.27 1" />
        </material>
      </visual>
    <visual name="pivot_drum">
      <origin xyz="0.055 0 0.074" rpy="1.5708 0 0" />
      <geometry>
        <cylinder radius="0.06" length="0.18" />
        </geometry>
      <material name="steel">
        <color rgba="0.63 0.65 0.68 1" />
        </material>
      </visual>
    <visual name="pivot_cap">
      <origin xyz="0.025 0 0.074" rpy="1.5708 0 0" />
      <geometry>
        <cylinder radius="0.03" length="0.22" />
        </geometry>
      <material name="rubber_black">
        <color rgba="0.1 0.1 0.11 1" />
        </material>
      </visual>
    <visual name="main_boom">
      <origin xyz="2.2 0 0.054" rpy="0 0 0" />
      <geometry>
        <box size="3.92 0.1 0.08" />
        </geometry>
      <material name="arm_white">
        <color rgba="0.93 0.94 0.95 1" />
        </material>
      </visual>
    <visual name="underslung_reinforcement">
      <origin xyz="0.86 0 0.002" rpy="0 0 0" />
      <geometry>
        <box size="1.2 0.05 0.04" />
        </geometry>
      <material name="rubber_black">
        <color rgba="0.1 0.1 0.11 1" />
        </material>
      </visual>
    <visual name="drive_cowl">
      <origin xyz="0.35 0 0.119" rpy="0 0 0" />
      <geometry>
        <box size="0.2 0.08 0.052" />
        </geometry>
      <material name="cover_gray">
        <color rgba="0.23 0.24 0.27 1" />
        </material>
      </visual>
    <visual name="stripe_1">
      <origin xyz="0.56 0 0.054" rpy="0 0 0" />
      <geometry>
        <box size="0.16 0.104 0.082" />
        </geometry>
      <material name="stripe_red">
        <color rgba="0.82 0.14 0.12 1" />
        </material>
      </visual>
    <visual name="stripe_2">
      <origin xyz="1.22 0 0.054" rpy="0 0 0" />
      <geometry>
        <box size="0.16 0.104 0.082" />
        </geometry>
      <material name="stripe_red">
        <color rgba="0.82 0.14 0.12 1" />
        </material>
      </visual>
    <visual name="stripe_3">
      <origin xyz="1.88 0 0.054" rpy="0 0 0" />
      <geometry>
        <box size="0.16 0.104 0.082" />
        </geometry>
      <material name="stripe_red">
        <color rgba="0.82 0.14 0.12 1" />
        </material>
      </visual>
    <visual name="stripe_4">
      <origin xyz="2.54 0 0.054" rpy="0 0 0" />
      <geometry>
        <box size="0.16 0.104 0.082" />
        </geometry>
      <material name="stripe_red">
        <color rgba="0.82 0.14 0.12 1" />
        </material>
      </visual>
    <visual name="stripe_5">
      <origin xyz="3.2 0 0.054" rpy="0 0 0" />
      <geometry>
        <box size="0.16 0.104 0.082" />
        </geometry>
      <material name="stripe_red">
        <color rgba="0.82 0.14 0.12 1" />
        </material>
      </visual>
    <visual name="stripe_6">
      <origin xyz="3.86 0 0.054" rpy="0 0 0" />
      <geometry>
        <box size="0.16 0.104 0.082" />
        </geometry>
      <material name="stripe_red">
        <color rgba="0.82 0.14 0.12 1" />
        </material>
      </visual>
    <visual name="tip_cap">
      <origin xyz="4.21 0 0.054" rpy="0 0 0" />
      <geometry>
        <box size="0.1 0.14 0.14" />
        </geometry>
      <material name="rubber_black">
        <color rgba="0.1 0.1 0.11 1" />
        </material>
      </visual>
    <visual name="tip_light_housing">
      <origin xyz="4.19 0 0.005" rpy="0 0 0" />
      <geometry>
        <box size="0.06 0.12 0.05" />
        </geometry>
      <material name="rubber_black">
        <color rgba="0.1 0.1 0.11 1" />
        </material>
      </visual>
    </link>
  <joint name="arm_hinge" type="revolute">
    <origin xyz="0.29 0 0.99" rpy="0 0 0" />
    <parent link="base_housing" />
    <child link="gate_arm" />
    <axis xyz="0 -1 0" />
    <limit effort="220" velocity="1.2" lower="0" upper="1.35" />
    </joint>
  </robot>
