<robot name="air_purifier">
  <link name="body">
    <inertial>
      <origin xyz="0 0 0.334" rpy="0 0 0" />
      <mass value="9" />
      <inertia ixx="0.385368" ixy="0" ixz="0" iyy="0.431868" iyz="0" izz="0.1479" />
    </inertial>
    <visual>
      <geometry>
        <mesh filename="meshes/base_plinth.glb" />
      </geometry>
      <material name="charcoal_abs">
        <color rgba="0.14 0.15 0.16 1" />
      </material>
    </visual>
    <visual>
      <origin xyz="0 0 0.02" rpy="0 0 0" />
      <geometry>
        <mesh filename="meshes/main_shell.glb" />
      </geometry>
      <material name="shell_white">
        <color rgba="0.93 0.94 0.92 1" />
      </material>
    </visual>
    <visual>
      <origin xyz="0 0 0.654" rpy="0 0 0" />
      <geometry>
        <mesh filename="meshes/top_cap.glb" />
      </geometry>
      <material name="shell_white">
        <color rgba="0.93 0.94 0.92 1" />
      </material>
    </visual>
    <visual>
      <origin xyz="0 -0.03 0.658" rpy="0 0 0" />
      <geometry>
        <mesh filename="meshes/top_exhaust.glb" />
      </geometry>
      <material name="charcoal_abs">
        <color rgba="0.14 0.15 0.16 1" />
      </material>
    </visual>
    <visual>
      <origin xyz="0 0.03 0.658" rpy="0 0 0" />
      <geometry>
        <mesh filename="meshes/control_deck.glb" />
      </geometry>
      <material name="smoked_glass">
        <color rgba="0.1 0.11 0.12 0.9" />
      </material>
    </visual>
    <visual>
      <origin xyz="0 -0.117 0.305" rpy="1.5708 0 0" />
      <geometry>
        <mesh filename="meshes/rear_intake.glb" />
      </geometry>
      <material name="charcoal_abs">
        <color rgba="0.14 0.15 0.16 1" />
      </material>
    </visual>
    <visual>
      <origin xyz="0 0.117 0.58" rpy="0 0 0" />
      <geometry>
        <box size="0.182 0.008 0.062" />
      </geometry>
      <material name="smoked_glass">
        <color rgba="0.1 0.11 0.12 0.9" />
      </material>
    </visual>
    <visual>
      <origin xyz="0 0.1185 0.536" rpy="0 0 0" />
      <geometry>
        <box size="0.128 0.003 0.012" />
      </geometry>
      <material name="brushed_aluminum">
        <color rgba="0.63 0.65 0.67 1" />
      </material>
    </visual>
    <visual>
      <origin xyz="0.052 0.03 0.662" rpy="0 0 0" />
      <geometry>
        <cylinder radius="0.03" length="0.004" />
      </geometry>
      <material name="brushed_aluminum">
        <color rgba="0.63 0.65 0.67 1" />
      </material>
    </visual>
    <visual>
      <origin xyz="-0.05 0.036 0.662" rpy="0 0 0" />
      <geometry>
        <cylinder radius="0.017" length="0.004" />
      </geometry>
      <material name="brushed_aluminum">
        <color rgba="0.63 0.65 0.67 1" />
      </material>
    </visual>
    <collision name="body__visual_1__hull_001">
      <geometry>
        <mesh filename="meshes/collision/cache/ea7131efe0071874e7fa7aa3__hull_001.obj" />
      </geometry>
    </collision>
    <collision name="body__visual_2__hull_001">
      <origin xyz="0 0 0.02" rpy="0 0 0" />
      <geometry>
        <mesh filename="meshes/collision/cache/fce6f4a88becaa7b729aeb84__hull_001.obj" />
      </geometry>
    </collision>
    <collision name="body__visual_3__hull_001">
      <origin xyz="0 0 0.654" rpy="0 0 0" />
      <geometry>
        <mesh filename="meshes/collision/cache/f56e50df85797498d2b95fa3__hull_001.obj" />
      </geometry>
    </collision>
    <collision name="body__visual_4__hull_001">
      <origin xyz="0 -0.03 0.658" rpy="0 0 0" />
      <geometry>
        <mesh filename="meshes/collision/cache/e8f8333ead6528121746bf22__hull_001.obj" />
      </geometry>
    </collision>
    <collision name="body__visual_5__hull_001">
      <origin xyz="0 0.03 0.658" rpy="0 0 0" />
      <geometry>
        <mesh filename="meshes/collision/cache/e530d58affb329de1ba5adee__hull_001.obj" />
      </geometry>
    </collision>
    <collision name="body__visual_6__hull_001">
      <origin xyz="0 -0.117 0.305" rpy="1.5708 0 0" />
      <geometry>
        <mesh filename="meshes/collision/cache/5c7f7a3e9c482f12d4eb3c29__hull_001.obj" />
      </geometry>
    </collision>
    <collision name="body__visual_7">
      <origin xyz="0 0.117 0.58" rpy="0 0 0" />
      <geometry>
        <box size="0.182 0.008 0.062" />
      </geometry>
    </collision>
    <collision name="body__visual_8">
      <origin xyz="0 0.1185 0.536" rpy="0 0 0" />
      <geometry>
        <box size="0.128 0.003 0.012" />
      </geometry>
    </collision>
    <collision name="body__visual_9">
      <origin xyz="0.052 0.03 0.662" rpy="0 0 0" />
      <geometry>
        <cylinder radius="0.03" length="0.004" />
      </geometry>
    </collision>
    <collision name="body__visual_10">
      <origin xyz="-0.05 0.036 0.662" rpy="0 0 0" />
      <geometry>
        <cylinder radius="0.017" length="0.004" />
      </geometry>
    </collision>
  </link>
  <link name="filter_door">
    <inertial>
      <origin xyz="-0.144 0.009 0" rpy="0 0 0" />
      <mass value="1.1" />
      <inertia ixx="0.0220389" ixy="0" ixz="0" iyy="0.0296124" iyz="0" izz="0.0076329" />
    </inertial>
    <visual>
      <origin xyz="-0.144 0.009 0" rpy="0 0 0" />
      <geometry>
        <mesh filename="meshes/filter_door_panel.glb" />
      </geometry>
      <material name="shell_white">
        <color rgba="0.93 0.94 0.92 1" />
      </material>
    </visual>
    <visual>
      <origin xyz="-0.144 0.016 -0.055" rpy="1.5708 0 0" />
      <geometry>
        <mesh filename="meshes/filter_door_grille.glb" />
      </geometry>
      <material name="charcoal_abs">
        <color rgba="0.14 0.15 0.16 1" />
      </material>
    </visual>
    <visual>
      <origin xyz="-0.263 0.022 0.02" rpy="0 0 0" />
      <geometry>
        <box size="0.018 0.012 0.095" />
      </geometry>
      <material name="brushed_aluminum">
        <color rgba="0.63 0.65 0.67 1" />
      </material>
    </visual>
    <collision name="filter_door__visual_1__hull_001">
      <origin xyz="-0.144 0.009 0" rpy="0 0 0" />
      <geometry>
        <mesh filename="meshes/collision/cache/64c93fb4611c499a2d91a11c__hull_001.obj" />
      </geometry>
    </collision>
    <collision name="filter_door__visual_2__hull_001">
      <origin xyz="-0.144 0.016 -0.055" rpy="1.5708 0 0" />
      <geometry>
        <mesh filename="meshes/collision/cache/056f5a6ad1d4830ec753c25b__hull_001.obj" />
      </geometry>
    </collision>
    <collision name="filter_door__visual_3">
      <origin xyz="-0.263 0.022 0.02" rpy="0 0 0" />
      <geometry>
        <box size="0.018 0.012 0.095" />
      </geometry>
    </collision>
  </link>
  <link name="control_knob">
    <inertial>
      <origin xyz="0 0 0.01225" rpy="0 0 0" />
      <mass value="0.09" />
      <inertia ixx="1.67569e-05" ixy="0" ixz="0" iyy="1.67569e-05" iyz="0" izz="2.592e-05" />
    </inertial>
    <visual>
      <origin xyz="0 0 0.007" rpy="0 0 0" />
      <geometry>
        <cylinder radius="0.024" length="0.012" />
      </geometry>
      <material name="soft_rubber">
        <color rgba="0.07 0.08 0.08 1" />
      </material>
    </visual>
    <visual>
      <origin xyz="0 0 0.0175" rpy="0 0 0" />
      <geometry>
        <cylinder radius="0.02" length="0.009" />
      </geometry>
      <material name="brushed_aluminum">
        <color rgba="0.63 0.65 0.67 1" />
      </material>
    </visual>
    <visual>
      <origin xyz="0.01 0 0.0235" rpy="0 0 0" />
      <geometry>
        <box size="0.012 0.005 0.003" />
      </geometry>
      <material name="charcoal_abs">
        <color rgba="0.14 0.15 0.16 1" />
      </material>
    </visual>
    <collision name="control_knob__visual_1">
      <origin xyz="0 0 0.007" rpy="0 0 0" />
      <geometry>
        <cylinder radius="0.024" length="0.012" />
      </geometry>
    </collision>
    <collision name="control_knob__visual_2">
      <origin xyz="0 0 0.0175" rpy="0 0 0" />
      <geometry>
        <cylinder radius="0.02" length="0.009" />
      </geometry>
    </collision>
    <collision name="control_knob__visual_3">
      <origin xyz="0.01 0 0.0235" rpy="0 0 0" />
      <geometry>
        <box size="0.012 0.005 0.003" />
      </geometry>
    </collision>
  </link>
  <link name="power_button">
    <inertial>
      <origin xyz="0 0 0.01" rpy="0 0 0" />
      <mass value="0.02" />
      <inertia ixx="1.085e-06" ixy="0" ixz="0" iyy="1.085e-06" iyz="0" izz="1.69e-06" />
    </inertial>
    <visual>
      <origin xyz="0 0 0.008" rpy="0 0 0" />
      <geometry>
        <cylinder radius="0.0065" length="0.008" />
      </geometry>
      <material name="soft_rubber">
        <color rgba="0.07 0.08 0.08 1" />
      </material>
    </visual>
    <visual>
      <origin xyz="0 0 0.014" rpy="0 0 0" />
      <geometry>
        <cylinder radius="0.013" length="0.004" />
      </geometry>
      <material name="charcoal_abs">
        <color rgba="0.14 0.15 0.16 1" />
      </material>
    </visual>
    <collision name="power_button__visual_1">
      <origin xyz="0 0 0.008" rpy="0 0 0" />
      <geometry>
        <cylinder radius="0.0065" length="0.008" />
      </geometry>
    </collision>
    <collision name="power_button__visual_2">
      <origin xyz="0 0 0.014" rpy="0 0 0" />
      <geometry>
        <cylinder radius="0.013" length="0.004" />
      </geometry>
    </collision>
  </link>
  <joint name="filter_door_hinge" type="revolute">
    <origin xyz="0.144 0.124 0.33" rpy="0 0 0" />
    <parent link="body" />
    <child link="filter_door" />
    <axis xyz="0 0 -1" />
    <limit effort="12" velocity="1.5" lower="0" upper="1.45" />
  </joint>
  <joint name="control_knob_spin" type="continuous">
    <origin xyz="0.052 0.03 0.664" rpy="0 0 0" />
    <parent link="body" />
    <child link="control_knob" />
    <axis xyz="0 0 1" />
    <limit effort="2.5" velocity="6" />
  </joint>
  <joint name="power_button_slide" type="prismatic">
    <origin xyz="-0.05 0.036 0.664" rpy="0 0 0" />
    <parent link="body" />
    <child link="power_button" />
    <axis xyz="0 0 -1" />
    <limit effort="8" velocity="0.2" lower="0" upper="0.0025" />
  </joint>
</robot>