<robot name="dock_loading_ramp">
  <material name="painted_steel">
    <color rgba="0.27 0.29 0.31 1" />
    </material>
  <material name="safety_yellow">
    <color rgba="0.89 0.74 0.16 1" />
    </material>
  <material name="brushed_steel">
    <color rgba="0.76 0.77 0.79 1" />
    </material>
  <material name="rubber_black">
    <color rgba="0.08 0.08 0.09 1" />
    </material>
  <link name="base_frame">
    <inertial>
      <origin xyz="0 -0.28 0.05" rpy="0 0 0" />
      <mass value="820" />
      <inertia ixx="22.1127" ixy="0" ixz="0" iyy="427.767" iyz="0" izz="448.513" />
      </inertial>
    <visual>
      <origin xyz="0 -0.28 0.05" rpy="0 0 0" />
      <geometry>
        <box size="2.5 0.56 0.1" />
        </geometry>
      <material name="painted_steel">
        <color rgba="0.27 0.29 0.31 1" />
        </material>
      </visual>
    <visual>
      <origin xyz="0 -0.02 0.12" rpy="0 0 0" />
      <geometry>
        <box size="2.44 0.08 0.12" />
        </geometry>
      <material name="painted_steel">
        <color rgba="0.27 0.29 0.31 1" />
        </material>
      </visual>
    <visual>
      <origin xyz="1.16 -0.08 0.12" rpy="0 0 0" />
      <geometry>
        <box size="0.14 0.18 0.24" />
        </geometry>
      <material name="painted_steel">
        <color rgba="0.27 0.29 0.31 1" />
        </material>
      </visual>
    <visual>
      <origin xyz="-1.16 -0.08 0.12" rpy="0 0 0" />
      <geometry>
        <box size="0.14 0.18 0.24" />
        </geometry>
      <material name="painted_steel">
        <color rgba="0.27 0.29 0.31 1" />
        </material>
      </visual>
    <visual>
      <origin xyz="0.84 -0.02 0.2" rpy="0 0 0" />
      <geometry>
        <box size="0.2 0.1 0.12" />
        </geometry>
      <material name="painted_steel">
        <color rgba="0.27 0.29 0.31 1" />
        </material>
      </visual>
    <visual>
      <origin xyz="-0.84 -0.02 0.2" rpy="0 0 0" />
      <geometry>
        <box size="0.2 0.1 0.12" />
        </geometry>
      <material name="painted_steel">
        <color rgba="0.27 0.29 0.31 1" />
        </material>
      </visual>
    <visual>
      <origin xyz="0 -0.22 0.14" rpy="0 0 0" />
      <geometry>
        <box size="1.86 0.16 0.16" />
        </geometry>
      <material name="painted_steel">
        <color rgba="0.27 0.29 0.31 1" />
        </material>
      </visual>
    <visual>
      <origin xyz="0.82 -0.12 0.055" rpy="0 0 0" />
      <geometry>
        <box size="0.18 0.22 0.11" />
        </geometry>
      <material name="painted_steel">
        <color rgba="0.27 0.29 0.31 1" />
        </material>
      </visual>
    <visual>
      <origin xyz="-0.82 -0.12 0.055" rpy="0 0 0" />
      <geometry>
        <box size="0.18 0.22 0.11" />
        </geometry>
      <material name="painted_steel">
        <color rgba="0.27 0.29 0.31 1" />
        </material>
      </visual>
    <visual>
      <origin xyz="-0.72 -0.3 0.19" rpy="0 0 0" />
      <geometry>
        <box size="0.42 0.24 0.18" />
        </geometry>
      <material name="painted_steel">
        <color rgba="0.27 0.29 0.31 1" />
        </material>
      </visual>
    <visual>
      <origin xyz="-0.48 -0.24 0.2" rpy="0 1.5708 0" />
      <geometry>
        <cylinder radius="0.055" length="0.3" />
        </geometry>
      <material name="brushed_steel">
        <color rgba="0.76 0.77 0.79 1" />
        </material>
      </visual>
    <visual>
      <origin xyz="0 -0.1 0.14" rpy="1.5708 0 0" />
      <geometry>
        <cylinder radius="0.06" length="0.28" />
        </geometry>
      <material name="painted_steel">
        <color rgba="0.27 0.29 0.31 1" />
        </material>
      </visual>
    <visual>
      <origin xyz="0 -0.22 0.13" rpy="0 0 0" />
      <geometry>
        <box size="0.18 0.1 0.16" />
        </geometry>
      <material name="painted_steel">
        <color rgba="0.27 0.29 0.31 1" />
        </material>
      </visual>
    <visual>
      <origin xyz="0.8 -0.52 0.14" rpy="0 0 0" />
      <geometry>
        <box size="0.18 0.12 0.28" />
        </geometry>
      <material name="rubber_black">
        <color rgba="0.08 0.08 0.09 1" />
        </material>
      </visual>
    <visual>
      <origin xyz="-0.8 -0.52 0.14" rpy="0 0 0" />
      <geometry>
        <box size="0.18 0.12 0.28" />
        </geometry>
      <material name="rubber_black">
        <color rgba="0.08 0.08 0.09 1" />
        </material>
      </visual>
    <collision name="base_frame__visual_1">
      <origin xyz="0 -0.28 0.05" rpy="0 0 0" />
      <geometry>
        <box size="2.5 0.56 0.1" />
        </geometry>
      </collision>
    <collision name="base_frame__visual_2">
      <origin xyz="0 -0.02 0.12" rpy="0 0 0" />
      <geometry>
        <box size="2.44 0.08 0.12" />
        </geometry>
      </collision>
    <collision name="base_frame__visual_3">
      <origin xyz="1.16 -0.08 0.12" rpy="0 0 0" />
      <geometry>
        <box size="0.14 0.18 0.24" />
        </geometry>
      </collision>
    <collision name="base_frame__visual_4">
      <origin xyz="-1.16 -0.08 0.12" rpy="0 0 0" />
      <geometry>
        <box size="0.14 0.18 0.24" />
        </geometry>
      </collision>
    <collision name="base_frame__visual_5">
      <origin xyz="0.84 -0.02 0.2" rpy="0 0 0" />
      <geometry>
        <box size="0.2 0.1 0.12" />
        </geometry>
      </collision>
    <collision name="base_frame__visual_6">
      <origin xyz="-0.84 -0.02 0.2" rpy="0 0 0" />
      <geometry>
        <box size="0.2 0.1 0.12" />
        </geometry>
      </collision>
    <collision name="base_frame__visual_7">
      <origin xyz="0 -0.22 0.14" rpy="0 0 0" />
      <geometry>
        <box size="1.86 0.16 0.16" />
        </geometry>
      </collision>
    <collision name="base_frame__visual_8">
      <origin xyz="0.82 -0.12 0.055" rpy="0 0 0" />
      <geometry>
        <box size="0.18 0.22 0.11" />
        </geometry>
      </collision>
    <collision name="base_frame__visual_9">
      <origin xyz="-0.82 -0.12 0.055" rpy="0 0 0" />
      <geometry>
        <box size="0.18 0.22 0.11" />
        </geometry>
      </collision>
    <collision name="base_frame__visual_10">
      <origin xyz="-0.72 -0.3 0.19" rpy="0 0 0" />
      <geometry>
        <box size="0.42 0.24 0.18" />
        </geometry>
      </collision>
    <collision name="base_frame__visual_11">
      <origin xyz="-0.48 -0.24 0.2" rpy="0 1.5708 0" />
      <geometry>
        <cylinder radius="0.055" length="0.3" />
        </geometry>
      </collision>
    <collision name="base_frame__visual_12">
      <origin xyz="0 -0.1 0.14" rpy="1.5708 0 0" />
      <geometry>
        <cylinder radius="0.06" length="0.28" />
        </geometry>
      </collision>
    <collision name="base_frame__visual_13">
      <origin xyz="0 -0.22 0.13" rpy="0 0 0" />
      <geometry>
        <box size="0.18 0.1 0.16" />
        </geometry>
      </collision>
    <collision name="base_frame__visual_14">
      <origin xyz="0.8 -0.52 0.14" rpy="0 0 0" />
      <geometry>
        <box size="0.18 0.12 0.28" />
        </geometry>
      </collision>
    <collision name="base_frame__visual_15">
      <origin xyz="-0.8 -0.52 0.14" rpy="0 0 0" />
      <geometry>
        <box size="0.18 0.12 0.28" />
        </geometry>
      </collision>
    </link>
  <link name="deck">
    <inertial>
      <origin xyz="0 1.05 0.025" rpy="0 0 0" />
      <mass value="1350" />
      <inertia ixx="459.326" ixy="0" ixz="0" iyy="595.406" iyz="0" izz="1054.17" />
      </inertial>
    <visual>
      <origin xyz="0 0.04 0.03" rpy="0 0 0" />
      <geometry>
        <box size="2.18 0.08 0.06" />
        </geometry>
      <material name="painted_steel">
        <color rgba="0.27 0.29 0.31 1" />
        </material>
      </visual>
    <visual>
      <origin xyz="0 1.05 0.025" rpy="0 0 0" />
      <geometry>
        <box size="2.3 2.02 0.05" />
        </geometry>
      <material name="painted_steel">
        <color rgba="0.27 0.29 0.31 1" />
        </material>
      </visual>
    <visual>
      <origin xyz="1.11 1.05 0.07" rpy="0 0 0" />
      <geometry>
        <box size="0.08 2.02 0.14" />
        </geometry>
      <material name="safety_yellow">
        <color rgba="0.89 0.74 0.16 1" />
        </material>
      </visual>
    <visual>
      <origin xyz="-1.11 1.05 0.07" rpy="0 0 0" />
      <geometry>
        <box size="0.08 2.02 0.14" />
        </geometry>
      <material name="safety_yellow">
        <color rgba="0.89 0.74 0.16 1" />
        </material>
      </visual>
    <visual>
      <origin xyz="0.62 1.01 -0.03" rpy="0 0 0" />
      <geometry>
        <box size="0.18 1.86 0.1" />
        </geometry>
      <material name="painted_steel">
        <color rgba="0.27 0.29 0.31 1" />
        </material>
      </visual>
    <visual>
      <origin xyz="-0.62 1.01 -0.03" rpy="0 0 0" />
      <geometry>
        <box size="0.18 1.86 0.1" />
        </geometry>
      <material name="painted_steel">
        <color rgba="0.27 0.29 0.31 1" />
        </material>
      </visual>
    <visual>
      <origin xyz="0 0.93 -0.04" rpy="0 0 0" />
      <geometry>
        <box size="0.22 1.68 0.12" />
        </geometry>
      <material name="painted_steel">
        <color rgba="0.27 0.29 0.31 1" />
        </material>
      </visual>
    <visual>
      <origin xyz="0 2.01 0.03" rpy="0 0 0" />
      <geometry>
        <box size="2.18 0.1 0.06" />
        </geometry>
      <material name="painted_steel">
        <color rgba="0.27 0.29 0.31 1" />
        </material>
      </visual>
    <visual>
      <origin xyz="0 2.04 0.055" rpy="0 0 0" />
      <geometry>
        <box size="2.18 0.06 0.03" />
        </geometry>
      <material name="safety_yellow">
        <color rgba="0.89 0.74 0.16 1" />
        </material>
      </visual>
    <visual>
      <origin xyz="-0.72 1.1 0.052" rpy="0 0 0" />
      <geometry>
        <box size="0.16 1.7 0.008" />
        </geometry>
      <material name="brushed_steel">
        <color rgba="0.76 0.77 0.79 1" />
        </material>
      </visual>
    <visual>
      <origin xyz="-0.36 1.1 0.052" rpy="0 0 0" />
      <geometry>
        <box size="0.16 1.7 0.008" />
        </geometry>
      <material name="brushed_steel">
        <color rgba="0.76 0.77 0.79 1" />
        </material>
      </visual>
    <visual>
      <origin xyz="0 1.1 0.052" rpy="0 0 0" />
      <geometry>
        <box size="0.16 1.7 0.008" />
        </geometry>
      <material name="brushed_steel">
        <color rgba="0.76 0.77 0.79 1" />
        </material>
      </visual>
    <visual>
      <origin xyz="0.36 1.1 0.052" rpy="0 0 0" />
      <geometry>
        <box size="0.16 1.7 0.008" />
        </geometry>
      <material name="brushed_steel">
        <color rgba="0.76 0.77 0.79 1" />
        </material>
      </visual>
    <visual>
      <origin xyz="0.72 1.1 0.052" rpy="0 0 0" />
      <geometry>
        <box size="0.16 1.7 0.008" />
        </geometry>
      <material name="brushed_steel">
        <color rgba="0.76 0.77 0.79 1" />
        </material>
      </visual>
    <visual>
      <origin xyz="0 0.22 -0.06" rpy="1.5708 0 0" />
      <geometry>
        <cylinder radius="0.035" length="0.34" />
        </geometry>
      <material name="brushed_steel">
        <color rgba="0.76 0.77 0.79 1" />
        </material>
      </visual>
    <collision name="deck__visual_1">
      <origin xyz="0 0.04 0.03" rpy="0 0 0" />
      <geometry>
        <box size="2.18 0.08 0.06" />
        </geometry>
      </collision>
    <collision name="deck__visual_2">
      <origin xyz="0 1.05 0.025" rpy="0 0 0" />
      <geometry>
        <box size="2.3 2.02 0.05" />
        </geometry>
      </collision>
    <collision name="deck__visual_3">
      <origin xyz="1.11 1.05 0.07" rpy="0 0 0" />
      <geometry>
        <box size="0.08 2.02 0.14" />
        </geometry>
      </collision>
    <collision name="deck__visual_4">
      <origin xyz="-1.11 1.05 0.07" rpy="0 0 0" />
      <geometry>
        <box size="0.08 2.02 0.14" />
        </geometry>
      </collision>
    <collision name="deck__visual_5">
      <origin xyz="0.62 1.01 -0.03" rpy="0 0 0" />
      <geometry>
        <box size="0.18 1.86 0.1" />
        </geometry>
      </collision>
    <collision name="deck__visual_6">
      <origin xyz="-0.62 1.01 -0.03" rpy="0 0 0" />
      <geometry>
        <box size="0.18 1.86 0.1" />
        </geometry>
      </collision>
    <collision name="deck__visual_7">
      <origin xyz="0 0.93 -0.04" rpy="0 0 0" />
      <geometry>
        <box size="0.22 1.68 0.12" />
        </geometry>
      </collision>
    <collision name="deck__visual_8">
      <origin xyz="0 2.01 0.03" rpy="0 0 0" />
      <geometry>
        <box size="2.18 0.1 0.06" />
        </geometry>
      </collision>
    <collision name="deck__visual_9">
      <origin xyz="0 2.04 0.055" rpy="0 0 0" />
      <geometry>
        <box size="2.18 0.06 0.03" />
        </geometry>
      </collision>
    <collision name="deck__visual_10">
      <origin xyz="-0.72 1.1 0.052" rpy="0 0 0" />
      <geometry>
        <box size="0.16 1.7 0.008" />
        </geometry>
      </collision>
    <collision name="deck__visual_11">
      <origin xyz="-0.36 1.1 0.052" rpy="0 0 0" />
      <geometry>
        <box size="0.16 1.7 0.008" />
        </geometry>
      </collision>
    <collision name="deck__visual_12">
      <origin xyz="0 1.1 0.052" rpy="0 0 0" />
      <geometry>
        <box size="0.16 1.7 0.008" />
        </geometry>
      </collision>
    <collision name="deck__visual_13">
      <origin xyz="0.36 1.1 0.052" rpy="0 0 0" />
      <geometry>
        <box size="0.16 1.7 0.008" />
        </geometry>
      </collision>
    <collision name="deck__visual_14">
      <origin xyz="0.72 1.1 0.052" rpy="0 0 0" />
      <geometry>
        <box size="0.16 1.7 0.008" />
        </geometry>
      </collision>
    <collision name="deck__visual_15">
      <origin xyz="0 0.22 -0.06" rpy="1.5708 0 0" />
      <geometry>
        <cylinder radius="0.035" length="0.34" />
        </geometry>
      </collision>
    </link>
  <link name="lip">
    <inertial>
      <origin xyz="0 0.21 -0.0175" rpy="0 0 0" />
      <mass value="220" />
      <inertia ixx="3.25646" ixy="0" ixz="0" iyy="87.1498" iyz="0" izz="90.3613" />
      </inertial>
    <visual>
      <origin xyz="0 0.02 -0.005" rpy="0 0 0" />
      <geometry>
        <box size="2.1 0.08 0.03" />
        </geometry>
      <material name="painted_steel">
        <color rgba="0.27 0.29 0.31 1" />
        </material>
      </visual>
    <visual>
      <origin xyz="0 0.21 -0.0175" rpy="0 0 0" />
      <geometry>
        <box size="2.18 0.42 0.035" />
        </geometry>
      <material name="safety_yellow">
        <color rgba="0.89 0.74 0.16 1" />
        </material>
      </visual>
    <visual>
      <origin xyz="1 0.09 -0.03" rpy="0 0 0" />
      <geometry>
        <box size="0.1 0.18 0.1" />
        </geometry>
      <material name="painted_steel">
        <color rgba="0.27 0.29 0.31 1" />
        </material>
      </visual>
    <visual>
      <origin xyz="-1 0.09 -0.03" rpy="0 0 0" />
      <geometry>
        <box size="0.1 0.18 0.1" />
        </geometry>
      <material name="painted_steel">
        <color rgba="0.27 0.29 0.31 1" />
        </material>
      </visual>
    <visual>
      <origin xyz="0 0.39 -0.0375" rpy="0 0 0" />
      <geometry>
        <box size="2.18 0.06 0.015" />
        </geometry>
      <material name="brushed_steel">
        <color rgba="0.76 0.77 0.79 1" />
        </material>
      </visual>
    <visual>
      <origin xyz="-0.6 0.23 0.004" rpy="0 0 0" />
      <geometry>
        <box size="0.26 0.22 0.01" />
        </geometry>
      <material name="brushed_steel">
        <color rgba="0.76 0.77 0.79 1" />
        </material>
      </visual>
    <visual>
      <origin xyz="0 0.23 0.004" rpy="0 0 0" />
      <geometry>
        <box size="0.26 0.22 0.01" />
        </geometry>
      <material name="brushed_steel">
        <color rgba="0.76 0.77 0.79 1" />
        </material>
      </visual>
    <visual>
      <origin xyz="0.6 0.23 0.004" rpy="0 0 0" />
      <geometry>
        <box size="0.26 0.22 0.01" />
        </geometry>
      <material name="brushed_steel">
        <color rgba="0.76 0.77 0.79 1" />
        </material>
      </visual>
    <collision name="lip__visual_1">
      <origin xyz="0 0.02 -0.005" rpy="0 0 0" />
      <geometry>
        <box size="2.1 0.08 0.03" />
        </geometry>
      </collision>
    <collision name="lip__visual_2">
      <origin xyz="0 0.21 -0.0175" rpy="0 0 0" />
      <geometry>
        <box size="2.18 0.42 0.035" />
        </geometry>
      </collision>
    <collision name="lip__visual_3">
      <origin xyz="1 0.09 -0.03" rpy="0 0 0" />
      <geometry>
        <box size="0.1 0.18 0.1" />
        </geometry>
      </collision>
    <collision name="lip__visual_4">
      <origin xyz="-1 0.09 -0.03" rpy="0 0 0" />
      <geometry>
        <box size="0.1 0.18 0.1" />
        </geometry>
      </collision>
    <collision name="lip__visual_5">
      <origin xyz="0 0.39 -0.0375" rpy="0 0 0" />
      <geometry>
        <box size="2.18 0.06 0.015" />
        </geometry>
      </collision>
    <collision name="lip__visual_6">
      <origin xyz="-0.6 0.23 0.004" rpy="0 0 0" />
      <geometry>
        <box size="0.26 0.22 0.01" />
        </geometry>
      </collision>
    <collision name="lip__visual_7">
      <origin xyz="0 0.23 0.004" rpy="0 0 0" />
      <geometry>
        <box size="0.26 0.22 0.01" />
        </geometry>
      </collision>
    <collision name="lip__visual_8">
      <origin xyz="0.6 0.23 0.004" rpy="0 0 0" />
      <geometry>
        <box size="0.26 0.22 0.01" />
        </geometry>
      </collision>
    </link>
  <joint name="deck_hinge" type="revolute">
    <origin xyz="0 0 0.14" rpy="0 0 0" />
    <parent link="base_frame" />
    <child link="deck" />
    <axis xyz="1 0 0" />
    <limit effort="8000" velocity="0.5" lower="0" upper="0.52" />
    </joint>
  <joint name="lip_hinge" type="revolute">
    <origin xyz="0 2.04 0.05" rpy="0 0 0" />
    <parent link="deck" />
    <child link="lip" />
    <axis xyz="1 0 0" />
    <limit effort="4000" velocity="0.7" lower="-0.85" upper="0.1" />
    </joint>
  </robot>
