<robot name="rotary_trunnion_table">
  <material name="cast_iron">
    <color rgba="0.31 0.33 0.35 1" />
    </material>
  <material name="machine_gray">
    <color rgba="0.55 0.58 0.61 1" />
    </material>
  <material name="machined_steel">
    <color rgba="0.78 0.8 0.83 1" />
    </material>
  <material name="dark_oxide">
    <color rgba="0.18 0.19 0.21 1" />
    </material>
  <link name="base">
    <inertial>
      <origin xyz="0 0 0.15" rpy="0 0 0" />
      <mass value="38" />
      <inertia ixx="0.57" ixy="0" ixz="0" iyy="0.898067" iyz="0" izz="0.898067" />
      </inertial>
    <visual>
      <origin xyz="0 0 0.03" rpy="0 0 0" />
      <geometry>
        <box size="0.44 0.3 0.06" />
        </geometry>
      <material name="cast_iron" />
      </visual>
    <visual>
      <origin xyz="0 0 0.11" rpy="0 0 0" />
      <geometry>
        <box size="0.24 0.18 0.1" />
        </geometry>
      <material name="cast_iron" />
      </visual>
    <visual>
      <origin xyz="0 -0.03 0.165" rpy="0 0 0" />
      <geometry>
        <box size="0.3 0.16 0.05" />
        </geometry>
      <material name="machine_gray" />
      </visual>
    <visual>
      <origin xyz="-0.165 0 0.215" rpy="0 0 0" />
      <geometry>
        <box size="0.07 0.14 0.19" />
        </geometry>
      <material name="cast_iron" />
      </visual>
    <visual>
      <origin xyz="-0.21 0 0.305" rpy="0 1.5708 0" />
      <geometry>
        <cylinder radius="0.035" length="0.02" />
        </geometry>
      <material name="machined_steel" />
      </visual>
    <visual>
      <origin xyz="0.165 0 0.215" rpy="0 0 0" />
      <geometry>
        <box size="0.07 0.14 0.19" />
        </geometry>
      <material name="cast_iron" />
      </visual>
    <visual>
      <origin xyz="0.21 0 0.305" rpy="0 1.5708 0" />
      <geometry>
        <cylinder radius="0.035" length="0.02" />
        </geometry>
      <material name="machined_steel" />
      </visual>
    <visual>
      <origin xyz="0 -0.075 0.18" rpy="0 0 0" />
      <geometry>
        <box size="0.34 0.06 0.06" />
        </geometry>
      <material name="machine_gray" />
      </visual>
    <collision name="base__visual_1">
      <origin xyz="0 0 0.03" rpy="0 0 0" />
      <geometry>
        <box size="0.44 0.3 0.06" />
        </geometry>
      </collision>
    <collision name="base__visual_2">
      <origin xyz="0 0 0.11" rpy="0 0 0" />
      <geometry>
        <box size="0.24 0.18 0.1" />
        </geometry>
      </collision>
    <collision name="base__visual_3">
      <origin xyz="0 -0.03 0.165" rpy="0 0 0" />
      <geometry>
        <box size="0.3 0.16 0.05" />
        </geometry>
      </collision>
    <collision name="base__visual_4">
      <origin xyz="-0.165 0 0.215" rpy="0 0 0" />
      <geometry>
        <box size="0.07 0.14 0.19" />
        </geometry>
      </collision>
    <collision name="base__visual_5">
      <origin xyz="-0.21 0 0.305" rpy="0 1.5708 0" />
      <geometry>
        <cylinder radius="0.035" length="0.02" />
        </geometry>
      </collision>
    <collision name="base__visual_6">
      <origin xyz="0.165 0 0.215" rpy="0 0 0" />
      <geometry>
        <box size="0.07 0.14 0.19" />
        </geometry>
      </collision>
    <collision name="base__visual_7">
      <origin xyz="0.21 0 0.305" rpy="0 1.5708 0" />
      <geometry>
        <cylinder radius="0.035" length="0.02" />
        </geometry>
      </collision>
    <collision name="base__visual_8">
      <origin xyz="0 -0.075 0.18" rpy="0 0 0" />
      <geometry>
        <box size="0.34 0.06 0.06" />
        </geometry>
      </collision>
    </link>
  <link name="trunnion">
    <inertial>
      <origin xyz="0.13 -0.035 -0.05" rpy="0 0 0" />
      <mass value="14" />
      <inertia ixx="0.0396667" ixy="0" ixz="0" iyy="0.101733" iyz="0" izz="0.0956667" />
      </inertial>
    <visual>
      <origin xyz="0.13 0 -0.038" rpy="0 0 0" />
      <geometry>
        <cylinder radius="0.078" length="0.07" />
        </geometry>
      <material name="machine_gray" />
      </visual>
    <visual>
      <origin xyz="0.13 0 -0.003" rpy="0 0 0" />
      <geometry>
        <cylinder radius="0.055" length="0.006" />
        </geometry>
      <material name="machined_steel" />
      </visual>
    <visual>
      <origin xyz="0.05 -0.04 -0.055" rpy="0 0 0" />
      <geometry>
        <box size="0.07 0.08 0.09" />
        </geometry>
      <material name="machine_gray" />
      </visual>
    <visual>
      <origin xyz="0.21 -0.04 -0.055" rpy="0 0 0" />
      <geometry>
        <box size="0.07 0.08 0.09" />
        </geometry>
      <material name="machine_gray" />
      </visual>
    <visual>
      <origin xyz="0.13 -0.075 -0.05" rpy="0 0 0" />
      <geometry>
        <box size="0.18 0.035 0.1" />
        </geometry>
      <material name="machine_gray" />
      </visual>
    <visual>
      <origin xyz="0.13 -0.035 -0.1" rpy="0 0 0" />
      <geometry>
        <box size="0.11 0.09 0.04" />
        </geometry>
      <material name="dark_oxide" />
      </visual>
    <visual>
      <origin xyz="0.015 0 0" rpy="0 1.5708 0" />
      <geometry>
        <cylinder radius="0.03" length="0.03" />
        </geometry>
      <material name="machined_steel" />
      </visual>
    <visual>
      <origin xyz="0.245 0 0" rpy="0 1.5708 0" />
      <geometry>
        <cylinder radius="0.03" length="0.03" />
        </geometry>
      <material name="machined_steel" />
      </visual>
    <collision name="trunnion__visual_1">
      <origin xyz="0.13 0 -0.038" rpy="0 0 0" />
      <geometry>
        <cylinder radius="0.078" length="0.07" />
        </geometry>
      </collision>
    <collision name="trunnion__visual_2">
      <origin xyz="0.13 0 -0.003" rpy="0 0 0" />
      <geometry>
        <cylinder radius="0.055" length="0.006" />
        </geometry>
      </collision>
    <collision name="trunnion__visual_3">
      <origin xyz="0.05 -0.04 -0.055" rpy="0 0 0" />
      <geometry>
        <box size="0.07 0.08 0.09" />
        </geometry>
      </collision>
    <collision name="trunnion__visual_4">
      <origin xyz="0.21 -0.04 -0.055" rpy="0 0 0" />
      <geometry>
        <box size="0.07 0.08 0.09" />
        </geometry>
      </collision>
    <collision name="trunnion__visual_5">
      <origin xyz="0.13 -0.075 -0.05" rpy="0 0 0" />
      <geometry>
        <box size="0.18 0.035 0.1" />
        </geometry>
      </collision>
    <collision name="trunnion__visual_6">
      <origin xyz="0.13 -0.035 -0.1" rpy="0 0 0" />
      <geometry>
        <box size="0.11 0.09 0.04" />
        </geometry>
      </collision>
    <collision name="trunnion__visual_7">
      <origin xyz="0.015 0 0" rpy="0 1.5708 0" />
      <geometry>
        <cylinder radius="0.03" length="0.03" />
        </geometry>
      </collision>
    <collision name="trunnion__visual_8">
      <origin xyz="0.245 0 0" rpy="0 1.5708 0" />
      <geometry>
        <cylinder radius="0.03" length="0.03" />
        </geometry>
      </collision>
    </link>
  <link name="turntable">
    <inertial>
      <origin xyz="0 0 0.014" rpy="0 0 0" />
      <mass value="9.5" />
      <inertia ixx="0.0243707" ixy="0" ixz="0" iyy="0.0243707" iyz="0" izz="0.0475" />
      </inertial>
    <visual>
      <geometry>
        <mesh filename="meshes/turntable.obj" />
        </geometry>
      <material name="machined_steel" />
      </visual>
    <collision name="turntable__visual_1__hull_001">
      <geometry>
        <mesh filename="meshes/collision/cache/turntable__a47bfca1f58c369f__hull_001.obj" />
        </geometry>
      </collision>
    <collision name="turntable__visual_1__hull_002">
      <geometry>
        <mesh filename="meshes/collision/cache/turntable__a47bfca1f58c369f__hull_002.obj" />
        </geometry>
      </collision>
    <collision name="turntable__visual_1__hull_003">
      <geometry>
        <mesh filename="meshes/collision/cache/turntable__a47bfca1f58c369f__hull_003.obj" />
        </geometry>
      </collision>
    <collision name="turntable__visual_1__hull_004">
      <geometry>
        <mesh filename="meshes/collision/cache/turntable__a47bfca1f58c369f__hull_004.obj" />
        </geometry>
      </collision>
    <collision name="turntable__visual_1__hull_005">
      <geometry>
        <mesh filename="meshes/collision/cache/turntable__a47bfca1f58c369f__hull_005.obj" />
        </geometry>
      </collision>
    <collision name="turntable__visual_1__hull_006">
      <geometry>
        <mesh filename="meshes/collision/cache/turntable__a47bfca1f58c369f__hull_006.obj" />
        </geometry>
      </collision>
    <collision name="turntable__visual_1__hull_007">
      <geometry>
        <mesh filename="meshes/collision/cache/turntable__a47bfca1f58c369f__hull_007.obj" />
        </geometry>
      </collision>
    <collision name="turntable__visual_1__hull_008">
      <geometry>
        <mesh filename="meshes/collision/cache/turntable__a47bfca1f58c369f__hull_008.obj" />
        </geometry>
      </collision>
    <collision name="turntable__visual_1__hull_009">
      <geometry>
        <mesh filename="meshes/collision/cache/turntable__a47bfca1f58c369f__hull_009.obj" />
        </geometry>
      </collision>
    <collision name="turntable__visual_1__hull_010">
      <geometry>
        <mesh filename="meshes/collision/cache/turntable__a47bfca1f58c369f__hull_010.obj" />
        </geometry>
      </collision>
    <collision name="turntable__visual_1__hull_011">
      <geometry>
        <mesh filename="meshes/collision/cache/turntable__a47bfca1f58c369f__hull_011.obj" />
        </geometry>
      </collision>
    </link>
  <joint name="trunnion_tilt" type="revolute">
    <origin xyz="-0.13 0 0.305" rpy="0 0 0" />
    <parent link="base" />
    <child link="trunnion" />
    <axis xyz="1 0 0" />
    <limit effort="120" velocity="0.9" lower="-0.35" upper="1.35" />
    </joint>
  <joint name="table_spin" type="continuous">
    <origin xyz="0.13 0 0" rpy="0 0 0" />
    <parent link="trunnion" />
    <child link="turntable" />
    <axis xyz="0 0 1" />
    <limit effort="60" velocity="3" />
    </joint>
  </robot>
