<robot name="swing_top_bottle">
  <material name="glass">
    <color rgba="0.55 0.71 0.62 0.34" />
    </material>
  <material name="amber_liquid">
    <color rgba="0.63 0.34 0.09 0.58" />
    </material>
  <material name="steel">
    <color rgba="0.67 0.68 0.71 1" />
    </material>
  <material name="ceramic">
    <color rgba="0.95 0.94 0.9 1" />
    </material>
  <material name="seal_rubber">
    <color rgba="0.72 0.25 0.1 1" />
    </material>
  <link name="bottle_body">
    <inertial>
      <origin xyz="0 0 0.14" rpy="0 0 0" />
      <mass value="0.85" />
      <inertia ixx="0.00586018" ixy="0" ixz="0" iyy="0.00586018" iyz="0" izz="0.0006137" />
      </inertial>
    <visual>
      <geometry>
        <mesh filename="assets/meshes/bottle_body.obj" />
        </geometry>
      <material name="glass">
        <color rgba="0.55 0.71 0.62 0.34" />
        </material>
      </visual>
    <visual name="neck_collar">
      <origin xyz="0 0 0.255" rpy="0 0 0" />
      <geometry>
        <cylinder radius="0.02" length="0.006" />
        </geometry>
      <material name="glass">
        <color rgba="0.55 0.71 0.62 0.34" />
        </material>
      </visual>
    <visual name="lip_ring">
      <origin xyz="0 0 0.272" rpy="0 0 0" />
      <geometry>
        <cylinder radius="0.019" length="0.008" />
        </geometry>
      <material name="glass">
        <color rgba="0.55 0.71 0.62 0.34" />
        </material>
      </visual>
    <visual name="left_lug">
      <origin xyz="-0.026 0 0.206" rpy="0 1.5708 0" />
      <geometry>
        <cylinder radius="0.004" length="0.01" />
        </geometry>
      <material name="glass">
        <color rgba="0.55 0.71 0.62 0.34" />
        </material>
      </visual>
    <visual name="left_lug_tip">
      <origin xyz="-0.031 0 0.206" rpy="0 0 0" />
      <geometry>
        <sphere radius="0.0044" />
        </geometry>
      <material name="glass">
        <color rgba="0.55 0.71 0.62 0.34" />
        </material>
      </visual>
    <visual name="right_lug">
      <origin xyz="0.026 0 0.206" rpy="0 1.5708 0" />
      <geometry>
        <cylinder radius="0.004" length="0.01" />
        </geometry>
      <material name="glass">
        <color rgba="0.55 0.71 0.62 0.34" />
        </material>
      </visual>
    <visual name="right_lug_tip">
      <origin xyz="0.031 0 0.206" rpy="0 0 0" />
      <geometry>
        <sphere radius="0.0044" />
        </geometry>
      <material name="glass">
        <color rgba="0.55 0.71 0.62 0.34" />
        </material>
      </visual>
    </link>
  <link name="liquid">
    <inertial>
      <origin xyz="-0.03 0 -0.05" rpy="0 0 0" />
      <mass value="0.45" />
      <inertia ixx="0.00159461" ixy="0" ixz="0" iyy="0.00159461" iyz="0" izz="0.000308025" />
      </inertial>
    <visual>
      <origin xyz="-0.03 0 -0.15" rpy="0 0 0" />
      <geometry>
        <mesh filename="assets/meshes/liquid.obj" />
        </geometry>
      <material name="amber_liquid">
        <color rgba="0.63 0.34 0.09 0.58" />
        </material>
      </visual>
    </link>
  <link name="wire_frame">
    <inertial>
      <origin xyz="0.026 0.001 0.037" rpy="0 0 0" />
      <mass value="0.06" />
      <inertia ixx="3.25e-05" ixy="0" ixz="0" iyy="4.09e-05" iyz="0" izz="1.864e-05" />
      </inertial>
    <visual>
      <geometry>
        <mesh filename="assets/meshes/left_outer_arm.obj" />
        </geometry>
      <material name="steel">
        <color rgba="0.67 0.68 0.71 1" />
        </material>
      </visual>
    <visual>
      <geometry>
        <mesh filename="assets/meshes/left_inner_arm.obj" />
        </geometry>
      <material name="steel">
        <color rgba="0.67 0.68 0.71 1" />
        </material>
      </visual>
    <visual>
      <geometry>
        <mesh filename="assets/meshes/right_outer_arm.obj" />
        </geometry>
      <material name="steel">
        <color rgba="0.67 0.68 0.71 1" />
        </material>
      </visual>
    <visual>
      <geometry>
        <mesh filename="assets/meshes/right_inner_arm.obj" />
        </geometry>
      <material name="steel">
        <color rgba="0.67 0.68 0.71 1" />
        </material>
      </visual>
    <visual>
      <geometry>
        <mesh filename="assets/meshes/rear_crown.obj" />
        </geometry>
      <material name="steel">
        <color rgba="0.67 0.68 0.71 1" />
        </material>
      </visual>
    <visual>
      <geometry>
        <mesh filename="assets/meshes/front_crossbar.obj" />
        </geometry>
      <material name="steel">
        <color rgba="0.67 0.68 0.71 1" />
        </material>
      </visual>
    </link>
  <link name="stopper">
    <inertial>
      <origin xyz="0.02 -0.009 0.006" rpy="0 0 0" />
      <mass value="0.1" />
      <inertia ixx="1.5e-05" ixy="0" ixz="0" iyy="2.08333e-05" iyz="0" izz="2.08333e-05" />
      </inertial>
    <visual>
      <origin xyz="0.02 -0.009 0.008" rpy="0 0 0" />
      <geometry>
        <mesh filename="assets/meshes/stopper_top.obj" />
        </geometry>
      <material name="ceramic">
        <color rgba="0.95 0.94 0.9 1" />
        </material>
      </visual>
    <visual name="gasket_ring">
      <origin xyz="0.02 -0.011 0.001" rpy="0 0 0" />
      <geometry>
        <cylinder radius="0.014" length="0.006" />
        </geometry>
      <material name="seal_rubber">
        <color rgba="0.72 0.25 0.1 1" />
        </material>
      </visual>
    <visual name="plug">
      <origin xyz="0.02 -0.011 -0.008" rpy="0 0 0" />
      <geometry>
        <cylinder radius="0.0115" length="0.02" />
        </geometry>
      <material name="seal_rubber">
        <color rgba="0.72 0.25 0.1 1" />
        </material>
      </visual>
    <visual name="hinge_pin">
      <origin xyz="0.02 0 0" rpy="0 1.5708 0" />
      <geometry>
        <cylinder radius="0.0025" length="0.04" />
        </geometry>
      <material name="steel">
        <color rgba="0.67 0.68 0.71 1" />
        </material>
      </visual>
    <visual name="left_ear">
      <geometry>
        <sphere radius="0.0042" />
        </geometry>
      <material name="ceramic">
        <color rgba="0.95 0.94 0.9 1" />
        </material>
      </visual>
    <visual name="right_ear">
      <origin xyz="0.04 0 0" rpy="0 0 0" />
      <geometry>
        <sphere radius="0.0042" />
        </geometry>
      <material name="ceramic">
        <color rgba="0.95 0.94 0.9 1" />
        </material>
      </visual>
    </link>
  <joint name="bottle_body_to_liquid" type="fixed">
    <origin xyz="0.03 0 0.15" rpy="0 0 0" />
    <parent link="bottle_body" />
    <child link="liquid" />
    </joint>
  <joint name="bottle_to_wire_frame" type="revolute">
    <origin xyz="-0.026 0 0.206" rpy="0 0 0" />
    <parent link="bottle_body" />
    <child link="wire_frame" />
    <axis xyz="1 0 0" />
    <limit effort="4" velocity="3" lower="0" upper="1.2" />
    </joint>
  <joint name="wire_frame_to_stopper" type="revolute">
    <origin xyz="0.006 0.012 0.07" rpy="0 0 0" />
    <parent link="wire_frame" />
    <child link="stopper" />
    <axis xyz="1 0 0" />
    <limit effort="2" velocity="3" lower="-1.1" upper="0.1" />
    </joint>
  </robot>
