<robot name="hard_shell_suitcase">
  <material name="polycarbonate_graphite">
    <color rgba="0.19 0.21 0.24 1" />
    </material>
  <material name="zipper_black">
    <color rgba="0.08 0.08 0.09 1" />
    </material>
  <material name="wheel_rubber">
    <color rgba="0.07 0.07 0.08 1" />
    </material>
  <material name="brushed_aluminum">
    <color rgba="0.73 0.75 0.78 1" />
    </material>
  <material name="black_plastic">
    <color rgba="0.12 0.12 0.13 1" />
    </material>
  <material name="hardware_steel">
    <color rgba="0.58 0.6 0.63 1" />
    </material>
  <link name="rear_shell">
    <inertial>
      <origin xyz="0 0 0.059" rpy="0 0 0" />
      <mass value="3.3" />
      <inertia ixx="0.127277" ixy="0" ixz="0" iyy="0.0546766" iyz="0" izz="0.174295" />
      </inertial>
    <visual>
      <geometry>
        <mesh filename="assets/meshes/rear_shell_body.obj" />
        </geometry>
      <material name="polycarbonate_graphite">
        <color rgba="0.19 0.21 0.24 1" />
        </material>
      </visual>
    <visual>
      <origin xyz="0 0 0.112" rpy="0 0 0" />
      <geometry>
        <mesh filename="assets/meshes/rear_seam_band.obj" />
        </geometry>
      <material name="zipper_black">
        <color rgba="0.08 0.08 0.09 1" />
        </material>
      </visual>
    <visual>
      <origin xyz="-0.115 -0.008 0.11" rpy="0 0 0" />
      <geometry>
        <box size="0.055 0.3484 0.01" />
        </geometry>
      <material name="polycarbonate_graphite">
        <color rgba="0.19 0.21 0.24 1" />
        </material>
      </visual>
    <visual>
      <origin xyz="0 -0.008 0.11" rpy="0 0 0" />
      <geometry>
        <box size="0.055 0.3484 0.01" />
        </geometry>
      <material name="polycarbonate_graphite">
        <color rgba="0.19 0.21 0.24 1" />
        </material>
      </visual>
    <visual>
      <origin xyz="0.115 -0.008 0.11" rpy="0 0 0" />
      <geometry>
        <box size="0.055 0.3484 0.01" />
        </geometry>
      <material name="polycarbonate_graphite">
        <color rgba="0.19 0.21 0.24 1" />
        </material>
      </visual>
    <visual>
      <origin xyz="-0.158 -0.294 0.025" rpy="0 0 0" />
      <geometry>
        <box size="0.06 0.082 0.05" />
        </geometry>
      <material name="black_plastic">
        <color rgba="0.12 0.12 0.13 1" />
        </material>
      </visual>
    <visual>
      <origin xyz="-0.158 -0.333 0.031" rpy="0 0 0" />
      <geometry>
        <box size="0.024 0.016 0.024" />
        </geometry>
      <material name="hardware_steel">
        <color rgba="0.58 0.6 0.63 1" />
        </material>
      </visual>
    <visual>
      <origin xyz="0.158 -0.294 0.025" rpy="0 0 0" />
      <geometry>
        <box size="0.06 0.082 0.05" />
        </geometry>
      <material name="black_plastic">
        <color rgba="0.12 0.12 0.13 1" />
        </material>
      </visual>
    <visual>
      <origin xyz="0.158 -0.333 0.031" rpy="0 0 0" />
      <geometry>
        <box size="0.024 0.016 0.024" />
        </geometry>
      <material name="hardware_steel">
        <color rgba="0.58 0.6 0.63 1" />
        </material>
      </visual>
    <visual>
      <origin xyz="0 0.322 0.103" rpy="0 0 0" />
      <geometry>
        <box size="0.058 0.022 0.03" />
        </geometry>
      <material name="black_plastic">
        <color rgba="0.12 0.12 0.13 1" />
        </material>
      </visual>
    <visual>
      <origin xyz="0 0.322 0.115" rpy="0 0 0" />
      <geometry>
        <box size="0.036 0.01 0.018" />
        </geometry>
      <material name="brushed_aluminum">
        <color rgba="0.73 0.75 0.78 1" />
        </material>
      </visual>
    <visual>
      <origin xyz="-0.13 -0.329 0.113" rpy="0 1.5708 0" />
      <geometry>
        <cylinder radius="0.006" length="0.072" />
        </geometry>
      <material name="hardware_steel">
        <color rgba="0.58 0.6 0.63 1" />
        </material>
      </visual>
    <visual>
      <origin xyz="0.13 -0.329 0.113" rpy="0 1.5708 0" />
      <geometry>
        <cylinder radius="0.006" length="0.072" />
        </geometry>
      <material name="hardware_steel">
        <color rgba="0.58 0.6 0.63 1" />
        </material>
      </visual>
    <visual>
      <origin xyz="-0.075 -0.215 0.108" rpy="0 0 0" />
      <geometry>
        <box size="0.018 0.17 0.006" />
        </geometry>
      <material name="brushed_aluminum">
        <color rgba="0.73 0.75 0.78 1" />
        </material>
      </visual>
    <visual>
      <origin xyz="0.075 -0.215 0.108" rpy="0 0 0" />
      <geometry>
        <box size="0.018 0.17 0.006" />
        </geometry>
      <material name="brushed_aluminum">
        <color rgba="0.73 0.75 0.78 1" />
        </material>
      </visual>
    </link>
  <link name="front_shell">
    <inertial>
      <origin xyz="0 0.335 0.0515" rpy="0 0 0" />
      <mass value="2.5" />
      <inertia ixx="0.095731" ixy="0" ixz="0" iyy="0.040731" iyz="0" izz="0.132042" />
      </inertial>
    <visual>
      <geometry>
        <mesh filename="assets/meshes/front_shell_body.obj" />
        </geometry>
      <material name="polycarbonate_graphite">
        <color rgba="0.19 0.21 0.24 1" />
        </material>
      </visual>
    <visual>
      <origin xyz="0 0.335 -0.004" rpy="0 0 0" />
      <geometry>
        <mesh filename="assets/meshes/front_gasket_band.obj" />
        </geometry>
      <material name="zipper_black">
        <color rgba="0.08 0.08 0.09 1" />
        </material>
      </visual>
    <visual>
      <origin xyz="-0.105 0.3752 0.097" rpy="0 0 0" />
      <geometry>
        <box size="0.05 0.3149 0.009" />
        </geometry>
      <material name="polycarbonate_graphite">
        <color rgba="0.19 0.21 0.24 1" />
        </material>
      </visual>
    <visual>
      <origin xyz="0 0.3752 0.097" rpy="0 0 0" />
      <geometry>
        <box size="0.05 0.3149 0.009" />
        </geometry>
      <material name="polycarbonate_graphite">
        <color rgba="0.19 0.21 0.24 1" />
        </material>
      </visual>
    <visual>
      <origin xyz="0.105 0.3752 0.097" rpy="0 0 0" />
      <geometry>
        <box size="0.05 0.3149 0.009" />
        </geometry>
      <material name="polycarbonate_graphite">
        <color rgba="0.19 0.21 0.24 1" />
        </material>
      </visual>
    <visual>
      <origin xyz="0 0.656 -0.003" rpy="0 0 0" />
      <geometry>
        <box size="0.046 0.016 0.012" />
        </geometry>
      <material name="brushed_aluminum">
        <color rgba="0.73 0.75 0.78 1" />
        </material>
      </visual>
    <visual>
      <origin xyz="-0.13 0.006 -0.0035" rpy="0 1.5708 0" />
      <geometry>
        <cylinder radius="0.0055" length="0.068" />
        </geometry>
      <material name="hardware_steel">
        <color rgba="0.58 0.6 0.63 1" />
        </material>
      </visual>
    <visual>
      <origin xyz="0.13 0.006 -0.0035" rpy="0 1.5708 0" />
      <geometry>
        <cylinder radius="0.0055" length="0.068" />
        </geometry>
      <material name="hardware_steel">
        <color rgba="0.58 0.6 0.63 1" />
        </material>
      </visual>
    <visual>
      <origin xyz="-0.0875 0.3752 0.099" rpy="0 0 0" />
      <geometry>
        <box size="0.028 0.018 0.012" />
        </geometry>
      <material name="black_plastic">
        <color rgba="0.12 0.12 0.13 1" />
        </material>
      </visual>
    <visual>
      <origin xyz="0.0875 0.3752 0.099" rpy="0 0 0" />
      <geometry>
        <box size="0.028 0.018 0.012" />
        </geometry>
      <material name="black_plastic">
        <color rgba="0.12 0.12 0.13 1" />
        </material>
      </visual>
    </link>
  <link name="carry_handle">
    <inertial>
      <origin xyz="0.0875 0.016 0.008" rpy="0 0 0" />
      <mass value="0.28" />
      <inertia ixx="4.43567e-05" ixy="0" ixz="0" iyy="0.000730357" iyz="0" izz="0.000743167" />
      </inertial>
    <visual>
      <geometry>
        <mesh filename="assets/meshes/carry_handle_arch.obj" />
        </geometry>
      <material name="black_plastic">
        <color rgba="0.12 0.12 0.13 1" />
        </material>
      </visual>
    <visual>
      <origin xyz="0.0875 0.019 0.007" rpy="0 0 0" />
      <geometry>
        <box size="0.105 0.022 0.012" />
        </geometry>
      <material name="brushed_aluminum">
        <color rgba="0.73 0.75 0.78 1" />
        </material>
      </visual>
    </link>
  <link name="left_wheel">
    <inertial>
      <mass value="0.18" />
      <inertia ixx="0.00015552" ixy="0" ixz="0" iyy="8.79e-05" iyz="0" izz="8.79e-05" />
      </inertial>
    <visual>
      <origin xyz="0 0 0" rpy="0 1.5708 0" />
      <geometry>
        <cylinder radius="0.036" length="0.026" />
        </geometry>
      <material name="wheel_rubber">
        <color rgba="0.07 0.07 0.08 1" />
        </material>
      </visual>
    <visual>
      <origin xyz="0 0 0" rpy="0 1.5708 0" />
      <geometry>
        <cylinder radius="0.018" length="0.028" />
        </geometry>
      <material name="brushed_aluminum">
        <color rgba="0.73 0.75 0.78 1" />
        </material>
      </visual>
    </link>
  <link name="right_wheel">
    <inertial>
      <mass value="0.18" />
      <inertia ixx="0.00015552" ixy="0" ixz="0" iyy="8.79e-05" iyz="0" izz="8.79e-05" />
      </inertial>
    <visual>
      <origin xyz="0 0 0" rpy="0 1.5708 0" />
      <geometry>
        <cylinder radius="0.036" length="0.026" />
        </geometry>
      <material name="wheel_rubber">
        <color rgba="0.07 0.07 0.08 1" />
        </material>
      </visual>
    <visual>
      <origin xyz="0 0 0" rpy="0 1.5708 0" />
      <geometry>
        <cylinder radius="0.018" length="0.028" />
        </geometry>
      <material name="brushed_aluminum">
        <color rgba="0.73 0.75 0.78 1" />
        </material>
      </visual>
    </link>
  <joint name="shell_hinge" type="revolute">
    <origin xyz="0 -0.335 0.118" rpy="0 0 0" />
    <parent link="rear_shell" />
    <child link="front_shell" />
    <axis xyz="1 0 0" />
    <limit effort="25" velocity="1.8" lower="0" upper="1.55" />
    </joint>
  <joint name="carry_handle_hinge" type="revolute">
    <origin xyz="-0.0875 0.3752 0.102" rpy="0 0 0" />
    <parent link="front_shell" />
    <child link="carry_handle" />
    <axis xyz="1 0 0" />
    <limit effort="6" velocity="4" lower="0" upper="1.2" />
    </joint>
  <joint name="left_wheel_spin" type="continuous">
    <origin xyz="-0.158 -0.333 0.031" rpy="0 0 0" />
    <parent link="rear_shell" />
    <child link="left_wheel" />
    <axis xyz="1 0 0" />
    <limit effort="3" velocity="18" />
    </joint>
  <joint name="right_wheel_spin" type="continuous">
    <origin xyz="0.158 -0.333 0.031" rpy="0 0 0" />
    <parent link="rear_shell" />
    <child link="right_wheel" />
    <axis xyz="1 0 0" />
    <limit effort="3" velocity="18" />
    </joint>
  </robot>
