<robot name="multi_finger_end_effector">
  <material name="palm_plate">
    <color rgba="0.6 0.64 0.68 1" />
  </material>
  <material name="finger_plate">
    <color rgba="0.16 0.17 0.2 1" />
  </material>
  <link name="palm">
    <inertial>
      <mass value="0.22" />
      <inertia ixx="0.000124447" ixy="0" ixz="0" iyy="4.70067e-05" iyz="0" izz="0.000169107" />
    </inertial>
    <visual>
      <geometry>
        <mesh filename="meshes/palm_plate.glb" />
      </geometry>
      <material name="palm_plate" />
    </visual>
    <collision>
      <geometry>
        <box size="0.05 0.082 0.008" />
      </geometry>
    </collision>
    <collision name="palm_tab_collision_0">
      <origin xyz="0.027 0.0285 0" rpy="0 0 0" />
      <geometry>
        <box size="0.007 0.01 0.008" />
      </geometry>
    </collision>
    <collision name="palm_tab_collision_1">
      <origin xyz="0.027 0.01 0" rpy="0 0 0" />
      <geometry>
        <box size="0.007 0.01 0.008" />
      </geometry>
    </collision>
    <collision name="palm_tab_collision_2">
      <origin xyz="0.027 -0.01 0" rpy="0 0 0" />
      <geometry>
        <box size="0.007 0.01 0.008" />
      </geometry>
    </collision>
    <collision name="palm_tab_collision_3">
      <origin xyz="0.027 -0.0285 0" rpy="0 0 0" />
      <geometry>
        <box size="0.007 0.01 0.008" />
      </geometry>
    </collision>
  </link>
  <link name="finger_top_outer">
    <inertial>
      <origin xyz="0.01725 0 0" rpy="0 0 0" />
      <mass value="0.028" />
      <inertia ixx="4.2e-07" ixy="0" ixz="0" iyy="5.12925e-06" iyz="0" izz="5.38125e-06" />
    </inertial>
    <visual>
      <geometry>
        <mesh filename="meshes/finger_plate.glb" />
      </geometry>
      <material name="finger_plate" />
    </visual>
    <collision name="finger_root_collision">
      <geometry>
        <box size="0.012 0.012 0.006" />
      </geometry>
    </collision>
    <collision name="finger_body_collision">
      <origin xyz="0.021 0 0" rpy="0 0 0" />
      <geometry>
        <box size="0.028 0.0065 0.006" />
      </geometry>
    </collision>
    <collision name="finger_tip_collision">
      <origin xyz="0.036 0 0" rpy="0 0 0" />
      <geometry>
        <box size="0.009 0.009 0.006" />
      </geometry>
    </collision>
  </link>
  <link name="finger_top_inner">
    <inertial>
      <origin xyz="0.01725 0 0" rpy="0 0 0" />
      <mass value="0.028" />
      <inertia ixx="4.2e-07" ixy="0" ixz="0" iyy="5.12925e-06" iyz="0" izz="5.38125e-06" />
    </inertial>
    <visual>
      <geometry>
        <mesh filename="meshes/finger_plate.glb" />
      </geometry>
      <material name="finger_plate" />
    </visual>
    <collision name="finger_root_collision">
      <geometry>
        <box size="0.012 0.012 0.006" />
      </geometry>
    </collision>
    <collision name="finger_body_collision">
      <origin xyz="0.021 0 0" rpy="0 0 0" />
      <geometry>
        <box size="0.028 0.0065 0.006" />
      </geometry>
    </collision>
    <collision name="finger_tip_collision">
      <origin xyz="0.036 0 0" rpy="0 0 0" />
      <geometry>
        <box size="0.009 0.009 0.006" />
      </geometry>
    </collision>
  </link>
  <link name="finger_bottom_inner">
    <inertial>
      <origin xyz="0.01725 0 0" rpy="0 0 0" />
      <mass value="0.028" />
      <inertia ixx="4.2e-07" ixy="0" ixz="0" iyy="5.12925e-06" iyz="0" izz="5.38125e-06" />
    </inertial>
    <visual>
      <geometry>
        <mesh filename="meshes/finger_plate.glb" />
      </geometry>
      <material name="finger_plate" />
    </visual>
    <collision name="finger_root_collision">
      <geometry>
        <box size="0.012 0.012 0.006" />
      </geometry>
    </collision>
    <collision name="finger_body_collision">
      <origin xyz="0.021 0 0" rpy="0 0 0" />
      <geometry>
        <box size="0.028 0.0065 0.006" />
      </geometry>
    </collision>
    <collision name="finger_tip_collision">
      <origin xyz="0.036 0 0" rpy="0 0 0" />
      <geometry>
        <box size="0.009 0.009 0.006" />
      </geometry>
    </collision>
  </link>
  <link name="finger_bottom_outer">
    <inertial>
      <origin xyz="0.01725 0 0" rpy="0 0 0" />
      <mass value="0.028" />
      <inertia ixx="4.2e-07" ixy="0" ixz="0" iyy="5.12925e-06" iyz="0" izz="5.38125e-06" />
    </inertial>
    <visual>
      <geometry>
        <mesh filename="meshes/finger_plate.glb" />
      </geometry>
      <material name="finger_plate" />
    </visual>
    <collision name="finger_root_collision">
      <geometry>
        <box size="0.012 0.012 0.006" />
      </geometry>
    </collision>
    <collision name="finger_body_collision">
      <origin xyz="0.021 0 0" rpy="0 0 0" />
      <geometry>
        <box size="0.028 0.0065 0.006" />
      </geometry>
    </collision>
    <collision name="finger_tip_collision">
      <origin xyz="0.036 0 0" rpy="0 0 0" />
      <geometry>
        <box size="0.009 0.009 0.006" />
      </geometry>
    </collision>
  </link>
  <joint name="palm_to_finger_top_outer" type="revolute">
    <origin xyz="0.0275 0.0285 0.0075" rpy="0 0 0.32" />
    <parent link="palm" />
    <child link="finger_top_outer" />
    <axis xyz="0 0 -1" />
    <limit effort="2" velocity="3" lower="0" upper="0.22" />
  </joint>
  <joint name="palm_to_finger_top_inner" type="revolute">
    <origin xyz="0.0275 0.01 0.0075" rpy="0 0 0.15" />
    <parent link="palm" />
    <child link="finger_top_inner" />
    <axis xyz="0 0 -1" />
    <limit effort="2" velocity="3" lower="0" upper="0.09" />
  </joint>
  <joint name="palm_to_finger_bottom_inner" type="revolute">
    <origin xyz="0.0275 -0.01 0.0075" rpy="0 0 -0.15" />
    <parent link="palm" />
    <child link="finger_bottom_inner" />
    <axis xyz="0 0 1" />
    <limit effort="2" velocity="3" lower="0" upper="0.09" />
  </joint>
  <joint name="palm_to_finger_bottom_outer" type="revolute">
    <origin xyz="0.0275 -0.0285 0.0075" rpy="0 0 -0.32" />
    <parent link="palm" />
    <child link="finger_bottom_outer" />
    <axis xyz="0 0 1" />
    <limit effort="2" velocity="3" lower="0" upper="0.22" />
  </joint>
</robot>