<robot name="adjustable_louver_bank">
  <material name="frame_powdercoat">
    <color rgba="0.18 0.19 0.22 1" />
  </material>
  <material name="blade_aluminum">
    <color rgba="0.73 0.76 0.79 1" />
  </material>
  <link name="frame">
    <inertial>
      <mass value="3.6" />
      <inertia ixx="0.07104" ixy="0" ixz="0" iyy="0.18444" iyz="0" izz="0.11724" />
    </inertial>
    <visual>
      <geometry>
        <mesh filename="meshes/frame.glb" />
      </geometry>
      <material name="frame_powdercoat" />
    </visual>
    <collision>
      <origin xyz="-0.2875 0 0" rpy="0 0 0" />
      <geometry>
        <box size="0.045 0.08 0.48" />
      </geometry>
    </collision>
    <collision>
      <origin xyz="0.2875 0 0" rpy="0 0 0" />
      <geometry>
        <box size="0.045 0.08 0.48" />
      </geometry>
    </collision>
    <collision>
      <origin xyz="0 0 0.215" rpy="0 0 0" />
      <geometry>
        <box size="0.53 0.08 0.05" />
      </geometry>
    </collision>
    <collision>
      <origin xyz="0 0 -0.215" rpy="0 0 0" />
      <geometry>
        <box size="0.53 0.08 0.05" />
      </geometry>
    </collision>
  </link>
  <link name="vane_1">
    <inertial>
      <origin xyz="0.265 0.005 -0.006" rpy="0 0 0" />
      <mass value="0.22" />
      <inertia ixx="6.19989e-05" ixy="0" ixz="0" iyy="0.00480715" iyz="0" izz="0.0048668" />
    </inertial>
    <visual>
      <geometry>
        <mesh filename="meshes/vane_1.glb" />
      </geometry>
      <material name="blade_aluminum" />
    </visual>
    <collision>
      <origin xyz="0.265 0 0" rpy="0 1.5708 0" />
      <geometry>
        <cylinder radius="0.00475" length="0.53" />
      </geometry>
    </collision>
    <collision>
      <origin xyz="0.265 0.005 -0.006" rpy="0 0 0" />
      <geometry>
        <box size="0.512 0.0576 0.008" />
      </geometry>
    </collision>
  </link>
  <link name="vane_2">
    <inertial>
      <origin xyz="0.265 0.005 -0.006" rpy="0 0 0" />
      <mass value="0.23" />
      <inertia ixx="6.48171e-05" ixy="0" ixz="0" iyy="0.00502565" iyz="0" izz="0.00508802" />
    </inertial>
    <visual>
      <geometry>
        <mesh filename="meshes/vane_2.glb" />
      </geometry>
      <material name="blade_aluminum" />
    </visual>
    <collision>
      <origin xyz="0.265 0 0" rpy="0 1.5708 0" />
      <geometry>
        <cylinder radius="0.00475" length="0.53" />
      </geometry>
    </collision>
    <collision>
      <origin xyz="0.265 0.005 -0.006" rpy="0 0 0" />
      <geometry>
        <box size="0.512 0.0576 0.008" />
      </geometry>
    </collision>
  </link>
  <link name="vane_3">
    <inertial>
      <origin xyz="0.265 0.005 -0.006" rpy="0 0 0" />
      <mass value="0.24" />
      <inertia ixx="6.76352e-05" ixy="0" ixz="0" iyy="0.00524416" iyz="0" izz="0.00530924" />
    </inertial>
    <visual>
      <geometry>
        <mesh filename="meshes/vane_3.glb" />
      </geometry>
      <material name="blade_aluminum" />
    </visual>
    <collision>
      <origin xyz="0.265 0 0" rpy="0 1.5708 0" />
      <geometry>
        <cylinder radius="0.00475" length="0.53" />
      </geometry>
    </collision>
    <collision>
      <origin xyz="0.265 0.005 -0.006" rpy="0 0 0" />
      <geometry>
        <box size="0.512 0.0576 0.008" />
      </geometry>
    </collision>
  </link>
  <link name="vane_4">
    <inertial>
      <origin xyz="0.265 0.005 -0.006" rpy="0 0 0" />
      <mass value="0.25" />
      <inertia ixx="7.04533e-05" ixy="0" ixz="0" iyy="0.00546267" iyz="0" izz="0.00553045" />
    </inertial>
    <visual>
      <geometry>
        <mesh filename="meshes/vane_4.glb" />
      </geometry>
      <material name="blade_aluminum" />
    </visual>
    <collision>
      <origin xyz="0.265 0 0" rpy="0 1.5708 0" />
      <geometry>
        <cylinder radius="0.00475" length="0.53" />
      </geometry>
    </collision>
    <collision>
      <origin xyz="0.265 0.005 -0.006" rpy="0 0 0" />
      <geometry>
        <box size="0.512 0.0576 0.008" />
      </geometry>
    </collision>
  </link>
  <link name="vane_5">
    <inertial>
      <origin xyz="0.265 0.005 -0.006" rpy="0 0 0" />
      <mass value="0.26" />
      <inertia ixx="7.32715e-05" ixy="0" ixz="0" iyy="0.00568117" iyz="0" izz="0.00575167" />
    </inertial>
    <visual>
      <geometry>
        <mesh filename="meshes/vane_5.glb" />
      </geometry>
      <material name="blade_aluminum" />
    </visual>
    <collision>
      <origin xyz="0.265 0 0" rpy="0 1.5708 0" />
      <geometry>
        <cylinder radius="0.00475" length="0.53" />
      </geometry>
    </collision>
    <collision>
      <origin xyz="0.265 0.005 -0.006" rpy="0 0 0" />
      <geometry>
        <box size="0.512 0.0576 0.008" />
      </geometry>
    </collision>
  </link>
  <joint name="frame_to_vane_1" type="revolute">
    <origin xyz="-0.265 0 0.144" rpy="0 0 0" />
    <parent link="frame" />
    <child link="vane_1" />
    <axis xyz="1 0 0" />
    <limit effort="1.5" velocity="2.5" lower="-0.95" upper="0.95" />
  </joint>
  <joint name="frame_to_vane_2" type="revolute">
    <origin xyz="-0.265 0 0.072" rpy="0 0 0" />
    <parent link="frame" />
    <child link="vane_2" />
    <axis xyz="1 0 0" />
    <limit effort="1.5" velocity="2.5" lower="-0.95" upper="0.95" />
  </joint>
  <joint name="frame_to_vane_3" type="revolute">
    <origin xyz="-0.265 0 0" rpy="0 0 0" />
    <parent link="frame" />
    <child link="vane_3" />
    <axis xyz="1 0 0" />
    <limit effort="1.5" velocity="2.5" lower="-0.95" upper="0.95" />
  </joint>
  <joint name="frame_to_vane_4" type="revolute">
    <origin xyz="-0.265 0 -0.072" rpy="0 0 0" />
    <parent link="frame" />
    <child link="vane_4" />
    <axis xyz="1 0 0" />
    <limit effort="1.5" velocity="2.5" lower="-0.95" upper="0.95" />
  </joint>
  <joint name="frame_to_vane_5" type="revolute">
    <origin xyz="-0.265 0 -0.144" rpy="0 0 0" />
    <parent link="frame" />
    <child link="vane_5" />
    <axis xyz="1 0 0" />
    <limit effort="1.5" velocity="2.5" lower="-0.95" upper="0.95" />
  </joint>
</robot>