<robot name="glove_compartment_assembly">
  <material name="dashboard_plastic">
    <color rgba="0.15 0.16 0.17 1" />
    </material>
  <material name="soft_touch_trim">
    <color rgba="0.19 0.2 0.21 1" />
    </material>
  <material name="satin_trim">
    <color rgba="0.52 0.53 0.55 1" />
    </material>
  <material name="dark_rubber">
    <color rgba="0.06 0.06 0.07 1" />
    </material>
  <material name="liner_felt">
    <color rgba="0.1 0.1 0.11 1" />
    </material>
  <link name="dashboard_frame">
    <inertial>
      <origin xyz="0.166 0 0.005" rpy="0 0 0" />
      <mass value="0.55" />
      <inertia ixx="0.00202785" ixy="0" ixz="0" iyy="0.00741345" iyz="0" izz="0.0094281" />
      </inertial>
    <visual>
      <origin xyz="0.166 0 0.005" rpy="0 0 0" />
      <geometry>
        <mesh filename="assets/meshes/dashboard_bezel.obj" />
        </geometry>
      <material name="dashboard_plastic">
        <color rgba="0.15 0.16 0.17 1" />
        </material>
      </visual>
    <visual>
      <origin xyz="0.166 0 0.0095" rpy="0 0 0" />
      <geometry>
        <mesh filename="assets/meshes/bezel_trim.obj" />
        </geometry>
      <material name="satin_trim">
        <color rgba="0.52 0.53 0.55 1" />
        </material>
      </visual>
    </link>
  <link name="compartment_bin">
    <inertial>
      <origin xyz="0 0 -0.0825" rpy="0 0 0" />
      <mass value="1.4" />
      <inertia ixx="0.00871792" ixy="0" ixz="0" iyy="0.0224267" iyz="0" izz="0.0239988" />
      </inertial>
    <visual>
      <origin xyz="-0.1605 0 -0.09" rpy="0 0 0" />
      <geometry>
        <box size="0.011 0.136 0.17" />
        </geometry>
      <material name="soft_touch_trim">
        <color rgba="0.19 0.2 0.21 1" />
        </material>
      </visual>
    <visual>
      <origin xyz="0.1605 0 -0.09" rpy="0 0 0" />
      <geometry>
        <box size="0.011 0.136 0.17" />
        </geometry>
      <material name="soft_touch_trim">
        <color rgba="0.19 0.2 0.21 1" />
        </material>
      </visual>
    <visual>
      <origin xyz="0 0.074 -0.09" rpy="0 0 0" />
      <geometry>
        <box size="0.332 0.011 0.17" />
        </geometry>
      <material name="soft_touch_trim">
        <color rgba="0.19 0.2 0.21 1" />
        </material>
      </visual>
    <visual>
      <origin xyz="0 -0.072 -0.035" rpy="0 0 0" />
      <geometry>
        <box size="0.332 0.012 0.06" />
        </geometry>
      <material name="soft_touch_trim">
        <color rgba="0.19 0.2 0.21 1" />
        </material>
      </visual>
    <visual>
      <origin xyz="0 -0.058 -0.095" rpy="0 0 0" />
      <geometry>
        <box size="0.3 0.01 0.112" />
        </geometry>
      <material name="dashboard_plastic">
        <color rgba="0.15 0.16 0.17 1" />
        </material>
      </visual>
    <visual>
      <origin xyz="0 -0.002 -0.17" rpy="0 0 0" />
      <geometry>
        <box size="0.304 0.114 0.008" />
        </geometry>
      <material name="dashboard_plastic">
        <color rgba="0.15 0.16 0.17 1" />
        </material>
      </visual>
    <visual>
      <origin xyz="0 -0.066 -0.012" rpy="0 0 0" />
      <geometry>
        <box size="0.276 0.012 0.018" />
        </geometry>
      <material name="dashboard_plastic">
        <color rgba="0.15 0.16 0.17 1" />
        </material>
      </visual>
    <visual>
      <origin xyz="-0.136 -0.058 -0.014" rpy="0 0 0" />
      <geometry>
        <box size="0.026 0.024 0.022" />
        </geometry>
      <material name="dashboard_plastic">
        <color rgba="0.15 0.16 0.17 1" />
        </material>
      </visual>
    <visual>
      <origin xyz="0.136 -0.058 -0.014" rpy="0 0 0" />
      <geometry>
        <box size="0.026 0.024 0.022" />
        </geometry>
      <material name="dashboard_plastic">
        <color rgba="0.15 0.16 0.17 1" />
        </material>
      </visual>
    <visual>
      <origin xyz="0 -0.061 -0.094" rpy="0 0 0" />
      <geometry>
        <box size="0.286 0.002 0.108" />
        </geometry>
      <material name="liner_felt">
        <color rgba="0.1 0.1 0.11 1" />
        </material>
      </visual>
    <visual>
      <origin xyz="-0.142 0.062 -0.002" rpy="0 0 0" />
      <geometry>
        <box size="0.012 0.014 0.006" />
        </geometry>
      <material name="dark_rubber">
        <color rgba="0.06 0.06 0.07 1" />
        </material>
      </visual>
    <visual>
      <origin xyz="0.142 0.062 -0.002" rpy="0 0 0" />
      <geometry>
        <box size="0.012 0.014 0.006" />
        </geometry>
      <material name="dark_rubber">
        <color rgba="0.06 0.06 0.07 1" />
        </material>
      </visual>
    </link>
  <link name="glovebox_door">
    <inertial>
      <origin xyz="0 0.066 -0.003" rpy="0 0 0" />
      <mass value="0.7" />
      <inertia ixx="0.00103133" ixy="0" ixz="0" iyy="0.00606317" iyz="0" izz="0.00706463" />
      </inertial>
    <visual>
      <origin xyz="0 0.048 -0.0005" rpy="0 0 0" />
      <geometry>
        <mesh filename="assets/meshes/door_lower_panel.obj" />
        </geometry>
      <material name="dashboard_plastic">
        <color rgba="0.15 0.16 0.17 1" />
        </material>
      </visual>
    <visual>
      <origin xyz="0 0.123 -0.0003" rpy="0 0 0" />
      <geometry>
        <mesh filename="assets/meshes/door_upper_bridge.obj" />
        </geometry>
      <material name="dashboard_plastic">
        <color rgba="0.15 0.16 0.17 1" />
        </material>
      </visual>
    <visual>
      <origin xyz="-0.1055 0.104 -0.0005" rpy="0 0 0" />
      <geometry>
        <mesh filename="assets/meshes/door_shoulder_panel.obj" />
        </geometry>
      <material name="dashboard_plastic">
        <color rgba="0.15 0.16 0.17 1" />
        </material>
      </visual>
    <visual>
      <origin xyz="0.1055 0.104 -0.0005" rpy="0 0 0" />
      <geometry>
        <mesh filename="assets/meshes/door_shoulder_panel.obj" />
        </geometry>
      <material name="dashboard_plastic">
        <color rgba="0.15 0.16 0.17 1" />
        </material>
      </visual>
    <visual>
      <origin xyz="0 0.051 0.0015" rpy="0 0 0" />
      <geometry>
        <mesh filename="assets/meshes/door_applique.obj" />
        </geometry>
      <material name="soft_touch_trim">
        <color rgba="0.19 0.2 0.21 1" />
        </material>
      </visual>
    <visual>
      <origin xyz="0 0.105 -0.0035" rpy="0 0 0" />
      <geometry>
        <box size="0.086 0.024 0.003" />
        </geometry>
      <material name="dark_rubber">
        <color rgba="0.06 0.06 0.07 1" />
        </material>
      </visual>
    <visual>
      <origin xyz="-0.043 0.105 0.0005" rpy="0 0 0" />
      <geometry>
        <box size="0.004 0.028 0.008" />
        </geometry>
      <material name="dark_rubber">
        <color rgba="0.06 0.06 0.07 1" />
        </material>
      </visual>
    <visual>
      <origin xyz="0.043 0.105 0.0005" rpy="0 0 0" />
      <geometry>
        <box size="0.004 0.028 0.008" />
        </geometry>
      <material name="dark_rubber">
        <color rgba="0.06 0.06 0.07 1" />
        </material>
      </visual>
    <visual>
      <origin xyz="0 0.119 0.0005" rpy="0 0 0" />
      <geometry>
        <box size="0.086 0.004 0.008" />
        </geometry>
      <material name="dark_rubber">
        <color rgba="0.06 0.06 0.07 1" />
        </material>
      </visual>
    <visual>
      <origin xyz="0 0.091 0.0005" rpy="0 0 0" />
      <geometry>
        <box size="0.086 0.004 0.008" />
        </geometry>
      <material name="dark_rubber">
        <color rgba="0.06 0.06 0.07 1" />
        </material>
      </visual>
    <visual>
      <origin xyz="0 0.105 0.0025" rpy="0 0 0" />
      <geometry>
        <box size="0.074 0.012 0.0015" />
        </geometry>
      <material name="satin_trim">
        <color rgba="0.52 0.53 0.55 1" />
        </material>
      </visual>
    <visual>
      <origin xyz="0 0.105 -0.001" rpy="0 1.5708 0" />
      <geometry>
        <cylinder radius="0.003" length="0.05" />
        </geometry>
      <material name="satin_trim">
        <color rgba="0.52 0.53 0.55 1" />
        </material>
      </visual>
    <visual>
      <origin xyz="0 0.056 -0.0065" rpy="0 0 0" />
      <geometry>
        <box size="0.3 0.11 0.004" />
        </geometry>
      <material name="liner_felt">
        <color rgba="0.1 0.1 0.11 1" />
        </material>
      </visual>
    <visual>
      <origin xyz="0 0.117 -0.006" rpy="0 0 0" />
      <geometry>
        <box size="0.25 0.01 0.004" />
        </geometry>
      <material name="dashboard_plastic">
        <color rgba="0.15 0.16 0.17 1" />
        </material>
      </visual>
    <visual>
      <origin xyz="-0.146 0.056 -0.006" rpy="0 0 0" />
      <geometry>
        <box size="0.008 0.1 0.004" />
        </geometry>
      <material name="dashboard_plastic">
        <color rgba="0.15 0.16 0.17 1" />
        </material>
      </visual>
    <visual>
      <origin xyz="0.146 0.056 -0.006" rpy="0 0 0" />
      <geometry>
        <box size="0.008 0.1 0.004" />
        </geometry>
      <material name="dashboard_plastic">
        <color rgba="0.15 0.16 0.17 1" />
        </material>
      </visual>
    <visual>
      <origin xyz="0 0.004 -0.004" rpy="0 1.5708 0" />
      <geometry>
        <cylinder radius="0.005" length="0.262" />
        </geometry>
      <material name="dark_rubber">
        <color rgba="0.06 0.06 0.07 1" />
        </material>
      </visual>
    </link>
  <joint name="bin_to_frame" type="fixed">
    <origin xyz="-0.166 0 -0.005" rpy="0 0 0" />
    <parent link="compartment_bin" />
    <child link="dashboard_frame" />
    </joint>
  <joint name="door_hinge" type="revolute">
    <origin xyz="0 -0.066 -0.003" rpy="0 0 0" />
    <parent link="compartment_bin" />
    <child link="glovebox_door" />
    <axis xyz="1 0 0" />
    <limit effort="20" velocity="1.5" lower="0" upper="1.35" />
    </joint>
  </robot>
