<robot name="bench_manipulator">
  <material name="aluminum">
    <color rgba="0.76 0.78 0.8 1" />
  </material>
  <material name="bearing_dark">
    <color rgba="0.2 0.22 0.26 1" />
  </material>
  <material name="anodized_dark">
    <color rgba="0.28 0.3 0.34 1" />
  </material>
  <link name="bench_base">
    <inertial>
      <origin xyz="0 0 0.07" rpy="0 0 0" />
      <mass value="5" />
      <inertia ixx="0.0141667" ixy="0" ixz="0" iyy="0.0216667" iyz="0" izz="0.0195" />
    </inertial>
    <visual>
      <geometry>
        <mesh filename="meshes/bench_base.glb" />
      </geometry>
      <material name="aluminum" />
    </visual>
    <visual>
      <origin xyz="0 -0.024 0.153" rpy="-1.5708 0 0" />
      <geometry>
        <cylinder radius="0.024" length="0.008" />
      </geometry>
      <material name="bearing_dark" />
    </visual>
    <visual>
      <origin xyz="0 0.024 0.153" rpy="-1.5708 0 0" />
      <geometry>
        <cylinder radius="0.024" length="0.008" />
      </geometry>
      <material name="bearing_dark" />
    </visual>
    <collision>
      <origin xyz="0 0 0.009" rpy="0 0 0" />
      <geometry>
        <box size="0.18 0.12 0.018" />
      </geometry>
    </collision>
    <collision>
      <origin xyz="0 0 0.059" rpy="0 0 0" />
      <geometry>
        <box size="0.072 0.082 0.1" />
      </geometry>
    </collision>
    <collision>
      <origin xyz="0 0.028 0.141" rpy="0 0 0" />
      <geometry>
        <box size="0.03 0.012 0.072" />
      </geometry>
    </collision>
    <collision>
      <origin xyz="0 -0.028 0.141" rpy="0 0 0" />
      <geometry>
        <box size="0.03 0.012 0.072" />
      </geometry>
    </collision>
    <collision>
      <origin xyz="0 0 0.153" rpy="-1.5708 0 0" />
      <geometry>
        <cylinder radius="0.022" length="0.014" />
      </geometry>
    </collision>
  </link>
  <link name="upper_arm">
    <inertial>
      <origin xyz="0.085 0 0" rpy="0 0 0" />
      <mass value="0.9" />
      <inertia ixx="0.0003075" ixy="0" ixz="0" iyy="0.002355" iyz="0" izz="0.0022875" />
    </inertial>
    <visual>
      <geometry>
        <mesh filename="meshes/upper_arm.glb" />
      </geometry>
      <material name="aluminum" />
    </visual>
    <visual>
      <origin xyz="0.17 -0.022 0" rpy="-1.5708 0 0" />
      <geometry>
        <cylinder radius="0.022" length="0.006" />
      </geometry>
      <material name="bearing_dark" />
    </visual>
    <visual>
      <origin xyz="0.17 0.022 0" rpy="-1.5708 0 0" />
      <geometry>
        <cylinder radius="0.022" length="0.006" />
      </geometry>
      <material name="bearing_dark" />
    </visual>
    <collision>
      <origin xyz="0 0 0" rpy="-1.5708 0 0" />
      <geometry>
        <cylinder radius="0.024" length="0.038" />
      </geometry>
    </collision>
    <collision>
      <origin xyz="0.085 0 0" rpy="0 0 0" />
      <geometry>
        <box size="0.11 0.016 0.018" />
      </geometry>
    </collision>
    <collision>
      <origin xyz="0.17 0 0" rpy="-1.5708 0 0" />
      <geometry>
        <cylinder radius="0.021" length="0.038" />
      </geometry>
    </collision>
  </link>
  <link name="forearm">
    <inertial>
      <origin xyz="0.07 0 0" rpy="0 0 0" />
      <mass value="0.65" />
      <inertia ixx="0.000173333" ixy="0" ixz="0" iyy="0.00130542" iyz="0" izz="0.00130542" />
    </inertial>
    <visual>
      <geometry>
        <mesh filename="meshes/forearm.glb" />
      </geometry>
      <material name="aluminum" />
    </visual>
    <collision>
      <origin xyz="0 0 0" rpy="-1.5708 0 0" />
      <geometry>
        <cylinder radius="0.022" length="0.042" />
      </geometry>
    </collision>
    <collision>
      <origin xyz="0.045 0 0" rpy="0 0 0" />
      <geometry>
        <box size="0.09 0.018 0.026" />
      </geometry>
    </collision>
    <collision>
      <origin xyz="0.12 0 0.017" rpy="0 0 0" />
      <geometry>
        <box size="0.05 0.03 0.006" />
      </geometry>
    </collision>
    <collision>
      <origin xyz="0.12 0 -0.017" rpy="0 0 0" />
      <geometry>
        <box size="0.05 0.03 0.006" />
      </geometry>
    </collision>
    <collision>
      <origin xyz="0.12 0.012 0" rpy="0 0 0" />
      <geometry>
        <box size="0.05 0.006 0.028" />
      </geometry>
    </collision>
    <collision>
      <origin xyz="0.12 -0.012 0" rpy="0 0 0" />
      <geometry>
        <box size="0.05 0.006 0.028" />
      </geometry>
    </collision>
  </link>
  <link name="tool_slide">
    <inertial>
      <origin xyz="0.1 0 0" rpy="0 0 0" />
      <mass value="0.3" />
      <inertia ixx="8e-05" ixy="0" ixz="0" iyy="0.00104" iyz="0" izz="0.00104" />
    </inertial>
    <visual>
      <geometry>
        <mesh filename="meshes/tool_slide.glb" />
      </geometry>
      <material name="anodized_dark" />
    </visual>
    <collision>
      <origin xyz="0.015 0 0" rpy="0 0 0" />
      <geometry>
        <box size="0.03 0.016 0.026" />
      </geometry>
    </collision>
    <collision>
      <origin xyz="0.09 0 0" rpy="0 0 0" />
      <geometry>
        <box size="0.12 0.01 0.01" />
      </geometry>
    </collision>
    <collision>
      <origin xyz="0.165 0 0" rpy="0 0 0" />
      <geometry>
        <box size="0.04 0.016 0.02" />
      </geometry>
    </collision>
  </link>
  <joint name="shoulder_joint" type="revolute">
    <origin xyz="0 0 0.153" rpy="0 0 0" />
    <parent link="bench_base" />
    <child link="upper_arm" />
    <axis xyz="0 -1 0" />
    <limit effort="18" velocity="2.5" lower="0" upper="1.15" />
  </joint>
  <joint name="elbow_joint" type="revolute">
    <origin xyz="0.17 0 0" rpy="0 0 0" />
    <parent link="upper_arm" />
    <child link="forearm" />
    <axis xyz="0 -1 0" />
    <limit effort="12" velocity="2.8" lower="-0.45" upper="1.25" />
  </joint>
  <joint name="telescoping_slide" type="prismatic">
    <origin xyz="0.095 0 0" rpy="0 0 0" />
    <parent link="forearm" />
    <child link="tool_slide" />
    <axis xyz="1 0 0" />
    <limit effort="8" velocity="0.4" lower="0" upper="0.1" />
  </joint>
</robot>