<robot name="bench_vise">
  <material name="cast_iron_blue">
    <color rgba="0.23 0.3 0.37 1" />
    </material>
  <material name="machined_steel">
    <color rgba="0.72 0.74 0.76 1" />
    </material>
  <material name="hardened_jaw">
    <color rgba="0.32 0.34 0.36 1" />
    </material>
  <material name="oxide_black">
    <color rgba="0.09 0.09 0.1 1" />
    </material>
  <link name="base">
    <inertial>
      <origin xyz="0 0 0.03" rpy="0 0 0" />
      <mass value="11" />
      <inertia ixx="0.0267667" ixy="0" ixz="0" iyy="0.0652667" iyz="0" izz="0.0854333" />
      </inertial>
    <visual>
      <origin xyz="0 0 0.009" rpy="0 0 0" />
      <geometry>
        <mesh filename="assets/meshes/base_plate.obj" />
        </geometry>
      <material name="cast_iron_blue">
        <color rgba="0.23 0.3 0.37 1" />
        </material>
      </visual>
    <visual>
      <origin xyz="-0.02 0 0.027" rpy="0 0 0" />
      <geometry>
        <cylinder radius="0.06" length="0.014" />
        </geometry>
      <material name="cast_iron_blue">
        <color rgba="0.23 0.3 0.37 1" />
        </material>
      </visual>
    <visual>
      <origin xyz="-0.03 0 0.04" rpy="0 0 0" />
      <geometry>
        <box size="0.11 0.1 0.04" />
        </geometry>
      <material name="cast_iron_blue">
        <color rgba="0.23 0.3 0.37 1" />
        </material>
      </visual>
    <visual>
      <origin xyz="0.098 0.055 0.009" rpy="0 0 0" />
      <geometry>
        <cylinder radius="0.017" length="0.018" />
        </geometry>
      <material name="cast_iron_blue">
        <color rgba="0.23 0.3 0.37 1" />
        </material>
      </visual>
    <visual>
      <origin xyz="0.098 -0.055 0.009" rpy="0 0 0" />
      <geometry>
        <cylinder radius="0.017" length="0.018" />
        </geometry>
      <material name="cast_iron_blue">
        <color rgba="0.23 0.3 0.37 1" />
        </material>
      </visual>
    <visual>
      <origin xyz="-0.112 0.055 0.009" rpy="0 0 0" />
      <geometry>
        <cylinder radius="0.017" length="0.018" />
        </geometry>
      <material name="cast_iron_blue">
        <color rgba="0.23 0.3 0.37 1" />
        </material>
      </visual>
    <visual>
      <origin xyz="-0.112 -0.055 0.009" rpy="0 0 0" />
      <geometry>
        <cylinder radius="0.017" length="0.018" />
        </geometry>
      <material name="cast_iron_blue">
        <color rgba="0.23 0.3 0.37 1" />
        </material>
      </visual>
    </link>
  <link name="body">
    <inertial>
      <origin xyz="0.015 0 0.035" rpy="0 0 0" />
      <mass value="9" />
      <inertia ixx="0.01515" ixy="0" ixz="0" iyy="0.045375" iyz="0" izz="0.042375" />
      </inertial>
    <visual>
      <origin xyz="0 0 0.008" rpy="0 0 0" />
      <geometry>
        <box size="0.065 0.065 0.016" />
        </geometry>
      <material name="cast_iron_blue">
        <color rgba="0.23 0.3 0.37 1" />
        </material>
      </visual>
    <visual>
      <origin xyz="-0.005 0 0.02" rpy="0 0 0" />
      <geometry>
        <box size="0.09 0.06 0.04" />
        </geometry>
      <material name="cast_iron_blue">
        <color rgba="0.23 0.3 0.37 1" />
        </material>
      </visual>
    <visual>
      <origin xyz="0.04 0 0.045" rpy="0 0 0" />
      <geometry>
        <box size="0.18 0.07 0.03" />
        </geometry>
      <material name="cast_iron_blue">
        <color rgba="0.23 0.3 0.37 1" />
        </material>
      </visual>
    <visual>
      <origin xyz="0.04 0.029 0.015" rpy="0 0 0" />
      <geometry>
        <box size="0.18 0.012 0.03" />
        </geometry>
      <material name="cast_iron_blue">
        <color rgba="0.23 0.3 0.37 1" />
        </material>
      </visual>
    <visual>
      <origin xyz="0.04 -0.029 0.015" rpy="0 0 0" />
      <geometry>
        <box size="0.18 0.012 0.03" />
        </geometry>
      <material name="cast_iron_blue">
        <color rgba="0.23 0.3 0.37 1" />
        </material>
      </visual>
    <visual>
      <origin xyz="-0.064 0 0.025" rpy="0 0 0" />
      <geometry>
        <box size="0.028 0.078 0.09" />
        </geometry>
      <material name="cast_iron_blue">
        <color rgba="0.23 0.3 0.37 1" />
        </material>
      </visual>
    <visual>
      <origin xyz="-0.026 0 0.0675" rpy="0 0 0" />
      <geometry>
        <box size="0.065 0.08 0.015" />
        </geometry>
      <material name="machined_steel">
        <color rgba="0.72 0.74 0.76 1" />
        </material>
      </visual>
    <visual>
      <origin xyz="-0.047 0 0.022" rpy="0 0 0" />
      <geometry>
        <box size="0.006 0.068 0.038" />
        </geometry>
      <material name="hardened_jaw">
        <color rgba="0.32 0.34 0.36 1" />
        </material>
      </visual>
    <visual>
      <origin xyz="0.128 0 -0.005" rpy="0 1.5708 0" />
      <geometry>
        <cylinder radius="0.026" length="0.02" />
        </geometry>
      <material name="machined_steel">
        <color rgba="0.72 0.74 0.76 1" />
        </material>
      </visual>
    <visual>
      <origin xyz="0.095 0.031 0.004" rpy="0 -0.58 0" />
      <geometry>
        <box size="0.072 0.012 0.018" />
        </geometry>
      <material name="cast_iron_blue">
        <color rgba="0.23 0.3 0.37 1" />
        </material>
      </visual>
    <visual>
      <origin xyz="0.095 -0.031 0.004" rpy="0 -0.58 0" />
      <geometry>
        <box size="0.072 0.012 0.018" />
        </geometry>
      <material name="cast_iron_blue">
        <color rgba="0.23 0.3 0.37 1" />
        </material>
      </visual>
    <visual>
      <origin xyz="-0.02 0.039 0.013" rpy="0 0.58 0" />
      <geometry>
        <box size="0.078 0.012 0.036" />
        </geometry>
      <material name="cast_iron_blue">
        <color rgba="0.23 0.3 0.37 1" />
        </material>
      </visual>
    <visual>
      <origin xyz="-0.02 -0.039 0.013" rpy="0 0.58 0" />
      <geometry>
        <box size="0.078 0.012 0.036" />
        </geometry>
      <material name="cast_iron_blue">
        <color rgba="0.23 0.3 0.37 1" />
        </material>
      </visual>
    </link>
  <link name="sliding_jaw">
    <inertial>
      <origin xyz="0.01 0 0.018" rpy="0 0 0" />
      <mass value="5" />
      <inertia ixx="0.00754167" ixy="0" ixz="0" iyy="0.00754167" iyz="0" izz="0.00675" />
      </inertial>
    <visual>
      <origin xyz="-0.014 0.041 0.018" rpy="0 0 0" />
      <geometry>
        <box size="0.058 0.01 0.06" />
        </geometry>
      <material name="cast_iron_blue">
        <color rgba="0.23 0.3 0.37 1" />
        </material>
      </visual>
    <visual>
      <origin xyz="-0.014 -0.041 0.018" rpy="0 0 0" />
      <geometry>
        <box size="0.058 0.01 0.06" />
        </geometry>
      <material name="cast_iron_blue">
        <color rgba="0.23 0.3 0.37 1" />
        </material>
      </visual>
    <visual>
      <origin xyz="-0.014 0 0.054" rpy="0 0 0" />
      <geometry>
        <box size="0.058 0.094 0.012" />
        </geometry>
      <material name="cast_iron_blue">
        <color rgba="0.23 0.3 0.37 1" />
        </material>
      </visual>
    <visual>
      <origin xyz="0.025 0 0.013" rpy="0 0 0" />
      <geometry>
        <box size="0.03 0.082 0.09" />
        </geometry>
      <material name="cast_iron_blue">
        <color rgba="0.23 0.3 0.37 1" />
        </material>
      </visual>
    <visual>
      <origin xyz="0.018 0 -0.016" rpy="0 0 0" />
      <geometry>
        <box size="0.036 0.044 0.032" />
        </geometry>
      <material name="cast_iron_blue">
        <color rgba="0.23 0.3 0.37 1" />
        </material>
      </visual>
    <visual>
      <origin xyz="0.018 0 0.059" rpy="0 0 0" />
      <geometry>
        <box size="0.024 0.07 0.012" />
        </geometry>
      <material name="machined_steel">
        <color rgba="0.72 0.74 0.76 1" />
        </material>
      </visual>
    <visual>
      <origin xyz="0.013 0 0.01" rpy="0 0 0" />
      <geometry>
        <box size="0.006 0.068 0.038" />
        </geometry>
      <material name="hardened_jaw">
        <color rgba="0.32 0.34 0.36 1" />
        </material>
      </visual>
    </link>
  <link name="screw">
    <inertial>
      <origin xyz="-0.09 0 0" rpy="0 1.5708 0" />
      <mass value="1.8" />
      <inertia ixx="0.013905" ixy="0" ixz="0" iyy="0.013905" iyz="0" izz="0.00081" />
      </inertial>
    <visual>
      <origin xyz="-0.1175 0 0" rpy="0 1.5708 0" />
      <geometry>
        <cylinder radius="0.0105" length="0.235" />
        </geometry>
      <material name="machined_steel">
        <color rgba="0.72 0.74 0.76 1" />
        </material>
      </visual>
    <visual>
      <origin xyz="-0.2 0 0" rpy="0 1.5708 0" />
      <geometry>
        <cylinder radius="0.012" length="0.003" />
        </geometry>
      <material name="machined_steel">
        <color rgba="0.72 0.74 0.76 1" />
        </material>
      </visual>
    <visual>
      <origin xyz="-0.185 0 0" rpy="0 1.5708 0" />
      <geometry>
        <cylinder radius="0.012" length="0.003" />
        </geometry>
      <material name="machined_steel">
        <color rgba="0.72 0.74 0.76 1" />
        </material>
      </visual>
    <visual>
      <origin xyz="-0.17 0 0" rpy="0 1.5708 0" />
      <geometry>
        <cylinder radius="0.012" length="0.003" />
        </geometry>
      <material name="machined_steel">
        <color rgba="0.72 0.74 0.76 1" />
        </material>
      </visual>
    <visual>
      <origin xyz="-0.155 0 0" rpy="0 1.5708 0" />
      <geometry>
        <cylinder radius="0.012" length="0.003" />
        </geometry>
      <material name="machined_steel">
        <color rgba="0.72 0.74 0.76 1" />
        </material>
      </visual>
    <visual>
      <origin xyz="-0.14 0 0" rpy="0 1.5708 0" />
      <geometry>
        <cylinder radius="0.012" length="0.003" />
        </geometry>
      <material name="machined_steel">
        <color rgba="0.72 0.74 0.76 1" />
        </material>
      </visual>
    <visual>
      <origin xyz="-0.125 0 0" rpy="0 1.5708 0" />
      <geometry>
        <cylinder radius="0.012" length="0.003" />
        </geometry>
      <material name="machined_steel">
        <color rgba="0.72 0.74 0.76 1" />
        </material>
      </visual>
    <visual>
      <origin xyz="-0.11 0 0" rpy="0 1.5708 0" />
      <geometry>
        <cylinder radius="0.012" length="0.003" />
        </geometry>
      <material name="machined_steel">
        <color rgba="0.72 0.74 0.76 1" />
        </material>
      </visual>
    <visual>
      <origin xyz="-0.095 0 0" rpy="0 1.5708 0" />
      <geometry>
        <cylinder radius="0.012" length="0.003" />
        </geometry>
      <material name="machined_steel">
        <color rgba="0.72 0.74 0.76 1" />
        </material>
      </visual>
    <visual>
      <origin xyz="-0.08 0 0" rpy="0 1.5708 0" />
      <geometry>
        <cylinder radius="0.012" length="0.003" />
        </geometry>
      <material name="machined_steel">
        <color rgba="0.72 0.74 0.76 1" />
        </material>
      </visual>
    <visual>
      <origin xyz="-0.065 0 0" rpy="0 1.5708 0" />
      <geometry>
        <cylinder radius="0.012" length="0.003" />
        </geometry>
      <material name="machined_steel">
        <color rgba="0.72 0.74 0.76 1" />
        </material>
      </visual>
    <visual>
      <origin xyz="-0.05 0 0" rpy="0 1.5708 0" />
      <geometry>
        <cylinder radius="0.012" length="0.003" />
        </geometry>
      <material name="machined_steel">
        <color rgba="0.72 0.74 0.76 1" />
        </material>
      </visual>
    <visual>
      <origin xyz="-0.035 0 0" rpy="0 1.5708 0" />
      <geometry>
        <cylinder radius="0.012" length="0.003" />
        </geometry>
      <material name="machined_steel">
        <color rgba="0.72 0.74 0.76 1" />
        </material>
      </visual>
    <visual>
      <origin xyz="-0.02 0 0" rpy="0 1.5708 0" />
      <geometry>
        <cylinder radius="0.012" length="0.003" />
        </geometry>
      <material name="machined_steel">
        <color rgba="0.72 0.74 0.76 1" />
        </material>
      </visual>
    <visual>
      <origin xyz="-0.004 0 0" rpy="0 1.5708 0" />
      <geometry>
        <cylinder radius="0.018" length="0.004" />
        </geometry>
      <material name="machined_steel">
        <color rgba="0.72 0.74 0.76 1" />
        </material>
      </visual>
    <visual>
      <origin xyz="0.009 0 0" rpy="0 1.5708 0" />
      <geometry>
        <cylinder radius="0.026" length="0.018" />
        </geometry>
      <material name="machined_steel">
        <color rgba="0.72 0.74 0.76 1" />
        </material>
      </visual>
    <visual>
      <origin xyz="0.027 0 0" rpy="0 1.5708 0" />
      <geometry>
        <cylinder radius="0.02" length="0.026" />
        </geometry>
      <material name="oxide_black">
        <color rgba="0.09 0.09 0.1 1" />
        </material>
      </visual>
    <visual>
      <origin xyz="0.027 0 0" rpy="1.5708 0 0" />
      <geometry>
        <cylinder radius="0.0045" length="0.17" />
        </geometry>
      <material name="oxide_black">
        <color rgba="0.09 0.09 0.1 1" />
        </material>
      </visual>
    <visual>
      <origin xyz="0.027 0.085 0" rpy="0 0 0" />
      <geometry>
        <sphere radius="0.01" />
        </geometry>
      <material name="oxide_black">
        <color rgba="0.09 0.09 0.1 1" />
        </material>
      </visual>
    <visual>
      <origin xyz="0.027 -0.085 0" rpy="0 0 0" />
      <geometry>
        <sphere radius="0.01" />
        </geometry>
      <material name="oxide_black">
        <color rgba="0.09 0.09 0.1 1" />
        </material>
      </visual>
    </link>
  <joint name="base_to_body" type="fixed">
    <origin xyz="-0.04 0 0.06" rpy="0 0 0" />
    <parent link="base" />
    <child link="body" />
    </joint>
  <joint name="jaw_slide" type="prismatic">
    <origin xyz="0.138 0 0.03" rpy="0 0 0" />
    <parent link="body" />
    <child link="sliding_jaw" />
    <axis xyz="1 0 0" />
    <limit effort="6000" velocity="0.15" lower="0" upper="0.11" />
    </joint>
  <joint name="handle_spin" type="continuous">
    <origin xyz="0.018 0 -0.016" rpy="0 0 0" />
    <parent link="sliding_jaw" />
    <child link="screw" />
    <axis xyz="1 0 0" />
    <limit effort="120" velocity="8" />
    </joint>
  </robot>
