<robot name="ergonomic_office_chair">
  <link name="base">
    <inertial>
      <origin xyz="0 0 0.06" rpy="0 0 0" />
      <mass value="6.4" />
      <inertia ixx="0.299733" ixy="0" ixz="0" iyy="0.299733" iyz="0" izz="0.584107" />
      </inertial>
    <visual>
      <origin xyz="0 0 0.055" rpy="0 0 0" />
      <geometry>
        <cylinder radius="0.066" length="0.038" />
        </geometry>
      <material name="graphite_plastic">
        <color rgba="0.18 0.19 0.21 1" />
        </material>
      </visual>
    <visual>
      <origin xyz="0 0 0.078" rpy="0 0 0" />
      <geometry>
        <cylinder radius="0.052" length="0.044" />
        </geometry>
      <material name="accent_gray">
        <color rgba="0.34 0.36 0.39 1" />
        </material>
      </visual>
    <visual name="spoke_0">
      <origin xyz="0 0 0.055" rpy="0 0 -1.5708" />
      <geometry>
        <mesh filename="assets/meshes/base_spoke.obj" />
        </geometry>
      <material name="matte_aluminum">
        <color rgba="0.72 0.74 0.76 1" />
        </material>
      </visual>
    <visual name="caster_fork_arm_inner_0">
      <origin xyz="0.335 0 0.039" rpy="0 1.5708 1.5708" />
      <geometry>
        <box size="0.028 0.012 0.006" />
        </geometry>
      <material name="black_steel">
        <color rgba="0.13 0.13 0.14 1" />
        </material>
      </visual>
    <visual name="caster_fork_arm_outer_0">
      <origin xyz="0.335 0 0.039" rpy="0 1.5708 1.5708" />
      <geometry>
        <box size="0.028 0.012 0.006" />
        </geometry>
      <material name="black_steel">
        <color rgba="0.13 0.13 0.14 1" />
        </material>
      </visual>
    <visual name="caster_fork_cap_0">
      <origin xyz="0.335 0 0.053" rpy="0 1.5708 1.5708" />
      <geometry>
        <box size="0.014 0.016 0.034" />
        </geometry>
      <material name="graphite_plastic">
        <color rgba="0.18 0.19 0.21 1" />
        </material>
      </visual>
    <visual name="caster_stem_0">
      <origin xyz="0.335 0 0.049" rpy="0 1.5708 1.5708" />
      <geometry>
        <box size="0.014 0.014 0.012" />
        </geometry>
      <material name="accent_gray">
        <color rgba="0.34 0.36 0.39 1" />
        </material>
      </visual>
    <visual name="spoke_1">
      <origin xyz="0 0 0.055" rpy="0 0 -0.314159" />
      <geometry>
        <mesh filename="assets/meshes/base_spoke.obj" />
        </geometry>
      <material name="matte_aluminum">
        <color rgba="0.72 0.74 0.76 1" />
        </material>
      </visual>
    <visual name="caster_fork_arm_inner_1">
      <origin xyz="0.103521 0.318604 0.039" rpy="0 1.5708 2.82743" />
      <geometry>
        <box size="0.028 0.012 0.006" />
        </geometry>
      <material name="black_steel">
        <color rgba="0.13 0.13 0.14 1" />
        </material>
      </visual>
    <visual name="caster_fork_arm_outer_1">
      <origin xyz="0.103521 0.318604 0.039" rpy="0 1.5708 2.82743" />
      <geometry>
        <box size="0.028 0.012 0.006" />
        </geometry>
      <material name="black_steel">
        <color rgba="0.13 0.13 0.14 1" />
        </material>
      </visual>
    <visual name="caster_fork_cap_1">
      <origin xyz="0.103521 0.318604 0.053" rpy="0 1.5708 2.82743" />
      <geometry>
        <box size="0.014 0.016 0.034" />
        </geometry>
      <material name="graphite_plastic">
        <color rgba="0.18 0.19 0.21 1" />
        </material>
      </visual>
    <visual name="caster_stem_1">
      <origin xyz="0.103521 0.318604 0.049" rpy="0 1.5708 2.82743" />
      <geometry>
        <box size="0.014 0.014 0.012" />
        </geometry>
      <material name="accent_gray">
        <color rgba="0.34 0.36 0.39 1" />
        </material>
      </visual>
    <visual name="spoke_2">
      <origin xyz="0 0 0.055" rpy="0 0 0.942478" />
      <geometry>
        <mesh filename="assets/meshes/base_spoke.obj" />
        </geometry>
      <material name="matte_aluminum">
        <color rgba="0.72 0.74 0.76 1" />
        </material>
      </visual>
    <visual name="caster_fork_arm_inner_2">
      <origin xyz="-0.271021 0.196908 0.039" rpy="0 1.5708 4.08407" />
      <geometry>
        <box size="0.028 0.012 0.006" />
        </geometry>
      <material name="black_steel">
        <color rgba="0.13 0.13 0.14 1" />
        </material>
      </visual>
    <visual name="caster_fork_arm_outer_2">
      <origin xyz="-0.271021 0.196908 0.039" rpy="0 1.5708 4.08407" />
      <geometry>
        <box size="0.028 0.012 0.006" />
        </geometry>
      <material name="black_steel">
        <color rgba="0.13 0.13 0.14 1" />
        </material>
      </visual>
    <visual name="caster_fork_cap_2">
      <origin xyz="-0.271021 0.196908 0.053" rpy="0 1.5708 4.08407" />
      <geometry>
        <box size="0.014 0.016 0.034" />
        </geometry>
      <material name="graphite_plastic">
        <color rgba="0.18 0.19 0.21 1" />
        </material>
      </visual>
    <visual name="caster_stem_2">
      <origin xyz="-0.271021 0.196908 0.049" rpy="0 1.5708 4.08407" />
      <geometry>
        <box size="0.014 0.014 0.012" />
        </geometry>
      <material name="accent_gray">
        <color rgba="0.34 0.36 0.39 1" />
        </material>
      </visual>
    <visual name="spoke_3">
      <origin xyz="0 0 0.055" rpy="0 0 2.19911" />
      <geometry>
        <mesh filename="assets/meshes/base_spoke.obj" />
        </geometry>
      <material name="matte_aluminum">
        <color rgba="0.72 0.74 0.76 1" />
        </material>
      </visual>
    <visual name="caster_fork_arm_inner_3">
      <origin xyz="-0.271021 -0.196908 0.039" rpy="0 1.5708 5.34071" />
      <geometry>
        <box size="0.028 0.012 0.006" />
        </geometry>
      <material name="black_steel">
        <color rgba="0.13 0.13 0.14 1" />
        </material>
      </visual>
    <visual name="caster_fork_arm_outer_3">
      <origin xyz="-0.271021 -0.196908 0.039" rpy="0 1.5708 5.34071" />
      <geometry>
        <box size="0.028 0.012 0.006" />
        </geometry>
      <material name="black_steel">
        <color rgba="0.13 0.13 0.14 1" />
        </material>
      </visual>
    <visual name="caster_fork_cap_3">
      <origin xyz="-0.271021 -0.196908 0.053" rpy="0 1.5708 5.34071" />
      <geometry>
        <box size="0.014 0.016 0.034" />
        </geometry>
      <material name="graphite_plastic">
        <color rgba="0.18 0.19 0.21 1" />
        </material>
      </visual>
    <visual name="caster_stem_3">
      <origin xyz="-0.271021 -0.196908 0.049" rpy="0 1.5708 5.34071" />
      <geometry>
        <box size="0.014 0.014 0.012" />
        </geometry>
      <material name="accent_gray">
        <color rgba="0.34 0.36 0.39 1" />
        </material>
      </visual>
    <visual name="spoke_4">
      <origin xyz="0 0 0.055" rpy="0 0 3.45575" />
      <geometry>
        <mesh filename="assets/meshes/base_spoke.obj" />
        </geometry>
      <material name="matte_aluminum">
        <color rgba="0.72 0.74 0.76 1" />
        </material>
      </visual>
    <visual name="caster_fork_arm_inner_4">
      <origin xyz="0.103521 -0.318604 0.039" rpy="0 1.5708 6.59734" />
      <geometry>
        <box size="0.028 0.012 0.006" />
        </geometry>
      <material name="black_steel">
        <color rgba="0.13 0.13 0.14 1" />
        </material>
      </visual>
    <visual name="caster_fork_arm_outer_4">
      <origin xyz="0.103521 -0.318604 0.039" rpy="0 1.5708 6.59734" />
      <geometry>
        <box size="0.028 0.012 0.006" />
        </geometry>
      <material name="black_steel">
        <color rgba="0.13 0.13 0.14 1" />
        </material>
      </visual>
    <visual name="caster_fork_cap_4">
      <origin xyz="0.103521 -0.318604 0.053" rpy="0 1.5708 6.59734" />
      <geometry>
        <box size="0.014 0.016 0.034" />
        </geometry>
      <material name="graphite_plastic">
        <color rgba="0.18 0.19 0.21 1" />
        </material>
      </visual>
    <visual name="caster_stem_4">
      <origin xyz="0.103521 -0.318604 0.049" rpy="0 1.5708 6.59734" />
      <geometry>
        <box size="0.014 0.014 0.012" />
        </geometry>
      <material name="accent_gray">
        <color rgba="0.34 0.36 0.39 1" />
        </material>
      </visual>
    </link>
  <link name="column_upper">
    <inertial>
      <origin xyz="0 0 0.132" rpy="0 0 0" />
      <mass value="3" />
      <inertia ixx="0.019825" ixy="0" ixz="0" iyy="0.019825" iyz="0" izz="0.0045375" />
      </inertial>
    <visual>
      <geometry>
        <mesh filename="assets/meshes/column_shell.obj" />
        </geometry>
      <material name="graphite_plastic">
        <color rgba="0.18 0.19 0.21 1" />
        </material>
      </visual>
    <visual>
      <origin xyz="0 0 0.12" rpy="0 0 0" />
      <geometry>
        <cylinder radius="0.023" length="0.24" />
        </geometry>
      <material name="polished_chrome">
        <color rgba="0.83 0.84 0.87 1" />
        </material>
      </visual>
    <visual>
      <origin xyz="0 0 0.015" rpy="0 0 0" />
      <geometry>
        <cylinder radius="0.032" length="0.014" />
        </geometry>
      <material name="polished_chrome">
        <color rgba="0.83 0.84 0.87 1" />
        </material>
      </visual>
    <visual>
      <origin xyz="0 0 0.246" rpy="0 0 0" />
      <geometry>
        <cylinder radius="0.052" length="0.022" />
        </geometry>
      <material name="black_steel">
        <color rgba="0.13 0.13 0.14 1" />
        </material>
      </visual>
    <visual>
      <origin xyz="0 0 0.217" rpy="0 0 0" />
      <geometry>
        <cylinder radius="0.036" length="0.058" />
        </geometry>
      <material name="accent_gray">
        <color rgba="0.34 0.36 0.39 1" />
        </material>
      </visual>
    </link>
  <link name="seat">
    <inertial>
      <origin xyz="0 0 0.01" rpy="0 0 0" />
      <mass value="5.8" />
      <inertia ixx="0.136542" ixy="0" ixz="0" iyy="0.152057" iyz="0" izz="0.276902" />
      </inertial>
    <visual>
      <origin xyz="0 0 -0.02" rpy="0 0 0" />
      <geometry>
        <box size="0.21 0.185 0.04" />
        </geometry>
      <material name="black_steel">
        <color rgba="0.13 0.13 0.14 1" />
        </material>
      </visual>
    <visual>
      <origin xyz="0.09 -0.04 -0.022" rpy="1.5708 0 0" />
      <geometry>
        <cylinder radius="0.028" length="0.02" />
        </geometry>
      <material name="graphite_plastic">
        <color rgba="0.18 0.19 0.21 1" />
        </material>
      </visual>
    <visual>
      <origin xyz="-0.128 -0.02 -0.02" rpy="0 0 0" />
      <geometry>
        <box size="0.075 0.01 0.008" />
        </geometry>
      <material name="black_steel">
        <color rgba="0.13 0.13 0.14 1" />
        </material>
      </visual>
    <visual>
      <origin xyz="-0.162 -0.02 -0.02" rpy="0 0 0" />
      <geometry>
        <box size="0.01 0.055 0.01" />
        </geometry>
      <material name="black_steel">
        <color rgba="0.13 0.13 0.14 1" />
        </material>
      </visual>
    <visual>
      <geometry>
        <mesh filename="assets/meshes/seat_shell.obj" />
        </geometry>
      <material name="graphite_plastic">
        <color rgba="0.18 0.19 0.21 1" />
        </material>
      </visual>
    <visual>
      <geometry>
        <mesh filename="assets/meshes/seat_pad.obj" />
        </geometry>
      <material name="seat_fabric">
        <color rgba="0.09 0.1 0.11 1" />
        </material>
      </visual>
    </link>
  <link name="backrest">
    <inertial>
      <origin xyz="0 -0.028 0.315" rpy="0 0 0" />
      <mass value="4.1" />
      <inertia ixx="0.149274" ixy="0" ixz="0" iyy="0.219828" iyz="0" izz="0.0803942" />
      </inertial>
    <visual>
      <origin xyz="0 -0.022 0.011" rpy="0 0 0" />
      <geometry>
        <box size="0.07 0.05 0.022" />
        </geometry>
      <material name="black_steel">
        <color rgba="0.13 0.13 0.14 1" />
        </material>
      </visual>
    <visual>
      <origin xyz="0 -0.028 0.012" rpy="0 0 0" />
      <geometry>
        <mesh filename="assets/meshes/back_spine.obj" />
        </geometry>
      <material name="black_steel">
        <color rgba="0.13 0.13 0.14 1" />
        </material>
      </visual>
    <visual>
      <origin xyz="0 -0.032 0.028" rpy="0.11 0 0" />
      <geometry>
        <mesh filename="assets/meshes/back_shell.obj" />
        </geometry>
      <material name="graphite_plastic">
        <color rgba="0.18 0.19 0.21 1" />
        </material>
      </visual>
    <visual>
      <origin xyz="0 -0.032 0.028" rpy="0.11 0 0" />
      <geometry>
        <mesh filename="assets/meshes/back_pad.obj" />
        </geometry>
      <material name="mesh_back">
        <color rgba="0.12 0.13 0.15 0.94" />
        </material>
      </visual>
    <visual>
      <origin xyz="0 -0.05 0.14" rpy="0 1.5708 0" />
      <geometry>
        <cylinder radius="0.013" length="0.21" />
        </geometry>
      <material name="accent_gray">
        <color rgba="0.34 0.36 0.39 1" />
        </material>
      </visual>
    </link>
  <link name="armrest_right">
    <inertial>
      <origin xyz="0.048 0 0.11" rpy="0 0 0" />
      <mass value="1.1" />
      <inertia ixx="0.0121458" ixy="0" ixz="0" iyy="0.00535333" iyz="0" izz="0.00862583" />
      </inertial>
    <visual>
      <origin xyz="0.002 0 0.011" rpy="0 0 0" />
      <geometry>
        <box size="0.026 0.18 0.022" />
        </geometry>
      <material name="graphite_plastic">
        <color rgba="0.18 0.19 0.21 1" />
        </material>
      </visual>
    <visual>
      <origin xyz="0.015 -0.074 0.086" rpy="0 0 0" />
      <geometry>
        <cylinder radius="0.01" length="0.172" />
        </geometry>
      <material name="black_steel">
        <color rgba="0.13 0.13 0.14 1" />
        </material>
      </visual>
    <visual>
      <origin xyz="0.015 0.074 0.086" rpy="0 0 0" />
      <geometry>
        <cylinder radius="0.01" length="0.172" />
        </geometry>
      <material name="black_steel">
        <color rgba="0.13 0.13 0.14 1" />
        </material>
      </visual>
    <visual>
      <origin xyz="0.034 -0.074 0.17" rpy="0 0 0" />
      <geometry>
        <box size="0.05 0.02 0.018" />
        </geometry>
      <material name="graphite_plastic">
        <color rgba="0.18 0.19 0.21 1" />
        </material>
      </visual>
    <visual>
      <origin xyz="0.034 0.074 0.17" rpy="0 0 0" />
      <geometry>
        <box size="0.05 0.02 0.018" />
        </geometry>
      <material name="graphite_plastic">
        <color rgba="0.18 0.19 0.21 1" />
        </material>
      </visual>
    <visual>
      <origin xyz="0.054 0 0.17" rpy="0 0 0" />
      <geometry>
        <box size="0.02 0.17 0.018" />
        </geometry>
      <material name="graphite_plastic">
        <color rgba="0.18 0.19 0.21 1" />
        </material>
      </visual>
    <visual>
      <origin xyz="0.056 0 0.192" rpy="0 0 0" />
      <geometry>
        <mesh filename="assets/meshes/arm_pad.obj" />
        </geometry>
      <material name="arm_pad">
        <color rgba="0.11 0.11 0.12 1" />
        </material>
      </visual>
    </link>
  <link name="armrest_left">
    <inertial>
      <origin xyz="0.048 0 0.11" rpy="0 0 0" />
      <mass value="1.1" />
      <inertia ixx="0.0121458" ixy="0" ixz="0" iyy="0.00535333" iyz="0" izz="0.00862583" />
      </inertial>
    <visual>
      <origin xyz="0.002 0 0.011" rpy="0 0 0" />
      <geometry>
        <box size="0.026 0.18 0.022" />
        </geometry>
      <material name="graphite_plastic">
        <color rgba="0.18 0.19 0.21 1" />
        </material>
      </visual>
    <visual>
      <origin xyz="0.015 -0.074 0.086" rpy="0 0 0" />
      <geometry>
        <cylinder radius="0.01" length="0.172" />
        </geometry>
      <material name="black_steel">
        <color rgba="0.13 0.13 0.14 1" />
        </material>
      </visual>
    <visual>
      <origin xyz="0.015 0.074 0.086" rpy="0 0 0" />
      <geometry>
        <cylinder radius="0.01" length="0.172" />
        </geometry>
      <material name="black_steel">
        <color rgba="0.13 0.13 0.14 1" />
        </material>
      </visual>
    <visual>
      <origin xyz="0.034 -0.074 0.17" rpy="0 0 0" />
      <geometry>
        <box size="0.05 0.02 0.018" />
        </geometry>
      <material name="graphite_plastic">
        <color rgba="0.18 0.19 0.21 1" />
        </material>
      </visual>
    <visual>
      <origin xyz="0.034 0.074 0.17" rpy="0 0 0" />
      <geometry>
        <box size="0.05 0.02 0.018" />
        </geometry>
      <material name="graphite_plastic">
        <color rgba="0.18 0.19 0.21 1" />
        </material>
      </visual>
    <visual>
      <origin xyz="0.054 0 0.17" rpy="0 0 0" />
      <geometry>
        <box size="0.02 0.17 0.018" />
        </geometry>
      <material name="graphite_plastic">
        <color rgba="0.18 0.19 0.21 1" />
        </material>
      </visual>
    <visual>
      <origin xyz="0.056 0 0.192" rpy="0 0 0" />
      <geometry>
        <mesh filename="assets/meshes/arm_pad.obj" />
        </geometry>
      <material name="arm_pad">
        <color rgba="0.11 0.11 0.12 1" />
        </material>
      </visual>
    </link>
  <link name="caster_0">
    <inertial>
      <mass value="0.24" />
      <inertia ixx="8.6e-05" ixy="0" ixz="0" iyy="8.6e-05" iyz="0" izz="0.000108" />
      </inertial>
    <visual>
      <origin xyz="0 0 -0.011" rpy="0 0 0" />
      <geometry>
        <cylinder radius="0.027" length="0.01" />
        </geometry>
      <material name="rubber">
        <color rgba="0.05 0.05 0.05 1" />
        </material>
      </visual>
    <visual>
      <origin xyz="0 0 -0.011" rpy="0 0 0" />
      <geometry>
        <cylinder radius="0.015" length="0.009" />
        </geometry>
      <material name="accent_gray">
        <color rgba="0.34 0.36 0.39 1" />
        </material>
      </visual>
    <visual>
      <origin xyz="0 0 0.011" rpy="0 0 0" />
      <geometry>
        <cylinder radius="0.027" length="0.01" />
        </geometry>
      <material name="rubber">
        <color rgba="0.05 0.05 0.05 1" />
        </material>
      </visual>
    <visual>
      <origin xyz="0 0 0.011" rpy="0 0 0" />
      <geometry>
        <cylinder radius="0.015" length="0.009" />
        </geometry>
      <material name="accent_gray">
        <color rgba="0.34 0.36 0.39 1" />
        </material>
      </visual>
    <visual>
      <geometry>
        <cylinder radius="0.006" length="0.034" />
        </geometry>
      <material name="black_steel">
        <color rgba="0.13 0.13 0.14 1" />
        </material>
      </visual>
    </link>
  <link name="caster_1">
    <inertial>
      <mass value="0.24" />
      <inertia ixx="8.6e-05" ixy="0" ixz="0" iyy="8.6e-05" iyz="0" izz="0.000108" />
      </inertial>
    <visual>
      <origin xyz="0 0 -0.011" rpy="0 0 0" />
      <geometry>
        <cylinder radius="0.027" length="0.01" />
        </geometry>
      <material name="rubber">
        <color rgba="0.05 0.05 0.05 1" />
        </material>
      </visual>
    <visual>
      <origin xyz="0 0 -0.011" rpy="0 0 0" />
      <geometry>
        <cylinder radius="0.015" length="0.009" />
        </geometry>
      <material name="accent_gray">
        <color rgba="0.34 0.36 0.39 1" />
        </material>
      </visual>
    <visual>
      <origin xyz="0 0 0.011" rpy="0 0 0" />
      <geometry>
        <cylinder radius="0.027" length="0.01" />
        </geometry>
      <material name="rubber">
        <color rgba="0.05 0.05 0.05 1" />
        </material>
      </visual>
    <visual>
      <origin xyz="0 0 0.011" rpy="0 0 0" />
      <geometry>
        <cylinder radius="0.015" length="0.009" />
        </geometry>
      <material name="accent_gray">
        <color rgba="0.34 0.36 0.39 1" />
        </material>
      </visual>
    <visual>
      <geometry>
        <cylinder radius="0.006" length="0.034" />
        </geometry>
      <material name="black_steel">
        <color rgba="0.13 0.13 0.14 1" />
        </material>
      </visual>
    </link>
  <link name="caster_2">
    <inertial>
      <mass value="0.24" />
      <inertia ixx="8.6e-05" ixy="0" ixz="0" iyy="8.6e-05" iyz="0" izz="0.000108" />
      </inertial>
    <visual>
      <origin xyz="0 0 -0.011" rpy="0 0 0" />
      <geometry>
        <cylinder radius="0.027" length="0.01" />
        </geometry>
      <material name="rubber">
        <color rgba="0.05 0.05 0.05 1" />
        </material>
      </visual>
    <visual>
      <origin xyz="0 0 -0.011" rpy="0 0 0" />
      <geometry>
        <cylinder radius="0.015" length="0.009" />
        </geometry>
      <material name="accent_gray">
        <color rgba="0.34 0.36 0.39 1" />
        </material>
      </visual>
    <visual>
      <origin xyz="0 0 0.011" rpy="0 0 0" />
      <geometry>
        <cylinder radius="0.027" length="0.01" />
        </geometry>
      <material name="rubber">
        <color rgba="0.05 0.05 0.05 1" />
        </material>
      </visual>
    <visual>
      <origin xyz="0 0 0.011" rpy="0 0 0" />
      <geometry>
        <cylinder radius="0.015" length="0.009" />
        </geometry>
      <material name="accent_gray">
        <color rgba="0.34 0.36 0.39 1" />
        </material>
      </visual>
    <visual>
      <geometry>
        <cylinder radius="0.006" length="0.034" />
        </geometry>
      <material name="black_steel">
        <color rgba="0.13 0.13 0.14 1" />
        </material>
      </visual>
    </link>
  <link name="caster_3">
    <inertial>
      <mass value="0.24" />
      <inertia ixx="8.6e-05" ixy="0" ixz="0" iyy="8.6e-05" iyz="0" izz="0.000108" />
      </inertial>
    <visual>
      <origin xyz="0 0 -0.011" rpy="0 0 0" />
      <geometry>
        <cylinder radius="0.027" length="0.01" />
        </geometry>
      <material name="rubber">
        <color rgba="0.05 0.05 0.05 1" />
        </material>
      </visual>
    <visual>
      <origin xyz="0 0 -0.011" rpy="0 0 0" />
      <geometry>
        <cylinder radius="0.015" length="0.009" />
        </geometry>
      <material name="accent_gray">
        <color rgba="0.34 0.36 0.39 1" />
        </material>
      </visual>
    <visual>
      <origin xyz="0 0 0.011" rpy="0 0 0" />
      <geometry>
        <cylinder radius="0.027" length="0.01" />
        </geometry>
      <material name="rubber">
        <color rgba="0.05 0.05 0.05 1" />
        </material>
      </visual>
    <visual>
      <origin xyz="0 0 0.011" rpy="0 0 0" />
      <geometry>
        <cylinder radius="0.015" length="0.009" />
        </geometry>
      <material name="accent_gray">
        <color rgba="0.34 0.36 0.39 1" />
        </material>
      </visual>
    <visual>
      <geometry>
        <cylinder radius="0.006" length="0.034" />
        </geometry>
      <material name="black_steel">
        <color rgba="0.13 0.13 0.14 1" />
        </material>
      </visual>
    </link>
  <link name="caster_4">
    <inertial>
      <mass value="0.24" />
      <inertia ixx="8.6e-05" ixy="0" ixz="0" iyy="8.6e-05" iyz="0" izz="0.000108" />
      </inertial>
    <visual>
      <origin xyz="0 0 -0.011" rpy="0 0 0" />
      <geometry>
        <cylinder radius="0.027" length="0.01" />
        </geometry>
      <material name="rubber">
        <color rgba="0.05 0.05 0.05 1" />
        </material>
      </visual>
    <visual>
      <origin xyz="0 0 -0.011" rpy="0 0 0" />
      <geometry>
        <cylinder radius="0.015" length="0.009" />
        </geometry>
      <material name="accent_gray">
        <color rgba="0.34 0.36 0.39 1" />
        </material>
      </visual>
    <visual>
      <origin xyz="0 0 0.011" rpy="0 0 0" />
      <geometry>
        <cylinder radius="0.027" length="0.01" />
        </geometry>
      <material name="rubber">
        <color rgba="0.05 0.05 0.05 1" />
        </material>
      </visual>
    <visual>
      <origin xyz="0 0 0.011" rpy="0 0 0" />
      <geometry>
        <cylinder radius="0.015" length="0.009" />
        </geometry>
      <material name="accent_gray">
        <color rgba="0.34 0.36 0.39 1" />
        </material>
      </visual>
    <visual>
      <geometry>
        <cylinder radius="0.006" length="0.034" />
        </geometry>
      <material name="black_steel">
        <color rgba="0.13 0.13 0.14 1" />
        </material>
      </visual>
    </link>
  <joint name="height_adjust" type="prismatic">
    <origin xyz="0 0 0.1" rpy="0 0 0" />
    <parent link="base" />
    <child link="column_upper" />
    <axis xyz="0 0 1" />
    <limit effort="1500" velocity="0.3" lower="0" upper="0.1" />
    </joint>
  <joint name="swivel" type="continuous">
    <origin xyz="0 0 0.262" rpy="0 0 0" />
    <parent link="column_upper" />
    <child link="seat" />
    <axis xyz="0 0 1" />
    <limit effort="40" velocity="6" />
    </joint>
  <joint name="back_tilt" type="revolute">
    <origin xyz="0 -0.176 0.018" rpy="0 0 0" />
    <parent link="seat" />
    <child link="backrest" />
    <axis xyz="1 0 0" />
    <limit effort="90" velocity="1.4" lower="0" upper="0.45" />
    </joint>
  <joint name="seat_to_armrest_right" type="fixed">
    <origin xyz="0.214 -0.006 -0.004" rpy="0 0 0" />
    <parent link="seat" />
    <child link="armrest_right" />
    </joint>
  <joint name="seat_to_armrest_left" type="fixed">
    <origin xyz="-0.214 -0.006 -0.004" rpy="0 0 3.14159" />
    <parent link="seat" />
    <child link="armrest_left" />
    </joint>
  <joint name="caster_0_roll" type="continuous">
    <origin xyz="0.335 0 0.027" rpy="0 1.5708 1.5708" />
    <parent link="base" />
    <child link="caster_0" />
    <axis xyz="0 0 1" />
    <limit effort="2" velocity="20" />
    </joint>
  <joint name="caster_1_roll" type="continuous">
    <origin xyz="0.103521 0.318604 0.027" rpy="0 1.5708 2.82743" />
    <parent link="base" />
    <child link="caster_1" />
    <axis xyz="0 0 1" />
    <limit effort="2" velocity="20" />
    </joint>
  <joint name="caster_2_roll" type="continuous">
    <origin xyz="-0.271021 0.196908 0.027" rpy="0 1.5708 4.08407" />
    <parent link="base" />
    <child link="caster_2" />
    <axis xyz="0 0 1" />
    <limit effort="2" velocity="20" />
    </joint>
  <joint name="caster_3_roll" type="continuous">
    <origin xyz="-0.271021 -0.196908 0.027" rpy="0 1.5708 5.34071" />
    <parent link="base" />
    <child link="caster_3" />
    <axis xyz="0 0 1" />
    <limit effort="2" velocity="20" />
    </joint>
  <joint name="caster_4_roll" type="continuous">
    <origin xyz="0.103521 -0.318604 0.027" rpy="0 1.5708 6.59734" />
    <parent link="base" />
    <child link="caster_4" />
    <axis xyz="0 0 1" />
    <limit effort="2" velocity="20" />
    </joint>
  </robot>
