<robot name="rolling_suitcase">
  <material name="body_shell">
    <color rgba="0.16 0.18 0.21 1" />
    </material>
  <material name="zipper_trim">
    <color rgba="0.08 0.08 0.09 1" />
    </material>
  <material name="corner_guard">
    <color rgba="0.11 0.11 0.12 1" />
    </material>
  <material name="aluminum">
    <color rgba="0.76 0.78 0.8 1" />
    </material>
  <material name="rubber">
    <color rgba="0.05 0.05 0.05 1" />
    </material>
  <material name="hub">
    <color rgba="0.58 0.6 0.63 1" />
    </material>
  <link name="case_body">
    <inertial>
      <origin xyz="0 0 0.355" rpy="0 0 0" />
      <mass value="3" />
      <inertia ixx="0.104641" ixy="0" ixz="0" iyy="0.126481" iyz="0" izz="0.051122" />
      </inertial>
    <visual>
      <geometry>
        <mesh filename="meshes/suitcase_shell.obj" />
        </geometry>
      <material name="body_shell">
        <color rgba="0.16 0.18 0.21 1" />
        </material>
      </visual>
    <visual>
      <origin xyz="0 -0.119 0.325" rpy="0 0 0" />
      <geometry>
        <box size="0.054 0.01 0.42" />
        </geometry>
      <material name="zipper_trim">
        <color rgba="0.08 0.08 0.09 1" />
        </material>
      </visual>
    <visual>
      <origin xyz="-0.105 -0.119 0.308" rpy="0 0 0" />
      <geometry>
        <box size="0.032 0.01 0.465" />
        </geometry>
      <material name="zipper_trim">
        <color rgba="0.08 0.08 0.09 1" />
        </material>
      </visual>
    <visual>
      <origin xyz="0.105 -0.119 0.308" rpy="0 0 0" />
      <geometry>
        <box size="0.032 0.01 0.465" />
        </geometry>
      <material name="zipper_trim">
        <color rgba="0.08 0.08 0.09 1" />
        </material>
      </visual>
    <visual>
      <origin xyz="-0.182 0 0.326" rpy="0 0 0" />
      <geometry>
        <box size="0.015 0.014 0.468" />
        </geometry>
      <material name="zipper_trim">
        <color rgba="0.08 0.08 0.09 1" />
        </material>
      </visual>
    <visual>
      <origin xyz="0.182 0 0.326" rpy="0 0 0" />
      <geometry>
        <box size="0.015 0.014 0.468" />
        </geometry>
      <material name="zipper_trim">
        <color rgba="0.08 0.08 0.09 1" />
        </material>
      </visual>
    <visual>
      <origin xyz="0 0 0.642" rpy="0 0 0" />
      <geometry>
        <box size="0.252 0.014 0.016" />
        </geometry>
      <material name="zipper_trim">
        <color rgba="0.08 0.08 0.09 1" />
        </material>
      </visual>
    <visual>
      <origin xyz="0 0 0.07" rpy="0 0 0" />
      <geometry>
        <box size="0.198 0.014 0.014" />
        </geometry>
      <material name="zipper_trim">
        <color rgba="0.08 0.08 0.09 1" />
        </material>
      </visual>
    <visual>
      <origin xyz="-0.164 -0.112 0.107" rpy="0 0 0" />
      <geometry>
        <box size="0.046 0.028 0.054" />
        </geometry>
      <material name="corner_guard">
        <color rgba="0.11 0.11 0.12 1" />
        </material>
      </visual>
    <visual>
      <origin xyz="0.164 -0.112 0.107" rpy="0 0 0" />
      <geometry>
        <box size="0.046 0.028 0.054" />
        </geometry>
      <material name="corner_guard">
        <color rgba="0.11 0.11 0.12 1" />
        </material>
      </visual>
    <visual>
      <origin xyz="-0.164 -0.112 0.605" rpy="0 0 0" />
      <geometry>
        <box size="0.046 0.028 0.054" />
        </geometry>
      <material name="corner_guard">
        <color rgba="0.11 0.11 0.12 1" />
        </material>
      </visual>
    <visual>
      <origin xyz="0.164 -0.112 0.605" rpy="0 0 0" />
      <geometry>
        <box size="0.046 0.028 0.054" />
        </geometry>
      <material name="corner_guard">
        <color rgba="0.11 0.11 0.12 1" />
        </material>
      </visual>
    <visual>
      <origin xyz="-0.164 0.112 0.107" rpy="0 0 0" />
      <geometry>
        <box size="0.046 0.028 0.054" />
        </geometry>
      <material name="corner_guard">
        <color rgba="0.11 0.11 0.12 1" />
        </material>
      </visual>
    <visual>
      <origin xyz="0.164 0.112 0.107" rpy="0 0 0" />
      <geometry>
        <box size="0.046 0.028 0.054" />
        </geometry>
      <material name="corner_guard">
        <color rgba="0.11 0.11 0.12 1" />
        </material>
      </visual>
    <visual>
      <origin xyz="-0.164 0.112 0.605" rpy="0 0 0" />
      <geometry>
        <box size="0.046 0.028 0.054" />
        </geometry>
      <material name="corner_guard">
        <color rgba="0.11 0.11 0.12 1" />
        </material>
      </visual>
    <visual>
      <origin xyz="0.164 0.112 0.605" rpy="0 0 0" />
      <geometry>
        <box size="0.046 0.028 0.054" />
        </geometry>
      <material name="corner_guard">
        <color rgba="0.11 0.11 0.12 1" />
        </material>
      </visual>
    <visual>
      <origin xyz="-0.11 -0.088 0.0275" rpy="0 0 0" />
      <geometry>
        <box size="0.032 0.068 0.055" />
        </geometry>
      <material name="corner_guard">
        <color rgba="0.11 0.11 0.12 1" />
        </material>
      </visual>
    <visual>
      <origin xyz="0.11 -0.088 0.0275" rpy="0 0 0" />
      <geometry>
        <box size="0.032 0.068 0.055" />
        </geometry>
      <material name="corner_guard">
        <color rgba="0.11 0.11 0.12 1" />
        </material>
      </visual>
    <visual>
      <origin xyz="-0.156 0.108 0.056" rpy="0 0 0" />
      <geometry>
        <box size="0.074 0.082 0.112" />
        </geometry>
      <material name="corner_guard">
        <color rgba="0.11 0.11 0.12 1" />
        </material>
      </visual>
    <visual>
      <origin xyz="0.156 0.108 0.056" rpy="0 0 0" />
      <geometry>
        <box size="0.074 0.082 0.112" />
        </geometry>
      <material name="corner_guard">
        <color rgba="0.11 0.11 0.12 1" />
        </material>
      </visual>
    <visual>
      <origin xyz="0 0.106 0.034" rpy="0 0 0" />
      <geometry>
        <box size="0.242 0.042 0.068" />
        </geometry>
      <material name="corner_guard">
        <color rgba="0.11 0.11 0.12 1" />
        </material>
      </visual>
    <visual>
      <origin xyz="-0.095 0.102 0.604" rpy="0 0 0" />
      <geometry>
        <box size="0.03 0.048 0.058" />
        </geometry>
      <material name="corner_guard">
        <color rgba="0.11 0.11 0.12 1" />
        </material>
      </visual>
    <visual>
      <origin xyz="-0.095 0.102 0.648" rpy="0 0 0" />
      <geometry>
        <cylinder radius="0.009" length="0.126" />
        </geometry>
      <material name="aluminum">
        <color rgba="0.76 0.78 0.8 1" />
        </material>
      </visual>
    <visual>
      <origin xyz="0.095 0.102 0.604" rpy="0 0 0" />
      <geometry>
        <box size="0.03 0.048 0.058" />
        </geometry>
      <material name="corner_guard">
        <color rgba="0.11 0.11 0.12 1" />
        </material>
      </visual>
    <visual>
      <origin xyz="0.095 0.102 0.648" rpy="0 0 0" />
      <geometry>
        <cylinder radius="0.009" length="0.126" />
        </geometry>
      <material name="aluminum">
        <color rgba="0.76 0.78 0.8 1" />
        </material>
      </visual>
    <visual>
      <origin xyz="0 0.102 0.676" rpy="0 0 0" />
      <geometry>
        <box size="0.222 0.026 0.05" />
        </geometry>
      <material name="corner_guard">
        <color rgba="0.11 0.11 0.12 1" />
        </material>
      </visual>
    <visual>
      <origin xyz="-0.055 0.018 0.647" rpy="0 0 0" />
      <geometry>
        <box size="0.026 0.03 0.018" />
        </geometry>
      <material name="corner_guard">
        <color rgba="0.11 0.11 0.12 1" />
        </material>
      </visual>
    <visual>
      <origin xyz="0.055 0.018 0.647" rpy="0 0 0" />
      <geometry>
        <box size="0.026 0.03 0.018" />
        </geometry>
      <material name="corner_guard">
        <color rgba="0.11 0.11 0.12 1" />
        </material>
      </visual>
    <visual>
      <geometry>
        <mesh filename="meshes/carry_handle.obj" />
        </geometry>
      <material name="corner_guard">
        <color rgba="0.11 0.11 0.12 1" />
        </material>
      </visual>
    <collision name="case_body__visual_1__hull_001">
      <geometry>
        <mesh filename="meshes/collision/cache/0b1f5aa14230555731d622e6__hull_001.obj" />
        </geometry>
      </collision>
    <collision name="case_body__visual_2">
      <origin xyz="0 -0.119 0.325" rpy="0 0 0" />
      <geometry>
        <box size="0.054 0.01 0.42" />
        </geometry>
      </collision>
    <collision name="case_body__visual_3">
      <origin xyz="-0.105 -0.119 0.308" rpy="0 0 0" />
      <geometry>
        <box size="0.032 0.01 0.465" />
        </geometry>
      </collision>
    <collision name="case_body__visual_4">
      <origin xyz="0.105 -0.119 0.308" rpy="0 0 0" />
      <geometry>
        <box size="0.032 0.01 0.465" />
        </geometry>
      </collision>
    <collision name="case_body__visual_5">
      <origin xyz="-0.182 0 0.326" rpy="0 0 0" />
      <geometry>
        <box size="0.015 0.014 0.468" />
        </geometry>
      </collision>
    <collision name="case_body__visual_6">
      <origin xyz="0.182 0 0.326" rpy="0 0 0" />
      <geometry>
        <box size="0.015 0.014 0.468" />
        </geometry>
      </collision>
    <collision name="case_body__visual_7">
      <origin xyz="0 0 0.642" rpy="0 0 0" />
      <geometry>
        <box size="0.252 0.014 0.016" />
        </geometry>
      </collision>
    <collision name="case_body__visual_8">
      <origin xyz="0 0 0.07" rpy="0 0 0" />
      <geometry>
        <box size="0.198 0.014 0.014" />
        </geometry>
      </collision>
    <collision name="case_body__visual_9">
      <origin xyz="-0.164 -0.112 0.107" rpy="0 0 0" />
      <geometry>
        <box size="0.046 0.028 0.054" />
        </geometry>
      </collision>
    <collision name="case_body__visual_10">
      <origin xyz="0.164 -0.112 0.107" rpy="0 0 0" />
      <geometry>
        <box size="0.046 0.028 0.054" />
        </geometry>
      </collision>
    <collision name="case_body__visual_11">
      <origin xyz="-0.164 -0.112 0.605" rpy="0 0 0" />
      <geometry>
        <box size="0.046 0.028 0.054" />
        </geometry>
      </collision>
    <collision name="case_body__visual_12">
      <origin xyz="0.164 -0.112 0.605" rpy="0 0 0" />
      <geometry>
        <box size="0.046 0.028 0.054" />
        </geometry>
      </collision>
    <collision name="case_body__visual_13">
      <origin xyz="-0.164 0.112 0.107" rpy="0 0 0" />
      <geometry>
        <box size="0.046 0.028 0.054" />
        </geometry>
      </collision>
    <collision name="case_body__visual_14">
      <origin xyz="0.164 0.112 0.107" rpy="0 0 0" />
      <geometry>
        <box size="0.046 0.028 0.054" />
        </geometry>
      </collision>
    <collision name="case_body__visual_15">
      <origin xyz="-0.164 0.112 0.605" rpy="0 0 0" />
      <geometry>
        <box size="0.046 0.028 0.054" />
        </geometry>
      </collision>
    <collision name="case_body__visual_16">
      <origin xyz="0.164 0.112 0.605" rpy="0 0 0" />
      <geometry>
        <box size="0.046 0.028 0.054" />
        </geometry>
      </collision>
    <collision name="case_body__visual_17">
      <origin xyz="-0.11 -0.088 0.0275" rpy="0 0 0" />
      <geometry>
        <box size="0.032 0.068 0.055" />
        </geometry>
      </collision>
    <collision name="case_body__visual_18">
      <origin xyz="0.11 -0.088 0.0275" rpy="0 0 0" />
      <geometry>
        <box size="0.032 0.068 0.055" />
        </geometry>
      </collision>
    <collision name="case_body__visual_19">
      <origin xyz="-0.156 0.108 0.056" rpy="0 0 0" />
      <geometry>
        <box size="0.074 0.082 0.112" />
        </geometry>
      </collision>
    <collision name="case_body__visual_20">
      <origin xyz="0.156 0.108 0.056" rpy="0 0 0" />
      <geometry>
        <box size="0.074 0.082 0.112" />
        </geometry>
      </collision>
    <collision name="case_body__visual_21">
      <origin xyz="0 0.106 0.034" rpy="0 0 0" />
      <geometry>
        <box size="0.242 0.042 0.068" />
        </geometry>
      </collision>
    <collision name="case_body__visual_22">
      <origin xyz="-0.095 0.102 0.604" rpy="0 0 0" />
      <geometry>
        <box size="0.03 0.048 0.058" />
        </geometry>
      </collision>
    <collision name="case_body__visual_23">
      <origin xyz="-0.095 0.102 0.648" rpy="0 0 0" />
      <geometry>
        <cylinder radius="0.009" length="0.126" />
        </geometry>
      </collision>
    <collision name="case_body__visual_24">
      <origin xyz="0.095 0.102 0.604" rpy="0 0 0" />
      <geometry>
        <box size="0.03 0.048 0.058" />
        </geometry>
      </collision>
    <collision name="case_body__visual_25">
      <origin xyz="0.095 0.102 0.648" rpy="0 0 0" />
      <geometry>
        <cylinder radius="0.009" length="0.126" />
        </geometry>
      </collision>
    <collision name="case_body__visual_26">
      <origin xyz="0 0.102 0.676" rpy="0 0 0" />
      <geometry>
        <box size="0.222 0.026 0.05" />
        </geometry>
      </collision>
    <collision name="case_body__visual_27">
      <origin xyz="-0.055 0.018 0.647" rpy="0 0 0" />
      <geometry>
        <box size="0.026 0.03 0.018" />
        </geometry>
      </collision>
    <collision name="case_body__visual_28">
      <origin xyz="0.055 0.018 0.647" rpy="0 0 0" />
      <geometry>
        <box size="0.026 0.03 0.018" />
        </geometry>
      </collision>
    <collision name="case_body__visual_29__hull_001">
      <geometry>
        <mesh filename="meshes/collision/cache/0b0969157766f9af66e96b18__hull_001.obj" />
        </geometry>
      </collision>
    <collision name="case_body__visual_29__hull_002">
      <geometry>
        <mesh filename="meshes/collision/cache/0b0969157766f9af66e96b18__hull_002.obj" />
        </geometry>
      </collision>
    <collision name="case_body__visual_29__hull_003">
      <geometry>
        <mesh filename="meshes/collision/cache/0b0969157766f9af66e96b18__hull_003.obj" />
        </geometry>
      </collision>
    <collision name="case_body__visual_29__hull_004">
      <geometry>
        <mesh filename="meshes/collision/cache/0b0969157766f9af66e96b18__hull_004.obj" />
        </geometry>
      </collision>
    <collision name="case_body__visual_29__hull_005">
      <geometry>
        <mesh filename="meshes/collision/cache/0b0969157766f9af66e96b18__hull_005.obj" />
        </geometry>
      </collision>
    </link>
  <link name="left_wheel">
    <inertial>
      <origin xyz="0 0 0" rpy="0 1.5708 0" />
      <mass value="0.2" />
      <inertia ixx="7.52667e-05" ixy="0" ixz="0" iyy="7.52667e-05" iyz="0" izz="0.0001024" />
      </inertial>
    <visual>
      <origin xyz="0 0 0" rpy="0 1.5708 0" />
      <geometry>
        <cylinder radius="0.032" length="0.038" />
        </geometry>
      <material name="rubber">
        <color rgba="0.05 0.05 0.05 1" />
        </material>
      </visual>
    <visual>
      <origin xyz="0 0 0" rpy="0 1.5708 0" />
      <geometry>
        <cylinder radius="0.021" length="0.028" />
        </geometry>
      <material name="hub">
        <color rgba="0.58 0.6 0.63 1" />
        </material>
      </visual>
    <visual>
      <origin xyz="-0.01 0 0" rpy="0 1.5708 0" />
      <geometry>
        <cylinder radius="0.024" length="0.006" />
        </geometry>
      <material name="zipper_trim">
        <color rgba="0.08 0.08 0.09 1" />
        </material>
      </visual>
    <visual>
      <origin xyz="0.01 0 0" rpy="0 1.5708 0" />
      <geometry>
        <cylinder radius="0.024" length="0.006" />
        </geometry>
      <material name="zipper_trim">
        <color rgba="0.08 0.08 0.09 1" />
        </material>
      </visual>
    <visual>
      <origin xyz="0 0 0" rpy="0 1.5708 0" />
      <geometry>
        <cylinder radius="0.008" length="0.04" />
        </geometry>
      <material name="hub">
        <color rgba="0.58 0.6 0.63 1" />
        </material>
      </visual>
    <collision name="left_wheel__visual_1">
      <origin xyz="0 0 0" rpy="0 1.5708 0" />
      <geometry>
        <cylinder radius="0.032" length="0.038" />
        </geometry>
      </collision>
    <collision name="left_wheel__visual_2">
      <origin xyz="0 0 0" rpy="0 1.5708 0" />
      <geometry>
        <cylinder radius="0.021" length="0.028" />
        </geometry>
      </collision>
    <collision name="left_wheel__visual_3">
      <origin xyz="-0.01 0 0" rpy="0 1.5708 0" />
      <geometry>
        <cylinder radius="0.024" length="0.006" />
        </geometry>
      </collision>
    <collision name="left_wheel__visual_4">
      <origin xyz="0.01 0 0" rpy="0 1.5708 0" />
      <geometry>
        <cylinder radius="0.024" length="0.006" />
        </geometry>
      </collision>
    <collision name="left_wheel__visual_5">
      <origin xyz="0 0 0" rpy="0 1.5708 0" />
      <geometry>
        <cylinder radius="0.008" length="0.04" />
        </geometry>
      </collision>
    </link>
  <link name="right_wheel">
    <inertial>
      <origin xyz="0 0 0" rpy="0 1.5708 0" />
      <mass value="0.2" />
      <inertia ixx="7.52667e-05" ixy="0" ixz="0" iyy="7.52667e-05" iyz="0" izz="0.0001024" />
      </inertial>
    <visual>
      <origin xyz="0 0 0" rpy="0 1.5708 0" />
      <geometry>
        <cylinder radius="0.032" length="0.038" />
        </geometry>
      <material name="rubber">
        <color rgba="0.05 0.05 0.05 1" />
        </material>
      </visual>
    <visual>
      <origin xyz="0 0 0" rpy="0 1.5708 0" />
      <geometry>
        <cylinder radius="0.021" length="0.028" />
        </geometry>
      <material name="hub">
        <color rgba="0.58 0.6 0.63 1" />
        </material>
      </visual>
    <visual>
      <origin xyz="-0.01 0 0" rpy="0 1.5708 0" />
      <geometry>
        <cylinder radius="0.024" length="0.006" />
        </geometry>
      <material name="zipper_trim">
        <color rgba="0.08 0.08 0.09 1" />
        </material>
      </visual>
    <visual>
      <origin xyz="0.01 0 0" rpy="0 1.5708 0" />
      <geometry>
        <cylinder radius="0.024" length="0.006" />
        </geometry>
      <material name="zipper_trim">
        <color rgba="0.08 0.08 0.09 1" />
        </material>
      </visual>
    <visual>
      <origin xyz="0 0 0" rpy="0 1.5708 0" />
      <geometry>
        <cylinder radius="0.008" length="0.04" />
        </geometry>
      <material name="hub">
        <color rgba="0.58 0.6 0.63 1" />
        </material>
      </visual>
    <collision name="right_wheel__visual_1">
      <origin xyz="0 0 0" rpy="0 1.5708 0" />
      <geometry>
        <cylinder radius="0.032" length="0.038" />
        </geometry>
      </collision>
    <collision name="right_wheel__visual_2">
      <origin xyz="0 0 0" rpy="0 1.5708 0" />
      <geometry>
        <cylinder radius="0.021" length="0.028" />
        </geometry>
      </collision>
    <collision name="right_wheel__visual_3">
      <origin xyz="-0.01 0 0" rpy="0 1.5708 0" />
      <geometry>
        <cylinder radius="0.024" length="0.006" />
        </geometry>
      </collision>
    <collision name="right_wheel__visual_4">
      <origin xyz="0.01 0 0" rpy="0 1.5708 0" />
      <geometry>
        <cylinder radius="0.024" length="0.006" />
        </geometry>
      </collision>
    <collision name="right_wheel__visual_5">
      <origin xyz="0 0 0" rpy="0 1.5708 0" />
      <geometry>
        <cylinder radius="0.008" length="0.04" />
        </geometry>
      </collision>
    </link>
  <link name="pull_handle">
    <inertial>
      <origin xyz="0 0 0.02" rpy="0 0 0" />
      <mass value="0.55" />
      <inertia ixx="0.00362927" ixy="0" ixz="0" iyy="0.00581167" iyz="0" izz="0.00225427" />
      </inertial>
    <visual>
      <origin xyz="-0.095 0 0" rpy="0 0 0" />
      <geometry>
        <cylinder radius="0.0065" length="0.24" />
        </geometry>
      <material name="aluminum">
        <color rgba="0.76 0.78 0.8 1" />
        </material>
      </visual>
    <visual>
      <origin xyz="-0.095 0 -0.102" rpy="0 0 0" />
      <geometry>
        <cylinder radius="0.01" length="0.036" />
        </geometry>
      <material name="zipper_trim">
        <color rgba="0.08 0.08 0.09 1" />
        </material>
      </visual>
    <visual>
      <origin xyz="0.095 0 0" rpy="0 0 0" />
      <geometry>
        <cylinder radius="0.0065" length="0.24" />
        </geometry>
      <material name="aluminum">
        <color rgba="0.76 0.78 0.8 1" />
        </material>
      </visual>
    <visual>
      <origin xyz="0.095 0 -0.102" rpy="0 0 0" />
      <geometry>
        <cylinder radius="0.01" length="0.036" />
        </geometry>
      <material name="zipper_trim">
        <color rgba="0.08 0.08 0.09 1" />
        </material>
      </visual>
    <visual>
      <geometry>
        <box size="0.18 0.018 0.024" />
        </geometry>
      <material name="zipper_trim">
        <color rgba="0.08 0.08 0.09 1" />
        </material>
      </visual>
    <visual>
      <geometry>
        <mesh filename="meshes/pull_handle_grip.obj" />
        </geometry>
      <material name="corner_guard">
        <color rgba="0.11 0.11 0.12 1" />
        </material>
      </visual>
    <visual>
      <origin xyz="0 0 0.15" rpy="0 0 0" />
      <geometry>
        <box size="0.024 0.008 0.006" />
        </geometry>
      <material name="zipper_trim">
        <color rgba="0.08 0.08 0.09 1" />
        </material>
      </visual>
    <collision name="pull_handle__visual_1">
      <origin xyz="-0.095 0 0" rpy="0 0 0" />
      <geometry>
        <cylinder radius="0.0065" length="0.24" />
        </geometry>
      </collision>
    <collision name="pull_handle__visual_2">
      <origin xyz="-0.095 0 -0.102" rpy="0 0 0" />
      <geometry>
        <cylinder radius="0.01" length="0.036" />
        </geometry>
      </collision>
    <collision name="pull_handle__visual_3">
      <origin xyz="0.095 0 0" rpy="0 0 0" />
      <geometry>
        <cylinder radius="0.0065" length="0.24" />
        </geometry>
      </collision>
    <collision name="pull_handle__visual_4">
      <origin xyz="0.095 0 -0.102" rpy="0 0 0" />
      <geometry>
        <cylinder radius="0.01" length="0.036" />
        </geometry>
      </collision>
    <collision name="pull_handle__visual_5">
      <geometry>
        <box size="0.18 0.018 0.024" />
        </geometry>
      </collision>
    <collision name="pull_handle__visual_6__hull_001">
      <geometry>
        <mesh filename="meshes/collision/cache/21a05bc25194ce6d263699b1__hull_001.obj" />
        </geometry>
      </collision>
    <collision name="pull_handle__visual_6__hull_002">
      <geometry>
        <mesh filename="meshes/collision/cache/21a05bc25194ce6d263699b1__hull_002.obj" />
        </geometry>
      </collision>
    <collision name="pull_handle__visual_6__hull_003">
      <geometry>
        <mesh filename="meshes/collision/cache/21a05bc25194ce6d263699b1__hull_003.obj" />
        </geometry>
      </collision>
    <collision name="pull_handle__visual_6__hull_004">
      <geometry>
        <mesh filename="meshes/collision/cache/21a05bc25194ce6d263699b1__hull_004.obj" />
        </geometry>
      </collision>
    <collision name="pull_handle__visual_7">
      <origin xyz="0 0 0.15" rpy="0 0 0" />
      <geometry>
        <box size="0.024 0.008 0.006" />
        </geometry>
      </collision>
    </link>
  <joint name="left_wheel_spin" type="continuous">
    <origin xyz="-0.156 0.116 0.032" rpy="0 0 0" />
    <parent link="case_body" />
    <child link="left_wheel" />
    <axis xyz="1 0 0" />
    <limit effort="8" velocity="25" />
    </joint>
  <joint name="right_wheel_spin" type="continuous">
    <origin xyz="0.156 0.116 0.032" rpy="0 0 0" />
    <parent link="case_body" />
    <child link="right_wheel" />
    <axis xyz="1 0 0" />
    <limit effort="8" velocity="25" />
    </joint>
  <joint name="handle_slide" type="prismatic">
    <origin xyz="0 0.102 0.7" rpy="0 0 0" />
    <parent link="case_body" />
    <child link="pull_handle" />
    <axis xyz="0 0 1" />
    <limit effort="80" velocity="0.6" lower="0" upper="0.26" />
    </joint>
  </robot>
