<robot name="remote_weapon_station">
  <material name="olive_drab">
    <color rgba="0.35 0.38 0.29 1" />
    </material>
  <material name="dark_steel">
    <color rgba="0.22 0.23 0.25 1" />
    </material>
  <material name="brushed_steel">
    <color rgba="0.56 0.58 0.6 1" />
    </material>
  <material name="black_polymer">
    <color rgba="0.1 0.11 0.12 1" />
    </material>
  <material name="sensor_glass">
    <color rgba="0.38 0.52 0.58 0.35" />
    </material>
  <link name="mount_base">
    <inertial>
      <origin xyz="0 0 0.1" rpy="0 0 0" />
      <mass value="92" />
      <inertia ixx="1.63147" ixy="0" ixz="0" iyy="1.63147" iyz="0" izz="2.6496" />
      </inertial>
    <visual>
      <geometry>
        <mesh filename="meshes/mount_base.obj" />
        </geometry>
      <material name="olive_drab">
        <color rgba="0.35 0.38 0.29 1" />
        </material>
      </visual>
    <visual>
      <origin xyz="0 0 0.16" rpy="0 0 0" />
      <geometry>
        <cylinder radius="0.19" length="0.04" />
        </geometry>
      <material name="dark_steel">
        <color rgba="0.22 0.23 0.25 1" />
        </material>
      </visual>
    <visual>
      <origin xyz="0 0 0.181" rpy="0 0 0" />
      <geometry>
        <cylinder radius="0.125" length="0.022" />
        </geometry>
      <material name="dark_steel">
        <color rgba="0.22 0.23 0.25 1" />
        </material>
      </visual>
    <collision name="mount_base__visual_1__hull_001">
      <geometry>
        <mesh filename="meshes/collision/cache/1f1d1aefa6f1f5dfbcb899b1__hull_001.obj" />
        </geometry>
      </collision>
    <collision name="mount_base__visual_1__hull_002">
      <geometry>
        <mesh filename="meshes/collision/cache/1f1d1aefa6f1f5dfbcb899b1__hull_002.obj" />
        </geometry>
      </collision>
    <collision name="mount_base__visual_1__hull_003">
      <geometry>
        <mesh filename="meshes/collision/cache/1f1d1aefa6f1f5dfbcb899b1__hull_003.obj" />
        </geometry>
      </collision>
    <collision name="mount_base__visual_1__hull_004">
      <geometry>
        <mesh filename="meshes/collision/cache/1f1d1aefa6f1f5dfbcb899b1__hull_004.obj" />
        </geometry>
      </collision>
    <collision name="mount_base__visual_1__hull_005">
      <geometry>
        <mesh filename="meshes/collision/cache/1f1d1aefa6f1f5dfbcb899b1__hull_005.obj" />
        </geometry>
      </collision>
    <collision name="mount_base__visual_1__hull_006">
      <geometry>
        <mesh filename="meshes/collision/cache/1f1d1aefa6f1f5dfbcb899b1__hull_006.obj" />
        </geometry>
      </collision>
    <collision name="mount_base__visual_2">
      <origin xyz="0 0 0.16" rpy="0 0 0" />
      <geometry>
        <cylinder radius="0.19" length="0.04" />
        </geometry>
      </collision>
    <collision name="mount_base__visual_3">
      <origin xyz="0 0 0.181" rpy="0 0 0" />
      <geometry>
        <cylinder radius="0.125" length="0.022" />
        </geometry>
      </collision>
    </link>
  <link name="turret_housing">
    <inertial>
      <origin xyz="-0.015 0 0.105" rpy="0 0 0" />
      <mass value="68" />
      <inertia ixx="1.13163" ixy="0" ixz="0" iyy="1.13163" iyz="0" izz="1.31013" />
      </inertial>
    <visual>
      <geometry>
        <mesh filename="meshes/turret_housing.obj" />
        </geometry>
      <material name="olive_drab">
        <color rgba="0.35 0.38 0.29 1" />
        </material>
      </visual>
    <visual>
      <origin xyz="0.095 0 0.102" rpy="1.5708 0 0" />
      <geometry>
        <cylinder radius="0.035" length="0.24" />
        </geometry>
      <material name="dark_steel">
        <color rgba="0.22 0.23 0.25 1" />
        </material>
      </visual>
    <visual>
      <origin xyz="0.118 -0.158 0.132" rpy="0 1.3508 -0.18" />
      <geometry>
        <cylinder radius="0.012" length="0.082" />
        </geometry>
      <material name="dark_steel">
        <color rgba="0.22 0.23 0.25 1" />
        </material>
      </visual>
    <visual>
      <origin xyz="0.118 -0.158 0.157" rpy="0 1.3508 -0.18" />
      <geometry>
        <cylinder radius="0.012" length="0.082" />
        </geometry>
      <material name="dark_steel">
        <color rgba="0.22 0.23 0.25 1" />
        </material>
      </visual>
    <visual>
      <origin xyz="0.118 -0.158 0.182" rpy="0 1.3508 -0.18" />
      <geometry>
        <cylinder radius="0.012" length="0.082" />
        </geometry>
      <material name="dark_steel">
        <color rgba="0.22 0.23 0.25 1" />
        </material>
      </visual>
    <visual>
      <origin xyz="0.118 -0.158 0.207" rpy="0 1.3508 -0.18" />
      <geometry>
        <cylinder radius="0.012" length="0.082" />
        </geometry>
      <material name="dark_steel">
        <color rgba="0.22 0.23 0.25 1" />
        </material>
      </visual>
    <visual>
      <origin xyz="0.118 0.158 0.132" rpy="0 1.3508 0.18" />
      <geometry>
        <cylinder radius="0.012" length="0.082" />
        </geometry>
      <material name="dark_steel">
        <color rgba="0.22 0.23 0.25 1" />
        </material>
      </visual>
    <visual>
      <origin xyz="0.118 0.158 0.157" rpy="0 1.3508 0.18" />
      <geometry>
        <cylinder radius="0.012" length="0.082" />
        </geometry>
      <material name="dark_steel">
        <color rgba="0.22 0.23 0.25 1" />
        </material>
      </visual>
    <visual>
      <origin xyz="0.118 0.158 0.182" rpy="0 1.3508 0.18" />
      <geometry>
        <cylinder radius="0.012" length="0.082" />
        </geometry>
      <material name="dark_steel">
        <color rgba="0.22 0.23 0.25 1" />
        </material>
      </visual>
    <visual>
      <origin xyz="0.118 0.158 0.207" rpy="0 1.3508 0.18" />
      <geometry>
        <cylinder radius="0.012" length="0.082" />
        </geometry>
      <material name="dark_steel">
        <color rgba="0.22 0.23 0.25 1" />
        </material>
      </visual>
    <visual>
      <origin xyz="0.127 0.132 0.18" rpy="0 0 0" />
      <geometry>
        <box size="0.014 0.06 0.048" />
        </geometry>
      <material name="sensor_glass">
        <color rgba="0.38 0.52 0.58 0.35" />
        </material>
      </visual>
    <visual>
      <origin xyz="0.09 0.168 0.18" rpy="0 0 0" />
      <geometry>
        <box size="0.048 0.014 0.044" />
        </geometry>
      <material name="sensor_glass">
        <color rgba="0.38 0.52 0.58 0.35" />
        </material>
      </visual>
    <visual>
      <origin xyz="0.126 0.084 0.173" rpy="0 1.5708 0" />
      <geometry>
        <cylinder radius="0.02" length="0.016" />
        </geometry>
      <material name="sensor_glass">
        <color rgba="0.38 0.52 0.58 0.35" />
        </material>
      </visual>
    <collision name="turret_housing__visual_1__hull_001">
      <geometry>
        <mesh filename="meshes/collision/cache/4c992a5b1be5835fbd9d0137__hull_001.obj" />
        </geometry>
      </collision>
    <collision name="turret_housing__visual_1__hull_002">
      <geometry>
        <mesh filename="meshes/collision/cache/4c992a5b1be5835fbd9d0137__hull_002.obj" />
        </geometry>
      </collision>
    <collision name="turret_housing__visual_1__hull_003">
      <geometry>
        <mesh filename="meshes/collision/cache/4c992a5b1be5835fbd9d0137__hull_003.obj" />
        </geometry>
      </collision>
    <collision name="turret_housing__visual_1__hull_004">
      <geometry>
        <mesh filename="meshes/collision/cache/4c992a5b1be5835fbd9d0137__hull_004.obj" />
        </geometry>
      </collision>
    <collision name="turret_housing__visual_1__hull_005">
      <geometry>
        <mesh filename="meshes/collision/cache/4c992a5b1be5835fbd9d0137__hull_005.obj" />
        </geometry>
      </collision>
    <collision name="turret_housing__visual_1__hull_006">
      <geometry>
        <mesh filename="meshes/collision/cache/4c992a5b1be5835fbd9d0137__hull_006.obj" />
        </geometry>
      </collision>
    <collision name="turret_housing__visual_1__hull_007">
      <geometry>
        <mesh filename="meshes/collision/cache/4c992a5b1be5835fbd9d0137__hull_007.obj" />
        </geometry>
      </collision>
    <collision name="turret_housing__visual_1__hull_008">
      <geometry>
        <mesh filename="meshes/collision/cache/4c992a5b1be5835fbd9d0137__hull_008.obj" />
        </geometry>
      </collision>
    <collision name="turret_housing__visual_1__hull_009">
      <geometry>
        <mesh filename="meshes/collision/cache/4c992a5b1be5835fbd9d0137__hull_009.obj" />
        </geometry>
      </collision>
    <collision name="turret_housing__visual_1__hull_010">
      <geometry>
        <mesh filename="meshes/collision/cache/4c992a5b1be5835fbd9d0137__hull_010.obj" />
        </geometry>
      </collision>
    <collision name="turret_housing__visual_1__hull_011">
      <geometry>
        <mesh filename="meshes/collision/cache/4c992a5b1be5835fbd9d0137__hull_011.obj" />
        </geometry>
      </collision>
    <collision name="turret_housing__visual_1__hull_012">
      <geometry>
        <mesh filename="meshes/collision/cache/4c992a5b1be5835fbd9d0137__hull_012.obj" />
        </geometry>
      </collision>
    <collision name="turret_housing__visual_2">
      <origin xyz="0.095 0 0.102" rpy="1.5708 0 0" />
      <geometry>
        <cylinder radius="0.035" length="0.24" />
        </geometry>
      </collision>
    <collision name="turret_housing__visual_3">
      <origin xyz="0.118 -0.158 0.132" rpy="0 1.3508 -0.18" />
      <geometry>
        <cylinder radius="0.012" length="0.082" />
        </geometry>
      </collision>
    <collision name="turret_housing__visual_4">
      <origin xyz="0.118 -0.158 0.157" rpy="0 1.3508 -0.18" />
      <geometry>
        <cylinder radius="0.012" length="0.082" />
        </geometry>
      </collision>
    <collision name="turret_housing__visual_5">
      <origin xyz="0.118 -0.158 0.182" rpy="0 1.3508 -0.18" />
      <geometry>
        <cylinder radius="0.012" length="0.082" />
        </geometry>
      </collision>
    <collision name="turret_housing__visual_6">
      <origin xyz="0.118 -0.158 0.207" rpy="0 1.3508 -0.18" />
      <geometry>
        <cylinder radius="0.012" length="0.082" />
        </geometry>
      </collision>
    <collision name="turret_housing__visual_7">
      <origin xyz="0.118 0.158 0.132" rpy="0 1.3508 0.18" />
      <geometry>
        <cylinder radius="0.012" length="0.082" />
        </geometry>
      </collision>
    <collision name="turret_housing__visual_8">
      <origin xyz="0.118 0.158 0.157" rpy="0 1.3508 0.18" />
      <geometry>
        <cylinder radius="0.012" length="0.082" />
        </geometry>
      </collision>
    <collision name="turret_housing__visual_9">
      <origin xyz="0.118 0.158 0.182" rpy="0 1.3508 0.18" />
      <geometry>
        <cylinder radius="0.012" length="0.082" />
        </geometry>
      </collision>
    <collision name="turret_housing__visual_10">
      <origin xyz="0.118 0.158 0.207" rpy="0 1.3508 0.18" />
      <geometry>
        <cylinder radius="0.012" length="0.082" />
        </geometry>
      </collision>
    <collision name="turret_housing__visual_11">
      <origin xyz="0.127 0.132 0.18" rpy="0 0 0" />
      <geometry>
        <box size="0.014 0.06 0.048" />
        </geometry>
      </collision>
    <collision name="turret_housing__visual_12">
      <origin xyz="0.09 0.168 0.18" rpy="0 0 0" />
      <geometry>
        <box size="0.048 0.014 0.044" />
        </geometry>
      </collision>
    <collision name="turret_housing__visual_13">
      <origin xyz="0.126 0.084 0.173" rpy="0 1.5708 0" />
      <geometry>
        <cylinder radius="0.02" length="0.016" />
        </geometry>
      </collision>
    </link>
  <link name="weapon_cradle">
    <inertial>
      <origin xyz="0.46 0 0.055" rpy="0 0 0" />
      <mass value="56" />
      <inertia ixx="0.793333" ixy="0" ixz="0" iyy="6.48713" iyz="0" izz="6.64953" />
      </inertial>
    <visual>
      <geometry>
        <mesh filename="meshes/weapon_cradle.obj" />
        </geometry>
      <material name="olive_drab">
        <color rgba="0.35 0.38 0.29 1" />
        </material>
      </visual>
    <visual>
      <origin xyz="0 0 0" rpy="1.5708 0 0" />
      <geometry>
        <cylinder radius="0.032" length="0.22" />
        </geometry>
      <material name="dark_steel">
        <color rgba="0.22 0.23 0.25 1" />
        </material>
      </visual>
    <visual>
      <origin xyz="0.35 0 0.05" rpy="0 1.5708 0" />
      <geometry>
        <cylinder radius="0.05" length="0.28" />
        </geometry>
      <material name="dark_steel">
        <color rgba="0.22 0.23 0.25 1" />
        </material>
      </visual>
    <visual>
      <origin xyz="0.52 0 0.05" rpy="0 1.5708 0" />
      <geometry>
        <cylinder radius="0.036" length="0.33" />
        </geometry>
      <material name="black_polymer">
        <color rgba="0.1 0.11 0.12 1" />
        </material>
      </visual>
    <visual>
      <origin xyz="0.7 0 0.05" rpy="0 1.5708 0" />
      <geometry>
        <cylinder radius="0.022" length="0.72" />
        </geometry>
      <material name="dark_steel">
        <color rgba="0.22 0.23 0.25 1" />
        </material>
      </visual>
    <visual>
      <origin xyz="0.42 0 -0.02" rpy="0 1.5708 0" />
      <geometry>
        <cylinder radius="0.026" length="0.35" />
        </geometry>
      <material name="dark_steel">
        <color rgba="0.22 0.23 0.25 1" />
        </material>
      </visual>
    <visual>
      <origin xyz="1.09 0 0.05" rpy="0 1.5708 0" />
      <geometry>
        <cylinder radius="0.03" length="0.1" />
        </geometry>
      <material name="brushed_steel">
        <color rgba="0.56 0.58 0.6 1" />
        </material>
      </visual>
    <visual>
      <origin xyz="1.04 0 0.05" rpy="0 1.5708 0" />
      <geometry>
        <cylinder radius="0.035" length="0.024" />
        </geometry>
      <material name="brushed_steel">
        <color rgba="0.56 0.58 0.6 1" />
        </material>
      </visual>
    <visual>
      <geometry>
        <mesh filename="meshes/feed_chute.obj" />
        </geometry>
      <material name="black_polymer">
        <color rgba="0.1 0.11 0.12 1" />
        </material>
      </visual>
    <collision name="weapon_cradle__visual_1__hull_001">
      <geometry>
        <mesh filename="meshes/collision/cache/c2653c00799c55d12324098d__hull_001.obj" />
        </geometry>
      </collision>
    <collision name="weapon_cradle__visual_1__hull_002">
      <geometry>
        <mesh filename="meshes/collision/cache/c2653c00799c55d12324098d__hull_002.obj" />
        </geometry>
      </collision>
    <collision name="weapon_cradle__visual_1__hull_003">
      <geometry>
        <mesh filename="meshes/collision/cache/c2653c00799c55d12324098d__hull_003.obj" />
        </geometry>
      </collision>
    <collision name="weapon_cradle__visual_1__hull_004">
      <geometry>
        <mesh filename="meshes/collision/cache/c2653c00799c55d12324098d__hull_004.obj" />
        </geometry>
      </collision>
    <collision name="weapon_cradle__visual_1__hull_005">
      <geometry>
        <mesh filename="meshes/collision/cache/c2653c00799c55d12324098d__hull_005.obj" />
        </geometry>
      </collision>
    <collision name="weapon_cradle__visual_1__hull_006">
      <geometry>
        <mesh filename="meshes/collision/cache/c2653c00799c55d12324098d__hull_006.obj" />
        </geometry>
      </collision>
    <collision name="weapon_cradle__visual_1__hull_007">
      <geometry>
        <mesh filename="meshes/collision/cache/c2653c00799c55d12324098d__hull_007.obj" />
        </geometry>
      </collision>
    <collision name="weapon_cradle__visual_1__hull_008">
      <geometry>
        <mesh filename="meshes/collision/cache/c2653c00799c55d12324098d__hull_008.obj" />
        </geometry>
      </collision>
    <collision name="weapon_cradle__visual_1__hull_009">
      <geometry>
        <mesh filename="meshes/collision/cache/c2653c00799c55d12324098d__hull_009.obj" />
        </geometry>
      </collision>
    <collision name="weapon_cradle__visual_1__hull_010">
      <geometry>
        <mesh filename="meshes/collision/cache/c2653c00799c55d12324098d__hull_010.obj" />
        </geometry>
      </collision>
    <collision name="weapon_cradle__visual_1__hull_011">
      <geometry>
        <mesh filename="meshes/collision/cache/c2653c00799c55d12324098d__hull_011.obj" />
        </geometry>
      </collision>
    <collision name="weapon_cradle__visual_1__hull_012">
      <geometry>
        <mesh filename="meshes/collision/cache/c2653c00799c55d12324098d__hull_012.obj" />
        </geometry>
      </collision>
    <collision name="weapon_cradle__visual_1__hull_013">
      <geometry>
        <mesh filename="meshes/collision/cache/c2653c00799c55d12324098d__hull_013.obj" />
        </geometry>
      </collision>
    <collision name="weapon_cradle__visual_2">
      <origin xyz="0 0 0" rpy="1.5708 0 0" />
      <geometry>
        <cylinder radius="0.032" length="0.22" />
        </geometry>
      </collision>
    <collision name="weapon_cradle__visual_3">
      <origin xyz="0.35 0 0.05" rpy="0 1.5708 0" />
      <geometry>
        <cylinder radius="0.05" length="0.28" />
        </geometry>
      </collision>
    <collision name="weapon_cradle__visual_4">
      <origin xyz="0.52 0 0.05" rpy="0 1.5708 0" />
      <geometry>
        <cylinder radius="0.036" length="0.33" />
        </geometry>
      </collision>
    <collision name="weapon_cradle__visual_5">
      <origin xyz="0.7 0 0.05" rpy="0 1.5708 0" />
      <geometry>
        <cylinder radius="0.022" length="0.72" />
        </geometry>
      </collision>
    <collision name="weapon_cradle__visual_6">
      <origin xyz="0.42 0 -0.02" rpy="0 1.5708 0" />
      <geometry>
        <cylinder radius="0.026" length="0.35" />
        </geometry>
      </collision>
    <collision name="weapon_cradle__visual_7">
      <origin xyz="1.09 0 0.05" rpy="0 1.5708 0" />
      <geometry>
        <cylinder radius="0.03" length="0.1" />
        </geometry>
      </collision>
    <collision name="weapon_cradle__visual_8">
      <origin xyz="1.04 0 0.05" rpy="0 1.5708 0" />
      <geometry>
        <cylinder radius="0.035" length="0.024" />
        </geometry>
      </collision>
    <collision name="weapon_cradle__visual_9__hull_001">
      <geometry>
        <mesh filename="meshes/collision/cache/4e8f5ba8542b139cb0fd1c8d__hull_001.obj" />
        </geometry>
      </collision>
    <collision name="weapon_cradle__visual_9__hull_002">
      <geometry>
        <mesh filename="meshes/collision/cache/4e8f5ba8542b139cb0fd1c8d__hull_002.obj" />
        </geometry>
      </collision>
    <collision name="weapon_cradle__visual_9__hull_003">
      <geometry>
        <mesh filename="meshes/collision/cache/4e8f5ba8542b139cb0fd1c8d__hull_003.obj" />
        </geometry>
      </collision>
    </link>
  <joint name="turret_pan" type="continuous">
    <origin xyz="0 0 0.16" rpy="0 0 0" />
    <parent link="mount_base" />
    <child link="turret_housing" />
    <axis xyz="0 0 1" />
    <limit effort="1800" velocity="1" />
    </joint>
  <joint name="weapon_elevation" type="revolute">
    <origin xyz="0.095 0 0.102" rpy="0 0 0" />
    <parent link="turret_housing" />
    <child link="weapon_cradle" />
    <axis xyz="0 -1 0" />
    <limit effort="1200" velocity="1.2" lower="-0.18" upper="1" />
    </joint>
  </robot>
