<robot name="premium_lounge_chair">
  <material name="upholstery_taupe">
    <color rgba="0.66 0.61 0.57 1" />
    </material>
  <material name="walnut_trim">
    <color rgba="0.41 0.27 0.16 1" />
    </material>
  <material name="black_metal">
    <color rgba="0.13 0.13 0.14 1" />
    </material>
  <material name="charcoal_fabric">
    <color rgba="0.22 0.22 0.24 1" />
    </material>
  <link name="base">
    <inertial>
      <origin xyz="0 0 0.29" rpy="0 0 0" />
      <mass value="34" />
      <inertia ixx="2.58967" ixy="0" ixz="0" iyy="3.14727" iyz="0" izz="3.83067" />
      </inertial>
    <visual name="left_side_cheek">
      <origin xyz="-0.39 0 0.25" rpy="0 0 0" />
      <geometry>
        <mesh filename="assets/meshes/side_cheek.obj" />
        </geometry>
      <material name="walnut_trim">
        <color rgba="0.41 0.27 0.16 1" />
        </material>
      </visual>
    <visual name="right_side_cheek">
      <origin xyz="0.39 0 0.25" rpy="0 0 0" />
      <geometry>
        <mesh filename="assets/meshes/side_cheek.obj" />
        </geometry>
      <material name="walnut_trim">
        <color rgba="0.41 0.27 0.16 1" />
        </material>
      </visual>
    <visual name="seat_shell">
      <origin xyz="0 0 0.34" rpy="0 0 0" />
      <geometry>
        <mesh filename="assets/meshes/seat_shell.obj" />
        </geometry>
      <material name="upholstery_taupe">
        <color rgba="0.66 0.61 0.57 1" />
        </material>
      </visual>
    <visual name="seat_cushion">
      <origin xyz="0 0.01 0.445" rpy="-0.05 0 0" />
      <geometry>
        <mesh filename="assets/meshes/seat_cushion.obj" />
        </geometry>
      <material name="upholstery_taupe">
        <color rgba="0.66 0.61 0.57 1" />
        </material>
      </visual>
    <visual name="left_arm_pad">
      <origin xyz="-0.33 0 0.525" rpy="0 0 0" />
      <geometry>
        <mesh filename="assets/meshes/arm_pad.obj" />
        </geometry>
      <material name="upholstery_taupe">
        <color rgba="0.66 0.61 0.57 1" />
        </material>
      </visual>
    <visual name="right_arm_pad">
      <origin xyz="0.33 0 0.525" rpy="0 0 0" />
      <geometry>
        <mesh filename="assets/meshes/arm_pad.obj" />
        </geometry>
      <material name="upholstery_taupe">
        <color rgba="0.66 0.61 0.57 1" />
        </material>
      </visual>
    <visual name="front_stretcher">
      <origin xyz="0 0.255 0.11" rpy="0 1.5708 0" />
      <geometry>
        <cylinder radius="0.015" length="0.78" />
        </geometry>
      <material name="black_metal">
        <color rgba="0.13 0.13 0.14 1" />
        </material>
      </visual>
    <visual name="rear_stretcher">
      <origin xyz="0 -0.255 0.11" rpy="0 1.5708 0" />
      <geometry>
        <cylinder radius="0.015" length="0.78" />
        </geometry>
      <material name="black_metal">
        <color rgba="0.13 0.13 0.14 1" />
        </material>
      </visual>
    <visual name="footrest_hinge_beam">
      <origin xyz="0 0.315 0.2525" rpy="0 0 0" />
      <geometry>
        <box size="0.6 0.06 0.07" />
        </geometry>
      <material name="black_metal">
        <color rgba="0.13 0.13 0.14 1" />
        </material>
      </visual>
    <visual name="backrest_mount_beam">
      <origin xyz="0 -0.315 0.42" rpy="0 0 0" />
      <geometry>
        <box size="0.6 0.06 0.06" />
        </geometry>
      <material name="black_metal">
        <color rgba="0.13 0.13 0.14 1" />
        </material>
      </visual>
    </link>
  <link name="backrest">
    <inertial>
      <origin xyz="0 -0.055 0.4" rpy="0 0 0" />
      <mass value="10" />
      <inertia ixx="0.587333" ixy="0" ixz="0" iyy="0.923333" iyz="0" izz="0.39" />
      </inertial>
    <visual name="backrest_hinge_tube">
      <origin xyz="0 0 0.018" rpy="0 1.5708 0" />
      <geometry>
        <cylinder radius="0.018" length="0.46" />
        </geometry>
      <material name="black_metal">
        <color rgba="0.13 0.13 0.14 1" />
        </material>
      </visual>
    <visual name="left_backrest_bracket">
      <origin xyz="-0.23 -0.025 0.07" rpy="0 0 0" />
      <geometry>
        <box size="0.05 0.045 0.11" />
        </geometry>
      <material name="black_metal">
        <color rgba="0.13 0.13 0.14 1" />
        </material>
      </visual>
    <visual name="right_backrest_bracket">
      <origin xyz="0.23 -0.025 0.07" rpy="0 0 0" />
      <geometry>
        <box size="0.05 0.045 0.11" />
        </geometry>
      <material name="black_metal">
        <color rgba="0.13 0.13 0.14 1" />
        </material>
      </visual>
    <visual name="backrest_cushion">
      <origin xyz="0 0 0.06" rpy="0.09 0 0" />
      <geometry>
        <mesh filename="assets/meshes/backrest_cushion.obj" />
        </geometry>
      <material name="upholstery_taupe">
        <color rgba="0.66 0.61 0.57 1" />
        </material>
      </visual>
    <visual name="back_panel">
      <origin xyz="0 -0.078 0.345" rpy="0.09 0 0" />
      <geometry>
        <box size="0.54 0.025 0.56" />
        </geometry>
      <material name="charcoal_fabric">
        <color rgba="0.22 0.22 0.24 1" />
        </material>
      </visual>
    <visual name="head_pillow">
      <origin xyz="0 -0.01 0.72" rpy="0.09 0 0" />
      <geometry>
        <mesh filename="assets/meshes/head_pillow.obj" />
        </geometry>
      <material name="upholstery_taupe">
        <color rgba="0.66 0.61 0.57 1" />
        </material>
      </visual>
    </link>
  <link name="footrest">
    <inertial>
      <origin xyz="0 0.22 -0.05" rpy="0 0 0" />
      <mass value="5" />
      <inertia ixx="0.0785417" ixy="0" ixz="0" iyy="0.135708" iyz="0" izz="0.204167" />
      </inertial>
    <visual name="footrest_hinge_tube">
      <origin xyz="0 0 0.014" rpy="0 1.5708 0" />
      <geometry>
        <cylinder radius="0.014" length="0.44" />
        </geometry>
      <material name="black_metal">
        <color rgba="0.13 0.13 0.14 1" />
        </material>
      </visual>
    <visual name="footrest_cushion">
      <origin xyz="0 0.11 -0.005" rpy="0 0 0" />
      <geometry>
        <mesh filename="assets/meshes/footrest_cushion.obj" />
        </geometry>
      <material name="upholstery_taupe">
        <color rgba="0.66 0.61 0.57 1" />
        </material>
      </visual>
    <visual name="footrest_support_panel">
      <origin xyz="0 0.21 -0.038" rpy="0 0 0" />
      <geometry>
        <box size="0.48 0.32 0.018" />
        </geometry>
      <material name="charcoal_fabric">
        <color rgba="0.22 0.22 0.24 1" />
        </material>
      </visual>
    <visual name="left_footrest_link">
      <origin xyz="-0.22 0.09 -0.015" rpy="0 0 0" />
      <geometry>
        <box size="0.025 0.18 0.06" />
        </geometry>
      <material name="black_metal">
        <color rgba="0.13 0.13 0.14 1" />
        </material>
      </visual>
    <visual name="right_footrest_link">
      <origin xyz="0.22 0.09 -0.015" rpy="0 0 0" />
      <geometry>
        <box size="0.025 0.18 0.06" />
        </geometry>
      <material name="black_metal">
        <color rgba="0.13 0.13 0.14 1" />
        </material>
      </visual>
    </link>
  <joint name="backrest_hinge" type="revolute">
    <origin xyz="0 -0.325 0.455" rpy="0 0 0" />
    <parent link="base" />
    <child link="backrest" />
    <axis xyz="1 0 0" />
    <limit effort="40" velocity="1.5" lower="0" upper="0.58" />
    </joint>
  <joint name="footrest_hinge" type="revolute">
    <origin xyz="0 0.315 0.245" rpy="0 0 0" />
    <parent link="base" />
    <child link="footrest" />
    <axis xyz="1 0 0" />
    <limit effort="30" velocity="2" lower="0" upper="1.05" />
    </joint>
  </robot>
