<robot name="portal_gantry_axis">
  <material name="frame_aluminum">
    <color rgba="0.74 0.75 0.77 1" />
    </material>
  <material name="rail_steel">
    <color rgba="0.28 0.3 0.33 1" />
    </material>
  <material name="carriage_body">
    <color rgba="0.18 0.2 0.23 1" />
    </material>
  <material name="slide_body">
    <color rgba="0.86 0.87 0.88 1" />
    </material>
  <material name="accent_blue">
    <color rgba="0.15 0.42 0.78 1" />
    </material>
  <material name="tool_steel">
    <color rgba="0.42 0.44 0.48 1" />
    </material>
  <link name="frame">
    <inertial>
      <origin xyz="0 0 0.35" rpy="0 0 0" />
      <mass value="34" />
      <inertia ixx="1.48013" ixy="0" ixz="0" iyy="2.93987" iyz="0" izz="1.64333" />
      </inertial>
    <visual>
      <origin xyz="-0.27 0 0.02" rpy="0 0 0" />
      <geometry>
        <box size="0.2 0.16 0.04" />
        </geometry>
      <material name="frame_aluminum" />
      </visual>
    <visual>
      <origin xyz="0.27 0 0.02" rpy="0 0 0" />
      <geometry>
        <box size="0.2 0.16 0.04" />
        </geometry>
      <material name="frame_aluminum" />
      </visual>
    <visual>
      <origin xyz="-0.27 0 0.329" rpy="0 0 0" />
      <geometry>
        <box size="0.08 0.12 0.582" />
        </geometry>
      <material name="frame_aluminum" />
      </visual>
    <visual>
      <origin xyz="0.27 0 0.329" rpy="0 0 0" />
      <geometry>
        <box size="0.08 0.12 0.582" />
        </geometry>
      <material name="frame_aluminum" />
      </visual>
    <visual>
      <origin xyz="0 0 0.66" rpy="0 0 0" />
      <geometry>
        <box size="0.62 0.12 0.08" />
        </geometry>
      <material name="frame_aluminum" />
      </visual>
    <visual>
      <origin xyz="0 0 0.07" rpy="0 0 0" />
      <geometry>
        <box size="0.36 0.08 0.06" />
        </geometry>
      <material name="frame_aluminum" />
      </visual>
    <visual>
      <origin xyz="0 -0.02 0.18" rpy="0 0 0" />
      <geometry>
        <box size="0.46 0.06 0.05" />
        </geometry>
      <material name="frame_aluminum" />
      </visual>
    <visual>
      <origin xyz="0 0.054 0.682" rpy="0 0 0" />
      <geometry>
        <box size="0.56 0.012 0.018" />
        </geometry>
      <material name="rail_steel" />
      </visual>
    <visual>
      <origin xyz="0 0.054 0.638" rpy="0 0 0" />
      <geometry>
        <box size="0.56 0.012 0.018" />
        </geometry>
      <material name="rail_steel" />
      </visual>
    <visual>
      <origin xyz="-0.27 0 0.665" rpy="0 0 0" />
      <geometry>
        <box size="0.1 0.04 0.03" />
        </geometry>
      <material name="accent_blue" />
      </visual>
    <visual>
      <origin xyz="0.27 0 0.665" rpy="0 0 0" />
      <geometry>
        <box size="0.1 0.04 0.03" />
        </geometry>
      <material name="accent_blue" />
      </visual>
    <collision name="frame__visual_1">
      <origin xyz="-0.27 0 0.02" rpy="0 0 0" />
      <geometry>
        <box size="0.2 0.16 0.04" />
        </geometry>
      </collision>
    <collision name="frame__visual_2">
      <origin xyz="0.27 0 0.02" rpy="0 0 0" />
      <geometry>
        <box size="0.2 0.16 0.04" />
        </geometry>
      </collision>
    <collision name="frame__visual_3">
      <origin xyz="-0.27 0 0.329" rpy="0 0 0" />
      <geometry>
        <box size="0.08 0.12 0.582" />
        </geometry>
      </collision>
    <collision name="frame__visual_4">
      <origin xyz="0.27 0 0.329" rpy="0 0 0" />
      <geometry>
        <box size="0.08 0.12 0.582" />
        </geometry>
      </collision>
    <collision name="frame__visual_5">
      <origin xyz="0 0 0.66" rpy="0 0 0" />
      <geometry>
        <box size="0.62 0.12 0.08" />
        </geometry>
      </collision>
    <collision name="frame__visual_6">
      <origin xyz="0 0 0.07" rpy="0 0 0" />
      <geometry>
        <box size="0.36 0.08 0.06" />
        </geometry>
      </collision>
    <collision name="frame__visual_7">
      <origin xyz="0 -0.02 0.18" rpy="0 0 0" />
      <geometry>
        <box size="0.46 0.06 0.05" />
        </geometry>
      </collision>
    <collision name="frame__visual_8">
      <origin xyz="0 0.054 0.682" rpy="0 0 0" />
      <geometry>
        <box size="0.56 0.012 0.018" />
        </geometry>
      </collision>
    <collision name="frame__visual_9">
      <origin xyz="0 0.054 0.638" rpy="0 0 0" />
      <geometry>
        <box size="0.56 0.012 0.018" />
        </geometry>
      </collision>
    <collision name="frame__visual_10">
      <origin xyz="-0.27 0 0.665" rpy="0 0 0" />
      <geometry>
        <box size="0.1 0.04 0.03" />
        </geometry>
      </collision>
    <collision name="frame__visual_11">
      <origin xyz="0.27 0 0.665" rpy="0 0 0" />
      <geometry>
        <box size="0.1 0.04 0.03" />
        </geometry>
      </collision>
    </link>
  <link name="carriage">
    <inertial>
      <origin xyz="0 0.01 -0.19" rpy="0 0 0" />
      <mass value="7.5" />
      <inertia ixx="0.209312" ixy="0" ixz="0" iyy="0.223312" iyz="0" izz="0.0265" />
      </inertial>
    <visual>
      <geometry>
        <box size="0.17 0.086 0.14" />
        </geometry>
      <material name="carriage_body" />
      </visual>
    <visual>
      <origin xyz="0 0.018 -0.29" rpy="0 0 0" />
      <geometry>
        <box size="0.16 0.052 0.44" />
        </geometry>
      <material name="slide_body" />
      </visual>
    <visual>
      <origin xyz="-0.05 0.032 -0.27" rpy="0 0 0" />
      <geometry>
        <box size="0.024 0.014 0.4" />
        </geometry>
      <material name="rail_steel" />
      </visual>
    <visual>
      <origin xyz="0.05 0.032 -0.27" rpy="0 0 0" />
      <geometry>
        <box size="0.024 0.014 0.4" />
        </geometry>
      <material name="rail_steel" />
      </visual>
    <visual>
      <origin xyz="0 0.03 -0.27" rpy="0 0 0" />
      <geometry>
        <box size="0.032 0.022 0.42" />
        </geometry>
      <material name="carriage_body" />
      </visual>
    <visual>
      <origin xyz="0 -0.005 0.095" rpy="0 0 0" />
      <geometry>
        <box size="0.09 0.05 0.06" />
        </geometry>
      <material name="accent_blue" />
      </visual>
    <visual>
      <origin xyz="0 -0.028 0.04" rpy="0 0 0" />
      <geometry>
        <box size="0.11 0.028 0.02" />
        </geometry>
      <material name="tool_steel" />
      </visual>
    <visual>
      <origin xyz="0 -0.028 -0.04" rpy="0 0 0" />
      <geometry>
        <box size="0.11 0.028 0.02" />
        </geometry>
      <material name="tool_steel" />
      </visual>
    <collision name="carriage__visual_1">
      <geometry>
        <box size="0.17 0.086 0.14" />
        </geometry>
      </collision>
    <collision name="carriage__visual_2">
      <origin xyz="0 0.018 -0.29" rpy="0 0 0" />
      <geometry>
        <box size="0.16 0.052 0.44" />
        </geometry>
      </collision>
    <collision name="carriage__visual_3">
      <origin xyz="-0.05 0.032 -0.27" rpy="0 0 0" />
      <geometry>
        <box size="0.024 0.014 0.4" />
        </geometry>
      </collision>
    <collision name="carriage__visual_4">
      <origin xyz="0.05 0.032 -0.27" rpy="0 0 0" />
      <geometry>
        <box size="0.024 0.014 0.4" />
        </geometry>
      </collision>
    <collision name="carriage__visual_5">
      <origin xyz="0 0.03 -0.27" rpy="0 0 0" />
      <geometry>
        <box size="0.032 0.022 0.42" />
        </geometry>
      </collision>
    <collision name="carriage__visual_6">
      <origin xyz="0 -0.005 0.095" rpy="0 0 0" />
      <geometry>
        <box size="0.09 0.05 0.06" />
        </geometry>
      </collision>
    <collision name="carriage__visual_7">
      <origin xyz="0 -0.028 0.04" rpy="0 0 0" />
      <geometry>
        <box size="0.11 0.028 0.02" />
        </geometry>
      </collision>
    <collision name="carriage__visual_8">
      <origin xyz="0 -0.028 -0.04" rpy="0 0 0" />
      <geometry>
        <box size="0.11 0.028 0.02" />
        </geometry>
      </collision>
    </link>
  <link name="slide">
    <inertial>
      <origin xyz="0 0.018 -0.19" rpy="0 0 0" />
      <mass value="4.2" />
      <inertia ixx="0.05075" ixy="0" ixz="0" iyy="0.054775" iyz="0" izz="0.009695" />
      </inertial>
    <visual>
      <origin xyz="0 0 -0.12" rpy="0 0 0" />
      <geometry>
        <box size="0.13 0.036 0.26" />
        </geometry>
      <material name="slide_body" />
      </visual>
    <visual>
      <origin xyz="0 -0.02 -0.12" rpy="0 0 0" />
      <geometry>
        <box size="0.1 0.052 0.18" />
        </geometry>
      <material name="carriage_body" />
      </visual>
    <visual>
      <origin xyz="-0.05 0 -0.05" rpy="0 0 0" />
      <geometry>
        <box size="0.035 0.022 0.05" />
        </geometry>
      <material name="tool_steel" />
      </visual>
    <visual>
      <origin xyz="0.05 0 -0.05" rpy="0 0 0" />
      <geometry>
        <box size="0.035 0.022 0.05" />
        </geometry>
      <material name="tool_steel" />
      </visual>
    <visual>
      <origin xyz="-0.05 0 -0.17" rpy="0 0 0" />
      <geometry>
        <box size="0.035 0.022 0.05" />
        </geometry>
      <material name="tool_steel" />
      </visual>
    <visual>
      <origin xyz="0.05 0 -0.17" rpy="0 0 0" />
      <geometry>
        <box size="0.035 0.022 0.05" />
        </geometry>
      <material name="tool_steel" />
      </visual>
    <visual>
      <origin xyz="0 0.018 -0.305" rpy="0 0 0" />
      <geometry>
        <box size="0.082 0.054 0.11" />
        </geometry>
      <material name="carriage_body" />
      </visual>
    <visual>
      <origin xyz="0 0.004 -0.215" rpy="0 0 0" />
      <geometry>
        <box size="0.1 0.018 0.028" />
        </geometry>
      <material name="accent_blue" />
      </visual>
    <visual>
      <origin xyz="0 0.045 -0.33" rpy="1.5708 0 0" />
      <geometry>
        <cylinder radius="0.018" length="0.045" />
        </geometry>
      <material name="tool_steel" />
      </visual>
    <collision name="slide__visual_1">
      <origin xyz="0 0 -0.12" rpy="0 0 0" />
      <geometry>
        <box size="0.13 0.036 0.26" />
        </geometry>
      </collision>
    <collision name="slide__visual_2">
      <origin xyz="0 -0.02 -0.12" rpy="0 0 0" />
      <geometry>
        <box size="0.1 0.052 0.18" />
        </geometry>
      </collision>
    <collision name="slide__visual_3">
      <origin xyz="-0.05 0 -0.05" rpy="0 0 0" />
      <geometry>
        <box size="0.035 0.022 0.05" />
        </geometry>
      </collision>
    <collision name="slide__visual_4">
      <origin xyz="0.05 0 -0.05" rpy="0 0 0" />
      <geometry>
        <box size="0.035 0.022 0.05" />
        </geometry>
      </collision>
    <collision name="slide__visual_5">
      <origin xyz="-0.05 0 -0.17" rpy="0 0 0" />
      <geometry>
        <box size="0.035 0.022 0.05" />
        </geometry>
      </collision>
    <collision name="slide__visual_6">
      <origin xyz="0.05 0 -0.17" rpy="0 0 0" />
      <geometry>
        <box size="0.035 0.022 0.05" />
        </geometry>
      </collision>
    <collision name="slide__visual_7">
      <origin xyz="0 0.018 -0.305" rpy="0 0 0" />
      <geometry>
        <box size="0.082 0.054 0.11" />
        </geometry>
      </collision>
    <collision name="slide__visual_8">
      <origin xyz="0 0.004 -0.215" rpy="0 0 0" />
      <geometry>
        <box size="0.1 0.018 0.028" />
        </geometry>
      </collision>
    <collision name="slide__visual_9">
      <origin xyz="0 0.045 -0.33" rpy="1.5708 0 0" />
      <geometry>
        <cylinder radius="0.018" length="0.045" />
        </geometry>
      </collision>
    </link>
  <joint name="frame_to_carriage" type="prismatic">
    <origin xyz="0 0.055 0.66" rpy="0 0 0" />
    <parent link="frame" />
    <child link="carriage" />
    <axis xyz="1 0 0" />
    <limit effort="450" velocity="0.8" lower="-0.13" upper="0.13" />
    </joint>
  <joint name="carriage_to_slide" type="prismatic">
    <origin xyz="0 0.032 -0.08" rpy="0 0 0" />
    <parent link="carriage" />
    <child link="slide" />
    <axis xyz="0 0 -1" />
    <limit effort="220" velocity="0.5" lower="0" upper="0.18" />
    </joint>
  </robot>
