<robot name="trigger_spray_bottle">
  <link name="bottle">
    <inertial>
      <origin xyz="0 0 0.132" rpy="0 0 0" />
      <mass value="0.7" />
      <inertia ixx="0.00446979" ixy="0" ixz="0" iyy="0.00467979" iyz="0" izz="0.000956667" />
    </inertial>
    <visual name="body_shell">
      <geometry>
        <mesh filename="meshes/spray_bottle_body.glb" />
      </geometry>
      <material name="translucent_cleaner_blue">
        <color rgba="0.73 0.87 0.96 0.36" />
      </material>
    </visual>
    <visual name="liquid_fill">
      <geometry>
        <mesh filename="meshes/spray_bottle_liquid.glb" />
      </geometry>
      <material name="cleaner_liquid_blue">
        <color rgba="0.3 0.6 0.86 0.52" />
      </material>
    </visual>
    <visual name="bottle_shoulder">
      <geometry>
        <mesh filename="meshes/spray_bottle_shoulder.glb" />
      </geometry>
      <material name="translucent_cleaner_blue">
        <color rgba="0.73 0.87 0.96 0.36" />
      </material>
    </visual>
    <visual name="neck">
      <origin xyz="0 0 0.233" rpy="0 0 0" />
      <geometry>
        <cylinder radius="0.0185" length="0.04" />
      </geometry>
      <material name="translucent_cleaner_blue">
        <color rgba="0.73 0.87 0.96 0.36" />
      </material>
    </visual>
    <visual name="closure_cap">
      <origin xyz="0 0 0.248" rpy="0 0 0" />
      <geometry>
        <cylinder radius="0.0245" length="0.024" />
      </geometry>
      <material name="sprayer_white">
        <color rgba="0.96 0.96 0.95 1" />
      </material>
    </visual>
    <visual name="cap_top_ring">
      <origin xyz="0 0 0.26" rpy="0 0 0" />
      <geometry>
        <cylinder radius="0.0265" length="0.004" />
      </geometry>
      <material name="sprayer_white">
        <color rgba="0.96 0.96 0.95 1" />
      </material>
    </visual>
    <visual name="base_ring">
      <origin xyz="0 0 0.003" rpy="0 0 0" />
      <geometry>
        <cylinder radius="0.036" length="0.006" />
      </geometry>
      <material name="translucent_cleaner_blue">
        <color rgba="0.73 0.87 0.96 0.36" />
      </material>
    </visual>
    <visual name="front_label_panel">
      <origin xyz="0 0.032 0.104" rpy="0 0 0" />
      <geometry>
        <box size="0.055 0.0025 0.086" />
      </geometry>
      <material name="label_white">
        <color rgba="0.98 0.98 0.97 1" />
      </material>
    </visual>
    <visual name="right_grip_strip">
      <origin xyz="0.041 0.002 0.11" rpy="0 0 0" />
      <geometry>
        <box size="0.004 0.024 0.08" />
      </geometry>
      <material name="charcoal_plastic">
        <color rgba="0.18 0.18 0.2 1" />
      </material>
    </visual>
    <visual name="left_grip_strip">
      <origin xyz="-0.041 0.002 0.11" rpy="0 0 0" />
      <geometry>
        <box size="0.004 0.024 0.08" />
      </geometry>
      <material name="charcoal_plastic">
        <color rgba="0.18 0.18 0.2 1" />
      </material>
    </visual>
    <visual name="dip_tube">
      <geometry>
        <mesh filename="meshes/spray_bottle_dip_tube.glb" />
      </geometry>
      <material name="natural_tube">
        <color rgba="0.9 0.92 0.9 0.78" />
      </material>
    </visual>
    <collision name="bottle__body_shell__hull_001">
      <geometry>
        <mesh filename="meshes/collision/cache/37696459334c190e78fe9381__hull_001.obj" />
      </geometry>
    </collision>
    <collision name="bottle__liquid_fill__hull_001">
      <geometry>
        <mesh filename="meshes/collision/cache/d83a7d85919e5076986e8e95__hull_001.obj" />
      </geometry>
    </collision>
    <collision name="bottle__bottle_shoulder__hull_001">
      <geometry>
        <mesh filename="meshes/collision/cache/b0efd9b1755ee1fa03213504__hull_001.obj" />
      </geometry>
    </collision>
    <collision name="bottle__bottle_shoulder__hull_002">
      <geometry>
        <mesh filename="meshes/collision/cache/b0efd9b1755ee1fa03213504__hull_002.obj" />
      </geometry>
    </collision>
    <collision name="bottle__neck">
      <origin xyz="0 0 0.233" rpy="0 0 0" />
      <geometry>
        <cylinder radius="0.0185" length="0.04" />
      </geometry>
    </collision>
    <collision name="bottle__closure_cap">
      <origin xyz="0 0 0.248" rpy="0 0 0" />
      <geometry>
        <cylinder radius="0.0245" length="0.024" />
      </geometry>
    </collision>
    <collision name="bottle__cap_top_ring">
      <origin xyz="0 0 0.26" rpy="0 0 0" />
      <geometry>
        <cylinder radius="0.0265" length="0.004" />
      </geometry>
    </collision>
    <collision name="bottle__base_ring">
      <origin xyz="0 0 0.003" rpy="0 0 0" />
      <geometry>
        <cylinder radius="0.036" length="0.006" />
      </geometry>
    </collision>
    <collision name="bottle__front_label_panel">
      <origin xyz="0 0.032 0.104" rpy="0 0 0" />
      <geometry>
        <box size="0.055 0.0025 0.086" />
      </geometry>
    </collision>
    <collision name="bottle__right_grip_strip">
      <origin xyz="0.041 0.002 0.11" rpy="0 0 0" />
      <geometry>
        <box size="0.004 0.024 0.08" />
      </geometry>
    </collision>
    <collision name="bottle__left_grip_strip">
      <origin xyz="-0.041 0.002 0.11" rpy="0 0 0" />
      <geometry>
        <box size="0.004 0.024 0.08" />
      </geometry>
    </collision>
    <collision name="bottle__dip_tube__hull_001">
      <geometry>
        <mesh filename="meshes/collision/cache/c349fd7d91cf3a1c42b49625__hull_001.obj" />
      </geometry>
    </collision>
  </link>
  <link name="sprayer_head">
    <inertial>
      <origin xyz="0 0.018 0.024" rpy="0 0 0" />
      <mass value="0.16" />
      <inertia ixx="0.000172053" ixy="0" ixz="0" iyy="9.86667e-05" iyz="0" izz="0.000204053" />
    </inertial>
    <visual name="head_shell">
      <origin xyz="0 0.012 0.028" rpy="0 0 0" />
      <geometry>
        <mesh filename="meshes/sprayer_head_shell.glb" />
      </geometry>
      <material name="sprayer_white">
        <color rgba="0.96 0.96 0.95 1" />
      </material>
    </visual>
    <visual name="nozzle_barrel">
      <origin xyz="0 0.045 0.028" rpy="1.5708 0 0" />
      <geometry>
        <cylinder radius="0.0135" length="0.05" />
      </geometry>
      <material name="sprayer_white">
        <color rgba="0.96 0.96 0.95 1" />
      </material>
    </visual>
    <visual name="nozzle_collar">
      <origin xyz="0 0.02 0.028" rpy="1.5708 0 0" />
      <geometry>
        <cylinder radius="0.0155" length="0.01" />
      </geometry>
      <material name="sprayer_white">
        <color rgba="0.96 0.96 0.95 1" />
      </material>
    </visual>
    <visual name="rear_cap">
      <origin xyz="0 -0.018 0.028" rpy="1.5708 0 0" />
      <geometry>
        <cylinder radius="0.012" length="0.022" />
      </geometry>
      <material name="sprayer_white">
        <color rgba="0.96 0.96 0.95 1" />
      </material>
    </visual>
    <visual name="rear_stem">
      <origin xyz="0 -0.004 0.013" rpy="0 0 0" />
      <geometry>
        <box size="0.028 0.018 0.026" />
      </geometry>
      <material name="sprayer_white">
        <color rgba="0.96 0.96 0.95 1" />
      </material>
    </visual>
    <visual name="base_bridge">
      <origin xyz="0 0.008 0.004" rpy="0 0 0" />
      <geometry>
        <box size="0.032 0.02 0.008" />
      </geometry>
      <material name="sprayer_white">
        <color rgba="0.96 0.96 0.95 1" />
      </material>
    </visual>
    <collision name="sprayer_head__head_shell__hull_001">
      <origin xyz="0 0.012 0.028" rpy="0 0 0" />
      <geometry>
        <mesh filename="meshes/collision/cache/47304fa9092ee5a4cfdd104a__hull_001.obj" />
      </geometry>
    </collision>
    <collision name="sprayer_head__nozzle_barrel">
      <origin xyz="0 0.045 0.028" rpy="1.5708 0 0" />
      <geometry>
        <cylinder radius="0.0135" length="0.05" />
      </geometry>
    </collision>
    <collision name="sprayer_head__nozzle_collar">
      <origin xyz="0 0.02 0.028" rpy="1.5708 0 0" />
      <geometry>
        <cylinder radius="0.0155" length="0.01" />
      </geometry>
    </collision>
    <collision name="sprayer_head__rear_cap">
      <origin xyz="0 -0.018 0.028" rpy="1.5708 0 0" />
      <geometry>
        <cylinder radius="0.012" length="0.022" />
      </geometry>
    </collision>
    <collision name="sprayer_head__rear_stem">
      <origin xyz="0 -0.004 0.013" rpy="0 0 0" />
      <geometry>
        <box size="0.028 0.018 0.026" />
      </geometry>
    </collision>
    <collision name="sprayer_head__base_bridge">
      <origin xyz="0 0.008 0.004" rpy="0 0 0" />
      <geometry>
        <box size="0.032 0.02 0.008" />
      </geometry>
    </collision>
  </link>
  <link name="trigger">
    <inertial>
      <origin xyz="0 -0.002 -0.03" rpy="0 0 0" />
      <mass value="0.05" />
      <inertia ixx="1.89542e-05" ixy="0" ixz="0" iyy="2.04208e-05" iyz="0" izz="4.16667e-06" />
    </inertial>
    <visual name="trigger_body">
      <geometry>
        <mesh filename="meshes/sprayer_trigger.glb" />
      </geometry>
      <material name="charcoal_plastic">
        <color rgba="0.18 0.18 0.2 1" />
      </material>
    </visual>
    <visual name="pivot_boss">
      <origin xyz="0 0 0" rpy="0 1.5708 0" />
      <geometry>
        <cylinder radius="0.0035" length="0.026" />
      </geometry>
      <material name="charcoal_plastic">
        <color rgba="0.18 0.18 0.2 1" />
      </material>
    </visual>
    <visual name="finger_pad">
      <origin xyz="0 0.012 -0.044" rpy="0 0 0" />
      <geometry>
        <box size="0.018 0.01 0.011" />
      </geometry>
      <material name="charcoal_plastic">
        <color rgba="0.18 0.18 0.2 1" />
      </material>
    </visual>
    <collision name="trigger__trigger_body__hull_001">
      <geometry>
        <mesh filename="meshes/collision/cache/3f84969d8fea399d4c9f43f0__hull_001.obj" />
      </geometry>
    </collision>
    <collision name="trigger__pivot_boss">
      <origin xyz="0 0 0" rpy="0 1.5708 0" />
      <geometry>
        <cylinder radius="0.0035" length="0.026" />
      </geometry>
    </collision>
    <collision name="trigger__finger_pad">
      <origin xyz="0 0.012 -0.044" rpy="0 0 0" />
      <geometry>
        <box size="0.018 0.01 0.011" />
      </geometry>
    </collision>
  </link>
  <link name="nozzle_tip">
    <inertial>
      <origin xyz="0 0.008 0.002" rpy="0 0 0" />
      <mass value="0.015" />
      <inertia ixx="1e-06" ixy="0" ixz="0" iyy="1.22e-06" iyz="0" izz="1.22e-06" />
    </inertial>
    <visual name="selector_body">
      <origin xyz="0 0.007 0" rpy="1.5708 0 0" />
      <geometry>
        <cylinder radius="0.0105" length="0.014" />
      </geometry>
      <material name="selector_red">
        <color rgba="0.82 0.15 0.14 1" />
      </material>
    </visual>
    <visual name="selector_face">
      <origin xyz="0 0.0135 0" rpy="1.5708 0 0" />
      <geometry>
        <cylinder radius="0.0125" length="0.003" />
      </geometry>
      <material name="selector_red">
        <color rgba="0.82 0.15 0.14 1" />
      </material>
    </visual>
    <visual name="selector_tab">
      <origin xyz="0.007 0.006 0.008" rpy="0 0 0" />
      <geometry>
        <box size="0.01 0.004 0.009" />
      </geometry>
      <material name="selector_red">
        <color rgba="0.82 0.15 0.14 1" />
      </material>
    </visual>
    <visual name="spray_orifice">
      <origin xyz="0 0.015 0" rpy="1.5708 0 0" />
      <geometry>
        <cylinder radius="0.0025" length="0.004" />
      </geometry>
      <material name="charcoal_plastic">
        <color rgba="0.18 0.18 0.2 1" />
      </material>
    </visual>
    <collision name="nozzle_tip__selector_body">
      <origin xyz="0 0.007 0" rpy="1.5708 0 0" />
      <geometry>
        <cylinder radius="0.0105" length="0.014" />
      </geometry>
    </collision>
    <collision name="nozzle_tip__selector_face">
      <origin xyz="0 0.0135 0" rpy="1.5708 0 0" />
      <geometry>
        <cylinder radius="0.0125" length="0.003" />
      </geometry>
    </collision>
    <collision name="nozzle_tip__selector_tab">
      <origin xyz="0.007 0.006 0.008" rpy="0 0 0" />
      <geometry>
        <box size="0.01 0.004 0.009" />
      </geometry>
    </collision>
    <collision name="nozzle_tip__spray_orifice">
      <origin xyz="0 0.015 0" rpy="1.5708 0 0" />
      <geometry>
        <cylinder radius="0.0025" length="0.004" />
      </geometry>
    </collision>
  </link>
  <joint name="bottle_to_head" type="fixed">
    <origin xyz="0 0 0.262" rpy="0 0 0" />
    <parent link="bottle" />
    <child link="sprayer_head" />
  </joint>
  <joint name="trigger_hinge" type="revolute">
    <origin xyz="0 0.06 0.018" rpy="0 0 0" />
    <parent link="sprayer_head" />
    <child link="trigger" />
    <axis xyz="-1 0 0" />
    <limit effort="8" velocity="4" lower="0" upper="0.58" />
  </joint>
  <joint name="nozzle_selector" type="revolute">
    <origin xyz="0 0.068 0.028" rpy="0 0 0" />
    <parent link="sprayer_head" />
    <child link="nozzle_tip" />
    <axis xyz="0 1 0" />
    <limit effort="1" velocity="3" lower="0" upper="1.35" />
  </joint>
</robot>