<robot name="folding_kick_scooter">
  <link name="deck">
    <inertial>
      <origin xyz="0 0 0.085" rpy="0 0 0" />
      <mass value="4.2" />
      <inertia ixx="0.112175" ixy="0" ixz="0" iyy="0.01603" iyz="0" izz="0.107975" />
    </inertial>
    <visual>
      <origin xyz="0 0 0.017" rpy="0 0 0" />
      <geometry>
        <mesh filename="meshes/folding_scooter_deck.glb" />
      </geometry>
    </visual>
    <visual>
      <origin xyz="0 -0.01 0.036" rpy="0 0 0" />
      <geometry>
        <box size="0.108 0.335 0.002" />
      </geometry>
    </visual>
    <visual>
      <origin xyz="0.053 -0.015 0.03" rpy="0 0 0" />
      <geometry>
        <box size="0.006 0.405 0.01" />
      </geometry>
    </visual>
    <visual>
      <origin xyz="-0.053 -0.015 0.03" rpy="0 0 0" />
      <geometry>
        <box size="0.006 0.405 0.01" />
      </geometry>
    </visual>
    <visual>
      <origin xyz="0 0.22 0.078" rpy="0 0 0" />
      <geometry>
        <box size="0.058 0.06 0.086" />
      </geometry>
    </visual>
    <visual>
      <origin xyz="0.026 0.22 0.092" rpy="0 0 0" />
      <geometry>
        <box size="0.014 0.046 0.058" />
      </geometry>
    </visual>
    <visual>
      <origin xyz="-0.026 0.22 0.092" rpy="0 0 0" />
      <geometry>
        <box size="0.014 0.046 0.058" />
      </geometry>
    </visual>
    <visual>
      <origin xyz="0.03 -0.236 0.067" rpy="0 0 0" />
      <geometry>
        <box size="0.01 0.045 0.064" />
      </geometry>
    </visual>
    <visual>
      <origin xyz="-0.03 -0.236 0.067" rpy="0 0 0" />
      <geometry>
        <box size="0.01 0.045 0.064" />
      </geometry>
    </visual>
    <visual>
      <origin xyz="0 -0.236 0.1" rpy="0 1.5708 0" />
      <geometry>
        <cylinder radius="0.006" length="0.09" />
      </geometry>
    </visual>
    <visual>
      <origin xyz="0 -0.236 0.085" rpy="0 0 0" />
      <geometry>
        <box size="0.028 0.018 0.1" />
      </geometry>
    </visual>
    <visual>
      <origin xyz="0 -0.244 0.144" rpy="0 0 0" />
      <geometry>
        <box size="0.09 0.04 0.018" />
      </geometry>
    </visual>
    <visual>
      <origin xyz="0 -0.27 0.153" rpy="0 0 0" />
      <geometry>
        <box size="0.064 0.014 0.008" />
      </geometry>
    </visual>
    <collision name="deck__visual_1__hull_001">
      <origin xyz="0 0 0.017" rpy="0 0 0" />
      <geometry>
        <mesh filename="meshes/collision/cache/da097f06f194ee12f7040289__hull_001.obj" />
      </geometry>
    </collision>
    <collision name="deck__visual_2">
      <origin xyz="0 -0.01 0.036" rpy="0 0 0" />
      <geometry>
        <box size="0.108 0.335 0.002" />
      </geometry>
    </collision>
    <collision name="deck__visual_3">
      <origin xyz="0.053 -0.015 0.03" rpy="0 0 0" />
      <geometry>
        <box size="0.006 0.405 0.01" />
      </geometry>
    </collision>
    <collision name="deck__visual_4">
      <origin xyz="-0.053 -0.015 0.03" rpy="0 0 0" />
      <geometry>
        <box size="0.006 0.405 0.01" />
      </geometry>
    </collision>
    <collision name="deck__visual_5">
      <origin xyz="0 0.22 0.078" rpy="0 0 0" />
      <geometry>
        <box size="0.058 0.06 0.086" />
      </geometry>
    </collision>
    <collision name="deck__visual_6">
      <origin xyz="0.026 0.22 0.092" rpy="0 0 0" />
      <geometry>
        <box size="0.014 0.046 0.058" />
      </geometry>
    </collision>
    <collision name="deck__visual_7">
      <origin xyz="-0.026 0.22 0.092" rpy="0 0 0" />
      <geometry>
        <box size="0.014 0.046 0.058" />
      </geometry>
    </collision>
    <collision name="deck__visual_8">
      <origin xyz="0.03 -0.236 0.067" rpy="0 0 0" />
      <geometry>
        <box size="0.01 0.045 0.064" />
      </geometry>
    </collision>
    <collision name="deck__visual_9">
      <origin xyz="-0.03 -0.236 0.067" rpy="0 0 0" />
      <geometry>
        <box size="0.01 0.045 0.064" />
      </geometry>
    </collision>
    <collision name="deck__visual_10">
      <origin xyz="0 -0.236 0.1" rpy="0 1.5708 0" />
      <geometry>
        <cylinder radius="0.006" length="0.09" />
      </geometry>
    </collision>
    <collision name="deck__visual_11">
      <origin xyz="0 -0.236 0.085" rpy="0 0 0" />
      <geometry>
        <box size="0.028 0.018 0.1" />
      </geometry>
    </collision>
    <collision name="deck__visual_12">
      <origin xyz="0 -0.244 0.144" rpy="0 0 0" />
      <geometry>
        <box size="0.09 0.04 0.018" />
      </geometry>
    </collision>
    <collision name="deck__visual_13">
      <origin xyz="0 -0.27 0.153" rpy="0 0 0" />
      <geometry>
        <box size="0.064 0.014 0.008" />
      </geometry>
    </collision>
  </link>
  <link name="stem_base">
    <inertial>
      <origin xyz="0 0.008 0.11" rpy="0 0 0" />
      <mass value="0.8" />
      <inertia ixx="0.000906667" ixy="0" ixz="0" iyy="0.000906667" iyz="0" izz="0.00048" />
    </inertial>
    <visual>
      <origin xyz="0 0 0.01" rpy="0 0 0" />
      <geometry>
        <box size="0.03 0.022 0.02" />
      </geometry>
    </visual>
    <visual>
      <origin xyz="0.019 0 0.032" rpy="0 0 0" />
      <geometry>
        <box size="0.008 0.038 0.064" />
      </geometry>
    </visual>
    <visual>
      <origin xyz="-0.019 0 0.032" rpy="0 0 0" />
      <geometry>
        <box size="0.008 0.038 0.064" />
      </geometry>
    </visual>
    <visual>
      <origin xyz="0 0.018 0.05" rpy="0 0 0" />
      <geometry>
        <box size="0.038 0.06 0.036" />
      </geometry>
    </visual>
    <visual>
      <origin xyz="0 0.01 0.105" rpy="0 0 0" />
      <geometry>
        <cylinder radius="0.02" length="0.17" />
      </geometry>
    </visual>
    <visual>
      <origin xyz="0 0.01 0.192" rpy="0 0 0" />
      <geometry>
        <cylinder radius="0.024" length="0.034" />
      </geometry>
    </visual>
    <visual>
      <origin xyz="0 -0.018 0.018" rpy="0 0 0" />
      <geometry>
        <box size="0.034 0.02 0.026" />
      </geometry>
    </visual>
    <visual>
      <origin xyz="0 -0.034 0.03" rpy="0 0 0" />
      <geometry>
        <box size="0.012 0.018 0.032" />
      </geometry>
    </visual>
    <visual>
      <origin xyz="0 -0.012 0.118" rpy="0 0 0" />
      <geometry>
        <box size="0.016 0.014 0.05" />
      </geometry>
    </visual>
    <collision name="stem_base__visual_1">
      <origin xyz="0 0 0.01" rpy="0 0 0" />
      <geometry>
        <box size="0.03 0.022 0.02" />
      </geometry>
    </collision>
    <collision name="stem_base__visual_2">
      <origin xyz="0.019 0 0.032" rpy="0 0 0" />
      <geometry>
        <box size="0.008 0.038 0.064" />
      </geometry>
    </collision>
    <collision name="stem_base__visual_3">
      <origin xyz="-0.019 0 0.032" rpy="0 0 0" />
      <geometry>
        <box size="0.008 0.038 0.064" />
      </geometry>
    </collision>
    <collision name="stem_base__visual_4">
      <origin xyz="0 0.018 0.05" rpy="0 0 0" />
      <geometry>
        <box size="0.038 0.06 0.036" />
      </geometry>
    </collision>
    <collision name="stem_base__visual_5">
      <origin xyz="0 0.01 0.105" rpy="0 0 0" />
      <geometry>
        <cylinder radius="0.02" length="0.17" />
      </geometry>
    </collision>
    <collision name="stem_base__visual_6">
      <origin xyz="0 0.01 0.192" rpy="0 0 0" />
      <geometry>
        <cylinder radius="0.024" length="0.034" />
      </geometry>
    </collision>
    <collision name="stem_base__visual_7">
      <origin xyz="0 -0.018 0.018" rpy="0 0 0" />
      <geometry>
        <box size="0.034 0.02 0.026" />
      </geometry>
    </collision>
    <collision name="stem_base__visual_8">
      <origin xyz="0 -0.034 0.03" rpy="0 0 0" />
      <geometry>
        <box size="0.012 0.018 0.032" />
      </geometry>
    </collision>
    <collision name="stem_base__visual_9">
      <origin xyz="0 -0.012 0.118" rpy="0 0 0" />
      <geometry>
        <box size="0.016 0.014 0.05" />
      </geometry>
    </collision>
  </link>
  <link name="steering_assembly">
    <inertial>
      <origin xyz="0 0.025 0.318" rpy="0 0 0" />
      <mass value="1.9" />
      <inertia ixx="0.0945567" ixy="0" ixz="0" iyy="0.131037" iyz="0" izz="0.0426867" />
    </inertial>
    <visual>
      <origin xyz="0 0 -0.092" rpy="0 0 0" />
      <geometry>
        <cylinder radius="0.023" length="0.036" />
      </geometry>
    </visual>
    <visual>
      <origin xyz="0 0 -0.06" rpy="0 0 0" />
      <geometry>
        <cylinder radius="0.022" length="0.052" />
      </geometry>
    </visual>
    <visual>
      <origin xyz="0 0 0.226" rpy="0 0 0" />
      <geometry>
        <cylinder radius="0.018" length="0.52" />
      </geometry>
    </visual>
    <visual>
      <origin xyz="0 0.034 -0.09" rpy="0 0 0" />
      <geometry>
        <box size="0.036 0.06 0.04" />
      </geometry>
    </visual>
    <visual>
      <origin xyz="0 0.082 -0.086" rpy="0 0 0" />
      <geometry>
        <box size="0.082 0.05 0.036" />
      </geometry>
    </visual>
    <visual>
      <origin xyz="0 0.11 -0.09" rpy="0 0 0" />
      <geometry>
        <box size="0.06 0.024 0.018" />
      </geometry>
    </visual>
    <visual>
      <origin xyz="0.029 0.122 -0.126" rpy="0 0 0" />
      <geometry>
        <box size="0.012 0.028 0.156" />
      </geometry>
    </visual>
    <visual>
      <origin xyz="-0.029 0.122 -0.126" rpy="0 0 0" />
      <geometry>
        <box size="0.012 0.028 0.156" />
      </geometry>
    </visual>
    <visual>
      <origin xyz="0 0.136 -0.204" rpy="0 1.5708 0" />
      <geometry>
        <cylinder radius="0.006" length="0.082" />
      </geometry>
    </visual>
    <visual>
      <origin xyz="0 -0.004 0.506" rpy="0 0 0" />
      <geometry>
        <box size="0.072 0.042 0.04" />
      </geometry>
    </visual>
    <visual>
      <origin xyz="0 -0.002 0.532" rpy="0 0 0" />
      <geometry>
        <box size="0.024 0.024 0.018" />
      </geometry>
    </visual>
    <visual>
      <origin xyz="0 -0.008 0.526" rpy="0 0 0" />
      <geometry>
        <mesh filename="meshes/folding_scooter_handlebar.glb" />
      </geometry>
    </visual>
    <visual>
      <origin xyz="0 0.006 0.546" rpy="0 0 0" />
      <geometry>
        <box size="0.058 0.032 0.018" />
      </geometry>
    </visual>
    <visual>
      <origin xyz="0.212 -0.008 0.526" rpy="0 1.5708 0" />
      <geometry>
        <cylinder radius="0.017" length="0.095" />
      </geometry>
    </visual>
    <visual>
      <origin xyz="-0.212 -0.008 0.526" rpy="0 1.5708 0" />
      <geometry>
        <cylinder radius="0.017" length="0.095" />
      </geometry>
    </visual>
    <visual>
      <origin xyz="-0.176 -0.024 0.51" rpy="0 0 -0.72" />
      <geometry>
        <box size="0.008 0.046 0.016" />
      </geometry>
    </visual>
    <collision name="steering_assembly__visual_1">
      <origin xyz="0 0 -0.092" rpy="0 0 0" />
      <geometry>
        <cylinder radius="0.023" length="0.036" />
      </geometry>
    </collision>
    <collision name="steering_assembly__visual_2">
      <origin xyz="0 0 -0.06" rpy="0 0 0" />
      <geometry>
        <cylinder radius="0.022" length="0.052" />
      </geometry>
    </collision>
    <collision name="steering_assembly__visual_3">
      <origin xyz="0 0 0.226" rpy="0 0 0" />
      <geometry>
        <cylinder radius="0.018" length="0.52" />
      </geometry>
    </collision>
    <collision name="steering_assembly__visual_4">
      <origin xyz="0 0.034 -0.09" rpy="0 0 0" />
      <geometry>
        <box size="0.036 0.06 0.04" />
      </geometry>
    </collision>
    <collision name="steering_assembly__visual_5">
      <origin xyz="0 0.082 -0.086" rpy="0 0 0" />
      <geometry>
        <box size="0.082 0.05 0.036" />
      </geometry>
    </collision>
    <collision name="steering_assembly__visual_6">
      <origin xyz="0 0.11 -0.09" rpy="0 0 0" />
      <geometry>
        <box size="0.06 0.024 0.018" />
      </geometry>
    </collision>
    <collision name="steering_assembly__visual_7">
      <origin xyz="0.029 0.122 -0.126" rpy="0 0 0" />
      <geometry>
        <box size="0.012 0.028 0.156" />
      </geometry>
    </collision>
    <collision name="steering_assembly__visual_8">
      <origin xyz="-0.029 0.122 -0.126" rpy="0 0 0" />
      <geometry>
        <box size="0.012 0.028 0.156" />
      </geometry>
    </collision>
    <collision name="steering_assembly__visual_9">
      <origin xyz="0 0.136 -0.204" rpy="0 1.5708 0" />
      <geometry>
        <cylinder radius="0.006" length="0.082" />
      </geometry>
    </collision>
    <collision name="steering_assembly__visual_10">
      <origin xyz="0 -0.004 0.506" rpy="0 0 0" />
      <geometry>
        <box size="0.072 0.042 0.04" />
      </geometry>
    </collision>
    <collision name="steering_assembly__visual_11">
      <origin xyz="0 -0.002 0.532" rpy="0 0 0" />
      <geometry>
        <box size="0.024 0.024 0.018" />
      </geometry>
    </collision>
    <collision name="steering_assembly__visual_12__hull_001">
      <origin xyz="0 -0.008 0.526" rpy="0 0 0" />
      <geometry>
        <mesh filename="meshes/collision/cache/f7cd138d5e7661c4f6391a6b__hull_001.obj" />
      </geometry>
    </collision>
    <collision name="steering_assembly__visual_13">
      <origin xyz="0 0.006 0.546" rpy="0 0 0" />
      <geometry>
        <box size="0.058 0.032 0.018" />
      </geometry>
    </collision>
    <collision name="steering_assembly__visual_14">
      <origin xyz="0.212 -0.008 0.526" rpy="0 1.5708 0" />
      <geometry>
        <cylinder radius="0.017" length="0.095" />
      </geometry>
    </collision>
    <collision name="steering_assembly__visual_15">
      <origin xyz="-0.212 -0.008 0.526" rpy="0 1.5708 0" />
      <geometry>
        <cylinder radius="0.017" length="0.095" />
      </geometry>
    </collision>
    <collision name="steering_assembly__visual_16">
      <origin xyz="-0.176 -0.024 0.51" rpy="0 0 -0.72" />
      <geometry>
        <box size="0.008 0.046 0.016" />
      </geometry>
    </collision>
  </link>
  <link name="front_wheel">
    <inertial>
      <origin xyz="0 0 0" rpy="0 1.5708 0" />
      <mass value="0.7" />
      <inertia ixx="0.0017836" ixy="0" ixz="0" iyy="0.0017836" iyz="0" izz="0.0035" />
    </inertial>
    <visual>
      <origin xyz="0 0 0" rpy="0 1.5708 0" />
      <geometry>
        <cylinder radius="0.1" length="0.024" />
      </geometry>
    </visual>
    <visual>
      <origin xyz="0 0 0" rpy="0 1.5708 0" />
      <geometry>
        <cylinder radius="0.086" length="0.026" />
      </geometry>
    </visual>
    <visual>
      <origin xyz="0 0 0" rpy="0 1.5708 0" />
      <geometry>
        <cylinder radius="0.076" length="0.03" />
      </geometry>
    </visual>
    <visual>
      <origin xyz="0 0 0" rpy="0 1.5708 0" />
      <geometry>
        <cylinder radius="0.03" length="0.042" />
      </geometry>
    </visual>
    <visual>
      <origin xyz="0 0.051 0" rpy="0 0 0" />
      <geometry>
        <box size="0.008 0.058 0.018" />
      </geometry>
    </visual>
    <visual>
      <origin xyz="0 0.0255 0.0441673" rpy="1.0472 0 0" />
      <geometry>
        <box size="0.008 0.058 0.018" />
      </geometry>
    </visual>
    <visual>
      <origin xyz="0 -0.0255 0.0441673" rpy="2.0944 0 0" />
      <geometry>
        <box size="0.008 0.058 0.018" />
      </geometry>
    </visual>
    <visual>
      <origin xyz="0 -0.051 6.2457e-18" rpy="3.14159 0 0" />
      <geometry>
        <box size="0.008 0.058 0.018" />
      </geometry>
    </visual>
    <visual>
      <origin xyz="0 -0.0255 -0.0441673" rpy="4.18879 0 0" />
      <geometry>
        <box size="0.008 0.058 0.018" />
      </geometry>
    </visual>
    <visual>
      <origin xyz="0 0.0255 -0.0441673" rpy="5.23599 0 0" />
      <geometry>
        <box size="0.008 0.058 0.018" />
      </geometry>
    </visual>
    <collision name="front_wheel__visual_1">
      <origin xyz="0 0 0" rpy="0 1.5708 0" />
      <geometry>
        <cylinder radius="0.1" length="0.024" />
      </geometry>
    </collision>
    <collision name="front_wheel__visual_2">
      <origin xyz="0 0 0" rpy="0 1.5708 0" />
      <geometry>
        <cylinder radius="0.086" length="0.026" />
      </geometry>
    </collision>
    <collision name="front_wheel__visual_3">
      <origin xyz="0 0 0" rpy="0 1.5708 0" />
      <geometry>
        <cylinder radius="0.076" length="0.03" />
      </geometry>
    </collision>
    <collision name="front_wheel__visual_4">
      <origin xyz="0 0 0" rpy="0 1.5708 0" />
      <geometry>
        <cylinder radius="0.03" length="0.042" />
      </geometry>
    </collision>
    <collision name="front_wheel__visual_5">
      <origin xyz="0 0.051 0" rpy="0 0 0" />
      <geometry>
        <box size="0.008 0.058 0.018" />
      </geometry>
    </collision>
    <collision name="front_wheel__visual_6">
      <origin xyz="0 0.0255 0.0441673" rpy="1.0472 0 0" />
      <geometry>
        <box size="0.008 0.058 0.018" />
      </geometry>
    </collision>
    <collision name="front_wheel__visual_7">
      <origin xyz="0 -0.0255 0.0441673" rpy="2.0944 0 0" />
      <geometry>
        <box size="0.008 0.058 0.018" />
      </geometry>
    </collision>
    <collision name="front_wheel__visual_8">
      <origin xyz="0 -0.051 6.2457e-18" rpy="3.14159 0 0" />
      <geometry>
        <box size="0.008 0.058 0.018" />
      </geometry>
    </collision>
    <collision name="front_wheel__visual_9">
      <origin xyz="0 -0.0255 -0.0441673" rpy="4.18879 0 0" />
      <geometry>
        <box size="0.008 0.058 0.018" />
      </geometry>
    </collision>
    <collision name="front_wheel__visual_10">
      <origin xyz="0 0.0255 -0.0441673" rpy="5.23599 0 0" />
      <geometry>
        <box size="0.008 0.058 0.018" />
      </geometry>
    </collision>
  </link>
  <link name="rear_wheel">
    <inertial>
      <origin xyz="0 0 0" rpy="0 1.5708 0" />
      <mass value="0.7" />
      <inertia ixx="0.0017836" ixy="0" ixz="0" iyy="0.0017836" iyz="0" izz="0.0035" />
    </inertial>
    <visual>
      <origin xyz="0 0 0" rpy="0 1.5708 0" />
      <geometry>
        <cylinder radius="0.1" length="0.024" />
      </geometry>
    </visual>
    <visual>
      <origin xyz="0 0 0" rpy="0 1.5708 0" />
      <geometry>
        <cylinder radius="0.086" length="0.026" />
      </geometry>
    </visual>
    <visual>
      <origin xyz="0 0 0" rpy="0 1.5708 0" />
      <geometry>
        <cylinder radius="0.076" length="0.03" />
      </geometry>
    </visual>
    <visual>
      <origin xyz="0 0 0" rpy="0 1.5708 0" />
      <geometry>
        <cylinder radius="0.03" length="0.042" />
      </geometry>
    </visual>
    <visual>
      <origin xyz="0 0.051 0" rpy="0 0 0" />
      <geometry>
        <box size="0.008 0.058 0.018" />
      </geometry>
    </visual>
    <visual>
      <origin xyz="0 0.0255 0.0441673" rpy="1.0472 0 0" />
      <geometry>
        <box size="0.008 0.058 0.018" />
      </geometry>
    </visual>
    <visual>
      <origin xyz="0 -0.0255 0.0441673" rpy="2.0944 0 0" />
      <geometry>
        <box size="0.008 0.058 0.018" />
      </geometry>
    </visual>
    <visual>
      <origin xyz="0 -0.051 6.2457e-18" rpy="3.14159 0 0" />
      <geometry>
        <box size="0.008 0.058 0.018" />
      </geometry>
    </visual>
    <visual>
      <origin xyz="0 -0.0255 -0.0441673" rpy="4.18879 0 0" />
      <geometry>
        <box size="0.008 0.058 0.018" />
      </geometry>
    </visual>
    <visual>
      <origin xyz="0 0.0255 -0.0441673" rpy="5.23599 0 0" />
      <geometry>
        <box size="0.008 0.058 0.018" />
      </geometry>
    </visual>
    <collision name="rear_wheel__visual_1">
      <origin xyz="0 0 0" rpy="0 1.5708 0" />
      <geometry>
        <cylinder radius="0.1" length="0.024" />
      </geometry>
    </collision>
    <collision name="rear_wheel__visual_2">
      <origin xyz="0 0 0" rpy="0 1.5708 0" />
      <geometry>
        <cylinder radius="0.086" length="0.026" />
      </geometry>
    </collision>
    <collision name="rear_wheel__visual_3">
      <origin xyz="0 0 0" rpy="0 1.5708 0" />
      <geometry>
        <cylinder radius="0.076" length="0.03" />
      </geometry>
    </collision>
    <collision name="rear_wheel__visual_4">
      <origin xyz="0 0 0" rpy="0 1.5708 0" />
      <geometry>
        <cylinder radius="0.03" length="0.042" />
      </geometry>
    </collision>
    <collision name="rear_wheel__visual_5">
      <origin xyz="0 0.051 0" rpy="0 0 0" />
      <geometry>
        <box size="0.008 0.058 0.018" />
      </geometry>
    </collision>
    <collision name="rear_wheel__visual_6">
      <origin xyz="0 0.0255 0.0441673" rpy="1.0472 0 0" />
      <geometry>
        <box size="0.008 0.058 0.018" />
      </geometry>
    </collision>
    <collision name="rear_wheel__visual_7">
      <origin xyz="0 -0.0255 0.0441673" rpy="2.0944 0 0" />
      <geometry>
        <box size="0.008 0.058 0.018" />
      </geometry>
    </collision>
    <collision name="rear_wheel__visual_8">
      <origin xyz="0 -0.051 6.2457e-18" rpy="3.14159 0 0" />
      <geometry>
        <box size="0.008 0.058 0.018" />
      </geometry>
    </collision>
    <collision name="rear_wheel__visual_9">
      <origin xyz="0 -0.0255 -0.0441673" rpy="4.18879 0 0" />
      <geometry>
        <box size="0.008 0.058 0.018" />
      </geometry>
    </collision>
    <collision name="rear_wheel__visual_10">
      <origin xyz="0 0.0255 -0.0441673" rpy="5.23599 0 0" />
      <geometry>
        <box size="0.008 0.058 0.018" />
      </geometry>
    </collision>
  </link>
  <joint name="stem_fold" type="revolute">
    <origin xyz="0 0.22 0.124" rpy="0 0 0" />
    <parent link="deck" />
    <child link="stem_base" />
    <axis xyz="1 0 0" />
    <limit effort="18" velocity="2" lower="0" upper="0.72" />
  </joint>
  <joint name="steering_head" type="revolute">
    <origin xyz="0 0.01 0.19" rpy="0 0 0" />
    <parent link="stem_base" />
    <child link="steering_assembly" />
    <axis xyz="0 0 1" />
    <limit effort="12" velocity="4" lower="-0.9" upper="0.9" />
  </joint>
  <joint name="front_wheel_roll" type="continuous">
    <origin xyz="0 0.136 -0.204" rpy="0 0 0" />
    <parent link="steering_assembly" />
    <child link="front_wheel" />
    <axis xyz="1 0 0" />
    <limit effort="4" velocity="25" />
  </joint>
  <joint name="rear_wheel_roll" type="continuous">
    <origin xyz="0 -0.236 0.1" rpy="0 0 0" />
    <parent link="deck" />
    <child link="rear_wheel" />
    <axis xyz="1 0 0" />
    <limit effort="4" velocity="25" />
  </joint>
</robot>