<robot name="mechanical_finger_chain">
  <material name="mount_grey">
    <color rgba="0.28 0.3 0.33 1" />
  </material>
  <material name="proximal_blue">
    <color rgba="0.34 0.42 0.56 1" />
  </material>
  <material name="middle_steel">
    <color rgba="0.58 0.6 0.65 1" />
  </material>
  <material name="distal_brass">
    <color rgba="0.72 0.58 0.3 1" />
  </material>
  <link name="base_mount">
    <inertial>
      <origin xyz="-0.019 0 0" rpy="0 0 0" />
      <mass value="0.32" />
      <inertia ixx="2.15467e-05" ixy="0" ixz="0" iyy="3.264e-05" iyz="0" izz="3.69067e-05" />
    </inertial>
    <visual>
      <geometry>
        <mesh filename="meshes/base_mount.glb" />
      </geometry>
      <material name="mount_grey" />
    </visual>
    <collision>
      <origin xyz="-0.019 0 0" rpy="0 0 0" />
      <geometry>
        <box size="0.03 0.022 0.018" />
      </geometry>
    </collision>
    <collision>
      <origin xyz="-0.005 0.0069 0" rpy="0 0 0" />
      <geometry>
        <box size="0.01 0.0032 0.013" />
      </geometry>
    </collision>
    <collision>
      <origin xyz="-0.005 -0.0069 0" rpy="0 0 0" />
      <geometry>
        <box size="0.01 0.0032 0.013" />
      </geometry>
    </collision>
  </link>
  <link name="proximal">
    <inertial>
      <origin xyz="0.02714 0 0" rpy="0 0 0" />
      <mass value="0.14" />
      <inertia ixx="2.14527e-06" ixy="0" ixz="0" iyy="1.84566e-05" iyz="0" izz="1.78803e-05" />
    </inertial>
    <visual>
      <geometry>
        <mesh filename="meshes/proximal.glb" />
      </geometry>
      <material name="proximal_blue" />
    </visual>
    <collision>
      <origin xyz="0 0 0" rpy="-1.5708 0 0" />
      <geometry>
        <cylinder radius="0.00484" length="0.00836" />
      </geometry>
    </collision>
    <collision>
      <origin xyz="0.02714 0 0" rpy="0 0 0" />
      <geometry>
        <box size="0.03828 0.0082 0.0108" />
      </geometry>
    </collision>
    <collision>
      <origin xyz="0.053 0.0069 0" rpy="0 0 0" />
      <geometry>
        <box size="0.01 0.0032 0.0108" />
      </geometry>
    </collision>
    <collision>
      <origin xyz="0.053 -0.0069 0" rpy="0 0 0" />
      <geometry>
        <box size="0.01 0.0032 0.0108" />
      </geometry>
    </collision>
  </link>
  <link name="middle">
    <inertial>
      <origin xyz="0.02219 0 0" rpy="0 0 0" />
      <mass value="0.1" />
      <inertia ixx="1.18395e-06" ixy="0" ixz="0" iyy="7.44195e-06" iyz="0" izz="7.16574e-06" />
    </inertial>
    <visual>
      <geometry>
        <mesh filename="meshes/middle.glb" />
      </geometry>
      <material name="middle_steel" />
    </visual>
    <collision>
      <origin xyz="0 0 0" rpy="-1.5708 0 0" />
      <geometry>
        <cylinder radius="0.00484" length="0.00836" />
      </geometry>
    </collision>
    <collision>
      <origin xyz="0.02219 0 0" rpy="0 0 0" />
      <geometry>
        <box size="0.02838 0.00738 0.00936" />
      </geometry>
    </collision>
    <collision>
      <origin xyz="0.038 0.0069 0" rpy="0 0 0" />
      <geometry>
        <box size="0.01 0.0032 0.009" />
      </geometry>
    </collision>
    <collision>
      <origin xyz="0.038 -0.0069 0" rpy="0 0 0" />
      <geometry>
        <box size="0.01 0.0032 0.009" />
      </geometry>
    </collision>
  </link>
  <link name="distal">
    <inertial>
      <origin xyz="0.0182 0 0" rpy="0 0 0" />
      <mass value="0.07" />
      <inertia ixx="5.84792e-07" ixy="0" ixz="0" iyy="3.27279e-06" iyz="0" izz="3.16587e-06" />
    </inertial>
    <visual>
      <geometry>
        <mesh filename="meshes/distal.glb" />
      </geometry>
      <material name="distal_brass" />
    </visual>
    <collision>
      <origin xyz="0 0 0" rpy="-1.5708 0 0" />
      <geometry>
        <cylinder radius="0.00484" length="0.00836" />
      </geometry>
    </collision>
    <collision>
      <origin xyz="0.0182 0 0" rpy="0 0 0" />
      <geometry>
        <box size="0.0224 0.0064 0.0077" />
      </geometry>
    </collision>
    <collision>
      <origin xyz="0.02976 0 0" rpy="0 0 0" />
      <geometry>
        <box size="0.00448 0.00336 0.00345" />
      </geometry>
    </collision>
  </link>
  <joint name="base_to_proximal" type="revolute">
    <parent link="base_mount" />
    <child link="proximal" />
    <axis xyz="0 1 0" />
    <limit effort="4" velocity="2" lower="0" upper="1.2" />
  </joint>
  <joint name="proximal_to_middle" type="revolute">
    <origin xyz="0.058 0 0" rpy="0 0 0" />
    <parent link="proximal" />
    <child link="middle" />
    <axis xyz="0 1 0" />
    <limit effort="3.2" velocity="2.5" lower="0" upper="1.35" />
  </joint>
  <joint name="middle_to_distal" type="revolute">
    <origin xyz="0.043 0 0" rpy="0 0 0" />
    <parent link="middle" />
    <child link="distal" />
    <axis xyz="0 1 0" />
    <limit effort="2.3" velocity="3" lower="0" upper="1.1" />
  </joint>
</robot>