<robot name="satellite_dish_terminal">
  <link name="pedestal">
    <inertial>
      <origin xyz="0 0 0.51" rpy="0 0 0" />
      <mass value="92" />
      <inertia ixx="11.9508" ixy="0" ixz="0" iyy="11.9508" iyz="0" izz="7.9488" />
    </inertial>
    <visual>
      <origin xyz="0 0 0.03" rpy="0 0 0" />
      <geometry>
        <cylinder radius="0.36" length="0.06" />
      </geometry>
    </visual>
    <visual>
      <origin xyz="0 0 0.09" rpy="0 0 0" />
      <geometry>
        <cylinder radius="0.22" length="0.06" />
      </geometry>
    </visual>
    <visual>
      <origin xyz="0 0 0.48" rpy="0 0 0" />
      <geometry>
        <cylinder radius="0.12" length="0.72" />
      </geometry>
    </visual>
    <visual>
      <origin xyz="0 0 0.89" rpy="0 0 0" />
      <geometry>
        <cylinder radius="0.16" length="0.1" />
      </geometry>
    </visual>
    <visual>
      <origin xyz="0 0 0.945" rpy="0 0 0" />
      <geometry>
        <cylinder radius="0.19" length="0.07" />
      </geometry>
    </visual>
    <visual>
      <origin xyz="-0.18 0 0.25" rpy="0 0 0" />
      <geometry>
        <box size="0.22 0.16 0.28" />
      </geometry>
    </visual>
    <visual>
      <origin xyz="-0.125 0 0.59" rpy="0 0 0" />
      <geometry>
        <cylinder radius="0.025" length="0.52" />
      </geometry>
    </visual>
    <collision name="pedestal__visual_1">
      <origin xyz="0 0 0.03" rpy="0 0 0" />
      <geometry>
        <cylinder radius="0.36" length="0.06" />
      </geometry>
    </collision>
    <collision name="pedestal__visual_2">
      <origin xyz="0 0 0.09" rpy="0 0 0" />
      <geometry>
        <cylinder radius="0.22" length="0.06" />
      </geometry>
    </collision>
    <collision name="pedestal__visual_3">
      <origin xyz="0 0 0.48" rpy="0 0 0" />
      <geometry>
        <cylinder radius="0.12" length="0.72" />
      </geometry>
    </collision>
    <collision name="pedestal__visual_4">
      <origin xyz="0 0 0.89" rpy="0 0 0" />
      <geometry>
        <cylinder radius="0.16" length="0.1" />
      </geometry>
    </collision>
    <collision name="pedestal__visual_5">
      <origin xyz="0 0 0.945" rpy="0 0 0" />
      <geometry>
        <cylinder radius="0.19" length="0.07" />
      </geometry>
    </collision>
    <collision name="pedestal__visual_6">
      <origin xyz="-0.18 0 0.25" rpy="0 0 0" />
      <geometry>
        <box size="0.22 0.16 0.28" />
      </geometry>
    </collision>
    <collision name="pedestal__visual_7">
      <origin xyz="-0.125 0 0.59" rpy="0 0 0" />
      <geometry>
        <cylinder radius="0.025" length="0.52" />
      </geometry>
    </collision>
  </link>
  <link name="azimuth_stage">
    <inertial>
      <origin xyz="0.02 0 0.24" rpy="0 0 0" />
      <mass value="18" />
      <inertia ixx="0.7548" ixy="0" ixz="0" iyy="0.7278" iyz="0" izz="0.6078" />
    </inertial>
    <visual>
      <origin xyz="0 0 0.04" rpy="0 0 0" />
      <geometry>
        <cylinder radius="0.17" length="0.08" />
      </geometry>
    </visual>
    <visual>
      <origin xyz="-0.02 0 0.12" rpy="0 0 0" />
      <geometry>
        <box size="0.24 0.24 0.12" />
      </geometry>
    </visual>
    <visual>
      <origin xyz="0.12 0 0.42" rpy="-1.5708 0 0" />
      <geometry>
        <cylinder radius="0.018" length="0.36" />
      </geometry>
    </visual>
    <visual>
      <origin xyz="0.12 0.21 0.42" rpy="-1.5708 0 0" />
      <geometry>
        <cylinder radius="0.022" length="0.06" />
      </geometry>
    </visual>
    <visual>
      <origin xyz="0.12 -0.21 0.42" rpy="-1.5708 0 0" />
      <geometry>
        <cylinder radius="0.022" length="0.06" />
      </geometry>
    </visual>
    <visual>
      <geometry>
        <mesh filename="meshes/yoke_arms.glb" />
      </geometry>
    </visual>
    <visual>
      <origin xyz="0.028 0 0.28" rpy="0 0 0" />
      <geometry>
        <box size="0.11 0.14 0.09" />
      </geometry>
    </visual>
    <visual>
      <origin xyz="-0.055 0 0.23" rpy="0 1.5708 0" />
      <geometry>
        <cylinder radius="0.026" length="0.22" />
      </geometry>
    </visual>
    <collision name="azimuth_stage__visual_1">
      <origin xyz="0 0 0.04" rpy="0 0 0" />
      <geometry>
        <cylinder radius="0.17" length="0.08" />
      </geometry>
    </collision>
    <collision name="azimuth_stage__visual_2">
      <origin xyz="-0.02 0 0.12" rpy="0 0 0" />
      <geometry>
        <box size="0.24 0.24 0.12" />
      </geometry>
    </collision>
    <collision name="azimuth_stage__visual_3">
      <origin xyz="0.12 0 0.42" rpy="-1.5708 0 0" />
      <geometry>
        <cylinder radius="0.018" length="0.36" />
      </geometry>
    </collision>
    <collision name="azimuth_stage__visual_4">
      <origin xyz="0.12 0.21 0.42" rpy="-1.5708 0 0" />
      <geometry>
        <cylinder radius="0.022" length="0.06" />
      </geometry>
    </collision>
    <collision name="azimuth_stage__visual_5">
      <origin xyz="0.12 -0.21 0.42" rpy="-1.5708 0 0" />
      <geometry>
        <cylinder radius="0.022" length="0.06" />
      </geometry>
    </collision>
    <collision name="azimuth_stage__visual_6__hull_001">
      <geometry>
        <mesh filename="meshes/collision/cache/509f8cf1da6818aefb69eea6__hull_001.obj" />
      </geometry>
    </collision>
    <collision name="azimuth_stage__visual_6__hull_002">
      <geometry>
        <mesh filename="meshes/collision/cache/509f8cf1da6818aefb69eea6__hull_002.obj" />
      </geometry>
    </collision>
    <collision name="azimuth_stage__visual_6__hull_003">
      <geometry>
        <mesh filename="meshes/collision/cache/509f8cf1da6818aefb69eea6__hull_003.obj" />
      </geometry>
    </collision>
    <collision name="azimuth_stage__visual_6__hull_004">
      <geometry>
        <mesh filename="meshes/collision/cache/509f8cf1da6818aefb69eea6__hull_004.obj" />
      </geometry>
    </collision>
    <collision name="azimuth_stage__visual_7">
      <origin xyz="0.028 0 0.28" rpy="0 0 0" />
      <geometry>
        <box size="0.11 0.14 0.09" />
      </geometry>
    </collision>
    <collision name="azimuth_stage__visual_8">
      <origin xyz="-0.055 0 0.23" rpy="0 1.5708 0" />
      <geometry>
        <cylinder radius="0.026" length="0.22" />
      </geometry>
    </collision>
  </link>
  <link name="dish_assembly">
    <inertial>
      <origin xyz="0.3 0 0.16" rpy="0 0 0" />
      <mass value="13" />
      <inertia ixx="1.33337" ixy="0" ixz="0" iyy="1.49977" iyz="0" izz="2.00027" />
    </inertial>
    <visual>
      <origin xyz="0.28 0 0.16" rpy="0 1.5708 0" />
      <geometry>
        <mesh filename="meshes/reflector_shell.glb" />
      </geometry>
    </visual>
    <visual>
      <origin xyz="0.008 0 0" rpy="0 0 0" />
      <geometry>
        <box size="0.016 0.1 0.1" />
      </geometry>
    </visual>
    <visual>
      <origin xyz="0.055 0 0.04" rpy="0 0 0" />
      <geometry>
        <box size="0.08 0.17 0.12" />
      </geometry>
    </visual>
    <visual>
      <origin xyz="0.026 0 0" rpy="0 0 0" />
      <geometry>
        <cylinder radius="0.035" length="0.1" />
      </geometry>
    </visual>
    <visual>
      <geometry>
        <mesh filename="meshes/dish_supports.glb" />
      </geometry>
    </visual>
    <visual>
      <origin xyz="0.575 0 0.16" rpy="0 0 0" />
      <geometry>
        <box size="0.032 0.048 0.06" />
      </geometry>
    </visual>
    <visual>
      <origin xyz="0.645 0 0.16" rpy="0 1.5708 0" />
      <geometry>
        <cylinder radius="0.018" length="0.12" />
      </geometry>
    </visual>
    <visual>
      <origin xyz="0.725 0 0.16" rpy="0 1.5708 0" />
      <geometry>
        <cylinder radius="0.04" length="0.065" />
      </geometry>
    </visual>
    <visual>
      <origin xyz="0.615 0.042 0.182" rpy="0 0 0" />
      <geometry>
        <box size="0.03 0.04 0.055" />
      </geometry>
    </visual>
    <visual>
      <origin xyz="0.12 -0.112 0.08" rpy="0 0 0" />
      <geometry>
        <box size="0.09 0.074 0.09" />
      </geometry>
    </visual>
    <collision name="dish_assembly__visual_1__hull_001">
      <origin xyz="0.28 0 0.16" rpy="0 1.5708 0" />
      <geometry>
        <mesh filename="meshes/collision/cache/a70d1db5ba12bd3d43b754e3__hull_001.obj" />
      </geometry>
    </collision>
    <collision name="dish_assembly__visual_1__hull_002">
      <origin xyz="0.28 0 0.16" rpy="0 1.5708 0" />
      <geometry>
        <mesh filename="meshes/collision/cache/a70d1db5ba12bd3d43b754e3__hull_002.obj" />
      </geometry>
    </collision>
    <collision name="dish_assembly__visual_1__hull_003">
      <origin xyz="0.28 0 0.16" rpy="0 1.5708 0" />
      <geometry>
        <mesh filename="meshes/collision/cache/a70d1db5ba12bd3d43b754e3__hull_003.obj" />
      </geometry>
    </collision>
    <collision name="dish_assembly__visual_1__hull_004">
      <origin xyz="0.28 0 0.16" rpy="0 1.5708 0" />
      <geometry>
        <mesh filename="meshes/collision/cache/a70d1db5ba12bd3d43b754e3__hull_004.obj" />
      </geometry>
    </collision>
    <collision name="dish_assembly__visual_1__hull_005">
      <origin xyz="0.28 0 0.16" rpy="0 1.5708 0" />
      <geometry>
        <mesh filename="meshes/collision/cache/a70d1db5ba12bd3d43b754e3__hull_005.obj" />
      </geometry>
    </collision>
    <collision name="dish_assembly__visual_1__hull_006">
      <origin xyz="0.28 0 0.16" rpy="0 1.5708 0" />
      <geometry>
        <mesh filename="meshes/collision/cache/a70d1db5ba12bd3d43b754e3__hull_006.obj" />
      </geometry>
    </collision>
    <collision name="dish_assembly__visual_1__hull_007">
      <origin xyz="0.28 0 0.16" rpy="0 1.5708 0" />
      <geometry>
        <mesh filename="meshes/collision/cache/a70d1db5ba12bd3d43b754e3__hull_007.obj" />
      </geometry>
    </collision>
    <collision name="dish_assembly__visual_1__hull_008">
      <origin xyz="0.28 0 0.16" rpy="0 1.5708 0" />
      <geometry>
        <mesh filename="meshes/collision/cache/a70d1db5ba12bd3d43b754e3__hull_008.obj" />
      </geometry>
    </collision>
    <collision name="dish_assembly__visual_1__hull_009">
      <origin xyz="0.28 0 0.16" rpy="0 1.5708 0" />
      <geometry>
        <mesh filename="meshes/collision/cache/a70d1db5ba12bd3d43b754e3__hull_009.obj" />
      </geometry>
    </collision>
    <collision name="dish_assembly__visual_1__hull_010">
      <origin xyz="0.28 0 0.16" rpy="0 1.5708 0" />
      <geometry>
        <mesh filename="meshes/collision/cache/a70d1db5ba12bd3d43b754e3__hull_010.obj" />
      </geometry>
    </collision>
    <collision name="dish_assembly__visual_2">
      <origin xyz="0.008 0 0" rpy="0 0 0" />
      <geometry>
        <box size="0.016 0.1 0.1" />
      </geometry>
    </collision>
    <collision name="dish_assembly__visual_3">
      <origin xyz="0.055 0 0.04" rpy="0 0 0" />
      <geometry>
        <box size="0.08 0.17 0.12" />
      </geometry>
    </collision>
    <collision name="dish_assembly__visual_4">
      <origin xyz="0.026 0 0" rpy="0 0 0" />
      <geometry>
        <cylinder radius="0.035" length="0.1" />
      </geometry>
    </collision>
    <collision name="dish_assembly__visual_5__hull_001">
      <geometry>
        <mesh filename="meshes/collision/cache/fc3d3b5e5c088ad7fb869eba__hull_001.obj" />
      </geometry>
    </collision>
    <collision name="dish_assembly__visual_5__hull_002">
      <geometry>
        <mesh filename="meshes/collision/cache/fc3d3b5e5c088ad7fb869eba__hull_002.obj" />
      </geometry>
    </collision>
    <collision name="dish_assembly__visual_5__hull_003">
      <geometry>
        <mesh filename="meshes/collision/cache/fc3d3b5e5c088ad7fb869eba__hull_003.obj" />
      </geometry>
    </collision>
    <collision name="dish_assembly__visual_5__hull_004">
      <geometry>
        <mesh filename="meshes/collision/cache/fc3d3b5e5c088ad7fb869eba__hull_004.obj" />
      </geometry>
    </collision>
    <collision name="dish_assembly__visual_5__hull_005">
      <geometry>
        <mesh filename="meshes/collision/cache/fc3d3b5e5c088ad7fb869eba__hull_005.obj" />
      </geometry>
    </collision>
    <collision name="dish_assembly__visual_5__hull_006">
      <geometry>
        <mesh filename="meshes/collision/cache/fc3d3b5e5c088ad7fb869eba__hull_006.obj" />
      </geometry>
    </collision>
    <collision name="dish_assembly__visual_5__hull_007">
      <geometry>
        <mesh filename="meshes/collision/cache/fc3d3b5e5c088ad7fb869eba__hull_007.obj" />
      </geometry>
    </collision>
    <collision name="dish_assembly__visual_5__hull_008">
      <geometry>
        <mesh filename="meshes/collision/cache/fc3d3b5e5c088ad7fb869eba__hull_008.obj" />
      </geometry>
    </collision>
    <collision name="dish_assembly__visual_5__hull_009">
      <geometry>
        <mesh filename="meshes/collision/cache/fc3d3b5e5c088ad7fb869eba__hull_009.obj" />
      </geometry>
    </collision>
    <collision name="dish_assembly__visual_5__hull_010">
      <geometry>
        <mesh filename="meshes/collision/cache/fc3d3b5e5c088ad7fb869eba__hull_010.obj" />
      </geometry>
    </collision>
    <collision name="dish_assembly__visual_5__hull_011">
      <geometry>
        <mesh filename="meshes/collision/cache/fc3d3b5e5c088ad7fb869eba__hull_011.obj" />
      </geometry>
    </collision>
    <collision name="dish_assembly__visual_5__hull_012">
      <geometry>
        <mesh filename="meshes/collision/cache/fc3d3b5e5c088ad7fb869eba__hull_012.obj" />
      </geometry>
    </collision>
    <collision name="dish_assembly__visual_5__hull_013">
      <geometry>
        <mesh filename="meshes/collision/cache/fc3d3b5e5c088ad7fb869eba__hull_013.obj" />
      </geometry>
    </collision>
    <collision name="dish_assembly__visual_5__hull_014">
      <geometry>
        <mesh filename="meshes/collision/cache/fc3d3b5e5c088ad7fb869eba__hull_014.obj" />
      </geometry>
    </collision>
    <collision name="dish_assembly__visual_5__hull_015">
      <geometry>
        <mesh filename="meshes/collision/cache/fc3d3b5e5c088ad7fb869eba__hull_015.obj" />
      </geometry>
    </collision>
    <collision name="dish_assembly__visual_6">
      <origin xyz="0.575 0 0.16" rpy="0 0 0" />
      <geometry>
        <box size="0.032 0.048 0.06" />
      </geometry>
    </collision>
    <collision name="dish_assembly__visual_7">
      <origin xyz="0.645 0 0.16" rpy="0 1.5708 0" />
      <geometry>
        <cylinder radius="0.018" length="0.12" />
      </geometry>
    </collision>
    <collision name="dish_assembly__visual_8">
      <origin xyz="0.725 0 0.16" rpy="0 1.5708 0" />
      <geometry>
        <cylinder radius="0.04" length="0.065" />
      </geometry>
    </collision>
    <collision name="dish_assembly__visual_9">
      <origin xyz="0.615 0.042 0.182" rpy="0 0 0" />
      <geometry>
        <box size="0.03 0.04 0.055" />
      </geometry>
    </collision>
    <collision name="dish_assembly__visual_10">
      <origin xyz="0.12 -0.112 0.08" rpy="0 0 0" />
      <geometry>
        <box size="0.09 0.074 0.09" />
      </geometry>
    </collision>
  </link>
  <joint name="azimuth_slew" type="revolute">
    <origin xyz="0 0 0.98" rpy="0 0 0" />
    <parent link="pedestal" />
    <child link="azimuth_stage" />
    <axis xyz="0 0 1" />
    <limit effort="80" velocity="1.4" lower="-2.35" upper="2.35" />
  </joint>
  <joint name="elevation_tilt" type="revolute">
    <origin xyz="0.12 0 0.42" rpy="0 0 0" />
    <parent link="azimuth_stage" />
    <child link="dish_assembly" />
    <axis xyz="0 -1 0" />
    <limit effort="35" velocity="1.3" lower="-0.15" upper="0.95" />
  </joint>
</robot>