<robot name="hinged_flap_panel">
  <material name="frame_finish">
    <color rgba="0.22 0.24 0.27 1" />
  </material>
  <material name="flap_finish">
    <color rgba="0.78 0.8 0.83 1" />
  </material>
  <link name="frame">
    <inertial>
      <mass value="4.2" />
      <inertia ixx="0.0950687" ixy="0" ixz="0" iyy="0.13048" iyz="0" izz="0.0362688" />
    </inertial>
    <visual>
      <geometry>
        <mesh filename="meshes/panel_frame.glb" />
      </geometry>
      <material name="frame_finish" />
    </visual>
    <collision>
      <origin xyz="-0.149 0 0" rpy="0 0 0" />
      <geometry>
        <box size="0.022 0.035 0.52" />
      </geometry>
    </collision>
    <collision>
      <origin xyz="0.149 0 0" rpy="0 0 0" />
      <geometry>
        <box size="0.022 0.035 0.52" />
      </geometry>
    </collision>
    <collision>
      <origin xyz="0 0 0.249" rpy="0 0 0" />
      <geometry>
        <box size="0.276 0.035 0.022" />
      </geometry>
    </collision>
    <collision>
      <origin xyz="0 0 -0.249" rpy="0 0 0" />
      <geometry>
        <box size="0.276 0.035 0.022" />
      </geometry>
    </collision>
    <collision>
      <origin xyz="0 -0.007 0.222" rpy="0 0 0" />
      <geometry>
        <box size="0.276 0.006 0.01" />
      </geometry>
    </collision>
    <collision>
      <origin xyz="0 -0.007 0.103" rpy="0 0 0" />
      <geometry>
        <box size="0.276 0.006 0.01" />
      </geometry>
    </collision>
    <collision>
      <origin xyz="0 -0.007 -0.016" rpy="0 0 0" />
      <geometry>
        <box size="0.276 0.006 0.01" />
      </geometry>
    </collision>
    <collision>
      <origin xyz="0 -0.007 -0.135" rpy="0 0 0" />
      <geometry>
        <box size="0.276 0.006 0.01" />
      </geometry>
    </collision>
  </link>
  <link name="flap_1">
    <inertial>
      <origin xyz="0 0.0045 -0.0525" rpy="0 0 0" />
      <mass value="0.28" />
      <inertia ixx="0.000248383" ixy="0" ixz="0" iyy="0.00187378" iyz="0" izz="0.00162708" />
    </inertial>
    <visual>
      <geometry>
        <mesh filename="meshes/panel_flap.glb" />
      </geometry>
      <material name="flap_finish" />
    </visual>
    <collision>
      <geometry>
        <box size="0.248 0.012 0.012" />
      </geometry>
    </collision>
    <collision>
      <origin xyz="0 0.0045 -0.0525" rpy="0 0 0" />
      <geometry>
        <box size="0.264 0.006 0.103" />
      </geometry>
    </collision>
  </link>
  <link name="flap_2">
    <inertial>
      <origin xyz="0 0.0045 -0.0525" rpy="0 0 0" />
      <mass value="0.28" />
      <inertia ixx="0.000248383" ixy="0" ixz="0" iyy="0.00187378" iyz="0" izz="0.00162708" />
    </inertial>
    <visual>
      <geometry>
        <mesh filename="meshes/panel_flap.glb" />
      </geometry>
      <material name="flap_finish" />
    </visual>
    <collision>
      <geometry>
        <box size="0.248 0.012 0.012" />
      </geometry>
    </collision>
    <collision>
      <origin xyz="0 0.0045 -0.0525" rpy="0 0 0" />
      <geometry>
        <box size="0.264 0.006 0.103" />
      </geometry>
    </collision>
  </link>
  <link name="flap_3">
    <inertial>
      <origin xyz="0 0.0045 -0.0525" rpy="0 0 0" />
      <mass value="0.28" />
      <inertia ixx="0.000248383" ixy="0" ixz="0" iyy="0.00187378" iyz="0" izz="0.00162708" />
    </inertial>
    <visual>
      <geometry>
        <mesh filename="meshes/panel_flap.glb" />
      </geometry>
      <material name="flap_finish" />
    </visual>
    <collision>
      <geometry>
        <box size="0.248 0.012 0.012" />
      </geometry>
    </collision>
    <collision>
      <origin xyz="0 0.0045 -0.0525" rpy="0 0 0" />
      <geometry>
        <box size="0.264 0.006 0.103" />
      </geometry>
    </collision>
  </link>
  <link name="flap_4">
    <inertial>
      <origin xyz="0 0.0045 -0.0525" rpy="0 0 0" />
      <mass value="0.28" />
      <inertia ixx="0.000248383" ixy="0" ixz="0" iyy="0.00187378" iyz="0" izz="0.00162708" />
    </inertial>
    <visual>
      <geometry>
        <mesh filename="meshes/panel_flap.glb" />
      </geometry>
      <material name="flap_finish" />
    </visual>
    <collision>
      <geometry>
        <box size="0.248 0.012 0.012" />
      </geometry>
    </collision>
    <collision>
      <origin xyz="0 0.0045 -0.0525" rpy="0 0 0" />
      <geometry>
        <box size="0.264 0.006 0.103" />
      </geometry>
    </collision>
  </link>
  <joint name="frame_to_flap_1" type="revolute">
    <origin xyz="0 0 0.222" rpy="0 0 0" />
    <parent link="frame" />
    <child link="flap_1" />
    <axis xyz="1 0 0" />
    <limit effort="3" velocity="1.5" lower="0" upper="1.2" />
  </joint>
  <joint name="frame_to_flap_2" type="revolute">
    <origin xyz="0 0 0.103" rpy="0 0 0" />
    <parent link="frame" />
    <child link="flap_2" />
    <axis xyz="1 0 0" />
    <limit effort="3" velocity="1.5" lower="0" upper="1.2" />
  </joint>
  <joint name="frame_to_flap_3" type="revolute">
    <origin xyz="0 0 -0.016" rpy="0 0 0" />
    <parent link="frame" />
    <child link="flap_3" />
    <axis xyz="1 0 0" />
    <limit effort="3" velocity="1.5" lower="0" upper="1.2" />
  </joint>
  <joint name="frame_to_flap_4" type="revolute">
    <origin xyz="0 0 -0.135" rpy="0 0 0" />
    <parent link="frame" />
    <child link="flap_4" />
    <axis xyz="1 0 0" />
    <limit effort="3" velocity="1.5" lower="0" upper="1.2" />
  </joint>
</robot>