<robot name="desk_drawer">
  <material name="desk_shell">
    <color rgba="0.83 0.78 0.7 1" />
  </material>
  <material name="drawer_box">
    <color rgba="0.92 0.9 0.86 1" />
  </material>
  <material name="drawer_front">
    <color rgba="0.7 0.52 0.36 1" />
  </material>
  <material name="handle_metal">
    <color rgba="0.63 0.66 0.7 1" />
  </material>
  <link name="carcass">
    <inertial>
      <mass value="18" />
      <inertia ixx="0.60735" ixy="0" ixz="0" iyy="0.6936" iyz="0" izz="0.99375" />
    </inertial>
    <visual>
      <origin xyz="0 0 0.151" rpy="0 0 0" />
      <geometry>
        <box size="0.6 0.55 0.018" />
      </geometry>
      <material name="desk_shell" />
    </visual>
    <visual>
      <origin xyz="0 0 -0.151" rpy="0 0 0" />
      <geometry>
        <box size="0.6 0.55 0.018" />
      </geometry>
      <material name="desk_shell" />
    </visual>
    <visual>
      <origin xyz="-0.291 0 0" rpy="0 0 0" />
      <geometry>
        <box size="0.018 0.55 0.284" />
      </geometry>
      <material name="desk_shell" />
    </visual>
    <visual>
      <origin xyz="0.291 0 0" rpy="0 0 0" />
      <geometry>
        <box size="0.018 0.55 0.284" />
      </geometry>
      <material name="desk_shell" />
    </visual>
    <visual>
      <origin xyz="0 -0.272 0" rpy="0 0 0" />
      <geometry>
        <box size="0.564 0.006 0.284" />
      </geometry>
      <material name="desk_shell" />
    </visual>
    <collision>
      <origin xyz="0 0 0.151" rpy="0 0 0" />
      <geometry>
        <box size="0.6 0.55 0.018" />
      </geometry>
    </collision>
    <collision>
      <origin xyz="0 0 -0.151" rpy="0 0 0" />
      <geometry>
        <box size="0.6 0.55 0.018" />
      </geometry>
    </collision>
    <collision>
      <origin xyz="-0.291 0 0" rpy="0 0 0" />
      <geometry>
        <box size="0.018 0.55 0.284" />
      </geometry>
    </collision>
    <collision>
      <origin xyz="0.291 0 0" rpy="0 0 0" />
      <geometry>
        <box size="0.018 0.55 0.284" />
      </geometry>
    </collision>
    <collision>
      <origin xyz="0 -0.272 0" rpy="0 0 0" />
      <geometry>
        <box size="0.564 0.006 0.284" />
      </geometry>
    </collision>
  </link>
  <link name="drawer">
    <inertial>
      <origin xyz="0.271 0.1075 0" rpy="0 0 0" />
      <mass value="4.5" />
      <inertia ixx="0.103008" ixy="0" ixz="0" iyy="0.142837" iyz="0" izz="0.190357" />
    </inertial>
    <visual>
      <geometry>
        <box size="0.012 0.43 0.272" />
      </geometry>
      <material name="drawer_box" />
    </visual>
    <visual>
      <origin xyz="0.542 0 0" rpy="0 0 0" />
      <geometry>
        <box size="0.012 0.43 0.272" />
      </geometry>
      <material name="drawer_box" />
    </visual>
    <visual>
      <origin xyz="0.271 0 -0.131" rpy="0 0 0" />
      <geometry>
        <box size="0.53 0.43 0.01" />
      </geometry>
      <material name="drawer_box" />
    </visual>
    <visual>
      <origin xyz="0.271 -0.209 0.005" rpy="0 0 0" />
      <geometry>
        <box size="0.53 0.012 0.262" />
      </geometry>
      <material name="drawer_box" />
    </visual>
    <visual>
      <origin xyz="0.271 0.224 0" rpy="0 0 0" />
      <geometry>
        <box size="0.56 0.018 0.28" />
      </geometry>
      <material name="drawer_front" />
    </visual>
    <visual>
      <origin xyz="0.271 0.245 0" rpy="0 1.5708 0" />
      <geometry>
        <cylinder radius="0.005" length="0.12" />
      </geometry>
      <material name="handle_metal" />
    </visual>
    <visual>
      <origin xyz="0.226 0.236 0" rpy="1.5708 0 0" />
      <geometry>
        <cylinder radius="0.004" length="0.018" />
      </geometry>
      <material name="handle_metal" />
    </visual>
    <visual>
      <origin xyz="0.316 0.236 0" rpy="1.5708 0 0" />
      <geometry>
        <cylinder radius="0.004" length="0.018" />
      </geometry>
      <material name="handle_metal" />
    </visual>
    <collision>
      <geometry>
        <box size="0.012 0.43 0.272" />
      </geometry>
    </collision>
    <collision>
      <origin xyz="0.542 0 0" rpy="0 0 0" />
      <geometry>
        <box size="0.012 0.43 0.272" />
      </geometry>
    </collision>
    <collision>
      <origin xyz="0.271 0 -0.131" rpy="0 0 0" />
      <geometry>
        <box size="0.53 0.43 0.01" />
      </geometry>
    </collision>
    <collision>
      <origin xyz="0.271 -0.209 0.005" rpy="0 0 0" />
      <geometry>
        <box size="0.53 0.012 0.262" />
      </geometry>
    </collision>
    <collision>
      <origin xyz="0.271 0.224 0" rpy="0 0 0" />
      <geometry>
        <box size="0.56 0.018 0.28" />
      </geometry>
    </collision>
  </link>
  <joint name="carcass_to_drawer" type="prismatic">
    <origin xyz="-0.271 0.044 0" rpy="0 0 0" />
    <parent link="carcass" />
    <child link="drawer" />
    <axis xyz="0 1 0" />
    <limit effort="120" velocity="0.6" lower="0" upper="0.32" />
  </joint>
</robot>