<robot name="vacuum_cleaner">
  <material name="body_red">
    <color rgba="0.78 0.1 0.08 1" />
  </material>
  <material name="charcoal">
    <color rgba="0.18 0.19 0.21 1" />
  </material>
  <material name="rubber">
    <color rgba="0.1 0.1 0.11 1" />
  </material>
  <material name="steel">
    <color rgba="0.73 0.76 0.79 1" />
  </material>
  <material name="smoke_clear">
    <color rgba="0.58 0.68 0.76 0.35" />
  </material>
  <material name="mid_gray">
    <color rgba="0.42 0.45 0.48 1" />
  </material>
  <link name="main_body">
    <inertial>
      <origin xyz="0 0 0.12" rpy="0 0 0" />
      <mass value="6" />
      <inertia ixx="0.117" ixy="0" ixz="0" iyy="0.0738" iyz="0" izz="0.1332" />
    </inertial>
    <visual>
      <geometry>
        <mesh filename="meshes/vacuum_body_shell.glb" />
      </geometry>
      <material name="body_red">
        <color rgba="0.78 0.1 0.08 1" />
      </material>
    </visual>
    <visual>
      <origin xyz="0 0.02 0.025" rpy="0 0 0" />
      <geometry>
        <box size="0.22 0.14 0.05" />
      </geometry>
      <material name="charcoal">
        <color rgba="0.18 0.19 0.21 1" />
      </material>
    </visual>
    <visual>
      <origin xyz="0 0.205 0.03" rpy="0 0 0" />
      <geometry>
        <box size="0.18 0.05 0.06" />
      </geometry>
      <material name="charcoal">
        <color rgba="0.18 0.19 0.21 1" />
      </material>
    </visual>
    <visual>
      <origin xyz="0 0.055 0.145" rpy="0 0 0" />
      <geometry>
        <box size="0.14 0.1 0.09" />
      </geometry>
      <material name="smoke_clear">
        <color rgba="0.58 0.68 0.76 0.35" />
      </material>
    </visual>
    <visual>
      <origin xyz="0.145 -0.05 0.075" rpy="0 1.5708 0" />
      <geometry>
        <cylinder radius="0.075" length="0.03" />
      </geometry>
      <material name="rubber">
        <color rgba="0.1 0.1 0.11 1" />
      </material>
    </visual>
    <visual>
      <origin xyz="-0.145 -0.05 0.075" rpy="0 1.5708 0" />
      <geometry>
        <cylinder radius="0.075" length="0.03" />
      </geometry>
      <material name="rubber">
        <color rgba="0.1 0.1 0.11 1" />
      </material>
    </visual>
    <visual>
      <origin xyz="0.085 0.12 0.026" rpy="0 1.5708 0" />
      <geometry>
        <cylinder radius="0.026" length="0.022" />
      </geometry>
      <material name="rubber">
        <color rgba="0.1 0.1 0.11 1" />
      </material>
    </visual>
    <visual>
      <origin xyz="-0.085 0.12 0.026" rpy="0 1.5708 0" />
      <geometry>
        <cylinder radius="0.026" length="0.022" />
      </geometry>
      <material name="rubber">
        <color rgba="0.1 0.1 0.11 1" />
      </material>
    </visual>
    <visual>
      <origin xyz="0 0.205 0.14" rpy="1.5708 0 0" />
      <geometry>
        <cylinder radius="0.026" length="0.06" />
      </geometry>
      <material name="mid_gray">
        <color rgba="0.42 0.45 0.48 1" />
      </material>
    </visual>
    <visual>
      <geometry>
        <mesh filename="meshes/vacuum_carry_handle.glb" />
      </geometry>
      <material name="charcoal">
        <color rgba="0.18 0.19 0.21 1" />
      </material>
    </visual>
    <collision name="main_body__visual_1__hull_001">
      <geometry>
        <mesh filename="meshes/collision/cache/4d994256cdce22eccc84c646__hull_001.obj" />
      </geometry>
    </collision>
    <collision name="main_body__visual_2">
      <origin xyz="0 0.02 0.025" rpy="0 0 0" />
      <geometry>
        <box size="0.22 0.14 0.05" />
      </geometry>
    </collision>
    <collision name="main_body__visual_3">
      <origin xyz="0 0.205 0.03" rpy="0 0 0" />
      <geometry>
        <box size="0.18 0.05 0.06" />
      </geometry>
    </collision>
    <collision name="main_body__visual_4">
      <origin xyz="0 0.055 0.145" rpy="0 0 0" />
      <geometry>
        <box size="0.14 0.1 0.09" />
      </geometry>
    </collision>
    <collision name="main_body__visual_5">
      <origin xyz="0.145 -0.05 0.075" rpy="0 1.5708 0" />
      <geometry>
        <cylinder radius="0.075" length="0.03" />
      </geometry>
    </collision>
    <collision name="main_body__visual_6">
      <origin xyz="-0.145 -0.05 0.075" rpy="0 1.5708 0" />
      <geometry>
        <cylinder radius="0.075" length="0.03" />
      </geometry>
    </collision>
    <collision name="main_body__visual_7">
      <origin xyz="0.085 0.12 0.026" rpy="0 1.5708 0" />
      <geometry>
        <cylinder radius="0.026" length="0.022" />
      </geometry>
    </collision>
    <collision name="main_body__visual_8">
      <origin xyz="-0.085 0.12 0.026" rpy="0 1.5708 0" />
      <geometry>
        <cylinder radius="0.026" length="0.022" />
      </geometry>
    </collision>
    <collision name="main_body__visual_9">
      <origin xyz="0 0.205 0.14" rpy="1.5708 0 0" />
      <geometry>
        <cylinder radius="0.026" length="0.06" />
      </geometry>
    </collision>
    <collision name="main_body__visual_10__hull_001">
      <geometry>
        <mesh filename="meshes/collision/cache/0aeb67a94ea1323f0ebf7f43__hull_001.obj" />
      </geometry>
    </collision>
    <collision name="main_body__visual_10__hull_002">
      <geometry>
        <mesh filename="meshes/collision/cache/0aeb67a94ea1323f0ebf7f43__hull_002.obj" />
      </geometry>
    </collision>
    <collision name="main_body__visual_10__hull_003">
      <geometry>
        <mesh filename="meshes/collision/cache/0aeb67a94ea1323f0ebf7f43__hull_003.obj" />
      </geometry>
    </collision>
    <collision name="main_body__visual_10__hull_004">
      <geometry>
        <mesh filename="meshes/collision/cache/0aeb67a94ea1323f0ebf7f43__hull_004.obj" />
      </geometry>
    </collision>
  </link>
  <link name="connector_hose">
    <inertial>
      <origin xyz="0 0.13 0.34" rpy="0 0 0" />
      <mass value="0.45" />
      <inertia ixx="0.025035" ixy="0" ixz="0" iyy="0.021795" iyz="0" izz="0.00351" />
    </inertial>
    <visual>
      <geometry>
        <mesh filename="meshes/vacuum_hose.glb" />
      </geometry>
      <material name="charcoal">
        <color rgba="0.18 0.19 0.21 1" />
      </material>
    </visual>
    <visual>
      <origin xyz="0 0.028 0" rpy="1.5708 0 0" />
      <geometry>
        <cylinder radius="0.026" length="0.055" />
      </geometry>
      <material name="mid_gray">
        <color rgba="0.42 0.45 0.48 1" />
      </material>
    </visual>
    <visual>
      <origin xyz="0 0.25 0.705" rpy="0 0 0" />
      <geometry>
        <cylinder radius="0.024" length="0.085" />
      </geometry>
      <material name="mid_gray">
        <color rgba="0.42 0.45 0.48 1" />
      </material>
    </visual>
    <collision name="connector_hose__visual_1__hull_001">
      <geometry>
        <mesh filename="meshes/collision/cache/0d2ab83db3df0ecc3f50b87f__hull_001.obj" />
      </geometry>
    </collision>
    <collision name="connector_hose__visual_1__hull_002">
      <geometry>
        <mesh filename="meshes/collision/cache/0d2ab83db3df0ecc3f50b87f__hull_002.obj" />
      </geometry>
    </collision>
    <collision name="connector_hose__visual_2">
      <origin xyz="0 0.028 0" rpy="1.5708 0 0" />
      <geometry>
        <cylinder radius="0.026" length="0.055" />
      </geometry>
    </collision>
    <collision name="connector_hose__visual_3">
      <origin xyz="0 0.25 0.705" rpy="0 0 0" />
      <geometry>
        <cylinder radius="0.024" length="0.085" />
      </geometry>
    </collision>
  </link>
  <link name="wand">
    <inertial>
      <origin xyz="0 -0.01 -0.36" rpy="0 0 0" />
      <mass value="1.1" />
      <inertia ixx="0.0846633" ixy="0" ixz="0" iyy="0.0823167" iyz="0" izz="0.00498667" />
    </inertial>
    <visual>
      <origin xyz="0 0 -0.04" rpy="0 0 0" />
      <geometry>
        <cylinder radius="0.021" length="0.08" />
      </geometry>
      <material name="mid_gray">
        <color rgba="0.42 0.45 0.48 1" />
      </material>
    </visual>
    <visual>
      <origin xyz="0 0 -0.43" rpy="0 0 0" />
      <geometry>
        <cylinder radius="0.017" length="0.78" />
      </geometry>
      <material name="steel">
        <color rgba="0.73 0.76 0.79 1" />
      </material>
    </visual>
    <visual>
      <origin xyz="0 0 -0.76" rpy="0 0 0" />
      <geometry>
        <cylinder radius="0.02" length="0.12" />
      </geometry>
      <material name="charcoal">
        <color rgba="0.18 0.19 0.21 1" />
      </material>
    </visual>
    <visual>
      <origin xyz="0 -0.03 0.04" rpy="0 0 0" />
      <geometry>
        <box size="0.075 0.055 0.11" />
      </geometry>
      <material name="charcoal">
        <color rgba="0.18 0.19 0.21 1" />
      </material>
    </visual>
    <visual>
      <origin xyz="0 -0.095 0.1" rpy="1.5708 0 0" />
      <geometry>
        <cylinder radius="0.017" length="0.14" />
      </geometry>
      <material name="charcoal">
        <color rgba="0.18 0.19 0.21 1" />
      </material>
    </visual>
    <visual>
      <origin xyz="0 -0.015 0.105" rpy="0 0 0" />
      <geometry>
        <box size="0.022 0.02 0.04" />
      </geometry>
      <material name="body_red">
        <color rgba="0.78 0.1 0.08 1" />
      </material>
    </visual>
    <visual>
      <geometry>
        <mesh filename="meshes/vacuum_wand_handle.glb" />
      </geometry>
      <material name="charcoal">
        <color rgba="0.18 0.19 0.21 1" />
      </material>
    </visual>
    <collision name="wand__visual_1">
      <origin xyz="0 0 -0.04" rpy="0 0 0" />
      <geometry>
        <cylinder radius="0.021" length="0.08" />
      </geometry>
    </collision>
    <collision name="wand__visual_2">
      <origin xyz="0 0 -0.43" rpy="0 0 0" />
      <geometry>
        <cylinder radius="0.017" length="0.78" />
      </geometry>
    </collision>
    <collision name="wand__visual_3">
      <origin xyz="0 0 -0.76" rpy="0 0 0" />
      <geometry>
        <cylinder radius="0.02" length="0.12" />
      </geometry>
    </collision>
    <collision name="wand__visual_4">
      <origin xyz="0 -0.03 0.04" rpy="0 0 0" />
      <geometry>
        <box size="0.075 0.055 0.11" />
      </geometry>
    </collision>
    <collision name="wand__visual_5">
      <origin xyz="0 -0.095 0.1" rpy="1.5708 0 0" />
      <geometry>
        <cylinder radius="0.017" length="0.14" />
      </geometry>
    </collision>
    <collision name="wand__visual_6">
      <origin xyz="0 -0.015 0.105" rpy="0 0 0" />
      <geometry>
        <box size="0.022 0.02 0.04" />
      </geometry>
    </collision>
    <collision name="wand__visual_7__hull_001">
      <geometry>
        <mesh filename="meshes/collision/cache/1df1bf2cf48a5917ed2108ad__hull_001.obj" />
      </geometry>
    </collision>
    <collision name="wand__visual_7__hull_002">
      <geometry>
        <mesh filename="meshes/collision/cache/1df1bf2cf48a5917ed2108ad__hull_002.obj" />
      </geometry>
    </collision>
    <collision name="wand__visual_7__hull_003">
      <geometry>
        <mesh filename="meshes/collision/cache/1df1bf2cf48a5917ed2108ad__hull_003.obj" />
      </geometry>
    </collision>
    <collision name="wand__visual_7__hull_004">
      <geometry>
        <mesh filename="meshes/collision/cache/1df1bf2cf48a5917ed2108ad__hull_004.obj" />
      </geometry>
    </collision>
    <collision name="wand__visual_7__hull_005">
      <geometry>
        <mesh filename="meshes/collision/cache/1df1bf2cf48a5917ed2108ad__hull_005.obj" />
      </geometry>
    </collision>
    <collision name="wand__visual_7__hull_006">
      <geometry>
        <mesh filename="meshes/collision/cache/1df1bf2cf48a5917ed2108ad__hull_006.obj" />
      </geometry>
    </collision>
  </link>
  <link name="floor_head">
    <inertial>
      <origin xyz="0 0.1 -0.03" rpy="0 0 0" />
      <mass value="1.4" />
      <inertia ixx="0.0100917" ixy="0" ixz="0" iyy="0.0144317" iyz="0" izz="0.0226333" />
    </inertial>
    <visual>
      <origin xyz="0 -0.015 0" rpy="0 1.5708 0" />
      <geometry>
        <cylinder radius="0.018" length="0.085" />
      </geometry>
      <material name="mid_gray">
        <color rgba="0.42 0.45 0.48 1" />
      </material>
    </visual>
    <visual>
      <origin xyz="0 0 -0.04" rpy="0 0 0" />
      <geometry>
        <box size="0.07 0.05 0.07" />
      </geometry>
      <material name="charcoal">
        <color rgba="0.18 0.19 0.21 1" />
      </material>
    </visual>
    <visual>
      <origin xyz="0 0.095 -0.033" rpy="0 0 0" />
      <geometry>
        <box size="0.31 0.12 0.048" />
      </geometry>
      <material name="charcoal">
        <color rgba="0.18 0.19 0.21 1" />
      </material>
    </visual>
    <visual>
      <origin xyz="0 0.03 -0.01" rpy="0 0 0" />
      <geometry>
        <mesh filename="meshes/vacuum_floor_head_top.glb" />
      </geometry>
      <material name="body_red">
        <color rgba="0.78 0.1 0.08 1" />
      </material>
    </visual>
    <visual>
      <origin xyz="0 0.105 -0.056" rpy="0 0 0" />
      <geometry>
        <box size="0.28 0.09 0.01" />
      </geometry>
      <material name="rubber">
        <color rgba="0.1 0.1 0.11 1" />
      </material>
    </visual>
    <visual>
      <origin xyz="0.12 0.026 -0.046" rpy="0 1.5708 0" />
      <geometry>
        <cylinder radius="0.016" length="0.024" />
      </geometry>
      <material name="rubber">
        <color rgba="0.1 0.1 0.11 1" />
      </material>
    </visual>
    <visual>
      <origin xyz="-0.12 0.026 -0.046" rpy="0 1.5708 0" />
      <geometry>
        <cylinder radius="0.016" length="0.024" />
      </geometry>
      <material name="rubber">
        <color rgba="0.1 0.1 0.11 1" />
      </material>
    </visual>
    <visual>
      <origin xyz="0 0.03 -0.046" rpy="0 0 0" />
      <geometry>
        <box size="0.27 0.024 0.02" />
      </geometry>
      <material name="rubber">
        <color rgba="0.1 0.1 0.11 1" />
      </material>
    </visual>
    <collision name="floor_head__visual_1">
      <origin xyz="0 -0.015 0" rpy="0 1.5708 0" />
      <geometry>
        <cylinder radius="0.018" length="0.085" />
      </geometry>
    </collision>
    <collision name="floor_head__visual_2">
      <origin xyz="0 0 -0.04" rpy="0 0 0" />
      <geometry>
        <box size="0.07 0.05 0.07" />
      </geometry>
    </collision>
    <collision name="floor_head__visual_3">
      <origin xyz="0 0.095 -0.033" rpy="0 0 0" />
      <geometry>
        <box size="0.31 0.12 0.048" />
      </geometry>
    </collision>
    <collision name="floor_head__visual_4__hull_001">
      <origin xyz="0 0.03 -0.01" rpy="0 0 0" />
      <geometry>
        <mesh filename="meshes/collision/cache/ba4aa4052032cecb41529cdb__hull_001.obj" />
      </geometry>
    </collision>
    <collision name="floor_head__visual_5">
      <origin xyz="0 0.105 -0.056" rpy="0 0 0" />
      <geometry>
        <box size="0.28 0.09 0.01" />
      </geometry>
    </collision>
    <collision name="floor_head__visual_6">
      <origin xyz="0.12 0.026 -0.046" rpy="0 1.5708 0" />
      <geometry>
        <cylinder radius="0.016" length="0.024" />
      </geometry>
    </collision>
    <collision name="floor_head__visual_7">
      <origin xyz="-0.12 0.026 -0.046" rpy="0 1.5708 0" />
      <geometry>
        <cylinder radius="0.016" length="0.024" />
      </geometry>
    </collision>
    <collision name="floor_head__visual_8">
      <origin xyz="0 0.03 -0.046" rpy="0 0 0" />
      <geometry>
        <box size="0.27 0.024 0.02" />
      </geometry>
    </collision>
  </link>
  <joint name="body_to_hose" type="fixed">
    <origin xyz="0 0.208 0.14" rpy="0 0 0" />
    <parent link="main_body" />
    <child link="connector_hose" />
  </joint>
  <joint name="hose_to_wand" type="revolute">
    <origin xyz="0 0.25 0.748" rpy="0.58 0 0" />
    <parent link="connector_hose" />
    <child link="wand" />
    <axis xyz="1 0 0" />
    <limit effort="8" velocity="2.5" lower="-0.35" upper="0.45" />
  </joint>
  <joint name="wand_to_floor_head" type="revolute">
    <origin xyz="0 0 -0.82" rpy="-0.58 0 0" />
    <parent link="wand" />
    <child link="floor_head" />
    <axis xyz="1 0 0" />
    <limit effort="6" velocity="4" lower="-0.35" upper="0.6" />
  </joint>
</robot>