<robot name="rolling_tool_cart">
  <material name="powder_coat_red">
    <color rgba="0.72 0.1 0.08 1" />
    </material>
  <material name="charcoal_steel">
    <color rgba="0.18 0.19 0.22 1" />
    </material>
  <material name="brushed_steel">
    <color rgba="0.72 0.74 0.76 1" />
    </material>
  <material name="rubber_black">
    <color rgba="0.1 0.1 0.11 1" />
    </material>
  <material name="matte_black">
    <color rgba="0.16 0.16 0.17 1" />
    </material>
  <link name="body">
    <inertial>
      <origin xyz="-0.02 0 0.52" rpy="0 0 0" />
      <mass value="38" />
      <inertia ixx="2.2002" ixy="0" ixz="0" iyy="2.49787" iyz="0" izz="1.41487" />
      </inertial>
    <visual name="front_left_mount">
      <origin xyz="0.17 0.16 0.17" rpy="0 0 0" />
      <geometry>
        <box size="0.06 0.06 0.02" />
        </geometry>
      <material name="charcoal_steel">
        <color rgba="0.18 0.19 0.22 1" />
        </material>
      </visual>
    <visual name="front_right_mount">
      <origin xyz="0.17 -0.16 0.17" rpy="0 0 0" />
      <geometry>
        <box size="0.06 0.06 0.02" />
        </geometry>
      <material name="charcoal_steel">
        <color rgba="0.18 0.19 0.22 1" />
        </material>
      </visual>
    <visual name="rear_left_mount">
      <origin xyz="-0.21 0.16 0.17" rpy="0 0 0" />
      <geometry>
        <box size="0.06 0.06 0.02" />
        </geometry>
      <material name="charcoal_steel">
        <color rgba="0.18 0.19 0.22 1" />
        </material>
      </visual>
    <visual name="rear_right_mount">
      <origin xyz="-0.21 -0.16 0.17" rpy="0 0 0" />
      <geometry>
        <box size="0.06 0.06 0.02" />
        </geometry>
      <material name="charcoal_steel">
        <color rgba="0.18 0.19 0.22 1" />
        </material>
      </visual>
    <visual name="undercarriage_plate">
      <origin xyz="-0.02 0 0.19" rpy="0 0 0" />
      <geometry>
        <box size="0.46 0.34 0.02" />
        </geometry>
      <material name="charcoal_steel">
        <color rgba="0.18 0.19 0.22 1" />
        </material>
      </visual>
    <visual name="bottom_shelf">
      <origin xyz="-0.02 0 0.209" rpy="0 0 0" />
      <geometry>
        <box size="0.5 0.384 0.018" />
        </geometry>
      <material name="charcoal_steel">
        <color rgba="0.18 0.19 0.22 1" />
        </material>
      </visual>
    <visual name="middle_shelf">
      <origin xyz="-0.02 0 0.498" rpy="0 0 0" />
      <geometry>
        <box size="0.5 0.384 0.016" />
        </geometry>
      <material name="charcoal_steel">
        <color rgba="0.18 0.19 0.22 1" />
        </material>
      </visual>
    <visual name="left_side">
      <origin xyz="-0.02 0.201 0.52" rpy="0 0 0" />
      <geometry>
        <box size="0.52 0.018 0.62" />
        </geometry>
      <material name="powder_coat_red">
        <color rgba="0.72 0.1 0.08 1" />
        </material>
      </visual>
    <visual name="right_side">
      <origin xyz="-0.02 -0.201 0.52" rpy="0 0 0" />
      <geometry>
        <box size="0.52 0.018 0.62" />
        </geometry>
      <material name="powder_coat_red">
        <color rgba="0.72 0.1 0.08 1" />
        </material>
      </visual>
    <visual name="rear_panel">
      <origin xyz="-0.271 0 0.52" rpy="0 0 0" />
      <geometry>
        <box size="0.018 0.384 0.62" />
        </geometry>
      <material name="powder_coat_red">
        <color rgba="0.72 0.1 0.08 1" />
        </material>
      </visual>
    <visual name="top_tray_floor">
      <origin xyz="-0.02 0 0.84" rpy="0 0 0" />
      <geometry>
        <box size="0.52 0.42 0.02" />
        </geometry>
      <material name="powder_coat_red">
        <color rgba="0.72 0.1 0.08 1" />
        </material>
      </visual>
    <visual name="top_left_rail">
      <origin xyz="-0.02 0.201 0.8575" rpy="0 0 0" />
      <geometry>
        <box size="0.52 0.018 0.055" />
        </geometry>
      <material name="powder_coat_red">
        <color rgba="0.72 0.1 0.08 1" />
        </material>
      </visual>
    <visual name="top_right_rail">
      <origin xyz="-0.02 -0.201 0.8575" rpy="0 0 0" />
      <geometry>
        <box size="0.52 0.018 0.055" />
        </geometry>
      <material name="powder_coat_red">
        <color rgba="0.72 0.1 0.08 1" />
        </material>
      </visual>
    <visual name="top_rear_rail">
      <origin xyz="-0.271 0 0.8575" rpy="0 0 0" />
      <geometry>
        <box size="0.018 0.384 0.055" />
        </geometry>
      <material name="powder_coat_red">
        <color rgba="0.72 0.1 0.08 1" />
        </material>
      </visual>
    <visual name="top_front_rail">
      <origin xyz="0.231 0 0.8575" rpy="0 0 0" />
      <geometry>
        <box size="0.018 0.384 0.055" />
        </geometry>
      <material name="powder_coat_red">
        <color rgba="0.72 0.1 0.08 1" />
        </material>
      </visual>
    <visual name="front_left_stile">
      <origin xyz="0.229 0.183 0.52" rpy="0 0 0" />
      <geometry>
        <box size="0.01 0.018 0.62" />
        </geometry>
      <material name="powder_coat_red">
        <color rgba="0.72 0.1 0.08 1" />
        </material>
      </visual>
    <visual name="front_right_stile">
      <origin xyz="0.229 -0.183 0.52" rpy="0 0 0" />
      <geometry>
        <box size="0.01 0.018 0.62" />
        </geometry>
      <material name="powder_coat_red">
        <color rgba="0.72 0.1 0.08 1" />
        </material>
      </visual>
    <visual name="front_lower_rail">
      <origin xyz="0.229 0 0.19" rpy="0 0 0" />
      <geometry>
        <box size="0.01 0.348 0.04" />
        </geometry>
      <material name="powder_coat_red">
        <color rgba="0.72 0.1 0.08 1" />
        </material>
      </visual>
    <visual name="front_center_rail">
      <origin xyz="0.229 0 0.458" rpy="0 0 0" />
      <geometry>
        <box size="0.01 0.348 0.02" />
        </geometry>
      <material name="powder_coat_red">
        <color rgba="0.72 0.1 0.08 1" />
        </material>
      </visual>
    <visual name="front_header">
      <origin xyz="0.229 0 0.7" rpy="0 0 0" />
      <geometry>
        <box size="0.01 0.348 0.052" />
        </geometry>
      <material name="powder_coat_red">
        <color rgba="0.72 0.1 0.08 1" />
        </material>
      </visual>
    <visual name="lower_left_runner">
      <origin xyz="-0.035 0.189 0.228" rpy="0 0 0" />
      <geometry>
        <box size="0.3 0.022 0.012" />
        </geometry>
      <material name="brushed_steel">
        <color rgba="0.72 0.74 0.76 1" />
        </material>
      </visual>
    <visual name="lower_right_runner">
      <origin xyz="-0.035 -0.189 0.228" rpy="0 0 0" />
      <geometry>
        <box size="0.3 0.022 0.012" />
        </geometry>
      <material name="brushed_steel">
        <color rgba="0.72 0.74 0.76 1" />
        </material>
      </visual>
    <visual name="upper_left_runner">
      <origin xyz="-0.035 0.189 0.516" rpy="0 0 0" />
      <geometry>
        <box size="0.3 0.022 0.012" />
        </geometry>
      <material name="brushed_steel">
        <color rgba="0.72 0.74 0.76 1" />
        </material>
      </visual>
    <visual name="upper_right_runner">
      <origin xyz="-0.035 -0.189 0.516" rpy="0 0 0" />
      <geometry>
        <box size="0.3 0.022 0.012" />
        </geometry>
      <material name="brushed_steel">
        <color rgba="0.72 0.74 0.76 1" />
        </material>
      </visual>
    <visual name="handle_front_standoff">
      <origin xyz="0.105 0.219 0.6" rpy="0 0 0" />
      <geometry>
        <box size="0.018 0.038 0.022" />
        </geometry>
      <material name="brushed_steel">
        <color rgba="0.72 0.74 0.76 1" />
        </material>
      </visual>
    <visual name="handle_rear_standoff">
      <origin xyz="-0.105 0.219 0.6" rpy="0 0 0" />
      <geometry>
        <box size="0.018 0.038 0.022" />
        </geometry>
      <material name="brushed_steel">
        <color rgba="0.72 0.74 0.76 1" />
        </material>
      </visual>
    <visual name="side_push_handle">
      <origin xyz="0 0.247 0.6" rpy="0 1.5708 0" />
      <geometry>
        <cylinder radius="0.009" length="0.21" />
        </geometry>
      <material name="brushed_steel">
        <color rgba="0.72 0.74 0.76 1" />
        </material>
      </visual>
    <visual name="top_tray_liner">
      <origin xyz="-0.01 0 0.8515" rpy="0 0 0" />
      <geometry>
        <box size="0.47 0.34 0.003" />
        </geometry>
      <material name="matte_black">
        <color rgba="0.16 0.16 0.17 1" />
        </material>
      </visual>
    <visual name="left_stamp_rib">
      <origin xyz="-0.03 0.207 0.62" rpy="0 0 0" />
      <geometry>
        <box size="0.34 0.004 0.03" />
        </geometry>
      <material name="charcoal_steel">
        <color rgba="0.18 0.19 0.22 1" />
        </material>
      </visual>
    <visual name="right_stamp_rib">
      <origin xyz="-0.03 -0.207 0.62" rpy="0 0 0" />
      <geometry>
        <box size="0.34 0.004 0.03" />
        </geometry>
      <material name="charcoal_steel">
        <color rgba="0.18 0.19 0.22 1" />
        </material>
      </visual>
    <collision name="body__front_left_mount">
      <origin xyz="0.17 0.16 0.17" rpy="0 0 0" />
      <geometry>
        <box size="0.06 0.06 0.02" />
        </geometry>
      </collision>
    <collision name="body__front_right_mount">
      <origin xyz="0.17 -0.16 0.17" rpy="0 0 0" />
      <geometry>
        <box size="0.06 0.06 0.02" />
        </geometry>
      </collision>
    <collision name="body__rear_left_mount">
      <origin xyz="-0.21 0.16 0.17" rpy="0 0 0" />
      <geometry>
        <box size="0.06 0.06 0.02" />
        </geometry>
      </collision>
    <collision name="body__rear_right_mount">
      <origin xyz="-0.21 -0.16 0.17" rpy="0 0 0" />
      <geometry>
        <box size="0.06 0.06 0.02" />
        </geometry>
      </collision>
    <collision name="body__undercarriage_plate">
      <origin xyz="-0.02 0 0.19" rpy="0 0 0" />
      <geometry>
        <box size="0.46 0.34 0.02" />
        </geometry>
      </collision>
    <collision name="body__bottom_shelf">
      <origin xyz="-0.02 0 0.209" rpy="0 0 0" />
      <geometry>
        <box size="0.5 0.384 0.018" />
        </geometry>
      </collision>
    <collision name="body__middle_shelf">
      <origin xyz="-0.02 0 0.498" rpy="0 0 0" />
      <geometry>
        <box size="0.5 0.384 0.016" />
        </geometry>
      </collision>
    <collision name="body__left_side">
      <origin xyz="-0.02 0.201 0.52" rpy="0 0 0" />
      <geometry>
        <box size="0.52 0.018 0.62" />
        </geometry>
      </collision>
    <collision name="body__right_side">
      <origin xyz="-0.02 -0.201 0.52" rpy="0 0 0" />
      <geometry>
        <box size="0.52 0.018 0.62" />
        </geometry>
      </collision>
    <collision name="body__rear_panel">
      <origin xyz="-0.271 0 0.52" rpy="0 0 0" />
      <geometry>
        <box size="0.018 0.384 0.62" />
        </geometry>
      </collision>
    <collision name="body__top_tray_floor">
      <origin xyz="-0.02 0 0.84" rpy="0 0 0" />
      <geometry>
        <box size="0.52 0.42 0.02" />
        </geometry>
      </collision>
    <collision name="body__top_left_rail">
      <origin xyz="-0.02 0.201 0.8575" rpy="0 0 0" />
      <geometry>
        <box size="0.52 0.018 0.055" />
        </geometry>
      </collision>
    <collision name="body__top_right_rail">
      <origin xyz="-0.02 -0.201 0.8575" rpy="0 0 0" />
      <geometry>
        <box size="0.52 0.018 0.055" />
        </geometry>
      </collision>
    <collision name="body__top_rear_rail">
      <origin xyz="-0.271 0 0.8575" rpy="0 0 0" />
      <geometry>
        <box size="0.018 0.384 0.055" />
        </geometry>
      </collision>
    <collision name="body__top_front_rail">
      <origin xyz="0.231 0 0.8575" rpy="0 0 0" />
      <geometry>
        <box size="0.018 0.384 0.055" />
        </geometry>
      </collision>
    <collision name="body__front_left_stile">
      <origin xyz="0.229 0.183 0.52" rpy="0 0 0" />
      <geometry>
        <box size="0.01 0.018 0.62" />
        </geometry>
      </collision>
    <collision name="body__front_right_stile">
      <origin xyz="0.229 -0.183 0.52" rpy="0 0 0" />
      <geometry>
        <box size="0.01 0.018 0.62" />
        </geometry>
      </collision>
    <collision name="body__front_lower_rail">
      <origin xyz="0.229 0 0.19" rpy="0 0 0" />
      <geometry>
        <box size="0.01 0.348 0.04" />
        </geometry>
      </collision>
    <collision name="body__front_center_rail">
      <origin xyz="0.229 0 0.458" rpy="0 0 0" />
      <geometry>
        <box size="0.01 0.348 0.02" />
        </geometry>
      </collision>
    <collision name="body__front_header">
      <origin xyz="0.229 0 0.7" rpy="0 0 0" />
      <geometry>
        <box size="0.01 0.348 0.052" />
        </geometry>
      </collision>
    <collision name="body__lower_left_runner">
      <origin xyz="-0.035 0.189 0.228" rpy="0 0 0" />
      <geometry>
        <box size="0.3 0.022 0.012" />
        </geometry>
      </collision>
    <collision name="body__lower_right_runner">
      <origin xyz="-0.035 -0.189 0.228" rpy="0 0 0" />
      <geometry>
        <box size="0.3 0.022 0.012" />
        </geometry>
      </collision>
    <collision name="body__upper_left_runner">
      <origin xyz="-0.035 0.189 0.516" rpy="0 0 0" />
      <geometry>
        <box size="0.3 0.022 0.012" />
        </geometry>
      </collision>
    <collision name="body__upper_right_runner">
      <origin xyz="-0.035 -0.189 0.516" rpy="0 0 0" />
      <geometry>
        <box size="0.3 0.022 0.012" />
        </geometry>
      </collision>
    <collision name="body__handle_front_standoff">
      <origin xyz="0.105 0.219 0.6" rpy="0 0 0" />
      <geometry>
        <box size="0.018 0.038 0.022" />
        </geometry>
      </collision>
    <collision name="body__handle_rear_standoff">
      <origin xyz="-0.105 0.219 0.6" rpy="0 0 0" />
      <geometry>
        <box size="0.018 0.038 0.022" />
        </geometry>
      </collision>
    <collision name="body__side_push_handle">
      <origin xyz="0 0.247 0.6" rpy="0 1.5708 0" />
      <geometry>
        <cylinder radius="0.009" length="0.21" />
        </geometry>
      </collision>
    <collision name="body__top_tray_liner">
      <origin xyz="-0.01 0 0.8515" rpy="0 0 0" />
      <geometry>
        <box size="0.47 0.34 0.003" />
        </geometry>
      </collision>
    <collision name="body__left_stamp_rib">
      <origin xyz="-0.03 0.207 0.62" rpy="0 0 0" />
      <geometry>
        <box size="0.34 0.004 0.03" />
        </geometry>
      </collision>
    <collision name="body__right_stamp_rib">
      <origin xyz="-0.03 -0.207 0.62" rpy="0 0 0" />
      <geometry>
        <box size="0.34 0.004 0.03" />
        </geometry>
      </collision>
    </link>
  <link name="upper_drawer">
    <inertial>
      <origin xyz="0.244 0 0.08" rpy="0 0 0" />
      <mass value="4" />
      <inertia ixx="0.0546613" ixy="0" ixz="0" iyy="0.0879147" iyz="0" izz="0.125509" />
      </inertial>
    <visual name="upper_drawer_floor">
      <origin xyz="0.232 0 0.007" rpy="0 0 0" />
      <geometry>
        <box size="0.464 0.332 0.014" />
        </geometry>
      <material name="charcoal_steel">
        <color rgba="0.18 0.19 0.22 1" />
        </material>
      </visual>
    <visual name="upper_drawer_left_wall">
      <origin xyz="0.232 0.169 0.05" rpy="0 0 0" />
      <geometry>
        <box size="0.464 0.012 0.1" />
        </geometry>
      <material name="charcoal_steel">
        <color rgba="0.18 0.19 0.22 1" />
        </material>
      </visual>
    <visual name="upper_drawer_right_wall">
      <origin xyz="0.232 -0.169 0.05" rpy="0 0 0" />
      <geometry>
        <box size="0.464 0.012 0.1" />
        </geometry>
      <material name="charcoal_steel">
        <color rgba="0.18 0.19 0.22 1" />
        </material>
      </visual>
    <visual name="upper_drawer_back_wall">
      <origin xyz="0.007 0 0.05" rpy="0 0 0" />
      <geometry>
        <box size="0.014 0.35 0.1" />
        </geometry>
      <material name="charcoal_steel">
        <color rgba="0.18 0.19 0.22 1" />
        </material>
      </visual>
    <visual name="upper_drawer_face">
      <origin xyz="0.476 0 0.08" rpy="0 0 0" />
      <geometry>
        <box size="0.024 0.372 0.16" />
        </geometry>
      <material name="powder_coat_red">
        <color rgba="0.72 0.1 0.08 1" />
        </material>
      </visual>
    <visual name="upper_drawer_liner">
      <origin xyz="0.242 0 0.0155" rpy="0 0 0" />
      <geometry>
        <box size="0.434 0.314 0.003" />
        </geometry>
      <material name="matte_black">
        <color rgba="0.16 0.16 0.17 1" />
        </material>
      </visual>
    <visual name="upper_drawer_handle_left_post">
      <origin xyz="0.489 0.09 0.08" rpy="0 0 0" />
      <geometry>
        <box size="0.016 0.014 0.024" />
        </geometry>
      <material name="brushed_steel">
        <color rgba="0.72 0.74 0.76 1" />
        </material>
      </visual>
    <visual name="upper_drawer_handle_right_post">
      <origin xyz="0.489 -0.09 0.08" rpy="0 0 0" />
      <geometry>
        <box size="0.016 0.014 0.024" />
        </geometry>
      <material name="brushed_steel">
        <color rgba="0.72 0.74 0.76 1" />
        </material>
      </visual>
    <visual name="upper_drawer_handle_grip">
      <origin xyz="0.504 0 0.08" rpy="-1.5708 0 0" />
      <geometry>
        <cylinder radius="0.008" length="0.19" />
        </geometry>
      <material name="brushed_steel">
        <color rgba="0.72 0.74 0.76 1" />
        </material>
      </visual>
    <visual name="upper_drawer_label_frame">
      <origin xyz="0.487 0 0.1216" rpy="0 0 0" />
      <geometry>
        <box size="0.004 0.11 0.03" />
        </geometry>
      <material name="brushed_steel">
        <color rgba="0.72 0.74 0.76 1" />
        </material>
      </visual>
    <collision name="upper_drawer__upper_drawer_floor">
      <origin xyz="0.232 0 0.007" rpy="0 0 0" />
      <geometry>
        <box size="0.464 0.332 0.014" />
        </geometry>
      </collision>
    <collision name="upper_drawer__upper_drawer_left_wall">
      <origin xyz="0.232 0.169 0.05" rpy="0 0 0" />
      <geometry>
        <box size="0.464 0.012 0.1" />
        </geometry>
      </collision>
    <collision name="upper_drawer__upper_drawer_right_wall">
      <origin xyz="0.232 -0.169 0.05" rpy="0 0 0" />
      <geometry>
        <box size="0.464 0.012 0.1" />
        </geometry>
      </collision>
    <collision name="upper_drawer__upper_drawer_back_wall">
      <origin xyz="0.007 0 0.05" rpy="0 0 0" />
      <geometry>
        <box size="0.014 0.35 0.1" />
        </geometry>
      </collision>
    <collision name="upper_drawer__upper_drawer_face">
      <origin xyz="0.476 0 0.08" rpy="0 0 0" />
      <geometry>
        <box size="0.024 0.372 0.16" />
        </geometry>
      </collision>
    <collision name="upper_drawer__upper_drawer_liner">
      <origin xyz="0.242 0 0.0155" rpy="0 0 0" />
      <geometry>
        <box size="0.434 0.314 0.003" />
        </geometry>
      </collision>
    <collision name="upper_drawer__upper_drawer_handle_left_post">
      <origin xyz="0.489 0.09 0.08" rpy="0 0 0" />
      <geometry>
        <box size="0.016 0.014 0.024" />
        </geometry>
      </collision>
    <collision name="upper_drawer__upper_drawer_handle_right_post">
      <origin xyz="0.489 -0.09 0.08" rpy="0 0 0" />
      <geometry>
        <box size="0.016 0.014 0.024" />
        </geometry>
      </collision>
    <collision name="upper_drawer__upper_drawer_handle_grip">
      <origin xyz="0.504 0 0.08" rpy="-1.5708 0 0" />
      <geometry>
        <cylinder radius="0.008" length="0.19" />
        </geometry>
      </collision>
    <collision name="upper_drawer__upper_drawer_label_frame">
      <origin xyz="0.487 0 0.1216" rpy="0 0 0" />
      <geometry>
        <box size="0.004 0.11 0.03" />
        </geometry>
      </collision>
    </link>
  <link name="lower_drawer">
    <inertial>
      <origin xyz="0.244 0 0.105" rpy="0 0 0" />
      <mass value="5.5" />
      <inertia ixx="0.0836385" ixy="0" ixz="0" iyy="0.129362" iyz="0" izz="0.172575" />
      </inertial>
    <visual name="lower_drawer_floor">
      <origin xyz="0.232 0 0.007" rpy="0 0 0" />
      <geometry>
        <box size="0.464 0.332 0.014" />
        </geometry>
      <material name="charcoal_steel">
        <color rgba="0.18 0.19 0.22 1" />
        </material>
      </visual>
    <visual name="lower_drawer_left_wall">
      <origin xyz="0.232 0.169 0.0725" rpy="0 0 0" />
      <geometry>
        <box size="0.464 0.012 0.145" />
        </geometry>
      <material name="charcoal_steel">
        <color rgba="0.18 0.19 0.22 1" />
        </material>
      </visual>
    <visual name="lower_drawer_right_wall">
      <origin xyz="0.232 -0.169 0.0725" rpy="0 0 0" />
      <geometry>
        <box size="0.464 0.012 0.145" />
        </geometry>
      <material name="charcoal_steel">
        <color rgba="0.18 0.19 0.22 1" />
        </material>
      </visual>
    <visual name="lower_drawer_back_wall">
      <origin xyz="0.007 0 0.0725" rpy="0 0 0" />
      <geometry>
        <box size="0.014 0.35 0.145" />
        </geometry>
      <material name="charcoal_steel">
        <color rgba="0.18 0.19 0.22 1" />
        </material>
      </visual>
    <visual name="lower_drawer_face">
      <origin xyz="0.476 0 0.105" rpy="0 0 0" />
      <geometry>
        <box size="0.024 0.372 0.21" />
        </geometry>
      <material name="powder_coat_red">
        <color rgba="0.72 0.1 0.08 1" />
        </material>
      </visual>
    <visual name="lower_drawer_liner">
      <origin xyz="0.242 0 0.0155" rpy="0 0 0" />
      <geometry>
        <box size="0.434 0.314 0.003" />
        </geometry>
      <material name="matte_black">
        <color rgba="0.16 0.16 0.17 1" />
        </material>
      </visual>
    <visual name="lower_drawer_handle_left_post">
      <origin xyz="0.489 0.09 0.105" rpy="0 0 0" />
      <geometry>
        <box size="0.016 0.014 0.024" />
        </geometry>
      <material name="brushed_steel">
        <color rgba="0.72 0.74 0.76 1" />
        </material>
      </visual>
    <visual name="lower_drawer_handle_right_post">
      <origin xyz="0.489 -0.09 0.105" rpy="0 0 0" />
      <geometry>
        <box size="0.016 0.014 0.024" />
        </geometry>
      <material name="brushed_steel">
        <color rgba="0.72 0.74 0.76 1" />
        </material>
      </visual>
    <visual name="lower_drawer_handle_grip">
      <origin xyz="0.504 0 0.105" rpy="-1.5708 0 0" />
      <geometry>
        <cylinder radius="0.008" length="0.19" />
        </geometry>
      <material name="brushed_steel">
        <color rgba="0.72 0.74 0.76 1" />
        </material>
      </visual>
    <visual name="lower_drawer_label_frame">
      <origin xyz="0.487 0 0.1596" rpy="0 0 0" />
      <geometry>
        <box size="0.004 0.11 0.03" />
        </geometry>
      <material name="brushed_steel">
        <color rgba="0.72 0.74 0.76 1" />
        </material>
      </visual>
    <collision name="lower_drawer__lower_drawer_floor">
      <origin xyz="0.232 0 0.007" rpy="0 0 0" />
      <geometry>
        <box size="0.464 0.332 0.014" />
        </geometry>
      </collision>
    <collision name="lower_drawer__lower_drawer_left_wall">
      <origin xyz="0.232 0.169 0.0725" rpy="0 0 0" />
      <geometry>
        <box size="0.464 0.012 0.145" />
        </geometry>
      </collision>
    <collision name="lower_drawer__lower_drawer_right_wall">
      <origin xyz="0.232 -0.169 0.0725" rpy="0 0 0" />
      <geometry>
        <box size="0.464 0.012 0.145" />
        </geometry>
      </collision>
    <collision name="lower_drawer__lower_drawer_back_wall">
      <origin xyz="0.007 0 0.0725" rpy="0 0 0" />
      <geometry>
        <box size="0.014 0.35 0.145" />
        </geometry>
      </collision>
    <collision name="lower_drawer__lower_drawer_face">
      <origin xyz="0.476 0 0.105" rpy="0 0 0" />
      <geometry>
        <box size="0.024 0.372 0.21" />
        </geometry>
      </collision>
    <collision name="lower_drawer__lower_drawer_liner">
      <origin xyz="0.242 0 0.0155" rpy="0 0 0" />
      <geometry>
        <box size="0.434 0.314 0.003" />
        </geometry>
      </collision>
    <collision name="lower_drawer__lower_drawer_handle_left_post">
      <origin xyz="0.489 0.09 0.105" rpy="0 0 0" />
      <geometry>
        <box size="0.016 0.014 0.024" />
        </geometry>
      </collision>
    <collision name="lower_drawer__lower_drawer_handle_right_post">
      <origin xyz="0.489 -0.09 0.105" rpy="0 0 0" />
      <geometry>
        <box size="0.016 0.014 0.024" />
        </geometry>
      </collision>
    <collision name="lower_drawer__lower_drawer_handle_grip">
      <origin xyz="0.504 0 0.105" rpy="-1.5708 0 0" />
      <geometry>
        <cylinder radius="0.008" length="0.19" />
        </geometry>
      </collision>
    <collision name="lower_drawer__lower_drawer_label_frame">
      <origin xyz="0.487 0 0.1596" rpy="0 0 0" />
      <geometry>
        <box size="0.004 0.11 0.03" />
        </geometry>
      </collision>
    </link>
  <link name="front_left_caster_fork">
    <inertial>
      <origin xyz="0 0 -0.055" rpy="0 0 0" />
      <mass value="0.8" />
      <inertia ixx="0.00104667" ixy="0" ixz="0" iyy="0.000973333" iyz="0" izz="0.000406667" />
      </inertial>
    <visual name="front_left_caster_fork_stem">
      <origin xyz="0 0 -0.025" rpy="0 0 0" />
      <geometry>
        <cylinder radius="0.007" length="0.05" />
        </geometry>
      <material name="brushed_steel">
        <color rgba="0.72 0.74 0.76 1" />
        </material>
      </visual>
    <visual name="front_left_caster_fork_top_plate">
      <origin xyz="0 0 -0.054" rpy="0 0 0" />
      <geometry>
        <box size="0.05 0.06 0.008" />
        </geometry>
      <material name="brushed_steel">
        <color rgba="0.72 0.74 0.76 1" />
        </material>
      </visual>
    <visual name="front_left_caster_fork_left_fork">
      <origin xyz="0 0.019 -0.084" rpy="0 0 0" />
      <geometry>
        <box size="0.045 0.006 0.052" />
        </geometry>
      <material name="brushed_steel">
        <color rgba="0.72 0.74 0.76 1" />
        </material>
      </visual>
    <visual name="front_left_caster_fork_right_fork">
      <origin xyz="0 -0.019 -0.084" rpy="0 0 0" />
      <geometry>
        <box size="0.045 0.006 0.052" />
        </geometry>
      <material name="brushed_steel">
        <color rgba="0.72 0.74 0.76 1" />
        </material>
      </visual>
    <visual name="front_left_caster_fork_left_axle_boss">
      <origin xyz="0 0.0125 -0.11" rpy="0 0 0" />
      <geometry>
        <box size="0.014 0.007 0.014" />
        </geometry>
      <material name="brushed_steel">
        <color rgba="0.72 0.74 0.76 1" />
        </material>
      </visual>
    <visual name="front_left_caster_fork_right_axle_boss">
      <origin xyz="0 -0.0125 -0.11" rpy="0 0 0" />
      <geometry>
        <box size="0.014 0.007 0.014" />
        </geometry>
      <material name="brushed_steel">
        <color rgba="0.72 0.74 0.76 1" />
        </material>
      </visual>
    <visual name="front_left_caster_fork_front_bridge">
      <origin xyz="0.026 0 -0.05" rpy="0 0 0" />
      <geometry>
        <box size="0.022 0.032 0.008" />
        </geometry>
      <material name="brushed_steel">
        <color rgba="0.72 0.74 0.76 1" />
        </material>
      </visual>
    <visual name="front_left_caster_fork_lock_pedal">
      <origin xyz="0.029 0 -0.043" rpy="0 0 0" />
      <geometry>
        <box size="0.02 0.024 0.006" />
        </geometry>
      <material name="matte_black">
        <color rgba="0.16 0.16 0.17 1" />
        </material>
      </visual>
    <collision name="front_left_caster_fork__front_left_caster_fork_stem">
      <origin xyz="0 0 -0.025" rpy="0 0 0" />
      <geometry>
        <cylinder radius="0.007" length="0.05" />
        </geometry>
      </collision>
    <collision name="front_left_caster_fork__front_left_caster_fork_top_plate">
      <origin xyz="0 0 -0.054" rpy="0 0 0" />
      <geometry>
        <box size="0.05 0.06 0.008" />
        </geometry>
      </collision>
    <collision name="front_left_caster_fork__front_left_caster_fork_left_fork">
      <origin xyz="0 0.019 -0.084" rpy="0 0 0" />
      <geometry>
        <box size="0.045 0.006 0.052" />
        </geometry>
      </collision>
    <collision name="front_left_caster_fork__front_left_caster_fork_right_fork">
      <origin xyz="0 -0.019 -0.084" rpy="0 0 0" />
      <geometry>
        <box size="0.045 0.006 0.052" />
        </geometry>
      </collision>
    <collision name="front_left_caster_fork__front_left_caster_fork_left_axle_boss">
      <origin xyz="0 0.0125 -0.11" rpy="0 0 0" />
      <geometry>
        <box size="0.014 0.007 0.014" />
        </geometry>
      </collision>
    <collision name="front_left_caster_fork__front_left_caster_fork_right_axle_boss">
      <origin xyz="0 -0.0125 -0.11" rpy="0 0 0" />
      <geometry>
        <box size="0.014 0.007 0.014" />
        </geometry>
      </collision>
    <collision name="front_left_caster_fork__front_left_caster_fork_front_bridge">
      <origin xyz="0.026 0 -0.05" rpy="0 0 0" />
      <geometry>
        <box size="0.022 0.032 0.008" />
        </geometry>
      </collision>
    <collision name="front_left_caster_fork__front_left_caster_fork_lock_pedal">
      <origin xyz="0.029 0 -0.043" rpy="0 0 0" />
      <geometry>
        <box size="0.02 0.024 0.006" />
        </geometry>
      </collision>
    </link>
  <link name="front_left_caster_wheel">
    <inertial>
      <mass value="0.9" />
      <inertia ixx="0.0007743" ixy="0" ixz="0" iyy="0.0015" iyz="0" izz="0.0007743" />
      </inertial>
    <visual name="front_left_caster_wheel_tire">
      <origin xyz="0 0 0" rpy="-1.5708 0 0" />
      <geometry>
        <cylinder radius="0.05" length="0.018" />
        </geometry>
      <material name="rubber_black">
        <color rgba="0.1 0.1 0.11 1" />
        </material>
      </visual>
    <visual name="front_left_caster_wheel_hub">
      <origin xyz="0 0 0" rpy="-1.5708 0 0" />
      <geometry>
        <cylinder radius="0.032" length="0.014" />
        </geometry>
      <material name="charcoal_steel">
        <color rgba="0.18 0.19 0.22 1" />
        </material>
      </visual>
    <visual name="front_left_caster_wheel_outer_cap">
      <origin xyz="0 0.0075 0" rpy="-1.5708 0 0" />
      <geometry>
        <cylinder radius="0.014" length="0.003" />
        </geometry>
      <material name="charcoal_steel">
        <color rgba="0.18 0.19 0.22 1" />
        </material>
      </visual>
    <visual name="front_left_caster_wheel_inner_cap">
      <origin xyz="0 -0.0075 0" rpy="-1.5708 0 0" />
      <geometry>
        <cylinder radius="0.014" length="0.003" />
        </geometry>
      <material name="charcoal_steel">
        <color rgba="0.18 0.19 0.22 1" />
        </material>
      </visual>
    <collision name="front_left_caster_wheel__front_left_caster_wheel_tire">
      <origin xyz="0 0 0" rpy="-1.5708 0 0" />
      <geometry>
        <cylinder radius="0.05" length="0.018" />
        </geometry>
      </collision>
    <collision name="front_left_caster_wheel__front_left_caster_wheel_hub">
      <origin xyz="0 0 0" rpy="-1.5708 0 0" />
      <geometry>
        <cylinder radius="0.032" length="0.014" />
        </geometry>
      </collision>
    <collision name="front_left_caster_wheel__front_left_caster_wheel_outer_cap">
      <origin xyz="0 0.0075 0" rpy="-1.5708 0 0" />
      <geometry>
        <cylinder radius="0.014" length="0.003" />
        </geometry>
      </collision>
    <collision name="front_left_caster_wheel__front_left_caster_wheel_inner_cap">
      <origin xyz="0 -0.0075 0" rpy="-1.5708 0 0" />
      <geometry>
        <cylinder radius="0.014" length="0.003" />
        </geometry>
      </collision>
    </link>
  <link name="front_right_caster_fork">
    <inertial>
      <origin xyz="0 0 -0.055" rpy="0 0 0" />
      <mass value="0.8" />
      <inertia ixx="0.00104667" ixy="0" ixz="0" iyy="0.000973333" iyz="0" izz="0.000406667" />
      </inertial>
    <visual name="front_right_caster_fork_stem">
      <origin xyz="0 0 -0.025" rpy="0 0 0" />
      <geometry>
        <cylinder radius="0.007" length="0.05" />
        </geometry>
      <material name="brushed_steel">
        <color rgba="0.72 0.74 0.76 1" />
        </material>
      </visual>
    <visual name="front_right_caster_fork_top_plate">
      <origin xyz="0 0 -0.054" rpy="0 0 0" />
      <geometry>
        <box size="0.05 0.06 0.008" />
        </geometry>
      <material name="brushed_steel">
        <color rgba="0.72 0.74 0.76 1" />
        </material>
      </visual>
    <visual name="front_right_caster_fork_left_fork">
      <origin xyz="0 0.019 -0.084" rpy="0 0 0" />
      <geometry>
        <box size="0.045 0.006 0.052" />
        </geometry>
      <material name="brushed_steel">
        <color rgba="0.72 0.74 0.76 1" />
        </material>
      </visual>
    <visual name="front_right_caster_fork_right_fork">
      <origin xyz="0 -0.019 -0.084" rpy="0 0 0" />
      <geometry>
        <box size="0.045 0.006 0.052" />
        </geometry>
      <material name="brushed_steel">
        <color rgba="0.72 0.74 0.76 1" />
        </material>
      </visual>
    <visual name="front_right_caster_fork_left_axle_boss">
      <origin xyz="0 0.0125 -0.11" rpy="0 0 0" />
      <geometry>
        <box size="0.014 0.007 0.014" />
        </geometry>
      <material name="brushed_steel">
        <color rgba="0.72 0.74 0.76 1" />
        </material>
      </visual>
    <visual name="front_right_caster_fork_right_axle_boss">
      <origin xyz="0 -0.0125 -0.11" rpy="0 0 0" />
      <geometry>
        <box size="0.014 0.007 0.014" />
        </geometry>
      <material name="brushed_steel">
        <color rgba="0.72 0.74 0.76 1" />
        </material>
      </visual>
    <visual name="front_right_caster_fork_front_bridge">
      <origin xyz="0.026 0 -0.05" rpy="0 0 0" />
      <geometry>
        <box size="0.022 0.032 0.008" />
        </geometry>
      <material name="brushed_steel">
        <color rgba="0.72 0.74 0.76 1" />
        </material>
      </visual>
    <visual name="front_right_caster_fork_lock_pedal">
      <origin xyz="0.029 0 -0.043" rpy="0 0 0" />
      <geometry>
        <box size="0.02 0.024 0.006" />
        </geometry>
      <material name="matte_black">
        <color rgba="0.16 0.16 0.17 1" />
        </material>
      </visual>
    <collision name="front_right_caster_fork__front_right_caster_fork_stem">
      <origin xyz="0 0 -0.025" rpy="0 0 0" />
      <geometry>
        <cylinder radius="0.007" length="0.05" />
        </geometry>
      </collision>
    <collision name="front_right_caster_fork__front_right_caster_fork_top_plate">
      <origin xyz="0 0 -0.054" rpy="0 0 0" />
      <geometry>
        <box size="0.05 0.06 0.008" />
        </geometry>
      </collision>
    <collision name="front_right_caster_fork__front_right_caster_fork_left_fork">
      <origin xyz="0 0.019 -0.084" rpy="0 0 0" />
      <geometry>
        <box size="0.045 0.006 0.052" />
        </geometry>
      </collision>
    <collision name="front_right_caster_fork__front_right_caster_fork_right_fork">
      <origin xyz="0 -0.019 -0.084" rpy="0 0 0" />
      <geometry>
        <box size="0.045 0.006 0.052" />
        </geometry>
      </collision>
    <collision name="front_right_caster_fork__front_right_caster_fork_left_axle_boss">
      <origin xyz="0 0.0125 -0.11" rpy="0 0 0" />
      <geometry>
        <box size="0.014 0.007 0.014" />
        </geometry>
      </collision>
    <collision name="front_right_caster_fork__front_right_caster_fork_right_axle_boss">
      <origin xyz="0 -0.0125 -0.11" rpy="0 0 0" />
      <geometry>
        <box size="0.014 0.007 0.014" />
        </geometry>
      </collision>
    <collision name="front_right_caster_fork__front_right_caster_fork_front_bridge">
      <origin xyz="0.026 0 -0.05" rpy="0 0 0" />
      <geometry>
        <box size="0.022 0.032 0.008" />
        </geometry>
      </collision>
    <collision name="front_right_caster_fork__front_right_caster_fork_lock_pedal">
      <origin xyz="0.029 0 -0.043" rpy="0 0 0" />
      <geometry>
        <box size="0.02 0.024 0.006" />
        </geometry>
      </collision>
    </link>
  <link name="front_right_caster_wheel">
    <inertial>
      <mass value="0.9" />
      <inertia ixx="0.0007743" ixy="0" ixz="0" iyy="0.0015" iyz="0" izz="0.0007743" />
      </inertial>
    <visual name="front_right_caster_wheel_tire">
      <origin xyz="0 0 0" rpy="-1.5708 0 0" />
      <geometry>
        <cylinder radius="0.05" length="0.018" />
        </geometry>
      <material name="rubber_black">
        <color rgba="0.1 0.1 0.11 1" />
        </material>
      </visual>
    <visual name="front_right_caster_wheel_hub">
      <origin xyz="0 0 0" rpy="-1.5708 0 0" />
      <geometry>
        <cylinder radius="0.032" length="0.014" />
        </geometry>
      <material name="charcoal_steel">
        <color rgba="0.18 0.19 0.22 1" />
        </material>
      </visual>
    <visual name="front_right_caster_wheel_outer_cap">
      <origin xyz="0 0.0075 0" rpy="-1.5708 0 0" />
      <geometry>
        <cylinder radius="0.014" length="0.003" />
        </geometry>
      <material name="charcoal_steel">
        <color rgba="0.18 0.19 0.22 1" />
        </material>
      </visual>
    <visual name="front_right_caster_wheel_inner_cap">
      <origin xyz="0 -0.0075 0" rpy="-1.5708 0 0" />
      <geometry>
        <cylinder radius="0.014" length="0.003" />
        </geometry>
      <material name="charcoal_steel">
        <color rgba="0.18 0.19 0.22 1" />
        </material>
      </visual>
    <collision name="front_right_caster_wheel__front_right_caster_wheel_tire">
      <origin xyz="0 0 0" rpy="-1.5708 0 0" />
      <geometry>
        <cylinder radius="0.05" length="0.018" />
        </geometry>
      </collision>
    <collision name="front_right_caster_wheel__front_right_caster_wheel_hub">
      <origin xyz="0 0 0" rpy="-1.5708 0 0" />
      <geometry>
        <cylinder radius="0.032" length="0.014" />
        </geometry>
      </collision>
    <collision name="front_right_caster_wheel__front_right_caster_wheel_outer_cap">
      <origin xyz="0 0.0075 0" rpy="-1.5708 0 0" />
      <geometry>
        <cylinder radius="0.014" length="0.003" />
        </geometry>
      </collision>
    <collision name="front_right_caster_wheel__front_right_caster_wheel_inner_cap">
      <origin xyz="0 -0.0075 0" rpy="-1.5708 0 0" />
      <geometry>
        <cylinder radius="0.014" length="0.003" />
        </geometry>
      </collision>
    </link>
  <link name="rear_left_caster_fork">
    <inertial>
      <origin xyz="0 0 -0.055" rpy="0 0 0" />
      <mass value="0.8" />
      <inertia ixx="0.00104667" ixy="0" ixz="0" iyy="0.000973333" iyz="0" izz="0.000406667" />
      </inertial>
    <visual name="rear_left_caster_fork_stem">
      <origin xyz="0 0 -0.025" rpy="0 0 0" />
      <geometry>
        <cylinder radius="0.007" length="0.05" />
        </geometry>
      <material name="brushed_steel">
        <color rgba="0.72 0.74 0.76 1" />
        </material>
      </visual>
    <visual name="rear_left_caster_fork_top_plate">
      <origin xyz="0 0 -0.054" rpy="0 0 0" />
      <geometry>
        <box size="0.05 0.06 0.008" />
        </geometry>
      <material name="brushed_steel">
        <color rgba="0.72 0.74 0.76 1" />
        </material>
      </visual>
    <visual name="rear_left_caster_fork_left_fork">
      <origin xyz="0 0.019 -0.084" rpy="0 0 0" />
      <geometry>
        <box size="0.045 0.006 0.052" />
        </geometry>
      <material name="brushed_steel">
        <color rgba="0.72 0.74 0.76 1" />
        </material>
      </visual>
    <visual name="rear_left_caster_fork_right_fork">
      <origin xyz="0 -0.019 -0.084" rpy="0 0 0" />
      <geometry>
        <box size="0.045 0.006 0.052" />
        </geometry>
      <material name="brushed_steel">
        <color rgba="0.72 0.74 0.76 1" />
        </material>
      </visual>
    <visual name="rear_left_caster_fork_left_axle_boss">
      <origin xyz="0 0.0125 -0.11" rpy="0 0 0" />
      <geometry>
        <box size="0.014 0.007 0.014" />
        </geometry>
      <material name="brushed_steel">
        <color rgba="0.72 0.74 0.76 1" />
        </material>
      </visual>
    <visual name="rear_left_caster_fork_right_axle_boss">
      <origin xyz="0 -0.0125 -0.11" rpy="0 0 0" />
      <geometry>
        <box size="0.014 0.007 0.014" />
        </geometry>
      <material name="brushed_steel">
        <color rgba="0.72 0.74 0.76 1" />
        </material>
      </visual>
    <visual name="rear_left_caster_fork_front_bridge">
      <origin xyz="0.026 0 -0.05" rpy="0 0 0" />
      <geometry>
        <box size="0.022 0.032 0.008" />
        </geometry>
      <material name="brushed_steel">
        <color rgba="0.72 0.74 0.76 1" />
        </material>
      </visual>
    <collision name="rear_left_caster_fork__rear_left_caster_fork_stem">
      <origin xyz="0 0 -0.025" rpy="0 0 0" />
      <geometry>
        <cylinder radius="0.007" length="0.05" />
        </geometry>
      </collision>
    <collision name="rear_left_caster_fork__rear_left_caster_fork_top_plate">
      <origin xyz="0 0 -0.054" rpy="0 0 0" />
      <geometry>
        <box size="0.05 0.06 0.008" />
        </geometry>
      </collision>
    <collision name="rear_left_caster_fork__rear_left_caster_fork_left_fork">
      <origin xyz="0 0.019 -0.084" rpy="0 0 0" />
      <geometry>
        <box size="0.045 0.006 0.052" />
        </geometry>
      </collision>
    <collision name="rear_left_caster_fork__rear_left_caster_fork_right_fork">
      <origin xyz="0 -0.019 -0.084" rpy="0 0 0" />
      <geometry>
        <box size="0.045 0.006 0.052" />
        </geometry>
      </collision>
    <collision name="rear_left_caster_fork__rear_left_caster_fork_left_axle_boss">
      <origin xyz="0 0.0125 -0.11" rpy="0 0 0" />
      <geometry>
        <box size="0.014 0.007 0.014" />
        </geometry>
      </collision>
    <collision name="rear_left_caster_fork__rear_left_caster_fork_right_axle_boss">
      <origin xyz="0 -0.0125 -0.11" rpy="0 0 0" />
      <geometry>
        <box size="0.014 0.007 0.014" />
        </geometry>
      </collision>
    <collision name="rear_left_caster_fork__rear_left_caster_fork_front_bridge">
      <origin xyz="0.026 0 -0.05" rpy="0 0 0" />
      <geometry>
        <box size="0.022 0.032 0.008" />
        </geometry>
      </collision>
    </link>
  <link name="rear_left_caster_wheel">
    <inertial>
      <mass value="0.9" />
      <inertia ixx="0.0007743" ixy="0" ixz="0" iyy="0.0015" iyz="0" izz="0.0007743" />
      </inertial>
    <visual name="rear_left_caster_wheel_tire">
      <origin xyz="0 0 0" rpy="-1.5708 0 0" />
      <geometry>
        <cylinder radius="0.05" length="0.018" />
        </geometry>
      <material name="rubber_black">
        <color rgba="0.1 0.1 0.11 1" />
        </material>
      </visual>
    <visual name="rear_left_caster_wheel_hub">
      <origin xyz="0 0 0" rpy="-1.5708 0 0" />
      <geometry>
        <cylinder radius="0.032" length="0.014" />
        </geometry>
      <material name="charcoal_steel">
        <color rgba="0.18 0.19 0.22 1" />
        </material>
      </visual>
    <visual name="rear_left_caster_wheel_outer_cap">
      <origin xyz="0 0.0075 0" rpy="-1.5708 0 0" />
      <geometry>
        <cylinder radius="0.014" length="0.003" />
        </geometry>
      <material name="charcoal_steel">
        <color rgba="0.18 0.19 0.22 1" />
        </material>
      </visual>
    <visual name="rear_left_caster_wheel_inner_cap">
      <origin xyz="0 -0.0075 0" rpy="-1.5708 0 0" />
      <geometry>
        <cylinder radius="0.014" length="0.003" />
        </geometry>
      <material name="charcoal_steel">
        <color rgba="0.18 0.19 0.22 1" />
        </material>
      </visual>
    <collision name="rear_left_caster_wheel__rear_left_caster_wheel_tire">
      <origin xyz="0 0 0" rpy="-1.5708 0 0" />
      <geometry>
        <cylinder radius="0.05" length="0.018" />
        </geometry>
      </collision>
    <collision name="rear_left_caster_wheel__rear_left_caster_wheel_hub">
      <origin xyz="0 0 0" rpy="-1.5708 0 0" />
      <geometry>
        <cylinder radius="0.032" length="0.014" />
        </geometry>
      </collision>
    <collision name="rear_left_caster_wheel__rear_left_caster_wheel_outer_cap">
      <origin xyz="0 0.0075 0" rpy="-1.5708 0 0" />
      <geometry>
        <cylinder radius="0.014" length="0.003" />
        </geometry>
      </collision>
    <collision name="rear_left_caster_wheel__rear_left_caster_wheel_inner_cap">
      <origin xyz="0 -0.0075 0" rpy="-1.5708 0 0" />
      <geometry>
        <cylinder radius="0.014" length="0.003" />
        </geometry>
      </collision>
    </link>
  <link name="rear_right_caster_fork">
    <inertial>
      <origin xyz="0 0 -0.055" rpy="0 0 0" />
      <mass value="0.8" />
      <inertia ixx="0.00104667" ixy="0" ixz="0" iyy="0.000973333" iyz="0" izz="0.000406667" />
      </inertial>
    <visual name="rear_right_caster_fork_stem">
      <origin xyz="0 0 -0.025" rpy="0 0 0" />
      <geometry>
        <cylinder radius="0.007" length="0.05" />
        </geometry>
      <material name="brushed_steel">
        <color rgba="0.72 0.74 0.76 1" />
        </material>
      </visual>
    <visual name="rear_right_caster_fork_top_plate">
      <origin xyz="0 0 -0.054" rpy="0 0 0" />
      <geometry>
        <box size="0.05 0.06 0.008" />
        </geometry>
      <material name="brushed_steel">
        <color rgba="0.72 0.74 0.76 1" />
        </material>
      </visual>
    <visual name="rear_right_caster_fork_left_fork">
      <origin xyz="0 0.019 -0.084" rpy="0 0 0" />
      <geometry>
        <box size="0.045 0.006 0.052" />
        </geometry>
      <material name="brushed_steel">
        <color rgba="0.72 0.74 0.76 1" />
        </material>
      </visual>
    <visual name="rear_right_caster_fork_right_fork">
      <origin xyz="0 -0.019 -0.084" rpy="0 0 0" />
      <geometry>
        <box size="0.045 0.006 0.052" />
        </geometry>
      <material name="brushed_steel">
        <color rgba="0.72 0.74 0.76 1" />
        </material>
      </visual>
    <visual name="rear_right_caster_fork_left_axle_boss">
      <origin xyz="0 0.0125 -0.11" rpy="0 0 0" />
      <geometry>
        <box size="0.014 0.007 0.014" />
        </geometry>
      <material name="brushed_steel">
        <color rgba="0.72 0.74 0.76 1" />
        </material>
      </visual>
    <visual name="rear_right_caster_fork_right_axle_boss">
      <origin xyz="0 -0.0125 -0.11" rpy="0 0 0" />
      <geometry>
        <box size="0.014 0.007 0.014" />
        </geometry>
      <material name="brushed_steel">
        <color rgba="0.72 0.74 0.76 1" />
        </material>
      </visual>
    <visual name="rear_right_caster_fork_front_bridge">
      <origin xyz="0.026 0 -0.05" rpy="0 0 0" />
      <geometry>
        <box size="0.022 0.032 0.008" />
        </geometry>
      <material name="brushed_steel">
        <color rgba="0.72 0.74 0.76 1" />
        </material>
      </visual>
    <collision name="rear_right_caster_fork__rear_right_caster_fork_stem">
      <origin xyz="0 0 -0.025" rpy="0 0 0" />
      <geometry>
        <cylinder radius="0.007" length="0.05" />
        </geometry>
      </collision>
    <collision name="rear_right_caster_fork__rear_right_caster_fork_top_plate">
      <origin xyz="0 0 -0.054" rpy="0 0 0" />
      <geometry>
        <box size="0.05 0.06 0.008" />
        </geometry>
      </collision>
    <collision name="rear_right_caster_fork__rear_right_caster_fork_left_fork">
      <origin xyz="0 0.019 -0.084" rpy="0 0 0" />
      <geometry>
        <box size="0.045 0.006 0.052" />
        </geometry>
      </collision>
    <collision name="rear_right_caster_fork__rear_right_caster_fork_right_fork">
      <origin xyz="0 -0.019 -0.084" rpy="0 0 0" />
      <geometry>
        <box size="0.045 0.006 0.052" />
        </geometry>
      </collision>
    <collision name="rear_right_caster_fork__rear_right_caster_fork_left_axle_boss">
      <origin xyz="0 0.0125 -0.11" rpy="0 0 0" />
      <geometry>
        <box size="0.014 0.007 0.014" />
        </geometry>
      </collision>
    <collision name="rear_right_caster_fork__rear_right_caster_fork_right_axle_boss">
      <origin xyz="0 -0.0125 -0.11" rpy="0 0 0" />
      <geometry>
        <box size="0.014 0.007 0.014" />
        </geometry>
      </collision>
    <collision name="rear_right_caster_fork__rear_right_caster_fork_front_bridge">
      <origin xyz="0.026 0 -0.05" rpy="0 0 0" />
      <geometry>
        <box size="0.022 0.032 0.008" />
        </geometry>
      </collision>
    </link>
  <link name="rear_right_caster_wheel">
    <inertial>
      <mass value="0.9" />
      <inertia ixx="0.0007743" ixy="0" ixz="0" iyy="0.0015" iyz="0" izz="0.0007743" />
      </inertial>
    <visual name="rear_right_caster_wheel_tire">
      <origin xyz="0 0 0" rpy="-1.5708 0 0" />
      <geometry>
        <cylinder radius="0.05" length="0.018" />
        </geometry>
      <material name="rubber_black">
        <color rgba="0.1 0.1 0.11 1" />
        </material>
      </visual>
    <visual name="rear_right_caster_wheel_hub">
      <origin xyz="0 0 0" rpy="-1.5708 0 0" />
      <geometry>
        <cylinder radius="0.032" length="0.014" />
        </geometry>
      <material name="charcoal_steel">
        <color rgba="0.18 0.19 0.22 1" />
        </material>
      </visual>
    <visual name="rear_right_caster_wheel_outer_cap">
      <origin xyz="0 0.0075 0" rpy="-1.5708 0 0" />
      <geometry>
        <cylinder radius="0.014" length="0.003" />
        </geometry>
      <material name="charcoal_steel">
        <color rgba="0.18 0.19 0.22 1" />
        </material>
      </visual>
    <visual name="rear_right_caster_wheel_inner_cap">
      <origin xyz="0 -0.0075 0" rpy="-1.5708 0 0" />
      <geometry>
        <cylinder radius="0.014" length="0.003" />
        </geometry>
      <material name="charcoal_steel">
        <color rgba="0.18 0.19 0.22 1" />
        </material>
      </visual>
    <collision name="rear_right_caster_wheel__rear_right_caster_wheel_tire">
      <origin xyz="0 0 0" rpy="-1.5708 0 0" />
      <geometry>
        <cylinder radius="0.05" length="0.018" />
        </geometry>
      </collision>
    <collision name="rear_right_caster_wheel__rear_right_caster_wheel_hub">
      <origin xyz="0 0 0" rpy="-1.5708 0 0" />
      <geometry>
        <cylinder radius="0.032" length="0.014" />
        </geometry>
      </collision>
    <collision name="rear_right_caster_wheel__rear_right_caster_wheel_outer_cap">
      <origin xyz="0 0.0075 0" rpy="-1.5708 0 0" />
      <geometry>
        <cylinder radius="0.014" length="0.003" />
        </geometry>
      </collision>
    <collision name="rear_right_caster_wheel__rear_right_caster_wheel_inner_cap">
      <origin xyz="0 -0.0075 0" rpy="-1.5708 0 0" />
      <geometry>
        <cylinder radius="0.014" length="0.003" />
        </geometry>
      </collision>
    </link>
  <joint name="upper_drawer_slide" type="prismatic">
    <origin xyz="-0.216 0 0.51" rpy="0 0 0" />
    <parent link="body" />
    <child link="upper_drawer" />
    <axis xyz="1 0 0" />
    <limit effort="180" velocity="0.4" lower="0" upper="0.23" />
    </joint>
  <joint name="lower_drawer_slide" type="prismatic">
    <origin xyz="-0.216 0 0.222" rpy="0 0 0" />
    <parent link="body" />
    <child link="lower_drawer" />
    <axis xyz="1 0 0" />
    <limit effort="180" velocity="0.4" lower="0" upper="0.23" />
    </joint>
  <joint name="front_left_caster_swivel" type="continuous">
    <origin xyz="0.17 0.16 0.16" rpy="0 0 0" />
    <parent link="body" />
    <child link="front_left_caster_fork" />
    <axis xyz="0 0 1" />
    <limit effort="45" velocity="8" />
    </joint>
  <joint name="front_left_wheel_roll" type="continuous">
    <origin xyz="0 0 -0.11" rpy="0 0 0" />
    <parent link="front_left_caster_fork" />
    <child link="front_left_caster_wheel" />
    <axis xyz="0 1 0" />
    <limit effort="35" velocity="18" />
    </joint>
  <joint name="front_right_caster_swivel" type="continuous">
    <origin xyz="0.17 -0.16 0.16" rpy="0 0 0" />
    <parent link="body" />
    <child link="front_right_caster_fork" />
    <axis xyz="0 0 1" />
    <limit effort="45" velocity="8" />
    </joint>
  <joint name="front_right_wheel_roll" type="continuous">
    <origin xyz="0 0 -0.11" rpy="0 0 0" />
    <parent link="front_right_caster_fork" />
    <child link="front_right_caster_wheel" />
    <axis xyz="0 1 0" />
    <limit effort="35" velocity="18" />
    </joint>
  <joint name="rear_left_caster_swivel" type="continuous">
    <origin xyz="-0.21 0.16 0.16" rpy="0 0 0" />
    <parent link="body" />
    <child link="rear_left_caster_fork" />
    <axis xyz="0 0 1" />
    <limit effort="45" velocity="8" />
    </joint>
  <joint name="rear_left_wheel_roll" type="continuous">
    <origin xyz="0 0 -0.11" rpy="0 0 0" />
    <parent link="rear_left_caster_fork" />
    <child link="rear_left_caster_wheel" />
    <axis xyz="0 1 0" />
    <limit effort="35" velocity="18" />
    </joint>
  <joint name="rear_right_caster_swivel" type="continuous">
    <origin xyz="-0.21 -0.16 0.16" rpy="0 0 0" />
    <parent link="body" />
    <child link="rear_right_caster_fork" />
    <axis xyz="0 0 1" />
    <limit effort="45" velocity="8" />
    </joint>
  <joint name="rear_right_wheel_roll" type="continuous">
    <origin xyz="0 0 -0.11" rpy="0 0 0" />
    <parent link="rear_right_caster_fork" />
    <child link="rear_right_caster_wheel" />
    <axis xyz="0 1 0" />
    <limit effort="35" velocity="18" />
    </joint>
  </robot>
