<robot name="single_handle_faucet">
  <material name="polished_chrome">
    <color rgba="0.83 0.85 0.88 1" />
    </material>
  <material name="brushed_nickel">
    <color rgba="0.72 0.74 0.77 1" />
    </material>
  <material name="dark_rubber">
    <color rgba="0.08 0.08 0.09 1" />
    </material>
  <material name="dark_plastic">
    <color rgba="0.16 0.17 0.18 1" />
    </material>
  <link name="base_flange">
    <inertial>
      <origin xyz="0 0 0.007" rpy="0 0 0" />
      <mass value="0.85" />
      <inertia ixx="0.000198333" ixy="0" ixz="0" iyy="0.000198333" iyz="0" izz="0.0003825" />
      </inertial>
    <visual name="deck_gasket">
      <origin xyz="0 0 0.001" rpy="0 0 0" />
      <geometry>
        <cylinder radius="0.0315" length="0.002" />
        </geometry>
      <material name="dark_rubber">
        <color rgba="0.08 0.08 0.09 1" />
        </material>
      </visual>
    <visual name="flange_cap">
      <origin xyz="0 0 0.007" rpy="0 0 0" />
      <geometry>
        <cylinder radius="0.03" length="0.01" />
        </geometry>
      <material name="brushed_nickel">
        <color rgba="0.72 0.74 0.77 1" />
        </material>
      </visual>
    <visual name="inner_trim_ring">
      <origin xyz="0 0 0.011" rpy="0 0 0" />
      <geometry>
        <cylinder radius="0.022" length="0.002" />
        </geometry>
      <material name="polished_chrome">
        <color rgba="0.83 0.85 0.88 1" />
        </material>
      </visual>
    </link>
  <link name="faucet_body">
    <inertial>
      <origin xyz="0 0 0.05" rpy="0 0 0" />
      <mass value="1.65" />
      <inertia ixx="0.00165385" ixy="0" ixz="0" iyy="0.00165385" iyz="0" izz="0.0005577" />
      </inertial>
    <visual name="body_shell">
      <geometry>
        <mesh filename="assets/meshes/faucet_body_shell.obj" />
        </geometry>
      <material name="polished_chrome">
        <color rgba="0.83 0.85 0.88 1" />
        </material>
      </visual>
    <visual name="lower_body_band">
      <origin xyz="0 0 0.009" rpy="0 0 0" />
      <geometry>
        <cylinder radius="0.0245" length="0.004" />
        </geometry>
      <material name="brushed_nickel">
        <color rgba="0.72 0.74 0.77 1" />
        </material>
      </visual>
    <visual name="neck_cap">
      <origin xyz="0 0 0.094" rpy="0 0 0" />
      <geometry>
        <cylinder radius="0.0145" length="0.006" />
        </geometry>
      <material name="polished_chrome">
        <color rgba="0.83 0.85 0.88 1" />
        </material>
      </visual>
    <visual name="arched_spout">
      <geometry>
        <mesh filename="assets/meshes/faucet_spout.obj" />
        </geometry>
      <material name="polished_chrome">
        <color rgba="0.83 0.85 0.88 1" />
        </material>
      </visual>
    <visual name="spout_nozzle_ring">
      <origin xyz="0.149 0 0.078" rpy="0 1.5708 0" />
      <geometry>
        <cylinder radius="0.0112" length="0.01" />
        </geometry>
      <material name="polished_chrome">
        <color rgba="0.83 0.85 0.88 1" />
        </material>
      </visual>
    <visual name="aerator_insert">
      <origin xyz="0.154 0 0.078" rpy="0 1.5708 0" />
      <geometry>
        <cylinder radius="0.0062" length="0.004" />
        </geometry>
      <material name="dark_plastic">
        <color rgba="0.16 0.17 0.18 1" />
        </material>
      </visual>
    <visual name="cartridge_housing">
      <origin xyz="0 0.03 0.056" rpy="1.5708 0 0" />
      <geometry>
        <cylinder radius="0.011" length="0.038" />
        </geometry>
      <material name="polished_chrome">
        <color rgba="0.83 0.85 0.88 1" />
        </material>
      </visual>
    <visual name="handle_trim_cap">
      <origin xyz="0 0.047 0.056" rpy="1.5708 0 0" />
      <geometry>
        <cylinder radius="0.013" length="0.004" />
        </geometry>
      <material name="brushed_nickel">
        <color rgba="0.72 0.74 0.77 1" />
        </material>
      </visual>
    </link>
  <link name="control_handle">
    <inertial>
      <origin xyz="0.004 0.048 0.007" rpy="0 0 0" />
      <mass value="0.24" />
      <inertia ixx="0.0001908" ixy="0" ixz="0" iyy="1.8e-05" iyz="0" izz="0.00019584" />
      </inertial>
    <visual name="handle_hub">
      <origin xyz="0 0 0" rpy="1.5708 0 0" />
      <geometry>
        <cylinder radius="0.0125" length="0.012" />
        </geometry>
      <material name="polished_chrome">
        <color rgba="0.83 0.85 0.88 1" />
        </material>
      </visual>
    <visual name="handle_lever">
      <geometry>
        <mesh filename="assets/meshes/faucet_handle_lever.obj" />
        </geometry>
      <material name="polished_chrome">
        <color rgba="0.83 0.85 0.88 1" />
        </material>
      </visual>
    <visual name="handle_tip">
      <origin xyz="0.008 0.086 0.007" rpy="1.5708 0 0" />
      <geometry>
        <cylinder radius="0.006" length="0.008" />
        </geometry>
      <material name="polished_chrome">
        <color rgba="0.83 0.85 0.88 1" />
        </material>
      </visual>
    </link>
  <joint name="flange_to_body" type="fixed">
    <origin xyz="0 0 0.012" rpy="0 0 0" />
    <parent link="base_flange" />
    <child link="faucet_body" />
    </joint>
  <joint name="side_handle" type="revolute">
    <origin xyz="0 0.047 0.056" rpy="0 0 0" />
    <parent link="faucet_body" />
    <child link="control_handle" />
    <axis xyz="1 0 0" />
    <limit effort="6" velocity="2.5" lower="0" upper="0.907571" />
    </joint>
  </robot>
