<robot name="bicycle_crankset">
  <material name="frame_black">
    <color rgba="0.18 0.19 0.2 1" />
    </material>
  <material name="alloy">
    <color rgba="0.69 0.71 0.74 1" />
    </material>
  <material name="machined">
    <color rgba="0.59 0.61 0.64 1" />
    </material>
  <material name="anodized_black">
    <color rgba="0.11 0.11 0.12 1" />
    </material>
  <material name="steel">
    <color rgba="0.53 0.56 0.6 1" />
    </material>
  <material name="rubber">
    <color rgba="0.08 0.08 0.09 1" />
    </material>
  <link name="bb_shell">
    <inertial>
      <origin xyz="0 0 0.04" rpy="0 0 0" />
      <mass value="1.35" />
      <inertia ixx="0.004005" ixy="0" ixz="0" iyy="0.00738" iyz="0" izz="0.005625" />
      </inertial>
    <visual name="shell">
      <origin xyz="0 0 0" rpy="1.5708 0 0" />
      <geometry>
        <cylinder radius="0.021" length="0.073" />
        </geometry>
      <material name="frame_black">
        <color rgba="0.18 0.19 0.2 1" />
        </material>
      </visual>
    <visual name="drive_cup">
      <origin xyz="0 -0.0415 0" rpy="1.5708 0 0" />
      <geometry>
        <cylinder radius="0.0245" length="0.01" />
        </geometry>
      <material name="steel">
        <color rgba="0.53 0.56 0.6 1" />
        </material>
      </visual>
    <visual name="non_drive_cup">
      <origin xyz="0 0.0415 0" rpy="1.5708 0 0" />
      <geometry>
        <cylinder radius="0.0245" length="0.01" />
        </geometry>
      <material name="steel">
        <color rgba="0.53 0.56 0.6 1" />
        </material>
      </visual>
    <visual name="seat_tube_stub">
      <origin xyz="-0.015 0 0.072" rpy="0 -0.2 0" />
      <geometry>
        <cylinder radius="0.017" length="0.11" />
        </geometry>
      <material name="frame_black">
        <color rgba="0.18 0.19 0.2 1" />
        </material>
      </visual>
    <visual name="down_tube_stub">
      <origin xyz="0.061 0 0.046" rpy="0 0.89 0" />
      <geometry>
        <cylinder radius="0.019" length="0.12" />
        </geometry>
      <material name="frame_black">
        <color rgba="0.18 0.19 0.2 1" />
        </material>
      </visual>
    <visual name="left_chainstay_stub">
      <origin xyz="-0.054 0.028 0.002" rpy="0 -1.31 0" />
      <geometry>
        <cylinder radius="0.013" length="0.1" />
        </geometry>
      <material name="frame_black">
        <color rgba="0.18 0.19 0.2 1" />
        </material>
      </visual>
    <visual name="right_chainstay_stub">
      <origin xyz="-0.054 -0.028 0.002" rpy="0 -1.31 0" />
      <geometry>
        <cylinder radius="0.013" length="0.1" />
        </geometry>
      <material name="frame_black">
        <color rgba="0.18 0.19 0.2 1" />
        </material>
      </visual>
    <collision name="bb_shell__shell">
      <origin xyz="0 0 0" rpy="1.5708 0 0" />
      <geometry>
        <cylinder radius="0.021" length="0.073" />
        </geometry>
      </collision>
    <collision name="bb_shell__drive_cup">
      <origin xyz="0 -0.0415 0" rpy="1.5708 0 0" />
      <geometry>
        <cylinder radius="0.0245" length="0.01" />
        </geometry>
      </collision>
    <collision name="bb_shell__non_drive_cup">
      <origin xyz="0 0.0415 0" rpy="1.5708 0 0" />
      <geometry>
        <cylinder radius="0.0245" length="0.01" />
        </geometry>
      </collision>
    <collision name="bb_shell__seat_tube_stub">
      <origin xyz="-0.015 0 0.072" rpy="0 -0.2 0" />
      <geometry>
        <cylinder radius="0.017" length="0.11" />
        </geometry>
      </collision>
    <collision name="bb_shell__down_tube_stub">
      <origin xyz="0.061 0 0.046" rpy="0 0.89 0" />
      <geometry>
        <cylinder radius="0.019" length="0.12" />
        </geometry>
      </collision>
    <collision name="bb_shell__left_chainstay_stub">
      <origin xyz="-0.054 0.028 0.002" rpy="0 -1.31 0" />
      <geometry>
        <cylinder radius="0.013" length="0.1" />
        </geometry>
      </collision>
    <collision name="bb_shell__right_chainstay_stub">
      <origin xyz="-0.054 -0.028 0.002" rpy="0 -1.31 0" />
      <geometry>
        <cylinder radius="0.013" length="0.1" />
        </geometry>
      </collision>
    </link>
  <link name="crankset">
    <inertial>
      <origin xyz="0 -0.01 0" rpy="0 0 0" />
      <mass value="2.35" />
      <inertia ixx="0.0195833" ixy="0" ixz="0" iyy="0.0245183" iyz="0" izz="0.017625" />
      </inertial>
    <visual name="spindle">
      <origin xyz="0 0 0" rpy="1.5708 0 0" />
      <geometry>
        <cylinder radius="0.0115" length="0.152" />
        </geometry>
      <material name="steel">
        <color rgba="0.53 0.56 0.6 1" />
        </material>
      </visual>
    <visual name="drive_spider_mount">
      <origin xyz="0 -0.041 0" rpy="1.5708 0 0" />
      <geometry>
        <cylinder radius="0.032" length="0.022" />
        </geometry>
      <material name="anodized_black">
        <color rgba="0.11 0.11 0.12 1" />
        </material>
      </visual>
    <visual name="non_drive_interface">
      <origin xyz="0 0.044 0" rpy="1.5708 0 0" />
      <geometry>
        <cylinder radius="0.028" length="0.018" />
        </geometry>
      <material name="anodized_black">
        <color rgba="0.11 0.11 0.12 1" />
        </material>
      </visual>
    <visual name="right_crank_arm">
      <origin xyz="0 -0.052 0" rpy="0 2.66 0" />
      <geometry>
        <mesh filename="meshes/crank_arm.obj" />
        </geometry>
      <material name="alloy">
        <color rgba="0.69 0.71 0.74 1" />
        </material>
      </visual>
    <visual name="left_crank_arm">
      <origin xyz="0 0.052 0" rpy="0 5.80159 0" />
      <geometry>
        <mesh filename="meshes/crank_arm.obj" />
        </geometry>
      <material name="alloy">
        <color rgba="0.69 0.71 0.74 1" />
        </material>
      </visual>
    <visual name="spider">
      <origin xyz="0 -0.033 0" rpy="1.5708 0 0" />
      <geometry>
        <mesh filename="meshes/spider.obj" />
        </geometry>
      <material name="machined">
        <color rgba="0.59 0.61 0.64 1" />
        </material>
      </visual>
    <visual name="chainring">
      <origin xyz="0 -0.039 0" rpy="1.5708 0 0" />
      <geometry>
        <mesh filename="meshes/chainring.obj" />
        </geometry>
      <material name="anodized_black">
        <color rgba="0.11 0.11 0.12 1" />
        </material>
      </visual>
    <visual name="chainring_bolt_1">
      <origin xyz="0.055 -0.036 0" rpy="1.5708 0 0" />
      <geometry>
        <cylinder radius="0.0044" length="0.014" />
        </geometry>
      <material name="steel">
        <color rgba="0.53 0.56 0.6 1" />
        </material>
      </visual>
    <visual name="chainring_bolt_2">
      <origin xyz="0.0169959 -0.036 0.0523081" rpy="1.5708 0 0" />
      <geometry>
        <cylinder radius="0.0044" length="0.014" />
        </geometry>
      <material name="steel">
        <color rgba="0.53 0.56 0.6 1" />
        </material>
      </visual>
    <visual name="chainring_bolt_3">
      <origin xyz="-0.0444959 -0.036 0.0323282" rpy="1.5708 0 0" />
      <geometry>
        <cylinder radius="0.0044" length="0.014" />
        </geometry>
      <material name="steel">
        <color rgba="0.53 0.56 0.6 1" />
        </material>
      </visual>
    <visual name="chainring_bolt_4">
      <origin xyz="-0.0444959 -0.036 -0.0323282" rpy="1.5708 0 0" />
      <geometry>
        <cylinder radius="0.0044" length="0.014" />
        </geometry>
      <material name="steel">
        <color rgba="0.53 0.56 0.6 1" />
        </material>
      </visual>
    <visual name="chainring_bolt_5">
      <origin xyz="0.0169959 -0.036 -0.0523081" rpy="1.5708 0 0" />
      <geometry>
        <cylinder radius="0.0044" length="0.014" />
        </geometry>
      <material name="steel">
        <color rgba="0.53 0.56 0.6 1" />
        </material>
      </visual>
    <visual name="left_preload_cap">
      <origin xyz="0 0.057 0" rpy="1.5708 0 0" />
      <geometry>
        <cylinder radius="0.017" length="0.01" />
        </geometry>
      <material name="machined">
        <color rgba="0.59 0.61 0.64 1" />
        </material>
      </visual>
    <visual name="right_bolt_cap">
      <origin xyz="0 -0.058 0" rpy="1.5708 0 0" />
      <geometry>
        <cylinder radius="0.018" length="0.012" />
        </geometry>
      <material name="machined">
        <color rgba="0.59 0.61 0.64 1" />
        </material>
      </visual>
    <collision name="crankset__spindle">
      <origin xyz="0 0 0" rpy="1.5708 0 0" />
      <geometry>
        <cylinder radius="0.0115" length="0.152" />
        </geometry>
      </collision>
    <collision name="crankset__drive_spider_mount">
      <origin xyz="0 -0.041 0" rpy="1.5708 0 0" />
      <geometry>
        <cylinder radius="0.032" length="0.022" />
        </geometry>
      </collision>
    <collision name="crankset__non_drive_interface">
      <origin xyz="0 0.044 0" rpy="1.5708 0 0" />
      <geometry>
        <cylinder radius="0.028" length="0.018" />
        </geometry>
      </collision>
    <collision name="crankset__right_crank_arm__hull_001">
      <origin xyz="0 -0.052 0" rpy="0 2.66 0" />
      <geometry>
        <mesh filename="meshes/collision/cache/1a59e6e486a5874d122d273b__hull_001.obj" />
        </geometry>
      </collision>
    <collision name="crankset__left_crank_arm__hull_001">
      <origin xyz="0 0.052 0" rpy="0 5.80159 0" />
      <geometry>
        <mesh filename="meshes/collision/cache/1a59e6e486a5874d122d273b__hull_001.obj" />
        </geometry>
      </collision>
    <collision name="crankset__spider__hull_001">
      <origin xyz="0 -0.033 0" rpy="1.5708 0 0" />
      <geometry>
        <mesh filename="meshes/collision/cache/e3663cf4116e541193df75f2__hull_001.obj" />
        </geometry>
      </collision>
    <collision name="crankset__spider__hull_002">
      <origin xyz="0 -0.033 0" rpy="1.5708 0 0" />
      <geometry>
        <mesh filename="meshes/collision/cache/e3663cf4116e541193df75f2__hull_002.obj" />
        </geometry>
      </collision>
    <collision name="crankset__spider__hull_003">
      <origin xyz="0 -0.033 0" rpy="1.5708 0 0" />
      <geometry>
        <mesh filename="meshes/collision/cache/e3663cf4116e541193df75f2__hull_003.obj" />
        </geometry>
      </collision>
    <collision name="crankset__spider__hull_004">
      <origin xyz="0 -0.033 0" rpy="1.5708 0 0" />
      <geometry>
        <mesh filename="meshes/collision/cache/e3663cf4116e541193df75f2__hull_004.obj" />
        </geometry>
      </collision>
    <collision name="crankset__spider__hull_005">
      <origin xyz="0 -0.033 0" rpy="1.5708 0 0" />
      <geometry>
        <mesh filename="meshes/collision/cache/e3663cf4116e541193df75f2__hull_005.obj" />
        </geometry>
      </collision>
    <collision name="crankset__spider__hull_006">
      <origin xyz="0 -0.033 0" rpy="1.5708 0 0" />
      <geometry>
        <mesh filename="meshes/collision/cache/e3663cf4116e541193df75f2__hull_006.obj" />
        </geometry>
      </collision>
    <collision name="crankset__spider__hull_007">
      <origin xyz="0 -0.033 0" rpy="1.5708 0 0" />
      <geometry>
        <mesh filename="meshes/collision/cache/e3663cf4116e541193df75f2__hull_007.obj" />
        </geometry>
      </collision>
    <collision name="crankset__spider__hull_008">
      <origin xyz="0 -0.033 0" rpy="1.5708 0 0" />
      <geometry>
        <mesh filename="meshes/collision/cache/e3663cf4116e541193df75f2__hull_008.obj" />
        </geometry>
      </collision>
    <collision name="crankset__spider__hull_009">
      <origin xyz="0 -0.033 0" rpy="1.5708 0 0" />
      <geometry>
        <mesh filename="meshes/collision/cache/e3663cf4116e541193df75f2__hull_009.obj" />
        </geometry>
      </collision>
    <collision name="crankset__chainring__hull_001">
      <origin xyz="0 -0.039 0" rpy="1.5708 0 0" />
      <geometry>
        <mesh filename="meshes/collision/cache/7db60f8fc3ce10b4165b08c8__hull_001.obj" />
        </geometry>
      </collision>
    <collision name="crankset__chainring__hull_002">
      <origin xyz="0 -0.039 0" rpy="1.5708 0 0" />
      <geometry>
        <mesh filename="meshes/collision/cache/7db60f8fc3ce10b4165b08c8__hull_002.obj" />
        </geometry>
      </collision>
    <collision name="crankset__chainring__hull_003">
      <origin xyz="0 -0.039 0" rpy="1.5708 0 0" />
      <geometry>
        <mesh filename="meshes/collision/cache/7db60f8fc3ce10b4165b08c8__hull_003.obj" />
        </geometry>
      </collision>
    <collision name="crankset__chainring__hull_004">
      <origin xyz="0 -0.039 0" rpy="1.5708 0 0" />
      <geometry>
        <mesh filename="meshes/collision/cache/7db60f8fc3ce10b4165b08c8__hull_004.obj" />
        </geometry>
      </collision>
    <collision name="crankset__chainring__hull_005">
      <origin xyz="0 -0.039 0" rpy="1.5708 0 0" />
      <geometry>
        <mesh filename="meshes/collision/cache/7db60f8fc3ce10b4165b08c8__hull_005.obj" />
        </geometry>
      </collision>
    <collision name="crankset__chainring__hull_006">
      <origin xyz="0 -0.039 0" rpy="1.5708 0 0" />
      <geometry>
        <mesh filename="meshes/collision/cache/7db60f8fc3ce10b4165b08c8__hull_006.obj" />
        </geometry>
      </collision>
    <collision name="crankset__chainring__hull_007">
      <origin xyz="0 -0.039 0" rpy="1.5708 0 0" />
      <geometry>
        <mesh filename="meshes/collision/cache/7db60f8fc3ce10b4165b08c8__hull_007.obj" />
        </geometry>
      </collision>
    <collision name="crankset__chainring_bolt_1">
      <origin xyz="0.055 -0.036 0" rpy="1.5708 0 0" />
      <geometry>
        <cylinder radius="0.0044" length="0.014" />
        </geometry>
      </collision>
    <collision name="crankset__chainring_bolt_2">
      <origin xyz="0.0169959 -0.036 0.0523081" rpy="1.5708 0 0" />
      <geometry>
        <cylinder radius="0.0044" length="0.014" />
        </geometry>
      </collision>
    <collision name="crankset__chainring_bolt_3">
      <origin xyz="-0.0444959 -0.036 0.0323282" rpy="1.5708 0 0" />
      <geometry>
        <cylinder radius="0.0044" length="0.014" />
        </geometry>
      </collision>
    <collision name="crankset__chainring_bolt_4">
      <origin xyz="-0.0444959 -0.036 -0.0323282" rpy="1.5708 0 0" />
      <geometry>
        <cylinder radius="0.0044" length="0.014" />
        </geometry>
      </collision>
    <collision name="crankset__chainring_bolt_5">
      <origin xyz="0.0169959 -0.036 -0.0523081" rpy="1.5708 0 0" />
      <geometry>
        <cylinder radius="0.0044" length="0.014" />
        </geometry>
      </collision>
    <collision name="crankset__left_preload_cap">
      <origin xyz="0 0.057 0" rpy="1.5708 0 0" />
      <geometry>
        <cylinder radius="0.017" length="0.01" />
        </geometry>
      </collision>
    <collision name="crankset__right_bolt_cap">
      <origin xyz="0 -0.058 0" rpy="1.5708 0 0" />
      <geometry>
        <cylinder radius="0.018" length="0.012" />
        </geometry>
      </collision>
    </link>
  <link name="left_pedal">
    <inertial>
      <origin xyz="0 0.05 0" rpy="0 0 0" />
      <mass value="0.34" />
      <inertia ixx="0.000247208" ixy="0" ixz="0" iyy="0.000301042" iyz="0" izz="0.000512833" />
      </inertial>
    <visual name="left_pedal_body">
      <origin xyz="0 0 0" rpy="-1.5708 0 0" />
      <geometry>
        <mesh filename="meshes/pedal_body.obj" />
        </geometry>
      <material name="anodized_black">
        <color rgba="0.11 0.11 0.12 1" />
        </material>
      </visual>
    <visual name="left_spindle">
      <origin xyz="0 0.0275 0" rpy="1.5708 0 0" />
      <geometry>
        <cylinder radius="0.006" length="0.055" />
        </geometry>
      <material name="steel">
        <color rgba="0.53 0.56 0.6 1" />
        </material>
      </visual>
    <visual name="left_upper_tread">
      <origin xyz="0 0.052 0.0055" rpy="0 0 0" />
      <geometry>
        <box size="0.076 0.05 0.005" />
        </geometry>
      <material name="rubber">
        <color rgba="0.08 0.08 0.09 1" />
        </material>
      </visual>
    <visual name="left_lower_tread">
      <origin xyz="0 0.052 -0.0055" rpy="0 0 0" />
      <geometry>
        <box size="0.076 0.05 0.005" />
        </geometry>
      <material name="rubber">
        <color rgba="0.08 0.08 0.09 1" />
        </material>
      </visual>
    <visual name="left_end_cap">
      <origin xyz="0 0.084 0" rpy="1.5708 0 0" />
      <geometry>
        <cylinder radius="0.0072" length="0.012" />
        </geometry>
      <material name="steel">
        <color rgba="0.53 0.56 0.6 1" />
        </material>
      </visual>
    <collision name="left_pedal__left_pedal_body__hull_001">
      <origin xyz="0 0 0" rpy="-1.5708 0 0" />
      <geometry>
        <mesh filename="meshes/collision/cache/6547aff824bd182147c9c4f6__hull_001.obj" />
        </geometry>
      </collision>
    <collision name="left_pedal__left_spindle">
      <origin xyz="0 0.0275 0" rpy="1.5708 0 0" />
      <geometry>
        <cylinder radius="0.006" length="0.055" />
        </geometry>
      </collision>
    <collision name="left_pedal__left_upper_tread">
      <origin xyz="0 0.052 0.0055" rpy="0 0 0" />
      <geometry>
        <box size="0.076 0.05 0.005" />
        </geometry>
      </collision>
    <collision name="left_pedal__left_lower_tread">
      <origin xyz="0 0.052 -0.0055" rpy="0 0 0" />
      <geometry>
        <box size="0.076 0.05 0.005" />
        </geometry>
      </collision>
    <collision name="left_pedal__left_end_cap">
      <origin xyz="0 0.084 0" rpy="1.5708 0 0" />
      <geometry>
        <cylinder radius="0.0072" length="0.012" />
        </geometry>
      </collision>
    </link>
  <link name="right_pedal">
    <inertial>
      <origin xyz="0 -0.05 0" rpy="0 0 0" />
      <mass value="0.34" />
      <inertia ixx="0.000247208" ixy="0" ixz="0" iyy="0.000301042" iyz="0" izz="0.000512833" />
      </inertial>
    <visual name="right_pedal_body">
      <origin xyz="0 0 0" rpy="1.5708 0 0" />
      <geometry>
        <mesh filename="meshes/pedal_body.obj" />
        </geometry>
      <material name="anodized_black">
        <color rgba="0.11 0.11 0.12 1" />
        </material>
      </visual>
    <visual name="right_spindle">
      <origin xyz="0 -0.0275 0" rpy="1.5708 0 0" />
      <geometry>
        <cylinder radius="0.006" length="0.055" />
        </geometry>
      <material name="steel">
        <color rgba="0.53 0.56 0.6 1" />
        </material>
      </visual>
    <visual name="right_upper_tread">
      <origin xyz="0 -0.052 0.0055" rpy="0 0 0" />
      <geometry>
        <box size="0.076 0.05 0.005" />
        </geometry>
      <material name="rubber">
        <color rgba="0.08 0.08 0.09 1" />
        </material>
      </visual>
    <visual name="right_lower_tread">
      <origin xyz="0 -0.052 -0.0055" rpy="0 0 0" />
      <geometry>
        <box size="0.076 0.05 0.005" />
        </geometry>
      <material name="rubber">
        <color rgba="0.08 0.08 0.09 1" />
        </material>
      </visual>
    <visual name="right_end_cap">
      <origin xyz="0 -0.084 0" rpy="1.5708 0 0" />
      <geometry>
        <cylinder radius="0.0072" length="0.012" />
        </geometry>
      <material name="steel">
        <color rgba="0.53 0.56 0.6 1" />
        </material>
      </visual>
    <collision name="right_pedal__right_pedal_body__hull_001">
      <origin xyz="0 0 0" rpy="1.5708 0 0" />
      <geometry>
        <mesh filename="meshes/collision/cache/6547aff824bd182147c9c4f6__hull_001.obj" />
        </geometry>
      </collision>
    <collision name="right_pedal__right_spindle">
      <origin xyz="0 -0.0275 0" rpy="1.5708 0 0" />
      <geometry>
        <cylinder radius="0.006" length="0.055" />
        </geometry>
      </collision>
    <collision name="right_pedal__right_upper_tread">
      <origin xyz="0 -0.052 0.0055" rpy="0 0 0" />
      <geometry>
        <box size="0.076 0.05 0.005" />
        </geometry>
      </collision>
    <collision name="right_pedal__right_lower_tread">
      <origin xyz="0 -0.052 -0.0055" rpy="0 0 0" />
      <geometry>
        <box size="0.076 0.05 0.005" />
        </geometry>
      </collision>
    <collision name="right_pedal__right_end_cap">
      <origin xyz="0 -0.084 0" rpy="1.5708 0 0" />
      <geometry>
        <cylinder radius="0.0072" length="0.012" />
        </geometry>
      </collision>
    </link>
  <joint name="bb_to_crank" type="continuous">
    <parent link="bb_shell" />
    <child link="crankset" />
    <axis xyz="0 1 0" />
    <limit effort="160" velocity="18" />
    </joint>
  <joint name="left_pedal_spin" type="continuous">
    <origin xyz="-0.0796689 0.052 0.152436" rpy="0 0 0" />
    <parent link="crankset" />
    <child link="left_pedal" />
    <axis xyz="0 1 0" />
    <limit effort="35" velocity="28" />
    </joint>
  <joint name="right_pedal_spin" type="continuous">
    <origin xyz="0.0796689 -0.052 -0.152436" rpy="0 0 0" />
    <parent link="crankset" />
    <child link="right_pedal" />
    <axis xyz="0 1 0" />
    <limit effort="35" velocity="28" />
    </joint>
  </robot>
