<robot name="weatherproof_mailbox">
  <link name="support">
    <inertial>
      <origin xyz="0 -0.01 0.43" rpy="0 0 0" />
      <mass value="7.5" />
      <inertia ixx="0.54325" ixy="0" ixz="0" iyy="0.5185" iyz="0" izz="0.13725" />
      </inertial>
    <visual>
      <origin xyz="0 -0.06 0.412" rpy="0 0 0" />
      <geometry>
        <box size="0.09 0.09 0.824" />
        </geometry>
      <material name="cedar_post">
        <color rgba="0.5 0.35 0.22 1" />
        </material>
      </visual>
    <visual>
      <origin xyz="0 0 0.831" rpy="0 0 0" />
      <geometry>
        <box size="0.28 0.26 0.018" />
        </geometry>
      <material name="cedar_post">
        <color rgba="0.5 0.35 0.22 1" />
        </material>
      </visual>
    <visual>
      <origin xyz="0 0.02 0.797" rpy="0 0 0" />
      <geometry>
        <box size="0.07 0.3 0.05" />
        </geometry>
      <material name="cedar_post">
        <color rgba="0.5 0.35 0.22 1" />
        </material>
      </visual>
    <visual>
      <origin xyz="0.028 -0.025 0.725" rpy="-0.82 0 0" />
      <geometry>
        <box size="0.022 0.19 0.03" />
        </geometry>
      <material name="cedar_post">
        <color rgba="0.5 0.35 0.22 1" />
        </material>
      </visual>
    <visual>
      <origin xyz="-0.028 -0.025 0.725" rpy="-0.82 0 0" />
      <geometry>
        <box size="0.022 0.19 0.03" />
        </geometry>
      <material name="cedar_post">
        <color rgba="0.5 0.35 0.22 1" />
        </material>
      </visual>
    </link>
  <link name="body">
    <inertial>
      <origin xyz="0 0 0.09" rpy="0 0 0" />
      <mass value="2.6" />
      <inertia ixx="0.0628333" ixy="0" ixz="0" iyy="0.0222083" iyz="0" izz="0.0677083" />
      </inertial>
    <visual>
      <geometry>
        <mesh filename="assets/meshes/mailbox_shell.obj" />
        </geometry>
      <material name="painted_green">
        <color rgba="0.19 0.3 0.2 1" />
        </material>
      </visual>
    <visual>
      <origin xyz="0 -0.233 0" rpy="0 0 0" />
      <geometry>
        <mesh filename="assets/meshes/mailbox_rear_cap.obj" />
        </geometry>
      <material name="painted_green">
        <color rgba="0.19 0.3 0.2 1" />
        </material>
      </visual>
    <visual>
      <origin xyz="0 0.234 0" rpy="0 0 0" />
      <geometry>
        <mesh filename="assets/meshes/mailbox_front_frame.obj" />
        </geometry>
      <material name="trim_black">
        <color rgba="0.1 0.1 0.11 1" />
        </material>
      </visual>
    <visual>
      <origin xyz="0 -0.01 0.009" rpy="0 0 0" />
      <geometry>
        <box size="0.18 0.35 0.018" />
        </geometry>
      <material name="trim_black">
        <color rgba="0.1 0.1 0.11 1" />
        </material>
      </visual>
    <visual>
      <origin xyz="0 0.22 0.178" rpy="0 0 0" />
      <geometry>
        <box size="0.16 0.028 0.01" />
        </geometry>
      <material name="trim_black">
        <color rgba="0.1 0.1 0.11 1" />
        </material>
      </visual>
    <visual>
      <origin xyz="0.121 0.07 0.078" rpy="0 1.5708 0" />
      <geometry>
        <cylinder radius="0.008" length="0.016" />
        </geometry>
      <material name="trim_black">
        <color rgba="0.1 0.1 0.11 1" />
        </material>
      </visual>
    <visual>
      <origin xyz="0.126 0.069 0.053" rpy="0 0 0" />
      <geometry>
        <box size="0.004 0.036 0.074" />
        </geometry>
      <material name="signal_red">
        <color rgba="0.73 0.1 0.1 1" />
        </material>
      </visual>
    <visual>
      <origin xyz="0.128 0.102 0.091" rpy="0 0 0" />
      <geometry>
        <box size="0.004 0.082 0.032" />
        </geometry>
      <material name="signal_red">
        <color rgba="0.73 0.1 0.1 1" />
        </material>
      </visual>
    </link>
  <link name="door">
    <inertial>
      <origin xyz="0 0.009 0.085" rpy="0 0 0" />
      <mass value="0.45" />
      <inertia ixx="0.00110869" ixy="0" ixz="0" iyy="0.00275029" iyz="0" izz="0.0016659" />
      </inertial>
    <visual>
      <origin xyz="0 0.009 0" rpy="0 0 0" />
      <geometry>
        <mesh filename="assets/meshes/mailbox_door.obj" />
        </geometry>
      <material name="painted_green">
        <color rgba="0.19 0.3 0.2 1" />
        </material>
      </visual>
    <visual>
      <origin xyz="0 0.02 0.08" rpy="1.5708 0 0" />
      <geometry>
        <cylinder radius="0.01" length="0.004" />
        </geometry>
      <material name="trim_black">
        <color rgba="0.1 0.1 0.11 1" />
        </material>
      </visual>
    <visual>
      <origin xyz="0 0.028 0.08" rpy="1.5708 0 0" />
      <geometry>
        <cylinder radius="0.0055" length="0.02" />
        </geometry>
      <material name="brushed_steel">
        <color rgba="0.72 0.74 0.76 1" />
        </material>
      </visual>
    <visual>
      <origin xyz="0 0.025 0.065" rpy="0 0 0" />
      <geometry>
        <box size="0.03 0.006 0.01" />
        </geometry>
      <material name="brushed_steel">
        <color rgba="0.72 0.74 0.76 1" />
        </material>
      </visual>
    </link>
  <joint name="support_to_body" type="fixed">
    <origin xyz="0 0 0.843" rpy="0 0 0" />
    <parent link="support" />
    <child link="body" />
    </joint>
  <joint name="front_access_door" type="revolute">
    <origin xyz="0 0.24 0" rpy="0 0 0" />
    <parent link="body" />
    <child link="door" />
    <axis xyz="-1 0 0" />
    <limit effort="8" velocity="2.5" lower="0" upper="1.5" />
    </joint>
  </robot>
