<robot name="tv_wall_mount">
  <material name="powder_black">
    <color rgba="0.12 0.12 0.13 1" />
    </material>
  <material name="graphite">
    <color rgba="0.22 0.24 0.27 1" />
    </material>
  <material name="zinc">
    <color rgba="0.74 0.76 0.78 1" />
    </material>
  <material name="rubber">
    <color rgba="0.08 0.08 0.09 1" />
    </material>
  <link name="wall_plate">
    <inertial>
      <origin xyz="0.035 0 0" rpy="0 0 0" />
      <mass value="3.2" />
      <inertia ixx="0.0461867" ixy="0" ixz="0" iyy="0.0321333" iyz="0" izz="0.0166667" />
      </inertial>
    <visual>
      <origin xyz="0.007 0 0" rpy="0 0 0" />
      <geometry>
        <box size="0.014 0.24 0.34" />
        </geometry>
      <material name="powder_black" />
      </visual>
    <visual>
      <origin xyz="0.019 -0.072 0" rpy="0 0 0" />
      <geometry>
        <box size="0.024 0.026 0.28" />
        </geometry>
      <material name="graphite" />
      </visual>
    <visual>
      <origin xyz="0.019 0.072 0" rpy="0 0 0" />
      <geometry>
        <box size="0.024 0.026 0.28" />
        </geometry>
      <material name="graphite" />
      </visual>
    <visual>
      <origin xyz="0.024 0 0" rpy="0 0 0" />
      <geometry>
        <box size="0.038 0.12 0.12" />
        </geometry>
      <material name="graphite" />
      </visual>
    <visual>
      <origin xyz="0.038 0 0.056" rpy="0 0 0" />
      <geometry>
        <box size="0.024 0.088 0.06" />
        </geometry>
      <material name="graphite" />
      </visual>
    <visual>
      <origin xyz="0.038 0 -0.056" rpy="0 0 0" />
      <geometry>
        <box size="0.024 0.088 0.06" />
        </geometry>
      <material name="graphite" />
      </visual>
    <visual>
      <origin xyz="0.047 0 0" rpy="0 0 0" />
      <geometry>
        <box size="0.02 0.1 0.07" />
        </geometry>
      <material name="graphite" />
      </visual>
    <visual>
      <origin xyz="0.055 0 0" rpy="0 0 0" />
      <geometry>
        <cylinder radius="0.018" length="0.05" />
        </geometry>
      <material name="zinc" />
      </visual>
    <visual>
      <origin xyz="0.01 -0.08 -0.11" rpy="0 1.5708 0" />
      <geometry>
        <cylinder radius="0.009" length="0.004" />
        </geometry>
      <material name="zinc" />
      </visual>
    <visual>
      <origin xyz="0.01 -0.08 0.11" rpy="0 1.5708 0" />
      <geometry>
        <cylinder radius="0.009" length="0.004" />
        </geometry>
      <material name="zinc" />
      </visual>
    <visual>
      <origin xyz="0.01 0.08 -0.11" rpy="0 1.5708 0" />
      <geometry>
        <cylinder radius="0.009" length="0.004" />
        </geometry>
      <material name="zinc" />
      </visual>
    <visual>
      <origin xyz="0.01 0.08 0.11" rpy="0 1.5708 0" />
      <geometry>
        <cylinder radius="0.009" length="0.004" />
        </geometry>
      <material name="zinc" />
      </visual>
    <collision name="wall_plate__visual_1">
      <origin xyz="0.007 0 0" rpy="0 0 0" />
      <geometry>
        <box size="0.014 0.24 0.34" />
        </geometry>
      </collision>
    <collision name="wall_plate__visual_2">
      <origin xyz="0.019 -0.072 0" rpy="0 0 0" />
      <geometry>
        <box size="0.024 0.026 0.28" />
        </geometry>
      </collision>
    <collision name="wall_plate__visual_3">
      <origin xyz="0.019 0.072 0" rpy="0 0 0" />
      <geometry>
        <box size="0.024 0.026 0.28" />
        </geometry>
      </collision>
    <collision name="wall_plate__visual_4">
      <origin xyz="0.024 0 0" rpy="0 0 0" />
      <geometry>
        <box size="0.038 0.12 0.12" />
        </geometry>
      </collision>
    <collision name="wall_plate__visual_5">
      <origin xyz="0.038 0 0.056" rpy="0 0 0" />
      <geometry>
        <box size="0.024 0.088 0.06" />
        </geometry>
      </collision>
    <collision name="wall_plate__visual_6">
      <origin xyz="0.038 0 -0.056" rpy="0 0 0" />
      <geometry>
        <box size="0.024 0.088 0.06" />
        </geometry>
      </collision>
    <collision name="wall_plate__visual_7">
      <origin xyz="0.047 0 0" rpy="0 0 0" />
      <geometry>
        <box size="0.02 0.1 0.07" />
        </geometry>
      </collision>
    <collision name="wall_plate__visual_8">
      <origin xyz="0.055 0 0" rpy="0 0 0" />
      <geometry>
        <cylinder radius="0.018" length="0.05" />
        </geometry>
      </collision>
    <collision name="wall_plate__visual_9">
      <origin xyz="0.01 -0.08 -0.11" rpy="0 1.5708 0" />
      <geometry>
        <cylinder radius="0.009" length="0.004" />
        </geometry>
      </collision>
    <collision name="wall_plate__visual_10">
      <origin xyz="0.01 -0.08 0.11" rpy="0 1.5708 0" />
      <geometry>
        <cylinder radius="0.009" length="0.004" />
        </geometry>
      </collision>
    <collision name="wall_plate__visual_11">
      <origin xyz="0.01 0.08 -0.11" rpy="0 1.5708 0" />
      <geometry>
        <cylinder radius="0.009" length="0.004" />
        </geometry>
      </collision>
    <collision name="wall_plate__visual_12">
      <origin xyz="0.01 0.08 0.11" rpy="0 1.5708 0" />
      <geometry>
        <cylinder radius="0.009" length="0.004" />
        </geometry>
      </collision>
    </link>
  <link name="inner_arm">
    <inertial>
      <origin xyz="0.085 0 0" rpy="0 0 0" />
      <mass value="1.7" />
      <inertia ixx="0.00104833" ixy="0" ixz="0" iyy="0.00444833" iyz="0" izz="0.00478833" />
      </inertial>
    <visual>
      <geometry>
        <cylinder radius="0.017" length="0.04" />
        </geometry>
      <material name="zinc" />
      </visual>
    <visual>
      <origin xyz="0.012 0 0" rpy="0 0 0" />
      <geometry>
        <box size="0.032 0.07 0.046" />
        </geometry>
      <material name="graphite" />
      </visual>
    <visual>
      <origin xyz="0.078 -0.022 0" rpy="0 0 0" />
      <geometry>
        <box size="0.128 0.014 0.026" />
        </geometry>
      <material name="powder_black" />
      </visual>
    <visual>
      <origin xyz="0.078 0.022 0" rpy="0 0 0" />
      <geometry>
        <box size="0.128 0.014 0.026" />
        </geometry>
      <material name="powder_black" />
      </visual>
    <visual>
      <origin xyz="0.042 0 0" rpy="0 0 0" />
      <geometry>
        <box size="0.02 0.058 0.018" />
        </geometry>
      <material name="graphite" />
      </visual>
    <visual>
      <origin xyz="0.11 0 0" rpy="0 0 0" />
      <geometry>
        <box size="0.02 0.058 0.018" />
        </geometry>
      <material name="graphite" />
      </visual>
    <visual>
      <origin xyz="0.082 0 0.014" rpy="0 0 0" />
      <geometry>
        <box size="0.082 0.02 0.01" />
        </geometry>
      <material name="graphite" />
      </visual>
    <visual>
      <origin xyz="0.145 0 0" rpy="0 0 0" />
      <geometry>
        <box size="0.026 0.07 0.04" />
        </geometry>
      <material name="graphite" />
      </visual>
    <visual>
      <origin xyz="0.145 0 0" rpy="0 0 0" />
      <geometry>
        <cylinder radius="0.018" length="0.04" />
        </geometry>
      <material name="zinc" />
      </visual>
    <collision name="inner_arm__visual_1">
      <geometry>
        <cylinder radius="0.017" length="0.04" />
        </geometry>
      </collision>
    <collision name="inner_arm__visual_2">
      <origin xyz="0.012 0 0" rpy="0 0 0" />
      <geometry>
        <box size="0.032 0.07 0.046" />
        </geometry>
      </collision>
    <collision name="inner_arm__visual_3">
      <origin xyz="0.078 -0.022 0" rpy="0 0 0" />
      <geometry>
        <box size="0.128 0.014 0.026" />
        </geometry>
      </collision>
    <collision name="inner_arm__visual_4">
      <origin xyz="0.078 0.022 0" rpy="0 0 0" />
      <geometry>
        <box size="0.128 0.014 0.026" />
        </geometry>
      </collision>
    <collision name="inner_arm__visual_5">
      <origin xyz="0.042 0 0" rpy="0 0 0" />
      <geometry>
        <box size="0.02 0.058 0.018" />
        </geometry>
      </collision>
    <collision name="inner_arm__visual_6">
      <origin xyz="0.11 0 0" rpy="0 0 0" />
      <geometry>
        <box size="0.02 0.058 0.018" />
        </geometry>
      </collision>
    <collision name="inner_arm__visual_7">
      <origin xyz="0.082 0 0.014" rpy="0 0 0" />
      <geometry>
        <box size="0.082 0.02 0.01" />
        </geometry>
      </collision>
    <collision name="inner_arm__visual_8">
      <origin xyz="0.145 0 0" rpy="0 0 0" />
      <geometry>
        <box size="0.026 0.07 0.04" />
        </geometry>
      </collision>
    <collision name="inner_arm__visual_9">
      <origin xyz="0.145 0 0" rpy="0 0 0" />
      <geometry>
        <cylinder radius="0.018" length="0.04" />
        </geometry>
      </collision>
    </link>
  <link name="outer_arm">
    <inertial>
      <origin xyz="0.079 0 0" rpy="0 0 0" />
      <mass value="1.4" />
      <inertia ixx="0.000746667" ixy="0" ixz="0" iyy="0.00318127" iyz="0" izz="0.00339033" />
      </inertial>
    <visual>
      <geometry>
        <cylinder radius="0.017" length="0.04" />
        </geometry>
      <material name="zinc" />
      </visual>
    <visual>
      <origin xyz="0.011 0 0" rpy="0 0 0" />
      <geometry>
        <box size="0.03 0.062 0.044" />
        </geometry>
      <material name="graphite" />
      </visual>
    <visual>
      <origin xyz="0.074 -0.019 0" rpy="0 0 0" />
      <geometry>
        <box size="0.12 0.013 0.024" />
        </geometry>
      <material name="powder_black" />
      </visual>
    <visual>
      <origin xyz="0.074 0.019 0" rpy="0 0 0" />
      <geometry>
        <box size="0.12 0.013 0.024" />
        </geometry>
      <material name="powder_black" />
      </visual>
    <visual>
      <origin xyz="0.036 0 0" rpy="0 0 0" />
      <geometry>
        <box size="0.018 0.052 0.018" />
        </geometry>
      <material name="graphite" />
      </visual>
    <visual>
      <origin xyz="0.1 0 0" rpy="0 0 0" />
      <geometry>
        <box size="0.018 0.052 0.018" />
        </geometry>
      <material name="graphite" />
      </visual>
    <visual>
      <origin xyz="0.072 0 -0.013" rpy="0 0 0" />
      <geometry>
        <box size="0.064 0.018 0.01" />
        </geometry>
      <material name="graphite" />
      </visual>
    <visual>
      <origin xyz="0.137 0 0" rpy="0 0 0" />
      <geometry>
        <box size="0.028 0.062 0.04" />
        </geometry>
      <material name="graphite" />
      </visual>
    <visual>
      <origin xyz="0.137 0 0" rpy="0 0 0" />
      <geometry>
        <cylinder radius="0.0175" length="0.04" />
        </geometry>
      <material name="zinc" />
      </visual>
    <collision name="outer_arm__visual_1">
      <geometry>
        <cylinder radius="0.017" length="0.04" />
        </geometry>
      </collision>
    <collision name="outer_arm__visual_2">
      <origin xyz="0.011 0 0" rpy="0 0 0" />
      <geometry>
        <box size="0.03 0.062 0.044" />
        </geometry>
      </collision>
    <collision name="outer_arm__visual_3">
      <origin xyz="0.074 -0.019 0" rpy="0 0 0" />
      <geometry>
        <box size="0.12 0.013 0.024" />
        </geometry>
      </collision>
    <collision name="outer_arm__visual_4">
      <origin xyz="0.074 0.019 0" rpy="0 0 0" />
      <geometry>
        <box size="0.12 0.013 0.024" />
        </geometry>
      </collision>
    <collision name="outer_arm__visual_5">
      <origin xyz="0.036 0 0" rpy="0 0 0" />
      <geometry>
        <box size="0.018 0.052 0.018" />
        </geometry>
      </collision>
    <collision name="outer_arm__visual_6">
      <origin xyz="0.1 0 0" rpy="0 0 0" />
      <geometry>
        <box size="0.018 0.052 0.018" />
        </geometry>
      </collision>
    <collision name="outer_arm__visual_7">
      <origin xyz="0.072 0 -0.013" rpy="0 0 0" />
      <geometry>
        <box size="0.064 0.018 0.01" />
        </geometry>
      </collision>
    <collision name="outer_arm__visual_8">
      <origin xyz="0.137 0 0" rpy="0 0 0" />
      <geometry>
        <box size="0.028 0.062 0.04" />
        </geometry>
      </collision>
    <collision name="outer_arm__visual_9">
      <origin xyz="0.137 0 0" rpy="0 0 0" />
      <geometry>
        <cylinder radius="0.0175" length="0.04" />
        </geometry>
      </collision>
    </link>
  <link name="tilt_head">
    <inertial>
      <origin xyz="0.045 0 0" rpy="0 0 0" />
      <mass value="0.9" />
      <inertia ixx="0.0012246" ixy="0" ixz="0" iyy="0.0013278" iyz="0" izz="0.0011118" />
      </inertial>
    <visual>
      <geometry>
        <cylinder radius="0.018" length="0.042" />
        </geometry>
      <material name="zinc" />
      </visual>
    <visual>
      <origin xyz="0.012 0 0" rpy="0 0 0" />
      <geometry>
        <box size="0.032 0.072 0.044" />
        </geometry>
      <material name="graphite" />
      </visual>
    <visual>
      <origin xyz="0.042 0 0" rpy="0 0 0" />
      <geometry>
        <box size="0.06 0.05 0.028" />
        </geometry>
      <material name="powder_black" />
      </visual>
    <visual>
      <origin xyz="0.05 -0.028 0" rpy="0 0 0" />
      <geometry>
        <box size="0.06 0.01 0.09" />
        </geometry>
      <material name="graphite" />
      </visual>
    <visual>
      <origin xyz="0.05 0.028 0" rpy="0 0 0" />
      <geometry>
        <box size="0.06 0.01 0.09" />
        </geometry>
      <material name="graphite" />
      </visual>
    <visual>
      <origin xyz="0.038 0 0.032" rpy="0 0 0" />
      <geometry>
        <box size="0.028 0.072 0.014" />
        </geometry>
      <material name="graphite" />
      </visual>
    <visual>
      <origin xyz="0.046 0 -0.032" rpy="0 0 0" />
      <geometry>
        <box size="0.024 0.072 0.014" />
        </geometry>
      <material name="graphite" />
      </visual>
    <visual>
      <origin xyz="0.072 0 0" rpy="1.5708 0 0" />
      <geometry>
        <cylinder radius="0.015" length="0.074" />
        </geometry>
      <material name="zinc" />
      </visual>
    <collision name="tilt_head__visual_1">
      <geometry>
        <cylinder radius="0.018" length="0.042" />
        </geometry>
      </collision>
    <collision name="tilt_head__visual_2">
      <origin xyz="0.012 0 0" rpy="0 0 0" />
      <geometry>
        <box size="0.032 0.072 0.044" />
        </geometry>
      </collision>
    <collision name="tilt_head__visual_3">
      <origin xyz="0.042 0 0" rpy="0 0 0" />
      <geometry>
        <box size="0.06 0.05 0.028" />
        </geometry>
      </collision>
    <collision name="tilt_head__visual_4">
      <origin xyz="0.05 -0.028 0" rpy="0 0 0" />
      <geometry>
        <box size="0.06 0.01 0.09" />
        </geometry>
      </collision>
    <collision name="tilt_head__visual_5">
      <origin xyz="0.05 0.028 0" rpy="0 0 0" />
      <geometry>
        <box size="0.06 0.01 0.09" />
        </geometry>
      </collision>
    <collision name="tilt_head__visual_6">
      <origin xyz="0.038 0 0.032" rpy="0 0 0" />
      <geometry>
        <box size="0.028 0.072 0.014" />
        </geometry>
      </collision>
    <collision name="tilt_head__visual_7">
      <origin xyz="0.046 0 -0.032" rpy="0 0 0" />
      <geometry>
        <box size="0.024 0.072 0.014" />
        </geometry>
      </collision>
    <collision name="tilt_head__visual_8">
      <origin xyz="0.072 0 0" rpy="1.5708 0 0" />
      <geometry>
        <cylinder radius="0.015" length="0.074" />
        </geometry>
      </collision>
    </link>
  <link name="screen_bracket">
    <inertial>
      <origin xyz="0.02 0 0" rpy="0 0 0" />
      <mass value="2.4" />
      <inertia ixx="0.03848" ixy="0" ixz="0" iyy="0.01832" iyz="0" izz="0.0208" />
      </inertial>
    <visual>
      <origin xyz="0.014 0 0" rpy="0 0 0" />
      <geometry>
        <box size="0.028 0.11 0.03" />
        </geometry>
      <material name="graphite" />
      </visual>
    <visual>
      <origin xyz="0.012 0 0" rpy="0 0 0" />
      <geometry>
        <box size="0.018 0.14 0.17" />
        </geometry>
      <material name="powder_black" />
      </visual>
    <visual>
      <origin xyz="0.01 0 0.04" rpy="0 0 0" />
      <geometry>
        <box size="0.014 0.22 0.018" />
        </geometry>
      <material name="graphite" />
      </visual>
    <visual>
      <origin xyz="0.01 0 -0.04" rpy="0 0 0" />
      <geometry>
        <box size="0.014 0.22 0.018" />
        </geometry>
      <material name="graphite" />
      </visual>
    <visual>
      <origin xyz="0.014 0 0.11" rpy="0 0 0" />
      <geometry>
        <box size="0.016 0.32 0.02" />
        </geometry>
      <material name="powder_black" />
      </visual>
    <visual>
      <origin xyz="0.014 0 -0.11" rpy="0 0 0" />
      <geometry>
        <box size="0.016 0.32 0.02" />
        </geometry>
      <material name="powder_black" />
      </visual>
    <visual>
      <origin xyz="0.015 -0.11 0" rpy="0 0 0" />
      <geometry>
        <box size="0.014 0.024 0.28" />
        </geometry>
      <material name="powder_black" />
      </visual>
    <visual>
      <origin xyz="0.015 0.11 0" rpy="0 0 0" />
      <geometry>
        <box size="0.014 0.024 0.28" />
        </geometry>
      <material name="powder_black" />
      </visual>
    <visual>
      <origin xyz="0.02 -0.11 0.06" rpy="0 0 0" />
      <geometry>
        <box size="0.02 0.05 0.04" />
        </geometry>
      <material name="graphite" />
      </visual>
    <visual>
      <origin xyz="0.02 0.11 0.06" rpy="0 0 0" />
      <geometry>
        <box size="0.02 0.05 0.04" />
        </geometry>
      <material name="graphite" />
      </visual>
    <visual>
      <origin xyz="0.02 -0.11 -0.06" rpy="0 0 0" />
      <geometry>
        <box size="0.02 0.05 0.04" />
        </geometry>
      <material name="graphite" />
      </visual>
    <visual>
      <origin xyz="0.02 0.11 -0.06" rpy="0 0 0" />
      <geometry>
        <box size="0.02 0.05 0.04" />
        </geometry>
      <material name="graphite" />
      </visual>
    <visual>
      <origin xyz="0.024 -0.11 0.138" rpy="0 0 0" />
      <geometry>
        <box size="0.028 0.028 0.024" />
        </geometry>
      <material name="graphite" />
      </visual>
    <visual>
      <origin xyz="0.024 0.11 0.138" rpy="0 0 0" />
      <geometry>
        <box size="0.028 0.028 0.024" />
        </geometry>
      <material name="graphite" />
      </visual>
    <visual>
      <origin xyz="0.024 -0.11 -0.138" rpy="0 0 0" />
      <geometry>
        <box size="0.028 0.028 0.024" />
        </geometry>
      <material name="graphite" />
      </visual>
    <visual>
      <origin xyz="0.024 0.11 -0.138" rpy="0 0 0" />
      <geometry>
        <box size="0.028 0.028 0.024" />
        </geometry>
      <material name="graphite" />
      </visual>
    <visual>
      <origin xyz="0.009 -0.085 0.065" rpy="0 0 0" />
      <geometry>
        <box size="0.006 0.05 0.05" />
        </geometry>
      <material name="rubber" />
      </visual>
    <visual>
      <origin xyz="0.009 0.085 0.065" rpy="0 0 0" />
      <geometry>
        <box size="0.006 0.05 0.05" />
        </geometry>
      <material name="rubber" />
      </visual>
    <visual>
      <origin xyz="0.009 -0.085 -0.065" rpy="0 0 0" />
      <geometry>
        <box size="0.006 0.05 0.05" />
        </geometry>
      <material name="rubber" />
      </visual>
    <visual>
      <origin xyz="0.009 0.085 -0.065" rpy="0 0 0" />
      <geometry>
        <box size="0.006 0.05 0.05" />
        </geometry>
      <material name="rubber" />
      </visual>
    <visual>
      <origin xyz="0.02 -0.1 -0.06" rpy="0 1.5708 0" />
      <geometry>
        <cylinder radius="0.01" length="0.008" />
        </geometry>
      <material name="zinc" />
      </visual>
    <visual>
      <origin xyz="0.02 -0.1 0.06" rpy="0 1.5708 0" />
      <geometry>
        <cylinder radius="0.01" length="0.008" />
        </geometry>
      <material name="zinc" />
      </visual>
    <visual>
      <origin xyz="0.02 0.1 -0.06" rpy="0 1.5708 0" />
      <geometry>
        <cylinder radius="0.01" length="0.008" />
        </geometry>
      <material name="zinc" />
      </visual>
    <visual>
      <origin xyz="0.02 0.1 0.06" rpy="0 1.5708 0" />
      <geometry>
        <cylinder radius="0.01" length="0.008" />
        </geometry>
      <material name="zinc" />
      </visual>
    <collision name="screen_bracket__visual_1">
      <origin xyz="0.014 0 0" rpy="0 0 0" />
      <geometry>
        <box size="0.028 0.11 0.03" />
        </geometry>
      </collision>
    <collision name="screen_bracket__visual_2">
      <origin xyz="0.012 0 0" rpy="0 0 0" />
      <geometry>
        <box size="0.018 0.14 0.17" />
        </geometry>
      </collision>
    <collision name="screen_bracket__visual_3">
      <origin xyz="0.01 0 0.04" rpy="0 0 0" />
      <geometry>
        <box size="0.014 0.22 0.018" />
        </geometry>
      </collision>
    <collision name="screen_bracket__visual_4">
      <origin xyz="0.01 0 -0.04" rpy="0 0 0" />
      <geometry>
        <box size="0.014 0.22 0.018" />
        </geometry>
      </collision>
    <collision name="screen_bracket__visual_5">
      <origin xyz="0.014 0 0.11" rpy="0 0 0" />
      <geometry>
        <box size="0.016 0.32 0.02" />
        </geometry>
      </collision>
    <collision name="screen_bracket__visual_6">
      <origin xyz="0.014 0 -0.11" rpy="0 0 0" />
      <geometry>
        <box size="0.016 0.32 0.02" />
        </geometry>
      </collision>
    <collision name="screen_bracket__visual_7">
      <origin xyz="0.015 -0.11 0" rpy="0 0 0" />
      <geometry>
        <box size="0.014 0.024 0.28" />
        </geometry>
      </collision>
    <collision name="screen_bracket__visual_8">
      <origin xyz="0.015 0.11 0" rpy="0 0 0" />
      <geometry>
        <box size="0.014 0.024 0.28" />
        </geometry>
      </collision>
    <collision name="screen_bracket__visual_9">
      <origin xyz="0.02 -0.11 0.06" rpy="0 0 0" />
      <geometry>
        <box size="0.02 0.05 0.04" />
        </geometry>
      </collision>
    <collision name="screen_bracket__visual_10">
      <origin xyz="0.02 0.11 0.06" rpy="0 0 0" />
      <geometry>
        <box size="0.02 0.05 0.04" />
        </geometry>
      </collision>
    <collision name="screen_bracket__visual_11">
      <origin xyz="0.02 -0.11 -0.06" rpy="0 0 0" />
      <geometry>
        <box size="0.02 0.05 0.04" />
        </geometry>
      </collision>
    <collision name="screen_bracket__visual_12">
      <origin xyz="0.02 0.11 -0.06" rpy="0 0 0" />
      <geometry>
        <box size="0.02 0.05 0.04" />
        </geometry>
      </collision>
    <collision name="screen_bracket__visual_13">
      <origin xyz="0.024 -0.11 0.138" rpy="0 0 0" />
      <geometry>
        <box size="0.028 0.028 0.024" />
        </geometry>
      </collision>
    <collision name="screen_bracket__visual_14">
      <origin xyz="0.024 0.11 0.138" rpy="0 0 0" />
      <geometry>
        <box size="0.028 0.028 0.024" />
        </geometry>
      </collision>
    <collision name="screen_bracket__visual_15">
      <origin xyz="0.024 -0.11 -0.138" rpy="0 0 0" />
      <geometry>
        <box size="0.028 0.028 0.024" />
        </geometry>
      </collision>
    <collision name="screen_bracket__visual_16">
      <origin xyz="0.024 0.11 -0.138" rpy="0 0 0" />
      <geometry>
        <box size="0.028 0.028 0.024" />
        </geometry>
      </collision>
    <collision name="screen_bracket__visual_17">
      <origin xyz="0.009 -0.085 0.065" rpy="0 0 0" />
      <geometry>
        <box size="0.006 0.05 0.05" />
        </geometry>
      </collision>
    <collision name="screen_bracket__visual_18">
      <origin xyz="0.009 0.085 0.065" rpy="0 0 0" />
      <geometry>
        <box size="0.006 0.05 0.05" />
        </geometry>
      </collision>
    <collision name="screen_bracket__visual_19">
      <origin xyz="0.009 -0.085 -0.065" rpy="0 0 0" />
      <geometry>
        <box size="0.006 0.05 0.05" />
        </geometry>
      </collision>
    <collision name="screen_bracket__visual_20">
      <origin xyz="0.009 0.085 -0.065" rpy="0 0 0" />
      <geometry>
        <box size="0.006 0.05 0.05" />
        </geometry>
      </collision>
    <collision name="screen_bracket__visual_21">
      <origin xyz="0.02 -0.1 -0.06" rpy="0 1.5708 0" />
      <geometry>
        <cylinder radius="0.01" length="0.008" />
        </geometry>
      </collision>
    <collision name="screen_bracket__visual_22">
      <origin xyz="0.02 -0.1 0.06" rpy="0 1.5708 0" />
      <geometry>
        <cylinder radius="0.01" length="0.008" />
        </geometry>
      </collision>
    <collision name="screen_bracket__visual_23">
      <origin xyz="0.02 0.1 -0.06" rpy="0 1.5708 0" />
      <geometry>
        <cylinder radius="0.01" length="0.008" />
        </geometry>
      </collision>
    <collision name="screen_bracket__visual_24">
      <origin xyz="0.02 0.1 0.06" rpy="0 1.5708 0" />
      <geometry>
        <cylinder radius="0.01" length="0.008" />
        </geometry>
      </collision>
    </link>
  <joint name="wall_swing" type="revolute">
    <origin xyz="0.055 0 0" rpy="0 0 0" />
    <parent link="wall_plate" />
    <child link="inner_arm" />
    <axis xyz="0 0 1" />
    <limit effort="180" velocity="1.5" lower="-1.15" upper="1.15" />
    </joint>
  <joint name="elbow_swing" type="revolute">
    <origin xyz="0.145 0 0" rpy="0 0 0" />
    <parent link="inner_arm" />
    <child link="outer_arm" />
    <axis xyz="0 0 1" />
    <limit effort="160" velocity="1.6" lower="-1.45" upper="1.45" />
    </joint>
  <joint name="head_swivel" type="revolute">
    <origin xyz="0.137 0 0" rpy="0 0 0" />
    <parent link="outer_arm" />
    <child link="tilt_head" />
    <axis xyz="0 0 1" />
    <limit effort="90" velocity="1.6" lower="-0.45" upper="0.45" />
    </joint>
  <joint name="screen_tilt" type="revolute">
    <origin xyz="0.072 0 0" rpy="0 0 0" />
    <parent link="tilt_head" />
    <child link="screen_bracket" />
    <axis xyz="0 1 0" />
    <limit effort="70" velocity="1.2" lower="-0.35" upper="0.2" />
    </joint>
  </robot>
