<robot name="industrial_electrical_cabinet">
  <link name="cabinet">
    <inertial>
      <mass value="88" />
      <inertia ixx="13.4347" ixy="0" ixz="0" iyy="10.0467" iyz="0" izz="5.08347" />
      </inertial>
    <visual>
      <origin xyz="-0.1685 0 0" rpy="0 0 0" />
      <geometry>
        <box size="0.003 0.76 1.12" />
        </geometry>
      </visual>
    <visual>
      <origin xyz="0.0015 -0.371 0" rpy="0 0 0" />
      <geometry>
        <box size="0.337 0.018 1.12" />
        </geometry>
      </visual>
    <visual>
      <origin xyz="0.0015 0.371 0" rpy="0 0 0" />
      <geometry>
        <box size="0.337 0.018 1.12" />
        </geometry>
      </visual>
    <visual>
      <origin xyz="0.0015 0 -0.551" rpy="0 0 0" />
      <geometry>
        <box size="0.337 0.724 0.018" />
        </geometry>
      </visual>
    <visual>
      <origin xyz="0.0015 0 0.551" rpy="0 0 0" />
      <geometry>
        <box size="0.337 0.724 0.018" />
        </geometry>
      </visual>
    <visual>
      <origin xyz="0.148 -0.366 0" rpy="0 0 0" />
      <geometry>
        <box size="0.02 0.028 1.02" />
        </geometry>
      </visual>
    <visual>
      <origin xyz="0.148 0.366 0" rpy="0 0 0" />
      <geometry>
        <box size="0.02 0.028 1.02" />
        </geometry>
      </visual>
    <visual>
      <origin xyz="0.148 0 -0.546" rpy="0 0 0" />
      <geometry>
        <box size="0.02 0.704 0.028" />
        </geometry>
      </visual>
    <visual>
      <origin xyz="0.148 0 0.546" rpy="0 0 0" />
      <geometry>
        <box size="0.02 0.704 0.028" />
        </geometry>
      </visual>
    <visual>
      <origin xyz="-0.115 0 0" rpy="0 0 0" />
      <geometry>
        <box size="0.003 0.62 0.94" />
        </geometry>
      </visual>
    <visual>
      <origin xyz="-0.141 -0.25 -0.38" rpy="0 0 0" />
      <geometry>
        <box size="0.052 0.026 0.026" />
        </geometry>
      </visual>
    <visual>
      <origin xyz="-0.141 -0.25 0.38" rpy="0 0 0" />
      <geometry>
        <box size="0.052 0.026 0.026" />
        </geometry>
      </visual>
    <visual>
      <origin xyz="-0.141 0.25 -0.38" rpy="0 0 0" />
      <geometry>
        <box size="0.052 0.026 0.026" />
        </geometry>
      </visual>
    <visual>
      <origin xyz="-0.141 0.25 0.38" rpy="0 0 0" />
      <geometry>
        <box size="0.052 0.026 0.026" />
        </geometry>
      </visual>
    <visual>
      <origin xyz="-0.14 0 -0.545" rpy="0 0 0" />
      <geometry>
        <box size="0.06 0.68 0.03" />
        </geometry>
      </visual>
    <visual>
      <origin xyz="0.162 -0.36 0" rpy="0 0 0" />
      <geometry>
        <box size="0.016 0.04 0.88" />
        </geometry>
      </visual>
    <visual>
      <origin xyz="0.163 0.366 0" rpy="0 0 0" />
      <geometry>
        <box size="0.016 0.04 0.98" />
        </geometry>
      </visual>
    <visual>
      <origin xyz="0.162 0.365 -0.34" rpy="0 0 0" />
      <geometry>
        <box size="0.01 0.022 0.12" />
        </geometry>
      </visual>
    <visual>
      <origin xyz="0.162 0.365 0" rpy="0 0 0" />
      <geometry>
        <box size="0.01 0.022 0.12" />
        </geometry>
      </visual>
    <visual>
      <origin xyz="0.162 0.365 0.34" rpy="0 0 0" />
      <geometry>
        <box size="0.01 0.022 0.12" />
        </geometry>
      </visual>
    </link>
  <link name="door">
    <inertial>
      <origin xyz="0.01 -0.366 0" rpy="0 0 0" />
      <mass value="24" />
      <inertia ixx="3.2272" ixy="0" ixz="0" iyy="2.2522" iyz="0" izz="0.985" />
      </inertial>
    <visual>
      <origin xyz="0.008 -0.366 0" rpy="0 0 0" />
      <geometry>
        <box size="0.018 0.7 1.06" />
        </geometry>
      </visual>
    <visual>
      <origin xyz="0.014 -0.366 -0.5" rpy="0 0 0" />
      <geometry>
        <box size="0.008 0.7 0.06" />
        </geometry>
      </visual>
    <visual>
      <origin xyz="0.014 -0.366 0.5" rpy="0 0 0" />
      <geometry>
        <box size="0.008 0.7 0.06" />
        </geometry>
      </visual>
    <visual>
      <origin xyz="0.014 -0.0435 0" rpy="0 0 0" />
      <geometry>
        <box size="0.008 0.055 0.94" />
        </geometry>
      </visual>
    <visual>
      <origin xyz="0.014 -0.6885 0" rpy="0 0 0" />
      <geometry>
        <box size="0.008 0.055 0.94" />
        </geometry>
      </visual>
    <visual>
      <origin xyz="0.009 -0.366 0" rpy="0 0 0" />
      <geometry>
        <box size="0.01 0.52 0.88" />
        </geometry>
      </visual>
    <visual>
      <origin xyz="0.001 -0.032 0" rpy="0 0 0" />
      <geometry>
        <box size="0.028 0.032 0.98" />
        </geometry>
      </visual>
    <visual>
      <origin xyz="0.001 -0.7 0" rpy="0 0 0" />
      <geometry>
        <box size="0.028 0.032 0.98" />
        </geometry>
      </visual>
    <visual>
      <origin xyz="0.001 -0.366 -0.514" rpy="0 0 0" />
      <geometry>
        <box size="0.028 0.636 0.032" />
        </geometry>
      </visual>
    <visual>
      <origin xyz="0.001 -0.366 0.514" rpy="0 0 0" />
      <geometry>
        <box size="0.028 0.636 0.032" />
        </geometry>
      </visual>
    <visual>
      <origin xyz="0 -0.206 0" rpy="0 0 0" />
      <geometry>
        <box size="0.014 0.04 0.72" />
        </geometry>
      </visual>
    <visual>
      <origin xyz="0 -0.526 0" rpy="0 0 0" />
      <geometry>
        <box size="0.014 0.04 0.72" />
        </geometry>
      </visual>
    <visual>
      <origin xyz="0 -0.626 0" rpy="0 0 0" />
      <geometry>
        <box size="0.016 0.05 0.26" />
        </geometry>
      </visual>
    <visual>
      <origin xyz="0 -0.626 0.29" rpy="0 0 0" />
      <geometry>
        <cylinder radius="0.006" length="0.36" />
        </geometry>
      </visual>
    <visual>
      <origin xyz="0 -0.626 -0.29" rpy="0 0 0" />
      <geometry>
        <cylinder radius="0.006" length="0.36" />
        </geometry>
      </visual>
    <visual>
      <origin xyz="0.001 -0.626 0.11" rpy="0 0 0" />
      <geometry>
        <box size="0.018 0.038 0.02" />
        </geometry>
      </visual>
    <visual>
      <origin xyz="0.001 -0.626 -0.11" rpy="0 0 0" />
      <geometry>
        <box size="0.018 0.038 0.02" />
        </geometry>
      </visual>
    <visual>
      <origin xyz="0.001 -0.626 0.47" rpy="0 0 0" />
      <geometry>
        <box size="0.018 0.038 0.02" />
        </geometry>
      </visual>
    <visual>
      <origin xyz="0.001 -0.626 -0.47" rpy="0 0 0" />
      <geometry>
        <box size="0.018 0.038 0.02" />
        </geometry>
      </visual>
    <visual>
      <origin xyz="0.022 -0.626 0" rpy="0 0 0" />
      <geometry>
        <box size="0.02 0.09 0.3" />
        </geometry>
      </visual>
    <visual>
      <origin xyz="0.021 -0.626 0" rpy="0 1.5708 0" />
      <geometry>
        <cylinder radius="0.015" length="0.018" />
        </geometry>
      </visual>
    <visual>
      <origin xyz="0.034 -0.626 0" rpy="0 0 0" />
      <geometry>
        <box size="0.024 0.032 0.18" />
        </geometry>
      </visual>
    <visual>
      <origin xyz="0.041 -0.626 -0.04" rpy="0 0 0" />
      <geometry>
        <box size="0.01 0.032 0.1" />
        </geometry>
      </visual>
    <visual>
      <origin xyz="0.018 -0.276 0.41" rpy="0 0 0" />
      <geometry>
        <box size="0.004 0.18 0.07" />
        </geometry>
      </visual>
    <visual>
      <origin xyz="-0.01 -0.03 0" rpy="0 0 0" />
      <geometry>
        <box size="0.004 0.028 0.94" />
        </geometry>
      </visual>
    <visual>
      <origin xyz="-0.01 -0.702 0" rpy="0 0 0" />
      <geometry>
        <box size="0.004 0.028 0.94" />
        </geometry>
      </visual>
    <visual>
      <origin xyz="-0.01 -0.366 -0.516" rpy="0 0 0" />
      <geometry>
        <box size="0.004 0.644 0.028" />
        </geometry>
      </visual>
    <visual>
      <origin xyz="-0.01 -0.366 0.516" rpy="0 0 0" />
      <geometry>
        <box size="0.004 0.644 0.028" />
        </geometry>
      </visual>
    <visual>
      <origin xyz="0 0 -0.34" rpy="0 0 0" />
      <geometry>
        <cylinder radius="0.01" length="0.14" />
        </geometry>
      </visual>
    <visual>
      <origin xyz="0.004 -0.008 -0.34" rpy="0 0 0" />
      <geometry>
        <box size="0.008 0.02 0.14" />
        </geometry>
      </visual>
    <visual>
      <geometry>
        <cylinder radius="0.01" length="0.14" />
        </geometry>
      </visual>
    <visual>
      <origin xyz="0.004 -0.008 0" rpy="0 0 0" />
      <geometry>
        <box size="0.008 0.02 0.14" />
        </geometry>
      </visual>
    <visual>
      <origin xyz="0 0 0.34" rpy="0 0 0" />
      <geometry>
        <cylinder radius="0.01" length="0.14" />
        </geometry>
      </visual>
    <visual>
      <origin xyz="0.004 -0.008 0.34" rpy="0 0 0" />
      <geometry>
        <box size="0.008 0.02 0.14" />
        </geometry>
      </visual>
    </link>
  <joint name="door_hinge" type="revolute">
    <origin xyz="0.173 0.366 0" rpy="0 0 0" />
    <parent link="cabinet" />
    <child link="door" />
    <axis xyz="0 0 1" />
    <limit effort="90" velocity="1.2" lower="0" upper="2.1" />
    </joint>
  </robot>
