<robot name="inspection_fixture">
  <material name="fixture_base">
    <color rgba="0.42 0.44 0.48 1" />
  </material>
  <material name="fixture_carriage">
    <color rgba="0.78 0.46 0.14 1" />
  </material>
  <material name="fixture_flap">
    <color rgba="0.92 0.77 0.16 1" />
  </material>
  <link name="base">
    <inertial>
      <origin xyz="0 0 0.03" rpy="0 0 0" />
      <mass value="11" />
      <inertia ixx="0.0502333" ixy="0" ixz="0" iyy="0.167567" iyz="0" izz="0.206067" />
    </inertial>
    <visual>
      <geometry>
        <mesh filename="meshes/fixture_base.glb" />
      </geometry>
      <material name="fixture_base" />
    </visual>
    <collision>
      <geometry>
        <box size="0.42 0.22 0.02" />
      </geometry>
    </collision>
    <collision>
      <origin xyz="0 0.07 0.0275" rpy="0 0 0" />
      <geometry>
        <box size="0.3 0.032 0.035" />
      </geometry>
    </collision>
    <collision>
      <origin xyz="0 -0.07 0.0275" rpy="0 0 0" />
      <geometry>
        <box size="0.3 0.032 0.035" />
      </geometry>
    </collision>
    <collision>
      <origin xyz="-0.17 0 0.0425" rpy="0 0 0" />
      <geometry>
        <box size="0.04 0.18 0.065" />
      </geometry>
    </collision>
    <collision>
      <origin xyz="0.18 0 0.0225" rpy="0 0 0" />
      <geometry>
        <box size="0.03 0.1 0.025" />
      </geometry>
    </collision>
    <collision>
      <origin xyz="-0.12 0 0.016" rpy="0 0 0" />
      <geometry>
        <box size="0.05 0.06 0.012" />
      </geometry>
    </collision>
  </link>
  <link name="carriage">
    <inertial>
      <origin xyz="-0.01 -0.07 0.04" rpy="0 0 0" />
      <mass value="1.8" />
      <inertia ixx="0.005295" ixy="0" ixz="0" iyy="0.0039" iyz="0" izz="0.007275" />
    </inertial>
    <visual>
      <geometry>
        <mesh filename="meshes/carriage.glb" />
      </geometry>
      <material name="fixture_carriage" />
    </visual>
    <collision>
      <origin xyz="0 0 0.01" rpy="0 0 0" />
      <geometry>
        <box size="0.12 0.03 0.02" />
      </geometry>
    </collision>
    <collision>
      <origin xyz="0 -0.14 0.01" rpy="0 0 0" />
      <geometry>
        <box size="0.12 0.03 0.02" />
      </geometry>
    </collision>
    <collision>
      <origin xyz="0 -0.07 0.027" rpy="0 0 0" />
      <geometry>
        <box size="0.13 0.12 0.014" />
      </geometry>
    </collision>
    <collision>
      <origin xyz="-0.038 -0.07 0.042" rpy="0 0 0" />
      <geometry>
        <box size="0.04 0.07 0.016" />
      </geometry>
    </collision>
    <collision>
      <origin xyz="-0.012 -0.07 0.055" rpy="0 0 0" />
      <geometry>
        <box size="0.02 0.05 0.01" />
      </geometry>
    </collision>
    <collision>
      <origin xyz="-0.04 -0.045 0.065" rpy="0 0 0" />
      <geometry>
        <box size="0.018 0.014 0.03" />
      </geometry>
    </collision>
    <collision>
      <origin xyz="-0.04 -0.095 0.065" rpy="0 0 0" />
      <geometry>
        <box size="0.018 0.014 0.03" />
      </geometry>
    </collision>
  </link>
  <link name="flap">
    <inertial>
      <origin xyz="-0.055 0 -0.006" rpy="0 0 0" />
      <mass value="0.35" />
      <inertia ixx="0.0002625" ixy="0" ixz="0" iyy="0.00044625" iyz="0" izz="0.00065625" />
    </inertial>
    <visual>
      <geometry>
        <mesh filename="meshes/inspection_flap.glb" />
      </geometry>
      <material name="fixture_flap" />
    </visual>
    <collision>
      <origin xyz="-0.062 0 -0.0105" rpy="0 0 0" />
      <geometry>
        <box size="0.1 0.09 0.005" />
      </geometry>
    </collision>
    <collision>
      <origin xyz="-0.012 0 -0.0085" rpy="0 0 0" />
      <geometry>
        <box size="0.018 0.016 0.004" />
      </geometry>
    </collision>
    <collision>
      <geometry>
        <box size="0.014 0.03 0.014" />
      </geometry>
    </collision>
  </link>
  <joint name="base_to_carriage" type="prismatic">
    <origin xyz="0 0.07 0.045" rpy="0 0 0" />
    <parent link="base" />
    <child link="carriage" />
    <axis xyz="1 0 0" />
    <limit effort="120" velocity="0.25" lower="-0.08" upper="0.095" />
  </joint>
  <joint name="carriage_to_flap" type="revolute">
    <origin xyz="-0.04 -0.07 0.065" rpy="0 0 0" />
    <parent link="carriage" />
    <child link="flap" />
    <axis xyz="0 1 0" />
    <limit effort="10" velocity="1.5" lower="0" upper="1.3" />
  </joint>
</robot>