<robot name="monitor_mount">
  <material name="powder_black">
    <color rgba="0.11 0.11 0.12 1" />
    </material>
  <material name="anodized_aluminum">
    <color rgba="0.67 0.69 0.73 1" />
    </material>
  <material name="satin_steel">
    <color rgba="0.49 0.5 0.53 1" />
    </material>
  <material name="polymer_dark">
    <color rgba="0.18 0.18 0.19 1" />
    </material>
  <material name="accent_red">
    <color rgba="0.72 0.18 0.15 1" />
    </material>
  <link name="desk_clamp">
    <inertial>
      <origin xyz="0.01 0 0.088" rpy="0 0 0" />
      <mass value="3.8" />
      <inertia ixx="0.0666979" ixy="0" ixz="0" iyy="0.0693896" iyz="0" izz="0.00497167" />
      </inertial>
    <visual>
      <origin xyz="0.015 0 0.006" rpy="0 0 0" />
      <geometry>
        <box size="0.1 0.058 0.012" />
        </geometry>
      <material name="powder_black" />
      </visual>
    <visual>
      <origin xyz="-0.028 0 0.015" rpy="0 0 0" />
      <geometry>
        <box size="0.03 0.06 0.03" />
        </geometry>
      <material name="powder_black" />
      </visual>
    <visual>
      <origin xyz="-0.005 0 -0.04" rpy="0 0 0" />
      <geometry>
        <box size="0.055 0.058 0.08" />
        </geometry>
      <material name="powder_black" />
      </visual>
    <visual>
      <origin xyz="-0.028 0 -0.055" rpy="0 0 0" />
      <geometry>
        <box size="0.02 0.058 0.17" />
        </geometry>
      <material name="powder_black" />
      </visual>
    <visual>
      <origin xyz="0.041 0 -0.024" rpy="0 0 0" />
      <geometry>
        <box size="0.012 0.058 0.06" />
        </geometry>
      <material name="powder_black" />
      </visual>
    <visual>
      <origin xyz="0.008 0 -0.055" rpy="0 1.5708 0" />
      <geometry>
        <cylinder radius="0.008" length="0.075" />
        </geometry>
      <material name="satin_steel" />
      </visual>
    <visual>
      <origin xyz="-0.036 0 -0.055" rpy="0 1.5708 0" />
      <geometry>
        <cylinder radius="0.022" length="0.012" />
        </geometry>
      <material name="polymer_dark" />
      </visual>
    <visual>
      <origin xyz="0.047 0 -0.055" rpy="0 1.5708 0" />
      <geometry>
        <cylinder radius="0.015" length="0.008" />
        </geometry>
      <material name="polymer_dark" />
      </visual>
    <visual>
      <origin xyz="-0.028 0 0.04" rpy="0 0 0" />
      <geometry>
        <cylinder radius="0.025" length="0.02" />
        </geometry>
      <material name="powder_black" />
      </visual>
    <visual>
      <origin xyz="-0.028 0 0.1775" rpy="0 0 0" />
      <geometry>
        <cylinder radius="0.016" length="0.275" />
        </geometry>
      <material name="anodized_aluminum" />
      </visual>
    <visual>
      <origin xyz="-0.028 0 0.055" rpy="0 0 0" />
      <geometry>
        <cylinder radius="0.019" length="0.03" />
        </geometry>
      <material name="satin_steel" />
      </visual>
    <visual>
      <origin xyz="0.024 0.018 0.012" rpy="0 0 0" />
      <geometry>
        <cylinder radius="0.006" length="0.008" />
        </geometry>
      <material name="satin_steel" />
      </visual>
    <visual>
      <origin xyz="0.024 -0.018 0.012" rpy="0 0 0" />
      <geometry>
        <cylinder radius="0.006" length="0.008" />
        </geometry>
      <material name="satin_steel" />
      </visual>
    </link>
  <link name="lower_arm">
    <inertial>
      <origin xyz="0.122 0 0.016" rpy="0 0 0" />
      <mass value="1.2" />
      <inertia ixx="0.0003181" ixy="0" ixz="0" iyy="0.0061181" iyz="0" izz="0.006205" />
      </inertial>
    <visual>
      <origin xyz="0 0 0.012" rpy="0 0 0" />
      <geometry>
        <cylinder radius="0.028" length="0.024" />
        </geometry>
      <material name="anodized_aluminum" />
      </visual>
    <visual>
      <origin xyz="0 0 0.026" rpy="0 0 0" />
      <geometry>
        <cylinder radius="0.03" length="0.004" />
        </geometry>
      <material name="accent_red" />
      </visual>
    <visual>
      <origin xyz="0.115 0 0.012" rpy="0 0 0" />
      <geometry>
        <box size="0.19 0.04 0.018" />
        </geometry>
      <material name="anodized_aluminum" />
      </visual>
    <visual>
      <origin xyz="0.115 0 0.0245" rpy="0 0 0" />
      <geometry>
        <box size="0.155 0.034 0.007" />
        </geometry>
      <material name="polymer_dark" />
      </visual>
    <visual>
      <origin xyz="0.115 0 0.0045" rpy="0 0 0" />
      <geometry>
        <box size="0.12 0.022 0.006" />
        </geometry>
      <material name="satin_steel" />
      </visual>
    <visual>
      <origin xyz="0.226 0.017 0.012" rpy="0 0 0" />
      <geometry>
        <box size="0.038 0.008 0.042" />
        </geometry>
      <material name="anodized_aluminum" />
      </visual>
    <visual>
      <origin xyz="0.226 -0.017 0.012" rpy="0 0 0" />
      <geometry>
        <box size="0.038 0.008 0.042" />
        </geometry>
      <material name="anodized_aluminum" />
      </visual>
    <visual>
      <origin xyz="0.226 0 0.012" rpy="1.5708 0 0" />
      <geometry>
        <cylinder radius="0.011" length="0.034" />
        </geometry>
      <material name="satin_steel" />
      </visual>
    <visual>
      <origin xyz="0.07 0 0.028" rpy="0 0 0" />
      <geometry>
        <box size="0.032 0.01 0.01" />
        </geometry>
      <material name="polymer_dark" />
      </visual>
    </link>
  <link name="upper_arm">
    <inertial>
      <origin xyz="0.108 0 0.002" rpy="0 0 0" />
      <mass value="1" />
      <inertia ixx="0.000222" ixy="0" ixz="0" iyy="0.004407" iyz="0" izz="0.004479" />
      </inertial>
    <visual>
      <origin xyz="0 0 0" rpy="1.5708 0 0" />
      <geometry>
        <cylinder radius="0.0105" length="0.026" />
        </geometry>
      <material name="satin_steel" />
      </visual>
    <visual>
      <origin xyz="0.0975 0 0" rpy="0 0 0" />
      <geometry>
        <box size="0.185 0.038 0.017" />
        </geometry>
      <material name="anodized_aluminum" />
      </visual>
    <visual>
      <origin xyz="0.0975 0 0.0115" rpy="0 0 0" />
      <geometry>
        <box size="0.155 0.032 0.007" />
        </geometry>
      <material name="polymer_dark" />
      </visual>
    <visual>
      <origin xyz="0.095 0 -0.008" rpy="0 0 0" />
      <geometry>
        <box size="0.1 0.02 0.005" />
        </geometry>
      <material name="satin_steel" />
      </visual>
    <visual>
      <origin xyz="0.188 0 0" rpy="0 0 0" />
      <geometry>
        <box size="0.03 0.024 0.018" />
        </geometry>
      <material name="anodized_aluminum" />
      </visual>
    <visual>
      <origin xyz="0.205 0 0" rpy="0 0 0" />
      <geometry>
        <cylinder radius="0.022" length="0.022" />
        </geometry>
      <material name="anodized_aluminum" />
      </visual>
    <visual>
      <origin xyz="0.066 0 0.021" rpy="0 0 0" />
      <geometry>
        <box size="0.028 0.01 0.01" />
        </geometry>
      <material name="polymer_dark" />
      </visual>
    </link>
  <link name="head">
    <inertial>
      <origin xyz="0.024 0 0" rpy="0 0 0" />
      <mass value="0.45" />
      <inertia ixx="0.000286875" ixy="0" ixz="0" iyy="0.000475538" iyz="0" izz="0.000340538" />
      </inertial>
    <visual>
      <geometry>
        <cylinder radius="0.02" length="0.022" />
        </geometry>
      <material name="polymer_dark" />
      </visual>
    <visual>
      <origin xyz="0.026 0 0" rpy="0 0 0" />
      <geometry>
        <box size="0.042 0.024 0.018" />
        </geometry>
      <material name="polymer_dark" />
      </visual>
    <visual>
      <origin xyz="0.046 0 0" rpy="0 0 0" />
      <geometry>
        <box size="0.012 0.042 0.018" />
        </geometry>
      <material name="satin_steel" />
      </visual>
    <visual>
      <origin xyz="0.055 0.016 0" rpy="0 0 0" />
      <geometry>
        <box size="0.018 0.01 0.072" />
        </geometry>
      <material name="satin_steel" />
      </visual>
    <visual>
      <origin xyz="0.055 -0.016 0" rpy="0 0 0" />
      <geometry>
        <box size="0.018 0.01 0.072" />
        </geometry>
      <material name="satin_steel" />
      </visual>
    <visual>
      <origin xyz="0.018 0 0.014" rpy="0 0 0" />
      <geometry>
        <box size="0.02 0.03 0.01" />
        </geometry>
      <material name="polymer_dark" />
      </visual>
    </link>
  <link name="vesa_plate">
    <inertial>
      <origin xyz="0.002 0 0" rpy="0 0 0" />
      <mass value="0.55" />
      <inertia ixx="0.00143229" ixy="0" ixz="0" iyy="0.000738329" iyz="0" izz="0.000738329" />
      </inertial>
    <visual>
      <geometry>
        <box size="0.005 0.125 0.125" />
        </geometry>
      <material name="powder_black" />
      </visual>
    <visual>
      <origin xyz="-0.004 0 0" rpy="1.5708 0 0" />
      <geometry>
        <cylinder radius="0.01" length="0.034" />
        </geometry>
      <material name="satin_steel" />
      </visual>
    <visual>
      <origin xyz="0.006 0 0" rpy="0 0 0" />
      <geometry>
        <box size="0.012 0.07 0.012" />
        </geometry>
      <material name="satin_steel" />
      </visual>
    <visual>
      <origin xyz="0.006 0.024 0" rpy="0 0 0" />
      <geometry>
        <box size="0.012 0.012 0.088" />
        </geometry>
      <material name="satin_steel" />
      </visual>
    <visual>
      <origin xyz="0.006 -0.024 0" rpy="0 0 0" />
      <geometry>
        <box size="0.012 0.012 0.088" />
        </geometry>
      <material name="satin_steel" />
      </visual>
    <visual>
      <origin xyz="0.006 -0.0375 -0.0375" rpy="0 1.5708 0" />
      <geometry>
        <cylinder radius="0.006" length="0.01" />
        </geometry>
      <material name="satin_steel" />
      </visual>
    <visual>
      <origin xyz="0.006 -0.0375 0.0375" rpy="0 1.5708 0" />
      <geometry>
        <cylinder radius="0.006" length="0.01" />
        </geometry>
      <material name="satin_steel" />
      </visual>
    <visual>
      <origin xyz="0.006 0.0375 -0.0375" rpy="0 1.5708 0" />
      <geometry>
        <cylinder radius="0.006" length="0.01" />
        </geometry>
      <material name="satin_steel" />
      </visual>
    <visual>
      <origin xyz="0.006 0.0375 0.0375" rpy="0 1.5708 0" />
      <geometry>
        <cylinder radius="0.006" length="0.01" />
        </geometry>
      <material name="satin_steel" />
      </visual>
    </link>
  <joint name="base_to_lower_swivel" type="revolute">
    <origin xyz="-0.028 0 0.318" rpy="0 0 0" />
    <parent link="desk_clamp" />
    <child link="lower_arm" />
    <axis xyz="0 0 1" />
    <limit effort="60" velocity="2" lower="-2.4" upper="2.4" />
    </joint>
  <joint name="lower_to_upper_elbow" type="revolute">
    <origin xyz="0.226 0 0.012" rpy="0 0 0" />
    <parent link="lower_arm" />
    <child link="upper_arm" />
    <axis xyz="0 -1 0" />
    <limit effort="45" velocity="2" lower="0" upper="1.35" />
    </joint>
  <joint name="upper_to_head_yaw" type="revolute">
    <origin xyz="0.205 0 0" rpy="0 0 0" />
    <parent link="upper_arm" />
    <child link="head" />
    <axis xyz="0 0 1" />
    <limit effort="18" velocity="2.5" lower="-1.6" upper="1.6" />
    </joint>
  <joint name="head_to_vesa_tilt" type="revolute">
    <origin xyz="0.055 0 0" rpy="0 0 0" />
    <parent link="head" />
    <child link="vesa_plate" />
    <axis xyz="0 1 0" />
    <limit effort="18" velocity="2.5" lower="-0.65" upper="0.9" />
    </joint>
  </robot>
