<robot name="street_skateboard">
  <link name="deck">
    <inertial>
      <mass value="1.35" />
      <inertia ixx="0.00477281" ixy="0" ixz="0" iyy="0.072045" iyz="0" izz="0.0767278" />
    </inertial>
    <visual>
      <geometry>
        <mesh filename="meshes/skateboard_deck.glb" />
      </geometry>
      <material name="maple_veneer">
        <color rgba="0.72 0.57 0.37 1" />
      </material>
    </visual>
    <collision name="deck__visual_1__hull_001">
      <geometry>
        <mesh filename="meshes/collision/cache/0571cb3152259bb66d71751c__hull_001.obj" />
      </geometry>
    </collision>
    <collision name="deck__visual_1__hull_002">
      <geometry>
        <mesh filename="meshes/collision/cache/0571cb3152259bb66d71751c__hull_002.obj" />
      </geometry>
    </collision>
  </link>
  <link name="grip_tape">
    <inertial>
      <origin xyz="0 0 0.0073" rpy="0 0 0" />
      <mass value="0.1" />
      <inertia ixx="0.000300967" ixy="0" ixz="0" iyy="0.00507013" iyz="0" izz="0.00537083" />
    </inertial>
    <visual>
      <geometry>
        <mesh filename="meshes/skateboard_grip.glb" />
      </geometry>
      <material name="grip_tape">
        <color rgba="0.08 0.08 0.09 1" />
      </material>
    </visual>
    <visual>
      <origin xyz="-0.021 -0.233 0.0073" rpy="0 0 0" />
      <geometry>
        <cylinder radius="0.0031" length="0.0014" />
      </geometry>
      <material name="steel_hardware">
        <color rgba="0.47 0.49 0.52 1" />
      </material>
    </visual>
    <visual>
      <origin xyz="-0.021 -0.197 0.0073" rpy="0 0 0" />
      <geometry>
        <cylinder radius="0.0031" length="0.0014" />
      </geometry>
      <material name="steel_hardware">
        <color rgba="0.47 0.49 0.52 1" />
      </material>
    </visual>
    <visual>
      <origin xyz="0.021 -0.233 0.0073" rpy="0 0 0" />
      <geometry>
        <cylinder radius="0.0031" length="0.0014" />
      </geometry>
      <material name="steel_hardware">
        <color rgba="0.47 0.49 0.52 1" />
      </material>
    </visual>
    <visual>
      <origin xyz="0.021 -0.197 0.0073" rpy="0 0 0" />
      <geometry>
        <cylinder radius="0.0031" length="0.0014" />
      </geometry>
      <material name="steel_hardware">
        <color rgba="0.47 0.49 0.52 1" />
      </material>
    </visual>
    <visual>
      <origin xyz="-0.021 0.197 0.0073" rpy="0 0 0" />
      <geometry>
        <cylinder radius="0.0031" length="0.0014" />
      </geometry>
      <material name="steel_hardware">
        <color rgba="0.47 0.49 0.52 1" />
      </material>
    </visual>
    <visual>
      <origin xyz="-0.021 0.233 0.0073" rpy="0 0 0" />
      <geometry>
        <cylinder radius="0.0031" length="0.0014" />
      </geometry>
      <material name="steel_hardware">
        <color rgba="0.47 0.49 0.52 1" />
      </material>
    </visual>
    <visual>
      <origin xyz="0.021 0.197 0.0073" rpy="0 0 0" />
      <geometry>
        <cylinder radius="0.0031" length="0.0014" />
      </geometry>
      <material name="steel_hardware">
        <color rgba="0.47 0.49 0.52 1" />
      </material>
    </visual>
    <visual>
      <origin xyz="0.021 0.233 0.0073" rpy="0 0 0" />
      <geometry>
        <cylinder radius="0.0031" length="0.0014" />
      </geometry>
      <material name="steel_hardware">
        <color rgba="0.47 0.49 0.52 1" />
      </material>
    </visual>
    <collision name="grip_tape__visual_1__hull_001">
      <geometry>
        <mesh filename="meshes/collision/cache/6a34e05d23a3d5d5e716acd0__hull_001.obj" />
      </geometry>
    </collision>
    <collision name="grip_tape__visual_1__hull_002">
      <geometry>
        <mesh filename="meshes/collision/cache/6a34e05d23a3d5d5e716acd0__hull_002.obj" />
      </geometry>
    </collision>
    <collision name="grip_tape__visual_2">
      <origin xyz="-0.021 -0.233 0.0073" rpy="0 0 0" />
      <geometry>
        <cylinder radius="0.0031" length="0.0014" />
      </geometry>
    </collision>
    <collision name="grip_tape__visual_3">
      <origin xyz="-0.021 -0.197 0.0073" rpy="0 0 0" />
      <geometry>
        <cylinder radius="0.0031" length="0.0014" />
      </geometry>
    </collision>
    <collision name="grip_tape__visual_4">
      <origin xyz="0.021 -0.233 0.0073" rpy="0 0 0" />
      <geometry>
        <cylinder radius="0.0031" length="0.0014" />
      </geometry>
    </collision>
    <collision name="grip_tape__visual_5">
      <origin xyz="0.021 -0.197 0.0073" rpy="0 0 0" />
      <geometry>
        <cylinder radius="0.0031" length="0.0014" />
      </geometry>
    </collision>
    <collision name="grip_tape__visual_6">
      <origin xyz="-0.021 0.197 0.0073" rpy="0 0 0" />
      <geometry>
        <cylinder radius="0.0031" length="0.0014" />
      </geometry>
    </collision>
    <collision name="grip_tape__visual_7">
      <origin xyz="-0.021 0.233 0.0073" rpy="0 0 0" />
      <geometry>
        <cylinder radius="0.0031" length="0.0014" />
      </geometry>
    </collision>
    <collision name="grip_tape__visual_8">
      <origin xyz="0.021 0.197 0.0073" rpy="0 0 0" />
      <geometry>
        <cylinder radius="0.0031" length="0.0014" />
      </geometry>
    </collision>
    <collision name="grip_tape__visual_9">
      <origin xyz="0.021 0.233 0.0073" rpy="0 0 0" />
      <geometry>
        <cylinder radius="0.0031" length="0.0014" />
      </geometry>
    </collision>
  </link>
  <link name="front_baseplate">
    <inertial>
      <origin xyz="0 0 -0.014" rpy="0 0 0" />
      <mass value="0.2" />
      <inertia ixx="6.53333e-05" ixy="0" ixz="0" iyy="0.000114467" iyz="0" izz="0.000153667" />
    </inertial>
    <visual>
      <origin xyz="0 0 -0.0025" rpy="0 0 0" />
      <geometry>
        <box size="0.078 0.056 0.005" />
      </geometry>
      <material name="cast_aluminum">
        <color rgba="0.71 0.73 0.76 1" />
      </material>
    </visual>
    <visual>
      <origin xyz="0 0 -0.0075" rpy="0 0 0" />
      <geometry>
        <box size="0.05 0.032 0.007" />
      </geometry>
      <material name="cast_aluminum">
        <color rgba="0.71 0.73 0.76 1" />
      </material>
    </visual>
    <visual>
      <origin xyz="0 0 -0.01" rpy="0 1.5708 0" />
      <geometry>
        <cylinder radius="0.014" length="0.008" />
      </geometry>
      <material name="urethane_bushing">
        <color rgba="0.84 0.7 0.34 1" />
      </material>
    </visual>
    <visual>
      <origin xyz="0 0 -0.0055" rpy="0 1.5708 0" />
      <geometry>
        <cylinder radius="0.01" length="0.002" />
      </geometry>
      <material name="steel_hardware">
        <color rgba="0.47 0.49 0.52 1" />
      </material>
    </visual>
    <visual>
      <origin xyz="0 0 -0.016" rpy="0 1.5708 0" />
      <geometry>
        <cylinder radius="0.0055" length="0.024" />
      </geometry>
      <material name="steel_hardware">
        <color rgba="0.47 0.49 0.52 1" />
      </material>
    </visual>
    <visual>
      <origin xyz="-0.021 -0.018 -0.0052" rpy="0 0 0" />
      <geometry>
        <cylinder radius="0.0028" length="0.0022" />
      </geometry>
      <material name="steel_hardware">
        <color rgba="0.47 0.49 0.52 1" />
      </material>
    </visual>
    <visual>
      <origin xyz="-0.021 0.018 -0.0052" rpy="0 0 0" />
      <geometry>
        <cylinder radius="0.0028" length="0.0022" />
      </geometry>
      <material name="steel_hardware">
        <color rgba="0.47 0.49 0.52 1" />
      </material>
    </visual>
    <visual>
      <origin xyz="0.021 -0.018 -0.0052" rpy="0 0 0" />
      <geometry>
        <cylinder radius="0.0028" length="0.0022" />
      </geometry>
      <material name="steel_hardware">
        <color rgba="0.47 0.49 0.52 1" />
      </material>
    </visual>
    <visual>
      <origin xyz="0.021 0.018 -0.0052" rpy="0 0 0" />
      <geometry>
        <cylinder radius="0.0028" length="0.0022" />
      </geometry>
      <material name="steel_hardware">
        <color rgba="0.47 0.49 0.52 1" />
      </material>
    </visual>
    <collision name="front_baseplate__visual_1">
      <origin xyz="0 0 -0.0025" rpy="0 0 0" />
      <geometry>
        <box size="0.078 0.056 0.005" />
      </geometry>
    </collision>
    <collision name="front_baseplate__visual_2">
      <origin xyz="0 0 -0.0075" rpy="0 0 0" />
      <geometry>
        <box size="0.05 0.032 0.007" />
      </geometry>
    </collision>
    <collision name="front_baseplate__visual_3">
      <origin xyz="0 0 -0.01" rpy="0 1.5708 0" />
      <geometry>
        <cylinder radius="0.014" length="0.008" />
      </geometry>
    </collision>
    <collision name="front_baseplate__visual_4">
      <origin xyz="0 0 -0.0055" rpy="0 1.5708 0" />
      <geometry>
        <cylinder radius="0.01" length="0.002" />
      </geometry>
    </collision>
    <collision name="front_baseplate__visual_5">
      <origin xyz="0 0 -0.016" rpy="0 1.5708 0" />
      <geometry>
        <cylinder radius="0.0055" length="0.024" />
      </geometry>
    </collision>
    <collision name="front_baseplate__visual_6">
      <origin xyz="-0.021 -0.018 -0.0052" rpy="0 0 0" />
      <geometry>
        <cylinder radius="0.0028" length="0.0022" />
      </geometry>
    </collision>
    <collision name="front_baseplate__visual_7">
      <origin xyz="-0.021 0.018 -0.0052" rpy="0 0 0" />
      <geometry>
        <cylinder radius="0.0028" length="0.0022" />
      </geometry>
    </collision>
    <collision name="front_baseplate__visual_8">
      <origin xyz="0.021 -0.018 -0.0052" rpy="0 0 0" />
      <geometry>
        <cylinder radius="0.0028" length="0.0022" />
      </geometry>
    </collision>
    <collision name="front_baseplate__visual_9">
      <origin xyz="0.021 0.018 -0.0052" rpy="0 0 0" />
      <geometry>
        <cylinder radius="0.0028" length="0.0022" />
      </geometry>
    </collision>
  </link>
  <link name="rear_baseplate">
    <inertial>
      <origin xyz="0 0 -0.014" rpy="0 0 0" />
      <mass value="0.2" />
      <inertia ixx="6.53333e-05" ixy="0" ixz="0" iyy="0.000114467" iyz="0" izz="0.000153667" />
    </inertial>
    <visual>
      <origin xyz="0 0 -0.0025" rpy="0 0 0" />
      <geometry>
        <box size="0.078 0.056 0.005" />
      </geometry>
      <material name="cast_aluminum">
        <color rgba="0.71 0.73 0.76 1" />
      </material>
    </visual>
    <visual>
      <origin xyz="0 0 -0.0075" rpy="0 0 0" />
      <geometry>
        <box size="0.05 0.032 0.007" />
      </geometry>
      <material name="cast_aluminum">
        <color rgba="0.71 0.73 0.76 1" />
      </material>
    </visual>
    <visual>
      <origin xyz="0 0 -0.01" rpy="0 1.5708 0" />
      <geometry>
        <cylinder radius="0.014" length="0.008" />
      </geometry>
      <material name="urethane_bushing">
        <color rgba="0.84 0.7 0.34 1" />
      </material>
    </visual>
    <visual>
      <origin xyz="0 0 -0.0055" rpy="0 1.5708 0" />
      <geometry>
        <cylinder radius="0.01" length="0.002" />
      </geometry>
      <material name="steel_hardware">
        <color rgba="0.47 0.49 0.52 1" />
      </material>
    </visual>
    <visual>
      <origin xyz="0 0 -0.016" rpy="0 1.5708 0" />
      <geometry>
        <cylinder radius="0.0055" length="0.024" />
      </geometry>
      <material name="steel_hardware">
        <color rgba="0.47 0.49 0.52 1" />
      </material>
    </visual>
    <visual>
      <origin xyz="-0.021 -0.018 -0.0052" rpy="0 0 0" />
      <geometry>
        <cylinder radius="0.0028" length="0.0022" />
      </geometry>
      <material name="steel_hardware">
        <color rgba="0.47 0.49 0.52 1" />
      </material>
    </visual>
    <visual>
      <origin xyz="-0.021 0.018 -0.0052" rpy="0 0 0" />
      <geometry>
        <cylinder radius="0.0028" length="0.0022" />
      </geometry>
      <material name="steel_hardware">
        <color rgba="0.47 0.49 0.52 1" />
      </material>
    </visual>
    <visual>
      <origin xyz="0.021 -0.018 -0.0052" rpy="0 0 0" />
      <geometry>
        <cylinder radius="0.0028" length="0.0022" />
      </geometry>
      <material name="steel_hardware">
        <color rgba="0.47 0.49 0.52 1" />
      </material>
    </visual>
    <visual>
      <origin xyz="0.021 0.018 -0.0052" rpy="0 0 0" />
      <geometry>
        <cylinder radius="0.0028" length="0.0022" />
      </geometry>
      <material name="steel_hardware">
        <color rgba="0.47 0.49 0.52 1" />
      </material>
    </visual>
    <collision name="rear_baseplate__visual_1">
      <origin xyz="0 0 -0.0025" rpy="0 0 0" />
      <geometry>
        <box size="0.078 0.056 0.005" />
      </geometry>
    </collision>
    <collision name="rear_baseplate__visual_2">
      <origin xyz="0 0 -0.0075" rpy="0 0 0" />
      <geometry>
        <box size="0.05 0.032 0.007" />
      </geometry>
    </collision>
    <collision name="rear_baseplate__visual_3">
      <origin xyz="0 0 -0.01" rpy="0 1.5708 0" />
      <geometry>
        <cylinder radius="0.014" length="0.008" />
      </geometry>
    </collision>
    <collision name="rear_baseplate__visual_4">
      <origin xyz="0 0 -0.0055" rpy="0 1.5708 0" />
      <geometry>
        <cylinder radius="0.01" length="0.002" />
      </geometry>
    </collision>
    <collision name="rear_baseplate__visual_5">
      <origin xyz="0 0 -0.016" rpy="0 1.5708 0" />
      <geometry>
        <cylinder radius="0.0055" length="0.024" />
      </geometry>
    </collision>
    <collision name="rear_baseplate__visual_6">
      <origin xyz="-0.021 -0.018 -0.0052" rpy="0 0 0" />
      <geometry>
        <cylinder radius="0.0028" length="0.0022" />
      </geometry>
    </collision>
    <collision name="rear_baseplate__visual_7">
      <origin xyz="-0.021 0.018 -0.0052" rpy="0 0 0" />
      <geometry>
        <cylinder radius="0.0028" length="0.0022" />
      </geometry>
    </collision>
    <collision name="rear_baseplate__visual_8">
      <origin xyz="0.021 -0.018 -0.0052" rpy="0 0 0" />
      <geometry>
        <cylinder radius="0.0028" length="0.0022" />
      </geometry>
    </collision>
    <collision name="rear_baseplate__visual_9">
      <origin xyz="0.021 0.018 -0.0052" rpy="0 0 0" />
      <geometry>
        <cylinder radius="0.0028" length="0.0022" />
      </geometry>
    </collision>
  </link>
  <link name="front_hanger">
    <inertial>
      <origin xyz="0 0 -0.024" rpy="0 0 0" />
      <mass value="0.27" />
      <inertia ixx="5.364e-05" ixy="0" ixz="0" iyy="0.00083124" iyz="0" izz="0.00081288" />
    </inertial>
    <visual>
      <origin xyz="0 0 -0.001" rpy="0 0 0" />
      <geometry>
        <cylinder radius="0.0095" length="0.002" />
      </geometry>
      <material name="steel_hardware">
        <color rgba="0.47 0.49 0.52 1" />
      </material>
    </visual>
    <visual>
      <origin xyz="0 0 -0.007" rpy="0 0 0" />
      <geometry>
        <cylinder radius="0.01" length="0.014" />
      </geometry>
      <material name="cast_aluminum">
        <color rgba="0.71 0.73 0.76 1" />
      </material>
    </visual>
    <visual>
      <origin xyz="0 0 -0.018" rpy="0 0 0" />
      <geometry>
        <box size="0.032 0.022 0.025" />
      </geometry>
      <material name="cast_aluminum">
        <color rgba="0.71 0.73 0.76 1" />
      </material>
    </visual>
    <visual>
      <origin xyz="0 0 -0.031" rpy="0 0 0" />
      <geometry>
        <box size="0.094 0.024 0.018" />
      </geometry>
      <material name="cast_aluminum">
        <color rgba="0.71 0.73 0.76 1" />
      </material>
    </visual>
    <visual>
      <origin xyz="0 0 -0.031" rpy="0 1.5708 0" />
      <geometry>
        <cylinder radius="0.006" length="0.188" />
      </geometry>
      <material name="steel_hardware">
        <color rgba="0.47 0.49 0.52 1" />
      </material>
    </visual>
    <collision name="front_hanger__visual_1">
      <origin xyz="0 0 -0.001" rpy="0 0 0" />
      <geometry>
        <cylinder radius="0.0095" length="0.002" />
      </geometry>
    </collision>
    <collision name="front_hanger__visual_2">
      <origin xyz="0 0 -0.007" rpy="0 0 0" />
      <geometry>
        <cylinder radius="0.01" length="0.014" />
      </geometry>
    </collision>
    <collision name="front_hanger__visual_3">
      <origin xyz="0 0 -0.018" rpy="0 0 0" />
      <geometry>
        <box size="0.032 0.022 0.025" />
      </geometry>
    </collision>
    <collision name="front_hanger__visual_4">
      <origin xyz="0 0 -0.031" rpy="0 0 0" />
      <geometry>
        <box size="0.094 0.024 0.018" />
      </geometry>
    </collision>
    <collision name="front_hanger__visual_5">
      <origin xyz="0 0 -0.031" rpy="0 1.5708 0" />
      <geometry>
        <cylinder radius="0.006" length="0.188" />
      </geometry>
    </collision>
  </link>
  <link name="rear_hanger">
    <inertial>
      <origin xyz="0 0 -0.024" rpy="0 0 0" />
      <mass value="0.27" />
      <inertia ixx="5.364e-05" ixy="0" ixz="0" iyy="0.00083124" iyz="0" izz="0.00081288" />
    </inertial>
    <visual>
      <origin xyz="0 0 -0.001" rpy="0 0 0" />
      <geometry>
        <cylinder radius="0.0095" length="0.002" />
      </geometry>
      <material name="steel_hardware">
        <color rgba="0.47 0.49 0.52 1" />
      </material>
    </visual>
    <visual>
      <origin xyz="0 0 -0.007" rpy="0 0 0" />
      <geometry>
        <cylinder radius="0.01" length="0.014" />
      </geometry>
      <material name="cast_aluminum">
        <color rgba="0.71 0.73 0.76 1" />
      </material>
    </visual>
    <visual>
      <origin xyz="0 0 -0.018" rpy="0 0 0" />
      <geometry>
        <box size="0.032 0.022 0.025" />
      </geometry>
      <material name="cast_aluminum">
        <color rgba="0.71 0.73 0.76 1" />
      </material>
    </visual>
    <visual>
      <origin xyz="0 0 -0.031" rpy="0 0 0" />
      <geometry>
        <box size="0.094 0.024 0.018" />
      </geometry>
      <material name="cast_aluminum">
        <color rgba="0.71 0.73 0.76 1" />
      </material>
    </visual>
    <visual>
      <origin xyz="0 0 -0.031" rpy="0 1.5708 0" />
      <geometry>
        <cylinder radius="0.006" length="0.188" />
      </geometry>
      <material name="steel_hardware">
        <color rgba="0.47 0.49 0.52 1" />
      </material>
    </visual>
    <collision name="rear_hanger__visual_1">
      <origin xyz="0 0 -0.001" rpy="0 0 0" />
      <geometry>
        <cylinder radius="0.0095" length="0.002" />
      </geometry>
    </collision>
    <collision name="rear_hanger__visual_2">
      <origin xyz="0 0 -0.007" rpy="0 0 0" />
      <geometry>
        <cylinder radius="0.01" length="0.014" />
      </geometry>
    </collision>
    <collision name="rear_hanger__visual_3">
      <origin xyz="0 0 -0.018" rpy="0 0 0" />
      <geometry>
        <box size="0.032 0.022 0.025" />
      </geometry>
    </collision>
    <collision name="rear_hanger__visual_4">
      <origin xyz="0 0 -0.031" rpy="0 0 0" />
      <geometry>
        <box size="0.094 0.024 0.018" />
      </geometry>
    </collision>
    <collision name="rear_hanger__visual_5">
      <origin xyz="0 0 -0.031" rpy="0 1.5708 0" />
      <geometry>
        <cylinder radius="0.006" length="0.188" />
      </geometry>
    </collision>
  </link>
  <link name="front_left_wheel">
    <inertial>
      <origin xyz="0 0 0" rpy="0 1.5708 0" />
      <mass value="0.2" />
      <inertia ixx="4.77167e-05" ixy="0" ixz="0" iyy="4.77167e-05" iyz="0" izz="7.29e-05" />
    </inertial>
    <visual>
      <origin xyz="0 0 0" rpy="0 1.5708 0" />
      <geometry>
        <mesh filename="meshes/street_wheel.glb" />
      </geometry>
      <material name="wheel_urethane">
        <color rgba="0.94 0.93 0.87 0.98" />
      </material>
    </visual>
    <visual>
      <origin xyz="0 0 0" rpy="0 1.5708 0" />
      <geometry>
        <cylinder radius="0.011" length="0.02" />
      </geometry>
      <material name="wheel_hub">
        <color rgba="0.16 0.16 0.17 1" />
      </material>
    </visual>
    <visual>
      <origin xyz="-0.0115 0 0" rpy="0 1.5708 0" />
      <geometry>
        <cylinder radius="0.008" length="0.003" />
      </geometry>
      <material name="steel_hardware">
        <color rgba="0.47 0.49 0.52 1" />
      </material>
    </visual>
    <visual>
      <origin xyz="0.0115 0 0" rpy="0 1.5708 0" />
      <geometry>
        <cylinder radius="0.008" length="0.003" />
      </geometry>
      <material name="steel_hardware">
        <color rgba="0.47 0.49 0.52 1" />
      </material>
    </visual>
    <collision name="front_left_wheel__visual_1__hull_001">
      <origin xyz="0 0 0" rpy="0 1.5708 0" />
      <geometry>
        <mesh filename="meshes/collision/cache/51ab7d435d5ec58e429100d0__hull_001.obj" />
      </geometry>
    </collision>
    <collision name="front_left_wheel__visual_2">
      <origin xyz="0 0 0" rpy="0 1.5708 0" />
      <geometry>
        <cylinder radius="0.011" length="0.02" />
      </geometry>
    </collision>
    <collision name="front_left_wheel__visual_3">
      <origin xyz="-0.0115 0 0" rpy="0 1.5708 0" />
      <geometry>
        <cylinder radius="0.008" length="0.003" />
      </geometry>
    </collision>
    <collision name="front_left_wheel__visual_4">
      <origin xyz="0.0115 0 0" rpy="0 1.5708 0" />
      <geometry>
        <cylinder radius="0.008" length="0.003" />
      </geometry>
    </collision>
  </link>
  <link name="front_right_wheel">
    <inertial>
      <origin xyz="0 0 0" rpy="0 1.5708 0" />
      <mass value="0.2" />
      <inertia ixx="4.77167e-05" ixy="0" ixz="0" iyy="4.77167e-05" iyz="0" izz="7.29e-05" />
    </inertial>
    <visual>
      <origin xyz="0 0 0" rpy="0 1.5708 0" />
      <geometry>
        <mesh filename="meshes/street_wheel.glb" />
      </geometry>
      <material name="wheel_urethane">
        <color rgba="0.94 0.93 0.87 0.98" />
      </material>
    </visual>
    <visual>
      <origin xyz="0 0 0" rpy="0 1.5708 0" />
      <geometry>
        <cylinder radius="0.011" length="0.02" />
      </geometry>
      <material name="wheel_hub">
        <color rgba="0.16 0.16 0.17 1" />
      </material>
    </visual>
    <visual>
      <origin xyz="-0.0115 0 0" rpy="0 1.5708 0" />
      <geometry>
        <cylinder radius="0.008" length="0.003" />
      </geometry>
      <material name="steel_hardware">
        <color rgba="0.47 0.49 0.52 1" />
      </material>
    </visual>
    <visual>
      <origin xyz="0.0115 0 0" rpy="0 1.5708 0" />
      <geometry>
        <cylinder radius="0.008" length="0.003" />
      </geometry>
      <material name="steel_hardware">
        <color rgba="0.47 0.49 0.52 1" />
      </material>
    </visual>
    <collision name="front_right_wheel__visual_1__hull_001">
      <origin xyz="0 0 0" rpy="0 1.5708 0" />
      <geometry>
        <mesh filename="meshes/collision/cache/51ab7d435d5ec58e429100d0__hull_001.obj" />
      </geometry>
    </collision>
    <collision name="front_right_wheel__visual_2">
      <origin xyz="0 0 0" rpy="0 1.5708 0" />
      <geometry>
        <cylinder radius="0.011" length="0.02" />
      </geometry>
    </collision>
    <collision name="front_right_wheel__visual_3">
      <origin xyz="-0.0115 0 0" rpy="0 1.5708 0" />
      <geometry>
        <cylinder radius="0.008" length="0.003" />
      </geometry>
    </collision>
    <collision name="front_right_wheel__visual_4">
      <origin xyz="0.0115 0 0" rpy="0 1.5708 0" />
      <geometry>
        <cylinder radius="0.008" length="0.003" />
      </geometry>
    </collision>
  </link>
  <link name="rear_left_wheel">
    <inertial>
      <origin xyz="0 0 0" rpy="0 1.5708 0" />
      <mass value="0.2" />
      <inertia ixx="4.77167e-05" ixy="0" ixz="0" iyy="4.77167e-05" iyz="0" izz="7.29e-05" />
    </inertial>
    <visual>
      <origin xyz="0 0 0" rpy="0 1.5708 0" />
      <geometry>
        <mesh filename="meshes/street_wheel.glb" />
      </geometry>
      <material name="wheel_urethane">
        <color rgba="0.94 0.93 0.87 0.98" />
      </material>
    </visual>
    <visual>
      <origin xyz="0 0 0" rpy="0 1.5708 0" />
      <geometry>
        <cylinder radius="0.011" length="0.02" />
      </geometry>
      <material name="wheel_hub">
        <color rgba="0.16 0.16 0.17 1" />
      </material>
    </visual>
    <visual>
      <origin xyz="-0.0115 0 0" rpy="0 1.5708 0" />
      <geometry>
        <cylinder radius="0.008" length="0.003" />
      </geometry>
      <material name="steel_hardware">
        <color rgba="0.47 0.49 0.52 1" />
      </material>
    </visual>
    <visual>
      <origin xyz="0.0115 0 0" rpy="0 1.5708 0" />
      <geometry>
        <cylinder radius="0.008" length="0.003" />
      </geometry>
      <material name="steel_hardware">
        <color rgba="0.47 0.49 0.52 1" />
      </material>
    </visual>
    <collision name="rear_left_wheel__visual_1__hull_001">
      <origin xyz="0 0 0" rpy="0 1.5708 0" />
      <geometry>
        <mesh filename="meshes/collision/cache/51ab7d435d5ec58e429100d0__hull_001.obj" />
      </geometry>
    </collision>
    <collision name="rear_left_wheel__visual_2">
      <origin xyz="0 0 0" rpy="0 1.5708 0" />
      <geometry>
        <cylinder radius="0.011" length="0.02" />
      </geometry>
    </collision>
    <collision name="rear_left_wheel__visual_3">
      <origin xyz="-0.0115 0 0" rpy="0 1.5708 0" />
      <geometry>
        <cylinder radius="0.008" length="0.003" />
      </geometry>
    </collision>
    <collision name="rear_left_wheel__visual_4">
      <origin xyz="0.0115 0 0" rpy="0 1.5708 0" />
      <geometry>
        <cylinder radius="0.008" length="0.003" />
      </geometry>
    </collision>
  </link>
  <link name="rear_right_wheel">
    <inertial>
      <origin xyz="0 0 0" rpy="0 1.5708 0" />
      <mass value="0.2" />
      <inertia ixx="4.77167e-05" ixy="0" ixz="0" iyy="4.77167e-05" iyz="0" izz="7.29e-05" />
    </inertial>
    <visual>
      <origin xyz="0 0 0" rpy="0 1.5708 0" />
      <geometry>
        <mesh filename="meshes/street_wheel.glb" />
      </geometry>
      <material name="wheel_urethane">
        <color rgba="0.94 0.93 0.87 0.98" />
      </material>
    </visual>
    <visual>
      <origin xyz="0 0 0" rpy="0 1.5708 0" />
      <geometry>
        <cylinder radius="0.011" length="0.02" />
      </geometry>
      <material name="wheel_hub">
        <color rgba="0.16 0.16 0.17 1" />
      </material>
    </visual>
    <visual>
      <origin xyz="-0.0115 0 0" rpy="0 1.5708 0" />
      <geometry>
        <cylinder radius="0.008" length="0.003" />
      </geometry>
      <material name="steel_hardware">
        <color rgba="0.47 0.49 0.52 1" />
      </material>
    </visual>
    <visual>
      <origin xyz="0.0115 0 0" rpy="0 1.5708 0" />
      <geometry>
        <cylinder radius="0.008" length="0.003" />
      </geometry>
      <material name="steel_hardware">
        <color rgba="0.47 0.49 0.52 1" />
      </material>
    </visual>
    <collision name="rear_right_wheel__visual_1__hull_001">
      <origin xyz="0 0 0" rpy="0 1.5708 0" />
      <geometry>
        <mesh filename="meshes/collision/cache/51ab7d435d5ec58e429100d0__hull_001.obj" />
      </geometry>
    </collision>
    <collision name="rear_right_wheel__visual_2">
      <origin xyz="0 0 0" rpy="0 1.5708 0" />
      <geometry>
        <cylinder radius="0.011" length="0.02" />
      </geometry>
    </collision>
    <collision name="rear_right_wheel__visual_3">
      <origin xyz="-0.0115 0 0" rpy="0 1.5708 0" />
      <geometry>
        <cylinder radius="0.008" length="0.003" />
      </geometry>
    </collision>
    <collision name="rear_right_wheel__visual_4">
      <origin xyz="0.0115 0 0" rpy="0 1.5708 0" />
      <geometry>
        <cylinder radius="0.008" length="0.003" />
      </geometry>
    </collision>
  </link>
  <joint name="deck_to_grip" type="fixed">
    <parent link="deck" />
    <child link="grip_tape" />
  </joint>
  <joint name="deck_to_front_baseplate" type="fixed">
    <origin xyz="0 0.215 -0.0068" rpy="0 0 0" />
    <parent link="deck" />
    <child link="front_baseplate" />
  </joint>
  <joint name="deck_to_rear_baseplate" type="fixed">
    <origin xyz="0 -0.215 -0.0068" rpy="0 0 0" />
    <parent link="deck" />
    <child link="rear_baseplate" />
  </joint>
  <joint name="front_truck_steer" type="revolute">
    <origin xyz="0 0 -0.01" rpy="0 0 0" />
    <parent link="front_baseplate" />
    <child link="front_hanger" />
    <axis xyz="0.28 0 0.96" />
    <limit effort="24" velocity="6" lower="-0.38" upper="0.38" />
  </joint>
  <joint name="rear_truck_steer" type="revolute">
    <origin xyz="0 0 -0.01" rpy="0 0 0" />
    <parent link="rear_baseplate" />
    <child link="rear_hanger" />
    <axis xyz="0.28 0 0.96" />
    <limit effort="24" velocity="6" lower="-0.38" upper="0.38" />
  </joint>
  <joint name="front_left_wheel_spin" type="continuous">
    <origin xyz="0.103 0 -0.031" rpy="0 0 0" />
    <parent link="front_hanger" />
    <child link="front_left_wheel" />
    <axis xyz="1 0 0" />
    <limit effort="8" velocity="40" />
  </joint>
  <joint name="front_right_wheel_spin" type="continuous">
    <origin xyz="-0.103 0 -0.031" rpy="0 0 0" />
    <parent link="front_hanger" />
    <child link="front_right_wheel" />
    <axis xyz="1 0 0" />
    <limit effort="8" velocity="40" />
  </joint>
  <joint name="rear_left_wheel_spin" type="continuous">
    <origin xyz="0.103 0 -0.031" rpy="0 0 0" />
    <parent link="rear_hanger" />
    <child link="rear_left_wheel" />
    <axis xyz="1 0 0" />
    <limit effort="8" velocity="40" />
  </joint>
  <joint name="rear_right_wheel_spin" type="continuous">
    <origin xyz="-0.103 0 -0.031" rpy="0 0 0" />
    <parent link="rear_hanger" />
    <child link="rear_right_wheel" />
    <axis xyz="1 0 0" />
    <limit effort="8" velocity="40" />
  </joint>
</robot>