<robot name="enthusiast_motherboard">
  <material name="pcb">
    <color rgba="0.07 0.16 0.1 1" />
    </material>
  <material name="silkscreen">
    <color rgba="0.83 0.86 0.88 1" />
    </material>
  <material name="slot_black">
    <color rgba="0.12 0.12 0.13 1" />
    </material>
  <material name="socket_black">
    <color rgba="0.11 0.11 0.12 1" />
    </material>
  <material name="charcoal">
    <color rgba="0.18 0.19 0.21 1" />
    </material>
  <material name="steel">
    <color rgba="0.69 0.71 0.74 1" />
    </material>
  <material name="heatsink_dark">
    <color rgba="0.23 0.25 0.28 1" />
    </material>
  <material name="anodized_gray">
    <color rgba="0.36 0.38 0.42 1" />
    </material>
  <material name="accent_blue">
    <color rgba="0.2 0.42 0.74 1" />
    </material>
  <material name="gold">
    <color rgba="0.78 0.65 0.24 1" />
    </material>
  <material name="port_black">
    <color rgba="0.05 0.05 0.06 1" />
    </material>
  <link name="motherboard_base">
    <inertial>
      <origin xyz="0 0 0.02" rpy="0 0 0" />
      <mass value="1.55" />
      <inertia ixx="0.00789673" ixy="0" ixz="0" iyy="0.0122224" iyz="0" izz="0.0197058" />
      </inertial>
    <visual>
      <geometry>
        <mesh filename="assets/meshes/motherboard_pcb.obj" />
        </geometry>
      <material name="pcb" />
      </visual>
    <visual>
      <origin xyz="-0.136 0.083 0.002" rpy="0 0 0" />
      <geometry>
        <mesh filename="assets/meshes/rear_io_shroud.obj" />
        </geometry>
      <material name="anodized_gray" />
      </visual>
    <visual>
      <origin xyz="-0.04 0.096 0.002" rpy="0 0 0" />
      <geometry>
        <mesh filename="assets/meshes/vrm_sink_top.obj" />
        </geometry>
      <material name="heatsink_dark" />
      </visual>
    <visual>
      <origin xyz="-0.084 0.046 0.002" rpy="0 0 1.5708" />
      <geometry>
        <mesh filename="assets/meshes/vrm_sink_left.obj" />
        </geometry>
      <material name="heatsink_dark" />
      </visual>
    <visual>
      <origin xyz="0.07 -0.057 0.002" rpy="0 0 0" />
      <geometry>
        <mesh filename="assets/meshes/chipset_shroud.obj" />
        </geometry>
      <material name="anodized_gray" />
      </visual>
    <visual>
      <origin xyz="0.028 -0.009 0.006" rpy="0 0 0" />
      <geometry>
        <box size="0.088 0.018 0.008" />
        </geometry>
      <material name="anodized_gray" />
      </visual>
    <visual>
      <origin xyz="0.022 -0.056 0.008" rpy="0 0 0" />
      <geometry>
        <box size="0.136 0.008 0.012" />
        </geometry>
      <material name="slot_black" />
      </visual>
    <visual>
      <origin xyz="-0.055 -0.031 0.008" rpy="0 0 0" />
      <geometry>
        <box size="0.032 0.008 0.012" />
        </geometry>
      <material name="slot_black" />
      </visual>
    <visual>
      <origin xyz="-0.055 -0.082 0.008" rpy="0 0 0" />
      <geometry>
        <box size="0.032 0.008 0.012" />
        </geometry>
      <material name="slot_black" />
      </visual>
    <visual>
      <origin xyz="0.01 -0.097 0.008" rpy="0 0 0" />
      <geometry>
        <box size="0.114 0.008 0.012" />
        </geometry>
      <material name="slot_black" />
      </visual>
    <visual>
      <origin xyz="0.02 -0.056 0.00255" rpy="0 0 0" />
      <geometry>
        <box size="0.118 0.0016 0.0011" />
        </geometry>
      <material name="gold" />
      </visual>
    <visual>
      <origin xyz="-0.055 -0.031 0.00255" rpy="0 0 0" />
      <geometry>
        <box size="0.024 0.0016 0.0011" />
        </geometry>
      <material name="gold" />
      </visual>
    <visual>
      <origin xyz="-0.055 -0.082 0.00255" rpy="0 0 0" />
      <geometry>
        <box size="0.024 0.0016 0.0011" />
        </geometry>
      <material name="gold" />
      </visual>
    <visual>
      <origin xyz="0.006 -0.097 0.00255" rpy="0 0 0" />
      <geometry>
        <box size="0.096 0.0016 0.0011" />
        </geometry>
      <material name="gold" />
      </visual>
    <visual>
      <origin xyz="0.093 -0.056 0.0095" rpy="0 0 0" />
      <geometry>
        <box size="0.01 0.012 0.015" />
        </geometry>
      <material name="charcoal" />
      </visual>
    <visual>
      <origin xyz="0.14 0.051 0.013" rpy="0 0 0" />
      <geometry>
        <box size="0.012 0.053 0.022" />
        </geometry>
      <material name="slot_black" />
      </visual>
    <visual>
      <origin xyz="0.095 0.111 0.011" rpy="0 0 0" />
      <geometry>
        <box size="0.024 0.012 0.018" />
        </geometry>
      <material name="slot_black" />
      </visual>
    <visual>
      <origin xyz="0.128 -0.079 0.0085" rpy="0 0 0" />
      <geometry>
        <box size="0.02 0.012 0.013" />
        </geometry>
      <material name="slot_black" />
      </visual>
    <visual>
      <origin xyz="0.128 -0.065 0.0085" rpy="0 0 0" />
      <geometry>
        <box size="0.02 0.012 0.013" />
        </geometry>
      <material name="slot_black" />
      </visual>
    <visual>
      <origin xyz="0.123 -0.111 0.007" rpy="0 0 0" />
      <geometry>
        <box size="0.02 0.008 0.01" />
        </geometry>
      <material name="slot_black" />
      </visual>
    <visual>
      <origin xyz="0.09 -0.111 0.007" rpy="0 0 0" />
      <geometry>
        <box size="0.02 0.008 0.01" />
        </geometry>
      <material name="slot_black" />
      </visual>
    <visual>
      <origin xyz="-0.077 0.082 0.006" rpy="0 0 0" />
      <geometry>
        <box size="0.009 0.01 0.008" />
        </geometry>
      <material name="charcoal" />
      </visual>
    <visual>
      <origin xyz="-0.059 0.082 0.006" rpy="0 0 0" />
      <geometry>
        <box size="0.009 0.01 0.008" />
        </geometry>
      <material name="charcoal" />
      </visual>
    <visual>
      <origin xyz="-0.041 0.082 0.006" rpy="0 0 0" />
      <geometry>
        <box size="0.009 0.01 0.008" />
        </geometry>
      <material name="charcoal" />
      </visual>
    <visual>
      <origin xyz="-0.023 0.082 0.006" rpy="0 0 0" />
      <geometry>
        <box size="0.009 0.01 0.008" />
        </geometry>
      <material name="charcoal" />
      </visual>
    <visual>
      <origin xyz="-0.005 0.082 0.006" rpy="0 0 0" />
      <geometry>
        <box size="0.009 0.01 0.008" />
        </geometry>
      <material name="charcoal" />
      </visual>
    <visual>
      <origin xyz="0.013 0.082 0.006" rpy="0 0 0" />
      <geometry>
        <box size="0.009 0.01 0.008" />
        </geometry>
      <material name="charcoal" />
      </visual>
    <visual>
      <origin xyz="-0.063 0.014 0.006" rpy="0 0 0" />
      <geometry>
        <box size="0.01 0.009 0.008" />
        </geometry>
      <material name="charcoal" />
      </visual>
    <visual>
      <origin xyz="-0.063 0.027 0.006" rpy="0 0 0" />
      <geometry>
        <box size="0.01 0.009 0.008" />
        </geometry>
      <material name="charcoal" />
      </visual>
    <visual>
      <origin xyz="-0.063 0.04 0.006" rpy="0 0 0" />
      <geometry>
        <box size="0.01 0.009 0.008" />
        </geometry>
      <material name="charcoal" />
      </visual>
    <visual>
      <origin xyz="-0.063 0.053 0.006" rpy="0 0 0" />
      <geometry>
        <box size="0.01 0.009 0.008" />
        </geometry>
      <material name="charcoal" />
      </visual>
    <visual>
      <origin xyz="-0.063 0.066 0.006" rpy="0 0 0" />
      <geometry>
        <box size="0.01 0.009 0.008" />
        </geometry>
      <material name="charcoal" />
      </visual>
    <visual>
      <origin xyz="-0.103 0.097 0.0075" rpy="0 0 0" />
      <geometry>
        <cylinder radius="0.0034" length="0.011" />
        </geometry>
      <material name="slot_black" />
      </visual>
    <visual>
      <origin xyz="-0.09 0.097 0.0075" rpy="0 0 0" />
      <geometry>
        <cylinder radius="0.0034" length="0.011" />
        </geometry>
      <material name="slot_black" />
      </visual>
    <visual>
      <origin xyz="-0.077 0.097 0.0075" rpy="0 0 0" />
      <geometry>
        <cylinder radius="0.0034" length="0.011" />
        </geometry>
      <material name="slot_black" />
      </visual>
    <visual>
      <origin xyz="-0.103 0.081 0.0075" rpy="0 0 0" />
      <geometry>
        <cylinder radius="0.0034" length="0.011" />
        </geometry>
      <material name="slot_black" />
      </visual>
    <visual>
      <origin xyz="-0.118 -0.08 0.007" rpy="0 0 0" />
      <geometry>
        <cylinder radius="0.004" length="0.01" />
        </geometry>
      <material name="slot_black" />
      </visual>
    <visual>
      <origin xyz="-0.107 -0.087 0.007" rpy="0 0 0" />
      <geometry>
        <cylinder radius="0.0036" length="0.01" />
        </geometry>
      <material name="slot_black" />
      </visual>
    <visual>
      <origin xyz="-0.096 -0.094 0.007" rpy="0 0 0" />
      <geometry>
        <cylinder radius="0.0034" length="0.01" />
        </geometry>
      <material name="slot_black" />
      </visual>
    <visual>
      <origin xyz="-0.086 -0.101 0.007" rpy="0 0 0" />
      <geometry>
        <cylinder radius="0.0032" length="0.01" />
        </geometry>
      <material name="slot_black" />
      </visual>
    <visual>
      <origin xyz="-0.075 -0.108 0.007" rpy="0 0 0" />
      <geometry>
        <cylinder radius="0.003" length="0.01" />
        </geometry>
      <material name="slot_black" />
      </visual>
    <visual>
      <origin xyz="-0.109 -0.086 0.0025" rpy="0 0 0" />
      <geometry>
        <box size="0.014 0.06 0.001" />
        </geometry>
      <material name="silkscreen" />
      </visual>
    <visual>
      <origin xyz="0.077 -0.042 0.0175" rpy="0 0 0" />
      <geometry>
        <box size="0.03 0.004 0.001" />
        </geometry>
      <material name="accent_blue" />
      </visual>
    <visual>
      <origin xyz="0.028 -0.009 0.0104" rpy="0 0 0" />
      <geometry>
        <box size="0.05 0.0032 0.0008" />
        </geometry>
      <material name="accent_blue" />
      </visual>
    <visual>
      <origin xyz="-0.125 0.083 0.0365" rpy="0 0 0" />
      <geometry>
        <box size="0.018 0.074 0.001" />
        </geometry>
      <material name="accent_blue" />
      </visual>
    <visual>
      <origin xyz="-0.146 0.104 0.011" rpy="0 0 0" />
      <geometry>
        <box size="0.01 0.014 0.007" />
        </geometry>
      <material name="steel" />
      </visual>
    <visual>
      <origin xyz="-0.146 0.088 0.011" rpy="0 0 0" />
      <geometry>
        <box size="0.01 0.014 0.007" />
        </geometry>
      <material name="steel" />
      </visual>
    <visual>
      <origin xyz="-0.146 0.069 0.013" rpy="0 0 0" />
      <geometry>
        <box size="0.011 0.016 0.011" />
        </geometry>
      <material name="steel" />
      </visual>
    <visual>
      <origin xyz="-0.146 0.049 0.011" rpy="0 0 0" />
      <geometry>
        <box size="0.009 0.026 0.007" />
        </geometry>
      <material name="port_black" />
      </visual>
    </link>
  <link name="cpu_socket_frame">
    <inertial>
      <origin xyz="0 0 0.004" rpy="0 0 0" />
      <mass value="0.12" />
      <inertia ixx="4.16e-05" ixy="0" ixz="0" iyy="4.16e-05" iyz="0" izz="8.192e-05" />
      </inertial>
    <visual>
      <origin xyz="0 0 0.003" rpy="0 0 0" />
      <geometry>
        <box size="0.057 0.057 0.006" />
        </geometry>
      <material name="socket_black" />
      </visual>
    <visual>
      <origin xyz="0 0 0.0063" rpy="0 0 0" />
      <geometry>
        <box size="0.038 0.038 0.0008" />
        </geometry>
      <material name="charcoal" />
      </visual>
    <visual>
      <origin xyz="0 0 0.0057" rpy="0 0 0" />
      <geometry>
        <mesh filename="assets/meshes/cpu_socket_load_plate.obj" />
        </geometry>
      <material name="steel" />
      </visual>
    </link>
  <link name="dimm_bank">
    <inertial>
      <origin xyz="0 0 0.0085" rpy="0 0 0" />
      <mass value="0.1" />
      <inertia ixx="0.000189908" ixy="0" ixz="0" iyy="2.76167e-05" iyz="0" izz="0.000212708" />
      </inertial>
    <visual>
      <origin xyz="-0.01725 0 0.0045" rpy="0 0 0" />
      <geometry>
        <box size="0.0065 0.133 0.009" />
        </geometry>
      <material name="slot_black" />
      </visual>
    <visual>
      <origin xyz="-0.01725 0 0.0006" rpy="0 0 0" />
      <geometry>
        <box size="0.003 0.12635 0.0012" />
        </geometry>
      <material name="gold" />
      </visual>
    <visual>
      <origin xyz="-0.01725 -0.0645 0.0075" rpy="0 0 0" />
      <geometry>
        <box size="0.009 0.004 0.015" />
        </geometry>
      <material name="charcoal" />
      </visual>
    <visual>
      <origin xyz="-0.01725 0.0625 0.005" rpy="0 0 0" />
      <geometry>
        <box size="0.006 0.002 0.01" />
        </geometry>
      <material name="charcoal" />
      </visual>
    <visual>
      <origin xyz="-0.00575 0 0.0045" rpy="0 0 0" />
      <geometry>
        <box size="0.0065 0.133 0.009" />
        </geometry>
      <material name="slot_black" />
      </visual>
    <visual>
      <origin xyz="-0.00575 0 0.0006" rpy="0 0 0" />
      <geometry>
        <box size="0.003 0.12635 0.0012" />
        </geometry>
      <material name="gold" />
      </visual>
    <visual>
      <origin xyz="-0.00575 -0.0645 0.0075" rpy="0 0 0" />
      <geometry>
        <box size="0.009 0.004 0.015" />
        </geometry>
      <material name="charcoal" />
      </visual>
    <visual>
      <origin xyz="-0.00575 0.0645 0.0075" rpy="0 0 0" />
      <geometry>
        <box size="0.009 0.004 0.015" />
        </geometry>
      <material name="charcoal" />
      </visual>
    <visual>
      <origin xyz="0.00575 0 0.0045" rpy="0 0 0" />
      <geometry>
        <box size="0.0065 0.133 0.009" />
        </geometry>
      <material name="slot_black" />
      </visual>
    <visual>
      <origin xyz="0.00575 0 0.0006" rpy="0 0 0" />
      <geometry>
        <box size="0.003 0.12635 0.0012" />
        </geometry>
      <material name="gold" />
      </visual>
    <visual>
      <origin xyz="0.00575 -0.0645 0.0075" rpy="0 0 0" />
      <geometry>
        <box size="0.009 0.004 0.015" />
        </geometry>
      <material name="charcoal" />
      </visual>
    <visual>
      <origin xyz="0.00575 0.0645 0.0075" rpy="0 0 0" />
      <geometry>
        <box size="0.009 0.004 0.015" />
        </geometry>
      <material name="charcoal" />
      </visual>
    <visual>
      <origin xyz="0.01725 0 0.0045" rpy="0 0 0" />
      <geometry>
        <box size="0.0065 0.133 0.009" />
        </geometry>
      <material name="slot_black" />
      </visual>
    <visual>
      <origin xyz="0.01725 0 0.0006" rpy="0 0 0" />
      <geometry>
        <box size="0.003 0.12635 0.0012" />
        </geometry>
      <material name="gold" />
      </visual>
    <visual>
      <origin xyz="0.01725 -0.0645 0.0075" rpy="0 0 0" />
      <geometry>
        <box size="0.009 0.004 0.015" />
        </geometry>
      <material name="charcoal" />
      </visual>
    <visual>
      <origin xyz="0.01725 0.0645 0.0075" rpy="0 0 0" />
      <geometry>
        <box size="0.009 0.004 0.015" />
        </geometry>
      <material name="charcoal" />
      </visual>
    <visual>
      <origin xyz="0 -0.074 0.0015" rpy="0 0 0" />
      <geometry>
        <box size="0.058 0.006 0.003" />
        </geometry>
      <material name="accent_blue" />
      </visual>
    </link>
  <link name="cpu_retention_arm">
    <inertial>
      <origin xyz="0.015 0 0.011" rpy="0 0 0" />
      <mass value="0.014" />
      <inertia ixx="6.39333e-07" ixy="0" ixz="0" iyy="1.61467e-06" iyz="0" izz="1.12467e-06" />
      </inertial>
    <visual>
      <origin xyz="0.008 0 0.0013" rpy="0 1.5708 0" />
      <geometry>
        <cylinder radius="0.0011" length="0.013" />
        </geometry>
      <material name="steel" />
      </visual>
    <visual>
      <origin xyz="0.0145 0 0.007" rpy="0 0 0" />
      <geometry>
        <cylinder radius="0.0011" length="0.01" />
        </geometry>
      <material name="steel" />
      </visual>
    <visual>
      <origin xyz="0.0145 0 0.0121" rpy="0 0 0" />
      <geometry>
        <box size="0.0038 0.0028 0.0028" />
        </geometry>
      <material name="steel" />
      </visual>
    <visual>
      <origin xyz="0.0185 0 0.0152" rpy="0 0 0" />
      <geometry>
        <box size="0.0052 0.003 0.0012" />
        </geometry>
      <material name="steel" />
      </visual>
    <visual>
      <origin xyz="0.0195 0 0.0128" rpy="0 0 0" />
      <geometry>
        <box size="0.0035 0.0035 0.0048" />
        </geometry>
      <material name="steel" />
      </visual>
    <visual>
      <origin xyz="0.0015 0 0.0016" rpy="0 0 0" />
      <geometry>
        <box size="0.0055 0.004 0.002" />
        </geometry>
      <material name="steel" />
      </visual>
    <visual>
      <origin xyz="0 0 0.003" rpy="0 0 0" />
      <geometry>
        <cylinder radius="0.0016" length="0.006" />
        </geometry>
      <material name="steel" />
      </visual>
    </link>
  <link name="dimm_slot_latch">
    <inertial>
      <origin xyz="0 0.004 0.01" rpy="0 0 0" />
      <mass value="0.006" />
      <inertia ixx="2.5e-07" ixy="0" ixz="0" iyy="2.5e-07" iyz="0" izz="1e-07" />
      </inertial>
    <visual>
      <geometry>
        <mesh filename="assets/meshes/dimm_slot_latch.obj" />
        </geometry>
      <material name="charcoal" />
      </visual>
    </link>
  <joint name="base_to_cpu_socket" type="fixed">
    <origin xyz="-0.032 0.04 0.002" rpy="0 0 0" />
    <parent link="motherboard_base" />
    <child link="cpu_socket_frame" />
    </joint>
  <joint name="base_to_dimm_bank" type="fixed">
    <origin xyz="0.046 0.02 0.002" rpy="0 0 0" />
    <parent link="motherboard_base" />
    <child link="dimm_bank" />
    </joint>
  <joint name="cpu_retention_arm_joint" type="revolute">
    <origin xyz="0.031 0 0.0073" rpy="0 0 0" />
    <parent link="cpu_socket_frame" />
    <child link="cpu_retention_arm" />
    <axis xyz="0 -1 0" />
    <limit effort="1.5" velocity="2" lower="0" upper="1.35" />
    </joint>
  <joint name="dimm_latch_joint" type="revolute">
    <origin xyz="-0.01725 0.0675 0.0055" rpy="0 0 0" />
    <parent link="dimm_bank" />
    <child link="dimm_slot_latch" />
    <axis xyz="1 0 0" />
    <limit effort="0.5" velocity="3" lower="0" upper="1.05" />
    </joint>
  </robot>
