<robot name="two_stage_telescoping_storage_drawer">
  <material name="outer_body">
    <color rgba="0.18 0.2 0.22 1" />
    </material>
  <material name="middle_body">
    <color rgba="0.67 0.69 0.72 1" />
    </material>
  <material name="inner_body">
    <color rgba="0.8 0.82 0.85 1" />
    </material>
  <material name="runner_dark">
    <color rgba="0.1 0.11 0.13 1" />
    </material>
  <material name="grip_outer">
    <color rgba="0.42 0.46 0.52 1" />
    </material>
  <material name="grip_middle">
    <color rgba="0.18 0.45 0.7 1" />
    </material>
  <material name="grip_inner">
    <color rgba="0.83 0.48 0.18 1" />
    </material>
  <link name="outer_tray">
    <inertial>
      <origin xyz="0.172 0 0.04" rpy="0 0 0" />
      <mass value="1.5" />
      <inertia ixx="0.008" ixy="0" ixz="0" iyy="0.015592" iyz="0" izz="0.021992" />
      </inertial>
    <visual>
      <origin xyz="0.17 0 0.002" rpy="0 0 0" />
      <geometry>
        <box size="0.34 0.24 0.004" />
        </geometry>
      <material name="outer_body" />
      </visual>
    <visual>
      <origin xyz="0.17 0.118 0.042" rpy="0 0 0" />
      <geometry>
        <box size="0.34 0.004 0.076" />
        </geometry>
      <material name="outer_body" />
      </visual>
    <visual>
      <origin xyz="0.17 -0.118 0.042" rpy="0 0 0" />
      <geometry>
        <box size="0.34 0.004 0.076" />
        </geometry>
      <material name="outer_body" />
      </visual>
    <visual>
      <origin xyz="0.002 0 0.042" rpy="0 0 0" />
      <geometry>
        <box size="0.004 0.232 0.076" />
        </geometry>
      <material name="outer_body" />
      </visual>
    <visual>
      <origin xyz="0.338 0 0.077" rpy="0 0 0" />
      <geometry>
        <box size="0.004 0.232 0.006" />
        </geometry>
      <material name="outer_body" />
      </visual>
    <visual>
      <origin xyz="0.342 0 0.077" rpy="0 0 0" />
      <geometry>
        <box size="0.004 0.1536 0.024" />
        </geometry>
      <material name="grip_outer" />
      </visual>
    <visual>
      <origin xyz="0.17 0.1145 0.017" rpy="0 0 0" />
      <geometry>
        <box size="0.24 0.003 0.01" />
        </geometry>
      <material name="runner_dark" />
      </visual>
    <visual>
      <origin xyz="0.17 -0.1145 0.017" rpy="0 0 0" />
      <geometry>
        <box size="0.24 0.003 0.01" />
        </geometry>
      <material name="runner_dark" />
      </visual>
    <collision name="outer_tray__visual_1">
      <origin xyz="0.17 0 0.002" rpy="0 0 0" />
      <geometry>
        <box size="0.34 0.24 0.004" />
        </geometry>
      </collision>
    <collision name="outer_tray__visual_2">
      <origin xyz="0.17 0.118 0.042" rpy="0 0 0" />
      <geometry>
        <box size="0.34 0.004 0.076" />
        </geometry>
      </collision>
    <collision name="outer_tray__visual_3">
      <origin xyz="0.17 -0.118 0.042" rpy="0 0 0" />
      <geometry>
        <box size="0.34 0.004 0.076" />
        </geometry>
      </collision>
    <collision name="outer_tray__visual_4">
      <origin xyz="0.002 0 0.042" rpy="0 0 0" />
      <geometry>
        <box size="0.004 0.232 0.076" />
        </geometry>
      </collision>
    <collision name="outer_tray__visual_5">
      <origin xyz="0.338 0 0.077" rpy="0 0 0" />
      <geometry>
        <box size="0.004 0.232 0.006" />
        </geometry>
      </collision>
    <collision name="outer_tray__visual_6">
      <origin xyz="0.342 0 0.077" rpy="0 0 0" />
      <geometry>
        <box size="0.004 0.1536 0.024" />
        </geometry>
      </collision>
    <collision name="outer_tray__visual_7">
      <origin xyz="0.17 0.1145 0.017" rpy="0 0 0" />
      <geometry>
        <box size="0.24 0.003 0.01" />
        </geometry>
      </collision>
    <collision name="outer_tray__visual_8">
      <origin xyz="0.17 -0.1145 0.017" rpy="0 0 0" />
      <geometry>
        <box size="0.24 0.003 0.01" />
        </geometry>
      </collision>
    </link>
  <link name="middle_tray">
    <inertial>
      <origin xyz="0.148 0 0.033" rpy="0 0 0" />
      <mass value="0.95" />
      <inertia ixx="0.00410717" ixy="0" ixz="0" iyy="0.00728112" iyz="0" izz="0.0106986" />
      </inertial>
    <visual>
      <origin xyz="0.145 0 0.002" rpy="0 0 0" />
      <geometry>
        <box size="0.29 0.212 0.004" />
        </geometry>
      <material name="middle_body" />
      </visual>
    <visual>
      <origin xyz="0.145 0.104 0.035" rpy="0 0 0" />
      <geometry>
        <box size="0.29 0.004 0.062" />
        </geometry>
      <material name="middle_body" />
      </visual>
    <visual>
      <origin xyz="0.145 -0.104 0.035" rpy="0 0 0" />
      <geometry>
        <box size="0.29 0.004 0.062" />
        </geometry>
      <material name="middle_body" />
      </visual>
    <visual>
      <origin xyz="0.002 0 0.035" rpy="0 0 0" />
      <geometry>
        <box size="0.004 0.204 0.062" />
        </geometry>
      <material name="middle_body" />
      </visual>
    <visual>
      <origin xyz="0.288 0 0.064" rpy="0 0 0" />
      <geometry>
        <box size="0.004 0.204 0.004" />
        </geometry>
      <material name="middle_body" />
      </visual>
    <visual>
      <origin xyz="0.293 0 0.064" rpy="0 0 0" />
      <geometry>
        <box size="0.006 0.13568 0.024" />
        </geometry>
      <material name="grip_middle" />
      </visual>
    <visual>
      <origin xyz="0.145 0.1005 0.017" rpy="0 0 0" />
      <geometry>
        <box size="0.19 0.003 0.01" />
        </geometry>
      <material name="runner_dark" />
      </visual>
    <visual>
      <origin xyz="0.145 -0.1005 0.017" rpy="0 0 0" />
      <geometry>
        <box size="0.19 0.003 0.01" />
        </geometry>
      <material name="runner_dark" />
      </visual>
    <visual>
      <origin xyz="0.145 0.1075 0.017" rpy="0 0 0" />
      <geometry>
        <box size="0.19 0.003 0.01" />
        </geometry>
      <material name="runner_dark" />
      </visual>
    <visual>
      <origin xyz="0.145 -0.1075 0.017" rpy="0 0 0" />
      <geometry>
        <box size="0.19 0.003 0.01" />
        </geometry>
      <material name="runner_dark" />
      </visual>
    <collision name="middle_tray__visual_1">
      <origin xyz="0.145 0 0.002" rpy="0 0 0" />
      <geometry>
        <box size="0.29 0.212 0.004" />
        </geometry>
      </collision>
    <collision name="middle_tray__visual_2">
      <origin xyz="0.145 0.104 0.035" rpy="0 0 0" />
      <geometry>
        <box size="0.29 0.004 0.062" />
        </geometry>
      </collision>
    <collision name="middle_tray__visual_3">
      <origin xyz="0.145 -0.104 0.035" rpy="0 0 0" />
      <geometry>
        <box size="0.29 0.004 0.062" />
        </geometry>
      </collision>
    <collision name="middle_tray__visual_4">
      <origin xyz="0.002 0 0.035" rpy="0 0 0" />
      <geometry>
        <box size="0.004 0.204 0.062" />
        </geometry>
      </collision>
    <collision name="middle_tray__visual_5">
      <origin xyz="0.288 0 0.064" rpy="0 0 0" />
      <geometry>
        <box size="0.004 0.204 0.004" />
        </geometry>
      </collision>
    <collision name="middle_tray__visual_6">
      <origin xyz="0.293 0 0.064" rpy="0 0 0" />
      <geometry>
        <box size="0.006 0.13568 0.024" />
        </geometry>
      </collision>
    <collision name="middle_tray__visual_7">
      <origin xyz="0.145 0.1005 0.017" rpy="0 0 0" />
      <geometry>
        <box size="0.19 0.003 0.01" />
        </geometry>
      </collision>
    <collision name="middle_tray__visual_8">
      <origin xyz="0.145 -0.1005 0.017" rpy="0 0 0" />
      <geometry>
        <box size="0.19 0.003 0.01" />
        </geometry>
      </collision>
    <collision name="middle_tray__visual_9">
      <origin xyz="0.145 0.1075 0.017" rpy="0 0 0" />
      <geometry>
        <box size="0.19 0.003 0.01" />
        </geometry>
      </collision>
    <collision name="middle_tray__visual_10">
      <origin xyz="0.145 -0.1075 0.017" rpy="0 0 0" />
      <geometry>
        <box size="0.19 0.003 0.01" />
        </geometry>
      </collision>
    </link>
  <link name="inner_tray">
    <inertial>
      <origin xyz="0.123 0 0.027" rpy="0 0 0" />
      <mass value="0.6" />
      <inertia ixx="0.0019508" ixy="0" ixz="0" iyy="0.0031716" iyz="0" izz="0.0048308" />
      </inertial>
    <visual>
      <origin xyz="0.12 0 0.002" rpy="0 0 0" />
      <geometry>
        <box size="0.24 0.184 0.004" />
        </geometry>
      <material name="inner_body" />
      </visual>
    <visual>
      <origin xyz="0.12 0.09 0.029" rpy="0 0 0" />
      <geometry>
        <box size="0.24 0.004 0.05" />
        </geometry>
      <material name="inner_body" />
      </visual>
    <visual>
      <origin xyz="0.12 -0.09 0.029" rpy="0 0 0" />
      <geometry>
        <box size="0.24 0.004 0.05" />
        </geometry>
      <material name="inner_body" />
      </visual>
    <visual>
      <origin xyz="0.002 0 0.029" rpy="0 0 0" />
      <geometry>
        <box size="0.004 0.176 0.05" />
        </geometry>
      <material name="inner_body" />
      </visual>
    <visual>
      <origin xyz="0.238 0 0.024" rpy="0 0 0" />
      <geometry>
        <box size="0.004 0.176 0.04" />
        </geometry>
      <material name="inner_body" />
      </visual>
    <visual>
      <origin xyz="0.243 0 0.0264" rpy="0 0 0" />
      <geometry>
        <box size="0.006 0.11776 0.0208" />
        </geometry>
      <material name="grip_inner" />
      </visual>
    <visual>
      <origin xyz="0.12 0.0935 0.017" rpy="0 0 0" />
      <geometry>
        <box size="0.14 0.003 0.01" />
        </geometry>
      <material name="runner_dark" />
      </visual>
    <visual>
      <origin xyz="0.12 -0.0935 0.017" rpy="0 0 0" />
      <geometry>
        <box size="0.14 0.003 0.01" />
        </geometry>
      <material name="runner_dark" />
      </visual>
    <collision name="inner_tray__visual_1">
      <origin xyz="0.12 0 0.002" rpy="0 0 0" />
      <geometry>
        <box size="0.24 0.184 0.004" />
        </geometry>
      </collision>
    <collision name="inner_tray__visual_2">
      <origin xyz="0.12 0.09 0.029" rpy="0 0 0" />
      <geometry>
        <box size="0.24 0.004 0.05" />
        </geometry>
      </collision>
    <collision name="inner_tray__visual_3">
      <origin xyz="0.12 -0.09 0.029" rpy="0 0 0" />
      <geometry>
        <box size="0.24 0.004 0.05" />
        </geometry>
      </collision>
    <collision name="inner_tray__visual_4">
      <origin xyz="0.002 0 0.029" rpy="0 0 0" />
      <geometry>
        <box size="0.004 0.176 0.05" />
        </geometry>
      </collision>
    <collision name="inner_tray__visual_5">
      <origin xyz="0.238 0 0.024" rpy="0 0 0" />
      <geometry>
        <box size="0.004 0.176 0.04" />
        </geometry>
      </collision>
    <collision name="inner_tray__visual_6">
      <origin xyz="0.243 0 0.0264" rpy="0 0 0" />
      <geometry>
        <box size="0.006 0.11776 0.0208" />
        </geometry>
      </collision>
    <collision name="inner_tray__visual_7">
      <origin xyz="0.12 0.0935 0.017" rpy="0 0 0" />
      <geometry>
        <box size="0.14 0.003 0.01" />
        </geometry>
      </collision>
    <collision name="inner_tray__visual_8">
      <origin xyz="0.12 -0.0935 0.017" rpy="0 0 0" />
      <geometry>
        <box size="0.14 0.003 0.01" />
        </geometry>
      </collision>
    </link>
  <joint name="outer_to_middle_slide" type="prismatic">
    <origin xyz="0.01 0 0.006" rpy="0 0 0" />
    <parent link="outer_tray" />
    <child link="middle_tray" />
    <axis xyz="1 0 0" />
    <limit effort="120" velocity="0.25" lower="0" upper="0.19" />
    </joint>
  <joint name="middle_to_inner_slide" type="prismatic">
    <origin xyz="0.01 0 0.006" rpy="0 0 0" />
    <parent link="middle_tray" />
    <child link="inner_tray" />
    <axis xyz="1 0 0" />
    <limit effort="90" velocity="0.25" lower="0" upper="0.072" />
    </joint>
  </robot>
