<robot name="wheelie_bin">
  <material name="body_green">
    <color rgba="0.196 0.314 0.22 1" />
  </material>
  <material name="lid_green">
    <color rgba="0.176 0.286 0.204 1" />
  </material>
  <material name="wheel_black">
    <color rgba="0.085 0.085 0.085 1" />
  </material>
  <material name="hub_gray">
    <color rgba="0.585 0.595 0.62 1" />
  </material>
  <link name="body">
    <inertial>
      <origin xyz="0 0 0.46" rpy="0 0 0" />
      <mass value="12" />
      <inertia ixx="1.424" ixy="0" ixz="0" iyy="1.1945" iyz="0" izz="0.9257" />
    </inertial>
    <visual name="body_shell">
      <geometry>
        <mesh filename="meshes/wheelie_bin_body_shell.glb" />
      </geometry>
      <material name="body_green">
        <color rgba="0.196 0.314 0.22 1" />
      </material>
    </visual>
    <visual name="inner_collar">
      <geometry>
        <mesh filename="meshes/wheelie_bin_inner_collar.glb" />
      </geometry>
      <material name="body_green">
        <color rgba="0.196 0.314 0.22 1" />
      </material>
    </visual>
    <visual name="bottom_plate">
      <origin xyz="0 0 0.035" rpy="0 0 0" />
      <geometry>
        <box size="0.36 0.42 0.03" />
      </geometry>
      <material name="body_green">
        <color rgba="0.196 0.314 0.22 1" />
      </material>
    </visual>
    <visual name="front_rim">
      <origin xyz="0 0.356 0.872" rpy="0 0 0" />
      <geometry>
        <box size="0.52 0.034 0.028" />
      </geometry>
      <material name="body_green">
        <color rgba="0.196 0.314 0.22 1" />
      </material>
    </visual>
    <visual name="rear_rim">
      <origin xyz="0 -0.347 0.872" rpy="0 0 0" />
      <geometry>
        <box size="0.5 0.028 0.032" />
      </geometry>
      <material name="body_green">
        <color rgba="0.196 0.314 0.22 1" />
      </material>
    </visual>
    <visual name="right_rim">
      <origin xyz="0.278 0 0.872" rpy="0 0 0" />
      <geometry>
        <box size="0.032 0.66 0.028" />
      </geometry>
      <material name="body_green">
        <color rgba="0.196 0.314 0.22 1" />
      </material>
    </visual>
    <visual name="left_rim">
      <origin xyz="-0.278 0 0.872" rpy="0 0 0" />
      <geometry>
        <box size="0.032 0.66 0.028" />
      </geometry>
      <material name="body_green">
        <color rgba="0.196 0.314 0.22 1" />
      </material>
    </visual>
    <visual name="front_panel">
      <origin xyz="0 0.338 0.52" rpy="0 0 0" />
      <geometry>
        <box size="0.44 0.018 0.24" />
      </geometry>
      <material name="body_green">
        <color rgba="0.196 0.314 0.22 1" />
      </material>
    </visual>
    <visual name="front_rib_right">
      <origin xyz="0.125 0.338 0.39" rpy="0 0 0" />
      <geometry>
        <box size="0.045 0.022 0.46" />
      </geometry>
      <material name="body_green">
        <color rgba="0.196 0.314 0.22 1" />
      </material>
    </visual>
    <visual name="front_rib_left">
      <origin xyz="-0.125 0.338 0.39" rpy="0 0 0" />
      <geometry>
        <box size="0.045 0.022 0.46" />
      </geometry>
      <material name="body_green">
        <color rgba="0.196 0.314 0.22 1" />
      </material>
    </visual>
    <visual name="right_side_rib">
      <origin xyz="0.244 0.05 0.46" rpy="0 0 0" />
      <geometry>
        <box size="0.032 0.34 0.52" />
      </geometry>
      <material name="body_green">
        <color rgba="0.196 0.314 0.22 1" />
      </material>
    </visual>
    <visual name="left_side_rib">
      <origin xyz="-0.244 0.05 0.46" rpy="0 0 0" />
      <geometry>
        <box size="0.032 0.34 0.52" />
      </geometry>
      <material name="body_green">
        <color rgba="0.196 0.314 0.22 1" />
      </material>
    </visual>
    <visual name="right_wheel_housing">
      <origin xyz="0.176 -0.228 0.155" rpy="0 0 0" />
      <geometry>
        <box size="0.048 0.11 0.19" />
      </geometry>
      <material name="body_green">
        <color rgba="0.196 0.314 0.22 1" />
      </material>
    </visual>
    <visual name="left_wheel_housing">
      <origin xyz="-0.176 -0.228 0.155" rpy="0 0 0" />
      <geometry>
        <box size="0.048 0.11 0.19" />
      </geometry>
      <material name="body_green">
        <color rgba="0.196 0.314 0.22 1" />
      </material>
    </visual>
    <visual name="right_axle_stub">
      <origin xyz="0.236 -0.225 0.145" rpy="0 1.5708 0" />
      <geometry>
        <cylinder radius="0.018" length="0.062" />
      </geometry>
      <material name="hub_gray">
        <color rgba="0.585 0.595 0.62 1" />
      </material>
    </visual>
    <visual name="left_axle_stub">
      <origin xyz="-0.236 -0.225 0.145" rpy="0 1.5708 0" />
      <geometry>
        <cylinder radius="0.018" length="0.062" />
      </geometry>
      <material name="hub_gray">
        <color rgba="0.585 0.595 0.62 1" />
      </material>
    </visual>
    <visual name="rear_step_bar">
      <origin xyz="0 -0.236 0.06" rpy="0 0 0" />
      <geometry>
        <box size="0.3 0.05 0.05" />
      </geometry>
      <material name="body_green">
        <color rgba="0.196 0.314 0.22 1" />
      </material>
    </visual>
    <visual name="right_handle_tower">
      <origin xyz="0.162 -0.385 0.895" rpy="0 0 0" />
      <geometry>
        <box size="0.055 0.07 0.09" />
      </geometry>
      <material name="body_green">
        <color rgba="0.196 0.314 0.22 1" />
      </material>
    </visual>
    <visual name="left_handle_tower">
      <origin xyz="-0.162 -0.385 0.895" rpy="0 0 0" />
      <geometry>
        <box size="0.055 0.07 0.09" />
      </geometry>
      <material name="body_green">
        <color rgba="0.196 0.314 0.22 1" />
      </material>
    </visual>
    <visual name="handle_bar">
      <origin xyz="0 -0.41 0.922" rpy="0 0 0" />
      <geometry>
        <box size="0.34 0.036 0.03" />
      </geometry>
      <material name="body_green">
        <color rgba="0.196 0.314 0.22 1" />
      </material>
    </visual>
    <collision name="body__body_shell__hull_001">
      <geometry>
        <mesh filename="meshes/collision/cache/388a3f93b05fececc3c2c220__hull_001.obj" />
      </geometry>
    </collision>
    <collision name="body__body_shell__hull_002">
      <geometry>
        <mesh filename="meshes/collision/cache/388a3f93b05fececc3c2c220__hull_002.obj" />
      </geometry>
    </collision>
    <collision name="body__body_shell__hull_003">
      <geometry>
        <mesh filename="meshes/collision/cache/388a3f93b05fececc3c2c220__hull_003.obj" />
      </geometry>
    </collision>
    <collision name="body__body_shell__hull_004">
      <geometry>
        <mesh filename="meshes/collision/cache/388a3f93b05fececc3c2c220__hull_004.obj" />
      </geometry>
    </collision>
    <collision name="body__body_shell__hull_005">
      <geometry>
        <mesh filename="meshes/collision/cache/388a3f93b05fececc3c2c220__hull_005.obj" />
      </geometry>
    </collision>
    <collision name="body__body_shell__hull_006">
      <geometry>
        <mesh filename="meshes/collision/cache/388a3f93b05fececc3c2c220__hull_006.obj" />
      </geometry>
    </collision>
    <collision name="body__body_shell__hull_007">
      <geometry>
        <mesh filename="meshes/collision/cache/388a3f93b05fececc3c2c220__hull_007.obj" />
      </geometry>
    </collision>
    <collision name="body__body_shell__hull_008">
      <geometry>
        <mesh filename="meshes/collision/cache/388a3f93b05fececc3c2c220__hull_008.obj" />
      </geometry>
    </collision>
    <collision name="body__body_shell__hull_009">
      <geometry>
        <mesh filename="meshes/collision/cache/388a3f93b05fececc3c2c220__hull_009.obj" />
      </geometry>
    </collision>
    <collision name="body__body_shell__hull_010">
      <geometry>
        <mesh filename="meshes/collision/cache/388a3f93b05fececc3c2c220__hull_010.obj" />
      </geometry>
    </collision>
    <collision name="body__body_shell__hull_011">
      <geometry>
        <mesh filename="meshes/collision/cache/388a3f93b05fececc3c2c220__hull_011.obj" />
      </geometry>
    </collision>
    <collision name="body__body_shell__hull_012">
      <geometry>
        <mesh filename="meshes/collision/cache/388a3f93b05fececc3c2c220__hull_012.obj" />
      </geometry>
    </collision>
    <collision name="body__body_shell__hull_013">
      <geometry>
        <mesh filename="meshes/collision/cache/388a3f93b05fececc3c2c220__hull_013.obj" />
      </geometry>
    </collision>
    <collision name="body__body_shell__hull_014">
      <geometry>
        <mesh filename="meshes/collision/cache/388a3f93b05fececc3c2c220__hull_014.obj" />
      </geometry>
    </collision>
    <collision name="body__body_shell__hull_015">
      <geometry>
        <mesh filename="meshes/collision/cache/388a3f93b05fececc3c2c220__hull_015.obj" />
      </geometry>
    </collision>
    <collision name="body__body_shell__hull_016">
      <geometry>
        <mesh filename="meshes/collision/cache/388a3f93b05fececc3c2c220__hull_016.obj" />
      </geometry>
    </collision>
    <collision name="body__inner_collar__hull_001">
      <geometry>
        <mesh filename="meshes/collision/cache/5759c2cbaaead2e43e33d6ce__hull_001.obj" />
      </geometry>
    </collision>
    <collision name="body__inner_collar__hull_002">
      <geometry>
        <mesh filename="meshes/collision/cache/5759c2cbaaead2e43e33d6ce__hull_002.obj" />
      </geometry>
    </collision>
    <collision name="body__inner_collar__hull_003">
      <geometry>
        <mesh filename="meshes/collision/cache/5759c2cbaaead2e43e33d6ce__hull_003.obj" />
      </geometry>
    </collision>
    <collision name="body__inner_collar__hull_004">
      <geometry>
        <mesh filename="meshes/collision/cache/5759c2cbaaead2e43e33d6ce__hull_004.obj" />
      </geometry>
    </collision>
    <collision name="body__inner_collar__hull_005">
      <geometry>
        <mesh filename="meshes/collision/cache/5759c2cbaaead2e43e33d6ce__hull_005.obj" />
      </geometry>
    </collision>
    <collision name="body__inner_collar__hull_006">
      <geometry>
        <mesh filename="meshes/collision/cache/5759c2cbaaead2e43e33d6ce__hull_006.obj" />
      </geometry>
    </collision>
    <collision name="body__inner_collar__hull_007">
      <geometry>
        <mesh filename="meshes/collision/cache/5759c2cbaaead2e43e33d6ce__hull_007.obj" />
      </geometry>
    </collision>
    <collision name="body__inner_collar__hull_008">
      <geometry>
        <mesh filename="meshes/collision/cache/5759c2cbaaead2e43e33d6ce__hull_008.obj" />
      </geometry>
    </collision>
    <collision name="body__bottom_plate">
      <origin xyz="0 0 0.035" rpy="0 0 0" />
      <geometry>
        <box size="0.36 0.42 0.03" />
      </geometry>
    </collision>
    <collision name="body__front_rim">
      <origin xyz="0 0.356 0.872" rpy="0 0 0" />
      <geometry>
        <box size="0.52 0.034 0.028" />
      </geometry>
    </collision>
    <collision name="body__rear_rim">
      <origin xyz="0 -0.347 0.872" rpy="0 0 0" />
      <geometry>
        <box size="0.5 0.028 0.032" />
      </geometry>
    </collision>
    <collision name="body__right_rim">
      <origin xyz="0.278 0 0.872" rpy="0 0 0" />
      <geometry>
        <box size="0.032 0.66 0.028" />
      </geometry>
    </collision>
    <collision name="body__left_rim">
      <origin xyz="-0.278 0 0.872" rpy="0 0 0" />
      <geometry>
        <box size="0.032 0.66 0.028" />
      </geometry>
    </collision>
    <collision name="body__front_panel">
      <origin xyz="0 0.338 0.52" rpy="0 0 0" />
      <geometry>
        <box size="0.44 0.018 0.24" />
      </geometry>
    </collision>
    <collision name="body__front_rib_right">
      <origin xyz="0.125 0.338 0.39" rpy="0 0 0" />
      <geometry>
        <box size="0.045 0.022 0.46" />
      </geometry>
    </collision>
    <collision name="body__front_rib_left">
      <origin xyz="-0.125 0.338 0.39" rpy="0 0 0" />
      <geometry>
        <box size="0.045 0.022 0.46" />
      </geometry>
    </collision>
    <collision name="body__right_side_rib">
      <origin xyz="0.244 0.05 0.46" rpy="0 0 0" />
      <geometry>
        <box size="0.032 0.34 0.52" />
      </geometry>
    </collision>
    <collision name="body__left_side_rib">
      <origin xyz="-0.244 0.05 0.46" rpy="0 0 0" />
      <geometry>
        <box size="0.032 0.34 0.52" />
      </geometry>
    </collision>
    <collision name="body__right_wheel_housing">
      <origin xyz="0.176 -0.228 0.155" rpy="0 0 0" />
      <geometry>
        <box size="0.048 0.11 0.19" />
      </geometry>
    </collision>
    <collision name="body__left_wheel_housing">
      <origin xyz="-0.176 -0.228 0.155" rpy="0 0 0" />
      <geometry>
        <box size="0.048 0.11 0.19" />
      </geometry>
    </collision>
    <collision name="body__right_axle_stub">
      <origin xyz="0.236 -0.225 0.145" rpy="0 1.5708 0" />
      <geometry>
        <cylinder radius="0.018" length="0.062" />
      </geometry>
    </collision>
    <collision name="body__left_axle_stub">
      <origin xyz="-0.236 -0.225 0.145" rpy="0 1.5708 0" />
      <geometry>
        <cylinder radius="0.018" length="0.062" />
      </geometry>
    </collision>
    <collision name="body__rear_step_bar">
      <origin xyz="0 -0.236 0.06" rpy="0 0 0" />
      <geometry>
        <box size="0.3 0.05 0.05" />
      </geometry>
    </collision>
    <collision name="body__right_handle_tower">
      <origin xyz="0.162 -0.385 0.895" rpy="0 0 0" />
      <geometry>
        <box size="0.055 0.07 0.09" />
      </geometry>
    </collision>
    <collision name="body__left_handle_tower">
      <origin xyz="-0.162 -0.385 0.895" rpy="0 0 0" />
      <geometry>
        <box size="0.055 0.07 0.09" />
      </geometry>
    </collision>
    <collision name="body__handle_bar">
      <origin xyz="0 -0.41 0.922" rpy="0 0 0" />
      <geometry>
        <box size="0.34 0.036 0.03" />
      </geometry>
    </collision>
  </link>
  <link name="lid">
    <inertial>
      <origin xyz="0 0.36 0.04" rpy="0 0 0" />
      <mass value="2.4" />
      <inertia ixx="0.110965" ixy="0" ixz="0" iyy="0.075865" iyz="0" izz="0.18394" />
    </inertial>
    <visual name="lid_shell">
      <origin xyz="0 0.358 0.016" rpy="0 0 0" />
      <geometry>
        <mesh filename="meshes/wheelie_bin_lid_shell.glb" />
      </geometry>
      <material name="lid_green">
        <color rgba="0.176 0.286 0.204 1" />
      </material>
    </visual>
    <visual name="rear_flange">
      <origin xyz="0 0.01 0.024" rpy="0 0 0" />
      <geometry>
        <box size="0.55 0.032 0.026" />
      </geometry>
      <material name="lid_green">
        <color rgba="0.176 0.286 0.204 1" />
      </material>
    </visual>
    <visual name="hinge_barrel">
      <origin xyz="0 0 0.018" rpy="0 1.5708 0" />
      <geometry>
        <cylinder radius="0.014" length="0.5" />
      </geometry>
      <material name="lid_green">
        <color rgba="0.176 0.286 0.204 1" />
      </material>
    </visual>
    <visual name="front_grab_lip">
      <origin xyz="0 0.712 0.02" rpy="0 0 0" />
      <geometry>
        <box size="0.26 0.038 0.03" />
      </geometry>
      <material name="lid_green">
        <color rgba="0.176 0.286 0.204 1" />
      </material>
    </visual>
    <visual name="top_grip_pad">
      <origin xyz="0 0.565 0.056" rpy="0 0 0" />
      <geometry>
        <box size="0.22 0.11 0.018" />
      </geometry>
      <material name="lid_green">
        <color rgba="0.176 0.286 0.204 1" />
      </material>
    </visual>
    <collision name="lid__lid_shell__hull_001">
      <origin xyz="0 0.358 0.016" rpy="0 0 0" />
      <geometry>
        <mesh filename="meshes/collision/cache/470669cf4f876a31a66e1c0b__hull_001.obj" />
      </geometry>
    </collision>
    <collision name="lid__rear_flange">
      <origin xyz="0 0.01 0.024" rpy="0 0 0" />
      <geometry>
        <box size="0.55 0.032 0.026" />
      </geometry>
    </collision>
    <collision name="lid__hinge_barrel">
      <origin xyz="0 0 0.018" rpy="0 1.5708 0" />
      <geometry>
        <cylinder radius="0.014" length="0.5" />
      </geometry>
    </collision>
    <collision name="lid__front_grab_lip">
      <origin xyz="0 0.712 0.02" rpy="0 0 0" />
      <geometry>
        <box size="0.26 0.038 0.03" />
      </geometry>
    </collision>
    <collision name="lid__top_grip_pad">
      <origin xyz="0 0.565 0.056" rpy="0 0 0" />
      <geometry>
        <box size="0.22 0.11 0.018" />
      </geometry>
    </collision>
  </link>
  <link name="left_wheel">
    <inertial>
      <origin xyz="0 0 0" rpy="0 1.5708 0" />
      <mass value="1.1" />
      <inertia ixx="0.00517358" ixy="0" ixz="0" iyy="0.00517358" iyz="0" izz="0.0100238" />
    </inertial>
    <visual name="left_wheel_tire">
      <origin xyz="0 0 0" rpy="0 1.5708 0" />
      <geometry>
        <cylinder radius="0.135" length="0.042" />
      </geometry>
      <material name="wheel_black">
        <color rgba="0.085 0.085 0.085 1" />
      </material>
    </visual>
    <visual name="left_wheel_hub">
      <origin xyz="0 0 0" rpy="0 1.5708 0" />
      <geometry>
        <cylinder radius="0.052" length="0.05" />
      </geometry>
      <material name="hub_gray">
        <color rgba="0.585 0.595 0.62 1" />
      </material>
    </visual>
    <visual name="left_wheel_cap">
      <origin xyz="0 0 0" rpy="0 1.5708 0" />
      <geometry>
        <cylinder radius="0.026" length="0.058" />
      </geometry>
      <material name="hub_gray">
        <color rgba="0.585 0.595 0.62 1" />
      </material>
    </visual>
    <collision name="left_wheel__left_wheel_tire">
      <origin xyz="0 0 0" rpy="0 1.5708 0" />
      <geometry>
        <cylinder radius="0.135" length="0.042" />
      </geometry>
    </collision>
    <collision name="left_wheel__left_wheel_hub">
      <origin xyz="0 0 0" rpy="0 1.5708 0" />
      <geometry>
        <cylinder radius="0.052" length="0.05" />
      </geometry>
    </collision>
    <collision name="left_wheel__left_wheel_cap">
      <origin xyz="0 0 0" rpy="0 1.5708 0" />
      <geometry>
        <cylinder radius="0.026" length="0.058" />
      </geometry>
    </collision>
  </link>
  <link name="right_wheel">
    <inertial>
      <origin xyz="0 0 0" rpy="0 1.5708 0" />
      <mass value="1.1" />
      <inertia ixx="0.00517358" ixy="0" ixz="0" iyy="0.00517358" iyz="0" izz="0.0100238" />
    </inertial>
    <visual name="right_wheel_tire">
      <origin xyz="0 0 0" rpy="0 1.5708 0" />
      <geometry>
        <cylinder radius="0.135" length="0.042" />
      </geometry>
      <material name="wheel_black">
        <color rgba="0.085 0.085 0.085 1" />
      </material>
    </visual>
    <visual name="right_wheel_hub">
      <origin xyz="0 0 0" rpy="0 1.5708 0" />
      <geometry>
        <cylinder radius="0.052" length="0.05" />
      </geometry>
      <material name="hub_gray">
        <color rgba="0.585 0.595 0.62 1" />
      </material>
    </visual>
    <visual name="right_wheel_cap">
      <origin xyz="0 0 0" rpy="0 1.5708 0" />
      <geometry>
        <cylinder radius="0.026" length="0.058" />
      </geometry>
      <material name="hub_gray">
        <color rgba="0.585 0.595 0.62 1" />
      </material>
    </visual>
    <collision name="right_wheel__right_wheel_tire">
      <origin xyz="0 0 0" rpy="0 1.5708 0" />
      <geometry>
        <cylinder radius="0.135" length="0.042" />
      </geometry>
    </collision>
    <collision name="right_wheel__right_wheel_hub">
      <origin xyz="0 0 0" rpy="0 1.5708 0" />
      <geometry>
        <cylinder radius="0.052" length="0.05" />
      </geometry>
    </collision>
    <collision name="right_wheel__right_wheel_cap">
      <origin xyz="0 0 0" rpy="0 1.5708 0" />
      <geometry>
        <cylinder radius="0.026" length="0.058" />
      </geometry>
    </collision>
  </link>
  <joint name="lid_hinge" type="revolute">
    <origin xyz="0 -0.334 0.872" rpy="0 0 0" />
    <parent link="body" />
    <child link="lid" />
    <axis xyz="1 0 0" />
    <limit effort="18" velocity="2.5" lower="0" upper="1.85" />
  </joint>
  <joint name="left_wheel_axle" type="continuous">
    <origin xyz="-0.274 -0.225 0.145" rpy="0 0 0" />
    <parent link="body" />
    <child link="left_wheel" />
    <axis xyz="1 0 0" />
    <limit effort="30" velocity="18" />
  </joint>
  <joint name="right_wheel_axle" type="continuous">
    <origin xyz="0.274 -0.225 0.145" rpy="0 0 0" />
    <parent link="body" />
    <child link="right_wheel" />
    <axis xyz="1 0 0" />
    <limit effort="30" velocity="18" />
  </joint>
</robot>