<robot name="flatbed_scanner">
  <material name="silver_paint">
    <color rgba="0.82 0.83 0.85 1" />
    </material>
  <material name="cool_white">
    <color rgba="0.92 0.93 0.92 1" />
    </material>
  <material name="platen_white">
    <color rgba="0.96 0.96 0.94 1" />
    </material>
  <material name="charcoal_plastic">
    <color rgba="0.19 0.2 0.22 1" />
    </material>
  <material name="black_gloss">
    <color rgba="0.08 0.09 0.1 1" />
    </material>
  <material name="rubber">
    <color rgba="0.11 0.11 0.12 1" />
    </material>
  <material name="glass">
    <color rgba="0.7 0.84 0.92 0.32" />
    </material>
  <material name="status_blue">
    <color rgba="0.23 0.78 0.97 0.9" />
    </material>
  <link name="base">
    <inertial>
      <origin xyz="0 0 0.025" rpy="0 0 0" />
      <mass value="4.6" />
      <inertia ixx="0.0373229" ixy="0" ixz="0" iyy="0.0758479" iyz="0" izz="0.111254" />
      </inertial>
    <visual name="lower_shell">
      <geometry>
        <mesh filename="assets/meshes/scanner_body_lower.obj" />
        </geometry>
      <material name="charcoal_plastic">
        <color rgba="0.19 0.2 0.22 1" />
        </material>
      </visual>
    <visual name="upper_shell">
      <origin xyz="0 0 0.014" rpy="0 0 0" />
      <geometry>
        <mesh filename="assets/meshes/scanner_body_upper.obj" />
        </geometry>
      <material name="silver_paint">
        <color rgba="0.82 0.83 0.85 1" />
        </material>
      </visual>
    <visual name="scan_bed_bezel">
      <origin xyz="-0.046 0.004 0.046" rpy="0 0 0" />
      <geometry>
        <mesh filename="assets/meshes/scanner_bed_bezel.obj" />
        </geometry>
      <material name="black_gloss">
        <color rgba="0.08 0.09 0.1 1" />
        </material>
      </visual>
    <visual name="scan_glass">
      <origin xyz="-0.046 0.004 0.0481" rpy="0 0 0" />
      <geometry>
        <box size="0.292 0.216 0.0032" />
        </geometry>
      <material name="glass">
        <color rgba="0.7 0.84 0.92 0.32" />
        </material>
      </visual>
    <visual name="scan_platen">
      <origin xyz="-0.046 0.004 0.0458" rpy="0 0 0" />
      <geometry>
        <box size="0.286 0.206 0.0028" />
        </geometry>
      <material name="platen_white">
        <color rgba="0.96 0.96 0.94 1" />
        </material>
      </visual>
    <visual name="calibration_strip">
      <origin xyz="-0.175 0.004 0.0462" rpy="0 0 0" />
      <geometry>
        <box size="0.01 0.19 0.001" />
        </geometry>
      <material name="platen_white">
        <color rgba="0.96 0.96 0.94 1" />
        </material>
      </visual>
    <visual name="control_panel">
      <origin xyz="0.147 0.004 0.0475" rpy="0 0 0" />
      <geometry>
        <mesh filename="assets/meshes/scanner_control_panel.obj" />
        </geometry>
      <material name="black_gloss">
        <color rgba="0.08 0.09 0.1 1" />
        </material>
      </visual>
    <visual name="status_window">
      <origin xyz="0.147 0.073 0.0492" rpy="0 0 0" />
      <geometry>
        <box size="0.05 0.022 0.0012" />
        </geometry>
      <material name="charcoal_plastic">
        <color rgba="0.19 0.2 0.22 1" />
        </material>
      </visual>
    <visual name="power_button">
      <origin xyz="0.171 -0.059 0.0498" rpy="0 0 0" />
      <geometry>
        <cylinder radius="0.01" length="0.0024" />
        </geometry>
      <material name="silver_paint">
        <color rgba="0.82 0.83 0.85 1" />
        </material>
      </visual>
    <visual name="start_button">
      <origin xyz="0.123 -0.059 0.0498" rpy="0 0 0" />
      <geometry>
        <cylinder radius="0.009" length="0.0024" />
        </geometry>
      <material name="cool_white">
        <color rgba="0.92 0.93 0.92 1" />
        </material>
      </visual>
    <visual name="stop_button">
      <origin xyz="0.147 -0.059 0.0498" rpy="0 0 0" />
      <geometry>
        <cylinder radius="0.009" length="0.0024" />
        </geometry>
      <material name="cool_white">
        <color rgba="0.92 0.93 0.92 1" />
        </material>
      </visual>
    <visual name="mode_button_left">
      <origin xyz="0.125 -0.006 0.0494" rpy="0 0 0" />
      <geometry>
        <box size="0.018 0.01 0.002" />
        </geometry>
      <material name="silver_paint">
        <color rgba="0.82 0.83 0.85 1" />
        </material>
      </visual>
    <visual name="mode_button_right">
      <origin xyz="0.169 -0.006 0.0494" rpy="0 0 0" />
      <geometry>
        <box size="0.018 0.01 0.002" />
        </geometry>
      <material name="silver_paint">
        <color rgba="0.82 0.83 0.85 1" />
        </material>
      </visual>
    <visual name="status_led">
      <origin xyz="0.113 0.073 0.0495" rpy="0 0 0" />
      <geometry>
        <box size="0.006 0.006 0.0014" />
        </geometry>
      <material name="status_blue">
        <color rgba="0.23 0.78 0.97 0.9" />
        </material>
      </visual>
    <visual name="logo_plaque">
      <origin xyz="0.147 0.107 0.0499" rpy="0 0 0" />
      <geometry>
        <box size="0.044 0.01 0.0008" />
        </geometry>
      <material name="charcoal_plastic">
        <color rgba="0.19 0.2 0.22 1" />
        </material>
      </visual>
    <visual name="hinge_cover">
      <origin xyz="-0.046 -0.142 0.0465" rpy="0 0 0" />
      <geometry>
        <box size="0.36 0.018 0.009" />
        </geometry>
      <material name="charcoal_plastic">
        <color rgba="0.19 0.2 0.22 1" />
        </material>
      </visual>
    <visual name="front_fascia">
      <origin xyz="-0.01 0.1515 0.024" rpy="0 0 0" />
      <geometry>
        <box size="0.34 0.005 0.007" />
        </geometry>
      <material name="black_gloss">
        <color rgba="0.08 0.09 0.1 1" />
        </material>
      </visual>
    <visual name="foot_1">
      <origin xyz="-0.162 -0.112 0.0015" rpy="0 0 0" />
      <geometry>
        <box size="0.032 0.018 0.004" />
        </geometry>
      <material name="rubber">
        <color rgba="0.11 0.11 0.12 1" />
        </material>
      </visual>
    <visual name="foot_2">
      <origin xyz="-0.162 0.112 0.0015" rpy="0 0 0" />
      <geometry>
        <box size="0.032 0.018 0.004" />
        </geometry>
      <material name="rubber">
        <color rgba="0.11 0.11 0.12 1" />
        </material>
      </visual>
    <visual name="foot_3">
      <origin xyz="0.162 -0.112 0.0015" rpy="0 0 0" />
      <geometry>
        <box size="0.032 0.018 0.004" />
        </geometry>
      <material name="rubber">
        <color rgba="0.11 0.11 0.12 1" />
        </material>
      </visual>
    <visual name="foot_4">
      <origin xyz="0.162 0.112 0.0015" rpy="0 0 0" />
      <geometry>
        <box size="0.032 0.018 0.004" />
        </geometry>
      <material name="rubber">
        <color rgba="0.11 0.11 0.12 1" />
        </material>
      </visual>
    </link>
  <link name="lid">
    <inertial>
      <origin xyz="-0.046 0.1375 0.0065" rpy="0 0 0" />
      <mass value="1.2" />
      <inertia ixx="0.0084906" ixy="0" ixz="0" iyy="0.0113121" iyz="0" izz="0.0197577" />
      </inertial>
    <visual name="lid_shell">
      <origin xyz="-0.046 0.1375 -0.001" rpy="0 0 0" />
      <geometry>
        <mesh filename="assets/meshes/scanner_lid_shell.obj" />
        </geometry>
      <material name="cool_white">
        <color rgba="0.92 0.93 0.92 1" />
        </material>
      </visual>
    <visual name="lid_backing">
      <origin xyz="-0.046 0.126 -0.0004" rpy="0 0 0" />
      <geometry>
        <mesh filename="assets/meshes/scanner_lid_backing.obj" />
        </geometry>
      <material name="platen_white">
        <color rgba="0.96 0.96 0.94 1" />
        </material>
      </visual>
    <visual name="lid_hinge_trim">
      <origin xyz="-0.046 0.004 0.005" rpy="0 0 0" />
      <geometry>
        <box size="0.29568 0.016 0.01" />
        </geometry>
      <material name="charcoal_plastic">
        <color rgba="0.19 0.2 0.22 1" />
        </material>
      </visual>
    <visual name="lid_pull_grip">
      <origin xyz="-0.046 0.272 0.013" rpy="0 0 0" />
      <geometry>
        <box size="0.14 0.016 0.0036" />
        </geometry>
      <material name="black_gloss">
        <color rgba="0.08 0.09 0.1 1" />
        </material>
      </visual>
    <visual name="lid_badge">
      <origin xyz="0.049 0.235 0.0153" rpy="0 0 0" />
      <geometry>
        <box size="0.062 0.012 0.0009" />
        </geometry>
      <material name="charcoal_plastic">
        <color rgba="0.19 0.2 0.22 1" />
        </material>
      </visual>
    <visual name="lid_front_bumper_1">
      <origin xyz="-0.16 0.25 -0.0014" rpy="0 0 0" />
      <geometry>
        <box size="0.018 0.012 0.003" />
        </geometry>
      <material name="rubber">
        <color rgba="0.11 0.11 0.12 1" />
        </material>
      </visual>
    <visual name="lid_front_bumper_2">
      <origin xyz="0.068 0.25 -0.0014" rpy="0 0 0" />
      <geometry>
        <box size="0.018 0.012 0.003" />
        </geometry>
      <material name="rubber">
        <color rgba="0.11 0.11 0.12 1" />
        </material>
      </visual>
    <visual name="lid_rear_bumper_1">
      <origin xyz="-0.168 0.018 -0.0011" rpy="0 0 0" />
      <geometry>
        <box size="0.018 0.01 0.0024" />
        </geometry>
      <material name="rubber">
        <color rgba="0.11 0.11 0.12 1" />
        </material>
      </visual>
    <visual name="lid_rear_bumper_2">
      <origin xyz="0.076 0.018 -0.0011" rpy="0 0 0" />
      <geometry>
        <box size="0.018 0.01 0.0024" />
        </geometry>
      <material name="rubber">
        <color rgba="0.11 0.11 0.12 1" />
        </material>
      </visual>
    </link>
  <joint name="lid_hinge" type="revolute">
    <origin xyz="-0.046 -0.142 0.052" rpy="0 0 0" />
    <parent link="base" />
    <child link="lid" />
    <axis xyz="1 0 0" />
    <limit effort="16" velocity="1.5" lower="0" upper="1.16937" />
    </joint>
  </robot>
