<robot name="windshield_wiper_assembly">
  <material name="painted_black">
    <color rgba="0.12 0.12 0.13 1" />
  </material>
  <material name="textured_black">
    <color rgba="0.08 0.08 0.09 1" />
  </material>
  <material name="rubber_black">
    <color rgba="0.03 0.03 0.03 1" />
  </material>
  <material name="brushed_steel">
    <color rgba="0.57 0.59 0.62 1" />
  </material>
  <link name="base_mount">
    <inertial>
      <origin xyz="0 0 0.012" rpy="0 0 0" />
      <mass value="0.38" />
      <inertia ixx="5.06667e-05" ixy="0" ixz="0" iyy="0.000103867" iyz="0" izz="0.000118053" />
    </inertial>
    <visual>
      <geometry>
        <mesh filename="meshes/wiper_base_mount.glb" />
      </geometry>
      <material name="textured_black">
        <color rgba="0.08 0.08 0.09 1" />
      </material>
    </visual>
    <visual>
      <origin xyz="0 0 0.018" rpy="0 0 0" />
      <geometry>
        <cylinder radius="0.012" length="0.008" />
      </geometry>
      <material name="brushed_steel">
        <color rgba="0.57 0.59 0.62 1" />
      </material>
    </visual>
    <visual>
      <origin xyz="0 0 0.0115" rpy="0 0 0" />
      <geometry>
        <cylinder radius="0.015" length="0.0025" />
      </geometry>
      <material name="brushed_steel">
        <color rgba="0.57 0.59 0.62 1" />
      </material>
    </visual>
    <collision name="base_mount__visual_1__hull_001">
      <geometry>
        <mesh filename="meshes/collision/cache/807c18697fb0a49e5828ee30__hull_001.obj" />
      </geometry>
    </collision>
    <collision name="base_mount__visual_1__hull_002">
      <geometry>
        <mesh filename="meshes/collision/cache/807c18697fb0a49e5828ee30__hull_002.obj" />
      </geometry>
    </collision>
    <collision name="base_mount__visual_1__hull_003">
      <geometry>
        <mesh filename="meshes/collision/cache/807c18697fb0a49e5828ee30__hull_003.obj" />
      </geometry>
    </collision>
    <collision name="base_mount__visual_2">
      <origin xyz="0 0 0.018" rpy="0 0 0" />
      <geometry>
        <cylinder radius="0.012" length="0.008" />
      </geometry>
    </collision>
    <collision name="base_mount__visual_3">
      <origin xyz="0 0 0.0115" rpy="0 0 0" />
      <geometry>
        <cylinder radius="0.015" length="0.0025" />
      </geometry>
    </collision>
  </link>
  <link name="wiper_arm">
    <inertial>
      <origin xyz="0.16 0.002 0.004" rpy="0 0 0" />
      <mass value="0.2" />
      <inertia ixx="1.79333e-05" ixy="0" ixz="0" iyy="0.00171333" iyz="0" izz="0.00171793" />
    </inertial>
    <visual>
      <geometry>
        <mesh filename="meshes/wiper_arm.glb" />
      </geometry>
      <material name="painted_black">
        <color rgba="0.12 0.12 0.13 1" />
      </material>
    </visual>
    <visual>
      <origin xyz="0 0 0.0015" rpy="0 0 0" />
      <geometry>
        <cylinder radius="0.01" length="0.004" />
      </geometry>
      <material name="brushed_steel">
        <color rgba="0.57 0.59 0.62 1" />
      </material>
    </visual>
    <collision name="wiper_arm__visual_1__hull_001">
      <geometry>
        <mesh filename="meshes/collision/cache/0cc2c09e2bc76c85315931c0__hull_001.obj" />
      </geometry>
    </collision>
    <collision name="wiper_arm__visual_2">
      <origin xyz="0 0 0.0015" rpy="0 0 0" />
      <geometry>
        <cylinder radius="0.01" length="0.004" />
      </geometry>
    </collision>
  </link>
  <link name="blade_support">
    <inertial>
      <origin xyz="0 0 -0.005" rpy="0 0 0" />
      <mass value="0.16" />
      <inertia ixx="0.00154667" ixy="0" ixz="0" iyy="1.06667e-05" iyz="0" izz="0.00154667" />
    </inertial>
    <visual>
      <geometry>
        <mesh filename="meshes/wiper_blade_frame.glb" />
      </geometry>
      <material name="painted_black">
        <color rgba="0.12 0.12 0.13 1" />
      </material>
    </visual>
    <visual>
      <origin xyz="0 0 -0.01" rpy="0 0 0" />
      <geometry>
        <box size="0.0045 0.34 0.009" />
      </geometry>
      <material name="rubber_black">
        <color rgba="0.03 0.03 0.03 1" />
      </material>
    </visual>
    <visual>
      <origin xyz="0 0 0" rpy="1.5708 0 0" />
      <geometry>
        <cylinder radius="0.003" length="0.026" />
      </geometry>
      <material name="brushed_steel">
        <color rgba="0.57 0.59 0.62 1" />
      </material>
    </visual>
    <collision name="blade_support__visual_1__hull_001">
      <geometry>
        <mesh filename="meshes/collision/cache/40cf37228a6911724cd7f913__hull_001.obj" />
      </geometry>
    </collision>
    <collision name="blade_support__visual_2">
      <origin xyz="0 0 -0.01" rpy="0 0 0" />
      <geometry>
        <box size="0.0045 0.34 0.009" />
      </geometry>
    </collision>
    <collision name="blade_support__visual_3">
      <origin xyz="0 0 0" rpy="1.5708 0 0" />
      <geometry>
        <cylinder radius="0.003" length="0.026" />
      </geometry>
    </collision>
  </link>
  <joint name="wiper_sweep" type="revolute">
    <origin xyz="0 0 0.018" rpy="0 0 0" />
    <parent link="base_mount" />
    <child link="wiper_arm" />
    <axis xyz="0 0 1" />
    <limit effort="12" velocity="2.4" lower="-0.55" upper="1.25" />
  </joint>
  <joint name="blade_pitch" type="revolute">
    <origin xyz="0.3 0.0045 0" rpy="0 0 0" />
    <parent link="wiper_arm" />
    <child link="blade_support" />
    <axis xyz="0 1 0" />
    <limit effort="4" velocity="1.8" lower="-0.3" upper="0.3" />
  </joint>
</robot>