<robot name="dj_controller">
  <material name="shell_black">
    <color rgba="0.1 0.11 0.12 1" />
    </material>
  <material name="panel_charcoal">
    <color rgba="0.17 0.18 0.2 1" />
    </material>
  <material name="trim_graphite">
    <color rgba="0.26 0.27 0.29 1" />
    </material>
  <material name="brushed_aluminum">
    <color rgba="0.69 0.71 0.74 1" />
    </material>
  <material name="rubber_black">
    <color rgba="0.06 0.06 0.07 1" />
    </material>
  <material name="screen_glass">
    <color rgba="0.23 0.44 0.57 0.62" />
    </material>
  <material name="pad_amber">
    <color rgba="0.78 0.45 0.16 1" />
    </material>
  <material name="pad_cyan">
    <color rgba="0.18 0.62 0.76 1" />
    </material>
  <material name="play_green">
    <color rgba="0.23 0.63 0.28 1" />
    </material>
  <material name="cue_orange">
    <color rgba="0.84 0.49 0.18 1" />
    </material>
  <material name="internal_support">
    <color rgba="0 0 0 0" />
    </material>
  <link name="body">
    <inertial>
      <origin xyz="0 0 0.02" rpy="0 0 0" />
      <mass value="2.8" />
      <inertia ixx="0.0116667" ixy="0" ixz="0" iyy="0.0273467" iyz="0" izz="0.0382667" />
      </inertial>
    <visual>
      <geometry>
        <mesh filename="assets/meshes/dj_controller_body.obj" />
        </geometry>
      <material name="shell_black">
        <color rgba="0.1 0.11 0.12 1" />
        </material>
      </visual>
    <visual>
      <origin xyz="-0.135 -0.082 0.002" rpy="0 0 0" />
      <geometry>
        <box size="0.028 0.022 0.008" />
        </geometry>
      <material name="rubber_black">
        <color rgba="0.06 0.06 0.07 1" />
        </material>
      </visual>
    <visual>
      <origin xyz="-0.135 0.082 0.002" rpy="0 0 0" />
      <geometry>
        <box size="0.028 0.022 0.008" />
        </geometry>
      <material name="rubber_black">
        <color rgba="0.06 0.06 0.07 1" />
        </material>
      </visual>
    <visual>
      <origin xyz="0.135 -0.082 0.002" rpy="0 0 0" />
      <geometry>
        <box size="0.028 0.022 0.008" />
        </geometry>
      <material name="rubber_black">
        <color rgba="0.06 0.06 0.07 1" />
        </material>
      </visual>
    <visual>
      <origin xyz="0.135 0.082 0.002" rpy="0 0 0" />
      <geometry>
        <box size="0.028 0.022 0.008" />
        </geometry>
      <material name="rubber_black">
        <color rgba="0.06 0.06 0.07 1" />
        </material>
      </visual>
    </link>
  <link name="top_panel">
    <inertial>
      <origin xyz="0 0.015 0.046" rpy="0 0 0" />
      <mass value="0.85" />
      <inertia ixx="0.00211848" ixy="0" ixz="0" iyy="0.00736723" iyz="0" izz="0.00943982" />
      </inertial>
    <visual>
      <origin xyz="0 0.005 0.027" rpy="0 0 0" />
      <geometry>
        <box size="0.312 0.206 0.054" />
        </geometry>
      <material name="internal_support">
        <color rgba="0 0 0 0" />
        </material>
      </visual>
    <visual>
      <origin xyz="0 0.015 0.038" rpy="0 0 0" />
      <geometry>
        <box size="0.322 0.172 0.006" />
        </geometry>
      <material name="panel_charcoal">
        <color rgba="0.17 0.18 0.2 1" />
        </material>
      </visual>
    <visual>
      <origin xyz="0 0.015 0.0413" rpy="0 0 0" />
      <geometry>
        <box size="0.078 0.166 0.0016" />
        </geometry>
      <material name="trim_graphite">
        <color rgba="0.26 0.27 0.29 1" />
        </material>
      </visual>
    <visual>
      <origin xyz="0 0.094 0.046" rpy="0 0 0" />
      <geometry>
        <box size="0.088 0.029 0.008" />
        </geometry>
      <material name="trim_graphite">
        <color rgba="0.26 0.27 0.29 1" />
        </material>
      </visual>
    <visual>
      <origin xyz="0 0.094 0.0508" rpy="0 0 0" />
      <geometry>
        <box size="0.08 0.023 0.0015" />
        </geometry>
      <material name="screen_glass">
        <color rgba="0.23 0.44 0.57 0.62" />
        </material>
      </visual>
    <visual>
      <origin xyz="0 -0.086 0.0413" rpy="0 0 0" />
      <geometry>
        <box size="0.118 0.01 0.0016" />
        </geometry>
      <material name="trim_graphite">
        <color rgba="0.26 0.27 0.29 1" />
        </material>
      </visual>
    <visual>
      <origin xyz="0 -0.015 0.0413" rpy="0 0 0" />
      <geometry>
        <box size="0.012 0.094 0.0016" />
        </geometry>
      <material name="trim_graphite">
        <color rgba="0.26 0.27 0.29 1" />
        </material>
      </visual>
    <visual>
      <origin xyz="0 0.058 0.0412" rpy="0 0 0" />
      <geometry>
        <cylinder radius="0.02" length="0.0022" />
        </geometry>
      <material name="brushed_aluminum">
        <color rgba="0.69 0.71 0.74 1" />
        </material>
      </visual>
    <visual>
      <origin xyz="-0.105 0.028 0.044" rpy="0 0 0" />
      <geometry>
        <cylinder radius="0.046" length="0.007" />
        </geometry>
      <material name="rubber_black">
        <color rgba="0.06 0.06 0.07 1" />
        </material>
      </visual>
    <visual>
      <origin xyz="-0.105 0.028 0.0455" rpy="0 0 0" />
      <geometry>
        <cylinder radius="0.039" length="0.005" />
        </geometry>
      <material name="brushed_aluminum">
        <color rgba="0.69 0.71 0.74 1" />
        </material>
      </visual>
    <visual>
      <origin xyz="-0.105 0.028 0.049" rpy="0 0 0" />
      <geometry>
        <cylinder radius="0.016" length="0.002" />
        </geometry>
      <material name="trim_graphite">
        <color rgba="0.26 0.27 0.29 1" />
        </material>
      </visual>
    <visual>
      <origin xyz="-0.078 0.028 0.0488" rpy="0 0 0" />
      <geometry>
        <box size="0.003 0.016 0.0015" />
        </geometry>
      <material name="cue_orange">
        <color rgba="0.84 0.49 0.18 1" />
        </material>
      </visual>
    <visual>
      <origin xyz="0.105 0.028 0.044" rpy="0 0 0" />
      <geometry>
        <cylinder radius="0.046" length="0.007" />
        </geometry>
      <material name="rubber_black">
        <color rgba="0.06 0.06 0.07 1" />
        </material>
      </visual>
    <visual>
      <origin xyz="0.105 0.028 0.0455" rpy="0 0 0" />
      <geometry>
        <cylinder radius="0.039" length="0.005" />
        </geometry>
      <material name="brushed_aluminum">
        <color rgba="0.69 0.71 0.74 1" />
        </material>
      </visual>
    <visual>
      <origin xyz="0.105 0.028 0.049" rpy="0 0 0" />
      <geometry>
        <cylinder radius="0.016" length="0.002" />
        </geometry>
      <material name="trim_graphite">
        <color rgba="0.26 0.27 0.29 1" />
        </material>
      </visual>
    <visual>
      <origin xyz="0.132 0.028 0.0488" rpy="0 0 0" />
      <geometry>
        <box size="0.003 0.016 0.0015" />
        </geometry>
      <material name="cue_orange">
        <color rgba="0.84 0.49 0.18 1" />
        </material>
      </visual>
    <visual>
      <origin xyz="-0.036 0.048 0.041" rpy="0 0 0" />
      <geometry>
        <cylinder radius="0.0132" length="0.0018" />
        </geometry>
      <material name="trim_graphite">
        <color rgba="0.26 0.27 0.29 1" />
        </material>
      </visual>
    <visual>
      <origin xyz="-0.036 0.048 0.0458" rpy="0 0 0" />
      <geometry>
        <cylinder radius="0.011" length="0.01" />
        </geometry>
      <material name="rubber_black">
        <color rgba="0.06 0.06 0.07 1" />
        </material>
      </visual>
    <visual>
      <origin xyz="-0.036 0.048 0.0512" rpy="0 0 0" />
      <geometry>
        <cylinder radius="0.0033" length="0.0024" />
        </geometry>
      <material name="brushed_aluminum">
        <color rgba="0.69 0.71 0.74 1" />
        </material>
      </visual>
    <visual>
      <origin xyz="-0.03138 0.048 0.0515" rpy="0 0 0" />
      <geometry>
        <box size="0.0026 0.01265 0.0015" />
        </geometry>
      <material name="brushed_aluminum">
        <color rgba="0.69 0.71 0.74 1" />
        </material>
      </visual>
    <visual>
      <origin xyz="-0.036 0.016 0.041" rpy="0 0 0" />
      <geometry>
        <cylinder radius="0.0132" length="0.0018" />
        </geometry>
      <material name="trim_graphite">
        <color rgba="0.26 0.27 0.29 1" />
        </material>
      </visual>
    <visual>
      <origin xyz="-0.036 0.016 0.0458" rpy="0 0 0" />
      <geometry>
        <cylinder radius="0.011" length="0.01" />
        </geometry>
      <material name="rubber_black">
        <color rgba="0.06 0.06 0.07 1" />
        </material>
      </visual>
    <visual>
      <origin xyz="-0.036 0.016 0.0512" rpy="0 0 0" />
      <geometry>
        <cylinder radius="0.0033" length="0.0024" />
        </geometry>
      <material name="brushed_aluminum">
        <color rgba="0.69 0.71 0.74 1" />
        </material>
      </visual>
    <visual>
      <origin xyz="-0.03138 0.016 0.0515" rpy="0 0 0" />
      <geometry>
        <box size="0.0026 0.01265 0.0015" />
        </geometry>
      <material name="brushed_aluminum">
        <color rgba="0.69 0.71 0.74 1" />
        </material>
      </visual>
    <visual>
      <origin xyz="-0.036 -0.016 0.041" rpy="0 0 0" />
      <geometry>
        <cylinder radius="0.0132" length="0.0018" />
        </geometry>
      <material name="trim_graphite">
        <color rgba="0.26 0.27 0.29 1" />
        </material>
      </visual>
    <visual>
      <origin xyz="-0.036 -0.016 0.0458" rpy="0 0 0" />
      <geometry>
        <cylinder radius="0.011" length="0.01" />
        </geometry>
      <material name="rubber_black">
        <color rgba="0.06 0.06 0.07 1" />
        </material>
      </visual>
    <visual>
      <origin xyz="-0.036 -0.016 0.0512" rpy="0 0 0" />
      <geometry>
        <cylinder radius="0.0033" length="0.0024" />
        </geometry>
      <material name="brushed_aluminum">
        <color rgba="0.69 0.71 0.74 1" />
        </material>
      </visual>
    <visual>
      <origin xyz="-0.03138 -0.016 0.0515" rpy="0 0 0" />
      <geometry>
        <box size="0.0026 0.01265 0.0015" />
        </geometry>
      <material name="brushed_aluminum">
        <color rgba="0.69 0.71 0.74 1" />
        </material>
      </visual>
    <visual>
      <origin xyz="0.036 0.048 0.041" rpy="0 0 0" />
      <geometry>
        <cylinder radius="0.0132" length="0.0018" />
        </geometry>
      <material name="trim_graphite">
        <color rgba="0.26 0.27 0.29 1" />
        </material>
      </visual>
    <visual>
      <origin xyz="0.036 0.048 0.0458" rpy="0 0 0" />
      <geometry>
        <cylinder radius="0.011" length="0.01" />
        </geometry>
      <material name="rubber_black">
        <color rgba="0.06 0.06 0.07 1" />
        </material>
      </visual>
    <visual>
      <origin xyz="0.036 0.048 0.0512" rpy="0 0 0" />
      <geometry>
        <cylinder radius="0.0033" length="0.0024" />
        </geometry>
      <material name="brushed_aluminum">
        <color rgba="0.69 0.71 0.74 1" />
        </material>
      </visual>
    <visual>
      <origin xyz="0.04062 0.048 0.0515" rpy="0 0 0" />
      <geometry>
        <box size="0.0026 0.01265 0.0015" />
        </geometry>
      <material name="brushed_aluminum">
        <color rgba="0.69 0.71 0.74 1" />
        </material>
      </visual>
    <visual>
      <origin xyz="0.036 0.016 0.041" rpy="0 0 0" />
      <geometry>
        <cylinder radius="0.0132" length="0.0018" />
        </geometry>
      <material name="trim_graphite">
        <color rgba="0.26 0.27 0.29 1" />
        </material>
      </visual>
    <visual>
      <origin xyz="0.036 0.016 0.0458" rpy="0 0 0" />
      <geometry>
        <cylinder radius="0.011" length="0.01" />
        </geometry>
      <material name="rubber_black">
        <color rgba="0.06 0.06 0.07 1" />
        </material>
      </visual>
    <visual>
      <origin xyz="0.036 0.016 0.0512" rpy="0 0 0" />
      <geometry>
        <cylinder radius="0.0033" length="0.0024" />
        </geometry>
      <material name="brushed_aluminum">
        <color rgba="0.69 0.71 0.74 1" />
        </material>
      </visual>
    <visual>
      <origin xyz="0.04062 0.016 0.0515" rpy="0 0 0" />
      <geometry>
        <box size="0.0026 0.01265 0.0015" />
        </geometry>
      <material name="brushed_aluminum">
        <color rgba="0.69 0.71 0.74 1" />
        </material>
      </visual>
    <visual>
      <origin xyz="0.036 -0.016 0.041" rpy="0 0 0" />
      <geometry>
        <cylinder radius="0.0132" length="0.0018" />
        </geometry>
      <material name="trim_graphite">
        <color rgba="0.26 0.27 0.29 1" />
        </material>
      </visual>
    <visual>
      <origin xyz="0.036 -0.016 0.0458" rpy="0 0 0" />
      <geometry>
        <cylinder radius="0.011" length="0.01" />
        </geometry>
      <material name="rubber_black">
        <color rgba="0.06 0.06 0.07 1" />
        </material>
      </visual>
    <visual>
      <origin xyz="0.036 -0.016 0.0512" rpy="0 0 0" />
      <geometry>
        <cylinder radius="0.0033" length="0.0024" />
        </geometry>
      <material name="brushed_aluminum">
        <color rgba="0.69 0.71 0.74 1" />
        </material>
      </visual>
    <visual>
      <origin xyz="0.04062 -0.016 0.0515" rpy="0 0 0" />
      <geometry>
        <box size="0.0026 0.01265 0.0015" />
        </geometry>
      <material name="brushed_aluminum">
        <color rgba="0.69 0.71 0.74 1" />
        </material>
      </visual>
    <visual>
      <origin xyz="-0.048 0.068 0.042" rpy="0 0 0" />
      <geometry>
        <box size="0.016 0.0085 0.003" />
        </geometry>
      <material name="trim_graphite">
        <color rgba="0.26 0.27 0.29 1" />
        </material>
      </visual>
    <visual>
      <origin xyz="-0.022 0.068 0.042" rpy="0 0 0" />
      <geometry>
        <box size="0.016 0.0085 0.003" />
        </geometry>
      <material name="trim_graphite">
        <color rgba="0.26 0.27 0.29 1" />
        </material>
      </visual>
    <visual>
      <origin xyz="0.022 0.068 0.042" rpy="0 0 0" />
      <geometry>
        <box size="0.016 0.0085 0.003" />
        </geometry>
      <material name="trim_graphite">
        <color rgba="0.26 0.27 0.29 1" />
        </material>
      </visual>
    <visual>
      <origin xyz="0.048 0.068 0.042" rpy="0 0 0" />
      <geometry>
        <box size="0.016 0.0085 0.003" />
        </geometry>
      <material name="trim_graphite">
        <color rgba="0.26 0.27 0.29 1" />
        </material>
      </visual>
    <visual>
      <origin xyz="-0.052 -0.054 0.0426" rpy="0 0 0" />
      <geometry>
        <box size="0.018 0.018 0.0042" />
        </geometry>
      <material name="cue_orange">
        <color rgba="0.84 0.49 0.18 1" />
        </material>
      </visual>
    <visual>
      <origin xyz="0.052 -0.054 0.0426" rpy="0 0 0" />
      <geometry>
        <box size="0.018 0.018 0.0042" />
        </geometry>
      <material name="play_green">
        <color rgba="0.23 0.63 0.28 1" />
        </material>
      </visual>
    <visual>
      <origin xyz="-0.124 -0.056 0.0426" rpy="0 0 0" />
      <geometry>
        <box size="0.021 0.021 0.0042" />
        </geometry>
      <material name="pad_amber">
        <color rgba="0.78 0.45 0.16 1" />
        </material>
      </visual>
    <visual>
      <origin xyz="-0.124 -0.056 0.0452" rpy="0 0 0" />
      <geometry>
        <box size="0.01596 0.01596 0.0015" />
        </geometry>
      <material name="pad_amber">
        <color rgba="0.78 0.45 0.16 1" />
        </material>
      </visual>
    <visual>
      <origin xyz="-0.124 -0.032 0.0426" rpy="0 0 0" />
      <geometry>
        <box size="0.021 0.021 0.0042" />
        </geometry>
      <material name="pad_cyan">
        <color rgba="0.18 0.62 0.76 1" />
        </material>
      </visual>
    <visual>
      <origin xyz="-0.124 -0.032 0.0452" rpy="0 0 0" />
      <geometry>
        <box size="0.01596 0.01596 0.0015" />
        </geometry>
      <material name="pad_cyan">
        <color rgba="0.18 0.62 0.76 1" />
        </material>
      </visual>
    <visual>
      <origin xyz="-0.095 -0.056 0.0426" rpy="0 0 0" />
      <geometry>
        <box size="0.021 0.021 0.0042" />
        </geometry>
      <material name="pad_amber">
        <color rgba="0.78 0.45 0.16 1" />
        </material>
      </visual>
    <visual>
      <origin xyz="-0.095 -0.056 0.0452" rpy="0 0 0" />
      <geometry>
        <box size="0.01596 0.01596 0.0015" />
        </geometry>
      <material name="pad_amber">
        <color rgba="0.78 0.45 0.16 1" />
        </material>
      </visual>
    <visual>
      <origin xyz="-0.095 -0.032 0.0426" rpy="0 0 0" />
      <geometry>
        <box size="0.021 0.021 0.0042" />
        </geometry>
      <material name="pad_cyan">
        <color rgba="0.18 0.62 0.76 1" />
        </material>
      </visual>
    <visual>
      <origin xyz="-0.095 -0.032 0.0452" rpy="0 0 0" />
      <geometry>
        <box size="0.01596 0.01596 0.0015" />
        </geometry>
      <material name="pad_cyan">
        <color rgba="0.18 0.62 0.76 1" />
        </material>
      </visual>
    <visual>
      <origin xyz="0.095 -0.056 0.0426" rpy="0 0 0" />
      <geometry>
        <box size="0.021 0.021 0.0042" />
        </geometry>
      <material name="pad_amber">
        <color rgba="0.78 0.45 0.16 1" />
        </material>
      </visual>
    <visual>
      <origin xyz="0.095 -0.056 0.0452" rpy="0 0 0" />
      <geometry>
        <box size="0.01596 0.01596 0.0015" />
        </geometry>
      <material name="pad_amber">
        <color rgba="0.78 0.45 0.16 1" />
        </material>
      </visual>
    <visual>
      <origin xyz="0.095 -0.032 0.0426" rpy="0 0 0" />
      <geometry>
        <box size="0.021 0.021 0.0042" />
        </geometry>
      <material name="pad_cyan">
        <color rgba="0.18 0.62 0.76 1" />
        </material>
      </visual>
    <visual>
      <origin xyz="0.095 -0.032 0.0452" rpy="0 0 0" />
      <geometry>
        <box size="0.01596 0.01596 0.0015" />
        </geometry>
      <material name="pad_cyan">
        <color rgba="0.18 0.62 0.76 1" />
        </material>
      </visual>
    <visual>
      <origin xyz="0.124 -0.056 0.0426" rpy="0 0 0" />
      <geometry>
        <box size="0.021 0.021 0.0042" />
        </geometry>
      <material name="pad_amber">
        <color rgba="0.78 0.45 0.16 1" />
        </material>
      </visual>
    <visual>
      <origin xyz="0.124 -0.056 0.0452" rpy="0 0 0" />
      <geometry>
        <box size="0.01596 0.01596 0.0015" />
        </geometry>
      <material name="pad_amber">
        <color rgba="0.78 0.45 0.16 1" />
        </material>
      </visual>
    <visual>
      <origin xyz="0.124 -0.032 0.0426" rpy="0 0 0" />
      <geometry>
        <box size="0.021 0.021 0.0042" />
        </geometry>
      <material name="pad_cyan">
        <color rgba="0.18 0.62 0.76 1" />
        </material>
      </visual>
    <visual>
      <origin xyz="0.124 -0.032 0.0452" rpy="0 0 0" />
      <geometry>
        <box size="0.01596 0.01596 0.0015" />
        </geometry>
      <material name="pad_cyan">
        <color rgba="0.18 0.62 0.76 1" />
        </material>
      </visual>
    </link>
  <link name="channel_fader">
    <inertial>
      <origin xyz="0 0 0.0065" rpy="0 0 0" />
      <mass value="0.04" />
      <inertia ixx="1.25633e-05" ixy="0" ixz="0" iyy="1.31333e-06" iyz="0" izz="1.275e-05" />
      </inertial>
    <visual>
      <geometry>
        <box size="0.005 0.06 0.004" />
        </geometry>
      <material name="trim_graphite">
        <color rgba="0.26 0.27 0.29 1" />
        </material>
      </visual>
    <visual>
      <origin xyz="0 0 0.0065" rpy="0 0 0" />
      <geometry>
        <box size="0.015 0.024 0.013" />
        </geometry>
      <material name="brushed_aluminum">
        <color rgba="0.69 0.71 0.74 1" />
        </material>
      </visual>
    <visual>
      <origin xyz="0 0 0.0133" rpy="0 0 0" />
      <geometry>
        <box size="0.01 0.019 0.0018" />
        </geometry>
      <material name="rubber_black">
        <color rgba="0.06 0.06 0.07 1" />
        </material>
      </visual>
    </link>
  <link name="crossfader">
    <inertial>
      <origin xyz="0 0 0.006" rpy="0 0 0" />
      <mass value="0.05" />
      <inertia ixx="1.80417e-06" ixy="0" ixz="0" iyy="5.10167e-05" iyz="0" izz="5.16208e-05" />
      </inertial>
    <visual>
      <geometry>
        <box size="0.11 0.004 0.004" />
        </geometry>
      <material name="trim_graphite">
        <color rgba="0.26 0.27 0.29 1" />
        </material>
      </visual>
    <visual>
      <origin xyz="0 0 0.006" rpy="0 0 0" />
      <geometry>
        <box size="0.034 0.017 0.012" />
        </geometry>
      <material name="brushed_aluminum">
        <color rgba="0.69 0.71 0.74 1" />
        </material>
      </visual>
    <visual>
      <origin xyz="0 0 0.0122" rpy="0 0 0" />
      <geometry>
        <box size="0.022 0.01 0.0016" />
        </geometry>
      <material name="rubber_black">
        <color rgba="0.06 0.06 0.07 1" />
        </material>
      </visual>
    </link>
  <link name="browse_knob">
    <inertial>
      <origin xyz="0 0 0.01" rpy="0 0 0" />
      <mass value="0.05" />
      <inertia ixx="5.27917e-06" ixy="0" ixz="0" iyy="5.27917e-06" iyz="0" izz="7.225e-06" />
      </inertial>
    <visual>
      <origin xyz="0 0 0.001" rpy="0 0 0" />
      <geometry>
        <cylinder radius="0.005" length="0.008" />
        </geometry>
      <material name="brushed_aluminum">
        <color rgba="0.69 0.71 0.74 1" />
        </material>
      </visual>
    <visual>
      <origin xyz="0 0 0.006" rpy="0 0 0" />
      <geometry>
        <cylinder radius="0.017" length="0.004" />
        </geometry>
      <material name="rubber_black">
        <color rgba="0.06 0.06 0.07 1" />
        </material>
      </visual>
    <visual>
      <origin xyz="0 0 0.011" rpy="0 0 0" />
      <geometry>
        <cylinder radius="0.015" length="0.014" />
        </geometry>
      <material name="rubber_black">
        <color rgba="0.06 0.06 0.07 1" />
        </material>
      </visual>
    <visual>
      <origin xyz="0 0 0.0195" rpy="0 0 0" />
      <geometry>
        <cylinder radius="0.0105" length="0.003" />
        </geometry>
      <material name="brushed_aluminum">
        <color rgba="0.69 0.71 0.74 1" />
        </material>
      </visual>
    <visual>
      <origin xyz="0.009 0 0.02" rpy="0 0 0" />
      <geometry>
        <box size="0.004 0.018 0.0018" />
        </geometry>
      <material name="brushed_aluminum">
        <color rgba="0.69 0.71 0.74 1" />
        </material>
      </visual>
    </link>
  <joint name="body_to_top_panel" type="fixed">
    <parent link="body" />
    <child link="top_panel" />
    </joint>
  <joint name="channel_fader_slide" type="prismatic">
    <origin xyz="0 -0.015 0.041" rpy="0 0 0" />
    <parent link="top_panel" />
    <child link="channel_fader" />
    <axis xyz="0 1 0" />
    <limit effort="10" velocity="0.25" lower="-0.032" upper="0.032" />
    </joint>
  <joint name="crossfader_slide" type="prismatic">
    <origin xyz="0 -0.086 0.041" rpy="0 0 0" />
    <parent link="top_panel" />
    <child link="crossfader" />
    <axis xyz="1 0 0" />
    <limit effort="12" velocity="0.3" lower="-0.055" upper="0.055" />
    </joint>
  <joint name="browse_knob_turn" type="revolute">
    <origin xyz="0 0.058 0.041" rpy="0 0 0" />
    <parent link="top_panel" />
    <child link="browse_knob" />
    <axis xyz="0 0 1" />
    <limit effort="2" velocity="4.5" lower="-2.4" upper="2.4" />
    </joint>
  </robot>
