<robot name="front_load_washer">
  <material name="white_enamel">
    <color rgba="0.95 0.96 0.97 1" />
    </material>
  <material name="graphite">
    <color rgba="0.18 0.19 0.21 1" />
    </material>
  <material name="matte_black">
    <color rgba="0.08 0.08 0.09 1" />
    </material>
  <material name="rubber">
    <color rgba="0.12 0.12 0.13 1" />
    </material>
  <material name="stainless">
    <color rgba="0.7 0.72 0.74 1" />
    </material>
  <material name="silver_plastic">
    <color rgba="0.78 0.8 0.82 1" />
    </material>
  <material name="tinted_glass">
    <color rgba="0.58 0.68 0.76 0.28" />
    </material>
  <material name="screen_black">
    <color rgba="0.05 0.06 0.07 0.94" />
    </material>
  <material name="accent">
    <color rgba="0.96 0.53 0.2 1" />
    </material>
  <link name="cabinet">
    <inertial>
      <origin xyz="0 0 0.424" rpy="0 0 0" />
      <mass value="58" />
      <inertia ixx="5.42459" ixy="0" ixz="0" iyy="5.20409" iyz="0" izz="3.67734" />
      </inertial>
    <visual>
      <origin xyz="0 0 0.015" rpy="0 0 0" />
      <geometry>
        <box size="0.562 0.595 0.03" />
        </geometry>
      <material name="graphite">
        <color rgba="0.18 0.19 0.21 1" />
        </material>
      </visual>
    <visual>
      <origin xyz="-0.29 0 0.429" rpy="0 0 0" />
      <geometry>
        <box size="0.018 0.635 0.798" />
        </geometry>
      <material name="white_enamel">
        <color rgba="0.95 0.96 0.97 1" />
        </material>
      </visual>
    <visual>
      <origin xyz="0.29 0 0.429" rpy="0 0 0" />
      <geometry>
        <box size="0.018 0.635 0.798" />
        </geometry>
      <material name="white_enamel">
        <color rgba="0.95 0.96 0.97 1" />
        </material>
      </visual>
    <visual>
      <origin xyz="0 -0.3085 0.429" rpy="0 0 0" />
      <geometry>
        <box size="0.562 0.018 0.798" />
        </geometry>
      <material name="white_enamel">
        <color rgba="0.95 0.96 0.97 1" />
        </material>
      </visual>
    <visual>
      <origin xyz="0 0 0.838" rpy="0 0 0" />
      <geometry>
        <box size="0.598 0.635 0.02" />
        </geometry>
      <material name="white_enamel">
        <color rgba="0.95 0.96 0.97 1" />
        </material>
      </visual>
    <visual>
      <origin xyz="0 0.309 0.386" rpy="0 0 0" />
      <geometry>
        <mesh filename="assets/meshes/washer_lower_panel.obj" />
        </geometry>
      <material name="white_enamel">
        <color rgba="0.95 0.96 0.97 1" />
        </material>
      </visual>
    <visual>
      <origin xyz="0 0.291 0.775" rpy="0 0 0" />
      <geometry>
        <box size="0.562 0.052 0.112" />
        </geometry>
      <material name="white_enamel">
        <color rgba="0.95 0.96 0.97 1" />
        </material>
      </visual>
    <visual>
      <origin xyz="0 0.319 0.782" rpy="0 0 0" />
      <geometry>
        <mesh filename="assets/meshes/washer_fascia.obj" />
        </geometry>
      <material name="graphite">
        <color rgba="0.18 0.19 0.21 1" />
        </material>
      </visual>
    <visual>
      <origin xyz="-0.17 0.283 0.75" rpy="0 0 0" />
      <geometry>
        <box size="0.175 0.014 0.078" />
        </geometry>
      <material name="screen_black">
        <color rgba="0.05 0.06 0.07 0.94" />
        </material>
      </visual>
    <visual>
      <origin xyz="0.198 0.321 0.787" rpy="0 0 0" />
      <geometry>
        <box size="0.164 0.008 0.05" />
        </geometry>
      <material name="screen_black">
        <color rgba="0.05 0.06 0.07 0.94" />
        </material>
      </visual>
    <visual>
      <origin xyz="-0.018 0.321 0.736" rpy="0 0 0" />
      <geometry>
        <box size="0.024 0.006 0.012" />
        </geometry>
      <material name="graphite">
        <color rgba="0.18 0.19 0.21 1" />
        </material>
      </visual>
    <visual>
      <origin xyz="0.02 0.321 0.736" rpy="0 0 0" />
      <geometry>
        <box size="0.024 0.006 0.012" />
        </geometry>
      <material name="graphite">
        <color rgba="0.18 0.19 0.21 1" />
        </material>
      </visual>
    <visual>
      <origin xyz="0.058 0.321 0.736" rpy="0 0 0" />
      <geometry>
        <box size="0.024 0.006 0.012" />
        </geometry>
      <material name="graphite">
        <color rgba="0.18 0.19 0.21 1" />
        </material>
      </visual>
    <visual>
      <origin xyz="0.096 0.321 0.736" rpy="0 0 0" />
      <geometry>
        <box size="0.024 0.006 0.012" />
        </geometry>
      <material name="graphite">
        <color rgba="0.18 0.19 0.21 1" />
        </material>
      </visual>
    <visual>
      <origin xyz="0.134 0.321 0.736" rpy="0 0 0" />
      <geometry>
        <box size="0.024 0.006 0.012" />
        </geometry>
      <material name="graphite">
        <color rgba="0.18 0.19 0.21 1" />
        </material>
      </visual>
    <visual>
      <origin xyz="0.25 0.321 0.735" rpy="0 0 0" />
      <geometry>
        <box size="0.034 0.006 0.014" />
        </geometry>
      <material name="graphite">
        <color rgba="0.18 0.19 0.21 1" />
        </material>
      </visual>
    <visual>
      <origin xyz="0.278 0.321 0.735" rpy="0 0 0" />
      <geometry>
        <box size="0.012 0.006 0.012" />
        </geometry>
      <material name="accent">
        <color rgba="0.96 0.53 0.2 1" />
        </material>
      </visual>
    <visual>
      <origin xyz="0 0.285 0.425" rpy="0 0 0" />
      <geometry>
        <mesh filename="assets/meshes/washer_gasket_ring.obj" />
        </geometry>
      <material name="rubber">
        <color rgba="0.12 0.12 0.13 1" />
        </material>
      </visual>
    <visual>
      <origin xyz="0 0.2 0.425" rpy="1.5708 0 0" />
      <geometry>
        <cylinder radius="0.12" length="0.14" />
        </geometry>
      <material name="matte_black">
        <color rgba="0.08 0.08 0.09 1" />
        </material>
      </visual>
    <visual>
      <origin xyz="0 0.22 0.425" rpy="0 0 0" />
      <geometry>
        <mesh filename="assets/meshes/washer_drum_lip.obj" />
        </geometry>
      <material name="stainless">
        <color rgba="0.7 0.72 0.74 1" />
        </material>
      </visual>
    </link>
  <link name="door">
    <inertial>
      <origin xyz="0.198 0.038 0" rpy="0 0 0" />
      <mass value="4.5" />
      <inertia ixx="0.06855" ixy="0" ixz="0" iyy="0.1323" iyz="0" izz="0.06855" />
      </inertial>
    <visual>
      <origin xyz="0.014 0.01 0" rpy="0 0 0" />
      <geometry>
        <box size="0.028 0.02 0.14" />
        </geometry>
      <material name="graphite">
        <color rgba="0.18 0.19 0.21 1" />
        </material>
      </visual>
    <visual>
      <origin xyz="0.0525 0.01 0" rpy="0 0 0" />
      <geometry>
        <box size="0.105 0.022 0.06" />
        </geometry>
      <material name="graphite">
        <color rgba="0.18 0.19 0.21 1" />
        </material>
      </visual>
    <visual>
      <origin xyz="0 0.014 0" rpy="0 0 0" />
      <geometry>
        <cylinder radius="0.01" length="0.08" />
        </geometry>
      <material name="graphite">
        <color rgba="0.18 0.19 0.21 1" />
        </material>
      </visual>
    <visual>
      <origin xyz="0.198 0.038 0" rpy="0 0 0" />
      <geometry>
        <mesh filename="assets/meshes/washer_door_ring.obj" />
        </geometry>
      <material name="graphite">
        <color rgba="0.18 0.19 0.21 1" />
        </material>
      </visual>
    <visual>
      <origin xyz="0.198 0.018 0" rpy="0 0 0" />
      <geometry>
        <mesh filename="assets/meshes/washer_door_glass.obj" />
        </geometry>
      <material name="tinted_glass">
        <color rgba="0.58 0.68 0.76 0.28" />
        </material>
      </visual>
    <visual>
      <geometry>
        <mesh filename="assets/meshes/washer_door_handle.obj" />
        </geometry>
      <material name="silver_plastic">
        <color rgba="0.78 0.8 0.82 1" />
        </material>
      </visual>
    </link>
  <link name="selector_knob">
    <inertial>
      <origin xyz="0 0.02 0" rpy="0 0 0" />
      <mass value="0.35" />
      <inertia ixx="0.000309167" ixy="0" ixz="0" iyy="0.0004725" iyz="0" izz="0.000309167" />
      </inertial>
    <visual>
      <origin xyz="0 0.012 0" rpy="1.5708 0 0" />
      <geometry>
        <cylinder radius="0.04" length="0.024" />
        </geometry>
      <material name="silver_plastic">
        <color rgba="0.78 0.8 0.82 1" />
        </material>
      </visual>
    <visual>
      <origin xyz="0 0.03 0" rpy="1.5708 0 0" />
      <geometry>
        <cylinder radius="0.03" length="0.012" />
        </geometry>
      <material name="graphite">
        <color rgba="0.18 0.19 0.21 1" />
        </material>
      </visual>
    <visual>
      <origin xyz="0 0.022 0" rpy="0 0 0" />
      <geometry>
        <mesh filename="assets/meshes/washer_knob_grip.obj" />
        </geometry>
      <material name="silver_plastic">
        <color rgba="0.78 0.8 0.82 1" />
        </material>
      </visual>
    <visual>
      <origin xyz="0 0.035 0.03" rpy="0 0 0" />
      <geometry>
        <box size="0.006 0.006 0.014" />
        </geometry>
      <material name="accent">
        <color rgba="0.96 0.53 0.2 1" />
        </material>
      </visual>
    </link>
  <link name="detergent_drawer">
    <inertial>
      <origin xyz="0 -0.041 0" rpy="0 0 0" />
      <mass value="0.9" />
      <inertia ixx="0.001983" ixy="0" ixz="0" iyy="0.0028779" iyz="0" izz="0.0037515" />
      </inertial>
    <visual>
      <origin xyz="0 -0.055 0" rpy="0 0 0" />
      <geometry>
        <box size="0.17 0.11 0.078" />
        </geometry>
      <material name="white_enamel">
        <color rgba="0.95 0.96 0.97 1" />
        </material>
      </visual>
    <visual>
      <origin xyz="0 0.014 0" rpy="0 0 0" />
      <geometry>
        <box size="0.176 0.028 0.086" />
        </geometry>
      <material name="white_enamel">
        <color rgba="0.95 0.96 0.97 1" />
        </material>
      </visual>
    <visual>
      <origin xyz="0 0.024 0" rpy="0 0 0" />
      <geometry>
        <box size="0.11 0.01 0.022" />
        </geometry>
      <material name="screen_black">
        <color rgba="0.05 0.06 0.07 0.94" />
        </material>
      </visual>
    </link>
  <joint name="door_hinge" type="revolute">
    <origin xyz="-0.198 0.309 0.425" rpy="0 0 0" />
    <parent link="cabinet" />
    <child link="door" />
    <axis xyz="0 0 1" />
    <limit effort="18" velocity="2.2" lower="0" upper="1.65" />
    </joint>
  <joint name="selector_turn" type="continuous">
    <origin xyz="0.118 0.317 0.756" rpy="0 0 0" />
    <parent link="cabinet" />
    <child link="selector_knob" />
    <axis xyz="0 1 0" />
    <limit effort="1.2" velocity="8" />
    </joint>
  <joint name="drawer_slide" type="prismatic">
    <origin xyz="-0.17 0.29 0.75" rpy="0 0 0" />
    <parent link="cabinet" />
    <child link="detergent_drawer" />
    <axis xyz="0 1 0" />
    <limit effort="25" velocity="0.2" lower="0" upper="0.115" />
    </joint>
  </robot>
