<robot name="front_load_washing_machine">
  <material name="enamel_white">
    <color rgba="0.94 0.95 0.96 1" />
    </material>
  <material name="satin_steel">
    <color rgba="0.7 0.72 0.74 1" />
    </material>
  <material name="dark_plastic">
    <color rgba="0.12 0.12 0.13 1" />
    </material>
  <material name="knob_silver">
    <color rgba="0.74 0.75 0.77 1" />
    </material>
  <material name="smoked_glass">
    <color rgba="0.62 0.73 0.81 0.28" />
    </material>
  <material name="black_glass">
    <color rgba="0.07 0.08 0.09 0.92" />
    </material>
  <material name="rubber_gray">
    <color rgba="0.24 0.25 0.27 1" />
    </material>
  <link name="cabinet">
    <inertial>
      <origin xyz="0 0 0.425" rpy="0 0 0" />
      <mass value="54" />
      <inertia ixx="4.87125" ixy="0" ixz="0" iyy="5.2713" iyz="0" izz="3.64005" />
      </inertial>
    <visual>
      <origin xyz="0 0.289 0.425" rpy="0 0 0" />
      <geometry>
        <box size="0.67 0.022 0.85" />
        </geometry>
      <material name="enamel_white">
        <color rgba="0.94 0.95 0.96 1" />
        </material>
      </visual>
    <visual>
      <origin xyz="0 -0.289 0.425" rpy="0 0 0" />
      <geometry>
        <box size="0.67 0.022 0.85" />
        </geometry>
      <material name="enamel_white">
        <color rgba="0.94 0.95 0.96 1" />
        </material>
      </visual>
    <visual>
      <origin xyz="0 0 0.839" rpy="0 0 0" />
      <geometry>
        <box size="0.67 0.556 0.022" />
        </geometry>
      <material name="enamel_white">
        <color rgba="0.94 0.95 0.96 1" />
        </material>
      </visual>
    <visual>
      <origin xyz="0 0 0.011" rpy="0 0 0" />
      <geometry>
        <box size="0.67 0.556 0.022" />
        </geometry>
      <material name="enamel_white">
        <color rgba="0.94 0.95 0.96 1" />
        </material>
      </visual>
    <visual>
      <origin xyz="-0.326 0 0.425" rpy="0 0 0" />
      <geometry>
        <box size="0.018 0.556 0.806" />
        </geometry>
      <material name="enamel_white">
        <color rgba="0.94 0.95 0.96 1" />
        </material>
      </visual>
    <visual>
      <origin xyz="0.321 0 0.7775" rpy="0 0 0" />
      <geometry>
        <box size="0.028 0.556 0.145" />
        </geometry>
      <material name="enamel_white">
        <color rgba="0.94 0.95 0.96 1" />
        </material>
      </visual>
    <visual>
      <origin xyz="0.321 0 0.0375" rpy="0 0 0" />
      <geometry>
        <box size="0.028 0.556 0.075" />
        </geometry>
      <material name="enamel_white">
        <color rgba="0.94 0.95 0.96 1" />
        </material>
      </visual>
    <visual>
      <origin xyz="0.326 0 0.39" rpy="0 0 0" />
      <geometry>
        <mesh filename="meshes/washer_front_panel.obj" />
        </geometry>
      <material name="enamel_white">
        <color rgba="0.94 0.95 0.96 1" />
        </material>
      </visual>
    <visual>
      <origin xyz="0.329 0 0.42" rpy="0 1.5708 0" />
      <geometry>
        <mesh filename="meshes/washer_cabinet_bezel.obj" />
        </geometry>
      <material name="satin_steel">
        <color rgba="0.7 0.72 0.74 1" />
        </material>
      </visual>
    <visual>
      <origin xyz="0.338 0.025 0.774" rpy="0 0 0" />
      <geometry>
        <box size="0.006 0.165 0.05" />
        </geometry>
      <material name="black_glass">
        <color rgba="0.07 0.08 0.09 0.92" />
        </material>
      </visual>
    <visual>
      <origin xyz="0.337 0.065 0.735" rpy="0 0 0" />
      <geometry>
        <box size="0.01 0.026 0.012" />
        </geometry>
      <material name="dark_plastic">
        <color rgba="0.12 0.12 0.13 1" />
        </material>
      </visual>
    <visual>
      <origin xyz="0.337 0.025 0.735" rpy="0 0 0" />
      <geometry>
        <box size="0.01 0.026 0.012" />
        </geometry>
      <material name="dark_plastic">
        <color rgba="0.12 0.12 0.13 1" />
        </material>
      </visual>
    <visual>
      <origin xyz="0.337 -0.015 0.735" rpy="0 0 0" />
      <geometry>
        <box size="0.01 0.026 0.012" />
        </geometry>
      <material name="dark_plastic">
        <color rgba="0.12 0.12 0.13 1" />
        </material>
      </visual>
    <visual>
      <origin xyz="-0.25 -0.235 0.009" rpy="0 0 0" />
      <geometry>
        <cylinder radius="0.02" length="0.018" />
        </geometry>
      <material name="rubber_gray">
        <color rgba="0.24 0.25 0.27 1" />
        </material>
      </visual>
    <visual>
      <origin xyz="-0.25 0.235 0.009" rpy="0 0 0" />
      <geometry>
        <cylinder radius="0.02" length="0.018" />
        </geometry>
      <material name="rubber_gray">
        <color rgba="0.24 0.25 0.27 1" />
        </material>
      </visual>
    <visual>
      <origin xyz="0.25 -0.235 0.009" rpy="0 0 0" />
      <geometry>
        <cylinder radius="0.02" length="0.018" />
        </geometry>
      <material name="rubber_gray">
        <color rgba="0.24 0.25 0.27 1" />
        </material>
      </visual>
    <visual>
      <origin xyz="0.25 0.235 0.009" rpy="0 0 0" />
      <geometry>
        <cylinder radius="0.02" length="0.018" />
        </geometry>
      <material name="rubber_gray">
        <color rgba="0.24 0.25 0.27 1" />
        </material>
      </visual>
    <collision name="cabinet__visual_1">
      <origin xyz="0 0.289 0.425" rpy="0 0 0" />
      <geometry>
        <box size="0.67 0.022 0.85" />
        </geometry>
      </collision>
    <collision name="cabinet__visual_2">
      <origin xyz="0 -0.289 0.425" rpy="0 0 0" />
      <geometry>
        <box size="0.67 0.022 0.85" />
        </geometry>
      </collision>
    <collision name="cabinet__visual_3">
      <origin xyz="0 0 0.839" rpy="0 0 0" />
      <geometry>
        <box size="0.67 0.556 0.022" />
        </geometry>
      </collision>
    <collision name="cabinet__visual_4">
      <origin xyz="0 0 0.011" rpy="0 0 0" />
      <geometry>
        <box size="0.67 0.556 0.022" />
        </geometry>
      </collision>
    <collision name="cabinet__visual_5">
      <origin xyz="-0.326 0 0.425" rpy="0 0 0" />
      <geometry>
        <box size="0.018 0.556 0.806" />
        </geometry>
      </collision>
    <collision name="cabinet__visual_6">
      <origin xyz="0.321 0 0.7775" rpy="0 0 0" />
      <geometry>
        <box size="0.028 0.556 0.145" />
        </geometry>
      </collision>
    <collision name="cabinet__visual_7">
      <origin xyz="0.321 0 0.0375" rpy="0 0 0" />
      <geometry>
        <box size="0.028 0.556 0.075" />
        </geometry>
      </collision>
    <collision name="cabinet__visual_8__hull_001">
      <origin xyz="0.326 0 0.39" rpy="0 0 0" />
      <geometry>
        <mesh filename="meshes/collision/cache/c6dc465cffe3486d457a24e2__hull_001.obj" />
        </geometry>
      </collision>
    <collision name="cabinet__visual_8__hull_002">
      <origin xyz="0.326 0 0.39" rpy="0 0 0" />
      <geometry>
        <mesh filename="meshes/collision/cache/c6dc465cffe3486d457a24e2__hull_002.obj" />
        </geometry>
      </collision>
    <collision name="cabinet__visual_8__hull_003">
      <origin xyz="0.326 0 0.39" rpy="0 0 0" />
      <geometry>
        <mesh filename="meshes/collision/cache/c6dc465cffe3486d457a24e2__hull_003.obj" />
        </geometry>
      </collision>
    <collision name="cabinet__visual_8__hull_004">
      <origin xyz="0.326 0 0.39" rpy="0 0 0" />
      <geometry>
        <mesh filename="meshes/collision/cache/c6dc465cffe3486d457a24e2__hull_004.obj" />
        </geometry>
      </collision>
    <collision name="cabinet__visual_8__hull_005">
      <origin xyz="0.326 0 0.39" rpy="0 0 0" />
      <geometry>
        <mesh filename="meshes/collision/cache/c6dc465cffe3486d457a24e2__hull_005.obj" />
        </geometry>
      </collision>
    <collision name="cabinet__visual_8__hull_006">
      <origin xyz="0.326 0 0.39" rpy="0 0 0" />
      <geometry>
        <mesh filename="meshes/collision/cache/c6dc465cffe3486d457a24e2__hull_006.obj" />
        </geometry>
      </collision>
    <collision name="cabinet__visual_8__hull_007">
      <origin xyz="0.326 0 0.39" rpy="0 0 0" />
      <geometry>
        <mesh filename="meshes/collision/cache/c6dc465cffe3486d457a24e2__hull_007.obj" />
        </geometry>
      </collision>
    <collision name="cabinet__visual_8__hull_008">
      <origin xyz="0.326 0 0.39" rpy="0 0 0" />
      <geometry>
        <mesh filename="meshes/collision/cache/c6dc465cffe3486d457a24e2__hull_008.obj" />
        </geometry>
      </collision>
    <collision name="cabinet__visual_9__hull_001">
      <origin xyz="0.329 0 0.42" rpy="0 1.5708 0" />
      <geometry>
        <mesh filename="meshes/collision/cache/2ea47549dd7526a7570901df__hull_001.obj" />
        </geometry>
      </collision>
    <collision name="cabinet__visual_9__hull_002">
      <origin xyz="0.329 0 0.42" rpy="0 1.5708 0" />
      <geometry>
        <mesh filename="meshes/collision/cache/2ea47549dd7526a7570901df__hull_002.obj" />
        </geometry>
      </collision>
    <collision name="cabinet__visual_9__hull_003">
      <origin xyz="0.329 0 0.42" rpy="0 1.5708 0" />
      <geometry>
        <mesh filename="meshes/collision/cache/2ea47549dd7526a7570901df__hull_003.obj" />
        </geometry>
      </collision>
    <collision name="cabinet__visual_9__hull_004">
      <origin xyz="0.329 0 0.42" rpy="0 1.5708 0" />
      <geometry>
        <mesh filename="meshes/collision/cache/2ea47549dd7526a7570901df__hull_004.obj" />
        </geometry>
      </collision>
    <collision name="cabinet__visual_9__hull_005">
      <origin xyz="0.329 0 0.42" rpy="0 1.5708 0" />
      <geometry>
        <mesh filename="meshes/collision/cache/2ea47549dd7526a7570901df__hull_005.obj" />
        </geometry>
      </collision>
    <collision name="cabinet__visual_9__hull_006">
      <origin xyz="0.329 0 0.42" rpy="0 1.5708 0" />
      <geometry>
        <mesh filename="meshes/collision/cache/2ea47549dd7526a7570901df__hull_006.obj" />
        </geometry>
      </collision>
    <collision name="cabinet__visual_9__hull_007">
      <origin xyz="0.329 0 0.42" rpy="0 1.5708 0" />
      <geometry>
        <mesh filename="meshes/collision/cache/2ea47549dd7526a7570901df__hull_007.obj" />
        </geometry>
      </collision>
    <collision name="cabinet__visual_9__hull_008">
      <origin xyz="0.329 0 0.42" rpy="0 1.5708 0" />
      <geometry>
        <mesh filename="meshes/collision/cache/2ea47549dd7526a7570901df__hull_008.obj" />
        </geometry>
      </collision>
    <collision name="cabinet__visual_9__hull_009">
      <origin xyz="0.329 0 0.42" rpy="0 1.5708 0" />
      <geometry>
        <mesh filename="meshes/collision/cache/2ea47549dd7526a7570901df__hull_009.obj" />
        </geometry>
      </collision>
    <collision name="cabinet__visual_9__hull_010">
      <origin xyz="0.329 0 0.42" rpy="0 1.5708 0" />
      <geometry>
        <mesh filename="meshes/collision/cache/2ea47549dd7526a7570901df__hull_010.obj" />
        </geometry>
      </collision>
    <collision name="cabinet__visual_9__hull_011">
      <origin xyz="0.329 0 0.42" rpy="0 1.5708 0" />
      <geometry>
        <mesh filename="meshes/collision/cache/2ea47549dd7526a7570901df__hull_011.obj" />
        </geometry>
      </collision>
    <collision name="cabinet__visual_10">
      <origin xyz="0.338 0.025 0.774" rpy="0 0 0" />
      <geometry>
        <box size="0.006 0.165 0.05" />
        </geometry>
      </collision>
    <collision name="cabinet__visual_11">
      <origin xyz="0.337 0.065 0.735" rpy="0 0 0" />
      <geometry>
        <box size="0.01 0.026 0.012" />
        </geometry>
      </collision>
    <collision name="cabinet__visual_12">
      <origin xyz="0.337 0.025 0.735" rpy="0 0 0" />
      <geometry>
        <box size="0.01 0.026 0.012" />
        </geometry>
      </collision>
    <collision name="cabinet__visual_13">
      <origin xyz="0.337 -0.015 0.735" rpy="0 0 0" />
      <geometry>
        <box size="0.01 0.026 0.012" />
        </geometry>
      </collision>
    <collision name="cabinet__visual_14">
      <origin xyz="-0.25 -0.235 0.009" rpy="0 0 0" />
      <geometry>
        <cylinder radius="0.02" length="0.018" />
        </geometry>
      </collision>
    <collision name="cabinet__visual_15">
      <origin xyz="-0.25 0.235 0.009" rpy="0 0 0" />
      <geometry>
        <cylinder radius="0.02" length="0.018" />
        </geometry>
      </collision>
    <collision name="cabinet__visual_16">
      <origin xyz="0.25 -0.235 0.009" rpy="0 0 0" />
      <geometry>
        <cylinder radius="0.02" length="0.018" />
        </geometry>
      </collision>
    <collision name="cabinet__visual_17">
      <origin xyz="0.25 0.235 0.009" rpy="0 0 0" />
      <geometry>
        <cylinder radius="0.02" length="0.018" />
        </geometry>
      </collision>
    </link>
  <link name="drum_assembly">
    <inertial>
      <origin xyz="-0.16 0 0.175" rpy="0 1.5708 0" />
      <mass value="9" />
      <inertia ixx="0.1497" ixy="0" ixz="0" iyy="0.1497" iyz="0" izz="0.1458" />
      </inertial>
    <visual>
      <origin xyz="-0.012 0 0.175" rpy="0 1.5708 0" />
      <geometry>
        <mesh filename="meshes/washer_drum_boot.obj" />
        </geometry>
      <material name="rubber_gray">
        <color rgba="0.24 0.25 0.27 1" />
        </material>
      </visual>
    <visual>
      <origin xyz="-0.035 0 0.175" rpy="0 1.5708 0" />
      <geometry>
        <cylinder radius="0.168" length="0.022" />
        </geometry>
      <material name="satin_steel">
        <color rgba="0.7 0.72 0.74 1" />
        </material>
      </visual>
    <visual>
      <origin xyz="-0.16 0 0.175" rpy="0 1.5708 0" />
      <geometry>
        <cylinder radius="0.156" length="0.27" />
        </geometry>
      <material name="satin_steel">
        <color rgba="0.7 0.72 0.74 1" />
        </material>
      </visual>
    <visual>
      <origin xyz="-0.305 0 0.175" rpy="0 1.5708 0" />
      <geometry>
        <cylinder radius="0.158" length="0.02" />
        </geometry>
      <material name="dark_plastic">
        <color rgba="0.12 0.12 0.13 1" />
        </material>
      </visual>
    <visual>
      <origin xyz="-0.15 0.0683771 0.088834" rpy="0 0 -0.9" />
      <geometry>
        <box size="0.19 0.016 0.034" />
        </geometry>
      <material name="dark_plastic">
        <color rgba="0.12 0.12 0.13 1" />
        </material>
      </visual>
    <visual>
      <origin xyz="-0.15 0.107807 0.196854" rpy="0 0 0.2" />
      <geometry>
        <box size="0.19 0.016 0.034" />
        </geometry>
      <material name="dark_plastic">
        <color rgba="0.12 0.12 0.13 1" />
        </material>
      </visual>
    <visual>
      <origin xyz="-0.15 0.0294249 0.280991" rpy="0 0 1.3" />
      <geometry>
        <box size="0.19 0.016 0.034" />
        </geometry>
      <material name="dark_plastic">
        <color rgba="0.12 0.12 0.13 1" />
        </material>
      </visual>
    <collision name="drum_assembly__visual_1__hull_001">
      <origin xyz="-0.012 0 0.175" rpy="0 1.5708 0" />
      <geometry>
        <mesh filename="meshes/collision/cache/e578843bcb08814463555c3d__hull_001.obj" />
        </geometry>
      </collision>
    <collision name="drum_assembly__visual_1__hull_002">
      <origin xyz="-0.012 0 0.175" rpy="0 1.5708 0" />
      <geometry>
        <mesh filename="meshes/collision/cache/e578843bcb08814463555c3d__hull_002.obj" />
        </geometry>
      </collision>
    <collision name="drum_assembly__visual_1__hull_003">
      <origin xyz="-0.012 0 0.175" rpy="0 1.5708 0" />
      <geometry>
        <mesh filename="meshes/collision/cache/e578843bcb08814463555c3d__hull_003.obj" />
        </geometry>
      </collision>
    <collision name="drum_assembly__visual_1__hull_004">
      <origin xyz="-0.012 0 0.175" rpy="0 1.5708 0" />
      <geometry>
        <mesh filename="meshes/collision/cache/e578843bcb08814463555c3d__hull_004.obj" />
        </geometry>
      </collision>
    <collision name="drum_assembly__visual_1__hull_005">
      <origin xyz="-0.012 0 0.175" rpy="0 1.5708 0" />
      <geometry>
        <mesh filename="meshes/collision/cache/e578843bcb08814463555c3d__hull_005.obj" />
        </geometry>
      </collision>
    <collision name="drum_assembly__visual_1__hull_006">
      <origin xyz="-0.012 0 0.175" rpy="0 1.5708 0" />
      <geometry>
        <mesh filename="meshes/collision/cache/e578843bcb08814463555c3d__hull_006.obj" />
        </geometry>
      </collision>
    <collision name="drum_assembly__visual_1__hull_007">
      <origin xyz="-0.012 0 0.175" rpy="0 1.5708 0" />
      <geometry>
        <mesh filename="meshes/collision/cache/e578843bcb08814463555c3d__hull_007.obj" />
        </geometry>
      </collision>
    <collision name="drum_assembly__visual_1__hull_008">
      <origin xyz="-0.012 0 0.175" rpy="0 1.5708 0" />
      <geometry>
        <mesh filename="meshes/collision/cache/e578843bcb08814463555c3d__hull_008.obj" />
        </geometry>
      </collision>
    <collision name="drum_assembly__visual_2">
      <origin xyz="-0.035 0 0.175" rpy="0 1.5708 0" />
      <geometry>
        <cylinder radius="0.168" length="0.022" />
        </geometry>
      </collision>
    <collision name="drum_assembly__visual_3">
      <origin xyz="-0.16 0 0.175" rpy="0 1.5708 0" />
      <geometry>
        <cylinder radius="0.156" length="0.27" />
        </geometry>
      </collision>
    <collision name="drum_assembly__visual_4">
      <origin xyz="-0.305 0 0.175" rpy="0 1.5708 0" />
      <geometry>
        <cylinder radius="0.158" length="0.02" />
        </geometry>
      </collision>
    <collision name="drum_assembly__visual_5">
      <origin xyz="-0.15 0.0683771 0.088834" rpy="0 0 -0.9" />
      <geometry>
        <box size="0.19 0.016 0.034" />
        </geometry>
      </collision>
    <collision name="drum_assembly__visual_6">
      <origin xyz="-0.15 0.107807 0.196854" rpy="0 0 0.2" />
      <geometry>
        <box size="0.19 0.016 0.034" />
        </geometry>
      </collision>
    <collision name="drum_assembly__visual_7">
      <origin xyz="-0.15 0.0294249 0.280991" rpy="0 0 1.3" />
      <geometry>
        <box size="0.19 0.016 0.034" />
        </geometry>
      </collision>
    </link>
  <link name="door">
    <inertial>
      <origin xyz="0.047 -0.194 0" rpy="0 1.5708 0" />
      <mass value="3.5" />
      <inertia ixx="0.0414969" ixy="0" ixz="0" iyy="0.0414969" iyz="0" izz="0.0808937" />
      </inertial>
    <visual>
      <origin xyz="0.007 -0.01 0" rpy="0 0 0" />
      <geometry>
        <box size="0.014 0.055 0.24" />
        </geometry>
      <material name="dark_plastic">
        <color rgba="0.12 0.12 0.13 1" />
        </material>
      </visual>
    <visual>
      <origin xyz="0.029 0 0" rpy="0 0 0" />
      <geometry>
        <mesh filename="meshes/washer_door_frame.obj" />
        </geometry>
      <material name="dark_plastic">
        <color rgba="0.12 0.12 0.13 1" />
        </material>
      </visual>
    <visual>
      <origin xyz="0.049 -0.194 0" rpy="0 1.5708 0" />
      <geometry>
        <mesh filename="meshes/washer_door_outer_ring.obj" />
        </geometry>
      <material name="satin_steel">
        <color rgba="0.7 0.72 0.74 1" />
        </material>
      </visual>
    <visual>
      <origin xyz="0.034 -0.194 0" rpy="0 1.5708 0" />
      <geometry>
        <mesh filename="meshes/washer_door_inner_ring.obj" />
        </geometry>
      <material name="dark_plastic">
        <color rgba="0.12 0.12 0.13 1" />
        </material>
      </visual>
    <visual>
      <origin xyz="0.038 -0.194 0" rpy="0 1.5708 0" />
      <geometry>
        <cylinder radius="0.145" length="0.014" />
        </geometry>
      <material name="smoked_glass">
        <color rgba="0.62 0.73 0.81 0.28" />
        </material>
      </visual>
    <visual>
      <origin xyz="0.05 -0.356 0" rpy="0 0 0" />
      <geometry>
        <box size="0.034 0.05 0.128" />
        </geometry>
      <material name="dark_plastic">
        <color rgba="0.12 0.12 0.13 1" />
        </material>
      </visual>
    <visual>
      <origin xyz="0.06 -0.334 0" rpy="0 0 0" />
      <geometry>
        <box size="0.024 0.03 0.09" />
        </geometry>
      <material name="dark_plastic">
        <color rgba="0.12 0.12 0.13 1" />
        </material>
      </visual>
    <collision name="door__visual_1">
      <origin xyz="0.007 -0.01 0" rpy="0 0 0" />
      <geometry>
        <box size="0.014 0.055 0.24" />
        </geometry>
      </collision>
    <collision name="door__visual_2__hull_001">
      <origin xyz="0.029 0 0" rpy="0 0 0" />
      <geometry>
        <mesh filename="meshes/collision/cache/565a8d51f789a56a44673320__hull_001.obj" />
        </geometry>
      </collision>
    <collision name="door__visual_2__hull_002">
      <origin xyz="0.029 0 0" rpy="0 0 0" />
      <geometry>
        <mesh filename="meshes/collision/cache/565a8d51f789a56a44673320__hull_002.obj" />
        </geometry>
      </collision>
    <collision name="door__visual_2__hull_003">
      <origin xyz="0.029 0 0" rpy="0 0 0" />
      <geometry>
        <mesh filename="meshes/collision/cache/565a8d51f789a56a44673320__hull_003.obj" />
        </geometry>
      </collision>
    <collision name="door__visual_2__hull_004">
      <origin xyz="0.029 0 0" rpy="0 0 0" />
      <geometry>
        <mesh filename="meshes/collision/cache/565a8d51f789a56a44673320__hull_004.obj" />
        </geometry>
      </collision>
    <collision name="door__visual_2__hull_005">
      <origin xyz="0.029 0 0" rpy="0 0 0" />
      <geometry>
        <mesh filename="meshes/collision/cache/565a8d51f789a56a44673320__hull_005.obj" />
        </geometry>
      </collision>
    <collision name="door__visual_2__hull_006">
      <origin xyz="0.029 0 0" rpy="0 0 0" />
      <geometry>
        <mesh filename="meshes/collision/cache/565a8d51f789a56a44673320__hull_006.obj" />
        </geometry>
      </collision>
    <collision name="door__visual_2__hull_007">
      <origin xyz="0.029 0 0" rpy="0 0 0" />
      <geometry>
        <mesh filename="meshes/collision/cache/565a8d51f789a56a44673320__hull_007.obj" />
        </geometry>
      </collision>
    <collision name="door__visual_2__hull_008">
      <origin xyz="0.029 0 0" rpy="0 0 0" />
      <geometry>
        <mesh filename="meshes/collision/cache/565a8d51f789a56a44673320__hull_008.obj" />
        </geometry>
      </collision>
    <collision name="door__visual_3__hull_001">
      <origin xyz="0.049 -0.194 0" rpy="0 1.5708 0" />
      <geometry>
        <mesh filename="meshes/collision/cache/46714582e40703a5189f4d9a__hull_001.obj" />
        </geometry>
      </collision>
    <collision name="door__visual_3__hull_002">
      <origin xyz="0.049 -0.194 0" rpy="0 1.5708 0" />
      <geometry>
        <mesh filename="meshes/collision/cache/46714582e40703a5189f4d9a__hull_002.obj" />
        </geometry>
      </collision>
    <collision name="door__visual_3__hull_003">
      <origin xyz="0.049 -0.194 0" rpy="0 1.5708 0" />
      <geometry>
        <mesh filename="meshes/collision/cache/46714582e40703a5189f4d9a__hull_003.obj" />
        </geometry>
      </collision>
    <collision name="door__visual_3__hull_004">
      <origin xyz="0.049 -0.194 0" rpy="0 1.5708 0" />
      <geometry>
        <mesh filename="meshes/collision/cache/46714582e40703a5189f4d9a__hull_004.obj" />
        </geometry>
      </collision>
    <collision name="door__visual_3__hull_005">
      <origin xyz="0.049 -0.194 0" rpy="0 1.5708 0" />
      <geometry>
        <mesh filename="meshes/collision/cache/46714582e40703a5189f4d9a__hull_005.obj" />
        </geometry>
      </collision>
    <collision name="door__visual_3__hull_006">
      <origin xyz="0.049 -0.194 0" rpy="0 1.5708 0" />
      <geometry>
        <mesh filename="meshes/collision/cache/46714582e40703a5189f4d9a__hull_006.obj" />
        </geometry>
      </collision>
    <collision name="door__visual_3__hull_007">
      <origin xyz="0.049 -0.194 0" rpy="0 1.5708 0" />
      <geometry>
        <mesh filename="meshes/collision/cache/46714582e40703a5189f4d9a__hull_007.obj" />
        </geometry>
      </collision>
    <collision name="door__visual_3__hull_008">
      <origin xyz="0.049 -0.194 0" rpy="0 1.5708 0" />
      <geometry>
        <mesh filename="meshes/collision/cache/46714582e40703a5189f4d9a__hull_008.obj" />
        </geometry>
      </collision>
    <collision name="door__visual_3__hull_009">
      <origin xyz="0.049 -0.194 0" rpy="0 1.5708 0" />
      <geometry>
        <mesh filename="meshes/collision/cache/46714582e40703a5189f4d9a__hull_009.obj" />
        </geometry>
      </collision>
    <collision name="door__visual_3__hull_010">
      <origin xyz="0.049 -0.194 0" rpy="0 1.5708 0" />
      <geometry>
        <mesh filename="meshes/collision/cache/46714582e40703a5189f4d9a__hull_010.obj" />
        </geometry>
      </collision>
    <collision name="door__visual_4__hull_001">
      <origin xyz="0.034 -0.194 0" rpy="0 1.5708 0" />
      <geometry>
        <mesh filename="meshes/collision/cache/7d4a5b2fa4c34462919b974e__hull_001.obj" />
        </geometry>
      </collision>
    <collision name="door__visual_4__hull_002">
      <origin xyz="0.034 -0.194 0" rpy="0 1.5708 0" />
      <geometry>
        <mesh filename="meshes/collision/cache/7d4a5b2fa4c34462919b974e__hull_002.obj" />
        </geometry>
      </collision>
    <collision name="door__visual_4__hull_003">
      <origin xyz="0.034 -0.194 0" rpy="0 1.5708 0" />
      <geometry>
        <mesh filename="meshes/collision/cache/7d4a5b2fa4c34462919b974e__hull_003.obj" />
        </geometry>
      </collision>
    <collision name="door__visual_4__hull_004">
      <origin xyz="0.034 -0.194 0" rpy="0 1.5708 0" />
      <geometry>
        <mesh filename="meshes/collision/cache/7d4a5b2fa4c34462919b974e__hull_004.obj" />
        </geometry>
      </collision>
    <collision name="door__visual_4__hull_005">
      <origin xyz="0.034 -0.194 0" rpy="0 1.5708 0" />
      <geometry>
        <mesh filename="meshes/collision/cache/7d4a5b2fa4c34462919b974e__hull_005.obj" />
        </geometry>
      </collision>
    <collision name="door__visual_4__hull_006">
      <origin xyz="0.034 -0.194 0" rpy="0 1.5708 0" />
      <geometry>
        <mesh filename="meshes/collision/cache/7d4a5b2fa4c34462919b974e__hull_006.obj" />
        </geometry>
      </collision>
    <collision name="door__visual_4__hull_007">
      <origin xyz="0.034 -0.194 0" rpy="0 1.5708 0" />
      <geometry>
        <mesh filename="meshes/collision/cache/7d4a5b2fa4c34462919b974e__hull_007.obj" />
        </geometry>
      </collision>
    <collision name="door__visual_4__hull_008">
      <origin xyz="0.034 -0.194 0" rpy="0 1.5708 0" />
      <geometry>
        <mesh filename="meshes/collision/cache/7d4a5b2fa4c34462919b974e__hull_008.obj" />
        </geometry>
      </collision>
    <collision name="door__visual_4__hull_009">
      <origin xyz="0.034 -0.194 0" rpy="0 1.5708 0" />
      <geometry>
        <mesh filename="meshes/collision/cache/7d4a5b2fa4c34462919b974e__hull_009.obj" />
        </geometry>
      </collision>
    <collision name="door__visual_4__hull_010">
      <origin xyz="0.034 -0.194 0" rpy="0 1.5708 0" />
      <geometry>
        <mesh filename="meshes/collision/cache/7d4a5b2fa4c34462919b974e__hull_010.obj" />
        </geometry>
      </collision>
    <collision name="door__visual_4__hull_011">
      <origin xyz="0.034 -0.194 0" rpy="0 1.5708 0" />
      <geometry>
        <mesh filename="meshes/collision/cache/7d4a5b2fa4c34462919b974e__hull_011.obj" />
        </geometry>
      </collision>
    <collision name="door__visual_4__hull_012">
      <origin xyz="0.034 -0.194 0" rpy="0 1.5708 0" />
      <geometry>
        <mesh filename="meshes/collision/cache/7d4a5b2fa4c34462919b974e__hull_012.obj" />
        </geometry>
      </collision>
    <collision name="door__visual_5">
      <origin xyz="0.038 -0.194 0" rpy="0 1.5708 0" />
      <geometry>
        <cylinder radius="0.145" length="0.014" />
        </geometry>
      </collision>
    <collision name="door__visual_6">
      <origin xyz="0.05 -0.356 0" rpy="0 0 0" />
      <geometry>
        <box size="0.034 0.05 0.128" />
        </geometry>
      </collision>
    <collision name="door__visual_7">
      <origin xyz="0.06 -0.334 0" rpy="0 0 0" />
      <geometry>
        <box size="0.024 0.03 0.09" />
        </geometry>
      </collision>
    </link>
  <link name="selector_knob">
    <inertial>
      <origin xyz="0.018 0 0" rpy="0 1.5708 0" />
      <mass value="0.25" />
      <inertia ixx="0.000114333" ixy="0" ixz="0" iyy="0.000114333" iyz="0" izz="0.000162" />
      </inertial>
    <visual>
      <origin xyz="0.006 0 0" rpy="0 1.5708 0" />
      <geometry>
        <cylinder radius="0.03" length="0.012" />
        </geometry>
      <material name="dark_plastic">
        <color rgba="0.12 0.12 0.13 1" />
        </material>
      </visual>
    <visual>
      <origin xyz="0.012 0 0" rpy="0 1.5708 0" />
      <geometry>
        <mesh filename="meshes/washer_selector_knob.obj" />
        </geometry>
      <material name="knob_silver">
        <color rgba="0.74 0.75 0.77 1" />
        </material>
      </visual>
    <visual>
      <origin xyz="0.036 0 0.028" rpy="0 0 0" />
      <geometry>
        <box size="0.008 0.004 0.01" />
        </geometry>
      <material name="dark_plastic">
        <color rgba="0.12 0.12 0.13 1" />
        </material>
      </visual>
    <collision name="selector_knob__visual_1">
      <origin xyz="0.006 0 0" rpy="0 1.5708 0" />
      <geometry>
        <cylinder radius="0.03" length="0.012" />
        </geometry>
      </collision>
    <collision name="selector_knob__visual_2__hull_001">
      <origin xyz="0.012 0 0" rpy="0 1.5708 0" />
      <geometry>
        <mesh filename="meshes/collision/cache/9eff44a50b5452d40316639e__hull_001.obj" />
        </geometry>
      </collision>
    <collision name="selector_knob__visual_3">
      <origin xyz="0.036 0 0.028" rpy="0 0 0" />
      <geometry>
        <box size="0.008 0.004 0.01" />
        </geometry>
      </collision>
    </link>
  <link name="detergent_drawer">
    <inertial>
      <origin xyz="-0.105 0 0" rpy="0 0 0" />
      <mass value="0.8" />
      <inertia ixx="0.00333333" ixy="0" ixz="0" iyy="0.00483333" iyz="0" izz="0.00683333" />
      </inertial>
    <visual>
      <origin xyz="0.014 0 0" rpy="0 0 0" />
      <geometry>
        <box size="0.028 0.198 0.094" />
        </geometry>
      <material name="enamel_white">
        <color rgba="0.94 0.95 0.96 1" />
        </material>
      </visual>
    <visual>
      <origin xyz="-0.118 0 -0.004" rpy="0 0 0" />
      <geometry>
        <box size="0.24 0.182 0.072" />
        </geometry>
      <material name="enamel_white">
        <color rgba="0.94 0.95 0.96 1" />
        </material>
      </visual>
    <visual>
      <origin xyz="0.03 0 0.006" rpy="0 0 0" />
      <geometry>
        <box size="0.012 0.092 0.012" />
        </geometry>
      <material name="dark_plastic">
        <color rgba="0.12 0.12 0.13 1" />
        </material>
      </visual>
    <collision name="detergent_drawer__visual_1">
      <origin xyz="0.014 0 0" rpy="0 0 0" />
      <geometry>
        <box size="0.028 0.198 0.094" />
        </geometry>
      </collision>
    <collision name="detergent_drawer__visual_2">
      <origin xyz="-0.118 0 -0.004" rpy="0 0 0" />
      <geometry>
        <box size="0.24 0.182 0.072" />
        </geometry>
      </collision>
    <collision name="detergent_drawer__visual_3">
      <origin xyz="0.03 0 0.006" rpy="0 0 0" />
      <geometry>
        <box size="0.012 0.092 0.012" />
        </geometry>
      </collision>
    </link>
  <link name="power_button">
    <inertial>
      <origin xyz="0.005 0 0" rpy="0 1.5708 0" />
      <mass value="0.04" />
      <inertia ixx="1.77333e-06" ixy="0" ixz="0" iyy="1.77333e-06" iyz="0" izz="2.88e-06" />
      </inertial>
    <visual>
      <origin xyz="0.005 0 0" rpy="0 1.5708 0" />
      <geometry>
        <cylinder radius="0.012" length="0.01" />
        </geometry>
      <material name="dark_plastic">
        <color rgba="0.12 0.12 0.13 1" />
        </material>
      </visual>
    <collision name="power_button__visual_1">
      <origin xyz="0.005 0 0" rpy="0 1.5708 0" />
      <geometry>
        <cylinder radius="0.012" length="0.01" />
        </geometry>
      </collision>
    </link>
  <joint name="drum_mount" type="fixed">
    <origin xyz="0.307 0 0.25" rpy="0 0 0" />
    <parent link="cabinet" />
    <child link="drum_assembly" />
    </joint>
  <joint name="door_hinge" type="revolute">
    <origin xyz="0.329 0.194 0.42" rpy="0 0 0" />
    <parent link="cabinet" />
    <child link="door" />
    <axis xyz="0 0 1" />
    <limit effort="18" velocity="1.6" lower="0" upper="1.55" />
    </joint>
  <joint name="selector_rotation" type="revolute">
    <origin xyz="0.335 -0.102 0.755" rpy="0 0 0" />
    <parent link="cabinet" />
    <child link="selector_knob" />
    <axis xyz="1 0 0" />
    <limit effort="0.8" velocity="3" lower="-2.4" upper="2.4" />
    </joint>
  <joint name="drawer_slide" type="prismatic">
    <origin xyz="0.335 0.165 0.758" rpy="0 0 0" />
    <parent link="cabinet" />
    <child link="detergent_drawer" />
    <axis xyz="1 0 0" />
    <limit effort="35" velocity="0.45" lower="0" upper="0.18" />
    </joint>
  <joint name="power_button_press" type="prismatic">
    <origin xyz="0.335 -0.235 0.756" rpy="0 0 0" />
    <parent link="cabinet" />
    <child link="power_button" />
    <axis xyz="1 0 0" />
    <limit effort="5" velocity="0.05" lower="-0.004" upper="0" />
    </joint>
  </robot>
