<robot name="cctv_mast">
  <link name="mast">
    <inertial>
      <origin xyz="0 0 1.51" rpy="0 0 0" />
      <mass value="58" />
      <inertia ixx="44.1635" ixy="0" ixz="0" iyy="44.1635" iyz="0" izz="0.163125" />
    </inertial>
    <visual>
      <origin xyz="0 0 0.0125" rpy="0 0 0" />
      <geometry>
        <cylinder radius="0.13" length="0.025" />
      </geometry>
      <material name="galvanized_steel">
        <color rgba="0.7 0.72 0.74 1" />
      </material>
    </visual>
    <visual>
      <origin xyz="0 0 0.11" rpy="0 0 0" />
      <geometry>
        <cylinder radius="0.085" length="0.22" />
      </geometry>
      <material name="galvanized_steel">
        <color rgba="0.7 0.72 0.74 1" />
      </material>
    </visual>
    <visual>
      <origin xyz="0 0 1.435" rpy="0 0 0" />
      <geometry>
        <cylinder radius="0.065" length="2.82" />
      </geometry>
      <material name="galvanized_steel">
        <color rgba="0.7 0.72 0.74 1" />
      </material>
    </visual>
    <visual>
      <origin xyz="0 0.071 0.95" rpy="0 0 0" />
      <geometry>
        <box size="0.1 0.012 0.28" />
      </geometry>
      <material name="painted_white">
        <color rgba="0.9 0.91 0.92 1" />
      </material>
    </visual>
    <visual>
      <origin xyz="0.03 0.083 0.95" rpy="0 0 0" />
      <geometry>
        <box size="0.012 0.02 0.06" />
      </geometry>
      <material name="black_polymer">
        <color rgba="0.12 0.13 0.14 1" />
      </material>
    </visual>
    <visual>
      <origin xyz="0 -0.125 2.18" rpy="0 0 0" />
      <geometry>
        <box size="0.2 0.12 0.26" />
      </geometry>
      <material name="painted_white">
        <color rgba="0.9 0.91 0.92 1" />
      </material>
    </visual>
    <visual>
      <origin xyz="0 -0.187 2.18" rpy="0 0 0" />
      <geometry>
        <box size="0.16 0.004 0.22" />
      </geometry>
      <material name="painted_white">
        <color rgba="0.9 0.91 0.92 1" />
      </material>
    </visual>
    <visual>
      <origin xyz="0.055 -0.197 2.18" rpy="0 0 0" />
      <geometry>
        <box size="0.014 0.02 0.05" />
      </geometry>
      <material name="black_polymer">
        <color rgba="0.12 0.13 0.14 1" />
      </material>
    </visual>
    <visual>
      <origin xyz="0 -0.125 2.317" rpy="0 0 0" />
      <geometry>
        <box size="0.22 0.14 0.014" />
      </geometry>
      <material name="painted_white">
        <color rgba="0.9 0.91 0.92 1" />
      </material>
    </visual>
    <visual>
      <origin xyz="0 0 2.9225" rpy="0 0 0" />
      <geometry>
        <cylinder radius="0.082" length="0.155" />
      </geometry>
      <material name="galvanized_steel">
        <color rgba="0.7 0.72 0.74 1" />
      </material>
    </visual>
    <visual>
      <origin xyz="0 0 2.98" rpy="0 0 0" />
      <geometry>
        <cylinder radius="0.1" length="0.04" />
      </geometry>
      <material name="black_polymer">
        <color rgba="0.12 0.13 0.14 1" />
      </material>
    </visual>
    <visual>
      <geometry>
        <mesh filename="meshes/mast_conduit.glb" />
      </geometry>
      <material name="black_polymer">
        <color rgba="0.12 0.13 0.14 1" />
      </material>
    </visual>
    <collision name="mast__visual_1">
      <origin xyz="0 0 0.0125" rpy="0 0 0" />
      <geometry>
        <cylinder radius="0.13" length="0.025" />
      </geometry>
    </collision>
    <collision name="mast__visual_2">
      <origin xyz="0 0 0.11" rpy="0 0 0" />
      <geometry>
        <cylinder radius="0.085" length="0.22" />
      </geometry>
    </collision>
    <collision name="mast__visual_3">
      <origin xyz="0 0 1.435" rpy="0 0 0" />
      <geometry>
        <cylinder radius="0.065" length="2.82" />
      </geometry>
    </collision>
    <collision name="mast__visual_4">
      <origin xyz="0 0.071 0.95" rpy="0 0 0" />
      <geometry>
        <box size="0.1 0.012 0.28" />
      </geometry>
    </collision>
    <collision name="mast__visual_5">
      <origin xyz="0.03 0.083 0.95" rpy="0 0 0" />
      <geometry>
        <box size="0.012 0.02 0.06" />
      </geometry>
    </collision>
    <collision name="mast__visual_6">
      <origin xyz="0 -0.125 2.18" rpy="0 0 0" />
      <geometry>
        <box size="0.2 0.12 0.26" />
      </geometry>
    </collision>
    <collision name="mast__visual_7">
      <origin xyz="0 -0.187 2.18" rpy="0 0 0" />
      <geometry>
        <box size="0.16 0.004 0.22" />
      </geometry>
    </collision>
    <collision name="mast__visual_8">
      <origin xyz="0.055 -0.197 2.18" rpy="0 0 0" />
      <geometry>
        <box size="0.014 0.02 0.05" />
      </geometry>
    </collision>
    <collision name="mast__visual_9">
      <origin xyz="0 -0.125 2.317" rpy="0 0 0" />
      <geometry>
        <box size="0.22 0.14 0.014" />
      </geometry>
    </collision>
    <collision name="mast__visual_10">
      <origin xyz="0 0 2.9225" rpy="0 0 0" />
      <geometry>
        <cylinder radius="0.082" length="0.155" />
      </geometry>
    </collision>
    <collision name="mast__visual_11">
      <origin xyz="0 0 2.98" rpy="0 0 0" />
      <geometry>
        <cylinder radius="0.1" length="0.04" />
      </geometry>
    </collision>
    <collision name="mast__visual_12__hull_001">
      <geometry>
        <mesh filename="meshes/collision/cache/bf1d636ebf8b7dc476b19c62__hull_001.obj" />
      </geometry>
    </collision>
    <collision name="mast__visual_12__hull_002">
      <geometry>
        <mesh filename="meshes/collision/cache/bf1d636ebf8b7dc476b19c62__hull_002.obj" />
      </geometry>
    </collision>
  </link>
  <link name="pan_head">
    <inertial>
      <origin xyz="-0.01 0 0.27" rpy="0 0 0" />
      <mass value="9.5" />
      <inertia ixx="0.280329" ixy="0" ixz="0" iyy="0.280329" iyz="0" izz="0.0989583" />
    </inertial>
    <visual>
      <origin xyz="0 0 0.055" rpy="0 0 0" />
      <geometry>
        <cylinder radius="0.115" length="0.11" />
      </geometry>
      <material name="black_polymer">
        <color rgba="0.12 0.13 0.14 1" />
      </material>
    </visual>
    <visual>
      <origin xyz="0 0 0.135" rpy="0 0 0" />
      <geometry>
        <cylinder radius="0.095" length="0.05" />
      </geometry>
      <material name="painted_white">
        <color rgba="0.9 0.91 0.92 1" />
      </material>
    </visual>
    <visual>
      <origin xyz="-0.02 0.102 0.34" rpy="0 0 0" />
      <geometry>
        <box size="0.12 0.028 0.36" />
      </geometry>
      <material name="painted_white">
        <color rgba="0.9 0.91 0.92 1" />
      </material>
    </visual>
    <visual>
      <origin xyz="-0.02 -0.102 0.34" rpy="0 0 0" />
      <geometry>
        <box size="0.12 0.028 0.36" />
      </geometry>
      <material name="painted_white">
        <color rgba="0.9 0.91 0.92 1" />
      </material>
    </visual>
    <visual>
      <origin xyz="-0.09 0 0.34" rpy="0 0 0" />
      <geometry>
        <box size="0.04 0.176 0.28" />
      </geometry>
      <material name="painted_white">
        <color rgba="0.9 0.91 0.92 1" />
      </material>
    </visual>
    <visual>
      <origin xyz="-0.07 0 0.5" rpy="0 0 0" />
      <geometry>
        <box size="0.08 0.176 0.04" />
      </geometry>
      <material name="painted_white">
        <color rgba="0.9 0.91 0.92 1" />
      </material>
    </visual>
    <visual>
      <origin xyz="0 0.049 0.32" rpy="1.5708 0 0" />
      <geometry>
        <cylinder radius="0.03" length="0.082" />
      </geometry>
      <material name="dark_rubber">
        <color rgba="0.08 0.08 0.08 1" />
      </material>
    </visual>
    <visual>
      <origin xyz="0 -0.049 0.32" rpy="1.5708 0 0" />
      <geometry>
        <cylinder radius="0.03" length="0.082" />
      </geometry>
      <material name="dark_rubber">
        <color rgba="0.08 0.08 0.08 1" />
      </material>
    </visual>
    <collision name="pan_head__visual_1">
      <origin xyz="0 0 0.055" rpy="0 0 0" />
      <geometry>
        <cylinder radius="0.115" length="0.11" />
      </geometry>
    </collision>
    <collision name="pan_head__visual_2">
      <origin xyz="0 0 0.135" rpy="0 0 0" />
      <geometry>
        <cylinder radius="0.095" length="0.05" />
      </geometry>
    </collision>
    <collision name="pan_head__visual_3">
      <origin xyz="-0.02 0.102 0.34" rpy="0 0 0" />
      <geometry>
        <box size="0.12 0.028 0.36" />
      </geometry>
    </collision>
    <collision name="pan_head__visual_4">
      <origin xyz="-0.02 -0.102 0.34" rpy="0 0 0" />
      <geometry>
        <box size="0.12 0.028 0.36" />
      </geometry>
    </collision>
    <collision name="pan_head__visual_5">
      <origin xyz="-0.09 0 0.34" rpy="0 0 0" />
      <geometry>
        <box size="0.04 0.176 0.28" />
      </geometry>
    </collision>
    <collision name="pan_head__visual_6">
      <origin xyz="-0.07 0 0.5" rpy="0 0 0" />
      <geometry>
        <box size="0.08 0.176 0.04" />
      </geometry>
    </collision>
    <collision name="pan_head__visual_7">
      <origin xyz="0 0.049 0.32" rpy="1.5708 0 0" />
      <geometry>
        <cylinder radius="0.03" length="0.082" />
      </geometry>
    </collision>
    <collision name="pan_head__visual_8">
      <origin xyz="0 -0.049 0.32" rpy="1.5708 0 0" />
      <geometry>
        <cylinder radius="0.03" length="0.082" />
      </geometry>
    </collision>
  </link>
  <link name="camera_head">
    <inertial>
      <origin xyz="0.14 0 0" rpy="0 0 0" />
      <mass value="6.8" />
      <inertia ixx="0.0500933" ixy="0" ixz="0" iyy="0.127387" iyz="0" izz="0.122627" />
    </inertial>
    <visual>
      <origin xyz="0.125 0 -0.005" rpy="0 0 0" />
      <geometry>
        <box size="0.27 0.16 0.15" />
      </geometry>
      <material name="painted_white">
        <color rgba="0.9 0.91 0.92 1" />
      </material>
    </visual>
    <visual>
      <origin xyz="-0.035 0 0" rpy="0 0 0" />
      <geometry>
        <box size="0.05 0.12 0.11" />
      </geometry>
      <material name="painted_white">
        <color rgba="0.9 0.91 0.92 1" />
      </material>
    </visual>
    <visual>
      <origin xyz="0.17 0 0.08" rpy="0 0 0" />
      <geometry>
        <box size="0.24 0.18 0.02" />
      </geometry>
      <material name="black_polymer">
        <color rgba="0.12 0.13 0.14 1" />
      </material>
    </visual>
    <visual>
      <origin xyz="0.18 0 -0.102" rpy="0 0 0" />
      <geometry>
        <box size="0.12 0.11 0.05" />
      </geometry>
      <material name="black_polymer">
        <color rgba="0.12 0.13 0.14 1" />
      </material>
    </visual>
    <visual>
      <origin xyz="0.295 0 -0.005" rpy="0 1.5708 0" />
      <geometry>
        <cylinder radius="0.072" length="0.07" />
      </geometry>
      <material name="painted_white">
        <color rgba="0.9 0.91 0.92 1" />
      </material>
    </visual>
    <visual>
      <origin xyz="0.338 0 -0.005" rpy="0 1.5708 0" />
      <geometry>
        <cylinder radius="0.05" length="0.03" />
      </geometry>
      <material name="black_polymer">
        <color rgba="0.12 0.13 0.14 1" />
      </material>
    </visual>
    <visual>
      <origin xyz="0.356 0 -0.005" rpy="0 1.5708 0" />
      <geometry>
        <cylinder radius="0.035" length="0.008" />
      </geometry>
      <material name="smoked_glass">
        <color rgba="0.18 0.24 0.28 0.42" />
      </material>
    </visual>
    <visual>
      <origin xyz="0 0.08 0" rpy="1.5708 0 0" />
      <geometry>
        <cylinder radius="0.023" length="0.036" />
      </geometry>
      <material name="dark_rubber">
        <color rgba="0.08 0.08 0.08 1" />
      </material>
    </visual>
    <visual>
      <origin xyz="0 -0.08 0" rpy="1.5708 0 0" />
      <geometry>
        <cylinder radius="0.023" length="0.036" />
      </geometry>
      <material name="dark_rubber">
        <color rgba="0.08 0.08 0.08 1" />
      </material>
    </visual>
    <collision name="camera_head__visual_1">
      <origin xyz="0.125 0 -0.005" rpy="0 0 0" />
      <geometry>
        <box size="0.27 0.16 0.15" />
      </geometry>
    </collision>
    <collision name="camera_head__visual_2">
      <origin xyz="-0.035 0 0" rpy="0 0 0" />
      <geometry>
        <box size="0.05 0.12 0.11" />
      </geometry>
    </collision>
    <collision name="camera_head__visual_3">
      <origin xyz="0.17 0 0.08" rpy="0 0 0" />
      <geometry>
        <box size="0.24 0.18 0.02" />
      </geometry>
    </collision>
    <collision name="camera_head__visual_4">
      <origin xyz="0.18 0 -0.102" rpy="0 0 0" />
      <geometry>
        <box size="0.12 0.11 0.05" />
      </geometry>
    </collision>
    <collision name="camera_head__visual_5">
      <origin xyz="0.295 0 -0.005" rpy="0 1.5708 0" />
      <geometry>
        <cylinder radius="0.072" length="0.07" />
      </geometry>
    </collision>
    <collision name="camera_head__visual_6">
      <origin xyz="0.338 0 -0.005" rpy="0 1.5708 0" />
      <geometry>
        <cylinder radius="0.05" length="0.03" />
      </geometry>
    </collision>
    <collision name="camera_head__visual_7">
      <origin xyz="0.356 0 -0.005" rpy="0 1.5708 0" />
      <geometry>
        <cylinder radius="0.035" length="0.008" />
      </geometry>
    </collision>
    <collision name="camera_head__visual_8">
      <origin xyz="0 0.08 0" rpy="1.5708 0 0" />
      <geometry>
        <cylinder radius="0.023" length="0.036" />
      </geometry>
    </collision>
    <collision name="camera_head__visual_9">
      <origin xyz="0 -0.08 0" rpy="1.5708 0 0" />
      <geometry>
        <cylinder radius="0.023" length="0.036" />
      </geometry>
    </collision>
  </link>
  <joint name="camera_pan" type="revolute">
    <origin xyz="0 0 3" rpy="0 0 0" />
    <parent link="mast" />
    <child link="pan_head" />
    <axis xyz="0 0 1" />
    <limit effort="60" velocity="1.8" lower="-2.8" upper="2.8" />
  </joint>
  <joint name="camera_tilt" type="revolute">
    <origin xyz="0 0 0.32" rpy="0 0 0" />
    <parent link="pan_head" />
    <child link="camera_head" />
    <axis xyz="0 -1 0" />
    <limit effort="20" velocity="1.5" lower="-0.7" upper="0.45" />
  </joint>
</robot>