<robot name="tri_lobe_fidget_spinner">
  <link name="hub">
    <inertial>
      <mass value="0.028" />
      <inertia ixx="1.75959e-06" ixy="0" ixz="0" iyy="1.75959e-06" iyz="0" izz="2.5515e-06" />
      </inertial>
    <visual name="inner_race">
      <geometry>
        <cylinder radius="0.0042" length="0.008" />
        </geometry>
      <material name="brushed_steel">
        <color rgba="0.73 0.75 0.78 1" />
        </material>
      </visual>
    <visual name="button_base_bottom">
      <origin xyz="0 0 -0.0054" rpy="0 0 0" />
      <geometry>
        <cylinder radius="0.0135" length="0.0028" />
        </geometry>
      <material name="matte_black">
        <color rgba="0.1 0.1 0.11 1" />
        </material>
      </visual>
    <visual name="button_shoulder_bottom">
      <origin xyz="0 0 -0.0062" rpy="0 0 0" />
      <geometry>
        <cylinder radius="0.0105" length="0.0012" />
        </geometry>
      <material name="matte_black">
        <color rgba="0.1 0.1 0.11 1" />
        </material>
      </visual>
    <visual name="button_accent_bottom">
      <origin xyz="0 0 -0.0068" rpy="0 0 0" />
      <geometry>
        <cylinder radius="0.0055" length="0.0008" />
        </geometry>
      <material name="brushed_steel">
        <color rgba="0.73 0.75 0.78 1" />
        </material>
      </visual>
    <visual name="button_base_top">
      <origin xyz="0 0 0.0054" rpy="0 0 0" />
      <geometry>
        <cylinder radius="0.0135" length="0.0028" />
        </geometry>
      <material name="matte_black">
        <color rgba="0.1 0.1 0.11 1" />
        </material>
      </visual>
    <visual name="button_shoulder_top">
      <origin xyz="0 0 0.0062" rpy="0 0 0" />
      <geometry>
        <cylinder radius="0.0105" length="0.0012" />
        </geometry>
      <material name="matte_black">
        <color rgba="0.1 0.1 0.11 1" />
        </material>
      </visual>
    <visual name="button_accent_top">
      <origin xyz="0 0 0.0068" rpy="0 0 0" />
      <geometry>
        <cylinder radius="0.0055" length="0.0008" />
        </geometry>
      <material name="brushed_steel">
        <color rgba="0.73 0.75 0.78 1" />
        </material>
      </visual>
    </link>
  <link name="spinner_frame">
    <inertial>
      <mass value="0.085" />
      <inertia ixx="2.82483e-05" ixy="0" ixz="0" iyy="2.82483e-05" iyz="0" izz="5.508e-05" />
      </inertial>
    <visual name="body_shell">
      <geometry>
        <mesh filename="assets/meshes/spinner_body_shell.obj" />
        </geometry>
      <material name="anodized_body">
        <color rgba="0.16 0.22 0.31 1" />
        </material>
      </visual>
    <visual name="center_bearing_outer_race">
      <geometry>
        <mesh filename="assets/meshes/spinner_center_bearing_ring.obj" />
        </geometry>
      <material name="brushed_steel">
        <color rgba="0.73 0.75 0.78 1" />
        </material>
      </visual>
    <visual name="weight_ring_0">
      <origin xyz="1.59204e-18 0.026 0" rpy="0 0 0" />
      <geometry>
        <mesh filename="assets/meshes/spinner_lobe_weight_ring.obj" />
        </geometry>
      <material name="brushed_steel">
        <color rgba="0.73 0.75 0.78 1" />
        </material>
      </visual>
    <visual name="grip_pad_0_bottom">
      <origin xyz="1.59204e-18 0.026 -0.0037" rpy="0 0 0" />
      <geometry>
        <cylinder radius="0.0066" length="0.0008" />
        </geometry>
      <material name="rubber_black">
        <color rgba="0.18 0.18 0.19 1" />
        </material>
      </visual>
    <visual name="grip_pad_0_top">
      <origin xyz="1.59204e-18 0.026 0.0037" rpy="0 0 0" />
      <geometry>
        <cylinder radius="0.0066" length="0.0008" />
        </geometry>
      <material name="rubber_black">
        <color rgba="0.18 0.18 0.19 1" />
        </material>
      </visual>
    <visual name="weight_ring_1">
      <origin xyz="-0.0225167 -0.013 0" rpy="0 0 0" />
      <geometry>
        <mesh filename="assets/meshes/spinner_lobe_weight_ring.obj" />
        </geometry>
      <material name="brushed_steel">
        <color rgba="0.73 0.75 0.78 1" />
        </material>
      </visual>
    <visual name="grip_pad_1_bottom">
      <origin xyz="-0.0225167 -0.013 -0.0037" rpy="0 0 0" />
      <geometry>
        <cylinder radius="0.0066" length="0.0008" />
        </geometry>
      <material name="rubber_black">
        <color rgba="0.18 0.18 0.19 1" />
        </material>
      </visual>
    <visual name="grip_pad_1_top">
      <origin xyz="-0.0225167 -0.013 0.0037" rpy="0 0 0" />
      <geometry>
        <cylinder radius="0.0066" length="0.0008" />
        </geometry>
      <material name="rubber_black">
        <color rgba="0.18 0.18 0.19 1" />
        </material>
      </visual>
    <visual name="weight_ring_2">
      <origin xyz="0.0225167 -0.013 0" rpy="0 0 0" />
      <geometry>
        <mesh filename="assets/meshes/spinner_lobe_weight_ring.obj" />
        </geometry>
      <material name="brushed_steel">
        <color rgba="0.73 0.75 0.78 1" />
        </material>
      </visual>
    <visual name="grip_pad_2_bottom">
      <origin xyz="0.0225167 -0.013 -0.0037" rpy="0 0 0" />
      <geometry>
        <cylinder radius="0.0066" length="0.0008" />
        </geometry>
      <material name="rubber_black">
        <color rgba="0.18 0.18 0.19 1" />
        </material>
      </visual>
    <visual name="grip_pad_2_top">
      <origin xyz="0.0225167 -0.013 0.0037" rpy="0 0 0" />
      <geometry>
        <cylinder radius="0.0066" length="0.0008" />
        </geometry>
      <material name="rubber_black">
        <color rgba="0.18 0.18 0.19 1" />
        </material>
      </visual>
    </link>
  <joint name="hub_to_spinner" type="continuous">
    <parent link="hub" />
    <child link="spinner_frame" />
    <axis xyz="0 0 1" />
    <limit effort="2" velocity="80" />
    </joint>
  </robot>
