<robot name="push_pull_plunger_chain">
  <material name="housing">
    <color rgba="0.18 0.2 0.22 1" />
  </material>
  <material name="steel">
    <color rgba="0.7 0.72 0.75 1" />
  </material>
  <material name="tool_steel">
    <color rgba="0.48 0.5 0.54 1" />
  </material>
  <link name="frame">
    <inertial>
      <origin xyz="-0.055 0 -0.004" rpy="0 0 0" />
      <mass value="4.2" />
      <inertia ixx="0.00707" ixy="0" ixz="0" iyy="0.022995" iyz="0" izz="0.024395" />
    </inertial>
    <visual>
      <geometry>
        <mesh filename="meshes/frame.glb" />
      </geometry>
      <material name="housing" />
    </visual>
    <collision name="rear_body">
      <origin xyz="-0.0875 0 0" rpy="0 0 0" />
      <geometry>
        <box size="0.125 0.1 0.052" />
      </geometry>
    </collision>
    <collision name="rear_block">
      <origin xyz="-0.135 0 0.014" rpy="0 0 0" />
      <geometry>
        <box size="0.055 0.11 0.075" />
      </geometry>
    </collision>
    <collision name="base_foot">
      <origin xyz="-0.03 0 -0.028" rpy="0 0 0" />
      <geometry>
        <box size="0.24 0.06 0.012" />
      </geometry>
    </collision>
    <collision name="guide_top">
      <origin xyz="0.025 0 0.0155" rpy="0 0 0" />
      <geometry>
        <box size="0.074 0.036 0.005" />
      </geometry>
    </collision>
    <collision name="guide_bottom">
      <origin xyz="0.025 0 -0.0155" rpy="0 0 0" />
      <geometry>
        <box size="0.074 0.036 0.005" />
      </geometry>
    </collision>
    <collision name="guide_left">
      <origin xyz="0.025 0.0155 0" rpy="0 0 0" />
      <geometry>
        <box size="0.074 0.005 0.026" />
      </geometry>
    </collision>
    <collision name="guide_right">
      <origin xyz="0.025 -0.0155 0" rpy="0 0 0" />
      <geometry>
        <box size="0.074 0.005 0.026" />
      </geometry>
    </collision>
  </link>
  <link name="stage1">
    <inertial>
      <origin xyz="0.03 0 0" rpy="0 0 0" />
      <mass value="1.1" />
      <inertia ixx="0.000165" ixy="0" ixz="0" iyy="0.00288979" iyz="0" izz="0.00288979" />
    </inertial>
    <visual>
      <geometry>
        <mesh filename="meshes/stage1.glb" />
      </geometry>
      <material name="steel" />
    </visual>
    <collision name="rod">
      <origin xyz="0.001 0 0" rpy="0 0 0" />
      <geometry>
        <box size="0.112 0.021 0.021" />
      </geometry>
    </collision>
    <collision name="guide_top">
      <origin xyz="0.0825 0 0.0115" rpy="0 0 0" />
      <geometry>
        <box size="0.055 0.028 0.005" />
      </geometry>
    </collision>
    <collision name="guide_bottom">
      <origin xyz="0.0825 0 -0.0115" rpy="0 0 0" />
      <geometry>
        <box size="0.055 0.028 0.005" />
      </geometry>
    </collision>
    <collision name="guide_left">
      <origin xyz="0.0825 0.0115 0" rpy="0 0 0" />
      <geometry>
        <box size="0.055 0.005 0.018" />
      </geometry>
    </collision>
    <collision name="guide_right">
      <origin xyz="0.0825 -0.0115 0" rpy="0 0 0" />
      <geometry>
        <box size="0.055 0.005 0.018" />
      </geometry>
    </collision>
  </link>
  <link name="stage2">
    <inertial>
      <origin xyz="0.026 0 0" rpy="0 0 0" />
      <mass value="0.55" />
      <inertia ixx="4.43667e-05" ixy="0" ixz="0" iyy="0.000985829" iyz="0" izz="0.000985829" />
    </inertial>
    <visual>
      <geometry>
        <mesh filename="meshes/stage2.glb" />
      </geometry>
      <material name="steel" />
    </visual>
    <collision name="rod">
      <geometry>
        <box size="0.09 0.014 0.014" />
      </geometry>
    </collision>
    <collision name="guide_top">
      <origin xyz="0.07 0 0.008" rpy="0 0 0" />
      <geometry>
        <box size="0.05 0.02 0.004" />
      </geometry>
    </collision>
    <collision name="guide_bottom">
      <origin xyz="0.07 0 -0.008" rpy="0 0 0" />
      <geometry>
        <box size="0.05 0.02 0.004" />
      </geometry>
    </collision>
    <collision name="guide_left">
      <origin xyz="0.07 0.008 0" rpy="0 0 0" />
      <geometry>
        <box size="0.05 0.004 0.012" />
      </geometry>
    </collision>
    <collision name="guide_right">
      <origin xyz="0.07 -0.008 0" rpy="0 0 0" />
      <geometry>
        <box size="0.05 0.004 0.012" />
      </geometry>
    </collision>
  </link>
  <link name="stage3">
    <inertial>
      <origin xyz="0.022 0 0" rpy="0 0 0" />
      <mass value="0.18" />
      <inertia ixx="7.68e-06" ixy="0" ixz="0" iyy="0.000202215" iyz="0" izz="0.000202215" />
    </inertial>
    <visual>
      <geometry>
        <mesh filename="meshes/stage3.glb" />
      </geometry>
      <material name="tool_steel" />
    </visual>
    <collision name="rod">
      <origin xyz="0.005 0 0" rpy="0 0 0" />
      <geometry>
        <box size="0.09 0.009 0.009" />
      </geometry>
    </collision>
    <collision name="tip">
      <origin xyz="0.063 0 0" rpy="0 0 0" />
      <geometry>
        <box size="0.018 0.015 0.015" />
      </geometry>
    </collision>
  </link>
  <joint name="frame_to_stage1" type="prismatic">
    <origin xyz="0.062 0 0" rpy="0 0 0" />
    <parent link="frame" />
    <child link="stage1" />
    <axis xyz="1 0 0" />
    <limit effort="180" velocity="0.18" lower="0" upper="0.03" />
  </joint>
  <joint name="stage1_to_stage2" type="prismatic">
    <origin xyz="0.11 0 0" rpy="0 0 0" />
    <parent link="stage1" />
    <child link="stage2" />
    <axis xyz="1 0 0" />
    <limit effort="120" velocity="0.2" lower="0" upper="0.025" />
  </joint>
  <joint name="stage2_to_stage3" type="prismatic">
    <origin xyz="0.095 0 0" rpy="0 0 0" />
    <parent link="stage2" />
    <child link="stage3" />
    <axis xyz="1 0 0" />
    <limit effort="80" velocity="0.24" lower="0" upper="0.022" />
  </joint>
</robot>