<robot name="enthusiast_pc_tower">
  <material name="case_charcoal">
    <color rgba="0.12 0.13 0.14 1" />
  </material>
  <material name="case_mesh">
    <color rgba="0.06 0.07 0.08 1" />
  </material>
  <material name="glass_smoke">
    <color rgba="0.52 0.62 0.68 0.28" />
  </material>
  <material name="io_shield">
    <color rgba="0.63 0.64 0.66 1" />
  </material>
  <link name="chassis">
    <inertial>
      <origin xyz="0 0 -0.009" rpy="0 0 0" />
      <mass value="10.5" />
      <inertia ixx="0.40253" ixy="0" ixz="0" iyy="0.269705" iyz="0" izz="0.229469" />
    </inertial>
    <visual>
      <geometry>
        <mesh filename="meshes/pc_tower_chassis.glb" />
      </geometry>
      <material name="case_charcoal" />
    </visual>
    <visual>
      <origin xyz="-0.06 0.2269 0.095" rpy="0 0 0" />
      <geometry>
        <box size="0.048 0.0012 0.128" />
      </geometry>
      <material name="io_shield" />
    </visual>
    <collision name="chassis__visual_1__hull_001">
      <geometry>
        <mesh filename="meshes/collision/cache/pc_tower_chassis__bd123cd56083312a__hull_001.obj" />
      </geometry>
    </collision>
    <collision name="chassis__visual_1__hull_002">
      <geometry>
        <mesh filename="meshes/collision/cache/pc_tower_chassis__bd123cd56083312a__hull_002.obj" />
      </geometry>
    </collision>
    <collision name="chassis__visual_1__hull_003">
      <geometry>
        <mesh filename="meshes/collision/cache/pc_tower_chassis__bd123cd56083312a__hull_003.obj" />
      </geometry>
    </collision>
    <collision name="chassis__visual_1__hull_004">
      <geometry>
        <mesh filename="meshes/collision/cache/pc_tower_chassis__bd123cd56083312a__hull_004.obj" />
      </geometry>
    </collision>
    <collision name="chassis__visual_1__hull_005">
      <geometry>
        <mesh filename="meshes/collision/cache/pc_tower_chassis__bd123cd56083312a__hull_005.obj" />
      </geometry>
    </collision>
    <collision name="chassis__visual_1__hull_006">
      <geometry>
        <mesh filename="meshes/collision/cache/pc_tower_chassis__bd123cd56083312a__hull_006.obj" />
      </geometry>
    </collision>
    <collision name="chassis__visual_1__hull_007">
      <geometry>
        <mesh filename="meshes/collision/cache/pc_tower_chassis__bd123cd56083312a__hull_007.obj" />
      </geometry>
    </collision>
    <collision name="chassis__visual_1__hull_008">
      <geometry>
        <mesh filename="meshes/collision/cache/pc_tower_chassis__bd123cd56083312a__hull_008.obj" />
      </geometry>
    </collision>
    <collision name="chassis__visual_1__hull_009">
      <geometry>
        <mesh filename="meshes/collision/cache/pc_tower_chassis__bd123cd56083312a__hull_009.obj" />
      </geometry>
    </collision>
    <collision name="chassis__visual_1__hull_010">
      <geometry>
        <mesh filename="meshes/collision/cache/pc_tower_chassis__bd123cd56083312a__hull_010.obj" />
      </geometry>
    </collision>
    <collision name="chassis__visual_1__hull_011">
      <geometry>
        <mesh filename="meshes/collision/cache/pc_tower_chassis__bd123cd56083312a__hull_011.obj" />
      </geometry>
    </collision>
    <collision name="chassis__visual_1__hull_012">
      <geometry>
        <mesh filename="meshes/collision/cache/pc_tower_chassis__bd123cd56083312a__hull_012.obj" />
      </geometry>
    </collision>
    <collision name="chassis__visual_1__hull_013">
      <geometry>
        <mesh filename="meshes/collision/cache/pc_tower_chassis__bd123cd56083312a__hull_013.obj" />
      </geometry>
    </collision>
    <collision name="chassis__visual_1__hull_014">
      <geometry>
        <mesh filename="meshes/collision/cache/pc_tower_chassis__bd123cd56083312a__hull_014.obj" />
      </geometry>
    </collision>
    <collision name="chassis__visual_1__hull_015">
      <geometry>
        <mesh filename="meshes/collision/cache/pc_tower_chassis__bd123cd56083312a__hull_015.obj" />
      </geometry>
    </collision>
    <collision name="chassis__visual_1__hull_016">
      <geometry>
        <mesh filename="meshes/collision/cache/pc_tower_chassis__bd123cd56083312a__hull_016.obj" />
      </geometry>
    </collision>
    <collision name="chassis__visual_2">
      <origin xyz="-0.06 0.2269 0.095" rpy="0 0 0" />
      <geometry>
        <box size="0.048 0.0012 0.128" />
      </geometry>
    </collision>
  </link>
  <link name="side_panel">
    <inertial>
      <origin xyz="0 0.2105 0" rpy="0 0 0" />
      <mass value="2.2" />
      <inertia ixx="0.0714564" ixy="0" ixz="0" iyy="0.0389651" iyz="0" izz="0.0324971" />
    </inertial>
    <visual>
      <geometry>
        <mesh filename="meshes/pc_tower_side_panel_frame.glb" />
      </geometry>
      <material name="case_charcoal" />
    </visual>
    <visual>
      <geometry>
        <mesh filename="meshes/pc_tower_side_panel_glass.glb" />
      </geometry>
      <material name="glass_smoke" />
    </visual>
    <collision name="side_panel__visual_1__hull_001">
      <geometry>
        <mesh filename="meshes/collision/cache/pc_tower_side_panel_frame__b48b85da5ef42705__hull_001.obj" />
      </geometry>
    </collision>
    <collision name="side_panel__visual_1__hull_002">
      <geometry>
        <mesh filename="meshes/collision/cache/pc_tower_side_panel_frame__b48b85da5ef42705__hull_002.obj" />
      </geometry>
    </collision>
    <collision name="side_panel__visual_1__hull_003">
      <geometry>
        <mesh filename="meshes/collision/cache/pc_tower_side_panel_frame__b48b85da5ef42705__hull_003.obj" />
      </geometry>
    </collision>
    <collision name="side_panel__visual_1__hull_004">
      <geometry>
        <mesh filename="meshes/collision/cache/pc_tower_side_panel_frame__b48b85da5ef42705__hull_004.obj" />
      </geometry>
    </collision>
    <collision name="side_panel__visual_2__hull_001">
      <geometry>
        <mesh filename="meshes/collision/cache/pc_tower_side_panel_glass__1adc6ac7c71bd4f6__hull_001.obj" />
      </geometry>
    </collision>
  </link>
  <link name="front_door">
    <inertial>
      <origin xyz="-0.1085 0 0" rpy="0 0 0" />
      <mass value="0.95" />
      <inertia ixx="0.0156782" ixy="0" ixz="0" iyy="0.0194049" iyz="0" izz="0.00372915" />
    </inertial>
    <visual>
      <geometry>
        <mesh filename="meshes/pc_tower_front_door_frame.glb" />
      </geometry>
      <material name="case_charcoal" />
    </visual>
    <visual>
      <geometry>
        <mesh filename="meshes/pc_tower_front_door_mesh.glb" />
      </geometry>
      <material name="case_mesh" />
    </visual>
    <collision name="front_door__visual_1__hull_001">
      <geometry>
        <mesh filename="meshes/collision/cache/pc_tower_front_door_frame__eb7f56271baeb484__hull_001.obj" />
      </geometry>
    </collision>
    <collision name="front_door__visual_1__hull_002">
      <geometry>
        <mesh filename="meshes/collision/cache/pc_tower_front_door_frame__eb7f56271baeb484__hull_002.obj" />
      </geometry>
    </collision>
    <collision name="front_door__visual_1__hull_003">
      <geometry>
        <mesh filename="meshes/collision/cache/pc_tower_front_door_frame__eb7f56271baeb484__hull_003.obj" />
      </geometry>
    </collision>
    <collision name="front_door__visual_1__hull_004">
      <geometry>
        <mesh filename="meshes/collision/cache/pc_tower_front_door_frame__eb7f56271baeb484__hull_004.obj" />
      </geometry>
    </collision>
    <collision name="front_door__visual_2__hull_001">
      <geometry>
        <mesh filename="meshes/collision/cache/pc_tower_front_door_mesh__b38bb562e138924e__hull_001.obj" />
      </geometry>
    </collision>
  </link>
  <joint name="chassis_to_side_panel" type="revolute">
    <origin xyz="-0.1165 -0.2105 0" rpy="0 0 0" />
    <parent link="chassis" />
    <child link="side_panel" />
    <axis xyz="0 0 1" />
    <limit effort="8" velocity="1.5" lower="0" upper="1.35" />
  </joint>
  <joint name="chassis_to_front_door" type="revolute">
    <origin xyz="0.1055 -0.2255 0" rpy="0 0 0" />
    <parent link="chassis" />
    <child link="front_door" />
    <axis xyz="0 0 1" />
    <limit effort="4" velocity="1.5" lower="0" upper="1.15" />
  </joint>
</robot>