<robot name="eyeglasses">
  <link name="frame_front">
    <inertial>
      <origin xyz="0 0 0.002" rpy="0 0 0" />
      <mass value="0.024" />
      <inertia ixx="8.336e-06" ixy="0" ixz="0" iyy="4.9738e-05" iyz="0" izz="4.2698e-05" />
    </inertial>
    <visual name="front_frame">
      <geometry>
        <mesh filename="meshes/glasses_front_frame.glb" />
      </geometry>
      <material name="black_acetate">
        <color rgba="0.1 0.1 0.11 1" />
      </material>
    </visual>
    <visual name="left_lens">
      <origin xyz="-0.034 0 0.0012" rpy="0 0 0" />
      <geometry>
        <mesh filename="meshes/glasses_lens.glb" />
      </geometry>
      <material name="smoked_lens">
        <color rgba="0.43 0.46 0.5 0.28" />
      </material>
    </visual>
    <visual name="right_lens">
      <origin xyz="0.034 0 0.0012" rpy="0 0 0" />
      <geometry>
        <mesh filename="meshes/glasses_lens.glb" />
      </geometry>
      <material name="smoked_lens">
        <color rgba="0.43 0.46 0.5 0.28" />
      </material>
    </visual>
    <visual name="bridge_saddle">
      <origin xyz="0 -0.0014 -0.0102" rpy="0 0 0" />
      <geometry>
        <box size="0.011 0.0034 0.0085" />
      </geometry>
      <material name="black_acetate">
        <color rgba="0.1 0.1 0.11 1" />
      </material>
    </visual>
    <visual name="left_pad_arm">
      <origin xyz="-0.0083 -0.0027 -0.008" rpy="0 0 0" />
      <geometry>
        <box size="0.0018 0.0052 0.012" />
      </geometry>
      <material name="brushed_steel">
        <color rgba="0.74 0.76 0.79 1" />
      </material>
    </visual>
    <visual name="right_pad_arm">
      <origin xyz="0.0083 -0.0027 -0.008" rpy="0 0 0" />
      <geometry>
        <box size="0.0018 0.0052 0.012" />
      </geometry>
      <material name="brushed_steel">
        <color rgba="0.74 0.76 0.79 1" />
      </material>
    </visual>
    <visual name="left_nose_pad">
      <origin xyz="-0.0106 -0.0043 -0.012" rpy="0 0 0" />
      <geometry>
        <sphere radius="0.0034" />
      </geometry>
      <material name="clear_pad">
        <color rgba="0.92 0.94 0.97 0.55" />
      </material>
    </visual>
    <visual name="right_nose_pad">
      <origin xyz="0.0106 -0.0043 -0.012" rpy="0 0 0" />
      <geometry>
        <sphere radius="0.0034" />
      </geometry>
      <material name="clear_pad">
        <color rgba="0.92 0.94 0.97 0.55" />
      </material>
    </visual>
    <visual name="left_hinge_plate">
      <origin xyz="-0.0685 -0.0028 0.0105" rpy="0 0 0" />
      <geometry>
        <box size="0.004 0.006 0.011" />
      </geometry>
      <material name="brushed_steel">
        <color rgba="0.74 0.76 0.79 1" />
      </material>
    </visual>
    <visual name="right_hinge_plate">
      <origin xyz="0.0685 -0.0042 0.0105" rpy="0 0 0" />
      <geometry>
        <box size="0.004 0.007 0.011" />
      </geometry>
      <material name="brushed_steel">
        <color rgba="0.74 0.76 0.79 1" />
      </material>
    </visual>
    <visual name="left_hinge_barrel">
      <origin xyz="-0.0685 -0.0028 0.0105" rpy="0 0 0" />
      <geometry>
        <cylinder radius="0.0018" length="0.0052" />
      </geometry>
      <material name="brushed_steel">
        <color rgba="0.74 0.76 0.79 1" />
      </material>
    </visual>
    <visual name="right_hinge_barrel">
      <origin xyz="0.0685 -0.0042 0.0105" rpy="0 0 0" />
      <geometry>
        <cylinder radius="0.0018" length="0.0052" />
      </geometry>
      <material name="brushed_steel">
        <color rgba="0.74 0.76 0.79 1" />
      </material>
    </visual>
    <collision name="frame_front__front_frame__hull_001">
      <geometry>
        <mesh filename="meshes/collision/cache/69724ba671907327b06d91db__hull_001.obj" />
      </geometry>
    </collision>
    <collision name="frame_front__front_frame__hull_002">
      <geometry>
        <mesh filename="meshes/collision/cache/69724ba671907327b06d91db__hull_002.obj" />
      </geometry>
    </collision>
    <collision name="frame_front__front_frame__hull_003">
      <geometry>
        <mesh filename="meshes/collision/cache/69724ba671907327b06d91db__hull_003.obj" />
      </geometry>
    </collision>
    <collision name="frame_front__front_frame__hull_004">
      <geometry>
        <mesh filename="meshes/collision/cache/69724ba671907327b06d91db__hull_004.obj" />
      </geometry>
    </collision>
    <collision name="frame_front__front_frame__hull_005">
      <geometry>
        <mesh filename="meshes/collision/cache/69724ba671907327b06d91db__hull_005.obj" />
      </geometry>
    </collision>
    <collision name="frame_front__front_frame__hull_006">
      <geometry>
        <mesh filename="meshes/collision/cache/69724ba671907327b06d91db__hull_006.obj" />
      </geometry>
    </collision>
    <collision name="frame_front__front_frame__hull_007">
      <geometry>
        <mesh filename="meshes/collision/cache/69724ba671907327b06d91db__hull_007.obj" />
      </geometry>
    </collision>
    <collision name="frame_front__front_frame__hull_008">
      <geometry>
        <mesh filename="meshes/collision/cache/69724ba671907327b06d91db__hull_008.obj" />
      </geometry>
    </collision>
    <collision name="frame_front__front_frame__hull_009">
      <geometry>
        <mesh filename="meshes/collision/cache/69724ba671907327b06d91db__hull_009.obj" />
      </geometry>
    </collision>
    <collision name="frame_front__left_lens__hull_001">
      <origin xyz="-0.034 0 0.0012" rpy="0 0 0" />
      <geometry>
        <mesh filename="meshes/collision/cache/aa1295d536fea4bdb19e5dfc__hull_001.obj" />
      </geometry>
    </collision>
    <collision name="frame_front__right_lens__hull_001">
      <origin xyz="0.034 0 0.0012" rpy="0 0 0" />
      <geometry>
        <mesh filename="meshes/collision/cache/aa1295d536fea4bdb19e5dfc__hull_001.obj" />
      </geometry>
    </collision>
    <collision name="frame_front__bridge_saddle">
      <origin xyz="0 -0.0014 -0.0102" rpy="0 0 0" />
      <geometry>
        <box size="0.011 0.0034 0.0085" />
      </geometry>
    </collision>
    <collision name="frame_front__left_pad_arm">
      <origin xyz="-0.0083 -0.0027 -0.008" rpy="0 0 0" />
      <geometry>
        <box size="0.0018 0.0052 0.012" />
      </geometry>
    </collision>
    <collision name="frame_front__right_pad_arm">
      <origin xyz="0.0083 -0.0027 -0.008" rpy="0 0 0" />
      <geometry>
        <box size="0.0018 0.0052 0.012" />
      </geometry>
    </collision>
    <collision name="frame_front__left_nose_pad">
      <origin xyz="-0.0106 -0.0043 -0.012" rpy="0 0 0" />
      <geometry>
        <sphere radius="0.0034" />
      </geometry>
    </collision>
    <collision name="frame_front__right_nose_pad">
      <origin xyz="0.0106 -0.0043 -0.012" rpy="0 0 0" />
      <geometry>
        <sphere radius="0.0034" />
      </geometry>
    </collision>
    <collision name="frame_front__left_hinge_plate">
      <origin xyz="-0.0685 -0.0028 0.0105" rpy="0 0 0" />
      <geometry>
        <box size="0.004 0.006 0.011" />
      </geometry>
    </collision>
    <collision name="frame_front__right_hinge_plate">
      <origin xyz="0.0685 -0.0042 0.0105" rpy="0 0 0" />
      <geometry>
        <box size="0.004 0.007 0.011" />
      </geometry>
    </collision>
    <collision name="frame_front__left_hinge_barrel">
      <origin xyz="-0.0685 -0.0028 0.0105" rpy="0 0 0" />
      <geometry>
        <cylinder radius="0.0018" length="0.0052" />
      </geometry>
    </collision>
    <collision name="frame_front__right_hinge_barrel">
      <origin xyz="0.0685 -0.0042 0.0105" rpy="0 0 0" />
      <geometry>
        <cylinder radius="0.0018" length="0.0052" />
      </geometry>
    </collision>
  </link>
  <link name="left_temple">
    <inertial>
      <origin xyz="0 -0.074 -0.013" rpy="0 0 0" />
      <mass value="0.007" />
      <inertia ixx="1.4154e-05" ixy="0" ixz="0" iyy="1.08733e-06" iyz="0" izz="1.31833e-05" />
    </inertial>
    <visual name="left_temple_body">
      <geometry>
        <mesh filename="meshes/glasses_temple_body.glb" />
      </geometry>
      <material name="black_acetate">
        <color rgba="0.1 0.1 0.11 1" />
      </material>
    </visual>
    <visual name="left_temple_tip">
      <geometry>
        <mesh filename="meshes/glasses_temple_tip.glb" />
      </geometry>
      <material name="rubber_tip">
        <color rgba="0.06 0.06 0.07 1" />
      </material>
    </visual>
    <visual name="left_temple_knuckle">
      <geometry>
        <cylinder radius="0.0016" length="0.0042" />
      </geometry>
      <material name="brushed_steel">
        <color rgba="0.74 0.76 0.79 1" />
      </material>
    </visual>
    <visual name="left_core_inlay">
      <origin xyz="0 -0.028 0.0026" rpy="0 0 0" />
      <geometry>
        <box size="0.001 0.028 0.0012" />
      </geometry>
      <material name="brushed_steel">
        <color rgba="0.74 0.76 0.79 1" />
      </material>
    </visual>
    <collision name="left_temple__left_temple_body__hull_001">
      <geometry>
        <mesh filename="meshes/collision/cache/f72302568965d2f4218bcdef__hull_001.obj" />
      </geometry>
    </collision>
    <collision name="left_temple__left_temple_body__hull_002">
      <geometry>
        <mesh filename="meshes/collision/cache/f72302568965d2f4218bcdef__hull_002.obj" />
      </geometry>
    </collision>
    <collision name="left_temple__left_temple_body__hull_003">
      <geometry>
        <mesh filename="meshes/collision/cache/f72302568965d2f4218bcdef__hull_003.obj" />
      </geometry>
    </collision>
    <collision name="left_temple__left_temple_tip__hull_001">
      <geometry>
        <mesh filename="meshes/collision/cache/06417c5ce0a7390857a5711d__hull_001.obj" />
      </geometry>
    </collision>
    <collision name="left_temple__left_temple_tip__hull_002">
      <geometry>
        <mesh filename="meshes/collision/cache/06417c5ce0a7390857a5711d__hull_002.obj" />
      </geometry>
    </collision>
    <collision name="left_temple__left_temple_knuckle">
      <geometry>
        <cylinder radius="0.0016" length="0.0042" />
      </geometry>
    </collision>
    <collision name="left_temple__left_core_inlay">
      <origin xyz="0 -0.028 0.0026" rpy="0 0 0" />
      <geometry>
        <box size="0.001 0.028 0.0012" />
      </geometry>
    </collision>
  </link>
  <link name="right_temple">
    <inertial>
      <origin xyz="0 -0.074 -0.013" rpy="0 0 0" />
      <mass value="0.007" />
      <inertia ixx="1.4154e-05" ixy="0" ixz="0" iyy="1.08733e-06" iyz="0" izz="1.31833e-05" />
    </inertial>
    <visual name="right_temple_body">
      <geometry>
        <mesh filename="meshes/glasses_temple_body.glb" />
      </geometry>
      <material name="black_acetate">
        <color rgba="0.1 0.1 0.11 1" />
      </material>
    </visual>
    <visual name="right_temple_tip">
      <geometry>
        <mesh filename="meshes/glasses_temple_tip.glb" />
      </geometry>
      <material name="rubber_tip">
        <color rgba="0.06 0.06 0.07 1" />
      </material>
    </visual>
    <visual name="right_temple_knuckle">
      <geometry>
        <cylinder radius="0.0016" length="0.0042" />
      </geometry>
      <material name="brushed_steel">
        <color rgba="0.74 0.76 0.79 1" />
      </material>
    </visual>
    <visual name="right_core_inlay">
      <origin xyz="0 -0.028 0.0026" rpy="0 0 0" />
      <geometry>
        <box size="0.001 0.028 0.0012" />
      </geometry>
      <material name="brushed_steel">
        <color rgba="0.74 0.76 0.79 1" />
      </material>
    </visual>
    <collision name="right_temple__right_temple_body__hull_001">
      <geometry>
        <mesh filename="meshes/collision/cache/f72302568965d2f4218bcdef__hull_001.obj" />
      </geometry>
    </collision>
    <collision name="right_temple__right_temple_body__hull_002">
      <geometry>
        <mesh filename="meshes/collision/cache/f72302568965d2f4218bcdef__hull_002.obj" />
      </geometry>
    </collision>
    <collision name="right_temple__right_temple_body__hull_003">
      <geometry>
        <mesh filename="meshes/collision/cache/f72302568965d2f4218bcdef__hull_003.obj" />
      </geometry>
    </collision>
    <collision name="right_temple__right_temple_tip__hull_001">
      <geometry>
        <mesh filename="meshes/collision/cache/06417c5ce0a7390857a5711d__hull_001.obj" />
      </geometry>
    </collision>
    <collision name="right_temple__right_temple_tip__hull_002">
      <geometry>
        <mesh filename="meshes/collision/cache/06417c5ce0a7390857a5711d__hull_002.obj" />
      </geometry>
    </collision>
    <collision name="right_temple__right_temple_knuckle">
      <geometry>
        <cylinder radius="0.0016" length="0.0042" />
      </geometry>
    </collision>
    <collision name="right_temple__right_core_inlay">
      <origin xyz="0 -0.028 0.0026" rpy="0 0 0" />
      <geometry>
        <box size="0.001 0.028 0.0012" />
      </geometry>
    </collision>
  </link>
  <joint name="left_hinge" type="revolute">
    <origin xyz="-0.0685 -0.0028 0.0105" rpy="0 0 0" />
    <parent link="frame_front" />
    <child link="left_temple" />
    <axis xyz="0 0 1" />
    <limit effort="0.6" velocity="5" lower="0" upper="1.28" />
  </joint>
  <joint name="right_hinge" type="revolute">
    <origin xyz="0.0685 -0.0042 0.0105" rpy="0 0 0" />
    <parent link="frame_front" />
    <child link="right_temple" />
    <axis xyz="0 0 -1" />
    <limit effort="0.6" velocity="5" lower="0" upper="1.28" />
  </joint>
</robot>