<robot name="inspection_arm">
  <material name="powder_steel">
    <color rgba="0.22 0.24 0.27 1" />
    </material>
  <material name="zinc">
    <color rgba="0.7 0.72 0.76 1" />
    </material>
  <material name="aluminum">
    <color rgba="0.67 0.7 0.74 1" />
    </material>
  <material name="anodized_dark">
    <color rgba="0.3 0.33 0.36 1" />
    </material>
  <material name="matte_black">
    <color rgba="0.1 0.11 0.12 1" />
    </material>
  <material name="glass">
    <color rgba="0.52 0.72 0.84 0.55" />
    </material>
  <material name="amber">
    <color rgba="0.93 0.64 0.17 0.95" />
    </material>
  <link name="base_mount">
    <inertial>
      <origin xyz="0 0 0.06" rpy="0 0 0" />
      <mass value="4.4" />
      <inertia ixx="0.00971667" ixy="0" ixz="0" iyy="0.01716" iyz="0" izz="0.0163167" />
      </inertial>
    <visual>
      <geometry>
        <mesh filename="meshes/base_mount.obj" />
        </geometry>
      <material name="powder_steel" />
      </visual>
    <visual>
      <origin xyz="-0.055 -0.032 0.014" rpy="0 0 0" />
      <geometry>
        <cylinder radius="0.008" length="0.004" />
        </geometry>
      <material name="zinc" />
      </visual>
    <visual>
      <origin xyz="-0.055 0.032 0.014" rpy="0 0 0" />
      <geometry>
        <cylinder radius="0.008" length="0.004" />
        </geometry>
      <material name="zinc" />
      </visual>
    <visual>
      <origin xyz="0.055 -0.032 0.014" rpy="0 0 0" />
      <geometry>
        <cylinder radius="0.008" length="0.004" />
        </geometry>
      <material name="zinc" />
      </visual>
    <visual>
      <origin xyz="0.055 0.032 0.014" rpy="0 0 0" />
      <geometry>
        <cylinder radius="0.008" length="0.004" />
        </geometry>
      <material name="zinc" />
      </visual>
    <collision name="base_mount__visual_1__hull_001">
      <geometry>
        <mesh filename="meshes/collision/cache/base_mount__3c1bb7cf56f4bc1f__hull_001.obj" />
        </geometry>
      </collision>
    <collision name="base_mount__visual_1__hull_002">
      <geometry>
        <mesh filename="meshes/collision/cache/base_mount__3c1bb7cf56f4bc1f__hull_002.obj" />
        </geometry>
      </collision>
    <collision name="base_mount__visual_1__hull_003">
      <geometry>
        <mesh filename="meshes/collision/cache/base_mount__3c1bb7cf56f4bc1f__hull_003.obj" />
        </geometry>
      </collision>
    <collision name="base_mount__visual_1__hull_004">
      <geometry>
        <mesh filename="meshes/collision/cache/base_mount__3c1bb7cf56f4bc1f__hull_004.obj" />
        </geometry>
      </collision>
    <collision name="base_mount__visual_1__hull_005">
      <geometry>
        <mesh filename="meshes/collision/cache/base_mount__3c1bb7cf56f4bc1f__hull_005.obj" />
        </geometry>
      </collision>
    <collision name="base_mount__visual_1__hull_006">
      <geometry>
        <mesh filename="meshes/collision/cache/base_mount__3c1bb7cf56f4bc1f__hull_006.obj" />
        </geometry>
      </collision>
    <collision name="base_mount__visual_1__hull_007">
      <geometry>
        <mesh filename="meshes/collision/cache/base_mount__3c1bb7cf56f4bc1f__hull_007.obj" />
        </geometry>
      </collision>
    <collision name="base_mount__visual_1__hull_008">
      <geometry>
        <mesh filename="meshes/collision/cache/base_mount__3c1bb7cf56f4bc1f__hull_008.obj" />
        </geometry>
      </collision>
    <collision name="base_mount__visual_1__hull_009">
      <geometry>
        <mesh filename="meshes/collision/cache/base_mount__3c1bb7cf56f4bc1f__hull_009.obj" />
        </geometry>
      </collision>
    <collision name="base_mount__visual_1__hull_010">
      <geometry>
        <mesh filename="meshes/collision/cache/base_mount__3c1bb7cf56f4bc1f__hull_010.obj" />
        </geometry>
      </collision>
    <collision name="base_mount__visual_1__hull_011">
      <geometry>
        <mesh filename="meshes/collision/cache/base_mount__3c1bb7cf56f4bc1f__hull_011.obj" />
        </geometry>
      </collision>
    <collision name="base_mount__visual_2">
      <origin xyz="-0.055 -0.032 0.014" rpy="0 0 0" />
      <geometry>
        <cylinder radius="0.008" length="0.004" />
        </geometry>
      </collision>
    <collision name="base_mount__visual_3">
      <origin xyz="-0.055 0.032 0.014" rpy="0 0 0" />
      <geometry>
        <cylinder radius="0.008" length="0.004" />
        </geometry>
      </collision>
    <collision name="base_mount__visual_4">
      <origin xyz="0.055 -0.032 0.014" rpy="0 0 0" />
      <geometry>
        <cylinder radius="0.008" length="0.004" />
        </geometry>
      </collision>
    <collision name="base_mount__visual_5">
      <origin xyz="0.055 0.032 0.014" rpy="0 0 0" />
      <geometry>
        <cylinder radius="0.008" length="0.004" />
        </geometry>
      </collision>
    </link>
  <link name="pivot_arm">
    <inertial>
      <origin xyz="0.145 0 0" rpy="0 0 0" />
      <mass value="1.3" />
      <inertia ixx="0.000589333" ixy="0" ixz="0" iyy="0.00844231" iyz="0" izz="0.00853244" />
      </inertial>
    <visual>
      <geometry>
        <mesh filename="meshes/pivot_arm.obj" />
        </geometry>
      <material name="aluminum" />
      </visual>
    <collision name="pivot_arm__visual_1__hull_001">
      <geometry>
        <mesh filename="meshes/collision/cache/pivot_arm__739fd369b5b812fc__hull_001.obj" />
        </geometry>
      </collision>
    <collision name="pivot_arm__visual_1__hull_002">
      <geometry>
        <mesh filename="meshes/collision/cache/pivot_arm__739fd369b5b812fc__hull_002.obj" />
        </geometry>
      </collision>
    <collision name="pivot_arm__visual_1__hull_003">
      <geometry>
        <mesh filename="meshes/collision/cache/pivot_arm__739fd369b5b812fc__hull_003.obj" />
        </geometry>
      </collision>
    <collision name="pivot_arm__visual_1__hull_004">
      <geometry>
        <mesh filename="meshes/collision/cache/pivot_arm__739fd369b5b812fc__hull_004.obj" />
        </geometry>
      </collision>
    <collision name="pivot_arm__visual_1__hull_005">
      <geometry>
        <mesh filename="meshes/collision/cache/pivot_arm__739fd369b5b812fc__hull_005.obj" />
        </geometry>
      </collision>
    <collision name="pivot_arm__visual_1__hull_006">
      <geometry>
        <mesh filename="meshes/collision/cache/pivot_arm__739fd369b5b812fc__hull_006.obj" />
        </geometry>
      </collision>
    <collision name="pivot_arm__visual_1__hull_007">
      <geometry>
        <mesh filename="meshes/collision/cache/pivot_arm__739fd369b5b812fc__hull_007.obj" />
        </geometry>
      </collision>
    <collision name="pivot_arm__visual_1__hull_008">
      <geometry>
        <mesh filename="meshes/collision/cache/pivot_arm__739fd369b5b812fc__hull_008.obj" />
        </geometry>
      </collision>
    <collision name="pivot_arm__visual_1__hull_009">
      <geometry>
        <mesh filename="meshes/collision/cache/pivot_arm__739fd369b5b812fc__hull_009.obj" />
        </geometry>
      </collision>
    </link>
  <link name="extension_stage">
    <inertial>
      <origin xyz="0.12 0 0" rpy="0 0 0" />
      <mass value="0.95" />
      <inertia ixx="0.000324583" ixy="0" ixz="0" iyy="0.00547833" iyz="0" izz="0.00554958" />
      </inertial>
    <visual>
      <geometry>
        <mesh filename="meshes/extension_rail.obj" />
        </geometry>
      <material name="anodized_dark" />
      </visual>
    <visual>
      <geometry>
        <mesh filename="meshes/inspection_head.obj" />
        </geometry>
      <material name="matte_black" />
      </visual>
    <visual>
      <origin xyz="0.242 0 0" rpy="0 1.5708 0" />
      <geometry>
        <cylinder radius="0.013" length="0.018" />
        </geometry>
      <material name="glass" />
      </visual>
    <visual>
      <origin xyz="0.229 0 -0.018" rpy="0 1.5708 0" />
      <geometry>
        <cylinder radius="0.006" length="0.005" />
        </geometry>
      <material name="amber" />
      </visual>
    <collision name="extension_stage__visual_1__hull_001">
      <geometry>
        <mesh filename="meshes/collision/cache/extension_rail__2b8df7652bc1a42d__hull_001.obj" />
        </geometry>
      </collision>
    <collision name="extension_stage__visual_2__hull_001">
      <geometry>
        <mesh filename="meshes/collision/cache/inspection_head__3044199908d7af50__hull_001.obj" />
        </geometry>
      </collision>
    <collision name="extension_stage__visual_2__hull_002">
      <geometry>
        <mesh filename="meshes/collision/cache/inspection_head__3044199908d7af50__hull_002.obj" />
        </geometry>
      </collision>
    <collision name="extension_stage__visual_3">
      <origin xyz="0.242 0 0" rpy="0 1.5708 0" />
      <geometry>
        <cylinder radius="0.013" length="0.018" />
        </geometry>
      </collision>
    <collision name="extension_stage__visual_4">
      <origin xyz="0.229 0 -0.018" rpy="0 1.5708 0" />
      <geometry>
        <cylinder radius="0.006" length="0.005" />
        </geometry>
      </collision>
    </link>
  <joint name="base_hinge" type="revolute">
    <origin xyz="0 0 0.095" rpy="0 0 0" />
    <parent link="base_mount" />
    <child link="pivot_arm" />
    <axis xyz="0 -1 0" />
    <limit effort="18" velocity="1.5" lower="0" upper="1.1" />
    </joint>
  <joint name="stage_extension" type="prismatic">
    <origin xyz="0.066 0 0" rpy="0 0 0" />
    <parent link="pivot_arm" />
    <child link="extension_stage" />
    <axis xyz="1 0 0" />
    <limit effort="12" velocity="0.25" lower="0" upper="0.14" />
    </joint>
  </robot>
