<robot name="turnstile_gate">
  <material name="powder_coat">
    <color rgba="0.16 0.18 0.2 1" />
  </material>
  <material name="brushed_steel">
    <color rgba="0.77 0.79 0.82 1" />
  </material>
  <material name="matte_black">
    <color rgba="0.08 0.08 0.09 1" />
  </material>
  <material name="glass">
    <color rgba="0.15 0.24 0.28 0.45" />
  </material>
  <material name="indicator_green">
    <color rgba="0.18 0.82 0.4 0.8" />
  </material>
  <material name="indicator_red">
    <color rgba="0.84 0.2 0.2 0.8" />
  </material>
  <material name="rubber">
    <color rgba="0.05 0.05 0.05 1" />
  </material>
  <link name="body">
    <inertial>
      <origin xyz="0 0 0.51" rpy="0 0 0" />
      <mass value="82" />
      <inertia ixx="7.995" ixy="0" ixz="0" iyy="8.55533" iyz="0" izz="2.33153" />
    </inertial>
    <visual name="floor_plinth">
      <origin xyz="0 0 0.02" rpy="0 0 0" />
      <geometry>
        <box size="0.46 0.36 0.04" />
      </geometry>
      <material name="powder_coat">
        <color rgba="0.16 0.18 0.2 1" />
      </material>
    </visual>
    <visual name="cabinet_shell">
      <geometry>
        <mesh filename="meshes/turnstile_body_shell.glb" />
      </geometry>
      <material name="brushed_steel">
        <color rgba="0.77 0.79 0.82 1" />
      </material>
    </visual>
    <visual name="top_deck">
      <origin xyz="0 0.03 0.895" rpy="0 0 0" />
      <geometry>
        <box size="0.34 0.2 0.014" />
      </geometry>
      <material name="matte_black">
        <color rgba="0.08 0.08 0.09 1" />
      </material>
    </visual>
    <visual name="service_panel">
      <origin xyz="0 -0.147 0.48" rpy="0 0 0" />
      <geometry>
        <box size="0.22 0.006 0.3" />
      </geometry>
      <material name="matte_black">
        <color rgba="0.08 0.08 0.09 1" />
      </material>
    </visual>
    <visual name="bearing_collar">
      <origin xyz="0 0.145 0.93" rpy="1.5708 0 0" />
      <geometry>
        <cylinder radius="0.062" length="0.018" />
      </geometry>
      <material name="brushed_steel">
        <color rgba="0.77 0.79 0.82 1" />
      </material>
    </visual>
    <collision name="body__floor_plinth">
      <origin xyz="0 0 0.02" rpy="0 0 0" />
      <geometry>
        <box size="0.46 0.36 0.04" />
      </geometry>
    </collision>
    <collision name="body__cabinet_shell__hull_001">
      <geometry>
        <mesh filename="meshes/collision/cache/c4c37c3b2c81afa709cad597__hull_001.obj" />
      </geometry>
    </collision>
    <collision name="body__top_deck">
      <origin xyz="0 0.03 0.895" rpy="0 0 0" />
      <geometry>
        <box size="0.34 0.2 0.014" />
      </geometry>
    </collision>
    <collision name="body__service_panel">
      <origin xyz="0 -0.147 0.48" rpy="0 0 0" />
      <geometry>
        <box size="0.22 0.006 0.3" />
      </geometry>
    </collision>
    <collision name="body__bearing_collar">
      <origin xyz="0 0.145 0.93" rpy="1.5708 0 0" />
      <geometry>
        <cylinder radius="0.062" length="0.018" />
      </geometry>
    </collision>
  </link>
  <link name="control_head">
    <inertial>
      <origin xyz="0 0.008 0.04" rpy="0 0 0" />
      <mass value="3.8" />
      <inertia ixx="0.00658667" ixy="0" ixz="0" iyy="0.00823333" iyz="0" izz="0.0107667" />
    </inertial>
    <visual name="reader_pod">
      <geometry>
        <mesh filename="meshes/turnstile_control_head.glb" />
      </geometry>
      <material name="matte_black">
        <color rgba="0.08 0.08 0.09 1" />
      </material>
    </visual>
    <visual name="display_glass">
      <origin xyz="0 0.047 0.04" rpy="-0.34 0 0" />
      <geometry>
        <box size="0.088 0.006 0.075" />
      </geometry>
      <material name="glass">
        <color rgba="0.15 0.24 0.28 0.45" />
      </material>
    </visual>
    <visual name="status_arrow">
      <origin xyz="-0.034 0.053 0.06" rpy="-0.34 0 0" />
      <geometry>
        <box size="0.03 0.004 0.018" />
      </geometry>
      <material name="indicator_green">
        <color rgba="0.18 0.82 0.4 0.8" />
      </material>
    </visual>
    <visual name="status_stop">
      <origin xyz="0.033 0.053 0.06" rpy="-0.34 0 0" />
      <geometry>
        <box size="0.026 0.004 0.018" />
      </geometry>
      <material name="indicator_red">
        <color rgba="0.84 0.2 0.2 0.8" />
      </material>
    </visual>
    <collision name="control_head__reader_pod__hull_001">
      <geometry>
        <mesh filename="meshes/collision/cache/b469808904f7a7c7441b4a16__hull_001.obj" />
      </geometry>
    </collision>
    <collision name="control_head__display_glass">
      <origin xyz="0 0.047 0.04" rpy="-0.34 0 0" />
      <geometry>
        <box size="0.088 0.006 0.075" />
      </geometry>
    </collision>
    <collision name="control_head__status_arrow">
      <origin xyz="-0.034 0.053 0.06" rpy="-0.34 0 0" />
      <geometry>
        <box size="0.03 0.004 0.018" />
      </geometry>
    </collision>
    <collision name="control_head__status_stop">
      <origin xyz="0.033 0.053 0.06" rpy="-0.34 0 0" />
      <geometry>
        <box size="0.026 0.004 0.018" />
      </geometry>
    </collision>
  </link>
  <link name="rotor">
    <inertial>
      <origin xyz="0 0.096 0" rpy="0 0 0" />
      <mass value="8.5" />
      <inertia ixx="0.375771" ixy="0" ixz="0" iyy="0.7344" iyz="0" izz="0.375771" />
    </inertial>
    <visual name="tripod_rotor">
      <geometry>
        <mesh filename="meshes/turnstile_rotor_core.glb" />
      </geometry>
      <material name="brushed_steel">
        <color rgba="0.77 0.79 0.82 1" />
      </material>
    </visual>
    <visual name="arm_tip_1">
      <origin xyz="0.35 0.096 0" rpy="0 0 0" />
      <geometry>
        <sphere radius="0.018" />
      </geometry>
      <material name="rubber">
        <color rgba="0.05 0.05 0.05 1" />
      </material>
    </visual>
    <visual name="arm_tip_2">
      <origin xyz="-0.175 0.096 0.303109" rpy="0 0 0" />
      <geometry>
        <sphere radius="0.018" />
      </geometry>
      <material name="rubber">
        <color rgba="0.05 0.05 0.05 1" />
      </material>
    </visual>
    <visual name="arm_tip_3">
      <origin xyz="-0.175 0.096 -0.303109" rpy="0 0 0" />
      <geometry>
        <sphere radius="0.018" />
      </geometry>
      <material name="rubber">
        <color rgba="0.05 0.05 0.05 1" />
      </material>
    </visual>
    <collision name="rotor__tripod_rotor__hull_001">
      <geometry>
        <mesh filename="meshes/collision/cache/1d4a553c3b9c076f2eda78c9__hull_001.obj" />
      </geometry>
    </collision>
    <collision name="rotor__tripod_rotor__hull_002">
      <geometry>
        <mesh filename="meshes/collision/cache/1d4a553c3b9c076f2eda78c9__hull_002.obj" />
      </geometry>
    </collision>
    <collision name="rotor__tripod_rotor__hull_003">
      <geometry>
        <mesh filename="meshes/collision/cache/1d4a553c3b9c076f2eda78c9__hull_003.obj" />
      </geometry>
    </collision>
    <collision name="rotor__tripod_rotor__hull_004">
      <geometry>
        <mesh filename="meshes/collision/cache/1d4a553c3b9c076f2eda78c9__hull_004.obj" />
      </geometry>
    </collision>
    <collision name="rotor__tripod_rotor__hull_005">
      <geometry>
        <mesh filename="meshes/collision/cache/1d4a553c3b9c076f2eda78c9__hull_005.obj" />
      </geometry>
    </collision>
    <collision name="rotor__tripod_rotor__hull_006">
      <geometry>
        <mesh filename="meshes/collision/cache/1d4a553c3b9c076f2eda78c9__hull_006.obj" />
      </geometry>
    </collision>
    <collision name="rotor__arm_tip_1">
      <origin xyz="0.35 0.096 0" rpy="0 0 0" />
      <geometry>
        <sphere radius="0.018" />
      </geometry>
    </collision>
    <collision name="rotor__arm_tip_2">
      <origin xyz="-0.175 0.096 0.303109" rpy="0 0 0" />
      <geometry>
        <sphere radius="0.018" />
      </geometry>
    </collision>
    <collision name="rotor__arm_tip_3">
      <origin xyz="-0.175 0.096 -0.303109" rpy="0 0 0" />
      <geometry>
        <sphere radius="0.018" />
      </geometry>
    </collision>
  </link>
  <joint name="body_to_control_head" type="fixed">
    <origin xyz="0 0.06 0.9" rpy="0 0 0" />
    <parent link="body" />
    <child link="control_head" />
  </joint>
  <joint name="tripod_rotation" type="continuous">
    <origin xyz="0 0.154 0.93" rpy="0 0 0" />
    <parent link="body" />
    <child link="rotor" />
    <axis xyz="0 1 0" />
    <limit effort="40" velocity="3.5" />
  </joint>
</robot>