<robot name="coaxial_rotary_stack">
  <material name="base_steel">
    <color rgba="0.58 0.6 0.63 1" />
  </material>
  <material name="outer_anodized">
    <color rgba="0.3 0.34 0.4 1" />
  </material>
  <material name="middle_anodized">
    <color rgba="0.42 0.46 0.52 1" />
  </material>
  <material name="inner_rotor">
    <color rgba="0.74 0.48 0.2 1" />
  </material>
  <link name="base">
    <inertial>
      <origin xyz="0 0 0.013" rpy="0 0 0" />
      <mass value="5.8" />
      <inertia ixx="0.0215446" ixy="0" ixz="0" iyy="0.0215446" iyz="0" izz="0.0383525" />
    </inertial>
    <visual>
      <geometry>
        <mesh filename="meshes/base.glb" />
      </geometry>
      <material name="base_steel" />
    </visual>
    <collision>
      <origin xyz="0 0 -0.015" rpy="0 0 0" />
      <geometry>
        <cylinder radius="0.115" length="0.014" />
      </geometry>
    </collision>
    <collision>
      <origin xyz="0 0 -0.005" rpy="0 0 0" />
      <geometry>
        <cylinder radius="0.07" length="0.006" />
      </geometry>
    </collision>
    <collision>
      <origin xyz="0 0 0.005" rpy="0 0 0" />
      <geometry>
        <cylinder radius="0.012" length="0.014" />
      </geometry>
    </collision>
    <collision>
      <origin xyz="-0.072 0 -0.004" rpy="0 0 0" />
      <geometry>
        <box size="0.03 0.018 0.012" />
      </geometry>
    </collision>
  </link>
  <link name="outer_stage">
    <inertial>
      <origin xyz="0.056 0 0.039" rpy="0 0 0" />
      <mass value="2.2" />
      <inertia ixx="0.00815833" ixy="0" ixz="0" iyy="0.0171783" iyz="0" izz="0.0231059" />
    </inertial>
    <visual>
      <geometry>
        <mesh filename="meshes/outer_stage.glb" />
      </geometry>
      <material name="outer_anodized" />
    </visual>
    <collision name="outer_hub_px">
      <origin xyz="0.023 0 0.01" rpy="0 0 0" />
      <geometry>
        <box size="0.014 0.014 0.016" />
      </geometry>
    </collision>
    <collision name="outer_hub_nx">
      <origin xyz="-0.023 0 0.01" rpy="0 0 0" />
      <geometry>
        <box size="0.014 0.014 0.016" />
      </geometry>
    </collision>
    <collision name="outer_hub_py">
      <origin xyz="0 0.023 0.01" rpy="0 0 0" />
      <geometry>
        <box size="0.014 0.014 0.016" />
      </geometry>
    </collision>
    <collision name="outer_hub_ny">
      <origin xyz="0 -0.023 0.01" rpy="0 0 0" />
      <geometry>
        <box size="0.014 0.014 0.016" />
      </geometry>
    </collision>
    <collision name="outer_shell_px">
      <origin xyz="0.077 0 0.044" rpy="0 0 0" />
      <geometry>
        <box size="0.03 0.05 0.068" />
      </geometry>
    </collision>
    <collision name="outer_shell_nx">
      <origin xyz="-0.077 0 0.044" rpy="0 0 0" />
      <geometry>
        <box size="0.03 0.05 0.068" />
      </geometry>
    </collision>
    <collision name="outer_shell_py">
      <origin xyz="0 0.077 0.044" rpy="0 0 0" />
      <geometry>
        <box size="0.05 0.03 0.068" />
      </geometry>
    </collision>
    <collision name="outer_shell_ny">
      <origin xyz="0 -0.077 0.044" rpy="0 0 0" />
      <geometry>
        <box size="0.05 0.03 0.068" />
      </geometry>
    </collision>
    <collision>
      <origin xyz="0 0 0.072" rpy="0 0 0" />
      <geometry>
        <cylinder radius="0.01" length="0.012" />
      </geometry>
    </collision>
    <collision>
      <origin xyz="0.122 0 0.044" rpy="0 0 0" />
      <geometry>
        <box size="0.048 0.032 0.02" />
      </geometry>
    </collision>
    <collision>
      <origin xyz="0.162 0 0.046" rpy="0 0 0" />
      <geometry>
        <box size="0.05 0.05 0.028" />
      </geometry>
    </collision>
    <collision>
      <origin xyz="0.186 0 0.046" rpy="0 0 0" />
      <geometry>
        <cylinder radius="0.018" length="0.026" />
      </geometry>
    </collision>
  </link>
  <link name="middle_stage">
    <inertial>
      <origin xyz="0 0 0.0315" rpy="0 0 0" />
      <mass value="1.3" />
      <inertia ixx="0.00211477" ixy="0" ixz="0" iyy="0.00211477" iyz="0" izz="0.0033696" />
    </inertial>
    <visual>
      <geometry>
        <mesh filename="meshes/middle_stage.glb" />
      </geometry>
      <material name="middle_anodized" />
    </visual>
    <collision name="middle_hub_px">
      <origin xyz="0.019 0 0.008" rpy="0 0 0" />
      <geometry>
        <box size="0.01 0.012 0.012" />
      </geometry>
    </collision>
    <collision name="middle_hub_nx">
      <origin xyz="-0.019 0 0.008" rpy="0 0 0" />
      <geometry>
        <box size="0.01 0.012 0.012" />
      </geometry>
    </collision>
    <collision name="middle_hub_py">
      <origin xyz="0 0.019 0.008" rpy="0 0 0" />
      <geometry>
        <box size="0.012 0.01 0.012" />
      </geometry>
    </collision>
    <collision name="middle_hub_ny">
      <origin xyz="0 -0.019 0.008" rpy="0 0 0" />
      <geometry>
        <box size="0.012 0.01 0.012" />
      </geometry>
    </collision>
    <collision name="middle_shell_px">
      <origin xyz="0.056 0 0.0355" rpy="0 0 0" />
      <geometry>
        <box size="0.024 0.038 0.055" />
      </geometry>
    </collision>
    <collision name="middle_shell_nx">
      <origin xyz="-0.056 0 0.0355" rpy="0 0 0" />
      <geometry>
        <box size="0.024 0.038 0.055" />
      </geometry>
    </collision>
    <collision name="middle_shell_py">
      <origin xyz="0 0.056 0.0355" rpy="0 0 0" />
      <geometry>
        <box size="0.038 0.024 0.055" />
      </geometry>
    </collision>
    <collision name="middle_shell_ny">
      <origin xyz="0 -0.056 0.0355" rpy="0 0 0" />
      <geometry>
        <box size="0.038 0.024 0.055" />
      </geometry>
    </collision>
    <collision>
      <origin xyz="0 0 0.057" rpy="0 0 0" />
      <geometry>
        <cylinder radius="0.008" length="0.012" />
      </geometry>
    </collision>
    <collision>
      <origin xyz="0 -0.072 0.032" rpy="0 0 0" />
      <geometry>
        <box size="0.014 0.022 0.016" />
      </geometry>
    </collision>
  </link>
  <link name="inner_stage">
    <inertial>
      <origin xyz="0 0 0.03" rpy="0 0 0" />
      <mass value="0.75" />
      <inertia ixx="0.000454688" ixy="0" ixz="0" iyy="0.000454688" iyz="0" izz="0.000459375" />
    </inertial>
    <visual>
      <geometry>
        <mesh filename="meshes/inner_stage.glb" />
      </geometry>
      <material name="inner_rotor" />
    </visual>
    <collision name="inner_hub_px">
      <origin xyz="0.014 0 0.007" rpy="0 0 0" />
      <geometry>
        <box size="0.008 0.01 0.01" />
      </geometry>
    </collision>
    <collision name="inner_hub_nx">
      <origin xyz="-0.014 0 0.007" rpy="0 0 0" />
      <geometry>
        <box size="0.008 0.01 0.01" />
      </geometry>
    </collision>
    <collision name="inner_hub_py">
      <origin xyz="0 0.014 0.007" rpy="0 0 0" />
      <geometry>
        <box size="0.01 0.008 0.01" />
      </geometry>
    </collision>
    <collision name="inner_hub_ny">
      <origin xyz="0 -0.014 0.007" rpy="0 0 0" />
      <geometry>
        <box size="0.01 0.008 0.01" />
      </geometry>
    </collision>
    <collision>
      <origin xyz="0 0 0.03" rpy="0 0 0" />
      <geometry>
        <cylinder radius="0.022" length="0.04" />
      </geometry>
    </collision>
    <collision>
      <origin xyz="0.008 0 0.056" rpy="0 0 0" />
      <geometry>
        <box size="0.07 0.028 0.01" />
      </geometry>
    </collision>
  </link>
  <joint name="base_to_outer" type="revolute">
    <parent link="base" />
    <child link="outer_stage" />
    <axis xyz="0 0 1" />
    <limit effort="24" velocity="2.4" lower="0" upper="2.4" />
  </joint>
  <joint name="outer_to_middle" type="revolute">
    <origin xyz="0 0 0.078" rpy="0 0 0" />
    <parent link="outer_stage" />
    <child link="middle_stage" />
    <axis xyz="0 0 1" />
    <limit effort="16" velocity="2.8" lower="-1.8" upper="1.8" />
  </joint>
  <joint name="middle_to_inner" type="revolute">
    <origin xyz="0 0 0.063" rpy="0 0 0" />
    <parent link="middle_stage" />
    <child link="inner_stage" />
    <axis xyz="0 0 1" />
    <limit effort="10" velocity="3.2" lower="-1.2" upper="1.2" />
  </joint>
</robot>