<robot name="outdoor_grill">
  <material name="painted_black">
    <color rgba="0.15 0.16 0.17 1" />
    </material>
  <material name="heat_enamel">
    <color rgba="0.23 0.24 0.25 1" />
    </material>
  <material name="stainless">
    <color rgba="0.74 0.76 0.78 1" />
    </material>
  <material name="dark_plastic">
    <color rgba="0.09 0.09 0.1 1" />
    </material>
  <material name="rubber">
    <color rgba="0.07 0.07 0.08 1" />
    </material>
  <material name="smoked_glass">
    <color rgba="0.22 0.25 0.28 0.45" />
    </material>
  <link name="cart_body">
    <inertial>
      <origin xyz="0 0 0.365" rpy="0 0 0" />
      <mass value="40" />
      <inertia ixx="2.97633" ixy="0" ixz="0" iyy="7.06833" iyz="0" izz="6.492" />
      </inertial>
    <visual>
      <origin xyz="0 0 0.345" rpy="0 0 0" />
      <geometry>
        <box size="0.74 0.52 0.45" />
        </geometry>
      <material name="painted_black">
        <color rgba="0.15 0.16 0.17 1" />
        </material>
      </visual>
    <visual>
      <origin xyz="-0.185 -0.271 0.335" rpy="0 0 0" />
      <geometry>
        <box size="0.35 0.024 0.39" />
        </geometry>
      <material name="painted_black">
        <color rgba="0.15 0.16 0.17 1" />
        </material>
      </visual>
    <visual>
      <origin xyz="0.185 -0.271 0.335" rpy="0 0 0" />
      <geometry>
        <box size="0.35 0.024 0.39" />
        </geometry>
      <material name="painted_black">
        <color rgba="0.15 0.16 0.17 1" />
        </material>
      </visual>
    <visual>
      <origin xyz="-0.11 -0.287 0.35" rpy="0 0 0" />
      <geometry>
        <cylinder radius="0.009" length="0.14" />
        </geometry>
      <material name="stainless">
        <color rgba="0.74 0.76 0.78 1" />
        </material>
      </visual>
    <visual>
      <origin xyz="0.11 -0.287 0.35" rpy="0 0 0" />
      <geometry>
        <cylinder radius="0.009" length="0.14" />
        </geometry>
      <material name="stainless">
        <color rgba="0.74 0.76 0.78 1" />
        </material>
      </visual>
    <visual>
      <origin xyz="0 0 0.575" rpy="0 0 0" />
      <geometry>
        <box size="0.68 0.34 0.08" />
        </geometry>
      <material name="heat_enamel">
        <color rgba="0.23 0.24 0.25 1" />
        </material>
      </visual>
    <visual>
      <origin xyz="-0.335 0 0.585" rpy="0 0 0" />
      <geometry>
        <box size="0.05 0.4 0.1" />
        </geometry>
      <material name="heat_enamel">
        <color rgba="0.23 0.24 0.25 1" />
        </material>
      </visual>
    <visual>
      <origin xyz="0.335 0 0.585" rpy="0 0 0" />
      <geometry>
        <box size="0.05 0.4 0.1" />
        </geometry>
      <material name="heat_enamel">
        <color rgba="0.23 0.24 0.25 1" />
        </material>
      </visual>
    <visual>
      <origin xyz="0 0.185 0.585" rpy="0 0 0" />
      <geometry>
        <box size="0.62 0.05 0.1" />
        </geometry>
      <material name="heat_enamel">
        <color rgba="0.23 0.24 0.25 1" />
        </material>
      </visual>
    <visual>
      <origin xyz="0 -0.19 0.575" rpy="0 0 0" />
      <geometry>
        <box size="0.62 0.04 0.07" />
        </geometry>
      <material name="heat_enamel">
        <color rgba="0.23 0.24 0.25 1" />
        </material>
      </visual>
    <visual>
      <origin xyz="0 -0.295 0.605" rpy="0 0 0" />
      <geometry>
        <box size="0.74 0.09 0.11" />
        </geometry>
      <material name="stainless">
        <color rgba="0.74 0.76 0.78 1" />
        </material>
      </visual>
    <visual>
      <origin xyz="0 -0.214 0.555" rpy="0 0 0" />
      <geometry>
        <box size="0.66 0.08 0.03" />
        </geometry>
      <material name="heat_enamel">
        <color rgba="0.23 0.24 0.25 1" />
        </material>
      </visual>
    <visual>
      <origin xyz="-0.492 0 0.672" rpy="0 0 0" />
      <geometry>
        <box size="0.27 0.44 0.03" />
        </geometry>
      <material name="stainless">
        <color rgba="0.74 0.76 0.78 1" />
        </material>
      </visual>
    <visual>
      <origin xyz="0.492 0 0.672" rpy="0 0 0" />
      <geometry>
        <box size="0.27 0.44 0.03" />
        </geometry>
      <material name="stainless">
        <color rgba="0.74 0.76 0.78 1" />
        </material>
      </visual>
    <visual>
      <origin xyz="-0.355 0 0.642" rpy="0 0 0" />
      <geometry>
        <box size="0.08 0.08 0.06" />
        </geometry>
      <material name="painted_black">
        <color rgba="0.15 0.16 0.17 1" />
        </material>
      </visual>
    <visual>
      <origin xyz="0.355 0 0.642" rpy="0 0 0" />
      <geometry>
        <box size="0.08 0.08 0.06" />
        </geometry>
      <material name="painted_black">
        <color rgba="0.15 0.16 0.17 1" />
        </material>
      </visual>
    <visual>
      <origin xyz="0 0.216 0.647" rpy="0 0 0" />
      <geometry>
        <box size="0.72 0.032 0.028" />
        </geometry>
      <material name="heat_enamel">
        <color rgba="0.23 0.24 0.25 1" />
        </material>
      </visual>
    <visual>
      <origin xyz="0 -0.105 0.635" rpy="0 0 0" />
      <geometry>
        <box size="0.66 0.012 0.012" />
        </geometry>
      <material name="stainless">
        <color rgba="0.74 0.76 0.78 1" />
        </material>
      </visual>
    <visual>
      <origin xyz="0 -0.035 0.635" rpy="0 0 0" />
      <geometry>
        <box size="0.66 0.012 0.012" />
        </geometry>
      <material name="stainless">
        <color rgba="0.74 0.76 0.78 1" />
        </material>
      </visual>
    <visual>
      <origin xyz="0 0.035 0.635" rpy="0 0 0" />
      <geometry>
        <box size="0.66 0.012 0.012" />
        </geometry>
      <material name="stainless">
        <color rgba="0.74 0.76 0.78 1" />
        </material>
      </visual>
    <visual>
      <origin xyz="0 0.105 0.635" rpy="0 0 0" />
      <geometry>
        <box size="0.66 0.012 0.012" />
        </geometry>
      <material name="stainless">
        <color rgba="0.74 0.76 0.78 1" />
        </material>
      </visual>
    <visual>
      <origin xyz="-0.19 -0.252 0.345" rpy="0 0 0" />
      <geometry>
        <box size="0.33 0.4 0.018" />
        </geometry>
      <material name="painted_black">
        <color rgba="0.15 0.16 0.17 1" />
        </material>
      </visual>
    <visual>
      <origin xyz="0.19 -0.252 0.345" rpy="0 0 0" />
      <geometry>
        <box size="0.33 0.4 0.018" />
        </geometry>
      <material name="painted_black">
        <color rgba="0.15 0.16 0.17 1" />
        </material>
      </visual>
    <visual>
      <origin xyz="-0.19 -0.282 0.345" rpy="0 0 0" />
      <geometry>
        <box size="0.022 0.16 0.018" />
        </geometry>
      <material name="stainless">
        <color rgba="0.74 0.76 0.78 1" />
        </material>
      </visual>
    <visual>
      <origin xyz="0.19 -0.282 0.345" rpy="0 0 0" />
      <geometry>
        <box size="0.022 0.16 0.018" />
        </geometry>
      <material name="stainless">
        <color rgba="0.74 0.76 0.78 1" />
        </material>
      </visual>
    <visual>
      <origin xyz="0 0.225 0.122" rpy="0 1.5708 0" />
      <geometry>
        <cylinder radius="0.018" length="0.82" />
        </geometry>
      <material name="stainless">
        <color rgba="0.74 0.76 0.78 1" />
        </material>
      </visual>
    <visual>
      <origin xyz="-0.415 0.225 0.122" rpy="0 1.5708 0" />
      <geometry>
        <cylinder radius="0.1" length="0.055" />
        </geometry>
      <material name="rubber">
        <color rgba="0.07 0.07 0.08 1" />
        </material>
      </visual>
    <visual>
      <origin xyz="0.415 0.225 0.122" rpy="0 1.5708 0" />
      <geometry>
        <cylinder radius="0.1" length="0.055" />
        </geometry>
      <material name="rubber">
        <color rgba="0.07 0.07 0.08 1" />
        </material>
      </visual>
    <visual>
      <origin xyz="-0.28 -0.18 0.06" rpy="0 0 0" />
      <geometry>
        <box size="0.06 0.1 0.12" />
        </geometry>
      <material name="painted_black">
        <color rgba="0.15 0.16 0.17 1" />
        </material>
      </visual>
    <visual>
      <origin xyz="0.28 -0.18 0.06" rpy="0 0 0" />
      <geometry>
        <box size="0.06 0.1 0.12" />
        </geometry>
      <material name="painted_black">
        <color rgba="0.15 0.16 0.17 1" />
        </material>
      </visual>
    <collision name="cart_body__visual_1">
      <origin xyz="0 0 0.345" rpy="0 0 0" />
      <geometry>
        <box size="0.74 0.52 0.45" />
        </geometry>
      </collision>
    <collision name="cart_body__visual_2">
      <origin xyz="-0.185 -0.271 0.335" rpy="0 0 0" />
      <geometry>
        <box size="0.35 0.024 0.39" />
        </geometry>
      </collision>
    <collision name="cart_body__visual_3">
      <origin xyz="0.185 -0.271 0.335" rpy="0 0 0" />
      <geometry>
        <box size="0.35 0.024 0.39" />
        </geometry>
      </collision>
    <collision name="cart_body__visual_4">
      <origin xyz="-0.11 -0.287 0.35" rpy="0 0 0" />
      <geometry>
        <cylinder radius="0.009" length="0.14" />
        </geometry>
      </collision>
    <collision name="cart_body__visual_5">
      <origin xyz="0.11 -0.287 0.35" rpy="0 0 0" />
      <geometry>
        <cylinder radius="0.009" length="0.14" />
        </geometry>
      </collision>
    <collision name="cart_body__visual_6">
      <origin xyz="0 0 0.575" rpy="0 0 0" />
      <geometry>
        <box size="0.68 0.34 0.08" />
        </geometry>
      </collision>
    <collision name="cart_body__visual_7">
      <origin xyz="-0.335 0 0.585" rpy="0 0 0" />
      <geometry>
        <box size="0.05 0.4 0.1" />
        </geometry>
      </collision>
    <collision name="cart_body__visual_8">
      <origin xyz="0.335 0 0.585" rpy="0 0 0" />
      <geometry>
        <box size="0.05 0.4 0.1" />
        </geometry>
      </collision>
    <collision name="cart_body__visual_9">
      <origin xyz="0 0.185 0.585" rpy="0 0 0" />
      <geometry>
        <box size="0.62 0.05 0.1" />
        </geometry>
      </collision>
    <collision name="cart_body__visual_10">
      <origin xyz="0 -0.19 0.575" rpy="0 0 0" />
      <geometry>
        <box size="0.62 0.04 0.07" />
        </geometry>
      </collision>
    <collision name="cart_body__visual_11">
      <origin xyz="0 -0.295 0.605" rpy="0 0 0" />
      <geometry>
        <box size="0.74 0.09 0.11" />
        </geometry>
      </collision>
    <collision name="cart_body__visual_12">
      <origin xyz="0 -0.214 0.555" rpy="0 0 0" />
      <geometry>
        <box size="0.66 0.08 0.03" />
        </geometry>
      </collision>
    <collision name="cart_body__visual_13">
      <origin xyz="-0.492 0 0.672" rpy="0 0 0" />
      <geometry>
        <box size="0.27 0.44 0.03" />
        </geometry>
      </collision>
    <collision name="cart_body__visual_14">
      <origin xyz="0.492 0 0.672" rpy="0 0 0" />
      <geometry>
        <box size="0.27 0.44 0.03" />
        </geometry>
      </collision>
    <collision name="cart_body__visual_15">
      <origin xyz="-0.355 0 0.642" rpy="0 0 0" />
      <geometry>
        <box size="0.08 0.08 0.06" />
        </geometry>
      </collision>
    <collision name="cart_body__visual_16">
      <origin xyz="0.355 0 0.642" rpy="0 0 0" />
      <geometry>
        <box size="0.08 0.08 0.06" />
        </geometry>
      </collision>
    <collision name="cart_body__visual_17">
      <origin xyz="0 0.216 0.647" rpy="0 0 0" />
      <geometry>
        <box size="0.72 0.032 0.028" />
        </geometry>
      </collision>
    <collision name="cart_body__visual_18">
      <origin xyz="0 -0.105 0.635" rpy="0 0 0" />
      <geometry>
        <box size="0.66 0.012 0.012" />
        </geometry>
      </collision>
    <collision name="cart_body__visual_19">
      <origin xyz="0 -0.035 0.635" rpy="0 0 0" />
      <geometry>
        <box size="0.66 0.012 0.012" />
        </geometry>
      </collision>
    <collision name="cart_body__visual_20">
      <origin xyz="0 0.035 0.635" rpy="0 0 0" />
      <geometry>
        <box size="0.66 0.012 0.012" />
        </geometry>
      </collision>
    <collision name="cart_body__visual_21">
      <origin xyz="0 0.105 0.635" rpy="0 0 0" />
      <geometry>
        <box size="0.66 0.012 0.012" />
        </geometry>
      </collision>
    <collision name="cart_body__visual_22">
      <origin xyz="-0.19 -0.252 0.345" rpy="0 0 0" />
      <geometry>
        <box size="0.33 0.4 0.018" />
        </geometry>
      </collision>
    <collision name="cart_body__visual_23">
      <origin xyz="0.19 -0.252 0.345" rpy="0 0 0" />
      <geometry>
        <box size="0.33 0.4 0.018" />
        </geometry>
      </collision>
    <collision name="cart_body__visual_24">
      <origin xyz="-0.19 -0.282 0.345" rpy="0 0 0" />
      <geometry>
        <box size="0.022 0.16 0.018" />
        </geometry>
      </collision>
    <collision name="cart_body__visual_25">
      <origin xyz="0.19 -0.282 0.345" rpy="0 0 0" />
      <geometry>
        <box size="0.022 0.16 0.018" />
        </geometry>
      </collision>
    <collision name="cart_body__visual_26">
      <origin xyz="0 0.225 0.122" rpy="0 1.5708 0" />
      <geometry>
        <cylinder radius="0.018" length="0.82" />
        </geometry>
      </collision>
    <collision name="cart_body__visual_27">
      <origin xyz="-0.415 0.225 0.122" rpy="0 1.5708 0" />
      <geometry>
        <cylinder radius="0.1" length="0.055" />
        </geometry>
      </collision>
    <collision name="cart_body__visual_28">
      <origin xyz="0.415 0.225 0.122" rpy="0 1.5708 0" />
      <geometry>
        <cylinder radius="0.1" length="0.055" />
        </geometry>
      </collision>
    <collision name="cart_body__visual_29">
      <origin xyz="-0.28 -0.18 0.06" rpy="0 0 0" />
      <geometry>
        <box size="0.06 0.1 0.12" />
        </geometry>
      </collision>
    <collision name="cart_body__visual_30">
      <origin xyz="0.28 -0.18 0.06" rpy="0 0 0" />
      <geometry>
        <box size="0.06 0.1 0.12" />
        </geometry>
      </collision>
    </link>
  <link name="lid">
    <inertial>
      <origin xyz="0 -0.215 0.115" rpy="0 0 0" />
      <mass value="12" />
      <inertia ixx="0.2612" ixy="0" ixz="0" iyy="0.6152" iyz="0" izz="0.7412" />
      </inertial>
    <visual>
      <origin xyz="0 -0.015 0.03" rpy="0 0 0" />
      <geometry>
        <box size="0.72 0.03 0.05" />
        </geometry>
      <material name="heat_enamel">
        <color rgba="0.23 0.24 0.25 1" />
        </material>
      </visual>
    <visual>
      <origin xyz="0 -0.21 0.08" rpy="0 0 0" />
      <geometry>
        <box size="0.72 0.42 0.14" />
        </geometry>
      <material name="painted_black">
        <color rgba="0.15 0.16 0.17 1" />
        </material>
      </visual>
    <visual>
      <origin xyz="0 -0.205 0.19" rpy="0 0 0" />
      <geometry>
        <box size="0.62 0.3 0.08" />
        </geometry>
      <material name="heat_enamel">
        <color rgba="0.23 0.24 0.25 1" />
        </material>
      </visual>
    <visual>
      <origin xyz="-0.345 -0.195 0.08" rpy="0 0 0" />
      <geometry>
        <box size="0.03 0.36 0.14" />
        </geometry>
      <material name="painted_black">
        <color rgba="0.15 0.16 0.17 1" />
        </material>
      </visual>
    <visual>
      <origin xyz="0.345 -0.195 0.08" rpy="0 0 0" />
      <geometry>
        <box size="0.03 0.36 0.14" />
        </geometry>
      <material name="painted_black">
        <color rgba="0.15 0.16 0.17 1" />
        </material>
      </visual>
    <visual>
      <origin xyz="0 -0.415 0.055" rpy="0 0 0" />
      <geometry>
        <box size="0.6 0.03 0.04" />
        </geometry>
      <material name="stainless">
        <color rgba="0.74 0.76 0.78 1" />
        </material>
      </visual>
    <visual>
      <origin xyz="-0.22 -0.365 0.09" rpy="0 0 0" />
      <geometry>
        <box size="0.03 0.05 0.05" />
        </geometry>
      <material name="stainless">
        <color rgba="0.74 0.76 0.78 1" />
        </material>
      </visual>
    <visual>
      <origin xyz="0.22 -0.365 0.09" rpy="0 0 0" />
      <geometry>
        <box size="0.03 0.05 0.05" />
        </geometry>
      <material name="stainless">
        <color rgba="0.74 0.76 0.78 1" />
        </material>
      </visual>
    <visual>
      <origin xyz="0 -0.34 0.1" rpy="0 1.5708 0" />
      <geometry>
        <cylinder radius="0.012" length="0.44" />
        </geometry>
      <material name="stainless">
        <color rgba="0.74 0.76 0.78 1" />
        </material>
      </visual>
    <visual>
      <origin xyz="0 -0.175 0.248" rpy="1.5708 0 0" />
      <geometry>
        <cylinder radius="0.018" length="0.014" />
        </geometry>
      <material name="stainless">
        <color rgba="0.74 0.76 0.78 1" />
        </material>
      </visual>
    <visual>
      <origin xyz="0 -0.185 0.248" rpy="1.5708 0 0" />
      <geometry>
        <cylinder radius="0.014" length="0.006" />
        </geometry>
      <material name="smoked_glass">
        <color rgba="0.22 0.25 0.28 0.45" />
        </material>
      </visual>
    <collision name="lid__visual_1">
      <origin xyz="0 -0.015 0.03" rpy="0 0 0" />
      <geometry>
        <box size="0.72 0.03 0.05" />
        </geometry>
      </collision>
    <collision name="lid__visual_2">
      <origin xyz="0 -0.21 0.08" rpy="0 0 0" />
      <geometry>
        <box size="0.72 0.42 0.14" />
        </geometry>
      </collision>
    <collision name="lid__visual_3">
      <origin xyz="0 -0.205 0.19" rpy="0 0 0" />
      <geometry>
        <box size="0.62 0.3 0.08" />
        </geometry>
      </collision>
    <collision name="lid__visual_4">
      <origin xyz="-0.345 -0.195 0.08" rpy="0 0 0" />
      <geometry>
        <box size="0.03 0.36 0.14" />
        </geometry>
      </collision>
    <collision name="lid__visual_5">
      <origin xyz="0.345 -0.195 0.08" rpy="0 0 0" />
      <geometry>
        <box size="0.03 0.36 0.14" />
        </geometry>
      </collision>
    <collision name="lid__visual_6">
      <origin xyz="0 -0.415 0.055" rpy="0 0 0" />
      <geometry>
        <box size="0.6 0.03 0.04" />
        </geometry>
      </collision>
    <collision name="lid__visual_7">
      <origin xyz="-0.22 -0.365 0.09" rpy="0 0 0" />
      <geometry>
        <box size="0.03 0.05 0.05" />
        </geometry>
      </collision>
    <collision name="lid__visual_8">
      <origin xyz="0.22 -0.365 0.09" rpy="0 0 0" />
      <geometry>
        <box size="0.03 0.05 0.05" />
        </geometry>
      </collision>
    <collision name="lid__visual_9">
      <origin xyz="0 -0.34 0.1" rpy="0 1.5708 0" />
      <geometry>
        <cylinder radius="0.012" length="0.44" />
        </geometry>
      </collision>
    <collision name="lid__visual_10">
      <origin xyz="0 -0.175 0.248" rpy="1.5708 0 0" />
      <geometry>
        <cylinder radius="0.018" length="0.014" />
        </geometry>
      </collision>
    <collision name="lid__visual_11">
      <origin xyz="0 -0.185 0.248" rpy="1.5708 0 0" />
      <geometry>
        <cylinder radius="0.014" length="0.006" />
        </geometry>
      </collision>
    </link>
  <link name="knob_1">
    <inertial>
      <origin xyz="0 -0.03 0" rpy="1.5708 0 0" />
      <mass value="0.18" />
      <inertia ixx="0.00011898" ixy="0" ixz="0" iyy="0.00011898" iyz="0" izz="0.00012996" />
      </inertial>
    <visual>
      <origin xyz="0 -0.025 0" rpy="1.5708 0 0" />
      <geometry>
        <cylinder radius="0.035" length="0.048" />
        </geometry>
      <material name="dark_plastic">
        <color rgba="0.09 0.09 0.1 1" />
        </material>
      </visual>
    <visual>
      <origin xyz="0 -0.055 0" rpy="1.5708 0 0" />
      <geometry>
        <cylinder radius="0.028" length="0.01" />
        </geometry>
      <material name="stainless">
        <color rgba="0.74 0.76 0.78 1" />
        </material>
      </visual>
    <visual>
      <origin xyz="0 -0.058 0.041" rpy="0 0 0" />
      <geometry>
        <box size="0.009 0.01 0.018" />
        </geometry>
      <material name="stainless">
        <color rgba="0.74 0.76 0.78 1" />
        </material>
      </visual>
    <collision name="knob_1__visual_1">
      <origin xyz="0 -0.025 0" rpy="1.5708 0 0" />
      <geometry>
        <cylinder radius="0.035" length="0.048" />
        </geometry>
      </collision>
    <collision name="knob_1__visual_2">
      <origin xyz="0 -0.055 0" rpy="1.5708 0 0" />
      <geometry>
        <cylinder radius="0.028" length="0.01" />
        </geometry>
      </collision>
    <collision name="knob_1__visual_3">
      <origin xyz="0 -0.058 0.041" rpy="0 0 0" />
      <geometry>
        <box size="0.009 0.01 0.018" />
        </geometry>
      </collision>
    </link>
  <link name="knob_2">
    <inertial>
      <origin xyz="0 -0.03 0" rpy="1.5708 0 0" />
      <mass value="0.18" />
      <inertia ixx="0.00011898" ixy="0" ixz="0" iyy="0.00011898" iyz="0" izz="0.00012996" />
      </inertial>
    <visual>
      <origin xyz="0 -0.025 0" rpy="1.5708 0 0" />
      <geometry>
        <cylinder radius="0.035" length="0.048" />
        </geometry>
      <material name="dark_plastic">
        <color rgba="0.09 0.09 0.1 1" />
        </material>
      </visual>
    <visual>
      <origin xyz="0 -0.055 0" rpy="1.5708 0 0" />
      <geometry>
        <cylinder radius="0.028" length="0.01" />
        </geometry>
      <material name="stainless">
        <color rgba="0.74 0.76 0.78 1" />
        </material>
      </visual>
    <visual>
      <origin xyz="0 -0.058 0.041" rpy="0 0 0" />
      <geometry>
        <box size="0.009 0.01 0.018" />
        </geometry>
      <material name="stainless">
        <color rgba="0.74 0.76 0.78 1" />
        </material>
      </visual>
    <collision name="knob_2__visual_1">
      <origin xyz="0 -0.025 0" rpy="1.5708 0 0" />
      <geometry>
        <cylinder radius="0.035" length="0.048" />
        </geometry>
      </collision>
    <collision name="knob_2__visual_2">
      <origin xyz="0 -0.055 0" rpy="1.5708 0 0" />
      <geometry>
        <cylinder radius="0.028" length="0.01" />
        </geometry>
      </collision>
    <collision name="knob_2__visual_3">
      <origin xyz="0 -0.058 0.041" rpy="0 0 0" />
      <geometry>
        <box size="0.009 0.01 0.018" />
        </geometry>
      </collision>
    </link>
  <link name="knob_3">
    <inertial>
      <origin xyz="0 -0.03 0" rpy="1.5708 0 0" />
      <mass value="0.18" />
      <inertia ixx="0.00011898" ixy="0" ixz="0" iyy="0.00011898" iyz="0" izz="0.00012996" />
      </inertial>
    <visual>
      <origin xyz="0 -0.025 0" rpy="1.5708 0 0" />
      <geometry>
        <cylinder radius="0.035" length="0.048" />
        </geometry>
      <material name="dark_plastic">
        <color rgba="0.09 0.09 0.1 1" />
        </material>
      </visual>
    <visual>
      <origin xyz="0 -0.055 0" rpy="1.5708 0 0" />
      <geometry>
        <cylinder radius="0.028" length="0.01" />
        </geometry>
      <material name="stainless">
        <color rgba="0.74 0.76 0.78 1" />
        </material>
      </visual>
    <visual>
      <origin xyz="0 -0.058 0.041" rpy="0 0 0" />
      <geometry>
        <box size="0.009 0.01 0.018" />
        </geometry>
      <material name="stainless">
        <color rgba="0.74 0.76 0.78 1" />
        </material>
      </visual>
    <collision name="knob_3__visual_1">
      <origin xyz="0 -0.025 0" rpy="1.5708 0 0" />
      <geometry>
        <cylinder radius="0.035" length="0.048" />
        </geometry>
      </collision>
    <collision name="knob_3__visual_2">
      <origin xyz="0 -0.055 0" rpy="1.5708 0 0" />
      <geometry>
        <cylinder radius="0.028" length="0.01" />
        </geometry>
      </collision>
    <collision name="knob_3__visual_3">
      <origin xyz="0 -0.058 0.041" rpy="0 0 0" />
      <geometry>
        <box size="0.009 0.01 0.018" />
        </geometry>
      </collision>
    </link>
  <link name="knob_4">
    <inertial>
      <origin xyz="0 -0.03 0" rpy="1.5708 0 0" />
      <mass value="0.18" />
      <inertia ixx="0.00011898" ixy="0" ixz="0" iyy="0.00011898" iyz="0" izz="0.00012996" />
      </inertial>
    <visual>
      <origin xyz="0 -0.025 0" rpy="1.5708 0 0" />
      <geometry>
        <cylinder radius="0.035" length="0.048" />
        </geometry>
      <material name="dark_plastic">
        <color rgba="0.09 0.09 0.1 1" />
        </material>
      </visual>
    <visual>
      <origin xyz="0 -0.055 0" rpy="1.5708 0 0" />
      <geometry>
        <cylinder radius="0.028" length="0.01" />
        </geometry>
      <material name="stainless">
        <color rgba="0.74 0.76 0.78 1" />
        </material>
      </visual>
    <visual>
      <origin xyz="0 -0.058 0.041" rpy="0 0 0" />
      <geometry>
        <box size="0.009 0.01 0.018" />
        </geometry>
      <material name="stainless">
        <color rgba="0.74 0.76 0.78 1" />
        </material>
      </visual>
    <collision name="knob_4__visual_1">
      <origin xyz="0 -0.025 0" rpy="1.5708 0 0" />
      <geometry>
        <cylinder radius="0.035" length="0.048" />
        </geometry>
      </collision>
    <collision name="knob_4__visual_2">
      <origin xyz="0 -0.055 0" rpy="1.5708 0 0" />
      <geometry>
        <cylinder radius="0.028" length="0.01" />
        </geometry>
      </collision>
    <collision name="knob_4__visual_3">
      <origin xyz="0 -0.058 0.041" rpy="0 0 0" />
      <geometry>
        <box size="0.009 0.01 0.018" />
        </geometry>
      </collision>
    </link>
  <joint name="lid_hinge" type="revolute">
    <origin xyz="0 0.205 0.645" rpy="0 0 0" />
    <parent link="cart_body" />
    <child link="lid" />
    <axis xyz="-1 0 0" />
    <limit effort="25" velocity="2" lower="0" upper="1.65" />
    </joint>
  <joint name="knob_1_joint" type="revolute">
    <origin xyz="-0.24 -0.339 0.605" rpy="0 0 0" />
    <parent link="cart_body" />
    <child link="knob_1" />
    <axis xyz="0 1 0" />
    <limit effort="1.5" velocity="6" lower="0" upper="4.71239" />
    </joint>
  <joint name="knob_2_joint" type="revolute">
    <origin xyz="-0.08 -0.339 0.605" rpy="0 0 0" />
    <parent link="cart_body" />
    <child link="knob_2" />
    <axis xyz="0 1 0" />
    <limit effort="1.5" velocity="6" lower="0" upper="4.71239" />
    </joint>
  <joint name="knob_3_joint" type="revolute">
    <origin xyz="0.08 -0.339 0.605" rpy="0 0 0" />
    <parent link="cart_body" />
    <child link="knob_3" />
    <axis xyz="0 1 0" />
    <limit effort="1.5" velocity="6" lower="0" upper="4.71239" />
    </joint>
  <joint name="knob_4_joint" type="revolute">
    <origin xyz="0.24 -0.339 0.605" rpy="0 0 0" />
    <parent link="cart_body" />
    <child link="knob_4" />
    <axis xyz="0 1 0" />
    <limit effort="1.5" velocity="6" lower="0" upper="4.71239" />
    </joint>
  </robot>
