<robot name="nested_linear_equipment_rack">
  <material name="rack_steel">
    <color rgba="0.28 0.3 0.34 1" />
  </material>
  <material name="slide_dark">
    <color rgba="0.16 0.17 0.19 1" />
  </material>
  <material name="equipment">
    <color rgba="0.1 0.11 0.12 1" />
  </material>
  <material name="panel">
    <color rgba="0.42 0.47 0.54 1" />
  </material>
  <material name="accent">
    <color rgba="0.84 0.22 0.1 1" />
  </material>
  <link name="rack_base">
    <inertial>
      <origin xyz="0.41 0 0.46" rpy="0 0 0" />
      <mass value="42" />
      <inertia ixx="4.3078" ixy="0" ixz="0" iyy="5.3158" iyz="0" izz="3.6988" />
    </inertial>
    <visual>
      <geometry>
        <mesh filename="meshes/rack_frame.glb" />
      </geometry>
      <material name="rack_steel" />
    </visual>
    <visual>
      <origin xyz="0.12 0 0.33" rpy="0 0 0" />
      <geometry>
        <box size="0.14 0.26 0.02" />
      </geometry>
      <material name="panel" />
    </visual>
    <collision>
      <origin xyz="0.02 -0.29 0.46" rpy="0 0 0" />
      <geometry>
        <box size="0.04 0.04 0.92" />
      </geometry>
    </collision>
    <collision>
      <origin xyz="0.02 0.29 0.46" rpy="0 0 0" />
      <geometry>
        <box size="0.04 0.04 0.92" />
      </geometry>
    </collision>
    <collision>
      <origin xyz="0.8 -0.29 0.46" rpy="0 0 0" />
      <geometry>
        <box size="0.04 0.04 0.92" />
      </geometry>
    </collision>
    <collision>
      <origin xyz="0.8 0.29 0.46" rpy="0 0 0" />
      <geometry>
        <box size="0.04 0.04 0.92" />
      </geometry>
    </collision>
    <collision>
      <origin xyz="0.006 0 0.46" rpy="0 0 0" />
      <geometry>
        <box size="0.012 0.54 0.72" />
      </geometry>
    </collision>
    <collision>
      <origin xyz="0.1 0 0.17" rpy="0 0 0" />
      <geometry>
        <box size="0.08 0.2 0.34" />
      </geometry>
    </collision>
    <collision>
      <origin xyz="0.12 0 0.33" rpy="0 0 0" />
      <geometry>
        <box size="0.14 0.26 0.02" />
      </geometry>
    </collision>
  </link>
  <link name="outer_slide_stage">
    <inertial>
      <origin xyz="0.33 0 0.05" rpy="0 0 0" />
      <mass value="10.5" />
      <inertia ixx="0.2275" ixy="0" ixz="0" iyy="0.3899" iyz="0" izz="0.5999" />
    </inertial>
    <visual>
      <geometry>
        <mesh filename="meshes/outer_slide_stage.glb" />
      </geometry>
      <material name="slide_dark" />
    </visual>
    <visual>
      <origin xyz="0.666 0 0.05" rpy="0 0 0" />
      <geometry>
        <box size="0.012 0.24 0.018" />
      </geometry>
      <material name="accent" />
    </visual>
    <collision>
      <origin xyz="0.32 0 0.006" rpy="0 0 0" />
      <geometry>
        <box size="0.64 0.42 0.012" />
      </geometry>
    </collision>
    <collision>
      <origin xyz="0.31 -0.221 0.025" rpy="0 0 0" />
      <geometry>
        <box size="0.6 0.018 0.05" />
      </geometry>
    </collision>
    <collision>
      <origin xyz="0.31 0.221 0.025" rpy="0 0 0" />
      <geometry>
        <box size="0.6 0.018 0.05" />
      </geometry>
    </collision>
    <collision>
      <origin xyz="0.007 0 0.025" rpy="0 0 0" />
      <geometry>
        <box size="0.014 0.42 0.05" />
      </geometry>
    </collision>
    <collision>
      <origin xyz="0.08 0 0.012" rpy="0 0 0" />
      <geometry>
        <box size="0.1 0.16 0.024" />
      </geometry>
    </collision>
  </link>
  <link name="inner_slide_stage">
    <inertial>
      <origin xyz="0.27 0 0.1" rpy="0 0 0" />
      <mass value="8" />
      <inertia ixx="0.133333" ixy="0" ixz="0" iyy="0.221067" iyz="0" izz="0.301067" />
    </inertial>
    <visual>
      <geometry>
        <mesh filename="meshes/inner_slide_stage_tray.glb" />
      </geometry>
      <material name="slide_dark" />
    </visual>
    <visual>
      <origin xyz="0.29 0 0.09" rpy="0 0 0" />
      <geometry>
        <box size="0.36 0.3 0.16" />
      </geometry>
      <material name="equipment" />
    </visual>
    <visual>
      <origin xyz="0.29 0 0.174" rpy="0 0 0" />
      <geometry>
        <box size="0.22 0.24 0.008" />
      </geometry>
      <material name="panel" />
    </visual>
    <visual>
      <origin xyz="0.47 0 0.108" rpy="0 0 0" />
      <geometry>
        <box size="0.1 0.3 0.012" />
      </geometry>
      <material name="accent" />
    </visual>
    <collision>
      <origin xyz="0.26 0 0.005" rpy="0 0 0" />
      <geometry>
        <box size="0.52 0.34 0.01" />
      </geometry>
    </collision>
    <collision>
      <origin xyz="0.29 0 0.09" rpy="0 0 0" />
      <geometry>
        <box size="0.34 0.28 0.16" />
      </geometry>
    </collision>
    <collision>
      <origin xyz="0.006 0 0.0225" rpy="0 0 0" />
      <geometry>
        <box size="0.012 0.34 0.045" />
      </geometry>
    </collision>
  </link>
  <joint name="rack_to_outer_stage" type="prismatic">
    <origin xyz="0.1 0 0.34" rpy="0 0 0" />
    <parent link="rack_base" />
    <child link="outer_slide_stage" />
    <axis xyz="1 0 0" />
    <limit effort="400" velocity="0.4" lower="0" upper="0.3" />
  </joint>
  <joint name="outer_stage_to_inner_stage" type="prismatic">
    <origin xyz="0.06 0 0.024" rpy="0 0 0" />
    <parent link="outer_slide_stage" />
    <child link="inner_slide_stage" />
    <axis xyz="1 0 0" />
    <limit effort="250" velocity="0.35" lower="0" upper="0.24" />
  </joint>
</robot>