<robot name="long_reach_inspection_arm">
  <material name="base_gray">
    <color rgba="0.27 0.29 0.32 1" />
  </material>
  <material name="steel_dark">
    <color rgba="0.16 0.18 0.21 1" />
  </material>
  <material name="arm_orange">
    <color rgba="0.92 0.45 0.09 1" />
  </material>
  <material name="arm_charcoal">
    <color rgba="0.2 0.22 0.26 1" />
  </material>
  <material name="sensor_black">
    <color rgba="0.08 0.09 0.11 1" />
  </material>
  <material name="optic_blue">
    <color rgba="0.35 0.63 0.88 1" />
  </material>
  <link name="base_mount">
    <inertial>
      <origin xyz="0 0 0.06" rpy="0 0 0" />
      <mass value="10.5" />
      <inertia ixx="0.035" ixy="0" ixz="0" iyy="0.04095" iyz="0" izz="0.05075" />
    </inertial>
    <visual>
      <geometry>
        <mesh filename="meshes/base_mount.glb" />
      </geometry>
      <material name="base_gray" />
    </visual>
    <collision>
      <origin xyz="0 0 0.04" rpy="0 0 0" />
      <geometry>
        <box size="0.18 0.16 0.08" />
      </geometry>
    </collision>
    <collision>
      <origin xyz="0 0 0.08" rpy="0 0 0" />
      <geometry>
        <box size="0.028 0.04 0.044" />
      </geometry>
    </collision>
  </link>
  <link name="segment_1">
    <inertial>
      <origin xyz="0.21 0 0" rpy="0 0 0" />
      <mass value="3.1" />
      <inertia ixx="0.000605533" ixy="0" ixz="0" iyy="0.0458025" iyz="0" izz="0.045943" />
    </inertial>
    <visual>
      <geometry>
        <mesh filename="meshes/segment_1.glb" />
      </geometry>
      <material name="arm_orange" />
    </visual>
    <collision>
      <origin xyz="0.21 0 0" rpy="0 0 0" />
      <geometry>
        <box size="0.364 0.038 0.028" />
      </geometry>
    </collision>
    <collision>
      <geometry>
        <box size="0.056 0.048 0.056" />
      </geometry>
    </collision>
    <collision>
      <origin xyz="0.42 0 0" rpy="0 0 0" />
      <geometry>
        <box size="0.056 0.048 0.056" />
      </geometry>
    </collision>
  </link>
  <link name="segment_2">
    <inertial>
      <origin xyz="0.17 0 0" rpy="0 0 0" />
      <mass value="2.4" />
      <inertia ixx="0.0004688" ixy="0" ixz="0" iyy="0.0233" iyz="0" izz="0.0234088" />
    </inertial>
    <visual>
      <geometry>
        <mesh filename="meshes/segment_2.glb" />
      </geometry>
      <material name="arm_charcoal" />
    </visual>
    <collision>
      <origin xyz="0.17 0 0" rpy="0 0 0" />
      <geometry>
        <box size="0.284 0.038 0.028" />
      </geometry>
    </collision>
    <collision>
      <geometry>
        <box size="0.056 0.048 0.056" />
      </geometry>
    </collision>
    <collision>
      <origin xyz="0.34 0 0" rpy="0 0 0" />
      <geometry>
        <box size="0.056 0.048 0.056" />
      </geometry>
    </collision>
  </link>
  <link name="segment_3">
    <inertial>
      <origin xyz="0.14 0 0" rpy="0 0 0" />
      <mass value="1.8" />
      <inertia ixx="0.0003516" ixy="0" ixz="0" iyy="0.011895" iyz="0" izz="0.0119766" />
    </inertial>
    <visual>
      <geometry>
        <mesh filename="meshes/segment_3.glb" />
      </geometry>
      <material name="arm_orange" />
    </visual>
    <collision>
      <origin xyz="0.14 0 0" rpy="0 0 0" />
      <geometry>
        <box size="0.224 0.038 0.028" />
      </geometry>
    </collision>
    <collision>
      <geometry>
        <box size="0.056 0.048 0.056" />
      </geometry>
    </collision>
    <collision>
      <origin xyz="0.28 0 0" rpy="0 0 0" />
      <geometry>
        <box size="0.056 0.048 0.056" />
      </geometry>
    </collision>
  </link>
  <link name="segment_4">
    <inertial>
      <origin xyz="0.17 0 0.002" rpy="0 0 0" />
      <mass value="1.4" />
      <inertia ixx="0.000355133" ixy="0" ixz="0" iyy="0.0136733" iyz="0" izz="0.0136551" />
    </inertial>
    <visual>
      <geometry>
        <mesh filename="meshes/segment_4.glb" />
      </geometry>
      <material name="arm_charcoal" />
    </visual>
    <visual>
      <origin xyz="0.212 0 -0.004" rpy="0 0 0" />
      <geometry>
        <box size="0.04 0.032 0.018" />
      </geometry>
      <material name="arm_charcoal" />
    </visual>
    <visual>
      <origin xyz="0.245 0 0.004" rpy="0 0 0" />
      <geometry>
        <box size="0.08 0.05 0.04" />
      </geometry>
      <material name="sensor_black" />
    </visual>
    <visual>
      <origin xyz="0.296 0 0.004" rpy="0 0 0" />
      <geometry>
        <box size="0.018 0.024 0.024" />
      </geometry>
      <material name="optic_blue" />
    </visual>
    <collision>
      <origin xyz="0.1 0 0" rpy="0 0 0" />
      <geometry>
        <box size="0.144 0.038 0.028" />
      </geometry>
    </collision>
    <collision>
      <geometry>
        <box size="0.056 0.048 0.056" />
      </geometry>
    </collision>
    <collision>
      <origin xyz="0.2 0 0" rpy="0 0 0" />
      <geometry>
        <box size="0.056 0.048 0.056" />
      </geometry>
    </collision>
    <collision>
      <origin xyz="0.245 0 0.004" rpy="0 0 0" />
      <geometry>
        <box size="0.08 0.05 0.04" />
      </geometry>
    </collision>
    <collision>
      <origin xyz="0.296 0 0.004" rpy="0 0 0" />
      <geometry>
        <box size="0.018 0.024 0.024" />
      </geometry>
    </collision>
  </link>
  <joint name="shoulder_hinge" type="revolute">
    <origin xyz="0 0 0.12" rpy="0 0 0" />
    <parent link="base_mount" />
    <child link="segment_1" />
    <axis xyz="0 -1 0" />
    <limit effort="90" velocity="1.1" lower="0" upper="0.95" />
  </joint>
  <joint name="elbow_hinge_1" type="revolute">
    <origin xyz="0.42 0 0" rpy="0 0 0" />
    <parent link="segment_1" />
    <child link="segment_2" />
    <axis xyz="0 -1 0" />
    <limit effort="70" velocity="1.4" lower="0" upper="0.85" />
  </joint>
  <joint name="elbow_hinge_2" type="revolute">
    <origin xyz="0.34 0 0" rpy="0 0 0" />
    <parent link="segment_2" />
    <child link="segment_3" />
    <axis xyz="0 -1 0" />
    <limit effort="45" velocity="1.7" lower="0" upper="0.75" />
  </joint>
  <joint name="wrist_hinge" type="revolute">
    <origin xyz="0.28 0 0" rpy="0 0 0" />
    <parent link="segment_3" />
    <child link="segment_4" />
    <axis xyz="0 -1 0" />
    <limit effort="25" velocity="2" lower="0" upper="0.6" />
  </joint>
</robot>