<robot name="windshield_sun_visor_assembly">
  <material name="headliner_fabric">
    <color rgba="0.72 0.72 0.7 1" />
    </material>
  <material name="visor_vinyl">
    <color rgba="0.63 0.64 0.66 1" />
    </material>
  <material name="textured_trim">
    <color rgba="0.26 0.27 0.29 1" />
    </material>
  <material name="clip_plastic">
    <color rgba="0.18 0.18 0.19 1" />
    </material>
  <material name="warning_label">
    <color rgba="0.88 0.86 0.8 1" />
    </material>
  <material name="brushed_steel">
    <color rgba="0.66 0.68 0.71 1" />
    </material>
  <link name="roof_mount">
    <inertial>
      <origin xyz="0.028 0.185 -0.01" rpy="0 0 0" />
      <mass value="0.55" />
      <inertia ixx="0.00630098" ixy="0" ixz="0" iyy="0.00039765" iyz="0" izz="0.00664583" />
      </inertial>
    <visual>
      <origin xyz="0.028 0.185 -0.003" rpy="0 0 0" />
      <geometry>
        <box size="0.07 0.37 0.006" />
        </geometry>
      <material name="headliner_fabric">
        <color rgba="0.72 0.72 0.7 1" />
        </material>
      </visual>
    <visual>
      <origin xyz="0.02 0.028 -0.006" rpy="0 0 0" />
      <geometry>
        <box size="0.084 0.07 0.012" />
        </geometry>
      <material name="textured_trim">
        <color rgba="0.26 0.27 0.29 1" />
        </material>
      </visual>
    <visual>
      <origin xyz="0.018 0.024 -0.013" rpy="0 0 0" />
      <geometry>
        <cylinder radius="0.016" length="0.014" />
        </geometry>
      <material name="textured_trim">
        <color rgba="0.26 0.27 0.29 1" />
        </material>
      </visual>
    <visual>
      <origin xyz="0.018 0.024 -0.0215" rpy="0 0 0" />
      <geometry>
        <cylinder radius="0.011" length="0.005" />
        </geometry>
      <material name="textured_trim">
        <color rgba="0.26 0.27 0.29 1" />
        </material>
      </visual>
    <visual>
      <origin xyz="0.036 0.11 -0.0055" rpy="0 0 0" />
      <geometry>
        <cylinder radius="0.006" length="0.002" />
        </geometry>
      <material name="headliner_fabric">
        <color rgba="0.72 0.72 0.7 1" />
        </material>
      </visual>
    <visual>
      <origin xyz="0.036 0.286 -0.0055" rpy="0 0 0" />
      <geometry>
        <cylinder radius="0.006" length="0.002" />
        </geometry>
      <material name="headliner_fabric">
        <color rgba="0.72 0.72 0.7 1" />
        </material>
      </visual>
    <collision name="roof_mount__visual_1">
      <origin xyz="0.028 0.185 -0.003" rpy="0 0 0" />
      <geometry>
        <box size="0.07 0.37 0.006" />
        </geometry>
      </collision>
    <collision name="roof_mount__visual_2">
      <origin xyz="0.02 0.028 -0.006" rpy="0 0 0" />
      <geometry>
        <box size="0.084 0.07 0.012" />
        </geometry>
      </collision>
    <collision name="roof_mount__visual_3">
      <origin xyz="0.018 0.024 -0.013" rpy="0 0 0" />
      <geometry>
        <cylinder radius="0.016" length="0.014" />
        </geometry>
      </collision>
    <collision name="roof_mount__visual_4">
      <origin xyz="0.018 0.024 -0.0215" rpy="0 0 0" />
      <geometry>
        <cylinder radius="0.011" length="0.005" />
        </geometry>
      </collision>
    <collision name="roof_mount__visual_5">
      <origin xyz="0.036 0.11 -0.0055" rpy="0 0 0" />
      <geometry>
        <cylinder radius="0.006" length="0.002" />
        </geometry>
      </collision>
    <collision name="roof_mount__visual_6">
      <origin xyz="0.036 0.286 -0.0055" rpy="0 0 0" />
      <geometry>
        <cylinder radius="0.006" length="0.002" />
        </geometry>
      </collision>
    </link>
  <link name="swivel_hub">
    <inertial>
      <origin xyz="0 0.01 -0.008" rpy="0 0 0" />
      <mass value="0.12" />
      <inertia ixx="1.625e-05" ixy="0" ixz="0" iyy="8e-06" iyz="0" izz="1.625e-05" />
      </inertial>
    <visual>
      <origin xyz="0 0 -0.008" rpy="0 0 0" />
      <geometry>
        <cylinder radius="0.007" length="0.016" />
        </geometry>
      <material name="brushed_steel">
        <color rgba="0.66 0.68 0.71 1" />
        </material>
      </visual>
    <visual>
      <origin xyz="0 0 -0.012" rpy="0 0 0" />
      <geometry>
        <cylinder radius="0.012" length="0.008" />
        </geometry>
      <material name="textured_trim">
        <color rgba="0.26 0.27 0.29 1" />
        </material>
      </visual>
    <visual>
      <origin xyz="0 0.014 -0.008" rpy="-1.5708 0 0" />
      <geometry>
        <cylinder radius="0.007" length="0.03" />
        </geometry>
      <material name="brushed_steel">
        <color rgba="0.66 0.68 0.71 1" />
        </material>
      </visual>
    <visual>
      <origin xyz="0 0.01 -0.008" rpy="0 0 0" />
      <geometry>
        <box size="0.014 0.02 0.01" />
        </geometry>
      <material name="textured_trim">
        <color rgba="0.26 0.27 0.29 1" />
        </material>
      </visual>
    <collision name="swivel_hub__visual_1">
      <origin xyz="0 0 -0.008" rpy="0 0 0" />
      <geometry>
        <cylinder radius="0.007" length="0.016" />
        </geometry>
      </collision>
    <collision name="swivel_hub__visual_2">
      <origin xyz="0 0 -0.012" rpy="0 0 0" />
      <geometry>
        <cylinder radius="0.012" length="0.008" />
        </geometry>
      </collision>
    <collision name="swivel_hub__visual_3">
      <origin xyz="0 0.014 -0.008" rpy="-1.5708 0 0" />
      <geometry>
        <cylinder radius="0.007" length="0.03" />
        </geometry>
      </collision>
    <collision name="swivel_hub__visual_4">
      <origin xyz="0 0.01 -0.008" rpy="0 0 0" />
      <geometry>
        <box size="0.014 0.02 0.01" />
        </geometry>
      </collision>
    </link>
  <link name="visor">
    <inertial>
      <origin xyz="0.082 0.21 -0.01" rpy="0 0 0" />
      <mass value="0.72" />
      <inertia ixx="0.0059775" ixy="0" ixz="0" iyy="0.0012855" iyz="0" izz="0.007215" />
      </inertial>
    <visual>
      <geometry>
        <mesh filename="meshes/visor_support_rod.obj" />
        </geometry>
      <material name="brushed_steel">
        <color rgba="0.66 0.68 0.71 1" />
        </material>
      </visual>
    <visual>
      <geometry>
        <mesh filename="meshes/visor_panel.obj" />
        </geometry>
      <material name="visor_vinyl">
        <color rgba="0.63 0.64 0.66 1" />
        </material>
      </visual>
    <visual>
      <origin xyz="0.018 0.082 -0.0006" rpy="0 0 0" />
      <geometry>
        <box size="0.024 0.038 0.0028" />
        </geometry>
      <material name="textured_trim">
        <color rgba="0.26 0.27 0.29 1" />
        </material>
      </visual>
    <visual>
      <origin xyz="0.082 0.235 -0.0179" rpy="0 0 0" />
      <geometry>
        <box size="0.05 0.095 0.0012" />
        </geometry>
      <material name="warning_label">
        <color rgba="0.88 0.86 0.8 1" />
        </material>
      </visual>
    <visual>
      <origin xyz="0.03 0.349 -0.0008" rpy="0 0 0" />
      <geometry>
        <box size="0.014 0.02 0.004" />
        </geometry>
      <material name="textured_trim">
        <color rgba="0.26 0.27 0.29 1" />
        </material>
      </visual>
    <collision name="visor__visual_1__hull_001">
      <geometry>
        <mesh filename="meshes/collision/cache/225adab010e18f081d36c6b3__hull_001.obj" />
        </geometry>
      </collision>
    <collision name="visor__visual_1__hull_002">
      <geometry>
        <mesh filename="meshes/collision/cache/225adab010e18f081d36c6b3__hull_002.obj" />
        </geometry>
      </collision>
    <collision name="visor__visual_2__hull_001">
      <geometry>
        <mesh filename="meshes/collision/cache/e34edf07bd4004c07f4eddf9__hull_001.obj" />
        </geometry>
      </collision>
    <collision name="visor__visual_3">
      <origin xyz="0.018 0.082 -0.0006" rpy="0 0 0" />
      <geometry>
        <box size="0.024 0.038 0.0028" />
        </geometry>
      </collision>
    <collision name="visor__visual_4">
      <origin xyz="0.082 0.235 -0.0179" rpy="0 0 0" />
      <geometry>
        <box size="0.05 0.095 0.0012" />
        </geometry>
      </collision>
    <collision name="visor__visual_5">
      <origin xyz="0.03 0.349 -0.0008" rpy="0 0 0" />
      <geometry>
        <box size="0.014 0.02 0.004" />
        </geometry>
      </collision>
    </link>
  <link name="retaining_clip">
    <inertial>
      <origin xyz="0 0 -0.01" rpy="0 0 0" />
      <mass value="0.03" />
      <inertia ixx="2.44e-06" ixy="0" ixz="0" iyy="2.96e-06" iyz="0" izz="3.4e-06" />
      </inertial>
    <visual>
      <origin xyz="0 0 -0.003" rpy="0 0 0" />
      <geometry>
        <box size="0.026 0.022 0.006" />
        </geometry>
      <material name="clip_plastic">
        <color rgba="0.18 0.18 0.19 1" />
        </material>
      </visual>
    <visual>
      <geometry>
        <mesh filename="meshes/visor_retaining_clip.obj" />
        </geometry>
      <material name="clip_plastic">
        <color rgba="0.18 0.18 0.19 1" />
        </material>
      </visual>
    <collision name="retaining_clip__visual_1">
      <origin xyz="0 0 -0.003" rpy="0 0 0" />
      <geometry>
        <box size="0.026 0.022 0.006" />
        </geometry>
      </collision>
    <collision name="retaining_clip__visual_2__hull_001">
      <geometry>
        <mesh filename="meshes/collision/cache/f25532af606ca3ad3316deb8__hull_001.obj" />
        </geometry>
      </collision>
    <collision name="retaining_clip__visual_2__hull_002">
      <geometry>
        <mesh filename="meshes/collision/cache/f25532af606ca3ad3316deb8__hull_002.obj" />
        </geometry>
      </collision>
    <collision name="retaining_clip__visual_2__hull_003">
      <geometry>
        <mesh filename="meshes/collision/cache/f25532af606ca3ad3316deb8__hull_003.obj" />
        </geometry>
      </collision>
    <collision name="retaining_clip__visual_2__hull_004">
      <geometry>
        <mesh filename="meshes/collision/cache/f25532af606ca3ad3316deb8__hull_004.obj" />
        </geometry>
      </collision>
    </link>
  <joint name="visor_swivel" type="revolute">
    <origin xyz="0.018 0.024 0" rpy="0 0 0" />
    <parent link="roof_mount" />
    <child link="swivel_hub" />
    <axis xyz="0 0 1" />
    <limit effort="8" velocity="2.5" lower="0" upper="1.65" />
    </joint>
  <joint name="visor_tilt" type="revolute">
    <origin xyz="0 0 -0.008" rpy="0 0 0" />
    <parent link="swivel_hub" />
    <child link="visor" />
    <axis xyz="0 1 0" />
    <limit effort="6" velocity="3" lower="0" upper="1.55" />
    </joint>
  <joint name="clip_mount" type="fixed">
    <origin xyz="0.03 0.347 0" rpy="0 0 0" />
    <parent link="roof_mount" />
    <child link="retaining_clip" />
    </joint>
  </robot>
