<robot name="miter_saw_arm_assembly">
  <material name="cast_aluminum">
    <color rgba="0.74 0.75 0.77 1" />
  </material>
  <material name="brushed_steel">
    <color rgba="0.72 0.74 0.76 1" />
  </material>
  <material name="tool_red">
    <color rgba="0.67 0.16 0.12 1" />
  </material>
  <material name="charcoal_plastic">
    <color rgba="0.18 0.19 0.21 1" />
  </material>
  <material name="rubber_black">
    <color rgba="0.08 0.08 0.09 1" />
  </material>
  <material name="blade_steel">
    <color rgba="0.82 0.84 0.86 1" />
  </material>
  <material name="amber_guard">
    <color rgba="0.78 0.6 0.18 0.32" />
  </material>
  <link name="base">
    <inertial>
      <origin xyz="0 -0.02 0.135" rpy="0 0 0" />
      <mass value="16" />
      <inertia ixx="0.486" ixy="0" ixz="0" iyy="0.609733" iyz="0" izz="0.901333" />
    </inertial>
    <visual>
      <geometry>
        <mesh filename="meshes/base_shell.glb" />
      </geometry>
      <material name="cast_aluminum">
        <color rgba="0.74 0.75 0.77 1" />
      </material>
    </visual>
    <visual>
      <origin xyz="0 0 0.066" rpy="0 0 0" />
      <geometry>
        <cylinder radius="0.13" length="0.024" />
      </geometry>
      <material name="brushed_steel">
        <color rgba="0.72 0.74 0.76 1" />
      </material>
    </visual>
    <visual>
      <origin xyz="-0.145 -0.206 0.1" rpy="0 0 0" />
      <geometry>
        <box size="0.22 0.028 0.09" />
      </geometry>
      <material name="cast_aluminum">
        <color rgba="0.74 0.75 0.77 1" />
      </material>
    </visual>
    <visual>
      <origin xyz="0.145 -0.206 0.1" rpy="0 0 0" />
      <geometry>
        <box size="0.22 0.028 0.09" />
      </geometry>
      <material name="cast_aluminum">
        <color rgba="0.74 0.75 0.77 1" />
      </material>
    </visual>
    <visual>
      <origin xyz="-0.075 -0.246 0.165" rpy="0 0 0" />
      <geometry>
        <box size="0.03 0.058 0.22" />
      </geometry>
      <material name="cast_aluminum">
        <color rgba="0.74 0.75 0.77 1" />
      </material>
    </visual>
    <visual>
      <origin xyz="0.075 -0.246 0.165" rpy="0 0 0" />
      <geometry>
        <box size="0.03 0.058 0.22" />
      </geometry>
      <material name="cast_aluminum">
        <color rgba="0.74 0.75 0.77 1" />
      </material>
    </visual>
    <visual>
      <origin xyz="0 -0.245 0.11" rpy="0 0 0" />
      <geometry>
        <box size="0.19 0.03 0.11" />
      </geometry>
      <material name="cast_aluminum">
        <color rgba="0.74 0.75 0.77 1" />
      </material>
    </visual>
    <visual>
      <origin xyz="0 -0.219 0.25" rpy="0 0 0" />
      <geometry>
        <box size="0.11 0.028 0.04" />
      </geometry>
      <material name="brushed_steel">
        <color rgba="0.72 0.74 0.76 1" />
      </material>
    </visual>
    <visual>
      <origin xyz="0 0.165 0.064" rpy="0 0 0" />
      <geometry>
        <box size="0.18 0.04 0.018" />
      </geometry>
      <material name="charcoal_plastic">
        <color rgba="0.18 0.19 0.21 1" />
      </material>
    </visual>
    <collision name="base__visual_1__hull_001">
      <geometry>
        <mesh filename="meshes/collision/cache/b003c2a62ee90e8f0b623815__hull_001.obj" />
      </geometry>
    </collision>
    <collision name="base__visual_2">
      <origin xyz="0 0 0.066" rpy="0 0 0" />
      <geometry>
        <cylinder radius="0.13" length="0.024" />
      </geometry>
    </collision>
    <collision name="base__visual_3">
      <origin xyz="-0.145 -0.206 0.1" rpy="0 0 0" />
      <geometry>
        <box size="0.22 0.028 0.09" />
      </geometry>
    </collision>
    <collision name="base__visual_4">
      <origin xyz="0.145 -0.206 0.1" rpy="0 0 0" />
      <geometry>
        <box size="0.22 0.028 0.09" />
      </geometry>
    </collision>
    <collision name="base__visual_5">
      <origin xyz="-0.075 -0.246 0.165" rpy="0 0 0" />
      <geometry>
        <box size="0.03 0.058 0.22" />
      </geometry>
    </collision>
    <collision name="base__visual_6">
      <origin xyz="0.075 -0.246 0.165" rpy="0 0 0" />
      <geometry>
        <box size="0.03 0.058 0.22" />
      </geometry>
    </collision>
    <collision name="base__visual_7">
      <origin xyz="0 -0.245 0.11" rpy="0 0 0" />
      <geometry>
        <box size="0.19 0.03 0.11" />
      </geometry>
    </collision>
    <collision name="base__visual_8">
      <origin xyz="0 -0.219 0.25" rpy="0 0 0" />
      <geometry>
        <box size="0.11 0.028 0.04" />
      </geometry>
    </collision>
    <collision name="base__visual_9">
      <origin xyz="0 0.165 0.064" rpy="0 0 0" />
      <geometry>
        <box size="0.18 0.04 0.018" />
      </geometry>
    </collision>
  </link>
  <link name="turntable">
    <inertial>
      <origin xyz="0 0 0.017" rpy="0 0 0" />
      <mass value="5.5" />
      <inertia ixx="0.0447333" ixy="0" ixz="0" iyy="0.0447333" iyz="0" izz="0.0891" />
    </inertial>
    <visual>
      <origin xyz="0 0 0.008" rpy="0 0 0" />
      <geometry>
        <cylinder radius="0.07" length="0.014" />
      </geometry>
      <material name="brushed_steel">
        <color rgba="0.72 0.74 0.76 1" />
      </material>
    </visual>
    <visual>
      <origin xyz="0 0 0.017" rpy="0 0 0" />
      <geometry>
        <cylinder radius="0.18" length="0.02" />
      </geometry>
      <material name="cast_aluminum">
        <color rgba="0.74 0.75 0.77 1" />
      </material>
    </visual>
    <visual>
      <origin xyz="0 0 0.003" rpy="0 0 0" />
      <geometry>
        <cylinder radius="0.19" length="0.004" />
      </geometry>
      <material name="charcoal_plastic">
        <color rgba="0.18 0.19 0.21 1" />
      </material>
    </visual>
    <visual>
      <origin xyz="0 0.146 0.012" rpy="0 0 0" />
      <geometry>
        <box size="0.072 0.07 0.02" />
      </geometry>
      <material name="charcoal_plastic">
        <color rgba="0.18 0.19 0.21 1" />
      </material>
    </visual>
    <visual>
      <origin xyz="0 0.204 0.015" rpy="1.5708 0 0" />
      <geometry>
        <cylinder radius="0.012" length="0.08" />
      </geometry>
      <material name="rubber_black">
        <color rgba="0.08 0.08 0.09 1" />
      </material>
    </visual>
    <collision name="turntable__visual_1">
      <origin xyz="0 0 0.008" rpy="0 0 0" />
      <geometry>
        <cylinder radius="0.07" length="0.014" />
      </geometry>
    </collision>
    <collision name="turntable__visual_2">
      <origin xyz="0 0 0.017" rpy="0 0 0" />
      <geometry>
        <cylinder radius="0.18" length="0.02" />
      </geometry>
    </collision>
    <collision name="turntable__visual_3">
      <origin xyz="0 0 0.003" rpy="0 0 0" />
      <geometry>
        <cylinder radius="0.19" length="0.004" />
      </geometry>
    </collision>
    <collision name="turntable__visual_4">
      <origin xyz="0 0.146 0.012" rpy="0 0 0" />
      <geometry>
        <box size="0.072 0.07 0.02" />
      </geometry>
    </collision>
    <collision name="turntable__visual_5">
      <origin xyz="0 0.204 0.015" rpy="1.5708 0 0" />
      <geometry>
        <cylinder radius="0.012" length="0.08" />
      </geometry>
    </collision>
  </link>
  <link name="saw_arm">
    <inertial>
      <origin xyz="0 0.165 0.035" rpy="0 0 0" />
      <mass value="9" />
      <inertia ixx="0.1383" ixy="0" ixz="0" iyy="0.1068" iyz="0" izz="0.1851" />
    </inertial>
    <visual>
      <origin xyz="0 0.019 0" rpy="0 0 0" />
      <geometry>
        <box size="0.11 0.036 0.06" />
      </geometry>
      <material name="brushed_steel">
        <color rgba="0.72 0.74 0.76 1" />
      </material>
    </visual>
    <visual>
      <origin xyz="0 0.061 0.028" rpy="0 0 0" />
      <geometry>
        <box size="0.13 0.075 0.085" />
      </geometry>
      <material name="charcoal_plastic">
        <color rgba="0.18 0.19 0.21 1" />
      </material>
    </visual>
    <visual>
      <origin xyz="-0.042 0.15 0.04" rpy="1.5708 0 0" />
      <geometry>
        <cylinder radius="0.012" length="0.19" />
      </geometry>
      <material name="brushed_steel">
        <color rgba="0.72 0.74 0.76 1" />
      </material>
    </visual>
    <visual>
      <origin xyz="0.042 0.15 0.04" rpy="1.5708 0 0" />
      <geometry>
        <cylinder radius="0.012" length="0.19" />
      </geometry>
      <material name="brushed_steel">
        <color rgba="0.72 0.74 0.76 1" />
      </material>
    </visual>
    <visual>
      <origin xyz="0 0.12 0.058" rpy="0 0 0" />
      <geometry>
        <box size="0.11 0.055 0.035" />
      </geometry>
      <material name="charcoal_plastic">
        <color rgba="0.18 0.19 0.21 1" />
      </material>
    </visual>
    <visual>
      <origin xyz="0 0.245 0.045" rpy="0 0 0" />
      <geometry>
        <box size="0.18 0.09 0.09" />
      </geometry>
      <material name="tool_red">
        <color rgba="0.67 0.16 0.12 1" />
      </material>
    </visual>
    <visual>
      <origin xyz="0 0.185 -0.005" rpy="0 0 0" />
      <geometry>
        <box size="0.075 0.125 0.11" />
      </geometry>
      <material name="charcoal_plastic">
        <color rgba="0.18 0.19 0.21 1" />
      </material>
    </visual>
    <visual>
      <origin xyz="0 0.245 0.032" rpy="0 1.5708 0" />
      <geometry>
        <cylinder radius="0.057" length="0.11" />
      </geometry>
      <material name="tool_red">
        <color rgba="0.67 0.16 0.12 1" />
      </material>
    </visual>
    <visual>
      <origin xyz="0 0.167 -0.012" rpy="0 1.5708 0" />
      <geometry>
        <cylinder radius="0.034" length="0.075" />
      </geometry>
      <material name="brushed_steel">
        <color rgba="0.72 0.74 0.76 1" />
      </material>
    </visual>
    <visual>
      <origin xyz="0 0.165 -0.015" rpy="0 1.5708 0" />
      <geometry>
        <mesh filename="meshes/turntable_blade.glb" />
      </geometry>
      <material name="blade_steel">
        <color rgba="0.82 0.84 0.86 1" />
      </material>
    </visual>
    <visual>
      <origin xyz="0 0.165 -0.015" rpy="0 1.5708 0" />
      <geometry>
        <mesh filename="meshes/upper_guard.glb" />
      </geometry>
      <material name="tool_red">
        <color rgba="0.67 0.16 0.12 1" />
      </material>
    </visual>
    <visual>
      <origin xyz="0 0.176 -0.01" rpy="0 1.5708 0" />
      <geometry>
        <mesh filename="meshes/lower_guard.glb" />
      </geometry>
      <material name="amber_guard">
        <color rgba="0.78 0.6 0.18 0.32" />
      </material>
    </visual>
    <visual>
      <geometry>
        <mesh filename="meshes/handle_tube.glb" />
      </geometry>
      <material name="rubber_black">
        <color rgba="0.08 0.08 0.09 1" />
      </material>
    </visual>
    <visual>
      <origin xyz="0 0.328 0.087" rpy="0 1.5708 0" />
      <geometry>
        <cylinder radius="0.014" length="0.1" />
      </geometry>
      <material name="rubber_black">
        <color rgba="0.08 0.08 0.09 1" />
      </material>
    </visual>
    <visual>
      <origin xyz="0 0.309 0.066" rpy="0 0 0" />
      <geometry>
        <box size="0.032 0.04 0.075" />
      </geometry>
      <material name="charcoal_plastic">
        <color rgba="0.18 0.19 0.21 1" />
      </material>
    </visual>
    <collision name="saw_arm__visual_1">
      <origin xyz="0 0.019 0" rpy="0 0 0" />
      <geometry>
        <box size="0.11 0.036 0.06" />
      </geometry>
    </collision>
    <collision name="saw_arm__visual_2">
      <origin xyz="0 0.061 0.028" rpy="0 0 0" />
      <geometry>
        <box size="0.13 0.075 0.085" />
      </geometry>
    </collision>
    <collision name="saw_arm__visual_3">
      <origin xyz="-0.042 0.15 0.04" rpy="1.5708 0 0" />
      <geometry>
        <cylinder radius="0.012" length="0.19" />
      </geometry>
    </collision>
    <collision name="saw_arm__visual_4">
      <origin xyz="0.042 0.15 0.04" rpy="1.5708 0 0" />
      <geometry>
        <cylinder radius="0.012" length="0.19" />
      </geometry>
    </collision>
    <collision name="saw_arm__visual_5">
      <origin xyz="0 0.12 0.058" rpy="0 0 0" />
      <geometry>
        <box size="0.11 0.055 0.035" />
      </geometry>
    </collision>
    <collision name="saw_arm__visual_6">
      <origin xyz="0 0.245 0.045" rpy="0 0 0" />
      <geometry>
        <box size="0.18 0.09 0.09" />
      </geometry>
    </collision>
    <collision name="saw_arm__visual_7">
      <origin xyz="0 0.185 -0.005" rpy="0 0 0" />
      <geometry>
        <box size="0.075 0.125 0.11" />
      </geometry>
    </collision>
    <collision name="saw_arm__visual_8">
      <origin xyz="0 0.245 0.032" rpy="0 1.5708 0" />
      <geometry>
        <cylinder radius="0.057" length="0.11" />
      </geometry>
    </collision>
    <collision name="saw_arm__visual_9">
      <origin xyz="0 0.167 -0.012" rpy="0 1.5708 0" />
      <geometry>
        <cylinder radius="0.034" length="0.075" />
      </geometry>
    </collision>
    <collision name="saw_arm__visual_10__hull_001">
      <origin xyz="0 0.165 -0.015" rpy="0 1.5708 0" />
      <geometry>
        <mesh filename="meshes/collision/cache/11201055ac88927f18717b44__hull_001.obj" />
      </geometry>
    </collision>
    <collision name="saw_arm__visual_10__hull_002">
      <origin xyz="0 0.165 -0.015" rpy="0 1.5708 0" />
      <geometry>
        <mesh filename="meshes/collision/cache/11201055ac88927f18717b44__hull_002.obj" />
      </geometry>
    </collision>
    <collision name="saw_arm__visual_10__hull_003">
      <origin xyz="0 0.165 -0.015" rpy="0 1.5708 0" />
      <geometry>
        <mesh filename="meshes/collision/cache/11201055ac88927f18717b44__hull_003.obj" />
      </geometry>
    </collision>
    <collision name="saw_arm__visual_10__hull_004">
      <origin xyz="0 0.165 -0.015" rpy="0 1.5708 0" />
      <geometry>
        <mesh filename="meshes/collision/cache/11201055ac88927f18717b44__hull_004.obj" />
      </geometry>
    </collision>
    <collision name="saw_arm__visual_11__hull_001">
      <origin xyz="0 0.165 -0.015" rpy="0 1.5708 0" />
      <geometry>
        <mesh filename="meshes/collision/cache/15d9aa3da39ddc3a147c6275__hull_001.obj" />
      </geometry>
    </collision>
    <collision name="saw_arm__visual_11__hull_002">
      <origin xyz="0 0.165 -0.015" rpy="0 1.5708 0" />
      <geometry>
        <mesh filename="meshes/collision/cache/15d9aa3da39ddc3a147c6275__hull_002.obj" />
      </geometry>
    </collision>
    <collision name="saw_arm__visual_11__hull_003">
      <origin xyz="0 0.165 -0.015" rpy="0 1.5708 0" />
      <geometry>
        <mesh filename="meshes/collision/cache/15d9aa3da39ddc3a147c6275__hull_003.obj" />
      </geometry>
    </collision>
    <collision name="saw_arm__visual_11__hull_004">
      <origin xyz="0 0.165 -0.015" rpy="0 1.5708 0" />
      <geometry>
        <mesh filename="meshes/collision/cache/15d9aa3da39ddc3a147c6275__hull_004.obj" />
      </geometry>
    </collision>
    <collision name="saw_arm__visual_11__hull_005">
      <origin xyz="0 0.165 -0.015" rpy="0 1.5708 0" />
      <geometry>
        <mesh filename="meshes/collision/cache/15d9aa3da39ddc3a147c6275__hull_005.obj" />
      </geometry>
    </collision>
    <collision name="saw_arm__visual_12__hull_001">
      <origin xyz="0 0.176 -0.01" rpy="0 1.5708 0" />
      <geometry>
        <mesh filename="meshes/collision/cache/6cda12581f75ee6267c6151e__hull_001.obj" />
      </geometry>
    </collision>
    <collision name="saw_arm__visual_12__hull_002">
      <origin xyz="0 0.176 -0.01" rpy="0 1.5708 0" />
      <geometry>
        <mesh filename="meshes/collision/cache/6cda12581f75ee6267c6151e__hull_002.obj" />
      </geometry>
    </collision>
    <collision name="saw_arm__visual_12__hull_003">
      <origin xyz="0 0.176 -0.01" rpy="0 1.5708 0" />
      <geometry>
        <mesh filename="meshes/collision/cache/6cda12581f75ee6267c6151e__hull_003.obj" />
      </geometry>
    </collision>
    <collision name="saw_arm__visual_12__hull_004">
      <origin xyz="0 0.176 -0.01" rpy="0 1.5708 0" />
      <geometry>
        <mesh filename="meshes/collision/cache/6cda12581f75ee6267c6151e__hull_004.obj" />
      </geometry>
    </collision>
    <collision name="saw_arm__visual_13__hull_001">
      <geometry>
        <mesh filename="meshes/collision/cache/8d0976c78270093b2d487659__hull_001.obj" />
      </geometry>
    </collision>
    <collision name="saw_arm__visual_13__hull_002">
      <geometry>
        <mesh filename="meshes/collision/cache/8d0976c78270093b2d487659__hull_002.obj" />
      </geometry>
    </collision>
    <collision name="saw_arm__visual_13__hull_003">
      <geometry>
        <mesh filename="meshes/collision/cache/8d0976c78270093b2d487659__hull_003.obj" />
      </geometry>
    </collision>
    <collision name="saw_arm__visual_13__hull_004">
      <geometry>
        <mesh filename="meshes/collision/cache/8d0976c78270093b2d487659__hull_004.obj" />
      </geometry>
    </collision>
    <collision name="saw_arm__visual_14">
      <origin xyz="0 0.328 0.087" rpy="0 1.5708 0" />
      <geometry>
        <cylinder radius="0.014" length="0.1" />
      </geometry>
    </collision>
    <collision name="saw_arm__visual_15">
      <origin xyz="0 0.309 0.066" rpy="0 0 0" />
      <geometry>
        <box size="0.032 0.04 0.075" />
      </geometry>
    </collision>
  </link>
  <joint name="miter_rotation" type="revolute">
    <origin xyz="0 0 0.079" rpy="0 0 0" />
    <parent link="base" />
    <child link="turntable" />
    <axis xyz="0 0 1" />
    <limit effort="25" velocity="1.5" lower="-0.82" upper="0.82" />
  </joint>
  <joint name="saw_arm_tilt" type="revolute">
    <origin xyz="0 -0.204 0.25" rpy="0 0 0" />
    <parent link="base" />
    <child link="saw_arm" />
    <axis xyz="1 0 0" />
    <limit effort="35" velocity="1.2" lower="-0.07" upper="0.95" />
  </joint>
</robot>