<robot name="transport_wheelchair">
  <material name="powder_coat_silver">
    <color rgba="0.74 0.76 0.79 1" />
  </material>
  <material name="dark_navy_upholstery">
    <color rgba="0.12 0.17 0.26 1" />
  </material>
  <material name="black_rubber">
    <color rgba="0.07 0.07 0.08 1" />
  </material>
  <material name="dark_plastic">
    <color rgba="0.14 0.14 0.15 1" />
  </material>
  <material name="brushed_alloy">
    <color rgba="0.64 0.66 0.7 1" />
  </material>
  <link name="chassis">
    <inertial>
      <origin xyz="0 0.09 0.39" rpy="0 0 0" />
      <mass value="8" />
      <inertia ixx="0.5592" ixy="0" ixz="0" iyy="0.585867" iyz="0" izz="0.333867" />
    </inertial>
    <visual>
      <geometry>
        <mesh filename="meshes/wheelchair_chassis.glb" />
      </geometry>
      <material name="powder_coat_silver">
        <color rgba="0.74 0.76 0.79 1" />
      </material>
    </visual>
    <visual>
      <origin xyz="0 0.05 0.456" rpy="0 0 0" />
      <geometry>
        <box size="0.406 0.34 0.012" />
      </geometry>
      <material name="dark_navy_upholstery">
        <color rgba="0.12 0.17 0.26 1" />
      </material>
    </visual>
    <visual>
      <origin xyz="-0.205 0.065 0.642" rpy="0 0 0" />
      <geometry>
        <box size="0.052 0.18 0.024" />
      </geometry>
      <material name="dark_plastic">
        <color rgba="0.14 0.14 0.15 1" />
      </material>
    </visual>
    <visual>
      <origin xyz="0.205 0.065 0.642" rpy="0 0 0" />
      <geometry>
        <box size="0.052 0.18 0.024" />
      </geometry>
      <material name="dark_plastic">
        <color rgba="0.14 0.14 0.15 1" />
      </material>
    </visual>
    <collision name="chassis__visual_1__hull_001">
      <geometry>
        <mesh filename="meshes/collision/cache/d0c3ab6ef39d39c4f1b09d17__hull_001.obj" />
      </geometry>
    </collision>
    <collision name="chassis__visual_1__hull_002">
      <geometry>
        <mesh filename="meshes/collision/cache/d0c3ab6ef39d39c4f1b09d17__hull_002.obj" />
      </geometry>
    </collision>
    <collision name="chassis__visual_1__hull_003">
      <geometry>
        <mesh filename="meshes/collision/cache/d0c3ab6ef39d39c4f1b09d17__hull_003.obj" />
      </geometry>
    </collision>
    <collision name="chassis__visual_1__hull_004">
      <geometry>
        <mesh filename="meshes/collision/cache/d0c3ab6ef39d39c4f1b09d17__hull_004.obj" />
      </geometry>
    </collision>
    <collision name="chassis__visual_1__hull_005">
      <geometry>
        <mesh filename="meshes/collision/cache/d0c3ab6ef39d39c4f1b09d17__hull_005.obj" />
      </geometry>
    </collision>
    <collision name="chassis__visual_1__hull_006">
      <geometry>
        <mesh filename="meshes/collision/cache/d0c3ab6ef39d39c4f1b09d17__hull_006.obj" />
      </geometry>
    </collision>
    <collision name="chassis__visual_1__hull_007">
      <geometry>
        <mesh filename="meshes/collision/cache/d0c3ab6ef39d39c4f1b09d17__hull_007.obj" />
      </geometry>
    </collision>
    <collision name="chassis__visual_1__hull_008">
      <geometry>
        <mesh filename="meshes/collision/cache/d0c3ab6ef39d39c4f1b09d17__hull_008.obj" />
      </geometry>
    </collision>
    <collision name="chassis__visual_1__hull_009">
      <geometry>
        <mesh filename="meshes/collision/cache/d0c3ab6ef39d39c4f1b09d17__hull_009.obj" />
      </geometry>
    </collision>
    <collision name="chassis__visual_1__hull_010">
      <geometry>
        <mesh filename="meshes/collision/cache/d0c3ab6ef39d39c4f1b09d17__hull_010.obj" />
      </geometry>
    </collision>
    <collision name="chassis__visual_1__hull_011">
      <geometry>
        <mesh filename="meshes/collision/cache/d0c3ab6ef39d39c4f1b09d17__hull_011.obj" />
      </geometry>
    </collision>
    <collision name="chassis__visual_1__hull_012">
      <geometry>
        <mesh filename="meshes/collision/cache/d0c3ab6ef39d39c4f1b09d17__hull_012.obj" />
      </geometry>
    </collision>
    <collision name="chassis__visual_1__hull_013">
      <geometry>
        <mesh filename="meshes/collision/cache/d0c3ab6ef39d39c4f1b09d17__hull_013.obj" />
      </geometry>
    </collision>
    <collision name="chassis__visual_1__hull_014">
      <geometry>
        <mesh filename="meshes/collision/cache/d0c3ab6ef39d39c4f1b09d17__hull_014.obj" />
      </geometry>
    </collision>
    <collision name="chassis__visual_1__hull_015">
      <geometry>
        <mesh filename="meshes/collision/cache/d0c3ab6ef39d39c4f1b09d17__hull_015.obj" />
      </geometry>
    </collision>
    <collision name="chassis__visual_1__hull_016">
      <geometry>
        <mesh filename="meshes/collision/cache/d0c3ab6ef39d39c4f1b09d17__hull_016.obj" />
      </geometry>
    </collision>
    <collision name="chassis__visual_2">
      <origin xyz="0 0.05 0.456" rpy="0 0 0" />
      <geometry>
        <box size="0.406 0.34 0.012" />
      </geometry>
    </collision>
    <collision name="chassis__visual_3">
      <origin xyz="-0.205 0.065 0.642" rpy="0 0 0" />
      <geometry>
        <box size="0.052 0.18 0.024" />
      </geometry>
    </collision>
    <collision name="chassis__visual_4">
      <origin xyz="0.205 0.065 0.642" rpy="0 0 0" />
      <geometry>
        <box size="0.052 0.18 0.024" />
      </geometry>
    </collision>
  </link>
  <link name="backrest">
    <inertial>
      <origin xyz="0 -0.02 0.23" rpy="0 0 0" />
      <mass value="2.2" />
      <inertia ixx="0.0440733" ixy="0" ixz="0" iyy="0.0687133" iyz="0" izz="0.0283067" />
    </inertial>
    <visual>
      <geometry>
        <mesh filename="meshes/wheelchair_backrest.glb" />
      </geometry>
      <material name="powder_coat_silver">
        <color rgba="0.74 0.76 0.79 1" />
      </material>
    </visual>
    <visual>
      <origin xyz="0 -0.015 0.235" rpy="0 0 0" />
      <geometry>
        <box size="0.34 0.014 0.28" />
      </geometry>
      <material name="dark_navy_upholstery">
        <color rgba="0.12 0.17 0.26 1" />
      </material>
    </visual>
    <visual>
      <origin xyz="-0.17 -0.06 0.425" rpy="1.5708 0 0" />
      <geometry>
        <cylinder radius="0.014" length="0.06" />
      </geometry>
      <material name="black_rubber">
        <color rgba="0.07 0.07 0.08 1" />
      </material>
    </visual>
    <visual>
      <origin xyz="0.17 -0.06 0.425" rpy="1.5708 0 0" />
      <geometry>
        <cylinder radius="0.014" length="0.06" />
      </geometry>
      <material name="black_rubber">
        <color rgba="0.07 0.07 0.08 1" />
      </material>
    </visual>
    <collision name="backrest__visual_1__hull_001">
      <geometry>
        <mesh filename="meshes/collision/cache/b11ebb265399b71d4f687bae__hull_001.obj" />
      </geometry>
    </collision>
    <collision name="backrest__visual_1__hull_002">
      <geometry>
        <mesh filename="meshes/collision/cache/b11ebb265399b71d4f687bae__hull_002.obj" />
      </geometry>
    </collision>
    <collision name="backrest__visual_1__hull_003">
      <geometry>
        <mesh filename="meshes/collision/cache/b11ebb265399b71d4f687bae__hull_003.obj" />
      </geometry>
    </collision>
    <collision name="backrest__visual_1__hull_004">
      <geometry>
        <mesh filename="meshes/collision/cache/b11ebb265399b71d4f687bae__hull_004.obj" />
      </geometry>
    </collision>
    <collision name="backrest__visual_1__hull_005">
      <geometry>
        <mesh filename="meshes/collision/cache/b11ebb265399b71d4f687bae__hull_005.obj" />
      </geometry>
    </collision>
    <collision name="backrest__visual_1__hull_006">
      <geometry>
        <mesh filename="meshes/collision/cache/b11ebb265399b71d4f687bae__hull_006.obj" />
      </geometry>
    </collision>
    <collision name="backrest__visual_1__hull_007">
      <geometry>
        <mesh filename="meshes/collision/cache/b11ebb265399b71d4f687bae__hull_007.obj" />
      </geometry>
    </collision>
    <collision name="backrest__visual_1__hull_008">
      <geometry>
        <mesh filename="meshes/collision/cache/b11ebb265399b71d4f687bae__hull_008.obj" />
      </geometry>
    </collision>
    <collision name="backrest__visual_1__hull_009">
      <geometry>
        <mesh filename="meshes/collision/cache/b11ebb265399b71d4f687bae__hull_009.obj" />
      </geometry>
    </collision>
    <collision name="backrest__visual_1__hull_010">
      <geometry>
        <mesh filename="meshes/collision/cache/b11ebb265399b71d4f687bae__hull_010.obj" />
      </geometry>
    </collision>
    <collision name="backrest__visual_2">
      <origin xyz="0 -0.015 0.235" rpy="0 0 0" />
      <geometry>
        <box size="0.34 0.014 0.28" />
      </geometry>
    </collision>
    <collision name="backrest__visual_3">
      <origin xyz="-0.17 -0.06 0.425" rpy="1.5708 0 0" />
      <geometry>
        <cylinder radius="0.014" length="0.06" />
      </geometry>
    </collision>
    <collision name="backrest__visual_4">
      <origin xyz="0.17 -0.06 0.425" rpy="1.5708 0 0" />
      <geometry>
        <cylinder radius="0.014" length="0.06" />
      </geometry>
    </collision>
  </link>
  <link name="rear_wheel_left">
    <inertial>
      <origin xyz="0 0 0" rpy="0 1.5708 0" />
      <mass value="0.85" />
      <inertia ixx="0.00157611" ixy="0" ixz="0" iyy="0.00157611" iyz="0" izz="0.00307063" />
    </inertial>
    <visual>
      <geometry>
        <mesh filename="meshes/wheelchair_rear_tire.glb" />
      </geometry>
      <material name="black_rubber">
        <color rgba="0.07 0.07 0.08 1" />
      </material>
    </visual>
    <visual>
      <geometry>
        <mesh filename="meshes/wheelchair_rear_core.glb" />
      </geometry>
      <material name="brushed_alloy">
        <color rgba="0.64 0.66 0.7 1" />
      </material>
    </visual>
    <collision name="rear_wheel_left__visual_1__hull_001">
      <geometry>
        <mesh filename="meshes/collision/cache/6ba3dff61bb27565f7a408bb__hull_001.obj" />
      </geometry>
    </collision>
    <collision name="rear_wheel_left__visual_1__hull_002">
      <geometry>
        <mesh filename="meshes/collision/cache/6ba3dff61bb27565f7a408bb__hull_002.obj" />
      </geometry>
    </collision>
    <collision name="rear_wheel_left__visual_1__hull_003">
      <geometry>
        <mesh filename="meshes/collision/cache/6ba3dff61bb27565f7a408bb__hull_003.obj" />
      </geometry>
    </collision>
    <collision name="rear_wheel_left__visual_1__hull_004">
      <geometry>
        <mesh filename="meshes/collision/cache/6ba3dff61bb27565f7a408bb__hull_004.obj" />
      </geometry>
    </collision>
    <collision name="rear_wheel_left__visual_1__hull_005">
      <geometry>
        <mesh filename="meshes/collision/cache/6ba3dff61bb27565f7a408bb__hull_005.obj" />
      </geometry>
    </collision>
    <collision name="rear_wheel_left__visual_1__hull_006">
      <geometry>
        <mesh filename="meshes/collision/cache/6ba3dff61bb27565f7a408bb__hull_006.obj" />
      </geometry>
    </collision>
    <collision name="rear_wheel_left__visual_1__hull_007">
      <geometry>
        <mesh filename="meshes/collision/cache/6ba3dff61bb27565f7a408bb__hull_007.obj" />
      </geometry>
    </collision>
    <collision name="rear_wheel_left__visual_1__hull_008">
      <geometry>
        <mesh filename="meshes/collision/cache/6ba3dff61bb27565f7a408bb__hull_008.obj" />
      </geometry>
    </collision>
    <collision name="rear_wheel_left__visual_2__hull_001">
      <geometry>
        <mesh filename="meshes/collision/cache/51a29cd0f452a8aa8146c88c__hull_001.obj" />
      </geometry>
    </collision>
    <collision name="rear_wheel_left__visual_2__hull_002">
      <geometry>
        <mesh filename="meshes/collision/cache/51a29cd0f452a8aa8146c88c__hull_002.obj" />
      </geometry>
    </collision>
    <collision name="rear_wheel_left__visual_2__hull_003">
      <geometry>
        <mesh filename="meshes/collision/cache/51a29cd0f452a8aa8146c88c__hull_003.obj" />
      </geometry>
    </collision>
    <collision name="rear_wheel_left__visual_2__hull_004">
      <geometry>
        <mesh filename="meshes/collision/cache/51a29cd0f452a8aa8146c88c__hull_004.obj" />
      </geometry>
    </collision>
    <collision name="rear_wheel_left__visual_2__hull_005">
      <geometry>
        <mesh filename="meshes/collision/cache/51a29cd0f452a8aa8146c88c__hull_005.obj" />
      </geometry>
    </collision>
    <collision name="rear_wheel_left__visual_2__hull_006">
      <geometry>
        <mesh filename="meshes/collision/cache/51a29cd0f452a8aa8146c88c__hull_006.obj" />
      </geometry>
    </collision>
    <collision name="rear_wheel_left__visual_2__hull_007">
      <geometry>
        <mesh filename="meshes/collision/cache/51a29cd0f452a8aa8146c88c__hull_007.obj" />
      </geometry>
    </collision>
    <collision name="rear_wheel_left__visual_2__hull_008">
      <geometry>
        <mesh filename="meshes/collision/cache/51a29cd0f452a8aa8146c88c__hull_008.obj" />
      </geometry>
    </collision>
    <collision name="rear_wheel_left__visual_2__hull_009">
      <geometry>
        <mesh filename="meshes/collision/cache/51a29cd0f452a8aa8146c88c__hull_009.obj" />
      </geometry>
    </collision>
    <collision name="rear_wheel_left__visual_2__hull_010">
      <geometry>
        <mesh filename="meshes/collision/cache/51a29cd0f452a8aa8146c88c__hull_010.obj" />
      </geometry>
    </collision>
    <collision name="rear_wheel_left__visual_2__hull_011">
      <geometry>
        <mesh filename="meshes/collision/cache/51a29cd0f452a8aa8146c88c__hull_011.obj" />
      </geometry>
    </collision>
    <collision name="rear_wheel_left__visual_2__hull_012">
      <geometry>
        <mesh filename="meshes/collision/cache/51a29cd0f452a8aa8146c88c__hull_012.obj" />
      </geometry>
    </collision>
    <collision name="rear_wheel_left__visual_2__hull_013">
      <geometry>
        <mesh filename="meshes/collision/cache/51a29cd0f452a8aa8146c88c__hull_013.obj" />
      </geometry>
    </collision>
    <collision name="rear_wheel_left__visual_2__hull_014">
      <geometry>
        <mesh filename="meshes/collision/cache/51a29cd0f452a8aa8146c88c__hull_014.obj" />
      </geometry>
    </collision>
    <collision name="rear_wheel_left__visual_2__hull_015">
      <geometry>
        <mesh filename="meshes/collision/cache/51a29cd0f452a8aa8146c88c__hull_015.obj" />
      </geometry>
    </collision>
    <collision name="rear_wheel_left__visual_2__hull_016">
      <geometry>
        <mesh filename="meshes/collision/cache/51a29cd0f452a8aa8146c88c__hull_016.obj" />
      </geometry>
    </collision>
  </link>
  <link name="rear_wheel_right">
    <inertial>
      <origin xyz="0 0 0" rpy="0 1.5708 0" />
      <mass value="0.85" />
      <inertia ixx="0.00157611" ixy="0" ixz="0" iyy="0.00157611" iyz="0" izz="0.00307063" />
    </inertial>
    <visual>
      <geometry>
        <mesh filename="meshes/wheelchair_rear_tire.glb" />
      </geometry>
      <material name="black_rubber">
        <color rgba="0.07 0.07 0.08 1" />
      </material>
    </visual>
    <visual>
      <geometry>
        <mesh filename="meshes/wheelchair_rear_core.glb" />
      </geometry>
      <material name="brushed_alloy">
        <color rgba="0.64 0.66 0.7 1" />
      </material>
    </visual>
    <collision name="rear_wheel_right__visual_1__hull_001">
      <geometry>
        <mesh filename="meshes/collision/cache/6ba3dff61bb27565f7a408bb__hull_001.obj" />
      </geometry>
    </collision>
    <collision name="rear_wheel_right__visual_1__hull_002">
      <geometry>
        <mesh filename="meshes/collision/cache/6ba3dff61bb27565f7a408bb__hull_002.obj" />
      </geometry>
    </collision>
    <collision name="rear_wheel_right__visual_1__hull_003">
      <geometry>
        <mesh filename="meshes/collision/cache/6ba3dff61bb27565f7a408bb__hull_003.obj" />
      </geometry>
    </collision>
    <collision name="rear_wheel_right__visual_1__hull_004">
      <geometry>
        <mesh filename="meshes/collision/cache/6ba3dff61bb27565f7a408bb__hull_004.obj" />
      </geometry>
    </collision>
    <collision name="rear_wheel_right__visual_1__hull_005">
      <geometry>
        <mesh filename="meshes/collision/cache/6ba3dff61bb27565f7a408bb__hull_005.obj" />
      </geometry>
    </collision>
    <collision name="rear_wheel_right__visual_1__hull_006">
      <geometry>
        <mesh filename="meshes/collision/cache/6ba3dff61bb27565f7a408bb__hull_006.obj" />
      </geometry>
    </collision>
    <collision name="rear_wheel_right__visual_1__hull_007">
      <geometry>
        <mesh filename="meshes/collision/cache/6ba3dff61bb27565f7a408bb__hull_007.obj" />
      </geometry>
    </collision>
    <collision name="rear_wheel_right__visual_1__hull_008">
      <geometry>
        <mesh filename="meshes/collision/cache/6ba3dff61bb27565f7a408bb__hull_008.obj" />
      </geometry>
    </collision>
    <collision name="rear_wheel_right__visual_2__hull_001">
      <geometry>
        <mesh filename="meshes/collision/cache/51a29cd0f452a8aa8146c88c__hull_001.obj" />
      </geometry>
    </collision>
    <collision name="rear_wheel_right__visual_2__hull_002">
      <geometry>
        <mesh filename="meshes/collision/cache/51a29cd0f452a8aa8146c88c__hull_002.obj" />
      </geometry>
    </collision>
    <collision name="rear_wheel_right__visual_2__hull_003">
      <geometry>
        <mesh filename="meshes/collision/cache/51a29cd0f452a8aa8146c88c__hull_003.obj" />
      </geometry>
    </collision>
    <collision name="rear_wheel_right__visual_2__hull_004">
      <geometry>
        <mesh filename="meshes/collision/cache/51a29cd0f452a8aa8146c88c__hull_004.obj" />
      </geometry>
    </collision>
    <collision name="rear_wheel_right__visual_2__hull_005">
      <geometry>
        <mesh filename="meshes/collision/cache/51a29cd0f452a8aa8146c88c__hull_005.obj" />
      </geometry>
    </collision>
    <collision name="rear_wheel_right__visual_2__hull_006">
      <geometry>
        <mesh filename="meshes/collision/cache/51a29cd0f452a8aa8146c88c__hull_006.obj" />
      </geometry>
    </collision>
    <collision name="rear_wheel_right__visual_2__hull_007">
      <geometry>
        <mesh filename="meshes/collision/cache/51a29cd0f452a8aa8146c88c__hull_007.obj" />
      </geometry>
    </collision>
    <collision name="rear_wheel_right__visual_2__hull_008">
      <geometry>
        <mesh filename="meshes/collision/cache/51a29cd0f452a8aa8146c88c__hull_008.obj" />
      </geometry>
    </collision>
    <collision name="rear_wheel_right__visual_2__hull_009">
      <geometry>
        <mesh filename="meshes/collision/cache/51a29cd0f452a8aa8146c88c__hull_009.obj" />
      </geometry>
    </collision>
    <collision name="rear_wheel_right__visual_2__hull_010">
      <geometry>
        <mesh filename="meshes/collision/cache/51a29cd0f452a8aa8146c88c__hull_010.obj" />
      </geometry>
    </collision>
    <collision name="rear_wheel_right__visual_2__hull_011">
      <geometry>
        <mesh filename="meshes/collision/cache/51a29cd0f452a8aa8146c88c__hull_011.obj" />
      </geometry>
    </collision>
    <collision name="rear_wheel_right__visual_2__hull_012">
      <geometry>
        <mesh filename="meshes/collision/cache/51a29cd0f452a8aa8146c88c__hull_012.obj" />
      </geometry>
    </collision>
    <collision name="rear_wheel_right__visual_2__hull_013">
      <geometry>
        <mesh filename="meshes/collision/cache/51a29cd0f452a8aa8146c88c__hull_013.obj" />
      </geometry>
    </collision>
    <collision name="rear_wheel_right__visual_2__hull_014">
      <geometry>
        <mesh filename="meshes/collision/cache/51a29cd0f452a8aa8146c88c__hull_014.obj" />
      </geometry>
    </collision>
    <collision name="rear_wheel_right__visual_2__hull_015">
      <geometry>
        <mesh filename="meshes/collision/cache/51a29cd0f452a8aa8146c88c__hull_015.obj" />
      </geometry>
    </collision>
    <collision name="rear_wheel_right__visual_2__hull_016">
      <geometry>
        <mesh filename="meshes/collision/cache/51a29cd0f452a8aa8146c88c__hull_016.obj" />
      </geometry>
    </collision>
  </link>
  <link name="caster_left_wheel">
    <inertial>
      <origin xyz="0 0 0" rpy="0 1.5708 0" />
      <mass value="0.28" />
      <inertia ixx="0.000223043" ixy="0" ixz="0" iyy="0.000223043" iyz="0" izz="0.0004235" />
    </inertial>
    <visual>
      <geometry>
        <mesh filename="meshes/wheelchair_caster_tire.glb" />
      </geometry>
      <material name="black_rubber">
        <color rgba="0.07 0.07 0.08 1" />
      </material>
    </visual>
    <visual>
      <geometry>
        <mesh filename="meshes/wheelchair_caster_core.glb" />
      </geometry>
      <material name="brushed_alloy">
        <color rgba="0.64 0.66 0.7 1" />
      </material>
    </visual>
    <collision name="caster_left_wheel__visual_1__hull_001">
      <geometry>
        <mesh filename="meshes/collision/cache/3ff78a8c1153ac18cb4ec004__hull_001.obj" />
      </geometry>
    </collision>
    <collision name="caster_left_wheel__visual_1__hull_002">
      <geometry>
        <mesh filename="meshes/collision/cache/3ff78a8c1153ac18cb4ec004__hull_002.obj" />
      </geometry>
    </collision>
    <collision name="caster_left_wheel__visual_1__hull_003">
      <geometry>
        <mesh filename="meshes/collision/cache/3ff78a8c1153ac18cb4ec004__hull_003.obj" />
      </geometry>
    </collision>
    <collision name="caster_left_wheel__visual_1__hull_004">
      <geometry>
        <mesh filename="meshes/collision/cache/3ff78a8c1153ac18cb4ec004__hull_004.obj" />
      </geometry>
    </collision>
    <collision name="caster_left_wheel__visual_1__hull_005">
      <geometry>
        <mesh filename="meshes/collision/cache/3ff78a8c1153ac18cb4ec004__hull_005.obj" />
      </geometry>
    </collision>
    <collision name="caster_left_wheel__visual_1__hull_006">
      <geometry>
        <mesh filename="meshes/collision/cache/3ff78a8c1153ac18cb4ec004__hull_006.obj" />
      </geometry>
    </collision>
    <collision name="caster_left_wheel__visual_1__hull_007">
      <geometry>
        <mesh filename="meshes/collision/cache/3ff78a8c1153ac18cb4ec004__hull_007.obj" />
      </geometry>
    </collision>
    <collision name="caster_left_wheel__visual_1__hull_008">
      <geometry>
        <mesh filename="meshes/collision/cache/3ff78a8c1153ac18cb4ec004__hull_008.obj" />
      </geometry>
    </collision>
    <collision name="caster_left_wheel__visual_1__hull_009">
      <geometry>
        <mesh filename="meshes/collision/cache/3ff78a8c1153ac18cb4ec004__hull_009.obj" />
      </geometry>
    </collision>
    <collision name="caster_left_wheel__visual_2__hull_001">
      <geometry>
        <mesh filename="meshes/collision/cache/15f0cc8ff941924fdbdbe04f__hull_001.obj" />
      </geometry>
    </collision>
    <collision name="caster_left_wheel__visual_2__hull_002">
      <geometry>
        <mesh filename="meshes/collision/cache/15f0cc8ff941924fdbdbe04f__hull_002.obj" />
      </geometry>
    </collision>
    <collision name="caster_left_wheel__visual_2__hull_003">
      <geometry>
        <mesh filename="meshes/collision/cache/15f0cc8ff941924fdbdbe04f__hull_003.obj" />
      </geometry>
    </collision>
    <collision name="caster_left_wheel__visual_2__hull_004">
      <geometry>
        <mesh filename="meshes/collision/cache/15f0cc8ff941924fdbdbe04f__hull_004.obj" />
      </geometry>
    </collision>
    <collision name="caster_left_wheel__visual_2__hull_005">
      <geometry>
        <mesh filename="meshes/collision/cache/15f0cc8ff941924fdbdbe04f__hull_005.obj" />
      </geometry>
    </collision>
    <collision name="caster_left_wheel__visual_2__hull_006">
      <geometry>
        <mesh filename="meshes/collision/cache/15f0cc8ff941924fdbdbe04f__hull_006.obj" />
      </geometry>
    </collision>
    <collision name="caster_left_wheel__visual_2__hull_007">
      <geometry>
        <mesh filename="meshes/collision/cache/15f0cc8ff941924fdbdbe04f__hull_007.obj" />
      </geometry>
    </collision>
    <collision name="caster_left_wheel__visual_2__hull_008">
      <geometry>
        <mesh filename="meshes/collision/cache/15f0cc8ff941924fdbdbe04f__hull_008.obj" />
      </geometry>
    </collision>
    <collision name="caster_left_wheel__visual_2__hull_009">
      <geometry>
        <mesh filename="meshes/collision/cache/15f0cc8ff941924fdbdbe04f__hull_009.obj" />
      </geometry>
    </collision>
    <collision name="caster_left_wheel__visual_2__hull_010">
      <geometry>
        <mesh filename="meshes/collision/cache/15f0cc8ff941924fdbdbe04f__hull_010.obj" />
      </geometry>
    </collision>
    <collision name="caster_left_wheel__visual_2__hull_011">
      <geometry>
        <mesh filename="meshes/collision/cache/15f0cc8ff941924fdbdbe04f__hull_011.obj" />
      </geometry>
    </collision>
    <collision name="caster_left_wheel__visual_2__hull_012">
      <geometry>
        <mesh filename="meshes/collision/cache/15f0cc8ff941924fdbdbe04f__hull_012.obj" />
      </geometry>
    </collision>
    <collision name="caster_left_wheel__visual_2__hull_013">
      <geometry>
        <mesh filename="meshes/collision/cache/15f0cc8ff941924fdbdbe04f__hull_013.obj" />
      </geometry>
    </collision>
    <collision name="caster_left_wheel__visual_2__hull_014">
      <geometry>
        <mesh filename="meshes/collision/cache/15f0cc8ff941924fdbdbe04f__hull_014.obj" />
      </geometry>
    </collision>
    <collision name="caster_left_wheel__visual_2__hull_015">
      <geometry>
        <mesh filename="meshes/collision/cache/15f0cc8ff941924fdbdbe04f__hull_015.obj" />
      </geometry>
    </collision>
    <collision name="caster_left_wheel__visual_2__hull_016">
      <geometry>
        <mesh filename="meshes/collision/cache/15f0cc8ff941924fdbdbe04f__hull_016.obj" />
      </geometry>
    </collision>
  </link>
  <link name="caster_right_wheel">
    <inertial>
      <origin xyz="0 0 0" rpy="0 1.5708 0" />
      <mass value="0.28" />
      <inertia ixx="0.000223043" ixy="0" ixz="0" iyy="0.000223043" iyz="0" izz="0.0004235" />
    </inertial>
    <visual>
      <geometry>
        <mesh filename="meshes/wheelchair_caster_tire.glb" />
      </geometry>
      <material name="black_rubber">
        <color rgba="0.07 0.07 0.08 1" />
      </material>
    </visual>
    <visual>
      <geometry>
        <mesh filename="meshes/wheelchair_caster_core.glb" />
      </geometry>
      <material name="brushed_alloy">
        <color rgba="0.64 0.66 0.7 1" />
      </material>
    </visual>
    <collision name="caster_right_wheel__visual_1__hull_001">
      <geometry>
        <mesh filename="meshes/collision/cache/3ff78a8c1153ac18cb4ec004__hull_001.obj" />
      </geometry>
    </collision>
    <collision name="caster_right_wheel__visual_1__hull_002">
      <geometry>
        <mesh filename="meshes/collision/cache/3ff78a8c1153ac18cb4ec004__hull_002.obj" />
      </geometry>
    </collision>
    <collision name="caster_right_wheel__visual_1__hull_003">
      <geometry>
        <mesh filename="meshes/collision/cache/3ff78a8c1153ac18cb4ec004__hull_003.obj" />
      </geometry>
    </collision>
    <collision name="caster_right_wheel__visual_1__hull_004">
      <geometry>
        <mesh filename="meshes/collision/cache/3ff78a8c1153ac18cb4ec004__hull_004.obj" />
      </geometry>
    </collision>
    <collision name="caster_right_wheel__visual_1__hull_005">
      <geometry>
        <mesh filename="meshes/collision/cache/3ff78a8c1153ac18cb4ec004__hull_005.obj" />
      </geometry>
    </collision>
    <collision name="caster_right_wheel__visual_1__hull_006">
      <geometry>
        <mesh filename="meshes/collision/cache/3ff78a8c1153ac18cb4ec004__hull_006.obj" />
      </geometry>
    </collision>
    <collision name="caster_right_wheel__visual_1__hull_007">
      <geometry>
        <mesh filename="meshes/collision/cache/3ff78a8c1153ac18cb4ec004__hull_007.obj" />
      </geometry>
    </collision>
    <collision name="caster_right_wheel__visual_1__hull_008">
      <geometry>
        <mesh filename="meshes/collision/cache/3ff78a8c1153ac18cb4ec004__hull_008.obj" />
      </geometry>
    </collision>
    <collision name="caster_right_wheel__visual_1__hull_009">
      <geometry>
        <mesh filename="meshes/collision/cache/3ff78a8c1153ac18cb4ec004__hull_009.obj" />
      </geometry>
    </collision>
    <collision name="caster_right_wheel__visual_2__hull_001">
      <geometry>
        <mesh filename="meshes/collision/cache/15f0cc8ff941924fdbdbe04f__hull_001.obj" />
      </geometry>
    </collision>
    <collision name="caster_right_wheel__visual_2__hull_002">
      <geometry>
        <mesh filename="meshes/collision/cache/15f0cc8ff941924fdbdbe04f__hull_002.obj" />
      </geometry>
    </collision>
    <collision name="caster_right_wheel__visual_2__hull_003">
      <geometry>
        <mesh filename="meshes/collision/cache/15f0cc8ff941924fdbdbe04f__hull_003.obj" />
      </geometry>
    </collision>
    <collision name="caster_right_wheel__visual_2__hull_004">
      <geometry>
        <mesh filename="meshes/collision/cache/15f0cc8ff941924fdbdbe04f__hull_004.obj" />
      </geometry>
    </collision>
    <collision name="caster_right_wheel__visual_2__hull_005">
      <geometry>
        <mesh filename="meshes/collision/cache/15f0cc8ff941924fdbdbe04f__hull_005.obj" />
      </geometry>
    </collision>
    <collision name="caster_right_wheel__visual_2__hull_006">
      <geometry>
        <mesh filename="meshes/collision/cache/15f0cc8ff941924fdbdbe04f__hull_006.obj" />
      </geometry>
    </collision>
    <collision name="caster_right_wheel__visual_2__hull_007">
      <geometry>
        <mesh filename="meshes/collision/cache/15f0cc8ff941924fdbdbe04f__hull_007.obj" />
      </geometry>
    </collision>
    <collision name="caster_right_wheel__visual_2__hull_008">
      <geometry>
        <mesh filename="meshes/collision/cache/15f0cc8ff941924fdbdbe04f__hull_008.obj" />
      </geometry>
    </collision>
    <collision name="caster_right_wheel__visual_2__hull_009">
      <geometry>
        <mesh filename="meshes/collision/cache/15f0cc8ff941924fdbdbe04f__hull_009.obj" />
      </geometry>
    </collision>
    <collision name="caster_right_wheel__visual_2__hull_010">
      <geometry>
        <mesh filename="meshes/collision/cache/15f0cc8ff941924fdbdbe04f__hull_010.obj" />
      </geometry>
    </collision>
    <collision name="caster_right_wheel__visual_2__hull_011">
      <geometry>
        <mesh filename="meshes/collision/cache/15f0cc8ff941924fdbdbe04f__hull_011.obj" />
      </geometry>
    </collision>
    <collision name="caster_right_wheel__visual_2__hull_012">
      <geometry>
        <mesh filename="meshes/collision/cache/15f0cc8ff941924fdbdbe04f__hull_012.obj" />
      </geometry>
    </collision>
    <collision name="caster_right_wheel__visual_2__hull_013">
      <geometry>
        <mesh filename="meshes/collision/cache/15f0cc8ff941924fdbdbe04f__hull_013.obj" />
      </geometry>
    </collision>
    <collision name="caster_right_wheel__visual_2__hull_014">
      <geometry>
        <mesh filename="meshes/collision/cache/15f0cc8ff941924fdbdbe04f__hull_014.obj" />
      </geometry>
    </collision>
    <collision name="caster_right_wheel__visual_2__hull_015">
      <geometry>
        <mesh filename="meshes/collision/cache/15f0cc8ff941924fdbdbe04f__hull_015.obj" />
      </geometry>
    </collision>
    <collision name="caster_right_wheel__visual_2__hull_016">
      <geometry>
        <mesh filename="meshes/collision/cache/15f0cc8ff941924fdbdbe04f__hull_016.obj" />
      </geometry>
    </collision>
  </link>
  <link name="caster_left_yoke">
    <inertial>
      <origin xyz="0 0 -0.075" rpy="0 0 0" />
      <mass value="0.22" />
      <inertia ixx="0.000429" ixy="0" ixz="0" iyy="0.0004785" iyz="0" izz="8.25e-05" />
    </inertial>
    <visual>
      <geometry>
        <mesh filename="meshes/wheelchair_caster_yoke.glb" />
      </geometry>
      <material name="powder_coat_silver">
        <color rgba="0.74 0.76 0.79 1" />
      </material>
    </visual>
    <collision name="caster_left_yoke__visual_1__hull_001">
      <geometry>
        <mesh filename="meshes/collision/cache/b6f5738ce7bcb10bbbb6b7d8__hull_001.obj" />
      </geometry>
    </collision>
    <collision name="caster_left_yoke__visual_1__hull_002">
      <geometry>
        <mesh filename="meshes/collision/cache/b6f5738ce7bcb10bbbb6b7d8__hull_002.obj" />
      </geometry>
    </collision>
    <collision name="caster_left_yoke__visual_1__hull_003">
      <geometry>
        <mesh filename="meshes/collision/cache/b6f5738ce7bcb10bbbb6b7d8__hull_003.obj" />
      </geometry>
    </collision>
    <collision name="caster_left_yoke__visual_1__hull_004">
      <geometry>
        <mesh filename="meshes/collision/cache/b6f5738ce7bcb10bbbb6b7d8__hull_004.obj" />
      </geometry>
    </collision>
    <collision name="caster_left_yoke__visual_1__hull_005">
      <geometry>
        <mesh filename="meshes/collision/cache/b6f5738ce7bcb10bbbb6b7d8__hull_005.obj" />
      </geometry>
    </collision>
  </link>
  <link name="caster_right_yoke">
    <inertial>
      <origin xyz="0 0 -0.075" rpy="0 0 0" />
      <mass value="0.22" />
      <inertia ixx="0.000429" ixy="0" ixz="0" iyy="0.0004785" iyz="0" izz="8.25e-05" />
    </inertial>
    <visual>
      <geometry>
        <mesh filename="meshes/wheelchair_caster_yoke.glb" />
      </geometry>
      <material name="powder_coat_silver">
        <color rgba="0.74 0.76 0.79 1" />
      </material>
    </visual>
    <collision name="caster_right_yoke__visual_1__hull_001">
      <geometry>
        <mesh filename="meshes/collision/cache/b6f5738ce7bcb10bbbb6b7d8__hull_001.obj" />
      </geometry>
    </collision>
    <collision name="caster_right_yoke__visual_1__hull_002">
      <geometry>
        <mesh filename="meshes/collision/cache/b6f5738ce7bcb10bbbb6b7d8__hull_002.obj" />
      </geometry>
    </collision>
    <collision name="caster_right_yoke__visual_1__hull_003">
      <geometry>
        <mesh filename="meshes/collision/cache/b6f5738ce7bcb10bbbb6b7d8__hull_003.obj" />
      </geometry>
    </collision>
    <collision name="caster_right_yoke__visual_1__hull_004">
      <geometry>
        <mesh filename="meshes/collision/cache/b6f5738ce7bcb10bbbb6b7d8__hull_004.obj" />
      </geometry>
    </collision>
    <collision name="caster_right_yoke__visual_1__hull_005">
      <geometry>
        <mesh filename="meshes/collision/cache/b6f5738ce7bcb10bbbb6b7d8__hull_005.obj" />
      </geometry>
    </collision>
  </link>
  <link name="footrest_left">
    <inertial>
      <origin xyz="0 0.08 -0.13" rpy="0 0 0" />
      <mass value="0.45" />
      <inertia ixx="0.003495" ixy="0" ixz="0" iyy="0.00316875" iyz="0" izz="0.00159375" />
    </inertial>
    <visual>
      <geometry>
        <mesh filename="meshes/wheelchair_footrest.glb" />
      </geometry>
      <material name="powder_coat_silver">
        <color rgba="0.74 0.76 0.79 1" />
      </material>
    </visual>
    <visual>
      <origin xyz="0 0.108 -0.223" rpy="0 0 0" />
      <geometry>
        <box size="0.108 0.082 0.003" />
      </geometry>
      <material name="black_rubber">
        <color rgba="0.07 0.07 0.08 1" />
      </material>
    </visual>
    <collision name="footrest_left__visual_1__hull_001">
      <geometry>
        <mesh filename="meshes/collision/cache/70768bd9a814806b4f5e8ee7__hull_001.obj" />
      </geometry>
    </collision>
    <collision name="footrest_left__visual_1__hull_002">
      <geometry>
        <mesh filename="meshes/collision/cache/70768bd9a814806b4f5e8ee7__hull_002.obj" />
      </geometry>
    </collision>
    <collision name="footrest_left__visual_1__hull_003">
      <geometry>
        <mesh filename="meshes/collision/cache/70768bd9a814806b4f5e8ee7__hull_003.obj" />
      </geometry>
    </collision>
    <collision name="footrest_left__visual_1__hull_004">
      <geometry>
        <mesh filename="meshes/collision/cache/70768bd9a814806b4f5e8ee7__hull_004.obj" />
      </geometry>
    </collision>
    <collision name="footrest_left__visual_2">
      <origin xyz="0 0.108 -0.223" rpy="0 0 0" />
      <geometry>
        <box size="0.108 0.082 0.003" />
      </geometry>
    </collision>
  </link>
  <link name="footrest_right">
    <inertial>
      <origin xyz="0 0.08 -0.13" rpy="0 0 0" />
      <mass value="0.45" />
      <inertia ixx="0.003495" ixy="0" ixz="0" iyy="0.00316875" iyz="0" izz="0.00159375" />
    </inertial>
    <visual>
      <geometry>
        <mesh filename="meshes/wheelchair_footrest.glb" />
      </geometry>
      <material name="powder_coat_silver">
        <color rgba="0.74 0.76 0.79 1" />
      </material>
    </visual>
    <visual>
      <origin xyz="0 0.108 -0.223" rpy="0 0 0" />
      <geometry>
        <box size="0.108 0.082 0.003" />
      </geometry>
      <material name="black_rubber">
        <color rgba="0.07 0.07 0.08 1" />
      </material>
    </visual>
    <collision name="footrest_right__visual_1__hull_001">
      <geometry>
        <mesh filename="meshes/collision/cache/70768bd9a814806b4f5e8ee7__hull_001.obj" />
      </geometry>
    </collision>
    <collision name="footrest_right__visual_1__hull_002">
      <geometry>
        <mesh filename="meshes/collision/cache/70768bd9a814806b4f5e8ee7__hull_002.obj" />
      </geometry>
    </collision>
    <collision name="footrest_right__visual_1__hull_003">
      <geometry>
        <mesh filename="meshes/collision/cache/70768bd9a814806b4f5e8ee7__hull_003.obj" />
      </geometry>
    </collision>
    <collision name="footrest_right__visual_1__hull_004">
      <geometry>
        <mesh filename="meshes/collision/cache/70768bd9a814806b4f5e8ee7__hull_004.obj" />
      </geometry>
    </collision>
    <collision name="footrest_right__visual_2">
      <origin xyz="0 0.108 -0.223" rpy="0 0 0" />
      <geometry>
        <box size="0.108 0.082 0.003" />
      </geometry>
    </collision>
  </link>
  <joint name="backrest_fold" type="revolute">
    <origin xyz="0 -0.135 0.468" rpy="0 0 0" />
    <parent link="chassis" />
    <child link="backrest" />
    <axis xyz="-1 0 0" />
    <limit effort="20" velocity="1.4" lower="0" upper="1.15" />
  </joint>
  <joint name="rear_left_wheel_spin" type="continuous">
    <origin xyz="-0.25 -0.11 0.085" rpy="0 0 0" />
    <parent link="chassis" />
    <child link="rear_wheel_left" />
    <axis xyz="1 0 0" />
    <limit effort="6" velocity="14" />
  </joint>
  <joint name="rear_right_wheel_spin" type="continuous">
    <origin xyz="0.25 -0.11 0.085" rpy="0 0 0" />
    <parent link="chassis" />
    <child link="rear_wheel_right" />
    <axis xyz="1 0 0" />
    <limit effort="6" velocity="14" />
  </joint>
  <joint name="caster_left_swivel" type="continuous">
    <origin xyz="-0.236 0.32 0.182" rpy="0 0 0" />
    <parent link="chassis" />
    <child link="caster_left_yoke" />
    <axis xyz="0 0 1" />
    <limit effort="2.5" velocity="6" />
  </joint>
  <joint name="caster_right_swivel" type="continuous">
    <origin xyz="0.236 0.32 0.182" rpy="0 0 0" />
    <parent link="chassis" />
    <child link="caster_right_yoke" />
    <axis xyz="0 0 1" />
    <limit effort="2.5" velocity="6" />
  </joint>
  <joint name="caster_left_wheel_spin" type="continuous">
    <origin xyz="0 0 -0.12" rpy="0 0 0" />
    <parent link="caster_left_yoke" />
    <child link="caster_left_wheel" />
    <axis xyz="1 0 0" />
    <limit effort="2" velocity="14" />
  </joint>
  <joint name="caster_right_wheel_spin" type="continuous">
    <origin xyz="0 0 -0.12" rpy="0 0 0" />
    <parent link="caster_right_yoke" />
    <child link="caster_right_wheel" />
    <axis xyz="1 0 0" />
    <limit effort="2" velocity="14" />
  </joint>
  <joint name="footrest_left_fold" type="revolute">
    <origin xyz="-0.095 0.285 0.285" rpy="0 0 0" />
    <parent link="chassis" />
    <child link="footrest_left" />
    <axis xyz="1 0 0" />
    <limit effort="8" velocity="2.2" lower="0" upper="1.3" />
  </joint>
  <joint name="footrest_right_fold" type="revolute">
    <origin xyz="0.095 0.285 0.285" rpy="0 0 0" />
    <parent link="chassis" />
    <child link="footrest_right" />
    <axis xyz="1 0 0" />
    <limit effort="8" velocity="2.2" lower="0" upper="1.3" />
  </joint>
</robot>