<robot name="hinged_ceiling_light_fixture">
  <link name="ceiling_canopy">
    <inertial>
      <origin xyz="0 0 0.0115" rpy="0 0 0" />
      <mass value="0.9" />
      <inertia ixx="0.00366967" ixy="0" ixz="0" iyy="0.00366967" iyz="0" izz="0.00726" />
      </inertial>
    <visual name="ceiling_gasket">
      <origin xyz="0 0 0.0005" rpy="0 0 0" />
      <geometry>
        <box size="0.206 0.206 0.001" />
        </geometry>
      <material name="black_polymer">
        <color rgba="0.14 0.15 0.16 1" />
        </material>
      </visual>
    <visual name="junction_box_cover">
      <origin xyz="0 0 0.009" rpy="0 0 0" />
      <geometry>
        <box size="0.16 0.16 0.018" />
        </geometry>
      <material name="painted_white_metal">
        <color rgba="0.94 0.95 0.96 1" />
        </material>
      </visual>
    <visual name="canopy_trim_plate">
      <origin xyz="0 0 0.02" rpy="0 0 0" />
      <geometry>
        <box size="0.22 0.22 0.006" />
        </geometry>
      <material name="satin_aluminum">
        <color rgba="0.78 0.8 0.82 1" />
        </material>
      </visual>
    <visual name="left_mount_screw">
      <origin xyz="-0.048 0 0.004" rpy="0 0 0" />
      <geometry>
        <cylinder radius="0.007" length="0.003" />
        </geometry>
      <material name="brushed_steel">
        <color rgba="0.6 0.62 0.65 1" />
        </material>
      </visual>
    <visual name="right_mount_screw">
      <origin xyz="0.048 0 0.004" rpy="0 0 0" />
      <geometry>
        <cylinder radius="0.007" length="0.003" />
        </geometry>
      <material name="brushed_steel">
        <color rgba="0.6 0.62 0.65 1" />
        </material>
      </visual>
    </link>
  <link name="housing">
    <inertial>
      <origin xyz="0 0 0.0365" rpy="0 0 0" />
      <mass value="3.6" />
      <inertia ixx="0.0545187" ixy="0" ixz="0" iyy="0.0545187" iyz="0" izz="0.10584" />
      </inertial>
    <visual name="upper_pan">
      <origin xyz="0 0 0.0105" rpy="0 0 0" />
      <geometry>
        <box size="0.358 0.358 0.021" />
        </geometry>
      <material name="painted_white_metal">
        <color rgba="0.94 0.95 0.96 1" />
        </material>
      </visual>
    <visual name="side_frame">
      <origin xyz="0 0 0.02" rpy="0 0 0" />
      <geometry>
        <mesh filename="assets/meshes/housing_frame.obj" />
        </geometry>
      <material name="painted_white_metal">
        <color rgba="0.94 0.95 0.96 1" />
        </material>
      </visual>
    <visual name="trim_bezel">
      <origin xyz="0 0 0.054" rpy="0 0 0" />
      <geometry>
        <mesh filename="assets/meshes/bezel_ring.obj" />
        </geometry>
      <material name="satin_aluminum">
        <color rgba="0.78 0.8 0.82 1" />
        </material>
      </visual>
    <visual name="retaining_lip">
      <origin xyz="0 0 0.067" rpy="0 0 0" />
      <geometry>
        <mesh filename="assets/meshes/retaining_lip.obj" />
        </geometry>
      <material name="painted_white_metal">
        <color rgba="0.94 0.95 0.96 1" />
        </material>
      </visual>
    <visual name="reflector_pan">
      <origin xyz="0 0 0.025" rpy="0 0 0" />
      <geometry>
        <box size="0.322 0.322 0.01" />
        </geometry>
      <material name="painted_white_metal">
        <color rgba="0.94 0.95 0.96 1" />
        </material>
      </visual>
    <visual name="led_tray">
      <origin xyz="0 0 0.031" rpy="0 0 0" />
      <geometry>
        <box size="0.29 0.29 0.004" />
        </geometry>
      <material name="satin_aluminum">
        <color rgba="0.78 0.8 0.82 1" />
        </material>
      </visual>
    <visual name="driver_cover">
      <origin xyz="0 0 0.037" rpy="0 0 0" />
      <geometry>
        <box size="0.09 0.09 0.016" />
        </geometry>
      <material name="painted_white_metal">
        <color rgba="0.94 0.95 0.96 1" />
        </material>
      </visual>
    <visual name="hinge_rail">
      <origin xyz="0 -0.196 0.069" rpy="0 0 0" />
      <geometry>
        <box size="0.33 0.012 0.01" />
        </geometry>
      <material name="brushed_steel">
        <color rgba="0.6 0.62 0.65 1" />
        </material>
      </visual>
    <visual name="latch_strike">
      <origin xyz="0 0.196 0.069" rpy="0 0 0" />
      <geometry>
        <box size="0.06 0.012 0.01" />
        </geometry>
      <material name="brushed_steel">
        <color rgba="0.6 0.62 0.65 1" />
        </material>
      </visual>
    <visual name="left_hinge_cap">
      <origin xyz="-0.118 -0.196 0.069" rpy="0 0 0" />
      <geometry>
        <cylinder radius="0.006" length="0.01" />
        </geometry>
      <material name="brushed_steel">
        <color rgba="0.6 0.62 0.65 1" />
        </material>
      </visual>
    <visual name="right_hinge_cap">
      <origin xyz="0.118 -0.196 0.069" rpy="0 0 0" />
      <geometry>
        <cylinder radius="0.006" length="0.01" />
        </geometry>
      <material name="brushed_steel">
        <color rgba="0.6 0.62 0.65 1" />
        </material>
      </visual>
    </link>
  <link name="access_panel">
    <inertial>
      <origin xyz="0 0.194 0.01" rpy="0 0 0" />
      <mass value="1.1" />
      <inertia ixx="0.0138365" ixy="0" ixz="0" iyy="0.0141225" iyz="0" izz="0.0278857" />
      </inertial>
    <visual name="hinge_leaf">
      <origin xyz="0 0.006 0.006" rpy="0 0 0" />
      <geometry>
        <box size="0.33 0.014 0.012" />
        </geometry>
      <material name="brushed_steel">
        <color rgba="0.6 0.62 0.65 1" />
        </material>
      </visual>
    <visual name="service_frame">
      <origin xyz="0 0.194 0" rpy="0 0 0" />
      <geometry>
        <mesh filename="assets/meshes/access_frame.obj" />
        </geometry>
      <material name="satin_aluminum">
        <color rgba="0.78 0.8 0.82 1" />
        </material>
      </visual>
    <visual name="diffuser_panel">
      <origin xyz="0 0.194 0.005" rpy="0 0 0" />
      <geometry>
        <box size="0.356 0.352 0.006" />
        </geometry>
      <material name="frosted_acrylic">
        <color rgba="0.96 0.97 0.99 0.48" />
        </material>
      </visual>
    <visual name="latch_tab">
      <origin xyz="0 0.388 0.006" rpy="0 0 0" />
      <geometry>
        <box size="0.054 0.012 0.012" />
        </geometry>
      <material name="brushed_steel">
        <color rgba="0.6 0.62 0.65 1" />
        </material>
      </visual>
    <visual name="finger_pull">
      <origin xyz="0 0.391 0.01" rpy="0 0 0" />
      <geometry>
        <cylinder radius="0.01" length="0.012" />
        </geometry>
      <material name="black_polymer">
        <color rgba="0.14 0.15 0.16 1" />
        </material>
      </visual>
    </link>
  <joint name="canopy_to_housing" type="fixed">
    <origin xyz="0 0 0.023" rpy="0 0 0" />
    <parent link="ceiling_canopy" />
    <child link="housing" />
    </joint>
  <joint name="service_hinge" type="revolute">
    <origin xyz="0 -0.194 0.073" rpy="0 0 0" />
    <parent link="housing" />
    <child link="access_panel" />
    <axis xyz="1 0 0" />
    <limit effort="10" velocity="1.5" lower="0" upper="1.55" />
    </joint>
  </robot>
