<robot name="graphics_card">
  <material name="shroud_graphite">
    <color rgba="0.14 0.15 0.16 1" />
    </material>
  <material name="fan_black">
    <color rgba="0.08 0.08 0.09 1" />
    </material>
  <material name="heatsink_dark">
    <color rgba="0.19 0.2 0.22 1" />
    </material>
  <material name="brushed_metal">
    <color rgba="0.62 0.64 0.68 1" />
    </material>
  <material name="backplate_metal">
    <color rgba="0.34 0.36 0.39 1" />
    </material>
  <material name="pcb_green">
    <color rgba="0.08 0.11 0.08 1" />
    </material>
  <material name="connector_gold">
    <color rgba="0.8 0.66 0.24 1" />
    </material>
  <material name="accent_silver">
    <color rgba="0.55 0.57 0.6 1" />
    </material>
  <link name="card_body">
    <inertial>
      <origin xyz="0 -0.002 0" rpy="0 0 0" />
      <mass value="1.35" />
      <inertia ixx="0.0018873" ixy="0" ixz="0" iyy="0.011911" iyz="0" izz="0.0102262" />
      </inertial>
    <visual>
      <origin xyz="0 0.004 0" rpy="0 0 0" />
      <geometry>
        <mesh filename="meshes/graphics_card_shroud.obj" />
        </geometry>
      <material name="shroud_graphite" />
      </visual>
    <visual>
      <origin xyz="0 -0.006 0" rpy="0 0 0" />
      <geometry>
        <box size="0.282 0.014 0.102" />
        </geometry>
      <material name="heatsink_dark" />
      </visual>
    <visual>
      <origin xyz="0 -0.0081 -0.004" rpy="0 0 0" />
      <geometry>
        <box size="0.286 0.0022 0.104" />
        </geometry>
      <material name="pcb_green" />
      </visual>
    <visual>
      <origin xyz="0 -0.0141 0.002" rpy="0 0 0" />
      <geometry>
        <box size="0.292 0.0022 0.114" />
        </geometry>
      <material name="backplate_metal" />
      </visual>
    <visual>
      <origin xyz="0 -0.0152 0.031" rpy="0 0 0" />
      <geometry>
        <box size="0.214 0.003 0.016" />
        </geometry>
      <material name="accent_silver" />
      </visual>
    <visual>
      <origin xyz="0.058 -0.0152 -0.024" rpy="0 0 0" />
      <geometry>
        <box size="0.134 0.003 0.014" />
        </geometry>
      <material name="accent_silver" />
      </visual>
    <visual>
      <origin xyz="0.018 0.006 0.055" rpy="0 0 0" />
      <geometry>
        <box size="0.21 0.008 0.012" />
        </geometry>
      <material name="accent_silver" />
      </visual>
    <visual>
      <origin xyz="0.105 0.0005 0.056" rpy="0 0 0" />
      <geometry>
        <box size="0.022 0.013 0.012" />
        </geometry>
      <material name="heatsink_dark" />
      </visual>
    <visual>
      <origin xyz="0.138 0.0005 -0.002" rpy="0 0 0" />
      <geometry>
        <box size="0.024 0.024 0.084" />
        </geometry>
      <material name="heatsink_dark" />
      </visual>
    <visual>
      <origin xyz="-0.01 -0.0081 -0.055" rpy="0 0 0" />
      <geometry>
        <box size="0.092 0.004 0.01" />
        </geometry>
      <material name="connector_gold" />
      </visual>
    <visual>
      <origin xyz="-0.092 -0.001 0" rpy="-1.5708 0 0" />
      <geometry>
        <cylinder radius="0.0055" length="0.014" />
        </geometry>
      <material name="heatsink_dark" />
      </visual>
    <visual>
      <origin xyz="0 -0.001 0" rpy="-1.5708 0 0" />
      <geometry>
        <cylinder radius="0.0055" length="0.014" />
        </geometry>
      <material name="heatsink_dark" />
      </visual>
    <visual>
      <origin xyz="0.092 -0.001 0" rpy="-1.5708 0 0" />
      <geometry>
        <cylinder radius="0.0055" length="0.014" />
        </geometry>
      <material name="heatsink_dark" />
      </visual>
    <collision name="card_body__visual_1__hull_001">
      <origin xyz="0 0.004 0" rpy="0 0 0" />
      <geometry>
        <mesh filename="meshes/collision/cache/graphics_card_shroud__4e14d90d67d21ff0__hull_001.obj" />
        </geometry>
      </collision>
    <collision name="card_body__visual_2">
      <origin xyz="0 -0.006 0" rpy="0 0 0" />
      <geometry>
        <box size="0.282 0.014 0.102" />
        </geometry>
      </collision>
    <collision name="card_body__visual_3">
      <origin xyz="0 -0.0081 -0.004" rpy="0 0 0" />
      <geometry>
        <box size="0.286 0.0022 0.104" />
        </geometry>
      </collision>
    <collision name="card_body__visual_4">
      <origin xyz="0 -0.0141 0.002" rpy="0 0 0" />
      <geometry>
        <box size="0.292 0.0022 0.114" />
        </geometry>
      </collision>
    <collision name="card_body__visual_5">
      <origin xyz="0 -0.0152 0.031" rpy="0 0 0" />
      <geometry>
        <box size="0.214 0.003 0.016" />
        </geometry>
      </collision>
    <collision name="card_body__visual_6">
      <origin xyz="0.058 -0.0152 -0.024" rpy="0 0 0" />
      <geometry>
        <box size="0.134 0.003 0.014" />
        </geometry>
      </collision>
    <collision name="card_body__visual_7">
      <origin xyz="0.018 0.006 0.055" rpy="0 0 0" />
      <geometry>
        <box size="0.21 0.008 0.012" />
        </geometry>
      </collision>
    <collision name="card_body__visual_8">
      <origin xyz="0.105 0.0005 0.056" rpy="0 0 0" />
      <geometry>
        <box size="0.022 0.013 0.012" />
        </geometry>
      </collision>
    <collision name="card_body__visual_9">
      <origin xyz="0.138 0.0005 -0.002" rpy="0 0 0" />
      <geometry>
        <box size="0.024 0.024 0.084" />
        </geometry>
      </collision>
    <collision name="card_body__visual_10">
      <origin xyz="-0.01 -0.0081 -0.055" rpy="0 0 0" />
      <geometry>
        <box size="0.092 0.004 0.01" />
        </geometry>
      </collision>
    <collision name="card_body__visual_11">
      <origin xyz="-0.092 -0.001 0" rpy="-1.5708 0 0" />
      <geometry>
        <cylinder radius="0.0055" length="0.014" />
        </geometry>
      </collision>
    <collision name="card_body__visual_12">
      <origin xyz="0 -0.001 0" rpy="-1.5708 0 0" />
      <geometry>
        <cylinder radius="0.0055" length="0.014" />
        </geometry>
      </collision>
    <collision name="card_body__visual_13">
      <origin xyz="0.092 -0.001 0" rpy="-1.5708 0 0" />
      <geometry>
        <cylinder radius="0.0055" length="0.014" />
        </geometry>
      </collision>
    </link>
  <link name="io_bracket">
    <inertial>
      <mass value="0.08" />
      <inertia ixx="0.000100507" ixy="0" ixz="0" iyy="9.60267e-05" iyz="0" izz="4.53333e-06" />
      </inertial>
    <visual>
      <geometry>
        <mesh filename="meshes/graphics_card_bracket.obj" />
        </geometry>
      <material name="brushed_metal" />
      </visual>
    <collision name="io_bracket__visual_1__hull_001">
      <geometry>
        <mesh filename="meshes/collision/cache/graphics_card_bracket__cac1435064bebe9e__hull_001.obj" />
        </geometry>
      </collision>
    <collision name="io_bracket__visual_1__hull_002">
      <geometry>
        <mesh filename="meshes/collision/cache/graphics_card_bracket__cac1435064bebe9e__hull_002.obj" />
        </geometry>
      </collision>
    <collision name="io_bracket__visual_1__hull_003">
      <geometry>
        <mesh filename="meshes/collision/cache/graphics_card_bracket__cac1435064bebe9e__hull_003.obj" />
        </geometry>
      </collision>
    <collision name="io_bracket__visual_1__hull_004">
      <geometry>
        <mesh filename="meshes/collision/cache/graphics_card_bracket__cac1435064bebe9e__hull_004.obj" />
        </geometry>
      </collision>
    <collision name="io_bracket__visual_1__hull_005">
      <geometry>
        <mesh filename="meshes/collision/cache/graphics_card_bracket__cac1435064bebe9e__hull_005.obj" />
        </geometry>
      </collision>
    <collision name="io_bracket__visual_1__hull_006">
      <geometry>
        <mesh filename="meshes/collision/cache/graphics_card_bracket__cac1435064bebe9e__hull_006.obj" />
        </geometry>
      </collision>
    <collision name="io_bracket__visual_1__hull_007">
      <geometry>
        <mesh filename="meshes/collision/cache/graphics_card_bracket__cac1435064bebe9e__hull_007.obj" />
        </geometry>
      </collision>
    <collision name="io_bracket__visual_1__hull_008">
      <geometry>
        <mesh filename="meshes/collision/cache/graphics_card_bracket__cac1435064bebe9e__hull_008.obj" />
        </geometry>
      </collision>
    </link>
  <link name="fan_left">
    <inertial>
      <origin xyz="0 0 0" rpy="-1.5708 0 0" />
      <mass value="0.05" />
      <inertia ixx="2.08406e-05" ixy="0" ixz="0" iyy="2.08406e-05" iyz="0" izz="4.10063e-05" />
      </inertial>
    <visual>
      <geometry>
        <mesh filename="meshes/graphics_card_fan.obj" />
        </geometry>
      <material name="fan_black" />
      </visual>
    <collision name="fan_left__visual_1__hull_001">
      <geometry>
        <mesh filename="meshes/collision/cache/graphics_card_fan__be805ed2de82bf0e__hull_001.obj" />
        </geometry>
      </collision>
    <collision name="fan_left__visual_1__hull_002">
      <geometry>
        <mesh filename="meshes/collision/cache/graphics_card_fan__be805ed2de82bf0e__hull_002.obj" />
        </geometry>
      </collision>
    <collision name="fan_left__visual_1__hull_003">
      <geometry>
        <mesh filename="meshes/collision/cache/graphics_card_fan__be805ed2de82bf0e__hull_003.obj" />
        </geometry>
      </collision>
    <collision name="fan_left__visual_1__hull_004">
      <geometry>
        <mesh filename="meshes/collision/cache/graphics_card_fan__be805ed2de82bf0e__hull_004.obj" />
        </geometry>
      </collision>
    <collision name="fan_left__visual_1__hull_005">
      <geometry>
        <mesh filename="meshes/collision/cache/graphics_card_fan__be805ed2de82bf0e__hull_005.obj" />
        </geometry>
      </collision>
    <collision name="fan_left__visual_1__hull_006">
      <geometry>
        <mesh filename="meshes/collision/cache/graphics_card_fan__be805ed2de82bf0e__hull_006.obj" />
        </geometry>
      </collision>
    <collision name="fan_left__visual_1__hull_007">
      <geometry>
        <mesh filename="meshes/collision/cache/graphics_card_fan__be805ed2de82bf0e__hull_007.obj" />
        </geometry>
      </collision>
    <collision name="fan_left__visual_1__hull_008">
      <geometry>
        <mesh filename="meshes/collision/cache/graphics_card_fan__be805ed2de82bf0e__hull_008.obj" />
        </geometry>
      </collision>
    <collision name="fan_left__visual_1__hull_009">
      <geometry>
        <mesh filename="meshes/collision/cache/graphics_card_fan__be805ed2de82bf0e__hull_009.obj" />
        </geometry>
      </collision>
    <collision name="fan_left__visual_1__hull_010">
      <geometry>
        <mesh filename="meshes/collision/cache/graphics_card_fan__be805ed2de82bf0e__hull_010.obj" />
        </geometry>
      </collision>
    <collision name="fan_left__visual_1__hull_011">
      <geometry>
        <mesh filename="meshes/collision/cache/graphics_card_fan__be805ed2de82bf0e__hull_011.obj" />
        </geometry>
      </collision>
    <collision name="fan_left__visual_1__hull_012">
      <geometry>
        <mesh filename="meshes/collision/cache/graphics_card_fan__be805ed2de82bf0e__hull_012.obj" />
        </geometry>
      </collision>
    <collision name="fan_left__visual_1__hull_013">
      <geometry>
        <mesh filename="meshes/collision/cache/graphics_card_fan__be805ed2de82bf0e__hull_013.obj" />
        </geometry>
      </collision>
    <collision name="fan_left__visual_1__hull_014">
      <geometry>
        <mesh filename="meshes/collision/cache/graphics_card_fan__be805ed2de82bf0e__hull_014.obj" />
        </geometry>
      </collision>
    <collision name="fan_left__visual_1__hull_015">
      <geometry>
        <mesh filename="meshes/collision/cache/graphics_card_fan__be805ed2de82bf0e__hull_015.obj" />
        </geometry>
      </collision>
    <collision name="fan_left__visual_1__hull_016">
      <geometry>
        <mesh filename="meshes/collision/cache/graphics_card_fan__be805ed2de82bf0e__hull_016.obj" />
        </geometry>
      </collision>
    </link>
  <link name="fan_center">
    <inertial>
      <origin xyz="0 0 0" rpy="-1.5708 0 0" />
      <mass value="0.05" />
      <inertia ixx="2.08406e-05" ixy="0" ixz="0" iyy="2.08406e-05" iyz="0" izz="4.10063e-05" />
      </inertial>
    <visual>
      <geometry>
        <mesh filename="meshes/graphics_card_fan.obj" />
        </geometry>
      <material name="fan_black" />
      </visual>
    <collision name="fan_center__visual_1__hull_001">
      <geometry>
        <mesh filename="meshes/collision/cache/graphics_card_fan__be805ed2de82bf0e__hull_001.obj" />
        </geometry>
      </collision>
    <collision name="fan_center__visual_1__hull_002">
      <geometry>
        <mesh filename="meshes/collision/cache/graphics_card_fan__be805ed2de82bf0e__hull_002.obj" />
        </geometry>
      </collision>
    <collision name="fan_center__visual_1__hull_003">
      <geometry>
        <mesh filename="meshes/collision/cache/graphics_card_fan__be805ed2de82bf0e__hull_003.obj" />
        </geometry>
      </collision>
    <collision name="fan_center__visual_1__hull_004">
      <geometry>
        <mesh filename="meshes/collision/cache/graphics_card_fan__be805ed2de82bf0e__hull_004.obj" />
        </geometry>
      </collision>
    <collision name="fan_center__visual_1__hull_005">
      <geometry>
        <mesh filename="meshes/collision/cache/graphics_card_fan__be805ed2de82bf0e__hull_005.obj" />
        </geometry>
      </collision>
    <collision name="fan_center__visual_1__hull_006">
      <geometry>
        <mesh filename="meshes/collision/cache/graphics_card_fan__be805ed2de82bf0e__hull_006.obj" />
        </geometry>
      </collision>
    <collision name="fan_center__visual_1__hull_007">
      <geometry>
        <mesh filename="meshes/collision/cache/graphics_card_fan__be805ed2de82bf0e__hull_007.obj" />
        </geometry>
      </collision>
    <collision name="fan_center__visual_1__hull_008">
      <geometry>
        <mesh filename="meshes/collision/cache/graphics_card_fan__be805ed2de82bf0e__hull_008.obj" />
        </geometry>
      </collision>
    <collision name="fan_center__visual_1__hull_009">
      <geometry>
        <mesh filename="meshes/collision/cache/graphics_card_fan__be805ed2de82bf0e__hull_009.obj" />
        </geometry>
      </collision>
    <collision name="fan_center__visual_1__hull_010">
      <geometry>
        <mesh filename="meshes/collision/cache/graphics_card_fan__be805ed2de82bf0e__hull_010.obj" />
        </geometry>
      </collision>
    <collision name="fan_center__visual_1__hull_011">
      <geometry>
        <mesh filename="meshes/collision/cache/graphics_card_fan__be805ed2de82bf0e__hull_011.obj" />
        </geometry>
      </collision>
    <collision name="fan_center__visual_1__hull_012">
      <geometry>
        <mesh filename="meshes/collision/cache/graphics_card_fan__be805ed2de82bf0e__hull_012.obj" />
        </geometry>
      </collision>
    <collision name="fan_center__visual_1__hull_013">
      <geometry>
        <mesh filename="meshes/collision/cache/graphics_card_fan__be805ed2de82bf0e__hull_013.obj" />
        </geometry>
      </collision>
    <collision name="fan_center__visual_1__hull_014">
      <geometry>
        <mesh filename="meshes/collision/cache/graphics_card_fan__be805ed2de82bf0e__hull_014.obj" />
        </geometry>
      </collision>
    <collision name="fan_center__visual_1__hull_015">
      <geometry>
        <mesh filename="meshes/collision/cache/graphics_card_fan__be805ed2de82bf0e__hull_015.obj" />
        </geometry>
      </collision>
    <collision name="fan_center__visual_1__hull_016">
      <geometry>
        <mesh filename="meshes/collision/cache/graphics_card_fan__be805ed2de82bf0e__hull_016.obj" />
        </geometry>
      </collision>
    </link>
  <link name="fan_right">
    <inertial>
      <origin xyz="0 0 0" rpy="-1.5708 0 0" />
      <mass value="0.05" />
      <inertia ixx="2.08406e-05" ixy="0" ixz="0" iyy="2.08406e-05" iyz="0" izz="4.10063e-05" />
      </inertial>
    <visual>
      <geometry>
        <mesh filename="meshes/graphics_card_fan.obj" />
        </geometry>
      <material name="fan_black" />
      </visual>
    <collision name="fan_right__visual_1__hull_001">
      <geometry>
        <mesh filename="meshes/collision/cache/graphics_card_fan__be805ed2de82bf0e__hull_001.obj" />
        </geometry>
      </collision>
    <collision name="fan_right__visual_1__hull_002">
      <geometry>
        <mesh filename="meshes/collision/cache/graphics_card_fan__be805ed2de82bf0e__hull_002.obj" />
        </geometry>
      </collision>
    <collision name="fan_right__visual_1__hull_003">
      <geometry>
        <mesh filename="meshes/collision/cache/graphics_card_fan__be805ed2de82bf0e__hull_003.obj" />
        </geometry>
      </collision>
    <collision name="fan_right__visual_1__hull_004">
      <geometry>
        <mesh filename="meshes/collision/cache/graphics_card_fan__be805ed2de82bf0e__hull_004.obj" />
        </geometry>
      </collision>
    <collision name="fan_right__visual_1__hull_005">
      <geometry>
        <mesh filename="meshes/collision/cache/graphics_card_fan__be805ed2de82bf0e__hull_005.obj" />
        </geometry>
      </collision>
    <collision name="fan_right__visual_1__hull_006">
      <geometry>
        <mesh filename="meshes/collision/cache/graphics_card_fan__be805ed2de82bf0e__hull_006.obj" />
        </geometry>
      </collision>
    <collision name="fan_right__visual_1__hull_007">
      <geometry>
        <mesh filename="meshes/collision/cache/graphics_card_fan__be805ed2de82bf0e__hull_007.obj" />
        </geometry>
      </collision>
    <collision name="fan_right__visual_1__hull_008">
      <geometry>
        <mesh filename="meshes/collision/cache/graphics_card_fan__be805ed2de82bf0e__hull_008.obj" />
        </geometry>
      </collision>
    <collision name="fan_right__visual_1__hull_009">
      <geometry>
        <mesh filename="meshes/collision/cache/graphics_card_fan__be805ed2de82bf0e__hull_009.obj" />
        </geometry>
      </collision>
    <collision name="fan_right__visual_1__hull_010">
      <geometry>
        <mesh filename="meshes/collision/cache/graphics_card_fan__be805ed2de82bf0e__hull_010.obj" />
        </geometry>
      </collision>
    <collision name="fan_right__visual_1__hull_011">
      <geometry>
        <mesh filename="meshes/collision/cache/graphics_card_fan__be805ed2de82bf0e__hull_011.obj" />
        </geometry>
      </collision>
    <collision name="fan_right__visual_1__hull_012">
      <geometry>
        <mesh filename="meshes/collision/cache/graphics_card_fan__be805ed2de82bf0e__hull_012.obj" />
        </geometry>
      </collision>
    <collision name="fan_right__visual_1__hull_013">
      <geometry>
        <mesh filename="meshes/collision/cache/graphics_card_fan__be805ed2de82bf0e__hull_013.obj" />
        </geometry>
      </collision>
    <collision name="fan_right__visual_1__hull_014">
      <geometry>
        <mesh filename="meshes/collision/cache/graphics_card_fan__be805ed2de82bf0e__hull_014.obj" />
        </geometry>
      </collision>
    <collision name="fan_right__visual_1__hull_015">
      <geometry>
        <mesh filename="meshes/collision/cache/graphics_card_fan__be805ed2de82bf0e__hull_015.obj" />
        </geometry>
      </collision>
    <collision name="fan_right__visual_1__hull_016">
      <geometry>
        <mesh filename="meshes/collision/cache/graphics_card_fan__be805ed2de82bf0e__hull_016.obj" />
        </geometry>
      </collision>
    </link>
  <joint name="body_to_io_bracket" type="fixed">
    <origin xyz="-0.151 0 0" rpy="0 0 0" />
    <parent link="card_body" />
    <child link="io_bracket" />
    </joint>
  <joint name="body_to_fan_left" type="continuous">
    <origin xyz="-0.092 0.004 0" rpy="0 0 0" />
    <parent link="card_body" />
    <child link="fan_left" />
    <axis xyz="0 1 0" />
    <limit effort="0.2" velocity="220" />
    </joint>
  <joint name="body_to_fan_center" type="continuous">
    <origin xyz="0 0.004 0" rpy="0 0 0" />
    <parent link="card_body" />
    <child link="fan_center" />
    <axis xyz="0 1 0" />
    <limit effort="0.2" velocity="220" />
    </joint>
  <joint name="body_to_fan_right" type="continuous">
    <origin xyz="0.092 0.004 0" rpy="0 0 0" />
    <parent link="card_body" />
    <child link="fan_right" />
    <axis xyz="0 1 0" />
    <limit effort="0.2" velocity="220" />
    </joint>
  </robot>
