<robot name="rotary_tree_mechanism">
  <material name="hub_gray">
    <color rgba="0.58 0.6 0.63 1" />
  </material>
  <material name="arm_blue">
    <color rgba="0.23 0.45 0.72 1" />
  </material>
  <link name="hub">
    <inertial>
      <mass value="1.15" />
      <inertia ixx="0.0008878" ixy="0" ixz="0" iyy="0.0008878" iyz="0" izz="0.0012167" />
    </inertial>
    <visual>
      <geometry>
        <mesh filename="meshes/rotary_tree_hub.glb" />
      </geometry>
      <material name="hub_gray" />
    </visual>
    <collision>
      <geometry>
        <cylinder radius="0.046" length="0.054" />
      </geometry>
    </collision>
    <collision>
      <geometry>
        <cylinder radius="0.017" length="0.072" />
      </geometry>
    </collision>
    <collision>
      <origin xyz="0.055 0 0" rpy="0 0 0" />
      <geometry>
        <box size="0.034 0.026 0.022" />
      </geometry>
    </collision>
    <collision>
      <origin xyz="-0.0275 0.0476314 0" rpy="0 0 2.0944" />
      <geometry>
        <box size="0.034 0.026 0.022" />
      </geometry>
    </collision>
    <collision>
      <origin xyz="-0.0275 -0.0476314 0" rpy="0 0 4.18879" />
      <geometry>
        <box size="0.034 0.026 0.022" />
      </geometry>
    </collision>
  </link>
  <link name="arm_a">
    <inertial>
      <origin xyz="0.082 0 0" rpy="0 0 0" />
      <mass value="0.24" />
      <inertia ixx="2.768e-05" ixy="0" ixz="0" iyy="0.0004964" iyz="0" izz="0.00050472" />
    </inertial>
    <visual>
      <geometry>
        <mesh filename="meshes/rotary_tree_arm.glb" />
      </geometry>
      <material name="arm_blue" />
    </visual>
    <collision>
      <geometry>
        <box size="0.03 0.028 0.03" />
      </geometry>
    </collision>
    <collision>
      <origin xyz="0.022 0 0" rpy="0 0 0" />
      <geometry>
        <box size="0.032 0.026 0.018" />
      </geometry>
    </collision>
    <collision>
      <origin xyz="0.092 0 0" rpy="0 0 0" />
      <geometry>
        <box size="0.118 0.018 0.012" />
      </geometry>
    </collision>
    <collision>
      <origin xyz="0.145 0 0" rpy="0 0 0" />
      <geometry>
        <box size="0.026 0.03 0.008" />
      </geometry>
    </collision>
    <collision>
      <origin xyz="0.16 0 0" rpy="0 0 0" />
      <geometry>
        <box size="0.028 0.028 0.028" />
      </geometry>
    </collision>
  </link>
  <link name="arm_b">
    <inertial>
      <origin xyz="0.082 0 0" rpy="0 0 0" />
      <mass value="0.24" />
      <inertia ixx="2.768e-05" ixy="0" ixz="0" iyy="0.0004964" iyz="0" izz="0.00050472" />
    </inertial>
    <visual>
      <geometry>
        <mesh filename="meshes/rotary_tree_arm.glb" />
      </geometry>
      <material name="arm_blue" />
    </visual>
    <collision>
      <geometry>
        <box size="0.03 0.028 0.03" />
      </geometry>
    </collision>
    <collision>
      <origin xyz="0.022 0 0" rpy="0 0 0" />
      <geometry>
        <box size="0.032 0.026 0.018" />
      </geometry>
    </collision>
    <collision>
      <origin xyz="0.092 0 0" rpy="0 0 0" />
      <geometry>
        <box size="0.118 0.018 0.012" />
      </geometry>
    </collision>
    <collision>
      <origin xyz="0.145 0 0" rpy="0 0 0" />
      <geometry>
        <box size="0.026 0.03 0.008" />
      </geometry>
    </collision>
    <collision>
      <origin xyz="0.16 0 0" rpy="0 0 0" />
      <geometry>
        <box size="0.028 0.028 0.028" />
      </geometry>
    </collision>
  </link>
  <link name="arm_c">
    <inertial>
      <origin xyz="0.082 0 0" rpy="0 0 0" />
      <mass value="0.24" />
      <inertia ixx="2.768e-05" ixy="0" ixz="0" iyy="0.0004964" iyz="0" izz="0.00050472" />
    </inertial>
    <visual>
      <geometry>
        <mesh filename="meshes/rotary_tree_arm.glb" />
      </geometry>
      <material name="arm_blue" />
    </visual>
    <collision>
      <geometry>
        <box size="0.03 0.028 0.03" />
      </geometry>
    </collision>
    <collision>
      <origin xyz="0.022 0 0" rpy="0 0 0" />
      <geometry>
        <box size="0.032 0.026 0.018" />
      </geometry>
    </collision>
    <collision>
      <origin xyz="0.092 0 0" rpy="0 0 0" />
      <geometry>
        <box size="0.118 0.018 0.012" />
      </geometry>
    </collision>
    <collision>
      <origin xyz="0.145 0 0" rpy="0 0 0" />
      <geometry>
        <box size="0.026 0.03 0.008" />
      </geometry>
    </collision>
    <collision>
      <origin xyz="0.16 0 0" rpy="0 0 0" />
      <geometry>
        <box size="0.028 0.028 0.028" />
      </geometry>
    </collision>
  </link>
  <joint name="hub_to_arm_a" type="revolute">
    <origin xyz="0.058 0 0" rpy="0 0 0" />
    <parent link="hub" />
    <child link="arm_a" />
    <axis xyz="0 -1 0" />
    <limit effort="8" velocity="1.5" lower="-0.65" upper="0.9" />
  </joint>
  <joint name="hub_to_arm_b" type="revolute">
    <origin xyz="-0.029 0.0502295 0" rpy="0 0 2.0944" />
    <parent link="hub" />
    <child link="arm_b" />
    <axis xyz="0 -1 0" />
    <limit effort="8" velocity="1.5" lower="-0.65" upper="0.9" />
  </joint>
  <joint name="hub_to_arm_c" type="revolute">
    <origin xyz="-0.029 -0.0502295 0" rpy="0 0 4.18879" />
    <parent link="hub" />
    <child link="arm_c" />
    <axis xyz="0 -1 0" />
    <limit effort="8" velocity="1.5" lower="-0.65" upper="0.9" />
  </joint>
</robot>