<robot name="folding_arm_chain">
  <material name="gunmetal">
    <color rgba="0.33 0.35 0.38 1" />
  </material>
  <material name="safety_orange">
    <color rgba="0.91 0.45 0.12 1" />
  </material>
  <material name="machine_black">
    <color rgba="0.12 0.13 0.14 1" />
  </material>
  <link name="base">
    <inertial>
      <origin xyz="-0.062 0 -0.008" rpy="0 0 0" />
      <mass value="2.4" />
      <inertia ixx="0.0013448" ixy="0" ixz="0" iyy="0.0034448" iyz="0" izz="0.00466" />
    </inertial>
    <visual>
      <origin xyz="0 0 -0.008" rpy="0 0 0" />
      <geometry>
        <mesh filename="meshes/base_mount.glb" />
      </geometry>
      <material name="gunmetal" />
    </visual>
    <collision>
      <origin xyz="-0.07 0 -0.008" rpy="0 0 0" />
      <geometry>
        <box size="0.13 0.08 0.016" />
      </geometry>
    </collision>
    <collision>
      <origin xyz="-0.024 0 -0.008" rpy="0 0 0" />
      <geometry>
        <box size="0.052 0.048 0.018" />
      </geometry>
    </collision>
    <collision>
      <origin xyz="0 0 -0.008" rpy="0 0 0" />
      <geometry>
        <cylinder radius="0.018" length="0.012" />
      </geometry>
    </collision>
  </link>
  <link name="arm_1">
    <inertial>
      <origin xyz="0.12 0 0.008" rpy="0 0 0" />
      <mass value="0.228" />
      <inertia ixx="4.6512e-05" ixy="0" ixz="0" iyy="0.00109714" iyz="0" izz="0.00113818" />
    </inertial>
    <visual>
      <origin xyz="0 0 0.008" rpy="0 0 0" />
      <geometry>
        <mesh filename="meshes/arm_1.glb" />
      </geometry>
      <material name="safety_orange" />
    </visual>
    <collision>
      <origin xyz="0.12 0 0.008" rpy="0 0 0" />
      <geometry>
        <box size="0.192 0.028 0.012" />
      </geometry>
    </collision>
    <collision>
      <origin xyz="0 0 0.008" rpy="0 0 0" />
      <geometry>
        <cylinder radius="0.016" length="0.012" />
      </geometry>
    </collision>
    <collision>
      <origin xyz="0.24 0 0.008" rpy="0 0 0" />
      <geometry>
        <cylinder radius="0.016" length="0.012" />
      </geometry>
    </collision>
  </link>
  <link name="arm_2">
    <inertial>
      <origin xyz="0.1 0 -0.008" rpy="0 0 0" />
      <mass value="0.19" />
      <inertia ixx="3.876e-05" ixy="0" ixz="0" iyy="0.000635613" iyz="0" izz="0.000669813" />
    </inertial>
    <visual>
      <origin xyz="0 0 -0.008" rpy="0 0 0" />
      <geometry>
        <mesh filename="meshes/arm_2.glb" />
      </geometry>
      <material name="gunmetal" />
    </visual>
    <collision>
      <origin xyz="0.1 0 -0.008" rpy="0 0 0" />
      <geometry>
        <box size="0.152 0.028 0.012" />
      </geometry>
    </collision>
    <collision>
      <origin xyz="0 0 -0.008" rpy="0 0 0" />
      <geometry>
        <cylinder radius="0.016" length="0.012" />
      </geometry>
    </collision>
    <collision>
      <origin xyz="0.2 0 -0.008" rpy="0 0 0" />
      <geometry>
        <cylinder radius="0.016" length="0.012" />
      </geometry>
    </collision>
  </link>
  <link name="arm_3">
    <inertial>
      <origin xyz="0.085 0 0.008" rpy="0 0 0" />
      <mass value="0.1615" />
      <inertia ixx="3.2946e-05" ixy="0" ixz="0" iyy="0.000390884" iyz="0" izz="0.000419954" />
    </inertial>
    <visual>
      <origin xyz="0 0 0.008" rpy="0 0 0" />
      <geometry>
        <mesh filename="meshes/arm_3.glb" />
      </geometry>
      <material name="safety_orange" />
    </visual>
    <collision>
      <origin xyz="0.085 0 0.008" rpy="0 0 0" />
      <geometry>
        <box size="0.122 0.028 0.012" />
      </geometry>
    </collision>
    <collision>
      <origin xyz="0 0 0.008" rpy="0 0 0" />
      <geometry>
        <cylinder radius="0.016" length="0.012" />
      </geometry>
    </collision>
    <collision>
      <origin xyz="0.17 0 0.008" rpy="0 0 0" />
      <geometry>
        <cylinder radius="0.016" length="0.012" />
      </geometry>
    </collision>
  </link>
  <link name="arm_4">
    <inertial>
      <origin xyz="0.07 0 -0.008" rpy="0 0 0" />
      <mass value="0.133" />
      <inertia ixx="2.7132e-05" ixy="0" ixz="0" iyy="0.000218829" iyz="0" izz="0.000242769" />
    </inertial>
    <visual>
      <origin xyz="0 0 -0.008" rpy="0 0 0" />
      <geometry>
        <mesh filename="meshes/arm_4.glb" />
      </geometry>
      <material name="gunmetal" />
    </visual>
    <collision>
      <origin xyz="0.07 0 -0.008" rpy="0 0 0" />
      <geometry>
        <box size="0.092 0.028 0.012" />
      </geometry>
    </collision>
    <collision>
      <origin xyz="0 0 -0.008" rpy="0 0 0" />
      <geometry>
        <cylinder radius="0.016" length="0.012" />
      </geometry>
    </collision>
    <collision>
      <origin xyz="0.14 0 -0.008" rpy="0 0 0" />
      <geometry>
        <cylinder radius="0.016" length="0.012" />
      </geometry>
    </collision>
  </link>
  <link name="tool_plate">
    <inertial>
      <origin xyz="0.052 0 0.008" rpy="0 0 0" />
      <mass value="0.22" />
      <inertia ixx="6.01333e-05" ixy="0" ixz="0" iyy="0.00019338" iyz="0" izz="0.000248233" />
    </inertial>
    <visual>
      <origin xyz="0 0 0.008" rpy="0 0 0" />
      <geometry>
        <mesh filename="meshes/tool_plate.glb" />
      </geometry>
      <material name="machine_black" />
    </visual>
    <collision>
      <origin xyz="0.052 0 0.008" rpy="0 0 0" />
      <geometry>
        <box size="0.084 0.056 0.012" />
      </geometry>
    </collision>
    <collision>
      <origin xyz="0 0 0.008" rpy="0 0 0" />
      <geometry>
        <cylinder radius="0.016" length="0.012" />
      </geometry>
    </collision>
  </link>
  <joint name="base_to_arm_1" type="revolute">
    <parent link="base" />
    <child link="arm_1" />
    <axis xyz="0 0 1" />
    <limit effort="40" velocity="1.5" lower="0" upper="0.7" />
  </joint>
  <joint name="arm_1_to_arm_2" type="revolute">
    <origin xyz="0.24 0 0" rpy="0 0 0" />
    <parent link="arm_1" />
    <child link="arm_2" />
    <axis xyz="0 0 1" />
    <limit effort="32" velocity="1.7" lower="0" upper="0.85" />
  </joint>
  <joint name="arm_2_to_arm_3" type="revolute">
    <origin xyz="0.2 0 0" rpy="0 0 0" />
    <parent link="arm_2" />
    <child link="arm_3" />
    <axis xyz="0 0 1" />
    <limit effort="24" velocity="1.9" lower="0" upper="0.85" />
  </joint>
  <joint name="arm_3_to_arm_4" type="revolute">
    <origin xyz="0.17 0 0" rpy="0 0 0" />
    <parent link="arm_3" />
    <child link="arm_4" />
    <axis xyz="0 0 1" />
    <limit effort="18" velocity="2.1" lower="0" upper="0.55" />
  </joint>
  <joint name="arm_4_to_tool_plate" type="fixed">
    <origin xyz="0.14 0 0" rpy="0 0 0" />
    <parent link="arm_4" />
    <child link="tool_plate" />
  </joint>
</robot>