<robot name="collectible_toy_airplane">
  <link name="airframe">
    <inertial>
      <origin xyz="0 0 0.005" rpy="0 0 0" />
      <mass value="0.36" />
      <inertia ixx="0.00432" ixy="0" ixz="0" iyy="0.003699" iyz="0" izz="0.007155" />
    </inertial>
    <visual>
      <geometry>
        <mesh filename="meshes/toy_plane_fuselage.glb" />
      </geometry>
    </visual>
    <visual>
      <geometry>
        <mesh filename="meshes/toy_plane_wing.glb" />
      </geometry>
    </visual>
    <visual>
      <geometry>
        <mesh filename="meshes/toy_plane_tailplane.glb" />
      </geometry>
    </visual>
    <visual>
      <geometry>
        <mesh filename="meshes/toy_plane_fin.glb" />
      </geometry>
    </visual>
    <visual>
      <geometry>
        <mesh filename="meshes/toy_plane_canopy.glb" />
      </geometry>
    </visual>
    <visual>
      <geometry>
        <mesh filename="meshes/toy_plane_left_main_strut.glb" />
      </geometry>
    </visual>
    <visual>
      <geometry>
        <mesh filename="meshes/toy_plane_right_main_strut.glb" />
      </geometry>
    </visual>
    <visual>
      <geometry>
        <mesh filename="meshes/toy_plane_tail_strut.glb" />
      </geometry>
    </visual>
    <visual>
      <origin xyz="0.046 -0.074 -0.052" rpy="1.5708 0 0" />
      <geometry>
        <cylinder radius="0.019" length="0.012" />
      </geometry>
    </visual>
    <visual>
      <origin xyz="0.046 0.074 -0.052" rpy="1.5708 0 0" />
      <geometry>
        <cylinder radius="0.019" length="0.012" />
      </geometry>
    </visual>
    <visual>
      <origin xyz="-0.146 0 -0.04" rpy="1.5708 0 0" />
      <geometry>
        <cylinder radius="0.011" length="0.008" />
      </geometry>
    </visual>
    <visual>
      <origin xyz="0.09 -0.024 0.005" rpy="0 1.5708 0" />
      <geometry>
        <cylinder radius="0.003" length="0.018" />
      </geometry>
    </visual>
    <visual>
      <origin xyz="0.09 0.024 0.005" rpy="0 1.5708 0" />
      <geometry>
        <cylinder radius="0.003" length="0.018" />
      </geometry>
    </visual>
    <collision name="airframe__visual_1__hull_001">
      <geometry>
        <mesh filename="meshes/collision/cache/526460b26769b7b0899ea411__hull_001.obj" />
      </geometry>
    </collision>
    <collision name="airframe__visual_2__hull_001">
      <geometry>
        <mesh filename="meshes/collision/cache/fbb459a0906f23db1389e195__hull_001.obj" />
      </geometry>
    </collision>
    <collision name="airframe__visual_3__hull_001">
      <geometry>
        <mesh filename="meshes/collision/cache/b7de6596d7c2887e06f2bf76__hull_001.obj" />
      </geometry>
    </collision>
    <collision name="airframe__visual_4__hull_001">
      <geometry>
        <mesh filename="meshes/collision/cache/cee55e9c14d07972907aa996__hull_001.obj" />
      </geometry>
    </collision>
    <collision name="airframe__visual_5__hull_001">
      <geometry>
        <mesh filename="meshes/collision/cache/5632e9a2729b9b041d73cce8__hull_001.obj" />
      </geometry>
    </collision>
    <collision name="airframe__visual_6__hull_001">
      <geometry>
        <mesh filename="meshes/collision/cache/1fad40890524711effa65c9d__hull_001.obj" />
      </geometry>
    </collision>
    <collision name="airframe__visual_7__hull_001">
      <geometry>
        <mesh filename="meshes/collision/cache/9b2577e0603d6a81fc2445b9__hull_001.obj" />
      </geometry>
    </collision>
    <collision name="airframe__visual_8__hull_001">
      <geometry>
        <mesh filename="meshes/collision/cache/28649420adb3537f48762635__hull_001.obj" />
      </geometry>
    </collision>
    <collision name="airframe__visual_9">
      <origin xyz="0.046 -0.074 -0.052" rpy="1.5708 0 0" />
      <geometry>
        <cylinder radius="0.019" length="0.012" />
      </geometry>
    </collision>
    <collision name="airframe__visual_10">
      <origin xyz="0.046 0.074 -0.052" rpy="1.5708 0 0" />
      <geometry>
        <cylinder radius="0.019" length="0.012" />
      </geometry>
    </collision>
    <collision name="airframe__visual_11">
      <origin xyz="-0.146 0 -0.04" rpy="1.5708 0 0" />
      <geometry>
        <cylinder radius="0.011" length="0.008" />
      </geometry>
    </collision>
    <collision name="airframe__visual_12">
      <origin xyz="0.09 -0.024 0.005" rpy="0 1.5708 0" />
      <geometry>
        <cylinder radius="0.003" length="0.018" />
      </geometry>
    </collision>
    <collision name="airframe__visual_13">
      <origin xyz="0.09 0.024 0.005" rpy="0 1.5708 0" />
      <geometry>
        <cylinder radius="0.003" length="0.018" />
      </geometry>
    </collision>
  </link>
  <link name="propeller">
    <inertial>
      <origin xyz="0.02 0 0" rpy="0 0 0" />
      <mass value="0.03" />
      <inertia ixx="0.0002645" ixy="0" ixz="0" iyy="0.0001445" iyz="0" izz="0.0001445" />
    </inertial>
    <visual>
      <geometry>
        <mesh filename="meshes/toy_plane_propeller.glb" />
      </geometry>
    </visual>
    <collision name="propeller__visual_1__hull_001">
      <geometry>
        <mesh filename="meshes/collision/cache/ea11232048b81ac7c3e28b5f__hull_001.obj" />
      </geometry>
    </collision>
    <collision name="propeller__visual_1__hull_002">
      <geometry>
        <mesh filename="meshes/collision/cache/ea11232048b81ac7c3e28b5f__hull_002.obj" />
      </geometry>
    </collision>
    <collision name="propeller__visual_1__hull_003">
      <geometry>
        <mesh filename="meshes/collision/cache/ea11232048b81ac7c3e28b5f__hull_003.obj" />
      </geometry>
    </collision>
    <collision name="propeller__visual_1__hull_004">
      <geometry>
        <mesh filename="meshes/collision/cache/ea11232048b81ac7c3e28b5f__hull_004.obj" />
      </geometry>
    </collision>
    <collision name="propeller__visual_1__hull_005">
      <geometry>
        <mesh filename="meshes/collision/cache/ea11232048b81ac7c3e28b5f__hull_005.obj" />
      </geometry>
    </collision>
  </link>
  <joint name="propeller_spin" type="continuous">
    <origin xyz="0.154 0 0" rpy="0 0 0" />
    <parent link="airframe" />
    <child link="propeller" />
    <axis xyz="1 0 0" />
    <limit effort="0.4" velocity="25" />
  </joint>
</robot>